Workbook
Name BTU_per_GWh: '[1]Conversion Factors'!$A$3
Name BTU_per_kg_biomass: '[1]Conversion Factors'!$B$25
Name BTU_per_thousand_tons_kerosene: '[1]Conversion Factors'!$A$18
Name BTU_per_thousand_tons_LPG: '[1]Conversion Factors'!$A$11
Name Preferences.AreaUnits: [2]Preferences!$C$7
Name Unit.m2: [2]Conversions!$F$77

Sheet About
A1: BASoBC BAU Amount Spent on Building Components
A3: Source: | B3: Building Component Costs per Unit
B4: NITI Aayog, Government of India
B5: 2023
B6: India Energy Security Scenarios, 2047 User Guide: Residential Lighting and Appliances
B7: http://indiaenergy.gov.in/iess/docs/Residential-Lighting_Appliances-documentation.pdf
B8: Page 7, Table 2 (Not updated since last IESS version)
B10: Building Envelope Costs per Square Meter of Surface by Surface Type
B11: NITI Aayog, Government of India
B12: 2023
B13: India Energy Security Scenarios, 2047 User Guide: Efficient Envelope Optimization for Residential and Commercial Buildings
B14: http://indiaenergy.gov.in/iess/docs/Building%20Envelope-documentation.pdf
B15: Page 13
B16: (Not updated since last version)
B17: Commercial Floorspace Projections | D17: Number of Rural and Urban Houshold Projections - for IESS low GDP scenario
B18: NITI Aayog, Government of India | D18: see bldgs/BCEU
B19: 2023 | D19: Tab: IESS Demand
B20: India Energy Security Scenarios 2047 downloadable Excel model | D20: Table: Urban/Rural Split (Number of Households)
B21: http://indiaenergy.gov.in/iess/docs/IESS_Version3.xlsx | D21: Updated till 2070 using intrapolation forumla for in between years of a five year interval values.
B22: Tab Xa
B24: Building Component Lifetimes
B25: See variable bldgs/CL
B27: Total Number of Appliances by Household Type
B28: World Bank
B29: 2008
B30: Residential Consumption of Electricity in India: Documentation of Data and Methodology
B31: http://www.moef.nic.in/downloads/public-information/Residentialpowerconsumption.pdf
B32: Pages 17-18, Tables 9-11 (using 2021 projection)
B34: Average Floorspace of Residential Unit in India
B35: Global Buildings Performance Network
B36: 2014
B37: Residential Buildings in India: Energy Use Projections and Savings Potentials
B38: http://www.gbpn.org/sites/default/files/08.%20INDIA%20Baseline_TR_low.pdf
B39: Page 28
A41: Note:
A42: We have data on the cost of various building components per component (such as per refrigerator)
A43: and data on the number of residences and square meters of commercial floorspace in future years.
A45: We multiply the component prices by the number of components in a typical residence to get the cost
A46: of that component per residence. We estimate components per square meter based on our urban
A47: residential data. We then estimate the number of new components as the number of net
...

Sheet Building Projections
A1: Number of households
M2: Millions
B3: Description | C3: Notes | D3: 2020 | E3: 2022 | F3: 2023 | G3: 2027 | H3: 2032 | I3: 2037 | J3: 2042 | K3: 2047 | L3: 2050 | M3: 2055 | N3: 2060 | O3: 2065 | P3: 2070 | R3: 2065
B4: Urban | D4: 112.1599 | E4: 119.89051 | F4: 123.86955 | G4: 140.51693 | H4: 162.89154 | I4: 186.7537 | J4: 211.82321 | K4: 238.10599 | L4: 248.39926 | M4: 264.79732 | N4: 280.25103 | O4: 294.5559 | P4: 307.44985
B5: Rural | D5: 195.00987 | E5: 197.3782 | F5: 198.48987 | G5: 202.38495 | H5: 205.85713 | I5: 207.47254 | J5: 207.04441 | K5: 204.75081 | L5: 198.85636 | M5: 188.02225 | N5: 176.20505 | O5: 163.5557 | P5: 150.20291
A7: Number of Households
B8: 2020 | C8: 2021 | D8: 2014 | E8: 2015 | F8: 2016 | G8: 2017 | H8: 2018 | I8: 2019 | J8: 2020 | K8: 2021 | L8: 2022 | M8: 2023 | N8: 2024 | O8: 2025 | P8: 2026 | Q8: 2027 | R8: 2028 | S8: 2029 | T8: 2030 | U8: 2031 | V8: 2032 | W8: 2033 | X8: 2034 | Y8: 2035 | Z8: 2036 | AA8: 2037 | AB8: 2038 | AC8: 2039 | AD8: 2040 | AE8: 2041 | AF8: 2042 | AG8: 2043 | AH8: 2044 | AI8: 2045 | AJ8: 2046 | AK8: 2047 | AL8: 2048 | AM8: 2049 | AN8: 2050 | AO8: 2051 | AP8: 2052 | AQ8: 2053 | AR8: 2054 | AS8: 2055 | AT8: 2056 | AU8: 2057 | AV8: 2058 | AW8: 2059 | AX8: 2060 | AY8: 2061 | AZ8: 2062 | BA8: 2063 | BB8: 2064 | BC8: 2065 | BD8: 2066 | BE8: 2067 | BF8: 2068 | BG8: 2069 | BH8: 2070
A9: Urban (mil) | B9: =TREND($D4:$E4,$D$3:$E$3,B$8) -> 112.1599 | C9: =TREND($D4:$E4,$D$3:$E$3,C$8) -> 116.0252 | D9: =TREND($D4:$E4,$D$3:$E$3,D$8) -> 88.968052 | E9: =TREND($D4:$E4,$D$3:$E$3,E$8) -> 92.83336 | F9: =TREND($D4:$E4,$D$3:$E$3,F$8) -> 96.698667 | G9: =TREND($D4:$E4,$D$3:$E$3,G$8) -> 100.56397 | H9: =TREND($E4:$F4,$E$3:$F$3,H$8) -> 103.97434 | I9: =TREND($E4:$F4,$E$3:$F$3,I$8) -> 107.95339 | J9: 112.1599 | K9: =TREND($E4:$F4,$E$3:$F$3,K$8) -> 115.91147 | L9: 119.89051 | M9: 123.86955 | N9: =TREND($F4:$G4,$F$3:$G$3,N$8) -> 128.0314 | O9: =TREND($F4:$G4,$F$3:$G$3,O$8) -> 132.19324 | P9: =TREND($F4:$G4,$F$3:$G$3,P$8) -> 136.35508 | Q9: =TREND($F4:$H4,$F$3:$H$3,Q$8) -> 140.97885 | R9: =TREND($G4:$H4,$G$3:$H$3,R$8) -> 144.99185 | S9: =TREND($G4:$H4,$G$3:$H$3,S$8) -> 149.46677 | T9: =TREND($G4:$H4,$G$3:$H$3,T$8) -> 153.94169 | U9: =TREND($G4:$H4,$G$3:$H$3,U$8) -> 158.41661 | V9: =TREND($H4:$I4,$H$3:$I$3,V$8) -> 162.89154 | W9: =TREND($H4:$I4,$H$3:$I$3,W$8) -> 167.66397 | X9: =TREND($H4:$I4,$H$3:$I$3,X$8) -> 172.4364 | Y9: =TREND($H4:$I4,$H$3:$I$3,Y$8) -> 177.20883 | Z9: =TREND($H4:$I4,$H$3:$I$3,Z$8) -> 181.98127 | AA9: =TREND($I4:$J4,$I$3:$J$3,AA$8) -> 186.7537 | AB9: =TREND($I4:$J4,$I$3:$J$3,AB$8) -> 191.7676 | AC9: =TREND($I4:$J4,$I$3:$J$3,AC$8) -> 196.7815 | AD9: =TREND($I4:$J4,$I$3:$J$3,AD$8) -> 201.79541 | AE9: =TREND($I4:$J4,$I$3:$J$3,AE$8) -> 206.80931 | AF9: =TREND($J4:$K4,$J$3:$K$3,AF$8) -> 211.82321 | AG9: =TREND($J4:$K4,$J$3:$K$3,AG$8) -> 217.07977 | AH9: =TREND($J4:$K4,$J$3:$K$3,AH$8) -> 222.33632 | AI9: =TREND($J4:$K4,$J$3:$K$3,AI$8) -> 227.59288 | AJ9: =TREND($J4:$K4,$J$3:$K$3,AJ$8) -> 232.84943 | AK9: =TREND($K4:$L4,$K$3:$L$3,AK$8) -> 238.10599 | AL9: =TREND($K4:$L4,$K$3:$L$3,AL$8) -> 241.53708 | AM9: =TREND($K4:$L4,$K$3:$L$3,AM$8) -> 244.96817 | AN9: =TREND($K4:$L4,$K$3:$L$3,AN$8) -> 248.39926 | AO9: =TREND($L4:$M4,$L$3:$M$3,AO$8) -> 251.67887 | AP9: =TREND($L4:$M4,$L$3:$M$3,AP$8) -> 254.95848 | AQ9: =TREND($L4:$M4,$L$3:$M$3,AQ$8) -> 258.23809 | AR9: =TREND($L4:$M4,$L$3:$M$3,AR$8) -> 261.51771 | AS9: 264.79732 | AT9: =TREND($M4:$N4,$M$3:$N$3,AT$8) -> 267.88806 | AU9: =TREND($M4:$N4,$M$3:$N$3,AU$8) -> 270.9788 | AV9: =TREND($M4:$N4,$M$3:$N$3,AV$8) -> 274.06955 | AW9: =TREND($M4:$N4,$M$3:$N$3,AW$8) -> 277.16029 | AX9: 280.25103 | AY9: =TREND($N4:$O4,$N$3:$O$3,AY$8) -> 283.11201 | AZ9: =TREND($N4:$O4,$N$3:$O$3,AZ$8) -> 285.97298 | BA9: =TREND($N4:$O4,$N$3:$O$3,BA$8) -> 288.83395 | BB9: =TREND($N4:$O4,$N$3:$O$3,BB$8) -> 291.69493 | BC9: 294.5559 | BD9: =TREND($O4:$P4,$O$3:$P$3,BD$8) -> 297.13469 | BE9: =TREND($O4:$P4,$O$3:$P$3,BE$8) -> 299.71348 | BF9: =TREND($O4:$P4,$O$3:$P$3,BF$8) -> 302.29227 | BG9: =TREND($O4:$P4,$O$3:$P$3,BG$8) -> 304.87106 | BH9: 307.44985
A10: Urban (households) | B10: =B9*10^6 -> 1.121599e+08 | C10: =C9*10^6 -> 1.160252e+08 | D10: =D9*10^6 -> 88968052 | E10: =E9*10^6 -> 92833360 | F10: =F9*10^6 -> 96698667 | G10: =G9*10^6 -> 1.0056397e+08 | H10: =H9*10^6 -> 1.0397434e+08 | I10: =I9*10^6 -> 1.0795339e+08 | ... BH10: =BH9*10^6 -> 3.0744985e+08
A11: Net Added Households | C11: =C10-B10 -> 3865307.5 | D11: =D10-C10 -> -27057153 | E11: =E10-D10 -> 3865307.5 | F11: =F10-E10 -> 3865307.5 | G11: =G10-F10 -> 3865307.5 | H11: =H10-G10 -> 3410369.4 | I11: =I10-H10 -> 3979042.1 | J11: =J10-I10 -> 4206511.2 | ... BH11: =BH10-BG10 -> 2578790.6
A13: Rural (mil) | B13: =TREND($D5:$E5,$D$3:$E$3,B$8) -> 195.00987 | C13: =TREND($D5:$E5,$D$3:$E$3,C$8) -> 196.19403 | D13: =TREND($D5:$E5,$D$3:$E$3,D$8) -> 187.90491 | E13: =TREND($D5:$E5,$D$3:$E$3,E$8) -> 189.08907 | F13: =TREND($D5:$E5,$D$3:$E$3,F$8) -> 190.27323 | G13: =TREND($D5:$E5,$D$3:$E$3,G$8) -> 191.45739 | H13: =TREND($E5:$F5,$E$3:$F$3,H$8) -> 192.93149 | I13: =TREND($E5:$F5,$E$3:$F$3,I$8) -> 194.04317 | J13: =TREND($E5:$F5,$E$3:$F$3,J$8) -> 195.15484 | K13: =TREND($E5:$F5,$E$3:$F$3,K$8) -> 196.26652 | L13: =TREND($E5:$F5,$E$3:$F$3,L$8) -> 197.3782 | M13: =TREND($F5:$H5,$F$3:$H$3,M$8) -> 198.71883 | N13: =TREND($F5:$H5,$F$3:$H$3,N$8) -> 199.53233 | O13: =TREND($F5:$H5,$F$3:$H$3,O$8) -> 200.34583 | P13: =TREND($F5:$H5,$F$3:$H$3,P$8) -> 201.15932 | Q13: =TREND($F5:$H5,$F$3:$H$3,Q$8) -> 201.97282 | R13: =TREND($H5:$I5,$H$3:$I$3,R$8) -> 204.56481 | S13: =TREND($H5:$I5,$H$3:$I$3,S$8) -> 204.88789 | T13: =TREND($H5:$I5,$H$3:$I$3,T$8) -> 205.21097 | U13: =TREND($H5:$I5,$H$3:$I$3,U$8) -> 205.53405 | V13: =TREND($H5:$I5,$H$3:$I$3,V$8) -> 205.85713 | W13: =TREND($I5:$J5,$I$3:$J$3,W$8) -> 207.81504 | X13: =TREND($I5:$J5,$I$3:$J$3,X$8) -> 207.72942 | Y13: =TREND($I5:$J5,$I$3:$J$3,Y$8) -> 207.64379 | Z13: =TREND($I5:$J5,$I$3:$J$3,Z$8) -> 207.55817 | AA13: =TREND($I5:$J5,$I$3:$J$3,AA$8) -> 207.47254 | AB13: =TREND($J5:$K5,$J$3:$K$3,AB$8) -> 208.8793 | AC13: =TREND($J5:$K5,$J$3:$K$3,AC$8) -> 208.42058 | AD13: =TREND($J5:$K5,$J$3:$K$3,AD$8) -> 207.96186 | AE13: =TREND($J5:$K5,$J$3:$K$3,AE$8) -> 207.50314 | AF13: =TREND($J5:$K5,$J$3:$K$3,AF$8) -> 207.04441 | AG13: =TREND($K5:$L5,$K$3:$L$3,AG$8) -> 212.61007 | AH13: =TREND($K5:$L5,$K$3:$L$3,AH$8) -> 210.64526 | AI13: =TREND($K5:$L5,$K$3:$L$3,AI$8) -> 208.68044 | AJ13: =TREND($K5:$L5,$K$3:$L$3,AJ$8) -> 206.71562 | AK13: =TREND($K5:$L5,$K$3:$L$3,AK$8) -> 204.75081 | AL13: =TREND($K5:$L5,$K$3:$L$3,AL$8) -> 202.78599 | AM13: =TREND($K5:$L5,$K$3:$L$3,AM$8) -> 200.82118 | AN13: =TREND($K5:$L5,$K$3:$L$3,AN$8) -> 198.85636 | AO13: =TREND($L5:$M5,$L$3:$M$3,AO$8) -> 196.68954 | AP13: =TREND($L5:$M5,$L$3:$M$3,AP$8) -> 194.52272 | AQ13: =TREND($L5:$M5,$L$3:$M$3,AQ$8) -> 192.3559 | AR13: =TREND($L5:$M5,$L$3:$M$3,AR$8) -> 190.18908 | AS13: 188.02225 | AT13: =TREND($M5:$N5,$M$3:$N$3,AT$8) -> 185.65881 | AU13: =TREND($M5:$N5,$M$3:$N$3,AU$8) -> 183.29537 | AV13: =TREND($M5:$N5,$M$3:$N$3,AV$8) -> 180.93193 | AW13: =TREND($M5:$N5,$M$3:$N$3,AW$8) -> 178.56849 | AX13: 176.20505 | AY13: =TREND($N5:$O5,$N$3:$O$3,AY$8) -> 173.67518 | AZ13: =TREND($N5:$O5,$N$3:$O$3,AZ$8) -> 171.14531 | BA13: =TREND($N5:$O5,$N$3:$O$3,BA$8) -> 168.61544 | BB13: =TREND($N5:$O5,$N$3:$O$3,BB$8) -> 166.08557 | BC13: 163.5557 | BD13: =TREND($O5:$P5,$O$3:$P$3,BD$8) -> 160.88514 | BE13: =TREND($O5:$P5,$O$3:$P$3,BE$8) -> 158.21458 | BF13: =TREND($O5:$P5,$O$3:$P$3,BF$8) -> 155.54402 | BG13: =TREND($O5:$P5,$O$3:$P$3,BG$8) -> 152.87347 | BH13: 150.20291
A14: Rural (households) | B14: =B13*10^6 -> 1.9500987e+08 | C14: =C13*10^6 -> 1.9619403e+08 | D14: =D13*10^6 -> 1.8790491e+08 | E14: =E13*10^6 -> 1.8908907e+08 | F14: =F13*10^6 -> 1.9027323e+08 | G14: =G13*10^6 -> 1.9145739e+08 | H14: =H13*10^6 -> 1.9293149e+08 | I14: =I13*10^6 -> 1.9404317e+08 | ... BH14: =BH13*10^6 -> 1.5020291e+08
A15: Net Added Households | C15: =C14-B14 -> 1184161.2 | D15: =D14-C14 -> -8289128.4 | E15: =E14-D14 -> 1184161.2 | F15: =F14-E14 -> 1184161.2 | G15: =G14-F14 -> 1184161.2 | H15: =H14-G14 -> 1474103.6 | I15: =I14-H14 -> 1111675.6 | J15: =J14-I14 -> 1111675.6 | ... BH15: =BH14-BG14 -> -2670558.1
A18: Average Space Requirement Per Capita | N18: M ha/Capita
A19: Description | D19: Notes | E19: . | F19: .. | G19: 2012 | H19: 2017 | I19: 2022 | J19: 2027 | K19: 2032 | L19: 2037 | M19: 2042 | N19: 2047
A20: Commercial floor space per capita | G20: 0.6142241 | H20: 0.69288691 | I20: 0.80537862 | J20: 0.98494484 | K20: 1.2465304 | L20: 1.6580494 | M20: 2.1418191 | N20: 2.781017
A22: Population | G22: 1.2159477e+09 | H22: 1.2935602e+09 | I22: 1.3835919e+09 | J22: 1.4534669e+09 | K22: 1.5339376e+09 | L22: 1.5921494e+09 | M22: 1.6595791e+09 | N22: 1.7041729e+09
A23: Total Commercial Floor space estimates | D23: m2 | G23: 0.074686438 | H23: 0.08962909 | I23: 0.11143153 | J23: 0.14315847 | K23: 0.19120998 | L23: 0.26398624 | M23: 0.35545182 | N23: 0.47393337
A25: Commercial Floorspace
B26: 2012 | C26: 2013 | D26: 2014 | E26: 2015 | F26: 2016 | G26: 2017 | H26: 2018 | I26: 2019 | J26: 2020 | K26: 2021 | L26: 2022 | M26: 2023 | N26: 2024 | O26: 2025 | P26: 2026 | Q26: 2027 | R26: 2028 | S26: 2029 | T26: 2030 | U26: 2031 | V26: 2032 | W26: 2033 | X26: 2034 | Y26: 2035 | Z26: 2036 | AA26: 2037 | AB26: 2038 | AC26: 2039 | AD26: 2040 | AE26: 2041 | AF26: 2042 | AG26: 2043 | AH26: 2044 | AI26: 2045 | AJ26: 2046 | AK26: 2047 | AL26: 2048 | AM26: 2049 | AN26: 2050 | AO26: 2051 | AP26: 2052 | AQ26: 2053 | AR26: 2054 | AS26: 2055 | AT26: 2056 | AU26: 2057 | AV26: 2058 | AW26: 2059 | AX26: 2060 | AY26: 2061 | AZ26: 2062 | BA26: 2063 | BB26: 2064 | BC26: 2065 | BD26: 2066 | BE26: 2067 | BF26: 2068 | BG26: 2069 | BH26: 2070
A27: Commercial (M ha) | B27: =0.0003541248*B26^2-1.4263696642*B26+1436.389731348 -> 0.082151349 | C27: =0.0003541248*C26^2-1.4263696642*C26+1436.389731348 -> 0.081134005 | D27: =0.0003541248*D26^2-1.4263696642*D26+1436.389731348 -> 0.08082491 | E27: =0.0003541248*E26^2-1.4263696642*E26+1436.389731348 -> 0.081224065 | F27: =0.0003541248*F26^2-1.4263696642*F26+1436.389731348 -> 0.08233147 | G27: =0.0003541248*G26^2-1.4263696642*G26+1436.389731348 -> 0.084147124 | H27: =0.0003541248*H26^2-1.4263696642*H26+1436.389731348 -> 0.086671028 | I27: =0.0003541248*I26^2-1.4263696642*I26+1436.389731348 -> 0.089903181 | ... BH27: =0.0003541248*BH26^2-1.4263696642*BH26+1436.389731348 -> 1.193882
A28: Commercial (sq m) | B28: =B27*10^10 -> 8.2151349e+08 | C28: =C27*10^10 -> 8.1134005e+08 | D28: =D27*10^10 -> 8.082491e+08 | E28: =E27*10^10 -> 8.1224065e+08 | F28: =F27*10^10 -> 8.233147e+08 | G28: =G27*10^10 -> 8.4147124e+08 | H28: =H27*10^10 -> 8.6671028e+08 | I28: =I27*10^10 -> 8.9903181e+08 | ... BH28: =BH27*10^10 -> 1.193882e+10
A29: Net Added Floorspace | C29: =C28-B28 -> -10173442 | D29: =D28-C28 -> -3090946 | E29: =E28-D28 -> 3991550 | F29: =F28-E28 -> 11074046 | G29: =G28-F28 -> 18156542 | H29: =H28-G28 -> 25239038 | I29: =I28-H28 -> 32321534 | J29: =J28-I28 -> 39404030 | ... BH29: =BH28-BG28 -> 3.9352883e+08
H37: Note: We have calculated interim polulation between two five years value by intrapolation method

Sheet Appliances per Household
A1: Average Number of Appliances per Household
A2: Appliance | B2: No of Appliances (MILLIONS) | D2: No of households(MILLIONS) | F2: Appliances per household
B3: URBAN | C3: RURAL | D3: URBAN | E3: RURAL | F3: URBAN | G3: RURAL
A4: Radio | B4: 50 | C4: 75.4 | D4: ='Building Projections'!F4 -> 123.86955 | E4: ='Building Projections'!F5 -> 198.48987 | F4: =B4/$D$4 -> 0.40365044 | G4: =C4/$E$4 -> 0.37986825
A5: CD player | B5: 61.4 | C5: 65.1 | F5: =B5/$D$4 -> 0.49568274 | G5: =C5/$E$4 -> 0.32797643
A6: TV | B6: 97.8 | C6: 130.7 | F6: =B6/$D$4 -> 0.78954026 | G6: =C6/$E$4 -> 0.65847189
A7: DVD player | B7: 19.5 | C7: 8 | F7: =B7/$D$4 -> 0.15742367 | G7: =C7/$E$4 -> 0.040304324
A8: computer | B8: 11 | C8: 1.3 | F8: =B8/$D$4 -> 0.088803097 | G8: =C8/$E$4 -> 0.0065494526
A10: Refrigerator | B10: 76.1 | C10: 57 | F10: =B10/$D$4 -> 0.61435597 | G10: =C10/$E$4 -> 0.28716831
A11: Washing Machines | B11: 41.2 | C11: 9.5 | F11: =B11/$D$4 -> 0.33260796 | G11: =C11/$E$4 -> 0.047861384
A12: Electric Oven | B12: 21.8 | C12: 0 | F12: =B12/$D$4 -> 0.17599159 | G12: =C12/$E$4 -> 0
A13: Toaster | B13: 21.1 | C13: 0 | F13: =B13/$D$4 -> 0.17034049 | G13: =C13/$E$4 -> 0
A14: Microwave | B14: 28.9 | C14: 0 | F14: =B14/$D$4 -> 0.23330995 | G14: =C14/$E$4 -> 0
A16: Electric Water Heater | B16: 78.1 | C16: 0 | F16: =B16/$D$4 -> 0.63050199 | G16: =C16/$E$4 -> 0
A17: Fans | B17: 344.7 | C17: 384.3 | F17: =B17/$D$4 -> 2.7827661 | G17: =C17/$E$4 -> 1.9361189
A18: Air Cooler | B18: 61.8 | C18: 33.5 | F18: =B18/$D$4 -> 0.49891194 | G18: =C18/$E$4 -> 0.16877435
A19: Air conditioning | B19: 17.5 | C19: 2.6 | F19: =B19/$D$4 -> 0.14127765 | G19: =C19/$E$4 -> 0.013098905

Sheet Component Lifetimes
A1: Building Component | B1: Lifetime (yr)
A2: heating | B2: 19
A3: cooling and ventilation | B3: 15.833333
A4: envelope | B4: 51.818182
A5: lighting | B5: 9.1324201
A6: appliances | B6: 13.533333
A7: other component | B7: 15.4

Sheet Component Costs
A1: Building Component Costs
A2: Item | B2: Estimate | C2: Cost (Rs) / unit
A3: Lighting | B3: low | C3: 15
A4: Lighting | B4: high | C4: 700
A5: Ceiling fans | B5: low | C5: 800
A6: Ceiling fans | B6: high | C6: 1400
A7: Televisions | B7: low | C7: 10000
A8: Televisions | B8: high | C8: 16000
A9: Refrigerators | B9: low | C9: 17000
A10: Refrigerators | B10: high | C10: 24000
A11: Room Air Conditioners | B11: low | C11: 25000
A12: Room Air Conditioners | B12: high | C12: 35000
A14: Envelope Costs
A15: Envelope Component | C15: Cost (Rs) / sq meter
A16: wall | C16: 250
A17: roof | C17: 700
A18: window | C18: 1300

Sheet Envelope Lighting Calcs
A1: Average Floorspace of Residential Unit in India
A2: 105.9 | B2: square meters
A5: Calculating Wall, Roof, and Window Area
A6: We assume that average dwellings in India are one-story and have a footprint twice as long as wide.
A7: width * length = | C7: =A2 -> 105.9
A8: width * (2*width) = | C8: =C7 -> 105.9
A9: 2*width^2 = | C9: =C8 -> 105.9
A10: width^2 = | C10: =C9/2 -> 52.95
A11: width = | C11: =SQRT(C10) -> 7.2766751
A12: length = | C12: =2*C11 -> 14.55335
A14: We assume that stories are:
A15: 3 | B15: meters | C15: high
A17: Thus we get a total wall area, before accounting for windows, of:
A18: =(2*C11+2*C12)*A15 -> 130.98015 | B18: square meters of wall + windows
A20: We assume that one of the long walls has two windows, one short wall has one window,
A21: and the remaining short or long wall has one window, for a total of four.
A22: We assume each window has an area of 1 square meter.
A23: This gives:
A25: 4 | B25: square meters of window
A26: =A18-A25 -> 126.98015 | B26: square meters of wall
A27: =A2 -> 105.9 | B27: square meters of roof
A30: Estimating Number of Lights
A31: The floor area above is typical for a two-bedroom apartment.
A33: We assume that an urban two-bedroom apartment has:
A34: 3 | B34: bulbs in bedroom 1
A35: 3 | B35: bulbs in bedroom 2
A36: 4 | B36: bulbs in the kitchen
A37: 4 | B37: bulbs in the living/dining area
A38: 2 | B38: bulbs in the bathroom
A39: 1 | B39: bulb outside the front door
A40: =SUM(A34:A39) -> 17 | B40: bulbs per urban household
A42: We halve this number for a rural residence:
A43: =A40/2 -> 8.5 | B43: bulbs per rural household

Sheet Calculations 1
A1: Residential Buildings
A2: Component | B2: Cost (Rs) / unit | C2: Units / Urban Household | D2: Units / Rural Household | E2: Cost / Urban Household | F2: Cost / Rural Household | G2: EPS Model Category
A3: Room Air Conditioners | B3: =AVERAGE('Component Costs'!C11:C12) -> 30000 | C3: ='Appliances per Household'!F19 -> 0.14127765 | D3: ='Appliances per Household'!G19 -> 0.013098905 | E3: =$B3*C3 -> 4238.3296 | F3: =$B3*D3 -> 392.96715 | G3: cooling and ventilation
A4: Ceiling fans | B4: =AVERAGE('Component Costs'!C5:C6) -> 1100 | C4: ='Appliances per Household'!F17 -> 2.7827661 | D4: ='Appliances per Household'!G17 -> 1.9361189 | E4: =$B4*C4 -> 3061.0427 | F4: =$B4*D4 -> 2129.7308 | G4: cooling and ventilation
A5: wall | B5: ='Component Costs'!C16 -> 250 | C5: ='Envelope Lighting Calcs'!$A26 -> 126.98015 | D5: ='Envelope Lighting Calcs'!$A26 -> 126.98015 | E5: =$B5*C5 -> 31745.038 | F5: =$B5*D5 -> 31745.038 | G5: envelope
A6: roof | B6: ='Component Costs'!C17 -> 700 | C6: ='Envelope Lighting Calcs'!$A27 -> 105.9 | D6: ='Envelope Lighting Calcs'!$A27 -> 105.9 | E6: =$B6*C6 -> 74130 | F6: =$B6*D6 -> 74130 | G6: envelope
A7: window | B7: ='Component Costs'!C18 -> 1300 | C7: ='Envelope Lighting Calcs'!$A25 -> 4 | D7: ='Envelope Lighting Calcs'!$A25 -> 4 | E7: =$B7*C7 -> 5200 | F7: =$B7*D7 -> 5200 | G7: envelope
A8: Lighting | B8: =AVERAGE('Component Costs'!C3:C4) -> 357.5 | C8: ='Envelope Lighting Calcs'!A40 -> 17 | D8: ='Envelope Lighting Calcs'!A43 -> 8.5 | E8: =$B8*C8 -> 6077.5 | F8: =$B8*D8 -> 3038.75 | G8: lighting
A9: Refrigerators | B9: =AVERAGE('Component Costs'!C9:C10) -> 20500 | C9: ='Appliances per Household'!F10 -> 0.61435597 | D9: ='Appliances per Household'!G10 -> 0.28716831 | E9: =$B9*C9 -> 12594.297 | F9: =$B9*D9 -> 5886.9503 | G9: appliances
A10: Televisions | B10: =AVERAGE('Component Costs'!C7:C8) -> 13000 | C10: ='Appliances per Household'!F6 -> 0.78954026 | D10: ='Appliances per Household'!G6 -> 0.65847189 | E10: =$B10*C10 -> 10264.023 | F10: =$B10*D10 -> 8560.1345 | G10: appliances
A12: Additional appliances from World Bank document
A13: Component | B13: Assumed cost / unit
A14: Radio | B14: =B8 -> 357.5 | C14: ='Appliances per Household'!F4 -> 0.40365044 | D14: ='Appliances per Household'!G4 -> 0.37986825 | E14: =$B14*C14 -> 144.30503 | F14: =$B14*D14 -> 135.8029 | G14: other component
A15: CD player | B15: =B4/2 -> 550 | C15: ='Appliances per Household'!F5 -> 0.49568274 | D15: ='Appliances per Household'!G5 -> 0.32797643 | E15: =$B15*C15 -> 272.62551 | F15: =$B15*D15 -> 180.38704 | G15: other component
A16: DVD player | B16: =B4 -> 1100 | C16: ='Appliances per Household'!F7 -> 0.15742367 | D16: ='Appliances per Household'!G7 -> 0.040304324 | E16: =$B16*C16 -> 173.16604 | F16: =$B16*D16 -> 44.334756 | G16: other component
A17: Computer | B17: =B9 -> 20500 | C17: ='Appliances per Household'!F8 -> 0.088803097 | D17: ='Appliances per Household'!G8 -> 0.0065494526 | E17: =$B17*C17 -> 1820.4635 | F17: =$B17*D17 -> 134.26378 | G17: other component
A18: Washing Machines | B18: =B3 -> 30000 | C18: ='Appliances per Household'!F11 -> 0.33260796 | D18: ='Appliances per Household'!G11 -> 0.047861384 | E18: =$B18*C18 -> 9978.2388 | F18: =$B18*D18 -> 1435.8415 | G18: appliances
A19: Electric Oven | B19: =B3 -> 30000 | C19: ='Appliances per Household'!F12 -> 0.17599159 | D19: ='Appliances per Household'!G12 -> 0 | E19: =$B19*C19 -> 5279.7477 | F19: =$B19*D19 -> 0 | G19: appliances
A20: Toaster | B20: =B8*2 -> 715 | C20: ='Appliances per Household'!F13 -> 0.17034049 | D20: ='Appliances per Household'!G13 -> 0 | E20: =$B20*C20 -> 121.79345 | F20: =$B20*D20 -> 0 | G20: appliances
A21: Microwave | B21: =B8*3 -> 1072.5 | C21: ='Appliances per Household'!F14 -> 0.23330995 | D21: ='Appliances per Household'!G14 -> 0 | E21: =$B21*C21 -> 250.22493 | F21: =$B21*D21 -> 0 | G21: appliances
A22: Electric Water Heater | B22: =B9 -> 20500 | C22: ='Appliances per Household'!F16 -> 0.63050199 | D22: ='Appliances per Household'!G16 -> 0 | E22: =$B22*C22 -> 12925.291 | F22: =$B22*D22 -> 0 | G22: appliances
A23: Air Cooler | B23: =B9 -> 20500 | C23: ='Appliances per Household'!F18 -> 0.49891194 | D23: ='Appliances per Household'!G18 -> 0.16877435 | E23: =$B23*C23 -> 10227.695 | F23: =$B23*D23 -> 3459.8743 | G23: cooling and ventilation
A27: Commercial Buildings
A28: We don't have data on the number of units of each item per commercial building square meter.
A29: We will use urban households as a proxy, converting the per-household figures to be per square meter.
A30: We first adjust some of the per-household figures to make the household resemble a commercial
A31: building- for instance, by increasing the share that have air conditioners and decreasing the share
A32: that have DVD players- to improve accuracy.
A34: Component | B34: Cost (Rs) / unit | C34: Units / Proxy Building | D34: Units / Sq Meter | E34: Cost / Sq Meter | F34: EPS Model Category
A35: Room Air Conditioners | B35: =B3 -> 30000 | C35: =C3*10 -> 1.4127765 | D35: =C35/'Envelope Lighting Calcs'!$A$2 -> 0.013340666 | E35: =B35*D35 -> 400.21998 | F35: cooling and ventilation
A36: Ceiling fans | B36: =B4 -> 1100 | C36: =C4 -> 2.7827661 | D36: =C36/'Envelope Lighting Calcs'!$A$2 -> 0.026277301 | E36: =B36*D36 -> 28.905031 | F36: cooling and ventilation
A37: wall | B37: =B5 -> 250 | C37: =C5 -> 126.98015 | D37: =C37/'Envelope Lighting Calcs'!$A$2 -> 1.1990571 | E37: =B37*D37 -> 299.76429 | F37: envelope
A38: roof | B38: =B6 -> 700 | C38: =C6 -> 105.9 | D38: =C38/'Envelope Lighting Calcs'!$A$2 -> 1 | E38: =B38*D38 -> 700 | F38: envelope
A39: window | B39: =B7 -> 1300 | C39: =C7 -> 4 | D39: =C39/'Envelope Lighting Calcs'!$A$2 -> 0.037771483 | E39: =B39*D39 -> 49.102927 | F39: envelope
A40: Lighting | B40: =B8 -> 357.5 | C40: =C8 -> 17 | D40: =C40/'Envelope Lighting Calcs'!$A$2 -> 0.1605288 | E40: =B40*D40 -> 57.389046 | F40: lighting
A41: Refrigerators | B41: =B9 -> 20500 | C41: =C9 -> 0.61435597 | D41: =C41/'Envelope Lighting Calcs'!$A$2 -> 0.0058012839 | E41: =B41*D41 -> 118.92632 | F41: appliances
A42: Televisions | B42: =B10 -> 13000 | C42: =C10/4 -> 0.19738506 | D42: =C42/'Envelope Lighting Calcs'!$A$2 -> 0.0018638816 | E42: =B42*D42 -> 24.230461 | F42: appliances
A44: Additional appliances from World Bank document
A45: Component | B45: Assumed cost / unit
A46: Radio | B46: =B14 -> 357.5 | C46: =C14/10 -> 0.040365044 | D46: =C46/'Envelope Lighting Calcs'!$A$2 -> 0.00038116189 | E46: =B46*D46 -> 0.13626537 | F46: other component
...

Sheet Calculations 2
A1: Ruppees per dollar | B1: ("scaling-factors.xlsx")
A2: 2012 | B2: 54.77
A3: Urban Residential
A4: Number of Households Adding or Replacing This Component
B5: 2017 | C5: 2018 | D5: 2019 | E5: 2020 | F5: 2021 | G5: 2022 | H5: 2023 | I5: 2024 | J5: 2025 | K5: 2026 | L5: 2027 | M5: 2028 | N5: 2029 | O5: 2030 | P5: 2031 | Q5: 2032 | R5: 2033 | S5: 2034 | T5: 2035 | U5: 2036 | V5: 2037 | W5: 2038 | X5: 2039 | Y5: 2040 | Z5: 2041 | AA5: 2042 | AB5: 2043 | AC5: 2044 | AD5: 2045 | AE5: 2046 | AF5: 2047 | AG5: 2048 | AH5: 2049 | AI5: 2050 | AJ5: 2051 | AK5: 2052 | AL5: 2053 | AM5: 2054 | AN5: 2055 | AO5: 2056 | AP5: 2057 | AQ5: 2058 | AR5: 2059 | AS5: 2060 | AT5: 2061 | AU5: 2062 | AV5: 2063 | AW5: 2064 | AX5: 2065 | AY5: 2066 | AZ5: 2067 | BA5: 2068 | BB5: 2069 | BC5: 2070
A6: heating | B6: ='Building Projections'!G$11+(1/'Component Lifetimes'!$B2)*'Building Projections'!F$10 -> 8954711.1 | C6: ='Building Projections'!H$11+(1/'Component Lifetimes'!$B2)*'Building Projections'!G$10 -> 8703210.1 | D6: ='Building Projections'!I$11+(1/'Component Lifetimes'!$B2)*'Building Projections'!H$10 -> 9451376 | E6: ='Building Projections'!J$11+(1/'Component Lifetimes'!$B2)*'Building Projections'!I$10 -> 9888268.3 | F6: ='Building Projections'!K$11+(1/'Component Lifetimes'!$B2)*'Building Projections'!J$10 -> 9654725.5 | G6: ='Building Projections'!L$11+(1/'Component Lifetimes'!$B2)*'Building Projections'!K$10 -> 10079646 | H6: ='Building Projections'!M$11+(1/'Component Lifetimes'!$B2)*'Building Projections'!L$10 -> 10289069 | I6: ='Building Projections'!N$11+(1/'Component Lifetimes'!$B2)*'Building Projections'!M$10 -> 10681293 | ... BC6: ='Building Projections'!BH$11+(1/'Component Lifetimes'!$B2)*'Building Projections'!BG$10 -> 18624636
A7: cooling and ventilation | B7: ='Building Projections'!G$11+(1/'Component Lifetimes'!$B3)*'Building Projections'!F$10 -> 9972591.8 | C7: ='Building Projections'!H$11+(1/'Component Lifetimes'!$B3)*'Building Projections'!G$10 -> 9761778.3 | D7: ='Building Projections'!I$11+(1/'Component Lifetimes'!$B3)*'Building Projections'!H$10 -> 10545843 | E7: ='Building Projections'!J$11+(1/'Component Lifetimes'!$B3)*'Building Projections'!I$10 -> 11024620 | F7: ='Building Projections'!K$11+(1/'Component Lifetimes'!$B3)*'Building Projections'!J$10 -> 10835356 | G7: ='Building Projections'!L$11+(1/'Component Lifetimes'!$B3)*'Building Projections'!K$10 -> 11299767 | H7: ='Building Projections'!M$11+(1/'Component Lifetimes'!$B3)*'Building Projections'!L$10 -> 11551074 | I7: ='Building Projections'!N$11+(1/'Component Lifetimes'!$B3)*'Building Projections'!M$10 -> 11985184 | ... BC7: ='Building Projections'!BH$11+(1/'Component Lifetimes'!$B3)*'Building Projections'!BG$10 -> 21833805
A8: envelope | B8: ='Building Projections'!G$11+(1/'Component Lifetimes'!$B4)*'Building Projections'!F$10 -> 5731422.2 | C8: ='Building Projections'!H$11+(1/'Component Lifetimes'!$B4)*'Building Projections'!G$10 -> 5351077.6 | D8: ='Building Projections'!I$11+(1/'Component Lifetimes'!$B4)*'Building Projections'!H$10 -> 5985564.5 | E8: ='Building Projections'!J$11+(1/'Component Lifetimes'!$B4)*'Building Projections'!I$10 -> 6289822.1 | F8: ='Building Projections'!K$11+(1/'Component Lifetimes'!$B4)*'Building Projections'!J$10 -> 5916062.2 | G8: ='Building Projections'!L$11+(1/'Component Lifetimes'!$B4)*'Building Projections'!K$10 -> 6215930.1 | H8: ='Building Projections'!M$11+(1/'Component Lifetimes'!$B4)*'Building Projections'!L$10 -> 6292718.6 | I8: ='Building Projections'!N$11+(1/'Component Lifetimes'!$B4)*'Building Projections'!M$10 -> 6552308.3 | ... BC8: ='Building Projections'!BH$11+(1/'Component Lifetimes'!$B4)*'Building Projections'!BG$10 -> 8462267.2
A9: lighting | B9: ='Building Projections'!G$11+(1/'Component Lifetimes'!$B5)*'Building Projections'!F$10 -> 14453812 | C9: ='Building Projections'!H$11+(1/'Component Lifetimes'!$B5)*'Building Projections'!G$10 -> 14422125 | D9: ='Building Projections'!I$11+(1/'Component Lifetimes'!$B5)*'Building Projections'!H$10 -> 15364233 | E9: ='Building Projections'!J$11+(1/'Component Lifetimes'!$B5)*'Building Projections'!I$10 -> 16027407 | F9: ='Building Projections'!K$11+(1/'Component Lifetimes'!$B5)*'Building Projections'!J$10 -> 16033082 | G9: ='Building Projections'!L$11+(1/'Component Lifetimes'!$B5)*'Building Projections'!K$10 -> 16671348 | H9: ='Building Projections'!M$11+(1/'Component Lifetimes'!$B5)*'Building Projections'!L$10 -> 17107053 | I9: ='Building Projections'!N$11+(1/'Component Lifetimes'!$B5)*'Building Projections'!M$10 -> 17725559 | ... BC9: ='Building Projections'!BH$11+(1/'Component Lifetimes'!$B5)*'Building Projections'!BG$10 -> 35962172
A10: appliances | B10: ='Building Projections'!G$11+(1/'Component Lifetimes'!$B6)*'Building Projections'!F$10 -> 11010529 | C10: ='Building Projections'!H$11+(1/'Component Lifetimes'!$B6)*'Building Projections'!G$10 -> 10841205 | D10: ='Building Projections'!I$11+(1/'Component Lifetimes'!$B6)*'Building Projections'!H$10 -> 11661875 | E10: ='Building Projections'!J$11+(1/'Component Lifetimes'!$B6)*'Building Projections'!I$10 -> 12183362 | F10: ='Building Projections'!K$11+(1/'Component Lifetimes'!$B6)*'Building Projections'!J$10 -> 12039250 | G10: ='Building Projections'!L$11+(1/'Component Lifetimes'!$B6)*'Building Projections'!K$10 -> 12543929 | H10: ='Building Projections'!M$11+(1/'Component Lifetimes'!$B6)*'Building Projections'!L$10 -> 12837947 | I10: ='Building Projections'!N$11+(1/'Component Lifetimes'!$B6)*'Building Projections'!M$10 -> 13314766 | ... BC10: ='Building Projections'!BH$11+(1/'Component Lifetimes'!$B6)*'Building Projections'!BG$10 -> 25106209
A11: other component | B11: ='Building Projections'!G$11+(1/'Component Lifetimes'!$B7)*'Building Projections'!F$10 -> 10144442 | C11: ='Building Projections'!H$11+(1/'Component Lifetimes'!$B7)*'Building Projections'!G$10 -> 9940497.6 | D11: ='Building Projections'!I$11+(1/'Component Lifetimes'!$B7)*'Building Projections'!H$10 -> 10730623 | E11: ='Building Projections'!J$11+(1/'Component Lifetimes'!$B7)*'Building Projections'!I$10 -> 11216471 | F11: ='Building Projections'!K$11+(1/'Component Lifetimes'!$B7)*'Building Projections'!J$10 -> 11034683 | G11: ='Building Projections'!L$11+(1/'Component Lifetimes'!$B7)*'Building Projections'!K$10 -> 11505761 | H11: ='Building Projections'!M$11+(1/'Component Lifetimes'!$B7)*'Building Projections'!L$10 -> 11764140 | I11: ='Building Projections'!N$11+(1/'Component Lifetimes'!$B7)*'Building Projections'!M$10 -> 12205321 | ... BC11: ='Building Projections'!BH$11+(1/'Component Lifetimes'!$B7)*'Building Projections'!BG$10 -> 22375613
A13: Total Amount Spent on This Type of Component by Households (Rs.)
B14: 2017 | C14: 2018 | D14: 2019 | E14: 2020 | F14: 2021 | G14: 2022 | H14: 2023 | I14: 2024 | J14: 2025 | K14: 2026 | L14: 2027 | M14: 2028 | N14: 2029 | O14: 2030 | P14: 2031 | Q14: 2032 | R14: 2033 | S14: 2034 | T14: 2035 | U14: 2036 | V14: 2037 | W14: 2038 | X14: 2039 | Y14: 2040 | Z14: 2041 | AA14: 2042 | AB14: 2043 | AC14: 2044 | AD14: 2045 | AE14: 2046 | AF14: 2047 | AG14: 2048 | AH14: 2049 | AI14: 2050 | AJ14: 2051 | AK14: 2052 | AL14: 2053 | AM14: 2054 | AN14: 2055 | AO14: 2056 | AP14: 2057 | AQ14: 2058 | AR14: 2059 | AS14: 2060 | AT14: 2061 | AU14: 2062 | AV14: 2063 | AW14: 2064 | AX14: 2065 | AY14: 2066 | AZ14: 2067 | BA14: 2068 | BB14: 2069 | BC14: 2070
A15: heating | B15: =SUMIFS('Calculations 1'!$E$3:$E$23,'Calculations 1'!$G$3:$G$23,$A15)*B6 -> 0 | C15: =SUMIFS('Calculations 1'!$E$3:$E$23,'Calculations 1'!$G$3:$G$23,$A15)*C6 -> 0 | D15: =SUMIFS('Calculations 1'!$E$3:$E$23,'Calculations 1'!$G$3:$G$23,$A15)*D6 -> 0 | E15: =SUMIFS('Calculations 1'!$E$3:$E$23,'Calculations 1'!$G$3:$G$23,$A15)*E6 -> 0 | F15: =SUMIFS('Calculations 1'!$E$3:$E$23,'Calculations 1'!$G$3:$G$23,$A15)*F6 -> 0 | G15: =SUMIFS('Calculations 1'!$E$3:$E$23,'Calculations 1'!$G$3:$G$23,$A15)*G6 -> 0 | H15: =SUMIFS('Calculations 1'!$E$3:$E$23,'Calculations 1'!$G$3:$G$23,$A15)*H6 -> 0 | I15: =SUMIFS('Calculations 1'!$E$3:$E$23,'Calculations 1'!$G$3:$G$23,$A15)*I6 -> 0 | ... BC15: =SUMIFS('Calculations 1'!$E$3:$E$23,'Calculations 1'!$G$3:$G$23,$A15)*BC6 -> 0
A16: cooling and ventilation | B16: =SUMIFS('Calculations 1'!$E$3:$E$23,'Calculations 1'!$G$3:$G$23,$A16)*B7 -> 1.7479029e+11 | C16: =SUMIFS('Calculations 1'!$E$3:$E$23,'Calculations 1'!$G$3:$G$23,$A16)*C7 -> 1.7109534e+11 | D16: =SUMIFS('Calculations 1'!$E$3:$E$23,'Calculations 1'!$G$3:$G$23,$A16)*D7 -> 1.8483769e+11 | E16: =SUMIFS('Calculations 1'!$E$3:$E$23,'Calculations 1'!$G$3:$G$23,$A16)*E7 -> 1.9322925e+11 | F16: =SUMIFS('Calculations 1'!$E$3:$E$23,'Calculations 1'!$G$3:$G$23,$A16)*F7 -> 1.8991201e+11 | G16: =SUMIFS('Calculations 1'!$E$3:$E$23,'Calculations 1'!$G$3:$G$23,$A16)*G7 -> 1.9805177e+11 | H16: =SUMIFS('Calculations 1'!$E$3:$E$23,'Calculations 1'!$G$3:$G$23,$A16)*H7 -> 2.0245646e+11 | I16: =SUMIFS('Calculations 1'!$E$3:$E$23,'Calculations 1'!$G$3:$G$23,$A16)*I7 -> 2.1006512e+11 | ... BC16: =SUMIFS('Calculations 1'!$E$3:$E$23,'Calculations 1'!$G$3:$G$23,$A16)*BC7 -> 3.8268257e+11
A17: envelope | B17: =SUMIFS('Calculations 1'!$E$3:$E$23,'Calculations 1'!$G$3:$G$23,$A17)*B8 -> 6.3661793e+11 | C17: =SUMIFS('Calculations 1'!$E$3:$E$23,'Calculations 1'!$G$3:$G$23,$A17)*C8 -> 5.9437115e+11 | D17: =SUMIFS('Calculations 1'!$E$3:$E$23,'Calculations 1'!$G$3:$G$23,$A17)*D8 -> 6.648468e+11 | E17: =SUMIFS('Calculations 1'!$E$3:$E$23,'Calculations 1'!$G$3:$G$23,$A17)*E8 -> 6.9864223e+11 | F17: =SUMIFS('Calculations 1'!$E$3:$E$23,'Calculations 1'!$G$3:$G$23,$A17)*F8 -> 6.5712684e+11 | G17: =SUMIFS('Calculations 1'!$E$3:$E$23,'Calculations 1'!$G$3:$G$23,$A17)*G8 -> 6.9043467e+11 | H17: =SUMIFS('Calculations 1'!$E$3:$E$23,'Calculations 1'!$G$3:$G$23,$A17)*H8 -> 6.9896396e+11 | I17: =SUMIFS('Calculations 1'!$E$3:$E$23,'Calculations 1'!$G$3:$G$23,$A17)*I8 -> 7.277979e+11 | ... BC17: =SUMIFS('Calculations 1'!$E$3:$E$23,'Calculations 1'!$G$3:$G$23,$A17)*BC8 -> 9.3994665e+11
A18: lighting | B18: =SUMIFS('Calculations 1'!$E$3:$E$23,'Calculations 1'!$G$3:$G$23,$A18)*B9 -> 8.784304e+10 | C18: =SUMIFS('Calculations 1'!$E$3:$E$23,'Calculations 1'!$G$3:$G$23,$A18)*C9 -> 8.7650462e+10 | D18: =SUMIFS('Calculations 1'!$E$3:$E$23,'Calculations 1'!$G$3:$G$23,$A18)*D9 -> 9.3376125e+10 | E18: =SUMIFS('Calculations 1'!$E$3:$E$23,'Calculations 1'!$G$3:$G$23,$A18)*E9 -> 9.7406566e+10 | F18: =SUMIFS('Calculations 1'!$E$3:$E$23,'Calculations 1'!$G$3:$G$23,$A18)*F9 -> 9.7441054e+10 | G18: =SUMIFS('Calculations 1'!$E$3:$E$23,'Calculations 1'!$G$3:$G$23,$A18)*G9 -> 1.0132012e+11 | H18: =SUMIFS('Calculations 1'!$E$3:$E$23,'Calculations 1'!$G$3:$G$23,$A18)*H9 -> 1.0396812e+11 | I18: =SUMIFS('Calculations 1'!$E$3:$E$23,'Calculations 1'!$G$3:$G$23,$A18)*I9 -> 1.0772709e+11 | ... BC18: =SUMIFS('Calculations 1'!$E$3:$E$23,'Calculations 1'!$G$3:$G$23,$A18)*BC9 -> 2.185601e+11
A19: appliances | B19: =SUMIFS('Calculations 1'!$E$3:$E$23,'Calculations 1'!$G$3:$G$23,$A19)*B10 -> 5.6609113e+11 | C19: =SUMIFS('Calculations 1'!$E$3:$E$23,'Calculations 1'!$G$3:$G$23,$A19)*C10 -> 5.5738555e+11 | D19: =SUMIFS('Calculations 1'!$E$3:$E$23,'Calculations 1'!$G$3:$G$23,$A19)*D10 -> 5.9957919e+11 | E19: =SUMIFS('Calculations 1'!$E$3:$E$23,'Calculations 1'!$G$3:$G$23,$A19)*E10 -> 6.2639072e+11 | F19: =SUMIFS('Calculations 1'!$E$3:$E$23,'Calculations 1'!$G$3:$G$23,$A19)*F10 -> 6.1898139e+11 | G19: =SUMIFS('Calculations 1'!$E$3:$E$23,'Calculations 1'!$G$3:$G$23,$A19)*G10 -> 6.4492876e+11 | H19: =SUMIFS('Calculations 1'!$E$3:$E$23,'Calculations 1'!$G$3:$G$23,$A19)*H10 -> 6.6004528e+11 | I19: =SUMIFS('Calculations 1'!$E$3:$E$23,'Calculations 1'!$G$3:$G$23,$A19)*I10 -> 6.8456027e+11 | ... BC19: =SUMIFS('Calculations 1'!$E$3:$E$23,'Calculations 1'!$G$3:$G$23,$A19)*BC10 -> 1.290801e+12
A20: other component | B20: =SUMIFS('Calculations 1'!$E$3:$E$23,'Calculations 1'!$G$3:$G$23,$A20)*B11 -> 2.4453786e+10 | C20: =SUMIFS('Calculations 1'!$E$3:$E$23,'Calculations 1'!$G$3:$G$23,$A20)*C11 -> 2.3962166e+10 | D20: =SUMIFS('Calculations 1'!$E$3:$E$23,'Calculations 1'!$G$3:$G$23,$A20)*D11 -> 2.5866811e+10 | E20: =SUMIFS('Calculations 1'!$E$3:$E$23,'Calculations 1'!$G$3:$G$23,$A20)*E11 -> 2.7037978e+10 | F20: =SUMIFS('Calculations 1'!$E$3:$E$23,'Calculations 1'!$G$3:$G$23,$A20)*F11 -> 2.6599767e+10 | G20: =SUMIFS('Calculations 1'!$E$3:$E$23,'Calculations 1'!$G$3:$G$23,$A20)*G11 -> 2.7735328e+10 | H20: =SUMIFS('Calculations 1'!$E$3:$E$23,'Calculations 1'!$G$3:$G$23,$A20)*H11 -> 2.8358167e+10 | I20: =SUMIFS('Calculations 1'!$E$3:$E$23,'Calculations 1'!$G$3:$G$23,$A20)*I11 -> 2.9421659e+10 | ... BC20: =SUMIFS('Calculations 1'!$E$3:$E$23,'Calculations 1'!$G$3:$G$23,$A20)*BC11 -> 5.3937758e+10
A22: Total Amount Spent on This Type of Component by Households ($)
B23: 2017 | C23: 2018 | D23: 2019 | E23: 2020 | F23: 2021 | G23: 2022 | H23: 2023 | I23: 2024 | J23: 2025 | K23: 2026 | L23: 2027 | M23: 2028 | N23: 2029 | O23: 2030 | P23: 2031 | Q23: 2032 | R23: 2033 | S23: 2034 | T23: 2035 | U23: 2036 | V23: 2037 | W23: 2038 | X23: 2039 | Y23: 2040 | Z23: 2041 | AA23: 2042 | AB23: 2043 | AC23: 2044 | AD23: 2045 | AE23: 2046 | AF23: 2047 | AG23: 2048 | AH23: 2049 | AI23: 2050 | AJ23: 2051 | AK23: 2052 | AL23: 2053 | AM23: 2054 | AN23: 2055 | AO23: 2056 | AP23: 2057 | AQ23: 2058 | AR23: 2059 | AS23: 2060 | AT23: 2061 | AU23: 2062 | AV23: 2063 | AW23: 2064 | AX23: 2065 | AY23: 2066 | AZ23: 2067 | BA23: 2068 | BB23: 2069 | BC23: 2070
A24: heating | B24: =B15 -> 0 | C24: =C15 -> 0 | D24: =D15 -> 0 | E24: =E15 -> 0 | F24: =F15 -> 0 | G24: =G15 -> 0 | H24: =H15 -> 0 | I24: =I15 -> 0 | ... BC24: =BC15 -> 0
A25: cooling and ventilation | B25: =B16/$B$2 -> 3.1913508e+09 | C25: =C16/$B$2 -> 3.123888e+09 | D25: =D16/$B$2 -> 3.3747981e+09 | E25: =E16/$B$2 -> 3.5280126e+09 | F25: =F16/$B$2 -> 3.4674459e+09 | G25: =G16/$B$2 -> 3.6160629e+09 | H25: =H16/$B$2 -> 3.6964845e+09 | I25: =I16/$B$2 -> 3.8354047e+09 | ... BC25: =BC16/$B$2 -> 6.9870836e+09
A26: envelope | B26: =B17/$B$2 -> 1.1623479e+10 | C26: =C17/$B$2 -> 1.085213e+10 | D26: =D17/$B$2 -> 1.2138886e+10 | E26: =E17/$B$2 -> 1.2755929e+10 | F26: =F17/$B$2 -> 1.1997934e+10 | G26: =G17/$B$2 -> 1.2606074e+10 | H26: =H17/$B$2 -> 1.2761803e+10 | I26: =I17/$B$2 -> 1.3288258e+10 | ... BC26: =BC17/$B$2 -> 1.7161706e+10
A27: lighting | B27: =B18/$B$2 -> 1.6038532e+09 | C27: =C18/$B$2 -> 1.6003371e+09 | D27: =D18/$B$2 -> 1.7048772e+09 | E27: =E18/$B$2 -> 1.7784657e+09 | F27: =F18/$B$2 -> 1.7790954e+09 | G27: =G18/$B$2 -> 1.84992e+09 | H27: =H18/$B$2 -> 1.8982676e+09 | I27: =I18/$B$2 -> 1.9668995e+09 | ... BC27: =BC18/$B$2 -> 3.9905076e+09
A28: appliances | B28: =B19/$B$2 -> 1.0335788e+10 | C28: =C19/$B$2 -> 1.017684e+10 | D28: =D19/$B$2 -> 1.0947219e+10 | E28: =E19/$B$2 -> 1.1436749e+10 | F28: =F19/$B$2 -> 1.1301468e+10 | G28: =G19/$B$2 -> 1.1775219e+10 | H28: =H19/$B$2 -> 1.2051219e+10 | I28: =I19/$B$2 -> 1.2498818e+10 | ... BC28: =BC19/$B$2 -> 2.3567665e+10
A29: other component | B29: =B20/$B$2 -> 4.464814e+08 | C29: =C20/$B$2 -> 4.3750532e+08 | D29: =D20/$B$2 -> 4.7228064e+08 | E29: =E20/$B$2 -> 4.9366401e+08 | F29: =F20/$B$2 -> 4.8566307e+08 | G29: =G20/$B$2 -> 5.0639634e+08 | H29: =H20/$B$2 -> 5.1776824e+08 | I29: =I20/$B$2 -> 5.3718566e+08 | ... BC29: =BC20/$B$2 -> 9.8480479e+08
A31: Rural Residential
A32: Number of Households Adding or Replacing This Component
B33: 2017 | C33: 2018 | D33: 2019 | E33: 2020 | F33: 2021 | G33: 2022 | H33: 2023 | I33: 2024 | J33: 2025 | K33: 2026 | L33: 2027 | M33: 2028 | N33: 2029 | O33: 2030 | P33: 2031 | Q33: 2032 | R33: 2033 | S33: 2034 | T33: 2035 | U33: 2036 | V33: 2037 | W33: 2038 | X33: 2039 | Y33: 2040 | Z33: 2041 | AA33: 2042 | AB33: 2043 | AC33: 2044 | AD33: 2045 | AE33: 2046 | AF33: 2047 | AG33: 2048 | AH33: 2049 | AI33: 2050 | AJ33: 2051 | AK33: 2052 | AL33: 2053 | AM33: 2054 | AN33: 2055 | AO33: 2056 | AP33: 2057 | AQ33: 2058 | AR33: 2059 | AS33: 2060 | AT33: 2061 | AU33: 2062 | AV33: 2063 | AW33: 2064 | AX33: 2065 | AY33: 2066 | AZ33: 2067 | BA33: 2068 | BB33: 2069 | BC33: 2070
A34: heating | B34: ='Building Projections'!G$15+(1/'Component Lifetimes'!$B2)*'Building Projections'!F$14 -> 11198542 | C34: ='Building Projections'!H$15+(1/'Component Lifetimes'!$B2)*'Building Projections'!G$14 -> 11550808 | D34: ='Building Projections'!I$15+(1/'Component Lifetimes'!$B2)*'Building Projections'!H$14 -> 11265965 | E34: ='Building Projections'!J$15+(1/'Component Lifetimes'!$B2)*'Building Projections'!I$14 -> 11324474 | F34: ='Building Projections'!K$15+(1/'Component Lifetimes'!$B2)*'Building Projections'!J$14 -> 11382983 | G34: ='Building Projections'!L$15+(1/'Component Lifetimes'!$B2)*'Building Projections'!K$14 -> 11441492 | H34: ='Building Projections'!M$15+(1/'Component Lifetimes'!$B2)*'Building Projections'!L$14 -> 11728963 | I34: ='Building Projections'!N$15+(1/'Component Lifetimes'!$B2)*'Building Projections'!M$14 -> 11272383 | ... BC34: ='Building Projections'!BH$15+(1/'Component Lifetimes'!$B2)*'Building Projections'!BG$14 -> 5375413.8
A35: cooling and ventilation | B35: ='Building Projections'!G$15+(1/'Component Lifetimes'!$B3)*'Building Projections'!F$14 -> 13201418 | C35: ='Building Projections'!H$15+(1/'Component Lifetimes'!$B3)*'Building Projections'!G$14 -> 13566149 | D35: ='Building Projections'!I$15+(1/'Component Lifetimes'!$B3)*'Building Projections'!H$14 -> 13296823 | E35: ='Building Projections'!J$15+(1/'Component Lifetimes'!$B3)*'Building Projections'!I$14 -> 13367034 | F35: ='Building Projections'!K$15+(1/'Component Lifetimes'!$B3)*'Building Projections'!J$14 -> 13437245 | G35: ='Building Projections'!L$15+(1/'Component Lifetimes'!$B3)*'Building Projections'!K$14 -> 13507456 | H35: ='Building Projections'!M$15+(1/'Component Lifetimes'!$B3)*'Building Projections'!L$14 -> 13806628 | I35: ='Building Projections'!N$15+(1/'Component Lifetimes'!$B3)*'Building Projections'!M$14 -> 13364160 | ... BC35: ='Building Projections'!BH$15+(1/'Component Lifetimes'!$B3)*'Building Projections'!BG$14 -> 6984608.2
A36: envelope | B36: ='Building Projections'!G$15+(1/'Component Lifetimes'!$B4)*'Building Projections'!F$14 -> 4856100.7 | C36: ='Building Projections'!H$15+(1/'Component Lifetimes'!$B4)*'Building Projections'!G$14 -> 5168895.3 | D36: ='Building Projections'!I$15+(1/'Component Lifetimes'!$B4)*'Building Projections'!H$14 -> 4834915 | E36: ='Building Projections'!J$15+(1/'Component Lifetimes'!$B4)*'Building Projections'!I$14 -> 4856368.4 | F36: ='Building Projections'!K$15+(1/'Component Lifetimes'!$B4)*'Building Projections'!J$14 -> 4877821.7 | G36: ='Building Projections'!L$15+(1/'Component Lifetimes'!$B4)*'Building Projections'!K$14 -> 4899275.1 | H36: ='Building Projections'!M$15+(1/'Component Lifetimes'!$B4)*'Building Projections'!L$14 -> 5149689.7 | I36: ='Building Projections'!N$15+(1/'Component Lifetimes'!$B4)*'Building Projections'!M$14 -> 4648421.5 | ... BC36: ='Building Projections'!BH$15+(1/'Component Lifetimes'!$B4)*'Building Projections'!BG$14 -> 279631.6
A37: lighting | B37: ='Building Projections'!G$15+(1/'Component Lifetimes'!$B5)*'Building Projections'!F$14 -> 22019080 | C37: ='Building Projections'!H$15+(1/'Component Lifetimes'!$B5)*'Building Projections'!G$14 -> 22438688 | D37: ='Building Projections'!I$15+(1/'Component Lifetimes'!$B5)*'Building Projections'!H$14 -> 22237674 | E37: ='Building Projections'!J$15+(1/'Component Lifetimes'!$B5)*'Building Projections'!I$14 -> 22359403 | F37: ='Building Projections'!K$15+(1/'Component Lifetimes'!$B5)*'Building Projections'!J$14 -> 22481131 | G37: ='Building Projections'!L$15+(1/'Component Lifetimes'!$B5)*'Building Projections'!K$14 -> 22602860 | H37: ='Building Projections'!M$15+(1/'Component Lifetimes'!$B5)*'Building Projections'!L$14 -> 22953549 | I37: ='Building Projections'!N$15+(1/'Component Lifetimes'!$B5)*'Building Projections'!M$14 -> 22573209 | ... BC37: ='Building Projections'!BH$15+(1/'Component Lifetimes'!$B5)*'Building Projections'!BG$14 -> 14069086
A38: appliances | B38: ='Building Projections'!G$15+(1/'Component Lifetimes'!$B6)*'Building Projections'!F$14 -> 15243759 | C38: ='Building Projections'!H$15+(1/'Component Lifetimes'!$B6)*'Building Projections'!G$14 -> 15621201 | D38: ='Building Projections'!I$15+(1/'Component Lifetimes'!$B6)*'Building Projections'!H$14 -> 15367697 | E38: ='Building Projections'!J$15+(1/'Component Lifetimes'!$B6)*'Building Projections'!I$14 -> 15449841 | F38: ='Building Projections'!K$15+(1/'Component Lifetimes'!$B6)*'Building Projections'!J$14 -> 15531984 | G38: ='Building Projections'!L$15+(1/'Component Lifetimes'!$B6)*'Building Projections'!K$14 -> 15614128 | H38: ='Building Projections'!M$15+(1/'Component Lifetimes'!$B6)*'Building Projections'!L$14 -> 15925233 | I38: ='Building Projections'!N$15+(1/'Component Lifetimes'!$B6)*'Building Projections'!M$14 -> 15497154 | ... BC38: ='Building Projections'!BH$15+(1/'Component Lifetimes'!$B6)*'Building Projections'!BG$14 -> 8625510.9
A39: other component | B39: ='Building Projections'!G$15+(1/'Component Lifetimes'!$B7)*'Building Projections'!F$14 -> 13539566 | C39: ='Building Projections'!H$15+(1/'Component Lifetimes'!$B7)*'Building Projections'!G$14 -> 13906402 | D39: ='Building Projections'!I$15+(1/'Component Lifetimes'!$B7)*'Building Projections'!H$14 -> 13639695 | E39: ='Building Projections'!J$15+(1/'Component Lifetimes'!$B7)*'Building Projections'!I$14 -> 13711881 | F39: ='Building Projections'!K$15+(1/'Component Lifetimes'!$B7)*'Building Projections'!J$14 -> 13784068 | G39: ='Building Projections'!L$15+(1/'Component Lifetimes'!$B7)*'Building Projections'!K$14 -> 13856255 | H39: ='Building Projections'!M$15+(1/'Component Lifetimes'!$B7)*'Building Projections'!L$14 -> 14157403 | I39: ='Building Projections'!N$15+(1/'Component Lifetimes'!$B7)*'Building Projections'!M$14 -> 13717317 | ... BC39: ='Building Projections'!BH$15+(1/'Component Lifetimes'!$B7)*'Building Projections'!BG$14 -> 7256290.4
A41: Total Amount Spent on This Type of Component by Households (Rs.)
B42: 2017 | C42: 2018 | D42: 2019 | E42: 2020 | F42: 2021 | G42: 2022 | H42: 2023 | I42: 2024 | J42: 2025 | K42: 2026 | L42: 2027 | M42: 2028 | N42: 2029 | O42: 2030 | P42: 2031 | Q42: 2032 | R42: 2033 | S42: 2034 | T42: 2035 | U42: 2036 | V42: 2037 | W42: 2038 | X42: 2039 | Y42: 2040 | Z42: 2041 | AA42: 2042 | AB42: 2043 | AC42: 2044 | AD42: 2045 | AE42: 2046 | AF42: 2047 | AG42: 2048 | AH42: 2049 | AI42: 2050 | AJ42: 2051 | AK42: 2052 | AL42: 2053 | AM42: 2054 | AN42: 2055 | AO42: 2056 | AP42: 2057 | AQ42: 2058 | AR42: 2059 | AS42: 2060 | AT42: 2061 | AU42: 2062 | AV42: 2063 | AW42: 2064 | AX42: 2065 | AY42: 2066 | AZ42: 2067 | BA42: 2068 | BB42: 2069 | BC42: 2070
A43: heating | B43: =SUMIFS('Calculations 1'!$F$3:$F$23,'Calculations 1'!$G$3:$G$23,$A43)*B34 -> 0 | C43: =SUMIFS('Calculations 1'!$F$3:$F$23,'Calculations 1'!$G$3:$G$23,$A43)*C34 -> 0 | D43: =SUMIFS('Calculations 1'!$F$3:$F$23,'Calculations 1'!$G$3:$G$23,$A43)*D34 -> 0 | E43: =SUMIFS('Calculations 1'!$F$3:$F$23,'Calculations 1'!$G$3:$G$23,$A43)*E34 -> 0 | F43: =SUMIFS('Calculations 1'!$F$3:$F$23,'Calculations 1'!$G$3:$G$23,$A43)*F34 -> 0 | G43: =SUMIFS('Calculations 1'!$F$3:$F$23,'Calculations 1'!$G$3:$G$23,$A43)*G34 -> 0 | H43: =SUMIFS('Calculations 1'!$F$3:$F$23,'Calculations 1'!$G$3:$G$23,$A43)*H34 -> 0 | I43: =SUMIFS('Calculations 1'!$F$3:$F$23,'Calculations 1'!$G$3:$G$23,$A43)*I34 -> 0 | ... BC43: =SUMIFS('Calculations 1'!$F$3:$F$23,'Calculations 1'!$G$3:$G$23,$A43)*BC34 -> 0
A44: cooling and ventilation | B44: =SUMIFS('Calculations 1'!$F$3:$F$23,'Calculations 1'!$G$3:$G$23,$A44)*B35 -> 7.8978436e+10 | C44: =SUMIFS('Calculations 1'!$F$3:$F$23,'Calculations 1'!$G$3:$G$23,$A44)*C35 -> 8.1160468e+10 | D44: =SUMIFS('Calculations 1'!$F$3:$F$23,'Calculations 1'!$G$3:$G$23,$A44)*D35 -> 7.9549202e+10 | E44: =SUMIFS('Calculations 1'!$F$3:$F$23,'Calculations 1'!$G$3:$G$23,$A44)*E35 -> 7.9969245e+10 | F44: =SUMIFS('Calculations 1'!$F$3:$F$23,'Calculations 1'!$G$3:$G$23,$A44)*F35 -> 8.0389288e+10 | G44: =SUMIFS('Calculations 1'!$F$3:$F$23,'Calculations 1'!$G$3:$G$23,$A44)*G35 -> 8.0809331e+10 | H44: =SUMIFS('Calculations 1'!$F$3:$F$23,'Calculations 1'!$G$3:$G$23,$A44)*H35 -> 8.259915e+10 | I44: =SUMIFS('Calculations 1'!$F$3:$F$23,'Calculations 1'!$G$3:$G$23,$A44)*I35 -> 7.9952051e+10 | ... BC44: =SUMIFS('Calculations 1'!$F$3:$F$23,'Calculations 1'!$G$3:$G$23,$A44)*BC35 -> 4.1785923e+10
...

Sheet BASoBC-urban-residential
A1: $ | B1: 2021 | C1: 2022 | D1: 2023 | E1: 2024 | F1: 2025 | G1: 2026 | H1: 2027 | I1: 2028 | J1: 2029 | K1: 2030 | L1: 2031 | M1: 2032 | N1: 2033 | O1: 2034 | P1: 2035 | Q1: 2036 | R1: 2037 | S1: 2038 | T1: 2039 | U1: 2040 | V1: 2041 | W1: 2042 | X1: 2043 | Y1: 2044 | Z1: 2045 | AA1: 2046 | AB1: 2047 | AC1: 2048 | AD1: 2049 | AE1: 2050 | AF1: 2051 | AG1: 2052 | AH1: 2053 | AI1: 2054 | AJ1: 2055 | AK1: 2056 | AL1: 2057 | AM1: 2058 | AN1: 2059 | AO1: 2060 | AP1: 2061 | AQ1: 2062 | AR1: 2063 | AS1: 2064 | AT1: 2065 | AU1: 2066 | AV1: 2067 | AW1: 2068 | AX1: 2069 | AY1: 2070
A2: heating | B2: ='Calculations 2'!F24 -> 0 | C2: ='Calculations 2'!G24 -> 0 | D2: ='Calculations 2'!H24 -> 0 | E2: ='Calculations 2'!I24 -> 0 | F2: ='Calculations 2'!J24 -> 0 | G2: ='Calculations 2'!K24 -> 0 | H2: ='Calculations 2'!L24 -> 0 | I2: ='Calculations 2'!M24 -> 0 | ... AY2: ='Calculations 2'!BC24 -> 0
A3: cooling and ventilation | B3: ='Calculations 2'!F25 -> 3.4674459e+09 | C3: ='Calculations 2'!G25 -> 3.6160629e+09 | D3: ='Calculations 2'!H25 -> 3.6964845e+09 | E3: ='Calculations 2'!I25 -> 3.8354047e+09 | F3: ='Calculations 2'!J25 -> 3.919521e+09 | G3: ='Calculations 2'!K25 -> 4.0036372e+09 | H3: ='Calculations 2'!L25 -> 4.2355731e+09 | I3: ='Calculations 2'!M25 -> 4.1335749e+09 | ... AY3: ='Calculations 2'!BC25 -> 6.9870836e+09
A4: envelope | B4: 0 | C4: 0 | D4: 0 | E4: 0 | F4: 0 | G4: 0 | H4: 0 | I4: 0 | J4: 0 | K4: 0 | L4: 0 | M4: 0 | N4: 0 | O4: 0 | P4: 0 | Q4: 0 | R4: 0 | S4: 0 | T4: 0 | U4: 0 | V4: 0 | W4: 0 | X4: 0 | Y4: 0 | Z4: 0 | AA4: 0 | AB4: 0 | AC4: 1 | AD4: 2 | AE4: 3 | AF4: 4 | AG4: 5 | AH4: 6 | AI4: 7 | AJ4: 8 | AK4: 9 | AL4: 10 | AM4: 11 | AN4: 12 | AO4: 13 | AP4: 14 | AQ4: 15 | AR4: 16 | AS4: 17 | AT4: 18 | AU4: 19 | AV4: 20 | AW4: 21 | AX4: 22 | AY4: 23
A5: lighting | B5: ='Calculations 2'!F27 -> 1.7790954e+09 | C5: ='Calculations 2'!G27 -> 1.84992e+09 | D5: ='Calculations 2'!H27 -> 1.8982676e+09 | E5: ='Calculations 2'!I27 -> 1.9668995e+09 | F5: ='Calculations 2'!J27 -> 2.0174683e+09 | G5: ='Calculations 2'!K27 -> 2.068037e+09 | H5: ='Calculations 2'!L27 -> 2.1698621e+09 | I5: ='Calculations 2'!M27 -> 2.1582711e+09 | ... AY5: ='Calculations 2'!BC27 -> 3.9905076e+09
A6: appliances | B6: ='Calculations 2'!F28 -> 1.1301468e+10 | C6: ='Calculations 2'!G28 -> 1.1775219e+10 | D6: ='Calculations 2'!H28 -> 1.2051219e+10 | E6: ='Calculations 2'!I28 -> 1.2498818e+10 | F6: ='Calculations 2'!J28 -> 1.2787498e+10 | G6: ='Calculations 2'!K28 -> 1.3076178e+10 | H6: ='Calculations 2'!L28 -> 1.3798469e+10 | I6: ='Calculations 2'!M28 -> 1.3545858e+10 | ... AY6: ='Calculations 2'!BC28 -> 2.3567665e+10
A7: other component | B7: ='Calculations 2'!F29 -> 4.8566307e+08 | C7: ='Calculations 2'!G29 -> 5.0639634e+08 | D7: ='Calculations 2'!H29 -> 5.1776824e+08 | E7: ='Calculations 2'!I29 -> 5.3718566e+08 | F7: ='Calculations 2'!J29 -> 5.4908e+08 | G7: ='Calculations 2'!K29 -> 5.6097434e+08 | H7: ='Calculations 2'!L29 -> 5.9319884e+08 | I7: ='Calculations 2'!M29 -> 5.7953232e+08 | ... AY7: ='Calculations 2'!BC29 -> 9.8480479e+08

Sheet BASoBC-rural-residential
A1: $ | B1: 2021 | C1: 2022 | D1: 2023 | E1: 2024 | F1: 2025 | G1: 2026 | H1: 2027 | I1: 2028 | J1: 2029 | K1: 2030 | L1: 2031 | M1: 2032 | N1: 2033 | O1: 2034 | P1: 2035 | Q1: 2036 | R1: 2037 | S1: 2038 | T1: 2039 | U1: 2040 | V1: 2041 | W1: 2042 | X1: 2043 | Y1: 2044 | Z1: 2045 | AA1: 2046 | AB1: 2047 | AC1: 2048 | AD1: 2049 | AE1: 2050 | AF1: 2051 | AG1: 2052 | AH1: 2053 | AI1: 2054 | AJ1: 2055 | AK1: 2056 | AL1: 2057 | AM1: 2058 | AN1: 2059 | AO1: 2060 | AP1: 2061 | AQ1: 2062 | AR1: 2063 | AS1: 2064 | AT1: 2065 | AU1: 2066 | AV1: 2067 | AW1: 2068 | AX1: 2069 | AY1: 2070
A2: heating | B2: ='Calculations 2'!F52 -> 0 | C2: ='Calculations 2'!G52 -> 0 | D2: ='Calculations 2'!H52 -> 0 | E2: ='Calculations 2'!I52 -> 0 | F2: ='Calculations 2'!J52 -> 0 | G2: ='Calculations 2'!K52 -> 0 | H2: ='Calculations 2'!L52 -> 0 | I2: ='Calculations 2'!M52 -> 0 | ... AY2: ='Calculations 2'!BC52 -> 0
A3: cooling and ventilation | B3: ='Calculations 2'!F53 -> 1.4677613e+09 | C3: ='Calculations 2'!G53 -> 1.4754305e+09 | D3: ='Calculations 2'!H53 -> 1.5081094e+09 | E3: ='Calculations 2'!I53 -> 1.4597782e+09 | F3: ='Calculations 2'!J53 -> 1.4653903e+09 | G3: ='Calculations 2'!K53 -> 1.4710025e+09 | H3: ='Calculations 2'!L53 -> 1.4766146e+09 | I3: ='Calculations 2'!M53 -> 1.6764928e+09 | ... AY3: ='Calculations 2'!BC53 -> 7.6293451e+08
A4: envelope | B4: 0 | C4: 0 | D4: 0 | E4: 0 | F4: 0 | G4: 0 | H4: 0 | I4: 0 | J4: 0 | K4: 0 | L4: 0 | M4: 0 | N4: 0 | O4: 0 | P4: 0 | Q4: 0 | R4: 0 | S4: 0 | T4: 0 | U4: 0 | V4: 0 | W4: 0 | X4: 0 | Y4: 0 | Z4: 0 | AA4: 0 | AB4: 0 | AC4: 1 | AD4: 2 | AE4: 3 | AF4: 4 | AG4: 5 | AH4: 6 | AI4: 7 | AJ4: 8 | AK4: 9 | AL4: 10 | AM4: 11 | AN4: 12 | AO4: 13 | AP4: 14 | AQ4: 15 | AR4: 16 | AS4: 17 | AT4: 18 | AU4: 19 | AV4: 20 | AW4: 21 | AX4: 22 | AY4: 23
A5: lighting | B5: ='Calculations 2'!F55 -> 1.2472985e+09 | C5: ='Calculations 2'!G55 -> 1.2540522e+09 | D5: ='Calculations 2'!H55 -> 1.2735092e+09 | E5: ='Calculations 2'!I55 -> 1.2524071e+09 | F5: ='Calculations 2'!J55 -> 1.2573493e+09 | G5: ='Calculations 2'!K55 -> 1.2622916e+09 | H5: ='Calculations 2'!L55 -> 1.2672338e+09 | I5: ='Calculations 2'!M55 -> 1.3708503e+09 | ... AY5: ='Calculations 2'!BC55 -> 7.8058128e+08
A6: appliances | B6: ='Calculations 2'!F56 -> 4.5041695e+09 | C6: ='Calculations 2'!G56 -> 4.5279905e+09 | D6: ='Calculations 2'!H56 -> 4.6182088e+09 | E6: ='Calculations 2'!I56 -> 4.494069e+09 | F6: ='Calculations 2'!J56 -> 4.5115006e+09 | G6: ='Calculations 2'!K56 -> 4.5289323e+09 | H6: ='Calculations 2'!L56 -> 4.546364e+09 | I6: ='Calculations 2'!M56 -> 5.0795459e+09 | ... AY6: ='Calculations 2'!BC56 -> 2.5013393e+09
A7: other component | B7: ='Calculations 2'!F57 -> 1.2452434e+08 | C7: ='Calculations 2'!G57 -> 1.2517647e+08 | D7: ='Calculations 2'!H57 -> 1.2789702e+08 | E7: ='Calculations 2'!I57 -> 1.2392131e+08 | F7: ='Calculations 2'!J57 -> 1.2439852e+08 | G7: ='Calculations 2'!K57 -> 1.2487574e+08 | H7: ='Calculations 2'!L57 -> 1.2535295e+08 | I7: ='Calculations 2'!M57 -> 1.4189693e+08 | ... AY7: ='Calculations 2'!BC57 -> 65552836

Sheet BASoBC-commercial
A1: $ | B1: 2021 | C1: 2022 | D1: 2023 | E1: 2024 | F1: 2025 | G1: 2026 | H1: 2027 | I1: 2028 | J1: 2029 | K1: 2030 | L1: 2031 | M1: 2032 | N1: 2033 | O1: 2034 | P1: 2035 | Q1: 2036 | R1: 2037 | S1: 2038 | T1: 2039 | U1: 2040 | V1: 2041 | W1: 2042 | X1: 2043 | Y1: 2044 | Z1: 2045 | AA1: 2046 | AB1: 2047 | AC1: 2048 | AD1: 2049 | AE1: 2050 | AF1: 2051 | AG1: 2052 | AH1: 2053 | AI1: 2054 | AJ1: 2055 | AK1: 2056 | AL1: 2057 | AM1: 2058 | AN1: 2059 | AO1: 2060 | AP1: 2061 | AQ1: 2062 | AR1: 2063 | AS1: 2064 | AT1: 2065 | AU1: 2066 | AV1: 2067 | AW1: 2068 | AX1: 2069 | AY1: 2070
A2: heating | B2: ='Calculations 2'!F80 -> 0 | C2: ='Calculations 2'!G80 -> 0 | D2: ='Calculations 2'!H80 -> 0 | E2: ='Calculations 2'!I80 -> 0 | F2: ='Calculations 2'!J80 -> 0 | G2: ='Calculations 2'!K80 -> 0 | H2: ='Calculations 2'!L80 -> 0 | I2: ='Calculations 2'!M80 -> 0 | ... AY2: ='Calculations 2'!BC80 -> 0
A3: cooling and ventilation | B3: ='Calculations 2'!F81 -> 1.0150888e+09 | C3: ='Calculations 2'!G81 -> 1.1112502e+09 | D3: ='Calculations 2'!H81 -> 1.211705e+09 | E3: ='Calculations 2'!I81 -> 1.3164534e+09 | F3: ='Calculations 2'!J81 -> 1.4254953e+09 | G3: ='Calculations 2'!K81 -> 1.5388306e+09 | H3: ='Calculations 2'!L81 -> 1.6564595e+09 | I3: ='Calculations 2'!M81 -> 1.7783819e+09 | ... AY3: ='Calculations 2'!BC81 -> 1.0776161e+10
A4: envelope | B4: 0 | C4: 0 | D4: 0 | E4: 0 | F4: 0 | G4: 0 | H4: 0 | I4: 0 | J4: 0 | K4: 0 | L4: 0 | M4: 0 | N4: 0 | O4: 0 | P4: 0 | Q4: 0 | R4: 0 | S4: 0 | T4: 0 | U4: 0 | V4: 0 | W4: 0 | X4: 0 | Y4: 0 | Z4: 0 | AA4: 0 | AB4: 0 | AC4: 1 | AD4: 2 | AE4: 3 | AF4: 4 | AG4: 5 | AH4: 6 | AI4: 7 | AJ4: 8 | AK4: 9 | AL4: 10 | AM4: 11 | AN4: 12 | AO4: 13 | AP4: 14 | AQ4: 15 | AR4: 16 | AS4: 17 | AT4: 18 | AU4: 19 | AV4: 20 | AW4: 21 | AX4: 22 | AY4: 23
A5: lighting | B5: ='Calculations 2'!F83 -> 1.5638201e+08 | C5: ='Calculations 2'!G83 -> 1.6913687e+08 | D5: ='Calculations 2'!H83 -> 1.8270435e+08 | E5: ='Calculations 2'!I83 -> 1.9708444e+08 | F5: ='Calculations 2'!J83 -> 2.1227716e+08 | G5: ='Calculations 2'!K83 -> 2.2828249e+08 | H5: ='Calculations 2'!L83 -> 2.4510045e+08 | I5: ='Calculations 2'!M83 -> 2.6273102e+08 | ... AY5: ='Calculations 2'!BC83 -> 1.7370096e+09
A6: appliances | B6: ='Calculations 2'!F84 -> 5.8212026e+08 | C6: ='Calculations 2'!G84 -> 6.3497769e+08 | D6: ='Calculations 2'!H84 -> 6.9046525e+08 | E6: ='Calculations 2'!I84 -> 7.4858293e+08 | F6: ='Calculations 2'!J84 -> 8.0933074e+08 | G6: ='Calculations 2'!K84 -> 8.7270868e+08 | H6: ='Calculations 2'!L84 -> 9.3871674e+08 | I6: ='Calculations 2'!M84 -> 1.0073549e+09 | ... AY6: ='Calculations 2'!BC84 -> 6.2651634e+09
A7: other component | B7: ='Calculations 2'!F85 -> 6.7542567e+08 | C7: ='Calculations 2'!G85 -> 7.3893613e+08 | D7: ='Calculations 2'!H85 -> 8.0533823e+08 | E7: ='Calculations 2'!I85 -> 8.7463195e+08 | F7: ='Calculations 2'!J85 -> 9.4681729e+08 | G7: ='Calculations 2'!K85 -> 1.0218943e+09 | H7: ='Calculations 2'!L85 -> 1.0998629e+09 | I7: ='Calculations 2'!M85 -> 1.1807231e+09 | ... AY7: ='Calculations 2'!BC85 -> 7.1879913e+09
