Workbook
Name Fraction_coal: [1]About!$C$50
Name GDP_per_capita_ratio: #REF!
Name INR: [2]Conversions!$E$105
Name Percent_rural: [1]About!$A$77
Name Percent_urban: [1]About!$A$76
Name Preferences.moneyunits: [2]Preferences!$C$9
Name quadrillion: [1]About!$B$79
Name Table4: '[1]AEO Table 4'!$C$34:$AI$72
Name Table5: '[1]AEO Table 5'!$C$31:$AI$58

Sheet About
A1: ICpUEfEBE Incremental Cost per Unit Energy for Electrified Building Equipment
A3: Sources: | B3: Cost of technologies except commerial heat pumps | D3: Commercial heating and water heating heat pump costs
B4: EIA | D4: NREL
B5: 2018 | D5: 2018
B6: Updated Buildings Sector Appliance and Equipment Costs and Efficiencies | D6: Electrification Futures Study Technology Report Figure Data
B7: https://www.eia.gov/analysis/studies/buildings/equipcosts/pdf/full.pdf | D7: https://data.nrel.gov/system/files/93/EFS_70485_figure_data.xlsx
B8: p. 9, 12, 29, 46, 51, 54, 58, 90, 92, 120, 123 | D8: Tables 22 and 23
B10: GDP Per Capita | D10: Commercial building equipment load factors
B11: The World Bank | D11: NREL
B12: 2021 | D12: 2018
B13: "GDP per capita (current US$) | D13: Electrification Futures Study: End-Use Electric Technology Cost and Performance Projections through 2050
B14: https://data.worldbank.org/indicator/NY.GDP.PCAP.CD | D14: https://www.nrel.gov/docs/fy18osti/70485.pdf
D15: P.90
B16: Residential Cooking Fuel Use and Costs
B17: NITI Aayog | D17: Residential building equipment stock and average annual energy consumption
B18: 2023 | D18: EIA
B19: India Energy Security Scenarios | D19: 20222023
B20: http://indiaenergy.gov.in/iess/docs/IESS_Version3.xlsx | D20: AEO 2022, AEO 2023
B21: Table XIII.a | D21: https://www.eia.gov/outlooks/aeo/tables_side.php
D22: Tables 4 and 21
A24: Notes:
A25: All policy-driven electrification in the EPS is assumed to rely on heat pumps,
A26: not electric resistance heating
A28: Methodology:
A29: For India, there is no fossil fuel use in the heating or other categories, so only the appliance tabs are
A30: used here.
A32: The primary driver of residential appliance energy consumption in India is cooking. We calculate the
A33: average energy used by equipment of different types, which allows us to find a $/BTU value. We then estimate
A34: the cost of switching to heat pump equipment based on the data from EIA
A35: and annual energy consumption.
A37: For commercial buildings, we use US data with a GDP per capita adjustment for India.
A39: US Notes:
... A57: other fuels based on the above mapping, with biomass mapped to petroleum.
B58: 54.77
A59: 2017 to 2012 USD
A60: 0.9366596
A61: 2016 to 2012 USD
A62: 0.95661377
A64: Ruppees per dollar
A65: 2012

Sheet EIA Costs
A1: Residential Gas Fired Furnaces
A2: DATA | B2: 2009 | C2: 2015 | D2: 2017 | H2: 2020 | J2: 2030 | L2: 2040 | N2: 2050
B3: Installed Base | C3: Installed Base | D3: Current Standard | E3: Typical | F3: ENERGY STAR (South) | G3: High | H3: Typical | I3: High | J3: Typical | K3: High | L3: Typical | M3: High | N3: Typical | O3: High
A4: Typical Input Capacity (kBtu/h) | B4: 80 | C4: 80 | D4: 80 | E4: 80 | F4: 80 | G4: 80 | H4: 80 | I4: 80 | J4: 80 | K4: 80 | L4: 80 | M4: 80 | N4: 80 | O4: 80
A5: AFUE (%) | B5: 80 | C5: 80 | D5: 80 | E5: 80 | F5: 90 | G5: 99 | H5: 80 | I5: 99 | J5: 80 | K5: 99 | L5: 80 | M5: 99 | N5: 80 | O5: 99
A6: Electric Consumption (kWh/yr)* | B6: 548 | C6: 522 | D6: 470 | E6: 470 | F6: 408 | G6: 418 | H6: 329 | I6: 334 | J6: 329 | K6: 334 | L6: 329 | M6: 334 | N6: 329 | O6: 334
A7: Average Life (yrs)** | B7: 16 | C7: 16 | D7: 16 | E7: 16 | F7: 16 | G7: 16 | H7: 16 | I7: 16 | J7: 16 | K7: 16 | L7: 16 | M7: 16 | N7: 16 | O7: 16
B8: 27 | C8: 27 | D8: 27 | E8: 27 | F8: 27 | G8: 27 | H8: 27 | I8: 27 | J8: 27 | K8: 27 | L8: 27 | M8: 27 | N8: 27 | O8: 27
A9: Retail Equipment Cost (2017$) | B9: 840 | C9: 860 | D9: 890 | E9: 890 | F9: 1150 | G9: 1620 | H9: 1080 | I9: 1620 | J9: 1080 | K9: 1620 | L9: 1080 | M9: 1620 | N9: 1080 | O9: 1620
A10: Total Installed Cost (2017$) | B10: 2000 | C10: 2020 | D10: 2050 | E10: 2050 | F10: 2560 | G10: 3040 | H10: 2240 | I10: 3040 | J10: 2240 | K10: 3040 | L10: 2240 | M10: 3040 | N10: 2240 | O10: 3040
A11: Annual Maintenance Cost (2017$) | B11: 40 | C11: 40 | D11: 40 | E11: 40 | F11: 40 | G11: 40 | H11: 40 | I11: 40 | J11: 40 | K11: 40 | L11: 40 | M11: 40 | N11: 40 | O11: 40
A13: Residential Oil Fired Furnaces
A14: DATA | B14: 2009 | C14: 2015 | D14: 2017 | H14: 2020 | J14: 2030 | L14: 2040 | N14: 2050
B15: Installed Base | C15: Installed Base | D15: Current Standard | E15: Typical | F15: ENERGY STAR | G15: High | H15: Typical | I15: High Typical | K15: High | L15: Typical | M15: High | N15: Typical | O15: High
A16: Typical Input Capacity (kBtu/h) | B16: 105 | C16: 105 | D16: 105 | E16: 105 | F16: 105 | G16: 105 | H16: 105 | I16: 105 | J16: 105 | K16: 105 | L16: 105 | M16: 105 | N16: 105 | O16: 105
A17: AFUE (%) | B17: 80 | C17: 83 | D17: 83 | E17: 83 | F17: 85 | G17: 97 | H17: 83 | I17: 97 | J17: 84 | K17: 97 | L17: 84 | M17: 97 | N17: 84 | O17: 97
A18: Electric Consumption (kWh/yr)* | B18: 490 | C18: 477 | D18: 477 | E18: 477 | F18: 466 | G18: 410 | H18: 477 | I18: 410 | J18: 472 | K18: 410 | L18: 472 | M18: 410 | N18: 472 | O18: 410
A19: Average Life (yrs)** | B19: 20 | C19: 20 | D19: 20 | E19: 20 | F19: 20 | G19: 20 | H19: 20 | I19: 20 | J19: 20 | K19: 20 | L19: 20 | M19: 20 | N19: 20 | O19: 20
B20: 33 | C20: 33 | D20: 33 | E20: 33 | F20: 33 | G20: 33 | H20: 33 | I20: 33 | J20: 33 | K20: 33 | L20: 33 | M20: 33 | N20: 33 | O20: 33
A21: Retail Equipment Cost (2017$) | B21: 2150 | C21: 2200 | D21: 2200 | E21: 2200 | F21: 2250 | G21: 2700 | H21: 2200 | I21: 2700 | J21: 2250 | K21: 2700 | L21: 2250 | M21: 2700 | N21: 2250 | O21: 2700
B22: 2350 | C22: 2900 | D22: 2900 | E22: 2900 | F22: 2950 | G22: 3450 | H22: 2900 | I22: 3450 | J22: 2950 | K22: 3450 | L22: 2950 | M22: 3450 | N22: 2950 | O22: 3450
A23: Total Installed Cost (2017$) | B23: 2700 | C23: 2750 | D23: 2750 | E23: 2750 | F23: 2950 | G23: 4350 | H23: 2750 | I23: 4350 | J23: 2750 | K23: 4350 | L23: 2750 | M23: 4350 | N23: 2750 | O23: 4350
B24: 3400 | C24: 5500 | D24: 5500 | E24: 5500 | F24: 5750 | G24: 8550 | H24: 5500 | I24: 8550 | J24: 5700 | K24: 8550 | L24: 5700 | M24: 8550 | N24: 5700 | O24: 8550
A25: Annual Maintenance Cost (2017$) | B25: 70 | C25: 70 | D25: 70 | E25: 70 | F25: 70 | G25: 200 | H25: 70 | I25: 200 | J25: 70 | K25: 200 | L25: 70 | M25: 200 | N25: 70 | O25: 200
A27: Residential Wood Pellet Stoves
A28: DATA | B28: 2009 | C28: 2015 | D28: 2017 | F28: 2020 | H28: 2030 | J28: 2040 | L28: 2050
B29: Installed Base | C29: Installed Base | D29: Typical | E29: High | F29: Typical | G29: High | H29: Typical | I29: High | J29: Typical | K29: High | L29: Typical | M29: High
A30: Typical Capacity (kBtu/h) | B30: 50 | C30: 50 | D30: 50 | E30: 50 | F30: 50 | G30: 50 | H30: 50 | I30: 50 | J30: 50 | K30: 50 | L30: 50 | M30: 50
A31: Efficiency (HHV) | B31: 65 | C31: 70 | D31: 76 | E31: 87 | F31: 76 | G31: 87 | H31: 77 | I31: 87 | J31: 78 | K31: 88 | L31: 79 | M31: 89
A32: Annual Electricity Consumption (kWh) | B32: 600 | C32: 600 | D32: 600 | E32: 600 | F32: 600 | G32: 600 | H32: 600 | I32: 600 | J32: 600 | K32: 600 | L32: 600 | M32: 600
A33: Average Life (yrs) | B33: 12 | C33: 12 | D33: 12 | E33: 12 | F33: 12 | G33: 12 | H33: 12 | I33: 12 | J33: 12 | K33: 12 | L33: 12 | M33: 12
B34: 25 | C34: 25 | D34: 25 | E34: 25 | F34: 25 | G34: 25 | H34: 25 | I34: 25 | J34: 25 | K34: 25 | L34: 25 | M34: 25
A35: Retail Equipment Cost (2017$) | B35: 3300 | C35: 3300 | D35: 3300 | E35: 4000 | F35: 3300 | G35: 4000 | H35: 3400 | I35: 4000 | J35: 3500 | K35: 4100 | L35: 3600 | M35: 4200
A36: Total Installed Cost (2017$) | B36: 4700 | C36: 4700 | D36: 4700 | E36: 5400 | F36: 4700 | G36: 5400 | H36: 4800 | I36: 5400 | J36: 4900 | K36: 5500 | L36: 5000 | M36: 5600
A37: Annual Maintenance Cost (2017$) | B37: 260 | C37: 260 | D37: 260 | E37: 260 | F37: 260 | G37: 260 | H37: 260 | I37: 260 | J37: 260 | K37: 260 | L37: 260 | M37: 260
A39: Residential Air Source Heat Pumps
A40: DATA | B40: 2009 | C40: 2015 | D40: 2017 | H40: 2020 | J40: 2030** | L40: 2040 | N40: 2050
B41: Installed Base | C41: Installed Base | D41: Current Standard | E41: Typical | F41: ENERGY STAR | G41: High | H41: Typical | I41: High | J41: Typical | K41: High | L41: Typical | M41: High | N41: Typical | O41: High
A42: Typical Capacity (kBtu/h) | B42: 36 | C42: 36 | D42: 36 | E42: 36 | F42: 36 | G42: 36 | H42: 36 | I42: 36 | J42: 36 | K42: 36 | L42: 36 | M42: 36 | N42: 36 | O42: 36
A43: SEER (Cooling)* | B43: 12 | C43: 13.1 | D43: 14 | E43: 15.3 | F43: 15 | G43: 19 | H43: 15.3 | I43: 19 | J43: 15.8 | K43: 19 | L43: 15.8 | M43: 19 | N43: 15.8 | O43: 19
...

Sheet EIA AEO Table 4
B1: ref2023.d020623a | C1: 2022 | D1: 2023 | E1: 2024 | F1: 2025 | G1: 2026 | H1: 2027 | I1: 2028 | J1: 2029 | K1: 2030 | L1: 2031 | M1: 2032 | N1: 2033 | O1: 2034 | P1: 2035 | Q1: 2036 | R1: 2037 | S1: 2038 | T1: 2039 | U1: 2040 | V1: 2041 | W1: 2042 | X1: 2043 | Y1: 2044 | Z1: 2045 | AA1: 2046 | AB1: 2047 | AC1: 2048 | AD1: 2049 | AE1: 2050
C3: Report | D3: Annual Energy Outlook 2023
C4: Scenario | D4: ref2023 | G4: Reference
C5: Datekey | D5: d020623a
C6: Release Date | E6: March 2023
A10: RKI000 | B10: 4. Residential Sector Key Indicators and Consumption | AF10: Average
B11: (quadrillion Btu, unless otherwise noted) | AF11: Annual
AF12: Change | AI12: 2019-
B13: Key Indicators and Consumption | C13: 2022 | D13: 2023 | E13: 2024 | F13: 2025 | G13: 2026 | H13: 2027 | I13: 2028 | J13: 2029 | K13: 2030 | L13: 2031 | M13: 2032 | N13: 2033 | O13: 2034 | P13: 2035 | Q13: 2036 | R13: 2037 | S13: 2038 | T13: 2039 | U13: 2040 | V13: 2041 | W13: 2042 | X13: 2043 | Y13: 2044 | Z13: 2045 | AA13: 2046 | AB13: 2047 | AC13: 2048 | AD13: 2049 | AE13: 2050 | AF13: 2022–2050 | AI13: 2050
B15: Key Indicators
B16: Households (millions)
A17: RKI000:ba_Single-Family | B17: Single-Family | C17: 86.924255 | D17: 87.748611 | E17: 88.618675 | F17: 89.519981 | G17: 90.411308 | H17: 91.302132 | I17: 92.198265 | J17: 93.091507 | K17: 93.970619 | L17: 94.836555 | M17: 95.694557 | N17: 96.533203 | O17: 97.347885 | P17: 98.154381 | Q17: 98.959145 | R17: 99.75724 | S17: 100.55006 | T17: 101.33466 | U17: 102.12499 | V17: 102.91761 | W17: 103.69783 | X17: 104.47331 | Y17: 105.24597 | Z17: 106.01605 | AA17: 106.78051 | AB17: 107.53815 | AC17: 108.28622 | AD17: 109.02242 | AE17: 109.74868 | AF17: 0.008362 | AI17: 0.007038
A18: RKI000:ba_Multifamily | B18: Multifamily | C18: 32.842152 | D18: 33.209229 | E18: 33.535469 | F18: 33.85815 | G18: 34.181629 | H18: 34.507633 | I18: 34.834255 | J18: 35.155056 | K18: 35.46513 | L18: 35.769081 | M18: 36.0718 | N18: 36.366608 | O18: 36.650593 | P18: 36.930111 | Q18: 37.212017 | R18: 37.496159 | S18: 37.783924 | T18: 38.073307 | U18: 38.36647 | V18: 38.656506 | W18: 38.941956 | X18: 39.223991 | Y18: 39.501945 | Z18: 39.776779 | AA18: 40.048443 | AB18: 40.322777 | AC18: 40.595905 | AD18: 40.869537 | AE18: 41.144089 | AF18: 0.008081 | AI18: 0.005591
A19: RKI000:ba_MobileHomes | B19: Mobile Homes | C19: 6.648376 | D19: 6.654435 | E19: 6.657747 | F19: 6.660283 | G19: 6.66859 | H19: 6.680898 | I19: 6.695705 | J19: 6.709839 | K19: 6.717811 | L19: 6.722091 | M19: 6.727011 | N19: 6.734098 | O19: 6.740673 | P19: 6.744905 | Q19: 6.74995 | R19: 6.752422 | S19: 6.751948 | T19: 6.750166 | U19: 6.750861 | V19: 6.753187 | W19: 6.756266 | X19: 6.759341 | Y19: 6.761881 | Z19: 6.763837 | AA19: 6.764435 | AB19: 6.765501 | AC19: 6.766449 | AD19: 6.766767 | AE19: 6.767235 | AF19: 0.000633 | AI19: -0.011866
A20: RKI000:ba_Total | B20: Total | C20: 126.41478 | D20: 127.61227 | E20: 128.81189 | F20: 130.03841 | G20: 131.26154 | H20: 132.49066 | I20: 133.72823 | J20: 134.95641 | K20: 136.15355 | L20: 137.32773 | M20: 138.49336 | N20: 139.63391 | O20: 140.73915 | P20: 141.82939 | Q20: 142.92111 | R20: 144.00583 | S20: 145.08594 | T20: 146.15813 | U20: 147.24231 | V20: 148.3273 | W20: 149.39606 | X20: 150.45664 | Y20: 151.50981 | Z20: 152.55667 | AA20: 153.59338 | AB20: 154.62643 | AC20: 155.64857 | AD20: 156.65874 | AE20: 157.66 | AF20: 0.00792 | AI20: 0.005904
A22: RKI000:ca_AverageHouseS | B22: Average House Square Footage | C22: 1798.9158 | D22: 1803.5209 | E22: 1808.4264 | F22: 1813.3185 | G22: 1818.0804 | H22: 1822.7229 | I22: 1827.2777 | J22: 1831.8 | K22: 1836.3394 | L22: 1840.8495 | M22: 1845.2855 | N22: 1849.6774 | O22: 1854.0608 | P22: 1858.4113 | Q22: 1862.6759 | R22: 1866.8663 | S22: 1870.9755 | T22: 1875.0114 | U22: 1878.9578 | V22: 1882.8684 | W22: 1886.7397 | X22: 1890.5779 | Y22: 1894.3921 | Z22: 1898.1798 | AA22: 1901.9388 | AB22: 1905.6209 | AC22: 1909.2523 | AD22: 1912.8229 | AE22: 1916.3303 | AF22: 0.002261 | AI22: 0.003435
B24: Energy Intensity
B25: (million Btu per household)
A26: RKI000:da_DeliveredEner | B26: Gross End-use Consumption 1/ | C26: 93.909477 | D26: 92.769119 | E26: 89.479935 | F26: 89.052956 | G26: 88.647408 | H26: 88.231392 | I26: 87.719673 | J26: 87.082458 | K26: 86.372932 | L26: 85.637901 | M26: 84.930008 | N26: 84.330368 | O26: 83.726021 | P26: 83.229088 | Q26: 82.803543 | R26: 82.42997 | S26: 82.039726 | T26: 81.693481 | U26: 81.360573 | V26: 81.06002 | W26: 80.817673 | X26: 80.633194 | Y26: 80.500008 | Z26: 80.389549 | AA26: 80.279945 | AB26: 80.223389 | AC26: 80.211197 | AD26: 80.229492 | AE26: 80.285049 | AF26: -0.005583 | AI26: -0.006009
A27: RKI000:da_TotalEnergyCo | B27: Delivered Energy Consumption | C27: 93.023323 | D27: 91.801674 | E27: 88.420021 | F27: 87.901169 | G27: 87.405548 | H27: 86.898582 | I27: 86.294922 | J27: 85.563858 | K27: 84.758438 | L27: 83.924873 | M27: 83.114105 | N27: 82.411514 | O27: 81.703484 | P27: 81.117577 | Q27: 80.600105 | R27: 80.131668 | S27: 79.641068 | T27: 79.188065 | U27: 78.743118 | V27: 78.324791 | W27: 77.958664 | X27: 77.644554 | Y27: 77.377632 | Z27: 77.127983 | AA27: 76.87487 | AB27: 76.670601 | AC27: 76.504471 | AD27: 76.365883 | AE27: 76.260414 | AF27: -0.007071 | AI27: -0.006295
B28: (thousand Btu per square foot)
A29: RKI000:ea_DeliveredEner | B29: Gross End-use Consumption 1/ | C29: 52.203377 | D29: 51.437782 | E29: 49.479443 | F29: 49.110489 | G29: 48.758793 | H29: 48.406364 | I29: 48.005661 | J29: 47.539284 | K29: 47.035389 | L29: 46.520859 | M29: 46.025402 | N29: 45.591934 | O29: 45.158184 | P29: 44.785076 | Q29: 44.454079 | R29: 44.15419 | S29: 43.848637 | T29: 43.569595 | U29: 43.300903 | V29: 43.051346 | W29: 42.83456 | X29: 42.650024 | Y29: 42.493847 | Z29: 42.350861 | AA29: 42.209534 | AB29: 42.098293 | AC29: 42.011837 | AD29: 41.942982 | AE29: 41.895203 | AF29: -0.007825 | AI29: -0.009412
A30: RKI000:ea_TotalEnergyCo | B30: Delivered Energy Consumption | C30: 51.710773 | D30: 50.901363 | E30: 48.893349 | F30: 48.475307 | G30: 48.075733 | H30: 47.675148 | I30: 47.225948 | J30: 46.710258 | K30: 46.156193 | L30: 45.590298 | M30: 45.041325 | N30: 44.554535 | O30: 44.067314 | P30: 43.648884 | Q30: 43.271141 | R30: 42.923088 | S30: 42.566601 | T30: 42.233379 | U30: 41.907867 | V30: 41.598656 | W30: 41.319248 | X30: 41.069218 | Y30: 40.845627 | Z30: 40.632603 | AA30: 40.419212 | AB30: 40.233921 | AC30: 40.070381 | AD30: 39.923134 | AE30: 39.795025 | AF30: -0.009311 | AI30: -0.009696
B32: Energy Consumption by Fuel
B33: Electricity 1/
A34: RKI000:fa_SpaceHeating | B34: Space Heating | C34: 0.74562 | D34: 0.744025 | E34: 0.657572 | F34: 0.656949 | G34: 0.655732 | H34: 0.653215 | I34: 0.649408 | J34: 0.644338 | K34: 0.637851 | L34: 0.630493 | M34: 0.623023 | N34: 0.615132 | O34: 0.606908 | P34: 0.599838 | Q34: 0.593122 | R34: 0.586547 | S34: 0.579423 | T34: 0.572275 | U34: 0.565611 | V34: 0.559325 | W34: 0.553414 | X34: 0.54783 | Y34: 0.542214 | Z34: 0.536676 | AA34: 0.531381 | AB34: 0.526393 | AC34: 0.521432 | AD34: 0.516688 | AE34: 0.512384 | AF34: -0.013309 | AI34: -0.009756
A35: RKI000:fa_SpaceCooling | B35: Space Cooling | C35: 0.853587 | D35: 0.735192 | E35: 0.890909 | F35: 0.91105 | G35: 0.930181 | H35: 0.950142 | I35: 0.969709 | J35: 0.988224 | K35: 1.004471 | L35: 1.019774 | M35: 1.036202 | N35: 1.052583 | O35: 1.069291 | P35: 1.088333 | Q35: 1.109122 | R35: 1.130924 | S35: 1.152515 | T35: 1.174549 | U35: 1.196908 | V35: 1.219416 | W35: 1.242558 | X35: 1.266365 | Y35: 1.29112 | Z35: 1.3168 | AA35: 1.344624 | AB35: 1.373569 | AC35: 1.403082 | AD35: 1.432529 | AE35: 1.463148 | AF35: 0.019433 | AI35: 0.016141
A36: RKI000:fa_WaterHeating | B36: Water Heating | C36: 0.599797 | D36: 0.598845 | E36: 0.598786 | F36: 0.599582 | G36: 0.599536 | H36: 0.599125 | I36: 0.59802 | J36: 0.596113 | K36: 0.593223 | L36: 0.589911 | M36: 0.586847 | N36: 0.586124 | O36: 0.586146 | P36: 0.588552 | Q36: 0.591464 | R36: 0.594365 | S36: 0.596931 | T36: 0.599321 | U36: 0.601795 | V36: 0.604464 | W36: 0.607404 | X36: 0.610584 | Y36: 0.613738 | Z36: 0.616835 | AA36: 0.620251 | AB36: 0.623921 | AC36: 0.627667 | AD36: 0.631618 | AE36: 0.63608 | AF36: 0.0021 | AI36: 0.001207
A37: RKI000:fa_Refrigeration | B37: Refrigeration | C37: 0.295558 | D37: 0.293987 | E37: 0.292668 | F37: 0.29163 | G37: 0.290783 | H37: 0.290158 | I37: 0.289778 | J37: 0.289615 | K37: 0.289659 | L37: 0.289986 | M37: 0.29063 | N37: 0.29157 | O37: 0.292795 | P37: 0.294343 | Q37: 0.296242 | R37: 0.298447 | S37: 0.30096 | T37: 0.303745 | U37: 0.306848 | V37: 0.310249 | W37: 0.313888 | X37: 0.317482 | Y37: 0.321024 | Z37: 0.324507 | AA37: 0.327915 | AB37: 0.33125 | AC37: 0.334496 | AD37: 0.337645 | AE37: 0.340702 | AF37: 0.00509 | AI37: 0.002205
A38: RKI000:fa_Cooking | B38: Cooking | C38: 0.055863 | D38: 0.056202 | E38: 0.056536 | F38: 0.056875 | G38: 0.057205 | H38: 0.05753 | I38: 0.057848 | J38: 0.058138 | K38: 0.058391 | L38: 0.058604 | M38: 0.058781 | N38: 0.058966 | O38: 0.05917 | P38: 0.059404 | Q38: 0.05968 | R38: 0.059996 | S38: 0.060304 | T38: 0.060601 | U38: 0.060895 | V38: 0.061182 | W38: 0.061454 | X38: 0.061714 | Y38: 0.061964 | Z38: 0.062203 | AA38: 0.062434 | AB38: 0.062659 | AC38: 0.06288 | AD38: 0.063098 | AE38: 0.063319 | AF38: 0.004485 | AI38: 0.002445
A39: RKI000:fa_ClothesDryers | B39: Clothes Dryers | C39: 0.222467 | D39: 0.227024 | E39: 0.231891 | F39: 0.237295 | G39: 0.242448 | H39: 0.247266 | I39: 0.251793 | J39: 0.25596 | K39: 0.259671 | L39: 0.263071 | M39: 0.266436 | N39: 0.269392 | O39: 0.272342 | P39: 0.275723 | Q39: 0.279342 | R39: 0.282799 | S39: 0.285963 | T39: 0.289075 | U39: 0.292206 | V39: 0.295411 | W39: 0.298723 | X39: 0.30216 | Y39: 0.305635 | Z39: 0.309109 | AA39: 0.31273 | AB39: 0.31651 | AC39: 0.320307 | AD39: 0.324172 | AE39: 0.328278 | AF39: 0.013993 | AI39: 0.011783
A40: RKI000:fa_Freezers | B40: Freezers | C40: 0.069007 | D40: 0.06885 | E40: 0.068687 | F40: 0.068516 | G40: 0.068318 | H40: 0.068105 | I40: 0.067922 | J40: 0.067761 | K40: 0.067615 | L40: 0.067486 | M40: 0.067377 | N40: 0.067287 | O40: 0.067216 | P40: 0.067169 | Q40: 0.067159 | R40: 0.067178 | S40: 0.067229 | T40: 0.067311 | U40: 0.067431 | V40: 0.067596 | W40: 0.067794 | X40: 0.068036 | Y40: 0.068326 | Z40: 0.068666 | AA40: 0.069053 | AB40: 0.069481 | AC40: 0.069904 | AD40: 0.070319 | AE40: 0.070729 | AF40: 0.000881 | AI40: -0.00151
A41: RKI000:fa_Lighting | B41: Lighting | C41: 0.22927 | D41: 0.21316 | E41: 0.206794 | F41: 0.205129 | G41: 0.2052 | H41: 0.206404 | I41: 0.20833 | J41: 0.210226 | K41: 0.209704 | L41: 0.209164 | M41: 0.208855 | N41: 0.208568 | O41: 0.208536 | P41: 0.209016 | Q41: 0.209627 | R41: 0.210178 | S41: 0.210558 | T41: 0.210954 | U41: 0.207703 | V41: 0.205012 | W41: 0.202911 | X41: 0.201467 | Y41: 0.200848 | Z41: 0.20064 | AA41: 0.200592 | AB41: 0.20073 | AC41: 0.200991 | AD41: 0.201423 | AE41: 0.202056 | AF41: -0.004503 | AI41: -0.010524
A42: RKI000:fa_ClothesWasher | B42: Clothes Washers 2/ | C42: 0.037489 | D42: 0.037813 | E42: 0.038144 | F42: 0.038486 | G42: 0.038827 | H42: 0.039168 | I42: 0.039519 | J42: 0.039875 | K42: 0.040246 | L42: 0.040617 | M42: 0.040992 | N42: 0.041365 | O42: 0.041733 | P42: 0.042099 | Q42: 0.042465 | R42: 0.042828 | S42: 0.043187 | T42: 0.043542 | U42: 0.043898 | V42: 0.044252 | W42: 0.044599 | X42: 0.044942 | Y42: 0.045282 | Z42: 0.045619 | AA42: 0.045952 | AB42: 0.046283 | AC42: 0.046611 | AD42: 0.046936 | AE42: 0.047258 | AF42: 0.008305 | AI42: 0.006674
A43: RKI000:fa_Dishwashers | B43: Dishwashers 2/ | C43: 0.027618 | D43: 0.028064 | E43: 0.028506 | F43: 0.028945 | G43: 0.02937 | H43: 0.029782 | I43: 0.030233 | J43: 0.030722 | K43: 0.031242 | L43: 0.031797 | M43: 0.032392 | N43: 0.033027 | O43: 0.033702 | P43: 0.034373 | Q43: 0.035043 | R43: 0.03571 | S43: 0.036375 | T43: 0.037036 | U43: 0.037698 | V43: 0.038359 | W43: 0.039015 | X43: 0.039667 | Y43: 0.040316 | Z43: 0.040962 | AA43: 0.041605 | AB43: 0.042245 | AC43: 0.042882 | AD43: 0.043514 | AE43: 0.044143 | AF43: 0.01689 | AI43: 0.014947
A44: RKI000:fa_ColorTelevisi | B44: Televisions and Related Equipment 3/ | C44: 0.185092 | D44: 0.181559 | E44: 0.178365 | F44: 0.175692 | G44: 0.172951 | H44: 0.170143 | I44: 0.167198 | J44: 0.164139 | K44: 0.160987 | L44: 0.157867 | M44: 0.154866 | N44: 0.151867 | O44: 0.148998 | P44: 0.146585 | Q44: 0.144473 | R44: 0.142566 | S44: 0.14076 | T44: 0.139189 | U44: 0.13791 | V44: 0.136911 | W44: 0.136207 | X44: 0.135755 | Y44: 0.135537 | Z44: 0.135552 | AA44: 0.135802 | AB44: 0.136265 | AC44: 0.13685 | AD44: 0.137593 | AE44: 0.138527 | AF44: -0.010296 | AI44: 0.007737
A45: RKI000:fa_PersonalCompu | B45: Computers and Related Equipment 4/ | C45: 0.120106 | D45: 0.118562 | E45: 0.116931 | F45: 0.115363 | G45: 0.113493 | H45: 0.111328 | I45: 0.108857 | J45: 0.106117 | K45: 0.103168 | L45: 0.100088 | M45: 0.09698 | N45: 0.093786 | O45: 0.09061 | P45: 0.087647 | Q45: 0.084848 | R45: 0.082133 | S45: 0.079493 | T45: 0.077008 | U45: 0.074726 | V45: 0.072652 | W45: 0.070825 | X45: 0.069227 | Y45: 0.067875 | Z45: 0.066753 | AA45: 0.065956 | AB45: 0.065417 | AC45: 0.065087 | AD45: 0.064993 | AE45: 0.065107 | AF45: -0.021632 | AI45: -0.026585
... A48: RKI000:fa_DeliveredEner | B48: Electricity Subtotal | C48: 5.259642 | D48: 5.170129 | E48: 5.25044 | F48: 5.307276 | G48: 5.362642 | H48: 5.422232 | I48: 5.47432 | J48: 5.518295 | K48: 5.554088 | L48: 5.587194 | M48: 5.622504 | N48: 5.659284 | O48: 5.694947 | P48: 5.742076 | Q48: 5.795343 | R48: 5.852389 | S48: 5.907059 | T48: 5.963454 | U48: 6.0203 | V48: 6.08025 | W48: 6.145656 | X48: 6.215189 | Y48: 6.288645 | Z48: 6.365698 | AA48: 6.448222 | AB48: 6.53561 | AC48: 6.625218 | AD48: 6.717607 | AE48: 6.816999 | AF48: 0.009306 | AI48: 0.006181
B49: On-site Generation for Own Use | C49: 0.112023 | D49: 0.123458 | E49: 0.136529 | F49: 0.149777 | G49: 0.163009 | H49: 0.176585 | I49: 0.19053 | J49: 0.204945 | K49: 0.21982 | L49: 0.235246 | M49: 0.25149 | N49: 0.267937 | O49: 0.28465 | P49: 0.299474 | Q49: 0.314918 | R49: 0.330968 | S49: 0.348012 | T49: 0.366187 | U49: 0.3854 | V49: 0.405709 | W49: 0.427124 | X49: 0.44966 | Y49: 0.473071 | Z49: 0.497574 | AA49: 0.522997 | AB49: 0.549355 | AC49: 0.576946 | AD49: 0.605268 | AE49: 0.634524 | AF49: 0.063893
B50: Purchased Electricity | C50: 5.147618 | D50: 5.046671 | E50: 5.113911 | F50: 5.157499 | G50: 5.199634 | H50: 5.245647 | I50: 5.28379 | J50: 5.31335 | K50: 5.334268 | L50: 5.351949 | M50: 5.371014 | N50: 5.391346 | O50: 5.410297 | P50: 5.442602 | Q50: 5.480425 | R50: 5.521421 | S50: 5.559047 | T50: 5.597267 | U50: 5.6349 | V50: 5.674541 | W50: 5.718532 | X50: 5.765529 | Y50: 5.815574 | Z50: 5.868124 | AA50: 5.925225 | AB50: 5.986255 | AC50: 6.048272 | AD50: 6.112339 | AE50: 6.182475 | AF50: 0.006564
...

Sheet EIA AEO Table 21
B1: Table 21. Residential Sector Equipment Stock and Efficiency, and Distributed Generation
B2: https://www.eia.gov/outlooks/aeo/data/browser/#/?id=30-AEO2022&cases=lowmacro&sourcekey=0
B3: Thu Apr 13 2023 14:53:57 GMT-0400 (Eastern Daylight Time)
B4: Source: U.S. Energy Information Administration
C5: full name | D5: api key | E5: units | F5: 2020 | G5: 2021 | H5: 2022 | I5: 2023 | J5: 2024 | K5: 2025 | L5: 2026 | M5: 2027 | N5: 2028 | O5: 2029 | P5: 2030 | Q5: 2031 | R5: 2032 | S5: 2033 | T5: 2034 | U5: 2035 | V5: 2036 | W5: 2037 | X5: 2038 | Y5: 2039 | Z5: 2040 | AA5: 2041 | AB5: 2042 | AC5: 2043 | AD5: 2044 | AE5: 2045 | AF5: 2046 | AG5: 2047 | AH5: 2048 | AI5: 2049 | AJ5: 2050 | AK5: Growth (2021-2050)
B6: Equipment Stock (million units)
B7: Main Space Heaters
B8: Electric Heat Pumps | C8: Residential Equipment: Equipment Stock: Main Space Heaters: Electric Heat Pumps: Low economic growth | D8: AEO.2022.LOWMACRO.EQNR_STK_RESD_MSHR_EHP_NA_NA_MILL.A | E8: millions | G8: 12.939867 | H8: 13.152194 | I8: 13.342212 | J8: 13.532937 | K8: 13.721616 | L8: 13.903946 | M8: 14.084397 | N8: 14.269409 | O8: 14.454908 | P8: 14.636997 | Q8: 14.814411 | R8: 14.999154 | S8: 15.181839 | T8: 15.3564 | U8: 15.527476 | V8: 15.696768 | W8: 15.868364 | X8: 16.039974 | Y8: 16.212418 | Z8: 16.385061 | AA8: 16.555988 | AB8: 16.72423 | AC8: 16.890961 | AD8: 17.056513 | AE8: 17.22121 | AF8: 17.385036 | AG8: 17.548895 | AH8: 17.710915 | AI8: 17.872004 | AJ8: 18.031734 | AK8: 0.012
B9: Electric Other | C9: Residential Equipment: Equipment Stock: Main Space Heaters: Electric Other: Low economic growth | D9: AEO.2022.LOWMACRO.EQNR_STK_RESD_MSHR_ELO_NA_NA_MILL.A | E9: millions | G9: 30.553938 | H9: 30.675936 | I9: 30.782753 | J9: 30.885431 | K9: 30.986736 | L9: 31.084375 | M9: 31.182482 | N9: 31.286263 | O9: 31.391994 | P9: 31.495815 | Q9: 31.596684 | R9: 31.703642 | S9: 31.809694 | T9: 31.908785 | U9: 32.005138 | V9: 32.098763 | W9: 32.194691 | X9: 32.291416 | Y9: 32.390797 | Z9: 32.491833 | AA9: 32.590778 | AB9: 32.687199 | AC9: 32.782112 | AD9: 32.876045 | AE9: 32.970554 | AF9: 33.064606 | AG9: 33.159756 | AH9: 33.253029 | AI9: 33.345913 | AJ9: 33.438988 | AK9: 0.003
A10: RST000 | B10: Natural Gas Heat Pumps | C10: Residential Equipment: Equipment Stock: Main Space Heaters: Natural Gas Heat Pumps: Low economic growth | D10: AEO.2022.LOWMACRO.EQNR_STK_RESD_MSHR_NHU_NA_NA_MILL.A | E10: millions | G10: 1.316486 | H10: 1.314569 | I10: 1.312659 | J10: 1.310759 | K10: 1.308866 | L10: 1.30698 | M10: 1.305104 | N10: 1.303233 | O10: 1.301371 | P10: 1.299515 | Q10: 1.297667 | R10: 1.295827 | S10: 1.293993 | T10: 1.292167 | U10: 1.290347 | V10: 1.288535 | W10: 1.286729 | X10: 1.28493 | Y10: 1.283138 | Z10: 1.281352 | AA10: 1.279573 | AB10: 1.2778 | AC10: 1.276034 | AD10: 1.274273 | AE10: 1.272519 | AF10: 1.270772 | AG10: 1.26903 | AH10: 1.267294 | AI10: 1.265564 | AJ10: 1.263841 | AK10: -0.001
B11: Natural Gas Other | C11: Residential Equipment: Equipment Stock: Main Space Heaters: Natural Gas Other: Low economic growth | D11: AEO.2022.LOWMACRO.EQNR_STK_RESD_MSHR_NGO_NA_NA_MILL.A | E11: millions | G11: 61.33672 | H11: 62.030872 | I11: 62.670055 | J11: 63.315552 | K11: 63.953545 | L11: 64.569389 | M11: 65.174591 | N11: 65.787827 | O11: 66.398575 | P11: 66.995453 | Q11: 67.574905 | R11: 68.175156 | S11: 68.765228 | T11: 69.327278 | U11: 69.872078 | V11: 70.404388 | W11: 70.934273 | X11: 71.465973 | Y11: 71.999748 | Z11: 72.535378 | AA11: 73.065193 | AB11: 73.586014 | AC11: 74.100395 | AD11: 74.608742 | AE11: 75.111382 | AF11: 75.607239 | AG11: 76.097046 | AH11: 76.576889 | AI11: 77.048859 | AJ11: 77.510254 | AK11: 0.008
B12: Distillate Fuel Oil | C12: Residential Equipment: Equipment Stock: Main Space Heaters: Distillate Fuel Oil: Low economic growth | D12: AEO.2022.LOWMACRO.EQNR_STK_RESD_MSHR_DFO_NA_NA_MILL.A | E12: millions | G12: 5.503068 | H12: 5.452685 | I12: 5.403224 | J12: 5.35462 | K12: 5.306357 | L12: 5.258382 | M12: 5.212059 | N12: 5.167742 | O12: 5.125732 | P12: 5.086065 | Q12: 5.047999 | R12: 5.01172 | S12: 4.976817 | T12: 4.942926 | U12: 4.909963 | V12: 4.877693 | W12: 4.846786 | X12: 4.816997 | Y12: 4.788019 | Z12: 4.759813 | AA12: 4.731733 | AB12: 4.702106 | AC12: 4.671 | AD12: 4.638635 | AE12: 4.60528 | AF12: 4.571091 | AG12: 4.535478 | AH12: 4.498829 | AI12: 4.461558 | AJ12: 4.424065 | AK12: -0.007
B13: Propane | C13: Residential Equipment: Equipment Stock: Main Space Heaters: Propane: Low economic growth | D13: AEO.2022.LOWMACRO.EQNR_STK_RESD_MSHR_PROP_NA_NA_MILL.A | E13: millions | G13: 5.245557 | H13: 5.245455 | I13: 5.243608 | J13: 5.240382 | K13: 5.236936 | L13: 5.233324 | M13: 5.229367 | N13: 5.225949 | O13: 5.223021 | P13: 5.219841 | Q13: 5.216552 | R13: 5.214471 | S13: 5.212708 | T13: 5.210732 | U13: 5.208905 | V13: 5.206887 | W13: 5.204187 | X13: 5.20069 | Y13: 5.19686 | Z13: 5.192907 | AA13: 5.188683 | AB13: 5.18278 | AC13: 5.175326 | AD13: 5.166907 | AE13: 5.158232 | AF13: 5.149588 | AG13: 5.1413 | AH13: 5.133091 | AI13: 5.125126 | AJ13: 5.117575 | AK13: -0.001
B14: Kerosene | C14: Residential Equipment: Equipment Stock: Main Space Heaters: Kerosene: Low economic growth | D14: AEO.2022.LOWMACRO.EQNR_STK_RESD_MSHR_KRS_NA_NA_MILL.A | E14: millions | G14: 0.003345 | H14: 0.006042 | I14: 0.008499 | J14: 0.010799 | K14: 0.013122 | L14: 0.015544 | M14: 0.017829 | N14: 0.020044 | O14: 0.022209 | P14: 0.024266 | Q14: 0.02626 | R14: 0.028255 | S14: 0.030243 | T14: 0.032189 | U14: 0.034111 | V14: 0.035971 | W14: 0.037734 | X14: 0.039376 | Y14: 0.040966 | Z14: 0.042535 | AA14: 0.044012 | AB14: 0.045418 | AC14: 0.046763 | AD14: 0.048074 | AE14: 0.049373 | AF14: 0.050627 | AG14: 0.051852 | AH14: 0.053008 | AI14: 0.054102 | AJ14: 0.05515 | AK14: 0.101
B15: Wood Stoves | C15: Residential Equipment: Equipment Stock: Main Space Heaters: Wood Stoves: Low economic growth | D15: AEO.2022.LOWMACRO.EQNR_STK_RESD_MSHR_WDS_NA_NA_MILL.A | E15: millions | G15: 3.324872 | H15: 3.296432 | I15: 3.269913 | J15: 3.244488 | K15: 3.219946 | L15: 3.196247 | M15: 3.172873 | N15: 3.149143 | O15: 3.124991 | P15: 3.100666 | Q15: 3.075778 | R15: 3.049958 | S15: 3.023234 | T15: 2.995832 | U15: 2.967745 | V15: 2.939001 | W15: 2.911176 | X15: 2.884129 | Y15: 2.857822 | Z15: 2.831723 | AA15: 2.806644 | AB15: 2.783075 | AC15: 2.760905 | AD15: 2.740153 | AE15: 2.7209 | AF15: 2.702927 | AG15: 2.684836 | AH15: 2.666614 | AI15: 2.648213 | AJ15: 2.629575 | AK15: -0.008
B16: Geothermal Heat Pumps | C16: Residential Equipment: Equipment Stock: Main Space Heaters: Geothermal Heat Pumps: Low economic growth | D16: AEO.2022.LOWMACRO.EQNR_STK_RESD_MSHR_GEHP_NA_NA_MILL.A | E16: millions | G16: 0.691816 | H16: 0.748202 | I16: 0.800437 | J16: 0.852791 | K16: 0.903986 | L16: 0.953071 | M16: 1.001114 | N16: 1.050052 | O16: 1.099535 | P16: 1.148657 | Q16: 1.197588 | R16: 1.24913 | S16: 1.301267 | T16: 1.352828 | U16: 1.404353 | V16: 1.456145 | W16: 1.50693 | X16: 1.557102 | Y16: 1.606632 | Z16: 1.656135 | AA16: 1.704539 | AB16: 1.75091 | AC16: 1.7955 | AD16: 1.838362 | AE16: 1.879344 | AF16: 1.918721 | AG16: 1.957791 | AH16: 1.99649 | AI16: 2.034937 | AJ16: 2.072986 | AK16: 0.039
A17: RST000:ba_ElectricHeatP | B17: Total | C17: Residential Equipment: Equipment Stock: Main Space Heaters: Total: Low economic growth | D17: AEO.2022.LOWMACRO.EQNR_STK_RESD_MSHR_TOT_NA_NA_MILL.A | E17: millions | G17: 120.91567 | H17: 121.92238 | I17: 122.83336 | J17: 123.74776 | K17: 124.65112 | L17: 125.52125 | M17: 126.37982 | N17: 127.25966 | O17: 128.14233 | P17: 129.00728 | Q17: 129.84784 | R17: 130.72731 | S17: 131.59502 | T17: 132.41914 | U17: 133.22011 | V17: 134.00415 | W17: 134.79088 | X17: 135.58058 | Y17: 136.37639 | Z17: 137.17673 | AA17: 137.96715 | AB17: 138.73956 | AC17: 139.49901 | AD17: 140.24771 | AE17: 140.98881 | AF17: 141.7206 | AG17: 142.44597 | AH17: 143.15616 | AI17: 143.85629 | AJ17: 144.54416 | AK17: 0.006
A18: RST000:ba_ElectricOther | B18: Space Cooling (million units)
A19: RST000:ba_NaturalGasHea | B19: Electric Heat Pumps | C19: Residential Equipment: Equipment Stock: Space Cooling: Electric Heat Pumps: Low economic growth | D19: AEO.2022.LOWMACRO.EQNR_STK_RESD_SPC_EHP_NA_NA_MILL.A | E19: millions | G19: 12.939865 | H19: 13.152193 | I19: 13.342216 | J19: 13.53294 | K19: 13.721614 | L19: 13.903946 | M19: 14.0844 | N19: 14.269408 | O19: 14.454908 | P19: 14.637002 | Q19: 14.814411 | R19: 14.999156 | S19: 15.181841 | T19: 15.356396 | U19: 15.527485 | V19: 15.69677 | W19: 15.868359 | X19: 16.039976 | Y19: 16.21242 | Z19: 16.385063 | AA19: 16.555988 | AB19: 16.72423 | AC19: 16.890959 | AD19: 17.056513 | AE19: 17.221212 | AF19: 17.38504 | AG19: 17.548897 | AH19: 17.710917 | AI19: 17.872009 | AJ19: 18.031742 | AK19: 0.012
A20: RST000:ba_NaturalGasOth | B20: Natural Gas Heat Pumps | C20: Residential Equipment: Equipment Stock: Space Cooling: Natural Gas Heat Pumps: Low economic growth | D20: AEO.2022.LOWMACRO.EQNR_STK_RESD_SPC_NHU_NA_NA_MILL.A | E20: millions | G20: 1.316486 | H20: 1.314569 | I20: 1.31266 | J20: 1.310759 | K20: 1.308866 | L20: 1.306981 | M20: 1.305103 | N20: 1.303233 | O20: 1.301371 | P20: 1.299515 | Q20: 1.297668 | R20: 1.295827 | S20: 1.293994 | T20: 1.292167 | U20: 1.290348 | V20: 1.288535 | W20: 1.286729 | X20: 1.28493 | Y20: 1.283138 | Z20: 1.281352 | AA20: 1.279573 | AB20: 1.2778 | AC20: 1.276034 | AD20: 1.274274 | AE20: 1.272519 | AF20: 1.270772 | AG20: 1.26903 | AH20: 1.267294 | AI20: 1.265564 | AJ20: 1.263841 | AK20: -0.001
A21: RST000:ba_Distillate | B21: Geothermal Heat Pumps | C21: Residential Equipment: Equipment Stock: Space Cooling: Geothermal Heat Pumps: Low economic growth | D21: AEO.2022.LOWMACRO.EQNR_STK_RESD_SPC_GEHP_NA_NA_MILL.A | E21: millions | G21: 0.691816 | H21: 0.748202 | I21: 0.800437 | J21: 0.852791 | K21: 0.903986 | L21: 0.953071 | M21: 1.001115 | N21: 1.050052 | O21: 1.099534 | P21: 1.148657 | Q21: 1.197588 | R21: 1.249131 | S21: 1.301267 | T21: 1.352828 | U21: 1.404353 | V21: 1.456146 | W21: 1.50693 | X21: 1.557102 | Y21: 1.606632 | Z21: 1.656135 | AA21: 1.70454 | AB21: 1.75091 | AC21: 1.795501 | AD21: 1.838362 | AE21: 1.879344 | AF21: 1.918721 | AG21: 1.957791 | AH21: 1.99649 | AI21: 2.034937 | AJ21: 2.072986 | AK21: 0.039
A22: RST000:ba_LiquefiedPetr | B22: Central Air Conditioners | C22: Residential Equipment: Equipment Stock: Space Cooling: Central Air Conditioners: Low economic growth | D22: AEO.2022.LOWMACRO.EQNR_STK_RESD_SPC_CAC_NA_NA_MILL.A | E22: millions | G22: 64.167404 | H22: 65.628075 | I22: 67.026932 | J22: 68.427589 | K22: 69.819656 | L22: 71.188896 | M22: 72.548157 | N22: 73.918556 | O22: 75.288826 | P22: 76.645782 | Q22: 77.985336 | R22: 79.348358 | S22: 80.702156 | T22: 82.026726 | U22: 83.334877 | V22: 84.630608 | W22: 85.925674 | X22: 87.220566 | Y22: 88.517242 | Z22: 89.814919 | AA22: 91.104797 | AB22: 92.381447 | AC22: 93.64814 | AD22: 94.906357 | AE22: 96.157784 | AF22: 97.401619 | AG22: 98.639374 | AH22: 99.865723 | AI22: 101.08376 | AJ22: 102.29199 | AK22: 0.016
A23: RST000:ba_Kerosene | B23: Room Air Conditioners | C23: Residential Equipment: Equipment Stock: Space Cooling: Room Air Conditioners: Low economic growth | D23: AEO.2022.LOWMACRO.EQNR_STK_RESD_SPC_RAC_NA_NA_MILL.A | E23: millions | G23: 58.043907 | H23: 58.031307 | I23: 58.008541 | J23: 57.986195 | K23: 57.964832 | L23: 57.943119 | M23: 57.920296 | N23: 57.900295 | O23: 57.881512 | P23: 57.861092 | Q23: 57.838936 | R23: 57.822067 | S23: 57.805351 | T23: 57.785152 | U23: 57.763771 | V23: 57.741295 | W23: 57.719055 | X23: 57.696808 | Y23: 57.67569 | Z23: 57.655998 | AA23: 57.635544 | AB23: 57.613773 | AC23: 57.591301 | AD23: 57.568768 | AE23: 57.546726 | AF23: 57.524544 | AG23: 57.502636 | AH23: 57.479496 | AI23: 57.455704 | AJ23: 57.431248 | AK23: 0
A24: RST000:ba_WoodStoves | B24: Total | C24: Residential Equipment: Equipment Stock: Space Cooling: Total: Low economic growth | D24: AEO.2022.LOWMACRO.EQNR_STK_RESD_SPC_TOT_NA_NA_MILL.A | E24: millions | G24: 137.15948 | H24: 138.87434 | I24: 140.49078 | J24: 142.11028 | K24: 143.71895 | L24: 145.29601 | M24: 146.85907 | N24: 148.44154 | O24: 150.02615 | P24: 151.59204 | Q24: 153.13394 | R24: 154.71454 | S24: 156.28461 | T24: 157.81326 | U24: 159.32083 | V24: 160.81335 | W24: 162.30675 | X24: 163.79938 | Y24: 165.29512 | Z24: 166.79346 | AA24: 168.28044 | AB24: 169.74815 | AC24: 171.20193 | AD24: 172.64427 | AE24: 174.07759 | AF24: 175.5007 | AG24: 176.91772 | AH24: 178.31992 | AI24: 179.71197 | AJ24: 181.09181 | AK24: 0.01
A25: RST000:ba_GeothermalHea | B25: Water Heaters (million units)
A26: RST000:ba_Total | B26: Electric | C26: Residential Equipment: Equipment Stock: Water Heaters: Electric: Low economic growth | D26: AEO.2022.LOWMACRO.EQNR_STK_RESD_WHT_ELE_NA_NA_MILL.A | E26: millions | G26: 59.829865 | H26: 60.213783 | I26: 60.580872 | J26: 61.03635 | K26: 61.449547 | L26: 61.813381 | M26: 62.155468 | N26: 62.490932 | O26: 62.81295 | P26: 63.113571 | Q26: 63.422279 | R26: 63.766239 | S26: 64.118187 | T26: 64.462593 | U26: 64.813332 | V26: 65.166489 | W26: 65.528687 | X26: 65.899277 | Y26: 66.268959 | Z26: 66.632172 | AA26: 66.986679 | AB26: 67.326195 | AC26: 67.657356 | AD26: 67.981659 | AE26: 68.299133 | AF26: 68.614403 | AG26: 68.928024 | AH26: 69.236954 | AI26: 69.544441 | AJ26: 69.853416 | AK26: 0.005
B27: Natural Gas | C27: Residential Equipment: Equipment Stock: Water Heaters: Natural Gas: Low economic growth | D27: AEO.2022.LOWMACRO.EQNR_STK_RESD_WHT_NG_NA_NA_MILL.A | E27: millions | G27: 60.704216 | H27: 61.224213 | I27: 61.727146 | J27: 62.283768 | K27: 62.85593 | L27: 63.432217 | M27: 64.010368 | N27: 64.605728 | O27: 65.206589 | P27: 65.80072 | Q27: 66.369591 | R27: 66.945938 | S27: 67.506172 | T27: 68.033279 | U27: 68.533333 | V27: 69.014732 | W27: 69.489388 | X27: 69.957626 | Y27: 70.43013 | Z27: 70.910095 | AA27: 71.386017 | AB27: 71.855698 | AC27: 72.318619 | AD27: 72.775093 | AE27: 73.227837 | AF27: 73.671577 | AG27: 74.108505 | AH27: 74.53334 | AI27: 74.948402 | AJ27: 75.348824 | AK27: 0.007
B28: Distillate Fuel Oil | C28: Residential Equipment: Equipment Stock: Water Heaters: Distillate Fuel Oil: Low economic growth | D28: AEO.2022.LOWMACRO.EQNR_STK_RESD_WHT_DFO_NA_NA_MILL.A | E28: millions | G28: 2.602572 | H28: 2.554386 | I28: 2.510953 | J28: 2.468833 | K28: 2.429554 | L28: 2.393059 | M28: 2.359057 | N28: 2.328569 | O28: 2.301511 | P28: 2.27756 | Q28: 2.251528 | R28: 2.224324 | S28: 2.196179 | T28: 2.167443 | U28: 2.137812 | V28: 2.107999 | W28: 2.078641 | X28: 2.049778 | Y28: 2.021623 | Z28: 1.994376 | AA28: 1.967958 | AB28: 1.942628 | AC28: 1.917783 | AD28: 1.893621 | AE28: 1.87028 | AF28: 1.84734 | AG28: 1.82491 | AH28: 1.802973 | AI28: 1.781409 | AJ28: 1.760126 | AK28: -0.013
A29: RST000:ca_ElectricHeatP | B29: Propane | C29: Residential Equipment: Equipment Stock: Water Heaters: Propane: Low economic growth | D29: AEO.2022.LOWMACRO.EQNR_STK_RESD_WHT_PROP_NA_NA_MILL.A | E29: millions | G29: 3.998682 | H29: 3.897122 | I29: 3.804604 | J29: 3.72221 | K29: 3.649823 | L29: 3.586324 | M29: 3.529158 | N29: 3.4795 | O29: 3.437484 | P29: 3.40298 | Q29: 3.363295 | R29: 3.320493 | S29: 3.274979 | T29: 3.227235 | U29: 3.178444 | V29: 3.129654 | W29: 3.081452 | X29: 3.034334 | Y29: 2.989191 | Z29: 2.946535 | AA29: 2.905906 | AB29: 2.867353 | AC29: 2.830608 | AD29: 2.795922 | AE29: 2.763403 | AF29: 2.732625 | AG29: 2.703559 | AH29: 2.67561 | AI29: 2.6487 | AJ29: 2.622729 | AK29: -0.014
A30: RST000:ca_NaturalGasHea | B30: Solar Thermal | C30: Residential Equipment: Equipment Stock: Water Heaters: Solar Thermal: Low economic growth | D30: AEO.2022.LOWMACRO.EQNR_STK_RESD_WHT_SLR_THERM_NA_MILL.A | E30: millions | G30: 1.873337 | H30: 2.106847 | I30: 2.264974 | J30: 2.272993 | K30: 2.28405 | L30: 2.295635 | M30: 2.306829 | N30: 2.317815 | O30: 2.328661 | P30: 2.339389 | Q30: 2.350307 | R30: 2.361829 | S30: 2.373521 | T30: 2.385176 | U30: 2.396525 | V30: 2.407451 | W30: 2.417866 | X30: 2.427773 | Y30: 2.437905 | Z30: 2.448268 | AA30: 2.458755 | AB30: 2.469354 | AC30: 2.479919 | AD30: 2.490493 | AE30: 2.501091 | AF30: 2.511559 | AG30: 2.522038 | AH30: 2.532417 | AI30: 2.542718 | AJ30: 2.552892 | AK30: 0.011
A31: RST000:ca_GeothermalHea | B31: Total | C31: Residential Equipment: Equipment Stock: Water Heaters: Total: Low economic growth | D31: AEO.2022.LOWMACRO.EQNR_STK_RESD_WHT_TOT_NA_NA_MILL.A | E31: millions | G31: 129.00867 | H31: 129.99635 | I31: 130.88855 | J31: 131.78415 | K31: 132.66891 | L31: 133.52061 | M31: 134.36087 | N31: 135.22253 | O31: 136.08719 | P31: 136.93422 | Q31: 137.757 | R31: 138.61882 | S31: 139.46904 | T31: 140.27574 | U31: 141.05946 | V31: 141.82632 | W31: 142.59602 | X31: 143.36879 | Y31: 144.14783 | Z31: 144.93144 | AA31: 145.70531 | AB31: 146.46123 | AC31: 147.2043 | AD31: 147.93678 | AE31: 148.66176 | AF31: 149.3775 | AG31: 150.08702 | AH31: 150.7813 | AI31: 151.46567 | AJ31: 152.13798 | AK31: 0.006
A32: RST000:ca_CentralAirCon | B32: Cooking Equipment (million units)
A33: RST000:ca_RoomAirCondit | B33: Electric | C33: Residential Equipment: Equipment Stock: Cooking Equipment: Electric: Low economic growth | D33: AEO.2022.LOWMACRO.EQNR_STK_RESD_CER_ELE_NA_NA_MILL.A | E33: millions | G33: 97.282806 | H33: 97.787354 | I33: 98.215042 | J33: 98.632729 | K33: 99.032143 | L33: 99.396202 | M33: 99.739357 | N33: 100.08295 | O33: 100.38844 | P33: 100.63934 | Q33: 100.82276 | R33: 100.97788 | S33: 101.15427 | T33: 101.35497 | U33: 101.59816 | V33: 101.89742 | W33: 102.27224 | X33: 102.63831 | Y33: 102.99777 | Z33: 103.34814 | AA33: 103.67843 | AB33: 103.98253 | AC33: 104.2638 | AD33: 104.52412 | AE33: 104.76753 | AF33: 104.99548 | AG33: 105.21425 | AH33: 105.42191 | AI33: 105.62772 | AJ33: 105.8353 | AK33: 0.003
A34: RST000:ca_Total | B34: Natural Gas | C34: Residential Equipment: Equipment Stock: Cooking Equipment: Natural Gas: Low economic growth | D34: AEO.2022.LOWMACRO.EQNR_STK_RESD_CER_NG_NA_NA_MILL.A | E34: millions | G34: 48.396942 | H34: 48.864845 | I34: 49.317436 | J34: 49.785069 | K34: 50.261314 | L34: 50.742012 | M34: 51.236866 | N34: 51.756042 | O34: 52.320065 | P34: 52.924976 | Q34: 53.576504 | R34: 54.296326 | S34: 54.979057 | T34: 55.590328 | U34: 56.132183 | V34: 56.597126 | W34: 56.98587 | X34: 57.389172 | Y34: 57.807804 | Z34: 58.242535 | AA34: 58.690311 | AB34: 59.148796 | AC34: 59.618919 | AD34: 60.099831 | AE34: 60.589512 | AF34: 61.083973 | AG34: 61.579159 | AH34: 62.068329 | AI34: 62.547977 | AJ34: 63.01305 | AK34: 0.009
B35: Propane | C35: Residential Equipment: Equipment Stock: Cooking Equipment: Propane: Low economic growth | D35: AEO.2022.LOWMACRO.EQNR_STK_RESD_CER_PROP_NA_NA_MILL.A | E35: millions | G35: 7.215937 | H35: 7.198987 | I35: 7.178784 | J35: 7.157144 | K35: 7.134501 | L35: 7.109806 | M35: 7.080655 | N35: 7.048186 | O35: 7.012279 | P35: 6.972398 | Q35: 6.929494 | R35: 6.885695 | S35: 6.846237 | T35: 6.810504 | U35: 6.778969 | V35: 6.751493 | W35: 6.727694 | X35: 6.701273 | Y35: 6.672495 | Z35: 6.641469 | AA35: 6.607776 | AB35: 6.571814 | AC35: 6.534314 | AD35: 6.496439 | AE35: 6.459413 | AF35: 6.423977 | AG35: 6.390821 | AH35: 6.359664 | AI35: 6.330132 | AJ35: 6.301469 | AK35: -0.005
B36: Total | C36: Residential Equipment: Equipment Stock: Cooking Equipment: Total: Low economic growth | D36: AEO.2022.LOWMACRO.EQNR_STK_RESD_CER_TOT_NA_NA_MILL.A | E36: millions | G36: 152.89569 | H36: 153.85118 | I36: 154.71126 | J36: 155.57495 | K36: 156.42796 | L36: 157.24802 | M36: 158.05688 | N36: 158.88718 | O36: 159.7208 | P36: 160.53671 | Q36: 161.32875 | R36: 162.1599 | S36: 162.97957 | T36: 163.7558 | U36: 164.50931 | V36: 165.24605 | W36: 165.98581 | X36: 166.72876 | Y36: 167.47807 | Z36: 168.23213 | AA36: 168.97652 | AB36: 169.70312 | AC36: 170.41704 | AD36: 171.12041 | AE36: 171.81645 | AF36: 172.50343 | AG36: 173.18424 | AH36: 173.8499 | AI36: 174.50583 | AJ36: 175.14983 | AK36: 0.005
A37: RST000:da_Electric | B37: Clothes Dryers (million units)
A38: RST000:da_NaturalGas | B38: Electric | C38: Residential Equipment: Equipment Stock: Clothes Dryers: Electric: Low economic growth | D38: AEO.2022.LOWMACRO.EQNR_STK_RESD_CDR_ELE_NA_NA_MILL.A | E38: millions | G38: 84.74617 | H38: 86.235474 | I38: 87.634346 | J38: 89.025757 | K38: 90.409912 | L38: 91.740776 | M38: 93.044624 | N38: 94.368134 | O38: 95.694359 | P38: 97.005806 | Q38: 98.296959 | R38: 99.628151 | S38: 100.95462 | T38: 102.28601 | U38: 103.60919 | V38: 104.9316 | W38: 106.24234 | X38: 107.54414 | Y38: 108.84335 | Z38: 110.13705 | AA38: 111.41454 | AB38: 112.66832 | AC38: 113.90573 | AD38: 115.13056 | AE38: 116.3458 | AF38: 117.55255 | AG38: 118.75244 | AH38: 119.93816 | AI38: 121.11373 | AJ38: 122.27639 | AK38: 0.013
A39: RST000:da_Distillate | B39: Natural Gas | C39: Residential Equipment: Equipment Stock: Clothes Dryers: Natural Gas: Low economic growth | D39: AEO.2022.LOWMACRO.EQNR_STK_RESD_CDR_NG_NA_NA_MILL.A | E39: millions | G39: 19.709597 | H39: 20.023542 | I39: 20.33856 | J39: 20.669289 | K39: 21.015242 | L39: 21.379358 | M39: 21.76585 | N39: 22.150591 | O39: 22.533482 | P39: 22.910875 | Q39: 23.281893 | R39: 23.653246 | S39: 24.01589 | T39: 24.363272 | U39: 24.692194 | V39: 25.002323 | W39: 25.322683 | X39: 25.652546 | Y39: 25.990679 | Z39: 26.336733 | AA39: 26.687059 | AB39: 27.039303 | AC39: 27.391558 | AD39: 27.742498 | AE39: 28.091402 | AF39: 28.436264 | AG39: 28.777365 | AH39: 29.113682 | AI39: 29.446186 | AJ39: 29.77441 | AK39: 0.014
A40: RST000:da_LiquefiedPetr | B40: Total | C40: Residential Equipment: Equipment Stock: Clothes Dryers: Total: Low economic growth | D40: AEO.2022.LOWMACRO.EQNR_STK_RESD_CDR_TOT_NA_NA_MILL.A | E40: millions | G40: 104.45576 | H40: 106.25902 | I40: 107.97291 | J40: 109.69504 | K40: 111.42516 | L40: 113.12013 | M40: 114.81047 | N40: 116.51872 | O40: 118.22784 | P40: 119.91668 | Q40: 121.57885 | R40: 123.2814 | S40: 124.97051 | T40: 126.64928 | U40: 128.30139 | V40: 129.93393 | W40: 131.56502 | X40: 133.19669 | Y40: 134.83403 | Z40: 136.47378 | AA40: 138.10161 | AB40: 139.70763 | AC40: 141.29729 | AD40: 142.87306 | AE40: 144.43721 | AF40: 145.98881 | AG40: 147.5298 | AH40: 149.05183 | AI40: 150.55992 | AJ40: 152.0508 | AK40: 0.013
...

Sheet NREL EF Table 22
A1: Figure 22. Installed unit costs (left) and performance projections (right) for commercial air-source heat pumps
A2: Figure Notes: | B2: Installed costs include both capital and installation costs.
A4: Year | B4: Technology | C4: EFS Case | D4: Installed Cost ($/kBtu/hr) | E4: Efficiency (COP)
A5: 2015 | B5: Air Source Heat Pump | C5: Moderate Advancement | D5: 96 | E5: 3.3
A6: 2015 | B6: Air Source Heat Pump | C6: Rapid Advancement | D6: 96 | E6: 3.3
A7: 2015 | B7: Air Source Heat Pump | C7: Slow Advancement | D7: 96 | E7: 3.3
A8: 2015 | B8: Cold Climate Air Source Heat Pump | C8: Moderate Advancement | D8: 96 | E8: 1.5
A9: 2015 | B9: Cold Climate Air Source Heat Pump | C9: Rapid Advancement | D9: 96 | E9: 1.5
A10: 2015 | B10: Cold Climate Air Source Heat Pump | C10: Slow Advancement | D10: 96 | E10: 1.5
A11: 2020 | B11: Air Source Heat Pump | C11: Moderate Advancement | D11: 85 | E11: 3.75
A12: 2020 | B12: Air Source Heat Pump | C12: Rapid Advancement | D12: 80 | E12: 4
A13: 2020 | B13: Air Source Heat Pump | C13: Slow Advancement | D13: 92.873543 | E13: 3.4
A14: 2020 | B14: Cold Climate Air Source Heat Pump | C14: Moderate Advancement | D14: 85 | E14: 2
A15: 2020 | B15: Cold Climate Air Source Heat Pump | C15: Rapid Advancement | D15: 80 | E15: 2.5
A16: 2020 | B16: Cold Climate Air Source Heat Pump | C16: Slow Advancement | D16: 92.873543 | E16: 1.75
... A34: 2050 | B34: Cold Climate Air Source Heat Pump | C34: Slow Advancement | D34: 76.140668 | E34: 2.75

Sheet NREL EF Table 23
A1: Figure 23. Installed costs (left) and performance projections (right) for commercial HPWHs
A2: Figure Notes: | B2: Installed costs include both capital and installation costs.
A4: Year | B4: Technology | C4: EFS Case | D4: Installed Cost ($/kBtu/hr) | E4: Efficiency (COP)
A5: 2015 | B5: Heat Pump Water Heater | C5: Moderate Advancement | D5: 310 | E5: 2.45
A6: 2015 | B6: Heat Pump Water Heater | C6: Rapid Advancement | D6: 310 | E6: 2.45
A7: 2015 | B7: Heat Pump Water Heater | C7: Slow Advancement | D7: 310 | E7: 2.45
A8: 2020 | B8: Heat Pump Water Heater | C8: Moderate Advancement | D8: 287.51781 | E8: 3
A9: 2020 | B9: Heat Pump Water Heater | C9: Rapid Advancement | D9: 281.0389 | E9: 3
A10: 2020 | B10: Heat Pump Water Heater | C10: Slow Advancement | D10: 302.85283 | E10: 3
A11: 2030 | B11: Heat Pump Water Heater | C11: Moderate Advancement | D11: 247.32663 | E11: 3.25
A12: 2030 | B12: Heat Pump Water Heater | C12: Rapid Advancement | D12: 219.56945 | E12: 3.6
A13: 2030 | B13: Heat Pump Water Heater | C13: Slow Advancement | D13: 289.04903 | E13: 3
A14: 2040 | B14: Heat Pump Water Heater | C14: Moderate Advancement | D14: 212.75364 | E14: 3.35
A15: 2040 | B15: Heat Pump Water Heater | C15: Rapid Advancement | D15: 180 | E15: 3.85
A16: 2040 | B16: Heat Pump Water Heater | C16: Slow Advancement | D16: 275.8744 | E16: 3
... A19: 2050 | B19: Heat Pump Water Heater | C19: Slow Advancement | D19: 263.5 | E19: 3

Sheet Calculations
A1: Residential Equipment
A2: Appliances (cooking)
A3: Appliances Energy Consumption per Unit per Year by Fuel (btu/household) | B3: 2019 | C3: 2020 | D3: 2021 | E3: 2022 | F3: 2023 | G3: 2024 | H3: 2025 | I3: 2026 | J3: 2027 | K3: 2028 | L3: 2029 | M3: 2030 | N3: 2031 | O3: 2032 | P3: 2033 | Q3: 2034 | R3: 2035 | S3: 2036 | T3: 2037 | U3: 2038 | V3: 2039 | W3: 2040 | X3: 2041 | Y3: 2042 | Z3: 2043 | AA3: 2044 | AB3: 2045 | AC3: 2046 | AD3: 2047 | AE3: 2048 | AF3: 2049 | AG3: 2050
A4: traditional biomass | B4: ='IESS Residential'!$B$10*'IESS Residential'!$B$14 -> 4243675 | C4: ='IESS Residential'!$B$10*'IESS Residential'!$B$14 -> 4243675 | D4: ='IESS Residential'!$B$10*'IESS Residential'!$B$14 -> 4243675 | E4: ='IESS Residential'!$B$10*'IESS Residential'!$B$14 -> 4243675 | F4: ='IESS Residential'!$B$10*'IESS Residential'!$B$14 -> 4243675 | G4: ='IESS Residential'!$B$10*'IESS Residential'!$B$14 -> 4243675 | H4: ='IESS Residential'!$B$10*'IESS Residential'!$B$14 -> 4243675 | I4: ='IESS Residential'!$B$10*'IESS Residential'!$B$14 -> 4243675 | ... AG4: ='IESS Residential'!$B$10*'IESS Residential'!$B$14 -> 4243675
A5: LPG | B5: ='IESS Residential'!$B$4*'IESS Residential'!$B$14 -> 4811393.9 | C5: ='IESS Residential'!$B$4*'IESS Residential'!$B$14 -> 4811393.9 | D5: ='IESS Residential'!$B$4*'IESS Residential'!$B$14 -> 4811393.9 | E5: ='IESS Residential'!$B$4*'IESS Residential'!$B$14 -> 4811393.9 | F5: ='IESS Residential'!$B$4*'IESS Residential'!$B$14 -> 4811393.9 | G5: ='IESS Residential'!$B$4*'IESS Residential'!$B$14 -> 4811393.9 | H5: ='IESS Residential'!$B$4*'IESS Residential'!$B$14 -> 4811393.9 | I5: ='IESS Residential'!$B$4*'IESS Residential'!$B$14 -> 4811393.9 | ... AG5: ='IESS Residential'!$B$4*'IESS Residential'!$B$14 -> 4811393.9
A7: Annualized Incremental Equipment Cost | B7: 2019 | C7: 2020 | D7: 2021 | E7: 2022 | F7: 2023 | G7: 2024 | H7: 2025 | I7: 2026 | J7: 2027 | K7: 2028 | L7: 2029 | M7: 2030 | N7: 2031 | O7: 2032 | P7: 2033 | Q7: 2034 | R7: 2035 | S7: 2036 | T7: 2037 | U7: 2038 | V7: 2039 | W7: 2040 | X7: 2041 | Y7: 2042 | Z7: 2043 | AA7: 2044 | AB7: 2045 | AC7: 2046 | AD7: 2047 | AE7: 2048 | AF7: 2049 | AG7: 2050
A8: traditional biomass (trillion Rs) | B8: ='IESS Residential'!M56+'IESS Residential'!H21*'IESS Residential'!F21-'IESS Residential'!M78 -> 7.0337685e-09 | C8: ='IESS Residential'!N56+'IESS Residential'!I21*'IESS Residential'!G21-'IESS Residential'!N78 -> 8.8725e-20 | D8: ='IESS Residential'!O56+'IESS Residential'!J21*'IESS Residential'!H21-'IESS Residential'!O78 -> 0 | E8: ='IESS Residential'!P56+'IESS Residential'!K21*'IESS Residential'!I21-'IESS Residential'!P78 -> 0.136 | F8: ='IESS Residential'!Q56+'IESS Residential'!L21*'IESS Residential'!J21-'IESS Residential'!Q78 -> 0.142 | G8: ='IESS Residential'!R56+'IESS Residential'!M21*'IESS Residential'!K21-'IESS Residential'!R78 -> 0.1585 | H8: ='IESS Residential'!S56+'IESS Residential'!N21*'IESS Residential'!L21-'IESS Residential'!S78 -> 0.175 | I8: ='IESS Residential'!T56+'IESS Residential'!O21*'IESS Residential'!M21-'IESS Residential'!T78 -> 0.1915 | ... AD8: ='IESS Residential'!AO56+'IESS Residential'!AJ21*'IESS Residential'!AH21-'IESS Residential'!AO78 -> 0.735667 | AE8: =AD8 -> 0.735667 | AF8: =AE8 -> 0.735667 | AG8: =AF8 -> 0.735667
A9: LPG (trillion Rs) | B9: =('IESS Residential'!M56+'IESS Residential'!H21*'IESS Residential'!F21)-('IESS Residential'!M34+'IESS Residential'!H20*'IESS Residential'!F20) -> 2.2e-09 | C9: =('IESS Residential'!N56+'IESS Residential'!I21*'IESS Residential'!G21)-('IESS Residential'!N34+'IESS Residential'!I20*'IESS Residential'!G20) -> 7.6437e-20 | D9: =('IESS Residential'!O56+'IESS Residential'!J21*'IESS Residential'!H21)-('IESS Residential'!O34+'IESS Residential'!J20*'IESS Residential'!H20) -> 0 | E9: =('IESS Residential'!P56+'IESS Residential'!K21*'IESS Residential'!I21)-('IESS Residential'!P34+'IESS Residential'!K20*'IESS Residential'!I20) -> 0.374 | F9: =('IESS Residential'!Q56+'IESS Residential'!L21*'IESS Residential'!J21)-('IESS Residential'!Q34+'IESS Residential'!L20*'IESS Residential'!J20) -> 0.0425 | G9: =('IESS Residential'!R56+'IESS Residential'!M21*'IESS Residential'!K21)-('IESS Residential'!R34+'IESS Residential'!M20*'IESS Residential'!K20) -> -0.289 | H9: =('IESS Residential'!S56+'IESS Residential'!N21*'IESS Residential'!L21)-('IESS Residential'!S34+'IESS Residential'!N20*'IESS Residential'!L20) -> -0.6205 | I9: =('IESS Residential'!T56+'IESS Residential'!O21*'IESS Residential'!M21)-('IESS Residential'!T34+'IESS Residential'!O20*'IESS Residential'!M20) -> -0.952 | ... AD9: =('IESS Residential'!AO56+'IESS Residential'!AJ21*'IESS Residential'!AH21)-('IESS Residential'!AO34+'IESS Residential'!AJ20*'IESS Residential'!AH20) -> 0.193334 | AE9: =AD9 -> 0.193334 | AF9: =AE9 -> 0.193334 | AG9: =AF9 -> 0.193334
A11: Annualized Incremental Equipment Cost | B11: 2019 | C11: 2020 | D11: 2021 | E11: 2022 | F11: 2023 | G11: 2024 | H11: 2025 | I11: 2026 | J11: 2027 | K11: 2028 | L11: 2029 | M11: 2030 | N11: 2031 | O11: 2032 | P11: 2033 | Q11: 2034 | R11: 2035 | S11: 2036 | T11: 2037 | U11: 2038 | V11: 2039 | W11: 2040 | X11: 2041 | Y11: 2042 | Z11: 2043 | AA11: 2044 | AB11: 2045 | AC11: 2046 | AD11: 2047 | AE11: 2048 | AF11: 2049 | AG11: 2050
A12: traditional biomass (2012 USD) | B12: =B8*1000000000000/About!$B$58 -> 128.42374 | C12: =C8*1000000000000/About!$B$58 -> 1.6199562e-09 | D12: =D8*1000000000000/About!$B$58 -> 0 | E12: =E8*1000000000000/About!$B$58 -> 2.4831112e+09 | F12: =F8*1000000000000/About!$B$58 -> 2.5926602e+09 | G12: =G8*1000000000000/About!$B$58 -> 2.89392e+09 | H12: =H8*1000000000000/About!$B$58 -> 3.1951798e+09 | I12: =I8*1000000000000/About!$B$58 -> 3.4964397e+09 | ... AG12: =AG8*1000000000000/About!$B$58 -> 1.3431934e+10
A13: LPG (2012 USD) | B13: =B9*1000000000000/About!$B$58 -> 40.167975 | C13: =C9*1000000000000/About!$B$58 -> 1.3955998e-09 | D13: =D9*1000000000000/About!$B$58 -> 0 | E13: =E9*1000000000000/About!$B$58 -> 6.8285558e+09 | F13: =F9*1000000000000/About!$B$58 -> 7.7597225e+08 | G13: =G9*1000000000000/About!$B$58 -> -5.2766113e+09 | H13: =H9*1000000000000/About!$B$58 -> -1.1329195e+10 | I13: =I9*1000000000000/About!$B$58 -> -1.7381778e+10 | ... AG13: =AG9*1000000000000/About!$B$58 -> 3.5299251e+09
A15: Annualized Incremental Cost per BTU Shifted | B15: 2019 | C15: 2020 | D15: 2021 | E15: 2022 | F15: 2023 | G15: 2024 | H15: 2025 | I15: 2026 | J15: 2027 | K15: 2028 | L15: 2029 | M15: 2030 | N15: 2031 | O15: 2032 | P15: 2033 | Q15: 2034 | R15: 2035 | S15: 2036 | T15: 2037 | U15: 2038 | V15: 2039 | W15: 2040 | X15: 2041 | Y15: 2042 | Z15: 2043 | AA15: 2044 | AB15: 2045 | AC15: 2046 | AD15: 2047 | AE15: 2048 | AF15: 2049 | AG15: 2050
A16: traditional biomass | B16: =B12/B4 -> 3.0262389e-05 | C16: =C12/C4 -> 3.8173427e-16 | D16: =D12/D4 -> 0 | E16: =E12/E4 -> 585.13227 | F16: =F12/F4 -> 610.94693 | G16: =G12/G4 -> 681.93724 | H16: =H12/H4 -> 752.92756 | I16: =I12/I4 -> 823.91787 | ... AG16: =AG12/AG4 -> 3165.1655
A17: LPG | B17: =B13/B5 -> 8.3485111e-06 | C17: =C13/C5 -> 2.9006143e-16 | D17: =D13/D5 -> 0 | E17: =E13/E5 -> 1419.2469 | F17: =F13/F5 -> 161.27805 | G17: =G13/G5 -> -1096.6908 | H17: =H13/H5 -> -2354.6596 | I17: =I13/I5 -> -3612.6284 | ... AG17: =AG13/AG5 -> 733.65956
A19: Commercial Equipment
A20: Appliances (water heaters)
A21: Utilization Assumption
A22: space heating | B22: 0.08
A23: water heating | B23: 0.25
A26: Installed Cost ($/kBTU/hr) | B26: 2015 | C26: 2017 | D26: 2020 | E26: 2030 | F26: 2040 | G26: 2050
A27: natural gas (2017 USD) | C27: =AVERAGE('EIA Costs'!D134:D135)/'EIA Costs'!D131 -> 19.472362 | D27: =AVERAGE('EIA Costs'!G134:G135)/'EIA Costs'!G131 -> 19.472362 | E27: =AVERAGE('EIA Costs'!I134:I135)/'EIA Costs'!I131 -> 19.472362 | F27: =AVERAGE('EIA Costs'!K134:K135)/'EIA Costs'!K131 -> 19.472362 | G27: =AVERAGE('EIA Costs'!M134:M135)/'EIA Costs'!M131 -> 19.472362
A28: oil (2017 USD) | C28: ='EIA Costs'!D148/'EIA Costs'!D144 -> 17.333333 | D28: ='EIA Costs'!F148/'EIA Costs'!F144 -> 17.333333 | E28: ='EIA Costs'!H148/'EIA Costs'!H144 -> 17.333333 | F28: ='EIA Costs'!J148/'EIA Costs'!J144 -> 17.333333 | G28: ='EIA Costs'!L148/'EIA Costs'!L144 -> 17.333333
A29: ASHP (2016 USD) | B29: ='NREL EF Table 23'!D5 -> 310 | D29: ='NREL EF Table 23'!D8 -> 287.51781 | E29: ='NREL EF Table 23'!D11 -> 247.32663 | F29: ='NREL EF Table 23'!D14 -> 212.75364 | G29: ='NREL EF Table 23'!D17 -> 184.45
A31: Annualized Installed Cost ($/kBTU/hr) | B31: 2019 | C31: 2020 | D31: 2021 | E31: 2022 | F31: 2023 | G31: 2024 | H31: 2025 | I31: 2026 | J31: 2027 | K31: 2028 | L31: 2029 | M31: 2030 | N31: 2031 | O31: 2032 | P31: 2033 | Q31: 2034 | R31: 2035 | S31: 2036 | T31: 2037 | U31: 2038 | V31: 2039 | W31: 2040 | X31: 2041 | Y31: 2042 | Z31: 2043 | AA31: 2044 | AB31: 2045 | AC31: 2046 | AD31: 2047 | AE31: 2048 | AF31: 2049 | AG31: 2050
A32: natural gas (2012 USD) | B32: =(TREND($C$27:$D$27,$C$26:$D$26,B$11))*(About!$A$60) -> 18.238975 | C32: =(TREND($C$27:$D$27,$C$26:$D$26,C$11))*(About!$A$60) -> 18.238975 | D32: =(TREND($D$27:$E$27,$D$26:$E$26,D$11))*(About!$A$60) -> 18.238975 | E32: =(TREND($D$27:$E$27,$D$26:$E$26,E$11))*(About!$A$60) -> 18.238975 | F32: =(TREND($D$27:$E$27,$D$26:$E$26,F$11))*(About!$A$60) -> 18.238975 | G32: =(TREND($D$27:$E$27,$D$26:$E$26,G$11))*(About!$A$60) -> 18.238975 | H32: =(TREND($D$27:$E$27,$D$26:$E$26,H$11))*(About!$A$60) -> 18.238975 | I32: =(TREND($D$27:$E$27,$D$26:$E$26,I$11))*(About!$A$60) -> 18.238975 | J32: =(TREND($D$27:$E$27,$D$26:$E$26,J$11))*(About!$A$60) -> 18.238975 | K32: =(TREND($D$27:$E$27,$D$26:$E$26,K$11))*(About!$A$60) -> 18.238975 | ... M32: =(TREND($D$27:$E$27,$D$26:$E$26,M$11))*(About!$A$60) -> 18.238975 | N32: =(TREND($E$27:$G$27,$E$26:$G$26,N$11))*(About!$A$60) -> 18.238975 | O32: =(TREND($E$27:$G$27,$E$26:$G$26,O$11))*(About!$A$60) -> 18.238975 | P32: =(TREND($E$27:$G$27,$E$26:$G$26,P$11))*(About!$A$60) -> 18.238975 | Q32: =(TREND($E$27:$G$27,$E$26:$G$26,Q$11))*(About!$A$60) -> 18.238975 | R32: =(TREND($E$27:$G$27,$E$26:$G$26,R$11))*(About!$A$60) -> 18.238975 | S32: =(TREND($E$27:$G$27,$E$26:$G$26,S$11))*(About!$A$60) -> 18.238975 | T32: =(TREND($E$27:$G$27,$E$26:$G$26,T$11))*(About!$A$60) -> 18.238975 | U32: =(TREND($E$27:$G$27,$E$26:$G$26,U$11))*(About!$A$60) -> 18.238975 | ... AG32: =(TREND($E$27:$G$27,$E$26:$G$26,AG$11))*(About!$A$60) -> 18.238975
