Workbook

Sheet About
A1: BCEU BAU Components Energy Use
A3: Sources: | B3: Future Year Scaling and non-electricity values
B4: NITI Aayog
B5: 2023
B6: India Energy Security Scenarios
B7: http://indiaenergy.gov.in/iess/docs/IESS_Version2.2.xlsx
B8: Tables X.a and X.b
B10: Electricity Use in Residential and Commercial Buildings
B11: Government of India, Ministry of Statistics and Programme Implementation
B12: 2022
B13: Energy Statistics 2022
B14: Energy Statistics India 2022.pdf (mospi.gov.in)
B15: Table 6.8
B17: LPG and Kerosene Use in Buildings
B18: Ministry of Petroleum and Natural Gas
B19: 2021
B20: Indian Petroleum & Natural Gas Statistics 2021-22
B21: IPNG-2021-22_L.pdf (mopng.gov.in)
B22: Pages 110, 113 Tables: V.9, V.12
B24: Biomass and Coal Use
B25: IIASA
B26: 2018
B27: GAINS Model: South Asia
B28: http://gains.iiasa.ac.at/models/index.html
B29: Activity Data, Energy use in the domestic sector by device type, ECLIPSE_V5a_CLE_base scenario
B31: Energy in LPG and Kerosene
B32: TERI
B33: 2021
B34: TERI Energy and Environmental Data Diary and Yearbook 2021-22
B35: TERI Energy & Environment Data Diary and Yearbook (TEDDY) 2021-22 by A TERI Publication buy online
B36: Page 15, Table 6
A38: Notes:
A39: The "Start Year" is the year before the first simulated year.
A40: The start year can be updated using the following field:
A41: 2022
A43: This variable is based on bldgs/BCEU and uses the same data sources.
A44: We separate the start year values into their own variable so that
A45: we do not need to access data from a year outside of the model's
A46: run range from BCEU, which helps people avoid introducing
A47: bugs when they update model data.

Sheet Calculations - from BCEU
A1: Building Type | B1: Fuel Type | C1: Service | D1: 2021 | E1: 2022 | F1: 2023 | G1: 2024 | H1: 2025 | I1: 2026 | J1: 2027 | K1: 2028 | L1: 2029 | M1: 2030 | N1: 2031 | O1: 2032 | P1: 2033 | Q1: 2034 | R1: 2035 | S1: 2036 | T1: 2037 | U1: 2038 | V1: 2039 | W1: 2040 | X1: 2041 | Y1: 2042 | Z1: 2043 | AA1: 2044 | AB1: 2045 | AC1: 2046 | AD1: 2047 | AE1: 2048 | AF1: 2049 | AG1: 2050 | AH1: 2051 | AI1: 2052 | AJ1: 2053 | AK1: 2054 | AL1: 2055 | AM1: 2056 | AN1: 2057 | AO1: 2058 | AP1: 2059 | AQ1: 2060 | AR1: 2061 | AS1: 2062 | AT1: 2063 | AU1: 2064 | AV1: 2065 | AW1: 2066 | AX1: 2067 | AY1: 2068 | AZ1: 2069 | BA1: 2070
A2: Urban Residential | B2: electricity (BTU) | C2: Heating | D2: 0 | E2: 0 | F2: 0 | G2: 0 | H2: 0 | I2: 0 | J2: 0 | K2: 0 | L2: 0 | M2: 0 | N2: 0 | O2: 0 | P2: 0 | Q2: 0 | R2: 0 | S2: 0 | T2: 0 | U2: 0 | V2: 0 | W2: 0 | X2: 0 | Y2: 0 | Z2: 0 | AA2: 0 | AB2: 0 | AC2: 0 | AD2: 0
A3: Urban Residential | B3: electricity (BTU) | C3: cooling & ventilation | D3: 137000000000000 | E3: 153000000000000 | F3: 173000000000000 | G3: 193000000000000 | H3: 213000000000000 | I3: 234000000000000 | J3: 255000000000000 | K3: 285000000000000 | L3: 315000000000000 | M3: 346000000000000 | N3: 378000000000000 | O3: 409000000000000 | P3: 441000000000000 | Q3: 473000000000000 | R3: 505000000000000 | S3: 538000000000000 | T3: 571000000000000 | U3: 603000000000000 | V3: 635000000000000 | W3: 668000000000000 | X3: 701000000000000 | Y3: 735000000000000 | Z3: 768000000000000 | AA3: 802000000000000 | AB3: 836000000000000 | AC3: 870000000000000 | AD3: 905000000000000
A4: Urban Residential | B4: electricity (BTU) | C4: Lighting | D4: 54900000000000 | E4: 57700000000000 | F4: 58600000000000 | G4: 59600000000000 | H4: 60500000000000 | I4: 61400000000000 | J4: 62300000000000 | K4: 63000000000000 | L4: 63600000000000 | M4: 64300000000000 | N4: 64900000000000 | O4: 65500000000000 | P4: 66900000000000 | Q4: 68200000000000 | R4: 69600000000000 | S4: 70900000000000 | T4: 72200000000000 | U4: 73500000000000 | V4: 74800000000000 | W4: 76100000000000 | X4: 77300000000000 | Y4: 78600000000000 | Z4: 79600000000000 | AA4: 80700000000000 | AB4: 81700000000000 | AC4: 82700000000000 | AD4: 83700000000000
A5: Urban Residential | B5: electricity (BTU) | C5: Appliances | D5: 185000000000000 | E5: 198000000000000 | F5: 210000000000000 | G5: 221000000000000 | H5: 233000000000000 | I5: 245000000000000 | J5: 256000000000000 | K5: 268000000000000 | L5: 281000000000000 | M5: 293000000000000 | N5: 305000000000000 | O5: 317000000000000 | P5: 328000000000000 | Q5: 338000000000000 | R5: 349000000000000 | S5: 359000000000000 | T5: 370000000000000 | U5: 382000000000000 | V5: 394000000000000 | W5: 406000000000000 | X5: 419000000000000 | Y5: 431000000000000 | Z5: 443000000000000 | AA5: 455000000000000 | AB5: 467000000000000 | AC5: 479000000000000 | AD5: 491000000000000
A6: Urban Residential | B6: electricity (BTU) | C6: Other | D6: 38000000000000 | E6: 33500000000000 | F6: 38100000000000 | G6: 42700000000000 | H6: 47500000000000 | I6: 52300000000000 | J6: 57100000000000 | K6: 64600000000000 | L6: 72100000000000 | M6: 79800000000000 | N6: 87600000000000 | O6: 95500000000000 | P6: 107000000000000 | Q6: 119000000000000 | R6: 131000000000000 | S6: 143000000000000 | T6: 156000000000000 | U6: 170000000000000 | V6: 183000000000000 | W6: 197000000000000 | X6: 212000000000000 | Y6: 226000000000000 | Z6: 242000000000000 | AA6: 258000000000000 | AB6: 274000000000000 | AC6: 290000000000000 | AD6: 307000000000000
A7: Rural Residential | B7: electricity (BTU) | C7: Heating | D7: 0 | E7: 0 | F7: 0 | G7: 0 | H7: 0 | I7: 0 | J7: 0 | K7: 0 | L7: 0 | M7: 0 | N7: 0 | O7: 0 | P7: 0 | Q7: 0 | R7: 0 | S7: 0 | T7: 0 | U7: 0 | V7: 0 | W7: 0 | X7: 0 | Y7: 0 | Z7: 0 | AA7: 0 | AB7: 0 | AC7: 0
A8: Rural Residential | B8: electricity (BTU) | C8: cooling & ventilation | D8: 298000000000000 | E8: 286000000000000 | F8: 317000000000000 | G8: 348000000000000 | H8: 379000000000000 | I8: 409000000000000 | J8: 439000000000000 | K8: 483000000000000 | L8: 525000000000000 | M8: 568000000000000 | N8: 610000000000000 | O8: 651000000000000 | P8: 690000000000000 | Q8: 728000000000000 | R8: 767000000000000 | S8: 804000000000000 | T8: 842000000000000 | U8: 875000000000000 | V8: 908000000000000 | W8: 941000000000000 | X8: 974000000000000 | Y8: 1.01e+15 | Z8: 1.04e+15 | AA8: 1.07e+15 | AB8: 1.09e+15 | AC8: 1.12e+15 | AD8: 1.15e+15
A9: Rural Residential | B9: electricity (BTU) | C9: Lighting | D9: 120000000000000 | E9: 108000000000000 | F9: 108000000000000 | G9: 108000000000000 | H9: 108000000000000 | I9: 107000000000000 | J9: 107000000000000 | K9: 107000000000000 | L9: 106000000000000 | M9: 105000000000000 | N9: 105000000000000 | O9: 104000000000000 | P9: 105000000000000 | Q9: 105000000000000 | R9: 106000000000000 | S9: 106000000000000 | T9: 107000000000000 | U9: 107000000000000 | V9: 107000000000000 | W9: 107000000000000 | X9: 107000000000000 | Y9: 108000000000000 | Z9: 107000000000000 | AA9: 107000000000000 | AB9: 107000000000000 | AC9: 107000000000000 | AD9: 107000000000000
A10: Rural Residential | B10: electricity (BTU) | C10: Appliances | D10: 403700000000000 | E10: 424700000000000 | F10: 441500000000000 | G10: 458200000000000 | H10: 474800000000000 | I10: 491200000000000 | J10: 507500000000000 | K10: 522100000000000 | L10: 536500000000000 | M10: 550800000000000 | N10: 565100000000000 | O10: 579300000000000 | P10: 588800000000000 | Q10: 598300000000000 | R10: 607800000000000 | S10: 617200000000000 | T10: 626500000000000 | U10: 636800000000000 | V10: 647000000000000 | W10: 657100000000000 | X10: 667200000000000 | Y10: 677300000000000 | Z10: 685400000000000 | AA10: 693400000000000 | AB10: 701400000000000 | AC10: 709400000000000 | AD10: 717400000000000
A11: Rural Residential | B11: electricity (BTU) | C11: Other | D11: 38000000000000 | E11: 33500000000000 | F11: 38100000000000 | G11: 42700000000000 | H11: 47500000000000 | I11: 52300000000000 | J11: 57100000000000 | K11: 64600000000000 | L11: 72100000000000 | M11: 79800000000000 | N11: 87600000000000 | O11: 95500000000000 | P11: 107000000000000 | Q11: 119000000000000 | R11: 131000000000000 | S11: 143000000000000 | T11: 156000000000000 | U11: 170000000000000 | V11: 183000000000000 | W11: 197000000000000 | X11: 212000000000000 | Y11: 226000000000000 | Z11: 242000000000000 | AA11: 258000000000000 | AB11: 274000000000000 | AC11: 290000000000000 | AD11: 307000000000000
A12: Commercial | B12: electricity (BTU) | C12: Heating | D12: 0 | E12: 0 | F12: 0 | G12: 0 | H12: 0 | I12: 0 | J12: 0 | K12: 0 | L12: 0 | M12: 0 | N12: 0 | O12: 0 | P12: 0 | Q12: 0 | R12: 0 | S12: 0 | T12: 0 | U12: 0 | V12: 0 | W12: 0 | X12: 0 | Y12: 0 | Z12: 0 | AA12: 0 | AB12: 0 | AC12: 0 | AD12: 0
A13: Commercial | B13: electricity (BTU) | C13: cooling & ventilation | D13: 191000000000000 | E13: 224000000000000 | F13: 236000000000000 | G13: 249000000000000 | H13: 261000000000000 | I13: 274000000000000 | J13: 286000000000000 | K13: 304000000000000 | L13: 323000000000000 | M13: 341000000000000 | N13: 359000000000000 | O13: 378000000000000 | P13: 404000000000000 | Q13: 430000000000000 | R13: 456000000000000 | S13: 482000000000000 | T13: 508000000000000 | U13: 539000000000000 | V13: 569000000000000 | W13: 600000000000000 | X13: 630000000000000 | Y13: 661000000000000 | Z13: 697000000000000 | AA13: 734000000000000 | AB13: 770000000000000 | AC13: 806000000000000 | AD13: 843000000000000
A14: Commercial | B14: electricity (BTU) | C14: Lighting | D14: 38200000000000 | E14: 44100000000000 | F14: 45500000000000 | G14: 47000000000000 | H14: 48400000000000 | I14: 49800000000000 | J14: 51300000000000 | K14: 53400000000000 | L14: 55500000000000 | M14: 57700000000000 | N14: 59800000000000 | O14: 62000000000000 | P14: 66700000000000 | Q14: 71400000000000 | R14: 76100000000000 | S14: 80800000000000 | T14: 85600000000000 | U14: 91500000000000 | V14: 97400000000000 | W14: 103000000000000 | X14: 109000000000000 | Y14: 115000000000000 | Z14: 123000000000000 | AA14: 131000000000000 | AB14: 138000000000000 | AC14: 146000000000000 | AD14: 154000000000000
A15: Commercial | B15: electricity (BTU) | C15: Appliances | D15: 58800000000000 | E15: 68000000000000 | F15: 69500000000000 | G15: 70900000000000 | H15: 72300000000000 | I15: 73800000000000 | J15: 75200000000000 | K15: 76900000000000 | L15: 78500000000000 | M15: 80200000000000 | N15: 81800000000000 | O15: 83500000000000 | P15: 84900000000000 | Q15: 86400000000000 | R15: 87800000000000 | S15: 89200000000000 | T15: 90700000000000 | U15: 92300000000000 | V15: 93900000000000 | W15: 95500000000000 | X15: 97100000000000 | Y15: 98700000000000 | Z15: 100000000000000 | AA15: 102000000000000 | AB15: 103000000000000 | AC15: 104000000000000 | AD15: 106000000000000
A16: Commercial | B16: electricity (BTU) | C16: Other | D16: 30800000000000 | E16: 31700000000000 | F16: 32500000000000 | G16: 33300000000000 | H16: 34100000000000 | I16: 34900000000000 | J16: 35700000000000 | K16: 37200000000000 | L16: 38700000000000 | M16: 40200000000000 | N16: 41700000000000 | O16: 43200000000000 | P16: 46500000000000 | Q16: 49700000000000 | R16: 53000000000000 | S16: 56300000000000 | T16: 59600000000000 | U16: 66500000000000 | V16: 73400000000000 | W16: 80200000000000 | X16: 87100000000000 | Y16: 94000000000000 | Z16: 96600000000000 | AA16: 99200000000000 | AB16: 102000000000000 | AC16: 104000000000000 | AD16: 107000000000000
A17: Urban Residential | B17: coal (BTU) | C17: Heating | D17: 0 | E17: 0 | F17: 0 | G17: 0 | H17: 0 | I17: 0 | J17: 0 | K17: 0 | L17: 0 | M17: 0 | N17: 0 | O17: 0 | P17: 0 | Q17: 0 | R17: 0 | S17: 0 | T17: 0 | U17: 0 | V17: 0 | W17: 0 | X17: 0 | Y17: 0 | Z17: 0 | AA17: 0 | AB17: 0 | AC17: 0 | AD17: 0
A18: Urban Residential | B18: coal (BTU) | C18: cooling & ventilation | D18: 0 | E18: 0 | F18: 0 | G18: 0 | H18: 0 | I18: 0 | J18: 0 | K18: 0 | L18: 0 | M18: 0 | N18: 0 | O18: 0 | P18: 0 | Q18: 0 | R18: 0 | S18: 0 | T18: 0 | U18: 0 | V18: 0 | W18: 0 | X18: 0 | Y18: 0 | Z18: 0 | AA18: 0 | AB18: 0 | AC18: 0 | AD18: 0
A19: Urban Residential | B19: coal (BTU) | C19: Lighting | D19: 0 | E19: 0 | F19: 0 | G19: 0 | H19: 0 | I19: 0 | J19: 0 | K19: 0 | L19: 0 | M19: 0 | N19: 0 | O19: 0 | P19: 0 | Q19: 0 | R19: 0 | S19: 0 | T19: 0 | U19: 0 | V19: 0 | W19: 0 | X19: 0 | Y19: 0 | Z19: 0 | AA19: 0 | AB19: 0 | AC19: 0 | AD19: 0
... A21: Urban Residential | B21: coal (BTU) | C21: Other | D21: 0 | E21: 0 | F21: 0 | G21: 0 | H21: 0 | I21: 0 | J21: 0 | K21: 0 | L21: 0 | M21: 0 | N21: 0 | O21: 0 | P21: 0 | Q21: 0 | R21: 0 | S21: 0 | T21: 0 | U21: 0 | V21: 0 | W21: 0 | X21: 0 | Y21: 0 | Z21: 0 | AA21: 0 | AB21: 0 | AC21: 0 | AD21: 0
A22: Rural Residential | B22: coal (BTU) | C22: Heating | D22: 0 | E22: 0 | F22: 0 | G22: 0 | H22: 0 | I22: 0 | J22: 0 | K22: 0 | L22: 0 | M22: 0 | N22: 0 | O22: 0 | P22: 0 | Q22: 0 | R22: 0 | S22: 0 | T22: 0 | U22: 0 | V22: 0 | W22: 0 | X22: 0 | Y22: 0 | Z22: 0 | AA22: 0 | AB22: 0 | AC22: 0
A23: Rural Residential | B23: coal (BTU) | C23: cooling & ventilation | D23: 0 | E23: 0 | F23: 0 | G23: 0 | H23: 0 | I23: 0 | J23: 0 | K23: 0 | L23: 0 | M23: 0 | N23: 0 | O23: 0 | P23: 0 | Q23: 0 | R23: 0 | S23: 0 | T23: 0 | U23: 0 | V23: 0 | W23: 0 | X23: 0 | Y23: 0 | Z23: 0 | AA23: 0 | AB23: 0 | AC23: 0 | AD23: 0
A24: Rural Residential | B24: coal (BTU) | C24: Lighting | D24: 0 | E24: 0 | F24: 0 | G24: 0 | H24: 0 | I24: 0 | J24: 0 | K24: 0 | L24: 0 | M24: 0 | N24: 0 | O24: 0 | P24: 0 | Q24: 0 | R24: 0 | S24: 0 | T24: 0 | U24: 0 | V24: 0 | W24: 0 | X24: 0 | Y24: 0 | Z24: 0 | AA24: 0 | AB24: 0 | AC24: 0 | AD24: 0
A25: Rural Residential | B25: coal (BTU) | C25: Appliances | D25: 0 | E25: 0 | F25: 0 | G25: 0 | H25: 0 | I25: 0 | J25: 0 | K25: 0 | L25: 0 | M25: 0 | N25: 0 | O25: 0 | P25: 0 | Q25: 0 | R25: 0 | S25: 0 | T25: 0 | U25: 0 | V25: 0 | W25: 0 | X25: 0 | Y25: 0 | Z25: 0 | AA25: 0 | AB25: 0 | AC25: 0 | AD25: 0
A26: Rural Residential | B26: coal (BTU) | C26: Other | D26: 0 | E26: 0 | F26: 0 | G26: 0 | H26: 0 | I26: 0 | J26: 0 | K26: 0 | L26: 0 | M26: 0 | N26: 0 | O26: 0 | P26: 0 | Q26: 0 | R26: 0 | S26: 0 | T26: 0 | U26: 0 | V26: 0 | W26: 0 | X26: 0 | Y26: 0 | Z26: 0 | AA26: 0 | AB26: 0 | AC26: 0 | AD26: 0
A27: Commercial | B27: coal (BTU) | C27: Heating | D27: 0 | E27: 0 | F27: 0 | G27: 0 | H27: 0 | I27: 0 | J27: 0 | K27: 0 | L27: 0 | M27: 0 | N27: 0 | O27: 0 | P27: 0 | Q27: 0 | R27: 0 | S27: 0 | T27: 0 | U27: 0 | V27: 0 | W27: 0 | X27: 0 | Y27: 0 | Z27: 0 | AA27: 0 | AB27: 0 | AC27: 0 | AD27: 0
A28: Commercial | B28: coal (BTU) | C28: cooling & ventilation | D28: 0 | E28: 0 | F28: 0 | G28: 0 | H28: 0 | I28: 0 | J28: 0 | K28: 0 | L28: 0 | M28: 0 | N28: 0 | O28: 0 | P28: 0 | Q28: 0 | R28: 0 | S28: 0 | T28: 0 | U28: 0 | V28: 0 | W28: 0 | X28: 0 | Y28: 0 | Z28: 0 | AA28: 0 | AB28: 0 | AC28: 0 | AD28: 0
A29: Commercial | B29: coal (BTU) | C29: Lighting | D29: 0 | E29: 0 | F29: 0 | G29: 0 | H29: 0 | I29: 0 | J29: 0 | K29: 0 | L29: 0 | M29: 0 | N29: 0 | O29: 0 | P29: 0 | Q29: 0 | R29: 0 | S29: 0 | T29: 0 | U29: 0 | V29: 0 | W29: 0 | X29: 0 | Y29: 0 | Z29: 0 | AA29: 0 | AB29: 0 | AC29: 0 | AD29: 0
A30: Commercial | B30: coal (BTU) | C30: Appliances | D30: 0 | E30: 0 | F30: 0 | G30: 0 | H30: 0 | I30: 0 | J30: 0 | K30: 0 | L30: 0 | M30: 0 | N30: 0 | O30: 0 | P30: 0 | Q30: 0 | R30: 0 | S30: 0 | T30: 0 | U30: 0 | V30: 0 | W30: 0 | X30: 0 | Y30: 0 | Z30: 0 | AA30: 0 | AB30: 0 | AC30: 0 | AD30: 0
A31: Commercial | B31: coal (BTU) | C31: Other | D31: 0 | E31: 0 | F31: 0 | G31: 0 | H31: 0 | I31: 0 | J31: 0 | K31: 0 | L31: 0 | M31: 0 | N31: 0 | O31: 0 | P31: 0 | Q31: 0 | R31: 0 | S31: 0 | T31: 0 | U31: 0 | V31: 0 | W31: 0 | X31: 0 | Y31: 0 | Z31: 0 | AA31: 0 | AB31: 0 | AC31: 0 | AD31: 0
A32: Urban Residential | B32: natural gas (BTU) | C32: Heating | D32: 0 | E32: 0 | F32: 0 | G32: 0 | H32: 0 | I32: 0 | J32: 0 | K32: 0 | L32: 0 | M32: 0 | N32: 0 | O32: 0 | P32: 0 | Q32: 0 | R32: 0 | S32: 0 | T32: 0 | U32: 0 | V32: 0 | W32: 0 | X32: 0 | Y32: 0 | Z32: 0 | AA32: 0 | AB32: 0 | AC32: 0 | AD32: 0
A33: Urban Residential | B33: natural gas (BTU) | C33: cooling & ventilation | D33: 0 | E33: 0 | F33: 0 | G33: 0 | H33: 0 | I33: 0 | J33: 0 | K33: 0 | L33: 0 | M33: 0 | N33: 0 | O33: 0 | P33: 0 | Q33: 0 | R33: 0 | S33: 0 | T33: 0 | U33: 0 | V33: 0 | W33: 0 | X33: 0 | Y33: 0 | Z33: 0 | AA33: 0 | AB33: 0 | AC33: 0 | AD33: 0
A34: Urban Residential | B34: natural gas (BTU) | C34: Lighting | D34: 0 | E34: 0 | F34: 0 | G34: 0 | H34: 0 | I34: 0 | J34: 0 | K34: 0 | L34: 0 | M34: 0 | N34: 0 | O34: 0 | P34: 0 | Q34: 0 | R34: 0 | S34: 0 | T34: 0 | U34: 0 | V34: 0 | W34: 0 | X34: 0 | Y34: 0 | Z34: 0 | AA34: 0 | AB34: 0 | AC34: 0 | AD34: 0
... A36: Urban Residential | B36: natural gas (BTU) | C36: Other | D36: 0 | E36: 0 | F36: 0 | G36: 0 | H36: 0 | I36: 0 | J36: 0 | K36: 0 | L36: 0 | M36: 0 | N36: 0 | O36: 0 | P36: 0 | Q36: 0 | R36: 0 | S36: 0 | T36: 0 | U36: 0 | V36: 0 | W36: 0 | X36: 0 | Y36: 0 | Z36: 0 | AA36: 0 | AB36: 0 | AC36: 0 | AD36: 0
A37: Rural Residential | B37: natural gas (BTU) | C37: Heating | D37: 0 | E37: 0 | F37: 0 | G37: 0 | H37: 0 | I37: 0 | J37: 0 | K37: 0 | L37: 0 | M37: 0 | N37: 0 | O37: 0 | P37: 0 | Q37: 0 | R37: 0 | S37: 0 | T37: 0 | U37: 0 | V37: 0 | W37: 0 | X37: 0 | Y37: 0 | Z37: 0 | AA37: 0 | AB37: 0 | AC37: 0
A38: Rural Residential | B38: natural gas (BTU) | C38: cooling & ventilation | D38: 0 | E38: 0 | F38: 0 | G38: 0 | H38: 0 | I38: 0 | J38: 0 | K38: 0 | L38: 0 | M38: 0 | N38: 0 | O38: 0 | P38: 0 | Q38: 0 | R38: 0 | S38: 0 | T38: 0 | U38: 0 | V38: 0 | W38: 0 | X38: 0 | Y38: 0 | Z38: 0 | AA38: 0 | AB38: 0 | AC38: 0 | AD38: 0
A39: Rural Residential | B39: natural gas (BTU) | C39: Lighting | D39: 0 | E39: 0 | F39: 0 | G39: 0 | H39: 0 | I39: 0 | J39: 0 | K39: 0 | L39: 0 | M39: 0 | N39: 0 | O39: 0 | P39: 0 | Q39: 0 | R39: 0 | S39: 0 | T39: 0 | U39: 0 | V39: 0 | W39: 0 | X39: 0 | Y39: 0 | Z39: 0 | AA39: 0 | AB39: 0 | AC39: 0 | AD39: 0
A40: Rural Residential | B40: natural gas (BTU) | C40: Appliances | D40: 62860000000000 | E40: 66860000000000 | F40: 70140000000000 | G40: 73420000000000 | H40: 76700000000000 | I40: 79980000000000 | J40: 83260000000000 | K40: 88330000000000 | L40: 93400000000000 | M40: 98470000000000 | N40: 103500000000000 | O40: 108600000000000 | P40: 114700000000000 | Q40: 120800000000000 | R40: 126900000000000 | S40: 133000000000000 | T40: 139100000000000 | U40: 143500000000000 | V40: 147900000000000 | W40: 152200000000000 | X40: 156600000000000 | Y40: 160900000000000 | Z40: 164900000000000 | AA40: 168900000000000 | AB40: 172900000000000 | AC40: 176900000000000 | AD40: 180900000000000
A41: Rural Residential | B41: natural gas (BTU) | C41: Other | D41: 0 | E41: 0 | F41: 0 | G41: 0 | H41: 0 | I41: 0 | J41: 0 | K41: 0 | L41: 0 | M41: 0 | N41: 0 | O41: 0 | P41: 0 | Q41: 0 | R41: 0 | S41: 0 | T41: 0 | U41: 0 | V41: 0 | W41: 0 | X41: 0 | Y41: 0 | Z41: 0 | AA41: 0 | AB41: 0 | AC41: 0 | AD41: 0
A42: Commercial | B42: natural gas (BTU) | C42: Heating | D42: 0 | E42: 0 | F42: 0 | G42: 0 | H42: 0 | I42: 0 | J42: 0 | K42: 0 | L42: 0 | M42: 0 | N42: 0 | O42: 0 | P42: 0 | Q42: 0 | R42: 0 | S42: 0 | T42: 0 | U42: 0 | V42: 0 | W42: 0 | X42: 0 | Y42: 0 | Z42: 0 | AA42: 0 | AB42: 0 | AC42: 0 | AD42: 0
...

Sheet SYCEU-urban-residential
A1: Year | B1: heating | C1: cooling & ventilation | D1: envelope | E1: lighting | F1: appliances | G1: other
A2: electricity (BTU) | B2: =SUMIFS(INDEX('Calculations - from BCEU'!$D$2:$AK$151,,MATCH(About!$A$41,'Calculations - from BCEU'!$D$1:$AK$1,0)),'Calculations - from BCEU'!$A$2:$A$151,"Urban Residential",'Calculations - from BCEU'!$C$2:$C$151,B$1,'Calculations - from BCEU'!$B$2:$B$151,$A2) -> 0 | C2: =SUMIFS(INDEX('Calculations - from BCEU'!$D$2:$AK$151,,MATCH(About!$A$41,'Calculations - from BCEU'!$D$1:$AK$1,0)),'Calculations - from BCEU'!$A$2:$A$151,"Urban Residential",'Calculations - from BCEU'!$C$2:$C$151,C$1,'Calculations - from BCEU'!$B$2:$B$151,$A2) -> 153000000000000 | D2: =SUMIFS(INDEX('Calculations - from BCEU'!$D$2:$AK$151,,MATCH(About!$A$41,'Calculations - from BCEU'!$D$1:$AK$1,0)),'Calculations - from BCEU'!$A$2:$A$151,"Urban Residential",'Calculations - from BCEU'!$C$2:$C$151,D$1,'Calculations - from BCEU'!$B$2:$B$151,$A2) -> 0 | E2: =SUMIFS(INDEX('Calculations - from BCEU'!$D$2:$AK$151,,MATCH(About!$A$41,'Calculations - from BCEU'!$D$1:$AK$1,0)),'Calculations - from BCEU'!$A$2:$A$151,"Urban Residential",'Calculations - from BCEU'!$C$2:$C$151,E$1,'Calculations - from BCEU'!$B$2:$B$151,$A2) -> 57700000000000 | F2: =SUMIFS(INDEX('Calculations - from BCEU'!$D$2:$AK$151,,MATCH(About!$A$41,'Calculations - from BCEU'!$D$1:$AK$1,0)),'Calculations - from BCEU'!$A$2:$A$151,"Urban Residential",'Calculations - from BCEU'!$C$2:$C$151,F$1,'Calculations - from BCEU'!$B$2:$B$151,$A2) -> 198000000000000 | G2: =SUMIFS(INDEX('Calculations - from BCEU'!$D$2:$AK$151,,MATCH(About!$A$41,'Calculations - from BCEU'!$D$1:$AK$1,0)),'Calculations - from BCEU'!$A$2:$A$151,"Urban Residential",'Calculations - from BCEU'!$C$2:$C$151,G$1,'Calculations - from BCEU'!$B$2:$B$151,$A2) -> 33500000000000
A3: coal (BTU) | B3: =SUMIFS(INDEX('Calculations - from BCEU'!$D$2:$AK$151,,MATCH(About!$A$41,'Calculations - from BCEU'!$D$1:$AK$1,0)),'Calculations - from BCEU'!$A$2:$A$151,"Urban Residential",'Calculations - from BCEU'!$C$2:$C$151,B$1,'Calculations - from BCEU'!$B$2:$B$151,$A3) -> 0 | C3: =SUMIFS(INDEX('Calculations - from BCEU'!$D$2:$AK$151,,MATCH(About!$A$41,'Calculations - from BCEU'!$D$1:$AK$1,0)),'Calculations - from BCEU'!$A$2:$A$151,"Urban Residential",'Calculations - from BCEU'!$C$2:$C$151,C$1,'Calculations - from BCEU'!$B$2:$B$151,$A3) -> 0 | D3: =SUMIFS(INDEX('Calculations - from BCEU'!$D$2:$AK$151,,MATCH(About!$A$41,'Calculations - from BCEU'!$D$1:$AK$1,0)),'Calculations - from BCEU'!$A$2:$A$151,"Urban Residential",'Calculations - from BCEU'!$C$2:$C$151,D$1,'Calculations - from BCEU'!$B$2:$B$151,$A3) -> 0 | E3: =SUMIFS(INDEX('Calculations - from BCEU'!$D$2:$AK$151,,MATCH(About!$A$41,'Calculations - from BCEU'!$D$1:$AK$1,0)),'Calculations - from BCEU'!$A$2:$A$151,"Urban Residential",'Calculations - from BCEU'!$C$2:$C$151,E$1,'Calculations - from BCEU'!$B$2:$B$151,$A3) -> 0 | F3: =SUMIFS(INDEX('Calculations - from BCEU'!$D$2:$AK$151,,MATCH(About!$A$41,'Calculations - from BCEU'!$D$1:$AK$1,0)),'Calculations - from BCEU'!$A$2:$A$151,"Urban Residential",'Calculations - from BCEU'!$C$2:$C$151,F$1,'Calculations - from BCEU'!$B$2:$B$151,$A3) -> 0 | G3: =SUMIFS(INDEX('Calculations - from BCEU'!$D$2:$AK$151,,MATCH(About!$A$41,'Calculations - from BCEU'!$D$1:$AK$1,0)),'Calculations - from BCEU'!$A$2:$A$151,"Urban Residential",'Calculations - from BCEU'!$C$2:$C$151,G$1,'Calculations - from BCEU'!$B$2:$B$151,$A3) -> 0
A4: natural gas (BTU) | B4: =SUMIFS(INDEX('Calculations - from BCEU'!$D$2:$AK$151,,MATCH(About!$A$41,'Calculations - from BCEU'!$D$1:$AK$1,0)),'Calculations - from BCEU'!$A$2:$A$151,"Urban Residential",'Calculations - from BCEU'!$C$2:$C$151,B$1,'Calculations - from BCEU'!$B$2:$B$151,$A4) -> 0 | C4: =SUMIFS(INDEX('Calculations - from BCEU'!$D$2:$AK$151,,MATCH(About!$A$41,'Calculations - from BCEU'!$D$1:$AK$1,0)),'Calculations - from BCEU'!$A$2:$A$151,"Urban Residential",'Calculations - from BCEU'!$C$2:$C$151,C$1,'Calculations - from BCEU'!$B$2:$B$151,$A4) -> 0 | D4: =SUMIFS(INDEX('Calculations - from BCEU'!$D$2:$AK$151,,MATCH(About!$A$41,'Calculations - from BCEU'!$D$1:$AK$1,0)),'Calculations - from BCEU'!$A$2:$A$151,"Urban Residential",'Calculations - from BCEU'!$C$2:$C$151,D$1,'Calculations - from BCEU'!$B$2:$B$151,$A4) -> 0 | E4: =SUMIFS(INDEX('Calculations - from BCEU'!$D$2:$AK$151,,MATCH(About!$A$41,'Calculations - from BCEU'!$D$1:$AK$1,0)),'Calculations - from BCEU'!$A$2:$A$151,"Urban Residential",'Calculations - from BCEU'!$C$2:$C$151,E$1,'Calculations - from BCEU'!$B$2:$B$151,$A4) -> 0 | F4: =SUMIFS(INDEX('Calculations - from BCEU'!$D$2:$AK$151,,MATCH(About!$A$41,'Calculations - from BCEU'!$D$1:$AK$1,0)),'Calculations - from BCEU'!$A$2:$A$151,"Urban Residential",'Calculations - from BCEU'!$C$2:$C$151,F$1,'Calculations - from BCEU'!$B$2:$B$151,$A4) -> 123167000000000 | G4: =SUMIFS(INDEX('Calculations - from BCEU'!$D$2:$AK$151,,MATCH(About!$A$41,'Calculations - from BCEU'!$D$1:$AK$1,0)),'Calculations - from BCEU'!$A$2:$A$151,"Urban Residential",'Calculations - from BCEU'!$C$2:$C$151,G$1,'Calculations - from BCEU'!$B$2:$B$151,$A4) -> 0
A5: petroleum diesel (BTU) | B5: =SUMIFS(INDEX('Calculations - from BCEU'!$D$2:$AK$151,,MATCH(About!$A$41,'Calculations - from BCEU'!$D$1:$AK$1,0)),'Calculations - from BCEU'!$A$2:$A$151,"Urban Residential",'Calculations - from BCEU'!$C$2:$C$151,B$1,'Calculations - from BCEU'!$B$2:$B$151,$A5) -> 0 | C5: =SUMIFS(INDEX('Calculations - from BCEU'!$D$2:$AK$151,,MATCH(About!$A$41,'Calculations - from BCEU'!$D$1:$AK$1,0)),'Calculations - from BCEU'!$A$2:$A$151,"Urban Residential",'Calculations - from BCEU'!$C$2:$C$151,C$1,'Calculations - from BCEU'!$B$2:$B$151,$A5) -> 0 | D5: =SUMIFS(INDEX('Calculations - from BCEU'!$D$2:$AK$151,,MATCH(About!$A$41,'Calculations - from BCEU'!$D$1:$AK$1,0)),'Calculations - from BCEU'!$A$2:$A$151,"Urban Residential",'Calculations - from BCEU'!$C$2:$C$151,D$1,'Calculations - from BCEU'!$B$2:$B$151,$A5) -> 0 | E5: =SUMIFS(INDEX('Calculations - from BCEU'!$D$2:$AK$151,,MATCH(About!$A$41,'Calculations - from BCEU'!$D$1:$AK$1,0)),'Calculations - from BCEU'!$A$2:$A$151,"Urban Residential",'Calculations - from BCEU'!$C$2:$C$151,E$1,'Calculations - from BCEU'!$B$2:$B$151,$A5) -> 0 | F5: =SUMIFS(INDEX('Calculations - from BCEU'!$D$2:$AK$151,,MATCH(About!$A$41,'Calculations - from BCEU'!$D$1:$AK$1,0)),'Calculations - from BCEU'!$A$2:$A$151,"Urban Residential",'Calculations - from BCEU'!$C$2:$C$151,F$1,'Calculations - from BCEU'!$B$2:$B$151,$A5) -> 0 | G5: =SUMIFS(INDEX('Calculations - from BCEU'!$D$2:$AK$151,,MATCH(About!$A$41,'Calculations - from BCEU'!$D$1:$AK$1,0)),'Calculations - from BCEU'!$A$2:$A$151,"Urban Residential",'Calculations - from BCEU'!$C$2:$C$151,G$1,'Calculations - from BCEU'!$B$2:$B$151,$A5) -> 0
A6: heat (BTU) | B6: =SUMIFS(INDEX('Calculations - from BCEU'!$D$2:$AK$151,,MATCH(About!$A$41,'Calculations - from BCEU'!$D$1:$AK$1,0)),'Calculations - from BCEU'!$A$2:$A$151,"Urban Residential",'Calculations - from BCEU'!$C$2:$C$151,B$1,'Calculations - from BCEU'!$B$2:$B$151,$A6) -> 0 | C6: =SUMIFS(INDEX('Calculations - from BCEU'!$D$2:$AK$151,,MATCH(About!$A$41,'Calculations - from BCEU'!$D$1:$AK$1,0)),'Calculations - from BCEU'!$A$2:$A$151,"Urban Residential",'Calculations - from BCEU'!$C$2:$C$151,C$1,'Calculations - from BCEU'!$B$2:$B$151,$A6) -> 0 | D6: =SUMIFS(INDEX('Calculations - from BCEU'!$D$2:$AK$151,,MATCH(About!$A$41,'Calculations - from BCEU'!$D$1:$AK$1,0)),'Calculations - from BCEU'!$A$2:$A$151,"Urban Residential",'Calculations - from BCEU'!$C$2:$C$151,D$1,'Calculations - from BCEU'!$B$2:$B$151,$A6) -> 0 | E6: =SUMIFS(INDEX('Calculations - from BCEU'!$D$2:$AK$151,,MATCH(About!$A$41,'Calculations - from BCEU'!$D$1:$AK$1,0)),'Calculations - from BCEU'!$A$2:$A$151,"Urban Residential",'Calculations - from BCEU'!$C$2:$C$151,E$1,'Calculations - from BCEU'!$B$2:$B$151,$A6) -> 0 | F6: =SUMIFS(INDEX('Calculations - from BCEU'!$D$2:$AK$151,,MATCH(About!$A$41,'Calculations - from BCEU'!$D$1:$AK$1,0)),'Calculations - from BCEU'!$A$2:$A$151,"Urban Residential",'Calculations - from BCEU'!$C$2:$C$151,F$1,'Calculations - from BCEU'!$B$2:$B$151,$A6) -> 0 | G6: =SUMIFS(INDEX('Calculations - from BCEU'!$D$2:$AK$151,,MATCH(About!$A$41,'Calculations - from BCEU'!$D$1:$AK$1,0)),'Calculations - from BCEU'!$A$2:$A$151,"Urban Residential",'Calculations - from BCEU'!$C$2:$C$151,G$1,'Calculations - from BCEU'!$B$2:$B$151,$A6) -> 0
A7: biomass (BTU) | B7: =SUMIFS(INDEX('Calculations - from BCEU'!$D$2:$AK$151,,MATCH(About!$A$41,'Calculations - from BCEU'!$D$1:$AK$1,0)),'Calculations - from BCEU'!$A$2:$A$151,"Urban Residential",'Calculations - from BCEU'!$C$2:$C$151,B$1,'Calculations - from BCEU'!$B$2:$B$151,$A7) -> 0 | C7: =SUMIFS(INDEX('Calculations - from BCEU'!$D$2:$AK$151,,MATCH(About!$A$41,'Calculations - from BCEU'!$D$1:$AK$1,0)),'Calculations - from BCEU'!$A$2:$A$151,"Urban Residential",'Calculations - from BCEU'!$C$2:$C$151,C$1,'Calculations - from BCEU'!$B$2:$B$151,$A7) -> 0 | D7: =SUMIFS(INDEX('Calculations - from BCEU'!$D$2:$AK$151,,MATCH(About!$A$41,'Calculations - from BCEU'!$D$1:$AK$1,0)),'Calculations - from BCEU'!$A$2:$A$151,"Urban Residential",'Calculations - from BCEU'!$C$2:$C$151,D$1,'Calculations - from BCEU'!$B$2:$B$151,$A7) -> 0 | E7: =SUMIFS(INDEX('Calculations - from BCEU'!$D$2:$AK$151,,MATCH(About!$A$41,'Calculations - from BCEU'!$D$1:$AK$1,0)),'Calculations - from BCEU'!$A$2:$A$151,"Urban Residential",'Calculations - from BCEU'!$C$2:$C$151,E$1,'Calculations - from BCEU'!$B$2:$B$151,$A7) -> 0 | F7: =SUMIFS(INDEX('Calculations - from BCEU'!$D$2:$AK$151,,MATCH(About!$A$41,'Calculations - from BCEU'!$D$1:$AK$1,0)),'Calculations - from BCEU'!$A$2:$A$151,"Urban Residential",'Calculations - from BCEU'!$C$2:$C$151,F$1,'Calculations - from BCEU'!$B$2:$B$151,$A7) -> 286512000000000 | G7: =SUMIFS(INDEX('Calculations - from BCEU'!$D$2:$AK$151,,MATCH(About!$A$41,'Calculations - from BCEU'!$D$1:$AK$1,0)),'Calculations - from BCEU'!$A$2:$A$151,"Urban Residential",'Calculations - from BCEU'!$C$2:$C$151,G$1,'Calculations - from BCEU'!$B$2:$B$151,$A7) -> 0
A8: kerosene (BTU) | B8: =SUMIFS(INDEX('Calculations - from BCEU'!$D$2:$AK$151,,MATCH(About!$A$41,'Calculations - from BCEU'!$D$1:$AK$1,0)),'Calculations - from BCEU'!$A$2:$A$151,"Urban Residential",'Calculations - from BCEU'!$C$2:$C$151,B$1,'Calculations - from BCEU'!$B$2:$B$151,$A8) -> 0 | C8: =SUMIFS(INDEX('Calculations - from BCEU'!$D$2:$AK$151,,MATCH(About!$A$41,'Calculations - from BCEU'!$D$1:$AK$1,0)),'Calculations - from BCEU'!$A$2:$A$151,"Urban Residential",'Calculations - from BCEU'!$C$2:$C$151,C$1,'Calculations - from BCEU'!$B$2:$B$151,$A8) -> 0 | D8: =SUMIFS(INDEX('Calculations - from BCEU'!$D$2:$AK$151,,MATCH(About!$A$41,'Calculations - from BCEU'!$D$1:$AK$1,0)),'Calculations - from BCEU'!$A$2:$A$151,"Urban Residential",'Calculations - from BCEU'!$C$2:$C$151,D$1,'Calculations - from BCEU'!$B$2:$B$151,$A8) -> 0 | E8: =SUMIFS(INDEX('Calculations - from BCEU'!$D$2:$AK$151,,MATCH(About!$A$41,'Calculations - from BCEU'!$D$1:$AK$1,0)),'Calculations - from BCEU'!$A$2:$A$151,"Urban Residential",'Calculations - from BCEU'!$C$2:$C$151,E$1,'Calculations - from BCEU'!$B$2:$B$151,$A8) -> 0 | F8: =SUMIFS(INDEX('Calculations - from BCEU'!$D$2:$AK$151,,MATCH(About!$A$41,'Calculations - from BCEU'!$D$1:$AK$1,0)),'Calculations - from BCEU'!$A$2:$A$151,"Urban Residential",'Calculations - from BCEU'!$C$2:$C$151,F$1,'Calculations - from BCEU'!$B$2:$B$151,$A8) -> 0 | G8: =SUMIFS(INDEX('Calculations - from BCEU'!$D$2:$AK$151,,MATCH(About!$A$41,'Calculations - from BCEU'!$D$1:$AK$1,0)),'Calculations - from BCEU'!$A$2:$A$151,"Urban Residential",'Calculations - from BCEU'!$C$2:$C$151,G$1,'Calculations - from BCEU'!$B$2:$B$151,$A8) -> 0
A9: heavy or residual fuel oil (BTU) | B9: =SUMIFS(INDEX('Calculations - from BCEU'!$D$2:$AK$151,,MATCH(About!$A$41,'Calculations - from BCEU'!$D$1:$AK$1,0)),'Calculations - from BCEU'!$A$2:$A$151,"Urban Residential",'Calculations - from BCEU'!$C$2:$C$151,B$1,'Calculations - from BCEU'!$B$2:$B$151,$A9) -> 0 | C9: =SUMIFS(INDEX('Calculations - from BCEU'!$D$2:$AK$151,,MATCH(About!$A$41,'Calculations - from BCEU'!$D$1:$AK$1,0)),'Calculations - from BCEU'!$A$2:$A$151,"Urban Residential",'Calculations - from BCEU'!$C$2:$C$151,C$1,'Calculations - from BCEU'!$B$2:$B$151,$A9) -> 0 | D9: =SUMIFS(INDEX('Calculations - from BCEU'!$D$2:$AK$151,,MATCH(About!$A$41,'Calculations - from BCEU'!$D$1:$AK$1,0)),'Calculations - from BCEU'!$A$2:$A$151,"Urban Residential",'Calculations - from BCEU'!$C$2:$C$151,D$1,'Calculations - from BCEU'!$B$2:$B$151,$A9) -> 0 | E9: =SUMIFS(INDEX('Calculations - from BCEU'!$D$2:$AK$151,,MATCH(About!$A$41,'Calculations - from BCEU'!$D$1:$AK$1,0)),'Calculations - from BCEU'!$A$2:$A$151,"Urban Residential",'Calculations - from BCEU'!$C$2:$C$151,E$1,'Calculations - from BCEU'!$B$2:$B$151,$A9) -> 0 | F9: =SUMIFS(INDEX('Calculations - from BCEU'!$D$2:$AK$151,,MATCH(About!$A$41,'Calculations - from BCEU'!$D$1:$AK$1,0)),'Calculations - from BCEU'!$A$2:$A$151,"Urban Residential",'Calculations - from BCEU'!$C$2:$C$151,F$1,'Calculations - from BCEU'!$B$2:$B$151,$A9) -> 0 | G9: =SUMIFS(INDEX('Calculations - from BCEU'!$D$2:$AK$151,,MATCH(About!$A$41,'Calculations - from BCEU'!$D$1:$AK$1,0)),'Calculations - from BCEU'!$A$2:$A$151,"Urban Residential",'Calculations - from BCEU'!$C$2:$C$151,G$1,'Calculations - from BCEU'!$B$2:$B$151,$A9) -> 0
A10: LPG propane or butane (BTU) | B10: =SUMIFS(INDEX('Calculations - from BCEU'!$D$2:$AK$151,,MATCH(About!$A$41,'Calculations - from BCEU'!$D$1:$AK$1,0)),'Calculations - from BCEU'!$A$2:$A$151,"Urban Residential",'Calculations - from BCEU'!$C$2:$C$151,B$1,'Calculations - from BCEU'!$B$2:$B$151,$A10) -> 0 | C10: =SUMIFS(INDEX('Calculations - from BCEU'!$D$2:$AK$151,,MATCH(About!$A$41,'Calculations - from BCEU'!$D$1:$AK$1,0)),'Calculations - from BCEU'!$A$2:$A$151,"Urban Residential",'Calculations - from BCEU'!$C$2:$C$151,C$1,'Calculations - from BCEU'!$B$2:$B$151,$A10) -> 0 | D10: =SUMIFS(INDEX('Calculations - from BCEU'!$D$2:$AK$151,,MATCH(About!$A$41,'Calculations - from BCEU'!$D$1:$AK$1,0)),'Calculations - from BCEU'!$A$2:$A$151,"Urban Residential",'Calculations - from BCEU'!$C$2:$C$151,D$1,'Calculations - from BCEU'!$B$2:$B$151,$A10) -> 0 | E10: =SUMIFS(INDEX('Calculations - from BCEU'!$D$2:$AK$151,,MATCH(About!$A$41,'Calculations - from BCEU'!$D$1:$AK$1,0)),'Calculations - from BCEU'!$A$2:$A$151,"Urban Residential",'Calculations - from BCEU'!$C$2:$C$151,E$1,'Calculations - from BCEU'!$B$2:$B$151,$A10) -> 0 | F10: =SUMIFS(INDEX('Calculations - from BCEU'!$D$2:$AK$151,,MATCH(About!$A$41,'Calculations - from BCEU'!$D$1:$AK$1,0)),'Calculations - from BCEU'!$A$2:$A$151,"Urban Residential",'Calculations - from BCEU'!$C$2:$C$151,F$1,'Calculations - from BCEU'!$B$2:$B$151,$A10) -> 601471000000000 | G10: =SUMIFS(INDEX('Calculations - from BCEU'!$D$2:$AK$151,,MATCH(About!$A$41,'Calculations - from BCEU'!$D$1:$AK$1,0)),'Calculations - from BCEU'!$A$2:$A$151,"Urban Residential",'Calculations - from BCEU'!$C$2:$C$151,G$1,'Calculations - from BCEU'!$B$2:$B$151,$A10) -> 0
A11: hydrogen (BTU) | B11: =SUMIFS(INDEX('Calculations - from BCEU'!$D$2:$AK$151,,MATCH(About!$A$41,'Calculations - from BCEU'!$D$1:$AK$1,0)),'Calculations - from BCEU'!$A$2:$A$151,"Urban Residential",'Calculations - from BCEU'!$C$2:$C$151,B$1,'Calculations - from BCEU'!$B$2:$B$151,$A11) -> 0 | C11: =SUMIFS(INDEX('Calculations - from BCEU'!$D$2:$AK$151,,MATCH(About!$A$41,'Calculations - from BCEU'!$D$1:$AK$1,0)),'Calculations - from BCEU'!$A$2:$A$151,"Urban Residential",'Calculations - from BCEU'!$C$2:$C$151,C$1,'Calculations - from BCEU'!$B$2:$B$151,$A11) -> 0 | D11: =SUMIFS(INDEX('Calculations - from BCEU'!$D$2:$AK$151,,MATCH(About!$A$41,'Calculations - from BCEU'!$D$1:$AK$1,0)),'Calculations - from BCEU'!$A$2:$A$151,"Urban Residential",'Calculations - from BCEU'!$C$2:$C$151,D$1,'Calculations - from BCEU'!$B$2:$B$151,$A11) -> 0 | E11: =SUMIFS(INDEX('Calculations - from BCEU'!$D$2:$AK$151,,MATCH(About!$A$41,'Calculations - from BCEU'!$D$1:$AK$1,0)),'Calculations - from BCEU'!$A$2:$A$151,"Urban Residential",'Calculations - from BCEU'!$C$2:$C$151,E$1,'Calculations - from BCEU'!$B$2:$B$151,$A11) -> 0 | F11: =SUMIFS(INDEX('Calculations - from BCEU'!$D$2:$AK$151,,MATCH(About!$A$41,'Calculations - from BCEU'!$D$1:$AK$1,0)),'Calculations - from BCEU'!$A$2:$A$151,"Urban Residential",'Calculations - from BCEU'!$C$2:$C$151,F$1,'Calculations - from BCEU'!$B$2:$B$151,$A11) -> 0 | G11: =SUMIFS(INDEX('Calculations - from BCEU'!$D$2:$AK$151,,MATCH(About!$A$41,'Calculations - from BCEU'!$D$1:$AK$1,0)),'Calculations - from BCEU'!$A$2:$A$151,"Urban Residential",'Calculations - from BCEU'!$C$2:$C$151,G$1,'Calculations - from BCEU'!$B$2:$B$151,$A11) -> 0

Sheet SYCEU-rural-residential
A1: Year | B1: heating | C1: cooling & ventilation | D1: envelope | E1: lighting | F1: appliances | G1: other
A2: electricity (BTU) | B2: =SUMIFS(INDEX('Calculations - from BCEU'!$D$2:$AK$151,,MATCH(About!$A$41,'Calculations - from BCEU'!$D$1:$AK$1,0)),'Calculations - from BCEU'!$A$2:$A$151,"Rural Residential",'Calculations - from BCEU'!$C$2:$C$151,B$1,'Calculations - from BCEU'!$B$2:$B$151,$A2) -> 0 | C2: =SUMIFS(INDEX('Calculations - from BCEU'!$D$2:$AK$151,,MATCH(About!$A$41,'Calculations - from BCEU'!$D$1:$AK$1,0)),'Calculations - from BCEU'!$A$2:$A$151,"Rural Residential",'Calculations - from BCEU'!$C$2:$C$151,C$1,'Calculations - from BCEU'!$B$2:$B$151,$A2) -> 286000000000000 | D2: =SUMIFS(INDEX('Calculations - from BCEU'!$D$2:$AK$151,,MATCH(About!$A$41,'Calculations - from BCEU'!$D$1:$AK$1,0)),'Calculations - from BCEU'!$A$2:$A$151,"Rural Residential",'Calculations - from BCEU'!$C$2:$C$151,D$1,'Calculations - from BCEU'!$B$2:$B$151,$A2) -> 0 | E2: =SUMIFS(INDEX('Calculations - from BCEU'!$D$2:$AK$151,,MATCH(About!$A$41,'Calculations - from BCEU'!$D$1:$AK$1,0)),'Calculations - from BCEU'!$A$2:$A$151,"Rural Residential",'Calculations - from BCEU'!$C$2:$C$151,E$1,'Calculations - from BCEU'!$B$2:$B$151,$A2) -> 108000000000000 | F2: =SUMIFS(INDEX('Calculations - from BCEU'!$D$2:$AK$151,,MATCH(About!$A$41,'Calculations - from BCEU'!$D$1:$AK$1,0)),'Calculations - from BCEU'!$A$2:$A$151,"Rural Residential",'Calculations - from BCEU'!$C$2:$C$151,F$1,'Calculations - from BCEU'!$B$2:$B$151,$A2) -> 424700000000000 | G2: =SUMIFS(INDEX('Calculations - from BCEU'!$D$2:$AK$151,,MATCH(About!$A$41,'Calculations - from BCEU'!$D$1:$AK$1,0)),'Calculations - from BCEU'!$A$2:$A$151,"Rural Residential",'Calculations - from BCEU'!$C$2:$C$151,G$1,'Calculations - from BCEU'!$B$2:$B$151,$A2) -> 33500000000000
A3: coal (BTU) | B3: =SUMIFS(INDEX('Calculations - from BCEU'!$D$2:$AK$151,,MATCH(About!$A$41,'Calculations - from BCEU'!$D$1:$AK$1,0)),'Calculations - from BCEU'!$A$2:$A$151,"Rural Residential",'Calculations - from BCEU'!$C$2:$C$151,B$1,'Calculations - from BCEU'!$B$2:$B$151,$A3) -> 0 | C3: =SUMIFS(INDEX('Calculations - from BCEU'!$D$2:$AK$151,,MATCH(About!$A$41,'Calculations - from BCEU'!$D$1:$AK$1,0)),'Calculations - from BCEU'!$A$2:$A$151,"Rural Residential",'Calculations - from BCEU'!$C$2:$C$151,C$1,'Calculations - from BCEU'!$B$2:$B$151,$A3) -> 0 | D3: =SUMIFS(INDEX('Calculations - from BCEU'!$D$2:$AK$151,,MATCH(About!$A$41,'Calculations - from BCEU'!$D$1:$AK$1,0)),'Calculations - from BCEU'!$A$2:$A$151,"Rural Residential",'Calculations - from BCEU'!$C$2:$C$151,D$1,'Calculations - from BCEU'!$B$2:$B$151,$A3) -> 0 | E3: =SUMIFS(INDEX('Calculations - from BCEU'!$D$2:$AK$151,,MATCH(About!$A$41,'Calculations - from BCEU'!$D$1:$AK$1,0)),'Calculations - from BCEU'!$A$2:$A$151,"Rural Residential",'Calculations - from BCEU'!$C$2:$C$151,E$1,'Calculations - from BCEU'!$B$2:$B$151,$A3) -> 0 | F3: =SUMIFS(INDEX('Calculations - from BCEU'!$D$2:$AK$151,,MATCH(About!$A$41,'Calculations - from BCEU'!$D$1:$AK$1,0)),'Calculations - from BCEU'!$A$2:$A$151,"Rural Residential",'Calculations - from BCEU'!$C$2:$C$151,F$1,'Calculations - from BCEU'!$B$2:$B$151,$A3) -> 0 | G3: =SUMIFS(INDEX('Calculations - from BCEU'!$D$2:$AK$151,,MATCH(About!$A$41,'Calculations - from BCEU'!$D$1:$AK$1,0)),'Calculations - from BCEU'!$A$2:$A$151,"Rural Residential",'Calculations - from BCEU'!$C$2:$C$151,G$1,'Calculations - from BCEU'!$B$2:$B$151,$A3) -> 0
A4: natural gas (BTU) | B4: =SUMIFS(INDEX('Calculations - from BCEU'!$D$2:$AK$151,,MATCH(About!$A$41,'Calculations - from BCEU'!$D$1:$AK$1,0)),'Calculations - from BCEU'!$A$2:$A$151,"Rural Residential",'Calculations - from BCEU'!$C$2:$C$151,B$1,'Calculations - from BCEU'!$B$2:$B$151,$A4) -> 0 | C4: =SUMIFS(INDEX('Calculations - from BCEU'!$D$2:$AK$151,,MATCH(About!$A$41,'Calculations - from BCEU'!$D$1:$AK$1,0)),'Calculations - from BCEU'!$A$2:$A$151,"Rural Residential",'Calculations - from BCEU'!$C$2:$C$151,C$1,'Calculations - from BCEU'!$B$2:$B$151,$A4) -> 0 | D4: =SUMIFS(INDEX('Calculations - from BCEU'!$D$2:$AK$151,,MATCH(About!$A$41,'Calculations - from BCEU'!$D$1:$AK$1,0)),'Calculations - from BCEU'!$A$2:$A$151,"Rural Residential",'Calculations - from BCEU'!$C$2:$C$151,D$1,'Calculations - from BCEU'!$B$2:$B$151,$A4) -> 0 | E4: =SUMIFS(INDEX('Calculations - from BCEU'!$D$2:$AK$151,,MATCH(About!$A$41,'Calculations - from BCEU'!$D$1:$AK$1,0)),'Calculations - from BCEU'!$A$2:$A$151,"Rural Residential",'Calculations - from BCEU'!$C$2:$C$151,E$1,'Calculations - from BCEU'!$B$2:$B$151,$A4) -> 0 | F4: =SUMIFS(INDEX('Calculations - from BCEU'!$D$2:$AK$151,,MATCH(About!$A$41,'Calculations - from BCEU'!$D$1:$AK$1,0)),'Calculations - from BCEU'!$A$2:$A$151,"Rural Residential",'Calculations - from BCEU'!$C$2:$C$151,F$1,'Calculations - from BCEU'!$B$2:$B$151,$A4) -> 66860000000000 | G4: =SUMIFS(INDEX('Calculations - from BCEU'!$D$2:$AK$151,,MATCH(About!$A$41,'Calculations - from BCEU'!$D$1:$AK$1,0)),'Calculations - from BCEU'!$A$2:$A$151,"Rural Residential",'Calculations - from BCEU'!$C$2:$C$151,G$1,'Calculations - from BCEU'!$B$2:$B$151,$A4) -> 0
A5: petroleum diesel (BTU) | B5: =SUMIFS(INDEX('Calculations - from BCEU'!$D$2:$AK$151,,MATCH(About!$A$41,'Calculations - from BCEU'!$D$1:$AK$1,0)),'Calculations - from BCEU'!$A$2:$A$151,"Rural Residential",'Calculations - from BCEU'!$C$2:$C$151,B$1,'Calculations - from BCEU'!$B$2:$B$151,$A5) -> 0 | C5: =SUMIFS(INDEX('Calculations - from BCEU'!$D$2:$AK$151,,MATCH(About!$A$41,'Calculations - from BCEU'!$D$1:$AK$1,0)),'Calculations - from BCEU'!$A$2:$A$151,"Rural Residential",'Calculations - from BCEU'!$C$2:$C$151,C$1,'Calculations - from BCEU'!$B$2:$B$151,$A5) -> 0 | D5: =SUMIFS(INDEX('Calculations - from BCEU'!$D$2:$AK$151,,MATCH(About!$A$41,'Calculations - from BCEU'!$D$1:$AK$1,0)),'Calculations - from BCEU'!$A$2:$A$151,"Rural Residential",'Calculations - from BCEU'!$C$2:$C$151,D$1,'Calculations - from BCEU'!$B$2:$B$151,$A5) -> 0 | E5: =SUMIFS(INDEX('Calculations - from BCEU'!$D$2:$AK$151,,MATCH(About!$A$41,'Calculations - from BCEU'!$D$1:$AK$1,0)),'Calculations - from BCEU'!$A$2:$A$151,"Rural Residential",'Calculations - from BCEU'!$C$2:$C$151,E$1,'Calculations - from BCEU'!$B$2:$B$151,$A5) -> 0 | F5: =SUMIFS(INDEX('Calculations - from BCEU'!$D$2:$AK$151,,MATCH(About!$A$41,'Calculations - from BCEU'!$D$1:$AK$1,0)),'Calculations - from BCEU'!$A$2:$A$151,"Rural Residential",'Calculations - from BCEU'!$C$2:$C$151,F$1,'Calculations - from BCEU'!$B$2:$B$151,$A5) -> 0 | G5: =SUMIFS(INDEX('Calculations - from BCEU'!$D$2:$AK$151,,MATCH(About!$A$41,'Calculations - from BCEU'!$D$1:$AK$1,0)),'Calculations - from BCEU'!$A$2:$A$151,"Rural Residential",'Calculations - from BCEU'!$C$2:$C$151,G$1,'Calculations - from BCEU'!$B$2:$B$151,$A5) -> 0
A6: heat (BTU) | B6: =SUMIFS(INDEX('Calculations - from BCEU'!$D$2:$AK$151,,MATCH(About!$A$41,'Calculations - from BCEU'!$D$1:$AK$1,0)),'Calculations - from BCEU'!$A$2:$A$151,"Rural Residential",'Calculations - from BCEU'!$C$2:$C$151,B$1,'Calculations - from BCEU'!$B$2:$B$151,$A6) -> 0 | C6: =SUMIFS(INDEX('Calculations - from BCEU'!$D$2:$AK$151,,MATCH(About!$A$41,'Calculations - from BCEU'!$D$1:$AK$1,0)),'Calculations - from BCEU'!$A$2:$A$151,"Rural Residential",'Calculations - from BCEU'!$C$2:$C$151,C$1,'Calculations - from BCEU'!$B$2:$B$151,$A6) -> 0 | D6: =SUMIFS(INDEX('Calculations - from BCEU'!$D$2:$AK$151,,MATCH(About!$A$41,'Calculations - from BCEU'!$D$1:$AK$1,0)),'Calculations - from BCEU'!$A$2:$A$151,"Rural Residential",'Calculations - from BCEU'!$C$2:$C$151,D$1,'Calculations - from BCEU'!$B$2:$B$151,$A6) -> 0 | E6: =SUMIFS(INDEX('Calculations - from BCEU'!$D$2:$AK$151,,MATCH(About!$A$41,'Calculations - from BCEU'!$D$1:$AK$1,0)),'Calculations - from BCEU'!$A$2:$A$151,"Rural Residential",'Calculations - from BCEU'!$C$2:$C$151,E$1,'Calculations - from BCEU'!$B$2:$B$151,$A6) -> 0 | F6: =SUMIFS(INDEX('Calculations - from BCEU'!$D$2:$AK$151,,MATCH(About!$A$41,'Calculations - from BCEU'!$D$1:$AK$1,0)),'Calculations - from BCEU'!$A$2:$A$151,"Rural Residential",'Calculations - from BCEU'!$C$2:$C$151,F$1,'Calculations - from BCEU'!$B$2:$B$151,$A6) -> 0 | G6: =SUMIFS(INDEX('Calculations - from BCEU'!$D$2:$AK$151,,MATCH(About!$A$41,'Calculations - from BCEU'!$D$1:$AK$1,0)),'Calculations - from BCEU'!$A$2:$A$151,"Rural Residential",'Calculations - from BCEU'!$C$2:$C$151,G$1,'Calculations - from BCEU'!$B$2:$B$151,$A6) -> 0
A7: biomass (BTU) | B7: =SUMIFS(INDEX('Calculations - from BCEU'!$D$2:$AK$151,,MATCH(About!$A$41,'Calculations - from BCEU'!$D$1:$AK$1,0)),'Calculations - from BCEU'!$A$2:$A$151,"Rural Residential",'Calculations - from BCEU'!$C$2:$C$151,B$1,'Calculations - from BCEU'!$B$2:$B$151,$A7) -> 0 | C7: =SUMIFS(INDEX('Calculations - from BCEU'!$D$2:$AK$151,,MATCH(About!$A$41,'Calculations - from BCEU'!$D$1:$AK$1,0)),'Calculations - from BCEU'!$A$2:$A$151,"Rural Residential",'Calculations - from BCEU'!$C$2:$C$151,C$1,'Calculations - from BCEU'!$B$2:$B$151,$A7) -> 0 | D7: =SUMIFS(INDEX('Calculations - from BCEU'!$D$2:$AK$151,,MATCH(About!$A$41,'Calculations - from BCEU'!$D$1:$AK$1,0)),'Calculations - from BCEU'!$A$2:$A$151,"Rural Residential",'Calculations - from BCEU'!$C$2:$C$151,D$1,'Calculations - from BCEU'!$B$2:$B$151,$A7) -> 0 | E7: =SUMIFS(INDEX('Calculations - from BCEU'!$D$2:$AK$151,,MATCH(About!$A$41,'Calculations - from BCEU'!$D$1:$AK$1,0)),'Calculations - from BCEU'!$A$2:$A$151,"Rural Residential",'Calculations - from BCEU'!$C$2:$C$151,E$1,'Calculations - from BCEU'!$B$2:$B$151,$A7) -> 0 | F7: =SUMIFS(INDEX('Calculations - from BCEU'!$D$2:$AK$151,,MATCH(About!$A$41,'Calculations - from BCEU'!$D$1:$AK$1,0)),'Calculations - from BCEU'!$A$2:$A$151,"Rural Residential",'Calculations - from BCEU'!$C$2:$C$151,F$1,'Calculations - from BCEU'!$B$2:$B$151,$A7) -> 2.47e+15 | G7: =SUMIFS(INDEX('Calculations - from BCEU'!$D$2:$AK$151,,MATCH(About!$A$41,'Calculations - from BCEU'!$D$1:$AK$1,0)),'Calculations - from BCEU'!$A$2:$A$151,"Rural Residential",'Calculations - from BCEU'!$C$2:$C$151,G$1,'Calculations - from BCEU'!$B$2:$B$151,$A7) -> 0
A8: kerosene (BTU) | B8: =SUMIFS(INDEX('Calculations - from BCEU'!$D$2:$AK$151,,MATCH(About!$A$41,'Calculations - from BCEU'!$D$1:$AK$1,0)),'Calculations - from BCEU'!$A$2:$A$151,"Rural Residential",'Calculations - from BCEU'!$C$2:$C$151,B$1,'Calculations - from BCEU'!$B$2:$B$151,$A8) -> 0 | C8: =SUMIFS(INDEX('Calculations - from BCEU'!$D$2:$AK$151,,MATCH(About!$A$41,'Calculations - from BCEU'!$D$1:$AK$1,0)),'Calculations - from BCEU'!$A$2:$A$151,"Rural Residential",'Calculations - from BCEU'!$C$2:$C$151,C$1,'Calculations - from BCEU'!$B$2:$B$151,$A8) -> 0 | D8: =SUMIFS(INDEX('Calculations - from BCEU'!$D$2:$AK$151,,MATCH(About!$A$41,'Calculations - from BCEU'!$D$1:$AK$1,0)),'Calculations - from BCEU'!$A$2:$A$151,"Rural Residential",'Calculations - from BCEU'!$C$2:$C$151,D$1,'Calculations - from BCEU'!$B$2:$B$151,$A8) -> 0 | E8: =SUMIFS(INDEX('Calculations - from BCEU'!$D$2:$AK$151,,MATCH(About!$A$41,'Calculations - from BCEU'!$D$1:$AK$1,0)),'Calculations - from BCEU'!$A$2:$A$151,"Rural Residential",'Calculations - from BCEU'!$C$2:$C$151,E$1,'Calculations - from BCEU'!$B$2:$B$151,$A8) -> 0 | F8: =SUMIFS(INDEX('Calculations - from BCEU'!$D$2:$AK$151,,MATCH(About!$A$41,'Calculations - from BCEU'!$D$1:$AK$1,0)),'Calculations - from BCEU'!$A$2:$A$151,"Rural Residential",'Calculations - from BCEU'!$C$2:$C$151,F$1,'Calculations - from BCEU'!$B$2:$B$151,$A8) -> 0 | G8: =SUMIFS(INDEX('Calculations - from BCEU'!$D$2:$AK$151,,MATCH(About!$A$41,'Calculations - from BCEU'!$D$1:$AK$1,0)),'Calculations - from BCEU'!$A$2:$A$151,"Rural Residential",'Calculations - from BCEU'!$C$2:$C$151,G$1,'Calculations - from BCEU'!$B$2:$B$151,$A8) -> 0
A9: heavy or residual fuel oil (BTU) | B9: =SUMIFS(INDEX('Calculations - from BCEU'!$D$2:$AK$151,,MATCH(About!$A$41,'Calculations - from BCEU'!$D$1:$AK$1,0)),'Calculations - from BCEU'!$A$2:$A$151,"Rural Residential",'Calculations - from BCEU'!$C$2:$C$151,B$1,'Calculations - from BCEU'!$B$2:$B$151,$A9) -> 0 | C9: =SUMIFS(INDEX('Calculations - from BCEU'!$D$2:$AK$151,,MATCH(About!$A$41,'Calculations - from BCEU'!$D$1:$AK$1,0)),'Calculations - from BCEU'!$A$2:$A$151,"Rural Residential",'Calculations - from BCEU'!$C$2:$C$151,C$1,'Calculations - from BCEU'!$B$2:$B$151,$A9) -> 0 | D9: =SUMIFS(INDEX('Calculations - from BCEU'!$D$2:$AK$151,,MATCH(About!$A$41,'Calculations - from BCEU'!$D$1:$AK$1,0)),'Calculations - from BCEU'!$A$2:$A$151,"Rural Residential",'Calculations - from BCEU'!$C$2:$C$151,D$1,'Calculations - from BCEU'!$B$2:$B$151,$A9) -> 0 | E9: =SUMIFS(INDEX('Calculations - from BCEU'!$D$2:$AK$151,,MATCH(About!$A$41,'Calculations - from BCEU'!$D$1:$AK$1,0)),'Calculations - from BCEU'!$A$2:$A$151,"Rural Residential",'Calculations - from BCEU'!$C$2:$C$151,E$1,'Calculations - from BCEU'!$B$2:$B$151,$A9) -> 0 | F9: =SUMIFS(INDEX('Calculations - from BCEU'!$D$2:$AK$151,,MATCH(About!$A$41,'Calculations - from BCEU'!$D$1:$AK$1,0)),'Calculations - from BCEU'!$A$2:$A$151,"Rural Residential",'Calculations - from BCEU'!$C$2:$C$151,F$1,'Calculations - from BCEU'!$B$2:$B$151,$A9) -> 0 | G9: =SUMIFS(INDEX('Calculations - from BCEU'!$D$2:$AK$151,,MATCH(About!$A$41,'Calculations - from BCEU'!$D$1:$AK$1,0)),'Calculations - from BCEU'!$A$2:$A$151,"Rural Residential",'Calculations - from BCEU'!$C$2:$C$151,G$1,'Calculations - from BCEU'!$B$2:$B$151,$A9) -> 0
A10: LPG propane or butane (BTU) | B10: =SUMIFS(INDEX('Calculations - from BCEU'!$D$2:$AK$151,,MATCH(About!$A$41,'Calculations - from BCEU'!$D$1:$AK$1,0)),'Calculations - from BCEU'!$A$2:$A$151,"Rural Residential",'Calculations - from BCEU'!$C$2:$C$151,B$1,'Calculations - from BCEU'!$B$2:$B$151,$A10) -> 0 | C10: =SUMIFS(INDEX('Calculations - from BCEU'!$D$2:$AK$151,,MATCH(About!$A$41,'Calculations - from BCEU'!$D$1:$AK$1,0)),'Calculations - from BCEU'!$A$2:$A$151,"Rural Residential",'Calculations - from BCEU'!$C$2:$C$151,C$1,'Calculations - from BCEU'!$B$2:$B$151,$A10) -> 0 | D10: =SUMIFS(INDEX('Calculations - from BCEU'!$D$2:$AK$151,,MATCH(About!$A$41,'Calculations - from BCEU'!$D$1:$AK$1,0)),'Calculations - from BCEU'!$A$2:$A$151,"Rural Residential",'Calculations - from BCEU'!$C$2:$C$151,D$1,'Calculations - from BCEU'!$B$2:$B$151,$A10) -> 0 | E10: =SUMIFS(INDEX('Calculations - from BCEU'!$D$2:$AK$151,,MATCH(About!$A$41,'Calculations - from BCEU'!$D$1:$AK$1,0)),'Calculations - from BCEU'!$A$2:$A$151,"Rural Residential",'Calculations - from BCEU'!$C$2:$C$151,E$1,'Calculations - from BCEU'!$B$2:$B$151,$A10) -> 0 | F10: =SUMIFS(INDEX('Calculations - from BCEU'!$D$2:$AK$151,,MATCH(About!$A$41,'Calculations - from BCEU'!$D$1:$AK$1,0)),'Calculations - from BCEU'!$A$2:$A$151,"Rural Residential",'Calculations - from BCEU'!$C$2:$C$151,F$1,'Calculations - from BCEU'!$B$2:$B$151,$A10) -> 476300000000000 | G10: =SUMIFS(INDEX('Calculations - from BCEU'!$D$2:$AK$151,,MATCH(About!$A$41,'Calculations - from BCEU'!$D$1:$AK$1,0)),'Calculations - from BCEU'!$A$2:$A$151,"Rural Residential",'Calculations - from BCEU'!$C$2:$C$151,G$1,'Calculations - from BCEU'!$B$2:$B$151,$A10) -> 0
A11: hydrogen (BTU) | B11: =SUMIFS(INDEX('Calculations - from BCEU'!$D$2:$AK$151,,MATCH(About!$A$41,'Calculations - from BCEU'!$D$1:$AK$1,0)),'Calculations - from BCEU'!$A$2:$A$151,"Rural Residential",'Calculations - from BCEU'!$C$2:$C$151,B$1,'Calculations - from BCEU'!$B$2:$B$151,$A11) -> 0 | C11: =SUMIFS(INDEX('Calculations - from BCEU'!$D$2:$AK$151,,MATCH(About!$A$41,'Calculations - from BCEU'!$D$1:$AK$1,0)),'Calculations - from BCEU'!$A$2:$A$151,"Rural Residential",'Calculations - from BCEU'!$C$2:$C$151,C$1,'Calculations - from BCEU'!$B$2:$B$151,$A11) -> 0 | D11: =SUMIFS(INDEX('Calculations - from BCEU'!$D$2:$AK$151,,MATCH(About!$A$41,'Calculations - from BCEU'!$D$1:$AK$1,0)),'Calculations - from BCEU'!$A$2:$A$151,"Rural Residential",'Calculations - from BCEU'!$C$2:$C$151,D$1,'Calculations - from BCEU'!$B$2:$B$151,$A11) -> 0 | E11: =SUMIFS(INDEX('Calculations - from BCEU'!$D$2:$AK$151,,MATCH(About!$A$41,'Calculations - from BCEU'!$D$1:$AK$1,0)),'Calculations - from BCEU'!$A$2:$A$151,"Rural Residential",'Calculations - from BCEU'!$C$2:$C$151,E$1,'Calculations - from BCEU'!$B$2:$B$151,$A11) -> 0 | F11: =SUMIFS(INDEX('Calculations - from BCEU'!$D$2:$AK$151,,MATCH(About!$A$41,'Calculations - from BCEU'!$D$1:$AK$1,0)),'Calculations - from BCEU'!$A$2:$A$151,"Rural Residential",'Calculations - from BCEU'!$C$2:$C$151,F$1,'Calculations - from BCEU'!$B$2:$B$151,$A11) -> 0 | G11: =SUMIFS(INDEX('Calculations - from BCEU'!$D$2:$AK$151,,MATCH(About!$A$41,'Calculations - from BCEU'!$D$1:$AK$1,0)),'Calculations - from BCEU'!$A$2:$A$151,"Rural Residential",'Calculations - from BCEU'!$C$2:$C$151,G$1,'Calculations - from BCEU'!$B$2:$B$151,$A11) -> 0

Sheet SYCEU-commercial
A1: Year | B1: heating | C1: cooling & ventilation | D1: envelope | E1: lighting | F1: appliances | G1: other
A2: electricity (BTU) | B2: =SUMIFS(INDEX('Calculations - from BCEU'!$D$2:$AK$151,,MATCH(About!$A$41,'Calculations - from BCEU'!$D$1:$AK$1,0)),'Calculations - from BCEU'!$A$2:$A$151,"Commercial",'Calculations - from BCEU'!$C$2:$C$151,B$1,'Calculations - from BCEU'!$B$2:$B$151,$A2) -> 0 | C2: =SUMIFS(INDEX('Calculations - from BCEU'!$D$2:$AK$151,,MATCH(About!$A$41,'Calculations - from BCEU'!$D$1:$AK$1,0)),'Calculations - from BCEU'!$A$2:$A$151,"Commercial",'Calculations - from BCEU'!$C$2:$C$151,C$1,'Calculations - from BCEU'!$B$2:$B$151,$A2) -> 224000000000000 | D2: =SUMIFS(INDEX('Calculations - from BCEU'!$D$2:$AK$151,,MATCH(About!$A$41,'Calculations - from BCEU'!$D$1:$AK$1,0)),'Calculations - from BCEU'!$A$2:$A$151,"Commercial",'Calculations - from BCEU'!$C$2:$C$151,D$1,'Calculations - from BCEU'!$B$2:$B$151,$A2) -> 0 | E2: =SUMIFS(INDEX('Calculations - from BCEU'!$D$2:$AK$151,,MATCH(About!$A$41,'Calculations - from BCEU'!$D$1:$AK$1,0)),'Calculations - from BCEU'!$A$2:$A$151,"Commercial",'Calculations - from BCEU'!$C$2:$C$151,E$1,'Calculations - from BCEU'!$B$2:$B$151,$A2) -> 44100000000000 | F2: =SUMIFS(INDEX('Calculations - from BCEU'!$D$2:$AK$151,,MATCH(About!$A$41,'Calculations - from BCEU'!$D$1:$AK$1,0)),'Calculations - from BCEU'!$A$2:$A$151,"Commercial",'Calculations - from BCEU'!$C$2:$C$151,F$1,'Calculations - from BCEU'!$B$2:$B$151,$A2) -> 68000000000000 | G2: =SUMIFS(INDEX('Calculations - from BCEU'!$D$2:$AK$151,,MATCH(About!$A$41,'Calculations - from BCEU'!$D$1:$AK$1,0)),'Calculations - from BCEU'!$A$2:$A$151,"Commercial",'Calculations - from BCEU'!$C$2:$C$151,G$1,'Calculations - from BCEU'!$B$2:$B$151,$A2) -> 31700000000000
A3: coal (BTU) | B3: =SUMIFS(INDEX('Calculations - from BCEU'!$D$2:$AK$151,,MATCH(About!$A$41,'Calculations - from BCEU'!$D$1:$AK$1,0)),'Calculations - from BCEU'!$A$2:$A$151,"Commercial",'Calculations - from BCEU'!$C$2:$C$151,B$1,'Calculations - from BCEU'!$B$2:$B$151,$A3) -> 0 | C3: =SUMIFS(INDEX('Calculations - from BCEU'!$D$2:$AK$151,,MATCH(About!$A$41,'Calculations - from BCEU'!$D$1:$AK$1,0)),'Calculations - from BCEU'!$A$2:$A$151,"Commercial",'Calculations - from BCEU'!$C$2:$C$151,C$1,'Calculations - from BCEU'!$B$2:$B$151,$A3) -> 0 | D3: =SUMIFS(INDEX('Calculations - from BCEU'!$D$2:$AK$151,,MATCH(About!$A$41,'Calculations - from BCEU'!$D$1:$AK$1,0)),'Calculations - from BCEU'!$A$2:$A$151,"Commercial",'Calculations - from BCEU'!$C$2:$C$151,D$1,'Calculations - from BCEU'!$B$2:$B$151,$A3) -> 0 | E3: =SUMIFS(INDEX('Calculations - from BCEU'!$D$2:$AK$151,,MATCH(About!$A$41,'Calculations - from BCEU'!$D$1:$AK$1,0)),'Calculations - from BCEU'!$A$2:$A$151,"Commercial",'Calculations - from BCEU'!$C$2:$C$151,E$1,'Calculations - from BCEU'!$B$2:$B$151,$A3) -> 0 | F3: =SUMIFS(INDEX('Calculations - from BCEU'!$D$2:$AK$151,,MATCH(About!$A$41,'Calculations - from BCEU'!$D$1:$AK$1,0)),'Calculations - from BCEU'!$A$2:$A$151,"Commercial",'Calculations - from BCEU'!$C$2:$C$151,F$1,'Calculations - from BCEU'!$B$2:$B$151,$A3) -> 0 | G3: =SUMIFS(INDEX('Calculations - from BCEU'!$D$2:$AK$151,,MATCH(About!$A$41,'Calculations - from BCEU'!$D$1:$AK$1,0)),'Calculations - from BCEU'!$A$2:$A$151,"Commercial",'Calculations - from BCEU'!$C$2:$C$151,G$1,'Calculations - from BCEU'!$B$2:$B$151,$A3) -> 0
A4: natural gas (BTU) | B4: =SUMIFS(INDEX('Calculations - from BCEU'!$D$2:$AK$151,,MATCH(About!$A$41,'Calculations - from BCEU'!$D$1:$AK$1,0)),'Calculations - from BCEU'!$A$2:$A$151,"Commercial",'Calculations - from BCEU'!$C$2:$C$151,B$1,'Calculations - from BCEU'!$B$2:$B$151,$A4) -> 0 | C4: =SUMIFS(INDEX('Calculations - from BCEU'!$D$2:$AK$151,,MATCH(About!$A$41,'Calculations - from BCEU'!$D$1:$AK$1,0)),'Calculations - from BCEU'!$A$2:$A$151,"Commercial",'Calculations - from BCEU'!$C$2:$C$151,C$1,'Calculations - from BCEU'!$B$2:$B$151,$A4) -> 0 | D4: =SUMIFS(INDEX('Calculations - from BCEU'!$D$2:$AK$151,,MATCH(About!$A$41,'Calculations - from BCEU'!$D$1:$AK$1,0)),'Calculations - from BCEU'!$A$2:$A$151,"Commercial",'Calculations - from BCEU'!$C$2:$C$151,D$1,'Calculations - from BCEU'!$B$2:$B$151,$A4) -> 0 | E4: =SUMIFS(INDEX('Calculations - from BCEU'!$D$2:$AK$151,,MATCH(About!$A$41,'Calculations - from BCEU'!$D$1:$AK$1,0)),'Calculations - from BCEU'!$A$2:$A$151,"Commercial",'Calculations - from BCEU'!$C$2:$C$151,E$1,'Calculations - from BCEU'!$B$2:$B$151,$A4) -> 0 | F4: =SUMIFS(INDEX('Calculations - from BCEU'!$D$2:$AK$151,,MATCH(About!$A$41,'Calculations - from BCEU'!$D$1:$AK$1,0)),'Calculations - from BCEU'!$A$2:$A$151,"Commercial",'Calculations - from BCEU'!$C$2:$C$151,F$1,'Calculations - from BCEU'!$B$2:$B$151,$A4) -> 0 | G4: =SUMIFS(INDEX('Calculations - from BCEU'!$D$2:$AK$151,,MATCH(About!$A$41,'Calculations - from BCEU'!$D$1:$AK$1,0)),'Calculations - from BCEU'!$A$2:$A$151,"Commercial",'Calculations - from BCEU'!$C$2:$C$151,G$1,'Calculations - from BCEU'!$B$2:$B$151,$A4) -> 0
A5: petroleum diesel (BTU) | B5: =SUMIFS(INDEX('Calculations - from BCEU'!$D$2:$AK$151,,MATCH(About!$A$41,'Calculations - from BCEU'!$D$1:$AK$1,0)),'Calculations - from BCEU'!$A$2:$A$151,"Commercial",'Calculations - from BCEU'!$C$2:$C$151,B$1,'Calculations - from BCEU'!$B$2:$B$151,$A5) -> 0 | C5: =SUMIFS(INDEX('Calculations - from BCEU'!$D$2:$AK$151,,MATCH(About!$A$41,'Calculations - from BCEU'!$D$1:$AK$1,0)),'Calculations - from BCEU'!$A$2:$A$151,"Commercial",'Calculations - from BCEU'!$C$2:$C$151,C$1,'Calculations - from BCEU'!$B$2:$B$151,$A5) -> 0 | D5: =SUMIFS(INDEX('Calculations - from BCEU'!$D$2:$AK$151,,MATCH(About!$A$41,'Calculations - from BCEU'!$D$1:$AK$1,0)),'Calculations - from BCEU'!$A$2:$A$151,"Commercial",'Calculations - from BCEU'!$C$2:$C$151,D$1,'Calculations - from BCEU'!$B$2:$B$151,$A5) -> 0 | E5: =SUMIFS(INDEX('Calculations - from BCEU'!$D$2:$AK$151,,MATCH(About!$A$41,'Calculations - from BCEU'!$D$1:$AK$1,0)),'Calculations - from BCEU'!$A$2:$A$151,"Commercial",'Calculations - from BCEU'!$C$2:$C$151,E$1,'Calculations - from BCEU'!$B$2:$B$151,$A5) -> 0 | F5: =SUMIFS(INDEX('Calculations - from BCEU'!$D$2:$AK$151,,MATCH(About!$A$41,'Calculations - from BCEU'!$D$1:$AK$1,0)),'Calculations - from BCEU'!$A$2:$A$151,"Commercial",'Calculations - from BCEU'!$C$2:$C$151,F$1,'Calculations - from BCEU'!$B$2:$B$151,$A5) -> 0 | G5: =SUMIFS(INDEX('Calculations - from BCEU'!$D$2:$AK$151,,MATCH(About!$A$41,'Calculations - from BCEU'!$D$1:$AK$1,0)),'Calculations - from BCEU'!$A$2:$A$151,"Commercial",'Calculations - from BCEU'!$C$2:$C$151,G$1,'Calculations - from BCEU'!$B$2:$B$151,$A5) -> 0
