Workbook

Sheet About
A1: SYDEC Start Year Distributed Electricity Capacity
A3: Sources: | B3: Distributed Generation Quantity, Urban vs. Rural Shares | E3: Distributed Rooftop PV Capacity Factor projections
B4: NITI Aayog, Government of India | E4: See variable "bldgs/DSCF" for more info
B5: 2023
B6: India Energy Security Scenarios 2047 downloadable Excel model | E6: Back up electricity from diesel generators
B7: http://indiaenergy.gov.in/iess/docs/IESS_Version2.2.xlsx | E7: NITI Aayog, Government of India
B8: Tab IV.e | E8: 2023
E9: India Energy Security Scenarios 2047 downloadable Excel model
B10: Residential vs. Non-Residential Shares | E10: http://indiaenergy.gov.in/iess/docs/IESS_Version2.2.xlsx
B11: CPI, ICRIER, SEI | E11: Tab I.e
B12: 2018
B13: Scaling up Rooftop Solar Power in India: The Potential of Municipal Solar Bonds
B14: http://icrier.org/pdf/Working_Paper_353.pdf
B15: Page 3, Figure 2
B17: Solar DC to AC Derate Value
B18: Jens Schoene, EnerNex
B19: 2015
B20: Production Levels of Utility-Scale and Residential-Scale PV Systems
B21: http://brattle.com/system/publications/pdfs/000/005/188/original/Comparative_Generation_Costs_of_Utility-Scale_and_Residential-Scale_PV_in_Xcel_Energy_Colorado's_Service_Area.pdf?1436797265
B22: This document is included as Appendix B of a report by Brattle Group. It is on Page 10 of the EnerNex report, which is Page 70 of the PDF
A24: Notes
A25: The start year is the year before the first simulated year.
A26: This can be adjusted using the yellow field below.
A27: The start year is:
A28: 2022
A30: Data copied from BDEQ - BAU Distributed Electricity Quantities

Sheet BDEQ - Combined
A1: BDESC-urban-residential
B2: MW | C2: 2020 | D2: 2021 | E2: 2022 | F2: 2023 | G2: 2024 | H2: 2025 | I2: 2026 | J2: 2027 | K2: 2028 | L2: 2029 | M2: 2030 | N2: 2031 | O2: 2032 | P2: 2033 | Q2: 2034 | R2: 2035 | S2: 2036 | T2: 2037 | U2: 2038 | V2: 2039 | W2: 2040 | X2: 2041 | Y2: 2042 | Z2: 2043 | AA2: 2044 | AB2: 2045 | AC2: 2046 | AD2: 2047 | AE2: 2048 | AF2: 2049 | AG2: 2050
A3: urban residential | B3: hard coal | C3: 0 | D3: 0 | E3: 0 | F3: 0 | G3: 0 | H3: 0 | I3: 0 | J3: 0 | K3: 0 | L3: 0 | M3: 0 | N3: 0 | O3: 0 | P3: 0 | Q3: 0 | R3: 0 | S3: 0 | T3: 0 | U3: 0 | V3: 0 | W3: 0 | X3: 0 | Y3: 0 | Z3: 0 | AA3: 0 | AB3: 0 | AC3: 0 | AD3: 0 | AE3: 0 | AF3: 0 | AG3: 0
A4: urban residential | B4: natural gas steam turbine | C4: 0 | D4: 0 | E4: 0 | F4: 0 | G4: 0 | H4: 0 | I4: 0 | J4: 0 | K4: 0 | L4: 0 | M4: 0 | N4: 0 | O4: 0 | P4: 0 | Q4: 0 | R4: 0 | S4: 0 | T4: 0 | U4: 0 | V4: 0 | W4: 0 | X4: 0 | Y4: 0 | Z4: 0 | AA4: 0 | AB4: 0 | AC4: 0 | AD4: 0 | AE4: 0 | AF4: 0 | AG4: 0
A5: urban residential | B5: natural gas combined cycle | C5: 0 | D5: 0 | E5: 0 | F5: 0 | G5: 0 | H5: 0 | I5: 0 | J5: 0 | K5: 0 | L5: 0 | M5: 0 | N5: 0 | O5: 0 | P5: 0 | Q5: 0 | R5: 0 | S5: 0 | T5: 0 | U5: 0 | V5: 0 | W5: 0 | X5: 0 | Y5: 0 | Z5: 0 | AA5: 0 | AB5: 0 | AC5: 0 | AD5: 0 | AE5: 1757.4504 | AF5: 1770.3062 | AG5: 1783.162
A6: urban residential | B6: nuclear | C6: 0 | D6: 0 | E6: 0 | F6: 0 | G6: 0 | H6: 0 | I6: 0 | J6: 0 | K6: 0 | L6: 0 | M6: 0 | N6: 0 | O6: 0 | P6: 0 | Q6: 0 | R6: 0 | S6: 0 | T6: 0 | U6: 0 | V6: 0 | W6: 0 | X6: 0 | Y6: 0 | Z6: 0 | AA6: 0 | AB6: 0 | AC6: 0 | AD6: 0 | AE6: 0 | AF6: 0 | AG6: 0
A7: urban residential | B7: hydro | C7: 0 | D7: 0 | E7: 0 | F7: 0 | G7: 0 | H7: 0 | I7: 0 | J7: 0 | K7: 0 | L7: 0 | M7: 0 | N7: 0 | O7: 0 | P7: 0 | Q7: 0 | R7: 0 | S7: 0 | T7: 0 | U7: 0 | V7: 0 | W7: 0 | X7: 0 | Y7: 0 | Z7: 0 | AA7: 0 | AB7: 0 | AC7: 0 | AD7: 0 | AE7: 0 | AF7: 0 | AG7: 0
A8: urban residential | B8: onshore wind | C8: 0 | D8: 0 | E8: 0 | F8: 0 | G8: 0 | H8: 0 | I8: 0 | J8: 0 | K8: 0 | L8: 0 | M8: 0 | N8: 0 | O8: 0 | P8: 0 | Q8: 0 | R8: 0 | S8: 0 | T8: 0 | U8: 0 | V8: 0 | W8: 0 | X8: 0 | Y8: 0 | Z8: 0 | AA8: 0 | AB8: 0 | AC8: 0 | AD8: 0 | AE8: 572.2922 | AF8: 572.3246 | AG8: 572.357
A9: urban residential | B9: solar PV | C9: 116.37606 | D9: 157.21797 | E9: 198.05989 | F9: 238.9018 | G9: 249.08587 | H9: 259.26994 | I9: 269.45402 | J9: 279.63809 | K9: 289.82216 | L9: 345.54818 | M9: 401.27419 | N9: 457.0002 | O9: 512.72621 | P9: 568.45222 | Q9: 653.86585 | R9: 739.27948 | S9: 824.69311 | T9: 910.10674 | U9: 995.52036 | V9: 1084.4739 | W9: 1173.4273 | X9: 1262.3808 | Y9: 1351.3343 | Z9: 1440.2878 | AA9: 1503.2486 | AB9: 1566.2093 | AC9: 1629.1701 | AD9: 1692.1308 | AE9: 64130.904 | AF9: 65974.059 | AG9: 67817.215
A10: urban residential | B10: solar thermal | C10: 0 | D10: 0 | E10: 0 | F10: 0 | G10: 0 | H10: 0 | I10: 0 | J10: 0 | K10: 0 | L10: 0 | M10: 0 | N10: 0 | O10: 0 | P10: 0 | Q10: 0 | R10: 0 | S10: 0 | T10: 0 | U10: 0 | V10: 0 | W10: 0 | X10: 0 | Y10: 0 | Z10: 0 | AA10: 0 | AB10: 0 | AC10: 0 | AD10: 0 | AE10: 0 | AF10: 0 | AG10: 0
A11: urban residential | B11: biomass | C11: 0 | D11: 0 | E11: 0 | F11: 0 | G11: 0 | H11: 0 | I11: 0 | J11: 0 | K11: 0 | L11: 0 | M11: 0 | N11: 0 | O11: 0 | P11: 0 | Q11: 0 | R11: 0 | S11: 0 | T11: 0 | U11: 0 | V11: 0 | W11: 0 | X11: 0 | Y11: 0 | Z11: 0 | AA11: 0 | AB11: 0 | AC11: 0 | AD11: 0 | AE11: 0 | AF11: 0 | AG11: 0
A12: urban residential | B12: geothermal | C12: 0 | D12: 0 | E12: 0 | F12: 0 | G12: 0 | H12: 0 | I12: 0 | J12: 0 | K12: 0 | L12: 0 | M12: 0 | N12: 0 | O12: 0 | P12: 0 | Q12: 0 | R12: 0 | S12: 0 | T12: 0 | U12: 0 | V12: 0 | W12: 0 | X12: 0 | Y12: 0 | Z12: 0 | AA12: 0 | AB12: 0 | AC12: 0 | AD12: 0 | AE12: 0 | AF12: 0 | AG12: 0
A13: urban residential | B13: petroleum | C13: 0 | D13: 0 | E13: 0 | F13: 0 | G13: 0 | H13: 0 | I13: 0 | J13: 0 | K13: 0 | L13: 0 | M13: 0 | N13: 0 | O13: 0 | P13: 0 | Q13: 0 | R13: 0 | S13: 0 | T13: 0 | U13: 0 | V13: 0 | W13: 0 | X13: 0 | Y13: 0 | Z13: 0 | AA13: 0 | AB13: 0 | AC13: 0 | AD13: 0 | AE13: 12.053 | AF13: 12.053 | AG13: 12.053
A14: urban residential | B14: natural gas peaker | C14: 0 | D14: 0 | E14: 0 | F14: 0 | G14: 0 | H14: 0 | I14: 0 | J14: 0 | K14: 0 | L14: 0 | M14: 0 | N14: 0 | O14: 0 | P14: 0 | Q14: 0 | R14: 0 | S14: 0 | T14: 0 | U14: 0 | V14: 0 | W14: 0 | X14: 0 | Y14: 0 | Z14: 0 | AA14: 0 | AB14: 0 | AC14: 0 | AD14: 0 | AE14: 0 | AF14: 0 | AG14: 0
... A26: urban residential | B26: hydrogen combined cycle | C26: 0 | D26: 0 | E26: 0 | F26: 0 | G26: 0 | H26: 0 | I26: 0 | J26: 0 | K26: 0 | L26: 0 | M26: 0 | N26: 0 | O26: 0 | P26: 0 | Q26: 0 | R26: 0 | S26: 0 | T26: 0 | U26: 0 | V26: 0 | W26: 0 | X26: 0 | Y26: 0 | Z26: 0 | AA26: 0 | AB26: 0 | AC26: 0 | AD26: 0 | AE26: 0 | AF26: 0 | AG26: 0
A28: BDESC-rural-residential
B29: MW | C29: 2020 | D29: 2021 | E29: 2022 | F29: 2023 | G29: 2024 | H29: 2025 | I29: 2026 | J29: 2027 | K29: 2028 | L29: 2029 | M29: 2030 | N29: 2031 | O29: 2032 | P29: 2033 | Q29: 2034 | R29: 2035 | S29: 2036 | T29: 2037 | U29: 2038 | V29: 2039 | W29: 2040 | X29: 2041 | Y29: 2042 | Z29: 2043 | AA29: 2044 | AB29: 2045 | AC29: 2046 | AD29: 2047 | AE29: 2048 | AF29: 2049 | AG29: 2050
A30: rural residential | B30: hard coal | C30: 0 | D30: 0 | E30: 0 | F30: 0 | G30: 0 | H30: 0 | I30: 0 | J30: 0 | K30: 0 | L30: 0 | M30: 0 | N30: 0 | O30: 0 | P30: 0 | Q30: 0 | R30: 0 | S30: 0 | T30: 0 | U30: 0 | V30: 0 | W30: 0 | X30: 0 | Y30: 0 | Z30: 0 | AA30: 0 | AB30: 0 | AC30: 0 | AD30: 0 | AE30: 0 | AF30: 0 | AG30: 0
A31: rural residential | B31: natural gas steam turbine | C31: 0 | D31: 0 | E31: 0 | F31: 0 | G31: 0 | H31: 0 | I31: 0 | J31: 0 | K31: 0 | L31: 0 | M31: 0 | N31: 0 | O31: 0 | P31: 0 | Q31: 0 | R31: 0 | S31: 0 | T31: 0 | U31: 0 | V31: 0 | W31: 0 | X31: 0 | Y31: 0 | Z31: 0 | AA31: 0 | AB31: 0 | AC31: 0 | AD31: 0 | AE31: 0 | AF31: 0 | AG31: 0
A32: rural residential | B32: natural gas combined cycle | C32: 0 | D32: 0 | E32: 0 | F32: 0 | G32: 0 | H32: 0 | I32: 0 | J32: 0 | K32: 0 | L32: 0 | M32: 0 | N32: 0 | O32: 0 | P32: 0 | Q32: 0 | R32: 0 | S32: 0 | T32: 0 | U32: 0 | V32: 0 | W32: 0 | X32: 0 | Y32: 0 | Z32: 0 | AA32: 0 | AB32: 0 | AC32: 0 | AD32: 0 | AE32: 0 | AF32: 0 | AG32: 0
A33: rural residential | B33: nuclear | C33: 0 | D33: 0 | E33: 0 | F33: 0 | G33: 0 | H33: 0 | I33: 0 | J33: 0 | K33: 0 | L33: 0 | M33: 0 | N33: 0 | O33: 0 | P33: 0 | Q33: 0 | R33: 0 | S33: 0 | T33: 0 | U33: 0 | V33: 0 | W33: 0 | X33: 0 | Y33: 0 | Z33: 0 | AA33: 0 | AB33: 0 | AC33: 0 | AD33: 0 | AE33: 0 | AF33: 0 | AG33: 0
A34: rural residential | B34: hydro | C34: 0 | D34: 0 | E34: 0 | F34: 0 | G34: 0 | H34: 0 | I34: 0 | J34: 0 | K34: 0 | L34: 0 | M34: 0 | N34: 0 | O34: 0 | P34: 0 | Q34: 0 | R34: 0 | S34: 0 | T34: 0 | U34: 0 | V34: 0 | W34: 0 | X34: 0 | Y34: 0 | Z34: 0 | AA34: 0 | AB34: 0 | AC34: 0 | AD34: 0 | AE34: 0 | AF34: 0 | AG34: 0
A35: rural residential | B35: onshore wind | C35: 0 | D35: 0 | E35: 0 | F35: 0 | G35: 0 | H35: 0 | I35: 0 | J35: 0 | K35: 0 | L35: 0 | M35: 0 | N35: 0 | O35: 0 | P35: 0 | Q35: 0 | R35: 0 | S35: 0 | T35: 0 | U35: 0 | V35: 0 | W35: 0 | X35: 0 | Y35: 0 | Z35: 0 | AA35: 0 | AB35: 0 | AC35: 0 | AD35: 0 | AE35: 0 | AF35: 0 | AG35: 0
A36: rural residential | B36: solar PV | C36: 212.14718 | D36: 283.00289 | E36: 353.8586 | F36: 424.71431 | G36: 430.43376 | H36: 436.15322 | I36: 441.87268 | J36: 447.59213 | K36: 453.31159 | L36: 519.65036 | M36: 585.98913 | N36: 652.32791 | O36: 718.66668 | P36: 785.00545 | Q36: 871.35378 | R36: 957.70211 | S36: 1044.0504 | T36: 1130.3988 | U36: 1216.7471 | V36: 1285.4601 | W36: 1354.173 | X36: 1422.8859 | Y36: 1491.5989 | Z36: 1560.3118 | AA36: 1585.5023 | AB36: 1610.6929 | AC36: 1635.8834 | AD36: 1661.0739 | AE36: 1686.2645 | AF36: 1711.455 | AG36: 1736.6455
A37: rural residential | B37: solar thermal | C37: 0 | D37: 0 | E37: 0 | F37: 0 | G37: 0 | H37: 0 | I37: 0 | J37: 0 | K37: 0 | L37: 0 | M37: 0 | N37: 0 | O37: 0 | P37: 0 | Q37: 0 | R37: 0 | S37: 0 | T37: 0 | U37: 0 | V37: 0 | W37: 0 | X37: 0 | Y37: 0 | Z37: 0 | AA37: 0 | AB37: 0 | AC37: 0 | AD37: 0 | AE37: 0 | AF37: 0 | AG37: 0
A38: rural residential | B38: biomass | C38: 0 | D38: 0 | E38: 0 | F38: 0 | G38: 0 | H38: 0 | I38: 0 | J38: 0 | K38: 0 | L38: 0 | M38: 0 | N38: 0 | O38: 0 | P38: 0 | Q38: 0 | R38: 0 | S38: 0 | T38: 0 | U38: 0 | V38: 0 | W38: 0 | X38: 0 | Y38: 0 | Z38: 0 | AA38: 0 | AB38: 0 | AC38: 0 | AD38: 0 | AE38: 0 | AF38: 0 | AG38: 0
A39: rural residential | B39: geothermal | C39: 0 | D39: 0 | E39: 0 | F39: 0 | G39: 0 | H39: 0 | I39: 0 | J39: 0 | K39: 0 | L39: 0 | M39: 0 | N39: 0 | O39: 0 | P39: 0 | Q39: 0 | R39: 0 | S39: 0 | T39: 0 | U39: 0 | V39: 0 | W39: 0 | X39: 0 | Y39: 0 | Z39: 0 | AA39: 0 | AB39: 0 | AC39: 0 | AD39: 0 | AE39: 0 | AF39: 0 | AG39: 0
A40: rural residential | B40: petroleum | C40: 0 | D40: 0 | E40: 0 | F40: 0 | G40: 0 | H40: 0 | I40: 0 | J40: 0 | K40: 0 | L40: 0 | M40: 0 | N40: 0 | O40: 0 | P40: 0 | Q40: 0 | R40: 0 | S40: 0 | T40: 0 | U40: 0 | V40: 0 | W40: 0 | X40: 0 | Y40: 0 | Z40: 0 | AA40: 0 | AB40: 0 | AC40: 0 | AD40: 0 | AE40: 0 | AF40: 0 | AG40: 0
A41: rural residential | B41: natural gas peaker | C41: 0 | D41: 0 | E41: 0 | F41: 0 | G41: 0 | H41: 0 | I41: 0 | J41: 0 | K41: 0 | L41: 0 | M41: 0 | N41: 0 | O41: 0 | P41: 0 | Q41: 0 | R41: 0 | S41: 0 | T41: 0 | U41: 0 | V41: 0 | W41: 0 | X41: 0 | Y41: 0 | Z41: 0 | AA41: 0 | AB41: 0 | AC41: 0 | AD41: 0 | AE41: 0 | AF41: 0 | AG41: 0
... A53: rural residential | B53: hydrogen combined cycle | C53: 0 | D53: 0 | E53: 0 | F53: 0 | G53: 0 | H53: 0 | I53: 0 | J53: 0 | K53: 0 | L53: 0 | M53: 0 | N53: 0 | O53: 0 | P53: 0 | Q53: 0 | R53: 0 | S53: 0 | T53: 0 | U53: 0 | V53: 0 | W53: 0 | X53: 0 | Y53: 0 | Z53: 0 | AA53: 0 | AB53: 0 | AC53: 0 | AD53: 0 | AE53: 0 | AF53: 0 | AG53: 0
A55: BDESC-commercial
B56: MW | C56: 2020 | D56: 2021 | E56: 2022 | F56: 2023 | G56: 2024 | H56: 2025 | I56: 2026 | J56: 2027 | K56: 2028 | L56: 2029 | M56: 2030 | N56: 2031 | O56: 2032 | P56: 2033 | Q56: 2034 | R56: 2035 | S56: 2036 | T56: 2037 | U56: 2038 | V56: 2039 | W56: 2040 | X56: 2041 | Y56: 2042 | Z56: 2043 | AA56: 2044 | AB56: 2045 | AC56: 2046 | AD56: 2047 | AE56: 2048 | AF56: 2049 | AG56: 2050
A57: commercial | B57: hard coal | C57: 0 | D57: 0 | E57: 0 | F57: 0 | G57: 0 | H57: 0 | I57: 0 | J57: 0 | K57: 0 | L57: 0 | M57: 0 | N57: 0 | O57: 0 | P57: 0 | Q57: 0 | R57: 0 | S57: 0 | T57: 0 | U57: 0 | V57: 0 | W57: 0 | X57: 0 | Y57: 0 | Z57: 0 | AA57: 0 | AB57: 0 | AC57: 0 | AD57: 0 | AE57: 0 | AF57: 0 | AG57: 0
A58: commercial | B58: natural gas steam turbine | C58: 0 | D58: 0 | E58: 0 | F58: 0 | G58: 0 | H58: 0 | I58: 0 | J58: 0 | K58: 0 | L58: 0 | M58: 0 | N58: 0 | O58: 0 | P58: 0 | Q58: 0 | R58: 0 | S58: 0 | T58: 0 | U58: 0 | V58: 0 | W58: 0 | X58: 0 | Y58: 0 | Z58: 0 | AA58: 0 | AB58: 0 | AC58: 0 | AD58: 0 | AE58: 0 | AF58: 0 | AG58: 0
A59: commercial | B59: natural gas combined cycle | C59: 0 | D59: 0 | E59: 0 | F59: 0 | G59: 0 | H59: 0 | I59: 0 | J59: 0 | K59: 0 | L59: 0 | M59: 0 | N59: 0 | O59: 0 | P59: 0 | Q59: 0 | R59: 0 | S59: 0 | T59: 0 | U59: 0 | V59: 0 | W59: 0 | X59: 0 | Y59: 0 | Z59: 0 | AA59: 0 | AB59: 0 | AC59: 0 | AD59: 0 | AE59: 0 | AF59: 0 | AG59: 0
A60: commercial | B60: nuclear | C60: 0 | D60: 0 | E60: 0 | F60: 0 | G60: 0 | H60: 0 | I60: 0 | J60: 0 | K60: 0 | L60: 0 | M60: 0 | N60: 0 | O60: 0 | P60: 0 | Q60: 0 | R60: 0 | S60: 0 | T60: 0 | U60: 0 | V60: 0 | W60: 0 | X60: 0 | Y60: 0 | Z60: 0 | AA60: 0 | AB60: 0 | AC60: 0 | AD60: 0 | AE60: 0 | AF60: 0 | AG60: 0
A61: commercial | B61: hydro | C61: 0 | D61: 0 | E61: 0 | F61: 0 | G61: 0 | H61: 0 | I61: 0 | J61: 0 | K61: 0 | L61: 0 | M61: 0 | N61: 0 | O61: 0 | P61: 0 | Q61: 0 | R61: 0 | S61: 0 | T61: 0 | U61: 0 | V61: 0 | W61: 0 | X61: 0 | Y61: 0 | Z61: 0 | AA61: 0 | AB61: 0 | AC61: 0 | AD61: 0 | AE61: 0 | AF61: 0 | AG61: 0
A62: commercial | B62: onshore wind | C62: 0 | D62: 0 | E62: 0 | F62: 0 | G62: 0 | H62: 0 | I62: 0 | J62: 0 | K62: 0 | L62: 0 | M62: 0 | N62: 0 | O62: 0 | P62: 0 | Q62: 0 | R62: 0 | S62: 0 | T62: 0 | U62: 0 | V62: 0 | W62: 0 | X62: 0 | Y62: 0 | Z62: 0 | AA62: 0 | AB62: 0 | AC62: 0 | AD62: 0 | AE62: 0 | AF62: 0 | AG62: 0
A63: commercial | B63: solar PV | C63: 985.56973 | D63: 1320.6626 | E63: 1655.7555 | F63: 1990.8483 | G63: 2038.5589 | H63: 2086.2695 | I63: 2133.9801 | J63: 2181.6907 | K63: 2229.4013 | L63: 2595.5956 | M63: 2961.79 | N63: 3327.9843 | O63: 3694.1787 | P63: 4060.373 | Q63: 4575.6589 | R63: 5090.9448 | S63: 5606.2307 | T63: 6121.5165 | U63: 6636.8024 | V63: 7109.8017 | W63: 7582.801 | X63: 8055.8003 | Y63: 8528.7996 | Z63: 9001.7989 | AA63: 9266.2527 | AB63: 9530.7066 | AC63: 9795.1604 | AD63: 10059.614 | AE63: 10324.068 | AF63: 10588.522 | AG63: 10852.976
A64: commercial | B64: solar thermal | C64: 0 | D64: 0 | E64: 0 | F64: 0 | G64: 0 | H64: 0 | I64: 0 | J64: 0 | K64: 0 | L64: 0 | M64: 0 | N64: 0 | O64: 0 | P64: 0 | Q64: 0 | R64: 0 | S64: 0 | T64: 0 | U64: 0 | V64: 0 | W64: 0 | X64: 0 | Y64: 0 | Z64: 0 | AA64: 0 | AB64: 0 | AC64: 0 | AD64: 0 | AE64: 0 | AF64: 0 | AG64: 0
...

Sheet SYDEC
A1: MW | B1: urban residential | C1: rural residential | D1: commercial
A2: hard coal | B2: =SUMIFS(INDEX('BDEQ - Combined'!$G$3:$AJ$56,,MATCH(About!$A$28,'BDEQ - Combined'!$D$2:$AG$2,0)),'BDEQ - Combined'!$A$3:$A$56,SYDEC!B$1,'BDEQ - Combined'!$B$3:$B$56,SYDEC!$A2) -> 0 | C2: =SUMIFS(INDEX('BDEQ - Combined'!$G$3:$AJ$56,,MATCH(About!$A$28,'BDEQ - Combined'!$D$2:$AG$2,0)),'BDEQ - Combined'!$A$3:$A$56,SYDEC!C$1,'BDEQ - Combined'!$B$3:$B$56,SYDEC!$A2) -> 0 | D2: =SUMIFS(INDEX('BDEQ - Combined'!$G$3:$AJ$56,,MATCH(About!$A$28,'BDEQ - Combined'!$D$2:$AG$2,0)),'BDEQ - Combined'!$A$3:$A$56,SYDEC!D$1,'BDEQ - Combined'!$B$3:$B$56,SYDEC!$A2) -> 0
A3: natural gas steam turbine | B3: =SUMIFS(INDEX('BDEQ - Combined'!$G$3:$AJ$56,,MATCH(About!$A$28,'BDEQ - Combined'!$D$2:$AG$2,0)),'BDEQ - Combined'!$A$3:$A$56,SYDEC!B$1,'BDEQ - Combined'!$B$3:$B$56,SYDEC!$A3) -> 0 | C3: =SUMIFS(INDEX('BDEQ - Combined'!$G$3:$AJ$56,,MATCH(About!$A$28,'BDEQ - Combined'!$D$2:$AG$2,0)),'BDEQ - Combined'!$A$3:$A$56,SYDEC!C$1,'BDEQ - Combined'!$B$3:$B$56,SYDEC!$A3) -> 0 | D3: =SUMIFS(INDEX('BDEQ - Combined'!$G$3:$AJ$56,,MATCH(About!$A$28,'BDEQ - Combined'!$D$2:$AG$2,0)),'BDEQ - Combined'!$A$3:$A$56,SYDEC!D$1,'BDEQ - Combined'!$B$3:$B$56,SYDEC!$A3) -> 0
A4: natural gas combined cycle | B4: =SUMIFS(INDEX('BDEQ - Combined'!$G$3:$AJ$56,,MATCH(About!$A$28,'BDEQ - Combined'!$D$2:$AG$2,0)),'BDEQ - Combined'!$A$3:$A$56,SYDEC!B$1,'BDEQ - Combined'!$B$3:$B$56,SYDEC!$A4) -> 0 | C4: =SUMIFS(INDEX('BDEQ - Combined'!$G$3:$AJ$56,,MATCH(About!$A$28,'BDEQ - Combined'!$D$2:$AG$2,0)),'BDEQ - Combined'!$A$3:$A$56,SYDEC!C$1,'BDEQ - Combined'!$B$3:$B$56,SYDEC!$A4) -> 0 | D4: =SUMIFS(INDEX('BDEQ - Combined'!$G$3:$AJ$56,,MATCH(About!$A$28,'BDEQ - Combined'!$D$2:$AG$2,0)),'BDEQ - Combined'!$A$3:$A$56,SYDEC!D$1,'BDEQ - Combined'!$B$3:$B$56,SYDEC!$A4) -> 0
A5: nuclear | B5: =SUMIFS(INDEX('BDEQ - Combined'!$G$3:$AJ$56,,MATCH(About!$A$28,'BDEQ - Combined'!$D$2:$AG$2,0)),'BDEQ - Combined'!$A$3:$A$56,SYDEC!B$1,'BDEQ - Combined'!$B$3:$B$56,SYDEC!$A5) -> 0 | C5: =SUMIFS(INDEX('BDEQ - Combined'!$G$3:$AJ$56,,MATCH(About!$A$28,'BDEQ - Combined'!$D$2:$AG$2,0)),'BDEQ - Combined'!$A$3:$A$56,SYDEC!C$1,'BDEQ - Combined'!$B$3:$B$56,SYDEC!$A5) -> 0 | D5: =SUMIFS(INDEX('BDEQ - Combined'!$G$3:$AJ$56,,MATCH(About!$A$28,'BDEQ - Combined'!$D$2:$AG$2,0)),'BDEQ - Combined'!$A$3:$A$56,SYDEC!D$1,'BDEQ - Combined'!$B$3:$B$56,SYDEC!$A5) -> 0
A6: hydro | B6: =SUMIFS(INDEX('BDEQ - Combined'!$G$3:$AJ$56,,MATCH(About!$A$28,'BDEQ - Combined'!$D$2:$AG$2,0)),'BDEQ - Combined'!$A$3:$A$56,SYDEC!B$1,'BDEQ - Combined'!$B$3:$B$56,SYDEC!$A6) -> 0 | C6: =SUMIFS(INDEX('BDEQ - Combined'!$G$3:$AJ$56,,MATCH(About!$A$28,'BDEQ - Combined'!$D$2:$AG$2,0)),'BDEQ - Combined'!$A$3:$A$56,SYDEC!C$1,'BDEQ - Combined'!$B$3:$B$56,SYDEC!$A6) -> 0 | D6: =SUMIFS(INDEX('BDEQ - Combined'!$G$3:$AJ$56,,MATCH(About!$A$28,'BDEQ - Combined'!$D$2:$AG$2,0)),'BDEQ - Combined'!$A$3:$A$56,SYDEC!D$1,'BDEQ - Combined'!$B$3:$B$56,SYDEC!$A6) -> 0
A7: onshore wind | B7: =SUMIFS(INDEX('BDEQ - Combined'!$G$3:$AJ$56,,MATCH(About!$A$28,'BDEQ - Combined'!$D$2:$AG$2,0)),'BDEQ - Combined'!$A$3:$A$56,SYDEC!B$1,'BDEQ - Combined'!$B$3:$B$56,SYDEC!$A7) -> 0 | C7: =SUMIFS(INDEX('BDEQ - Combined'!$G$3:$AJ$56,,MATCH(About!$A$28,'BDEQ - Combined'!$D$2:$AG$2,0)),'BDEQ - Combined'!$A$3:$A$56,SYDEC!C$1,'BDEQ - Combined'!$B$3:$B$56,SYDEC!$A7) -> 0 | D7: =SUMIFS(INDEX('BDEQ - Combined'!$G$3:$AJ$56,,MATCH(About!$A$28,'BDEQ - Combined'!$D$2:$AG$2,0)),'BDEQ - Combined'!$A$3:$A$56,SYDEC!D$1,'BDEQ - Combined'!$B$3:$B$56,SYDEC!$A7) -> 0
A8: solar PV | B8: =SUMIFS(INDEX('BDEQ - Combined'!$G$3:$AJ$56,,MATCH(About!$A$28,'BDEQ - Combined'!$D$2:$AG$2,0)),'BDEQ - Combined'!$A$3:$A$56,SYDEC!B$1,'BDEQ - Combined'!$B$3:$B$56,SYDEC!$A8) -> 259.26994 | C8: =SUMIFS(INDEX('BDEQ - Combined'!$G$3:$AJ$56,,MATCH(About!$A$28,'BDEQ - Combined'!$D$2:$AG$2,0)),'BDEQ - Combined'!$A$3:$A$56,SYDEC!C$1,'BDEQ - Combined'!$B$3:$B$56,SYDEC!$A8) -> 436.15322 | D8: =SUMIFS(INDEX('BDEQ - Combined'!$G$3:$AJ$56,,MATCH(About!$A$28,'BDEQ - Combined'!$D$2:$AG$2,0)),'BDEQ - Combined'!$A$3:$A$56,SYDEC!D$1,'BDEQ - Combined'!$B$3:$B$56,SYDEC!$A8) -> 0
A9: solar thermal | B9: =SUMIFS(INDEX('BDEQ - Combined'!$G$3:$AJ$56,,MATCH(About!$A$28,'BDEQ - Combined'!$D$2:$AG$2,0)),'BDEQ - Combined'!$A$3:$A$56,SYDEC!B$1,'BDEQ - Combined'!$B$3:$B$56,SYDEC!$A9) -> 0 | C9: =SUMIFS(INDEX('BDEQ - Combined'!$G$3:$AJ$56,,MATCH(About!$A$28,'BDEQ - Combined'!$D$2:$AG$2,0)),'BDEQ - Combined'!$A$3:$A$56,SYDEC!C$1,'BDEQ - Combined'!$B$3:$B$56,SYDEC!$A9) -> 0 | D9: =SUMIFS(INDEX('BDEQ - Combined'!$G$3:$AJ$56,,MATCH(About!$A$28,'BDEQ - Combined'!$D$2:$AG$2,0)),'BDEQ - Combined'!$A$3:$A$56,SYDEC!D$1,'BDEQ - Combined'!$B$3:$B$56,SYDEC!$A9) -> 0
A10: biomass | B10: =SUMIFS(INDEX('BDEQ - Combined'!$G$3:$AJ$56,,MATCH(About!$A$28,'BDEQ - Combined'!$D$2:$AG$2,0)),'BDEQ - Combined'!$A$3:$A$56,SYDEC!B$1,'BDEQ - Combined'!$B$3:$B$56,SYDEC!$A10) -> 0 | C10: =SUMIFS(INDEX('BDEQ - Combined'!$G$3:$AJ$56,,MATCH(About!$A$28,'BDEQ - Combined'!$D$2:$AG$2,0)),'BDEQ - Combined'!$A$3:$A$56,SYDEC!C$1,'BDEQ - Combined'!$B$3:$B$56,SYDEC!$A10) -> 0 | D10: =SUMIFS(INDEX('BDEQ - Combined'!$G$3:$AJ$56,,MATCH(About!$A$28,'BDEQ - Combined'!$D$2:$AG$2,0)),'BDEQ - Combined'!$A$3:$A$56,SYDEC!D$1,'BDEQ - Combined'!$B$3:$B$56,SYDEC!$A10) -> 0
A11: geothermal | B11: =SUMIFS(INDEX('BDEQ - Combined'!$G$3:$AJ$56,,MATCH(About!$A$28,'BDEQ - Combined'!$D$2:$AG$2,0)),'BDEQ - Combined'!$A$3:$A$56,SYDEC!B$1,'BDEQ - Combined'!$B$3:$B$56,SYDEC!$A11) -> 0 | C11: =SUMIFS(INDEX('BDEQ - Combined'!$G$3:$AJ$56,,MATCH(About!$A$28,'BDEQ - Combined'!$D$2:$AG$2,0)),'BDEQ - Combined'!$A$3:$A$56,SYDEC!C$1,'BDEQ - Combined'!$B$3:$B$56,SYDEC!$A11) -> 0 | D11: =SUMIFS(INDEX('BDEQ - Combined'!$G$3:$AJ$56,,MATCH(About!$A$28,'BDEQ - Combined'!$D$2:$AG$2,0)),'BDEQ - Combined'!$A$3:$A$56,SYDEC!D$1,'BDEQ - Combined'!$B$3:$B$56,SYDEC!$A11) -> 0
A12: petroleum | B12: =SUMIFS(INDEX('BDEQ - Combined'!$G$3:$AJ$56,,MATCH(About!$A$28,'BDEQ - Combined'!$D$2:$AG$2,0)),'BDEQ - Combined'!$A$3:$A$56,SYDEC!B$1,'BDEQ - Combined'!$B$3:$B$56,SYDEC!$A12) -> 0 | C12: =SUMIFS(INDEX('BDEQ - Combined'!$G$3:$AJ$56,,MATCH(About!$A$28,'BDEQ - Combined'!$D$2:$AG$2,0)),'BDEQ - Combined'!$A$3:$A$56,SYDEC!C$1,'BDEQ - Combined'!$B$3:$B$56,SYDEC!$A12) -> 0 | D12: =SUMIFS(INDEX('BDEQ - Combined'!$G$3:$AJ$56,,MATCH(About!$A$28,'BDEQ - Combined'!$D$2:$AG$2,0)),'BDEQ - Combined'!$A$3:$A$56,SYDEC!D$1,'BDEQ - Combined'!$B$3:$B$56,SYDEC!$A12) -> 0
A13: natural gas peaker | B13: =SUMIFS(INDEX('BDEQ - Combined'!$G$3:$AJ$56,,MATCH(About!$A$28,'BDEQ - Combined'!$D$2:$AG$2,0)),'BDEQ - Combined'!$A$3:$A$56,SYDEC!B$1,'BDEQ - Combined'!$B$3:$B$56,SYDEC!$A13) -> 0 | C13: =SUMIFS(INDEX('BDEQ - Combined'!$G$3:$AJ$56,,MATCH(About!$A$28,'BDEQ - Combined'!$D$2:$AG$2,0)),'BDEQ - Combined'!$A$3:$A$56,SYDEC!C$1,'BDEQ - Combined'!$B$3:$B$56,SYDEC!$A13) -> 0 | D13: =SUMIFS(INDEX('BDEQ - Combined'!$G$3:$AJ$56,,MATCH(About!$A$28,'BDEQ - Combined'!$D$2:$AG$2,0)),'BDEQ - Combined'!$A$3:$A$56,SYDEC!D$1,'BDEQ - Combined'!$B$3:$B$56,SYDEC!$A13) -> 0
... A25: hydrogen combined cycle | B25: =SUMIFS(INDEX('BDEQ - Combined'!$G$3:$AJ$56,,MATCH(About!$A$28,'BDEQ - Combined'!$D$2:$AG$2,0)),'BDEQ - Combined'!$A$3:$A$56,SYDEC!B$1,'BDEQ - Combined'!$B$3:$B$56,SYDEC!$A25) -> 0 | C25: =SUMIFS(INDEX('BDEQ - Combined'!$G$3:$AJ$56,,MATCH(About!$A$28,'BDEQ - Combined'!$D$2:$AG$2,0)),'BDEQ - Combined'!$A$3:$A$56,SYDEC!C$1,'BDEQ - Combined'!$B$3:$B$56,SYDEC!$A25) -> 0 | D25: =SUMIFS(INDEX('BDEQ - Combined'!$G$3:$AJ$56,,MATCH(About!$A$28,'BDEQ - Combined'!$D$2:$AG$2,0)),'BDEQ - Combined'!$A$3:$A$56,SYDEC!D$1,'BDEQ - Combined'!$B$3:$B$56,SYDEC!$A25) -> 0
