Workbook
Name base.year: '[1]Target Year Input'!$E$3
Name BTU_to_PJ: [2]Notes!$A$11
Name Eno_TM: '[3]1997 Table 1a Modified'!#REF!
Name Eno_Tons: '[3]1997 Table 1a Modified'!#REF!
Name MWh_to_PJ: [2]Notes!$A$12
Name Sum_T2: '[3]1997 Table 1a Modified'!#REF!
Name Sum_TTM: '[3]1997 Table 1a Modified'!#REF!
Name ti_tbl_50: #REF!
Name ti_tbl_69: #REF!
Name TWh_to_PJ: [2]Notes!$A$15

Sheet About
A1: SYVbT Start Year Vehicles by Technology
A3: Sources: | B3: All on-road modes (vehicle count, not by technology)
B4: Ministry of Road Transport and Highways
B6: Road Transport Year Book
B7: https://morth.nic.in/sites/default/files/RTYB_Publication_2019_20%20(1).pdf
B8: Table 2.3 - Page 23
B10: Division of on-road modes by technology
B11: NITI Aayog, Government of India
B12: 2023
B13: India Energy Security Scenarios 2047 downloadable Excel model
B14: https://iess2047.gov.in/_/theme/documents/IESS2047_Version_3.0.xlsx
B15: Tabs XIIa and XIIb (Table 12.1)
B17: Rail
B18: Ministry of Railways
B19: 2022
B20: Railway Year Book 2021-22
B21: https://iritm.indianrailways.gov.in/uploads/files/1680252282408-PDF%20Year%20Book%202021-22-English.pdf
B22: Tables - Key statistics - Page 3; Other important statistics - Page 4
B24: aircraft (count, and psgr traffic vs. freight traffic)
B25: Directorate General of Civil Aviation (DGCA)
B26: 2023
B27: Handbook of Civil Aviation Statistics 2022-23
B28: https://www.dgca.gov.in/digigov-portal/?page=jsp/dgca/InventoryList/dataReports/aviationDataStatistics/handbookCivilAviation/HANDBOOK%202022-23.pdf&mainnull
B29: Table 8 (aircraft), Tables 1 and 5 (psgr vs. freight)
B31: Vehicle loading
B32: See AVLo
B34: Ships
B35: Ministry of Shipping/Ministry of Statistics & Programme Implementation
B36: 2018
B37: SHIPPING - Statistical Year Book India 2018
B38: http://www.mospi.gov.in/statistical-year-book-india/2018/191
B39: Sr. No 22.1 - Strength of Indian Merchant Shipping Fleet
A42: Notes:
A43: Fleet sizes for each vehicle type are updated for latest available sources in govt. sources.
A44: The govt. reports don't give a breakdown of the vehicle fleet by technology type, so
A45: we use IESS Level 2 (BAU) trajectory values on "Vehicle Km by type of Vehicle" to determine
A46: the ratios for various technologies like diesel, electric, CNG etc. The ratios are for year 2021,
A47: and applied to the base year fleet of each vehicle type to disaggregate by technology.
A49: We assume jet fuel to be most similar to diesel, and apportion aircrafts to diesel technology type.
A50: We assume maritime heavy fuel oil to be closest to diesel, and apportion ships to diesel technology type.
...

Sheet India Ships
A1: Number of Ships (2016 - latest year available)*
A2: Passenger | B2: =F18+O18 -> 101 | C2: Categories: Passenger cum cargo
A3: Freight | B3: =R18-B2 -> 1200 | C3: Categories: all other categories
A4: *Includes both coastal and overseas
C7: SHIPPING | K7: SHIPPING
C9: Table 22.1 - STRENGTH OF INDIAN MERCHANT SHIPPING FLEET | K9: Table 22.1 - STRENGTH OF INDIAN MERCHANT SHIPPING FLEET
C10: (As on 31st December) | K10: (As on 31st December)
A12: Year | B12: Item | C12: Coastal Shipping | K12: Overseas Shipping | R12: Total
C13: Type of Vessels | K13: Type of Vessels
C14: Dry Cargo Liner (1) | D14: Dry Cargo Bulk Carrier (2) | E14: Oil Tanker (3) | F14: Passenger-cum-Cargo (4) | G14: Off-shore Supply | H14: Specialised for Off-shore Services (5) | I14: Timber Carrier | J14: Total | K14: Dry Cargo Liner (6) | L14: Dry Cargo Bulk Carrier (7) | M14: Oil Tanker (8) | N14: Ore/Oil Bulk Carrier (9) | O14: Passenger-cum-Cargo (10) | P14: Timber Carrier | Q14: Total
A17: 1 | B17: 2 | C17: 3 | D17: 4 | E17: 5 | F17: 6 | G17: 7 | H17: 8 | I17: 9 | J17: 10 | K17: 11 | L17: 12 | M17: 13 | N17: 14 | O17: 15 | P17: 16 | Q17: 17 | R17: 18
A18: 2016 | B18: No. Of Vessels | C18: 586 | D18: 37 | E18: 22 | F18: 96 | G18: 100 | H18: 57 | I18: - | J18: =SUM(C18:I18) -> 898 | K18: 155 | L18: 85 | M18: 128 | N18: 30 | O18: 5 | P18: 0 | Q18: =SUM(K18:P18) -> 403 | R18: =(J18+Q18) -> 1301

Sheet India Aircraft
A1: Aircraft Statistics - 2021
A2: Total Fleet (Passenger + Freight) | B2: 620
A5: Total Passengers | B5: =105.35*10^6 -> 105350000
A6: (Domestic & Intnl.)
A8: Freight Transported (MT) | B8: =(6.05+14.26)*10^5 -> 2031000
A12: Psgr/aircraft | B12: ='India AVLo'!B4 -> 155 | C12: (from AVLo)
A13: Freight MT/aircraft | B13: ='India AVLo'!C4 -> 17.34 | C13: (from AVLo)
A16: Psr aircraft scaling factor | B16: =B5/B12 -> 679677.42
A17: Frgt aircraft scaling factor | B17: =B8/B13 -> 117128.03
A20: Psrg aircraft (est.) | B20: =B2*(B16/SUM(B16:B17)) -> 528.86185
A21: Freight aircraft (est.) | B21: =B2*(B17/SUM(B16:B17)) -> 91.138154

Sheet India Road
K1: Passenger Vehicle Breakdown by Technology (Vehicle KM)
K2: Vehicle Km by type of Vehicle under Chosen Scenario
K3: Mode | L3: Sub-mode | M3: Technology | O3: 2021 | P3: 2020 | Q3: 2022
K4: ROAD | L4: BUS | M4: CV | O4: =AVERAGE(P4,Q4) -> 104.74413 | P4: 112.33148 | Q4: 97.15677
M5: NGV | O5: =AVERAGE(P5,Q5) -> 2.0377197 | P5: 1.8296892 | Q5: 2.2457502
M6: EV | O6: =AVERAGE(P6,Q6) -> 0.92532264 | P6: 0.19440448 | Q6: 1.6562408
M7: FCV | O7: =AVERAGE(P7,Q7) -> 0 | P7: 0 | Q7: 0
H8: Number from table | I8: EPS Classification | L8: OMNI-BUS | M8: CV | O8: =AVERAGE(P8,Q8) -> 11.25282 | P8: 11.982279 | Q8: 10.523361
H9: 1632594 | I9: Frgt HDV | J9: heavy 3+ axle truck | M9: NGV | O9: =AVERAGE(P9,Q9) -> 0.21700055 | P9: 0.1948338 | Q9: 0.2391673
H10: 5826471 | I10: Frgt HDV | J10: heavy 2-axle truck | L10: CAR | M10: CV | O10: =AVERAGE(P10,Q10) -> 284.06234 | P10: 303.59966 | Q10: 264.52503
H11: 6829196 | I11: Frgt LDV | J11: light truck | M11: NGV | O11: =AVERAGE(P11,Q11) -> 6.7071769 | P11: 6.2289632 | Q11: 7.1853907
H12: 1817717 | I12: Frgt Mtrbk | J12: frgt rickshaws | M12: EV | O12: =AVERAGE(P12,Q12) -> 3.5299488 | P12: 1.6195304 | Q12: 5.4403672
I13: not used | M13: FCV | O13: =AVERAGE(P13,Q13) -> 0 | P13: 0 | Q13: 0
I14: not used | M14: Hybrid | O14: =AVERAGE(P14,Q14) -> 0 | P14: 0 | Q14: 0
I15: not used | L15: 2W | M15: CV | O15: =AVERAGE(P15,Q15) -> 980.7577 | P15: 1056.5783 | Q15: 904.93712
I16: not used | M16: EV | O16: =AVERAGE(P16,Q16) -> 30.008641 | P16: 9.5955646 | Q16: 50.421717
I17: not used | L17: 3W | M17: CV | O17: =AVERAGE(P17,Q17) -> 170.32435 | P17: 186.11609 | Q17: 154.53261
H18: 1723423 | I18: Psgr HDV | J18: buses | M18: NGV | O18: =AVERAGE(P18,Q18) -> 40.782363 | P18: 43.819154 | Q18: 37.745571
I19: not used | M19: EV | O19: =AVERAGE(P19,Q19) -> 5.1108519 | P19: 0.69188139 | Q19: 9.5298223
I20: not used | L20: TAXI | M20: CV | O20: =AVERAGE(P20,Q20) -> 82.801943 | P20: 89.80152 | Q20: 75.802365
I21: not used | M21: NGV | O21: =AVERAGE(P21,Q21) -> 3.5168946 | P21: 3.7468038 | Q21: 3.2869854
H22: 3458917 | I22: Taxi | J22: taxis | M22: EV | O22: =AVERAGE(P22,Q22) -> 0.85648543 | P22: 0.12177112 | Q22: 1.5911997
I23: not used
I24: not used
H25: 8202990 | I25: Frgt Mtrbk | J25: psgr rickshaws
H26: 54372 | I26: Psgr Mtrbk | J26: hired 2-whl mtrbks
I27: not used
I28: not used
I29: not used | K29: Freight Vehcile Breakdown by Technology ("Modal Share")
I30: not used | K30: Mode | L30: Type | M30: Technology | N30: 2007 | O30: 2021 | P30: 2020 | Q30: 2022
H31: 243682349 | I31: Psgr Mtrbk | J31: 2-whl motorbikes | K31: ROAD | L31: HCV | M31: DIESEL | O31: =AVERAGE(P31,Q31) -> 275.00463 | P31: 272.5035 | Q31: 277.50575
H32: 37729158 | I32: Psgr LDV | J32: cars | M32: LNG | O32: =AVERAGE(P32,Q32) -> 2.1713301 | P32: 0.9651836 | Q32: 3.3774765
I33: not used | M33: ELECTRIC | O33: =AVERAGE(P33,Q33) -> 0 | P33: 0 | Q33: 0
H34: 471815 | I34: Psgr HDV | J34: omnibuses | L34: LCV | M34: DIESEL | O34: =AVERAGE(P34,Q34) -> 171.11752 | P34: 169.70199 | Q34: 172.53306
I35: not used | M35: CNG | O35: =AVERAGE(P35,Q35) -> 5.1470583 | P35: 3.4633059 | Q35: 6.8308108
I36: not used | M36: ELECTRIC | O36: =AVERAGE(P36,Q36) -> 1.3220924 | P36: 0 | Q36: 2.6441848
I37: not used
I38: not used
I39: not used
K41: LPG vehicle | L41: hydrogen vehicle
...

Sheet India Rail
A1: Ministry of Railways Data (2021):
A2: Steam locomotives | B2: 39
A3: Diesel locomotives | B3: 4747
A4: Electric locomotives | B4: 8429
A5: total | B5: =SUM(B2:B4) -> 13215
A7: Ministry of Railways Data: | E7: Rail Fleet Breakdown by Technology (Vehicle KM)
A8: Passenger Cars | B8: 74744 | E8: Vehicle Km by type of Vehicle under Chosen Scenario
A9: Freight Cars | B9: 318896 | E9: Mode | F9: Sub-mode | G9: Technology | H9: 2021 | I9: 2020 | J9: 2022
E10: RAIL | F10: RAIL-Passenger | G10: DIESEL | H10: =AVERAGE(I10,J10) -> 0.345 | I10: 0.42 | J10: 0.27
A11: Assumption: | E11: RAIL | F11: RAIL-Passenger | G11: ELECTRIC | H11: =AVERAGE(I11,J11) -> 0.65 | I11: 0.63 | J11: 0.67
A12: Number of Cars per Train | E12: RAIL | F12: RAIL-frieght | G12: DIESEL | H12: 0.1
A13: Passenger | B13: 10 | E13: RAIL | F13: RAIL-frieght | G13: ELECTRIC | H13: 0.3
A14: Freight | B14: 50
E15: Passenger diesel rail | G15: =B23*(H10/SUM(H10:H11)) -> 2472.3901
A16: Calculations | E16: Passenger electric rail | G16: =B23*(H11/SUM(H10:H11)) -> 4658.1263
A17: Number of Trains that could be supplied with these cars
A18: Passenger | B18: =B8/B13 -> 7474.4 | E18: Freight diesel rail | G18: =B24*(H12/SUM(H12:H13)) -> 1521.1209
A19: Freight | B19: =B9/B14 -> 6377.92 | E19: Freight electric rail | G19: =B24*(H13/SUM(H12:H13)) -> 4563.3626
A22: Number of Locomotives by Type:
A23: Passenger locomotives | B23: =SUM(B2:B4)*B18/SUM(B18:B19) -> 7130.5165
A24: Freight locomotives | B24: =SUM(B2:B4)*B19/SUM(B18:B19) -> 6084.4835

Sheet India AVLo
A1: Vehicle Loading | B1: (passengers) | C1: (tons)
A2: LDVs | B2: 3 | C2: 1.7
A3: HDVs | B3: 41 | C3: 6.1
A4: aircraft | B4: 155 | C4: 17.34
A5: rail | B5: 1000 | C5: 1728
A6: ships | B6: 3 | C6: 1974.4736
A7: motorbikes | B7: 2 | C7: 2

Sheet SYVbT-passenger
A1: Number of Vehicles | B1: battery electric vehicle | C1: natural gas vehicle | D1: gasoline vehicle | E1: diesel vehicle | F1: plugin hybrid vehicle | G1: LPG vehicle | H1: hydrogen vehicle
A2: LDVs | B2: ='India Road'!$B44*'India Road'!F44 -> 452539.03 | C2: ='India Road'!$B44*'India Road'!G44 -> 859859.3 | D2: ='India Road'!$B44*'India Road'!H44 -> 36416760 | E2: ='India Road'!$B44*'India Road'!I44 -> 0 | F2: ='India Road'!$B44*'India Road'!J44 -> 0 | G2: ='India Road'!$B44*'India Road'!K42 -> 0 | H2: ='India Road'!$B44*'India Road'!L42 -> 0
A3: HDVs | B3: ='India Road'!$B45*'India Road'!F45 -> 17044.427 | C3: ='India Road'!$B45*'India Road'!G45 -> 41531.907 | D3: ='India Road'!$B45*'India Road'!H45 -> 0 | E3: ='India Road'!$B45*'India Road'!I45 -> 2136661.7 | F3: ='India Road'!$B45*'India Road'!J45 -> 0 | G3: ='India Road'!$B45*'India Road'!K43 -> 0 | H3: ='India Road'!$B45*'India Road'!L43 -> 0
A4: aircraft | B4: 0 | C4: 0 | D4: 0 | E4: ='India Aircraft'!B20 -> 528.86185 | F4: 0 | G4: 0 | H4: 0
A5: rail | B5: ='India Rail'!G16 -> 4658.1263 | C5: 0 | D5: 0 | E5: ='India Rail'!G15 -> 2472.3901 | F5: 0 | G5: 0 | H5: 0
A6: ships | B6: ='India Road'!$B$47*'India Road'!F47 -> 33983.379 | C6: ='India Road'!$B$47*'India Road'!G47 -> 139542.32 | D6: ='India Road'!$B$47*'India Road'!H47 -> 0 | E6: ='India Road'!$B$47*'India Road'!I47+'India Road'!$B$47*'India Road'!K45 -> 3285391.3 | F6: ='India Road'!$B$47*'India Road'!J47 -> 0 | G6: 0 | H6: ='India Road'!$B$47*'India Road'!L45 -> 0
A7: motorbikes | B7: ='India Road'!$B46*'India Road'!F46 -> 7236299.2 | C7: ='India Road'!$B46*'India Road'!G46 -> 0 | D7: ='India Road'!$B46*'India Road'!H46 -> 2.3650042e+08 | E7: ='India Road'!$B46*'India Road'!I46 -> 0 | F7: ='India Road'!$B46*'India Road'!J46 -> 0 | G7: ='India Road'!$B46*'India Road'!K44 -> 0 | H7: ='India Road'!$B46*'India Road'!L44 -> 0

Sheet SYVbT-freight
A1: Number of Vehicles | B1: battery electric vehicle | C1: natural gas vehicle | D1: gasoline vehicle | E1: diesel vehicle | F1: plugin hybrid vehicle | G1: LPG vehicle | H1: hydrogen vehicle
A2: LDVs | B2: ='India Road'!$C44*'India Road'!F51 -> 50841.811 | C2: ='India Road'!$C44*'India Road'!G51 -> 197933.04 | D2: ='India Road'!$C44*'India Road'!H51 -> 0 | E2: ='India Road'!$C44*'India Road'!I51 -> 6580421.1 | F2: ='India Road'!$C44*'India Road'!J51 -> 0 | G2: ='India Road'!$C44*'India Road'!K49 -> 0 | H2: ='India Road'!$C44*'India Road'!L49 -> 0
A3: HDVs | B3: ='India Road'!$C45*'India Road'!$F45 -> 57914.215 | C3: ='India Road'!$C45*'India Road'!G52 -> 58432.528 | D3: ='India Road'!$C45*'India Road'!H52 -> 0 | E3: ='India Road'!$C45*'India Road'!I52 -> 7400632.5 | F3: ='India Road'!$C45*'India Road'!J52 -> 0 | G3: ='India Road'!$C45*'India Road'!K50 -> 0 | H3: ='India Road'!$C45*'India Road'!L50 -> 0
A4: aircraft | B4: 0 | C4: 0 | D4: 0 | E4: ='India Aircraft'!B21 -> 91.138154 | F4: 0 | G4: 0 | H4: 0
A5: rail | B5: ='India Rail'!G19 -> 4563.3626 | C5: 0 | D5: 0 | E5: ='India Rail'!G18 -> 1521.1209 | F5: 0 | G5: 0 | H5: 0
A6: ships | B6: 0 | C6: 0 | D6: 0 | E6: ='India Ships'!B3 -> 1200 | F6: 0 | G6: 0 | H6: 0
A7: motorbikes | B7: ='India Road'!$C46*'India Road'!F53 -> 236864.89 | C7: ='India Road'!$C46*'India Road'!G53 -> 1890078.2 | D7: ='India Road'!$C46*'India Road'!H53 -> 7893763.9 | E7: ='India Road'!$C46*'India Road'!I53 -> 0 | F7: ='India Road'!$C46*'India Road'!J53 -> 0 | G7: ='India Road'!$C46*'India Road'!K51 -> 0 | H7: ='India Road'!$C46*'India Road'!L51 -> 0
