Workbook
Name INRCr: [2]Conversions!$E$116
Name INRLac: [1]Conversions!$E$113
Name plantsize.iv.a: 'India Calcs'!$E$100
Name Preferences.PowerUnits: [1]Preferences!$C$5
Name Unit.kW: [1]Conversions!$F$57
Name Unit.MW: [2]Conversions!$F$66

Sheet About
A1: CpUDSC Cost per Unit Distributed Solar Capacity
A3: Sources: | B3: Cost Scaling | D3: Benchmark Capital Costs
B4: NITI Aayog, Government of India | D4: Ministry of New & Renewable Energy
B5: 2023 | D5: 2019
B6: India Energy Security Scenarios 2047 downloadable Excel model | D6: Benchmark costs for Grid Connected Rooftop Solar Power Plants for the Year 2019- 20
B7: http://indiaenergy.gov.in/iess/docs/IESS_Version2.2.xlsx | D7: https://mnre.gov.in/sites/default/files/uploads/benchmark%20cost%202019-20%20%281%29.pdf
B8: Tab IV.e (updated 2070)
B10: Solar DC to AC Derate Value | D10: O&M Costs
B11: Jens Schoene, EnerNex | D11: Karnataka Electricity Regulatory Commission
B12: 2015 | D12: 2019
B13: Production Levels of Utility-Scale and Residential-Scale PV Systems | D13: Generic Tariff Order for Solar PV Plants (Ground Mounted & Solar Rooftop PV) for FY19
B14: http://brattle.com/system/publications/pdfs/000/005/188/original/Comparative_Generation_Costs_of_Utility-Scale_and_Residential-Scale_PV_in_Xcel_Energy_Colorado's_Service_Area.pdf?1436797265 | D14: https://bescom.org/wp-content/uploads/2018/06/OMNew-SRTPV-tariff-for-entering-into-PPAs-from-01.04.2018-to-31.03.2019.pdf
B15: This document is included as Appendix B of a report by Brattle Group. | D15: Table 2(b), Page 22
B16: Page 10 of the EnerNex report (Page 70 of the PDF)
D17: Share of Costs that are Soft Costs
D18: NREL
D19: 2018
D20: U.S. Solar Photovoltaic System Cost Benchmark: Q1 2018
D21: https://www.nrel.gov/docs/fy17osti/68925.pdf
D22: Page viii, Figure ES-2
A25: Notes
A26: We assume solar capacities are reported in DC, as is typical when most sources
A27: report distributed solar PV capacities. Accordingly, we convert to AC using an
A28: appropriate derate factor.
A30: We use scaling factors from IESS's level 2 trajectory to project future costs.
A31: Since IESS was developed in 2015-16 and PV module costs have declined
A32: substantially since then, we estimate the base year cost from the most
A33: recent benchmark costs from MNRE.
A35: Benchmark (capital) costs are available for systems ranging residential,
A36: commercial, and industrial scales. We take an average of residential and
A37: commercial scales for the buildings sector.
A39: O&M costs are estimated from a representative tariff order from a
... A41: available here for future reference.

Sheet India Data
A1: Benchmark costs for Grid Connected Rooftop Solar Power Plants for the Year 2019- 20
B3: Capacity | C3: Capital (Installation) Cost
A4: Residential | B4: 1-10 kW | C4: 54000 | D4: INR/kW
A5: Commercial | B5: 10-100 kW | C5: 48000
A6: Industrial | B6: 100-500 kW | C6: 45000
B7: Average | C7: =AVERAGE(C4:C5) -> 51000
C8: =C7*1000 -> 51000000 | D8: INR/MW
A9: Source: MNRE, 2019
C10: O&M Cost
C11: 600 | D11: INR/kW
C12: =C11*1000 -> 600000 | D12: INR/MW
A13: Source: KERC, 2019
A14: Total Cost | C14: =C8+C12 -> 51600000 | D14: INR/MW

Sheet India Calcs
A1: Capital cost of a 0.0001 GW solar plant
L2: Trillion INR
C3: Delta | D3: 2007 | E3: 2012 | F3: 2020 | G3: 2022 | H3: 2027 | I3: 2032 | J3: 2037 | K3: 2042 | L3: 2047 | M3: 2050 | N3: 2055 | O3: 2060 | P3: 2065 | Q3: 2070
A4: Low estimate | E4: 1e-05 | F4: 0.043 | G4: 0.036 | H4: 0.0333 | I4: 0.0306 | J4: 0.0279 | K4: 0.0234 | L4: 0.0189 | M4: 0.01755 | N4: 0.0162 | O4: 0.0162 | P4: 0.0162 | Q4: 0.0162
A5: Point estimate | C5: 0 | E5: 1e-05 | F5: 0.043 | G5: 0.04 | H5: 0.037 | I5: 0.034 | J5: 0.031 | K5: 0.026 | L5: 0.021 | M5: 0.0195 | N5: 0.018 | O5: 0.018 | P5: 0.018 | Q5: 0.018
A6: High estimate | E6: 1e-05 | F6: 0.043 | G6: 0.044 | H6: 0.0407 | I6: 0.0374 | J6: 0.0341 | K6: 0.0286 | L6: 0.0231 | M6: 0.02145 | N6: 0.0198 | O6: 0.0198 | P6: 0.0198 | Q6: 0.0198
A7: 5yr decline rate | F7: =0 -> 0 | G7: =0 -> 0 | H7: =0 -> 0 | I7: =0 -> 0 | J7: =0 -> 0 | K7: =0 -> 0 | L7: =0 -> 0 | M7: =0 -> 0 | ... Q7: =0 -> 0
A8: Yearly decline rate | F8: =F7/5 -> 0 | G8: =G7/5 -> 0 | H8: =H7/5 -> 0 | I8: =I7/5 -> 0 | J8: =J7/5 -> 0 | K8: =K7/5 -> 0 | L8: =L7/5 -> 0 | M8: =M7/5 -> 0 | ... Q8: =Q7/5 -> 0
Q9: 43 | R9: =0.9*R10 -> 36 | S9: =0.9*S10 -> 33.3 | T9: =0.9*T10 -> 30.6 | U9: =0.9*U10 -> 27.9 | V9: =0.9*V10 -> 23.4 | W9: =0.9*W10 -> 18.9 | X9: =0.9*X10 -> 17.55 | Y9: =0.9*Y10 -> 16.2 | ... AB9: =0.9*AB10 -> 16.2
Q10: 43 | R10: 40 | S10: 37 | T10: 34 | U10: 31 | V10: 26 | W10: 21 | X10: 19.5 | Y10: 18 | Z10: 18 | AA10: 18 | AB10: 18
B11: 2018-19 | C11: 2022 | D11: 2027 | E11: 2032 | F11: 2037 | G11: 2042 | H11: 2047 | Q11: 43 | R11: =1.1*R10 -> 44 | S11: =1.1*S10 -> 40.7 | T11: =1.1*T10 -> 37.4 | U11: =1.1*U10 -> 34.1 | V11: =1.1*V10 -> 28.6 | W11: =1.1*W10 -> 23.1 | X11: =1.1*X10 -> 21.45 | Y11: =1.1*Y10 -> 19.8 | ... AB11: =1.1*AB10 -> 19.8
A12: Cap Cost (INR/MW DC) | B12: ='India Data'!C8 -> 51000000 | C12: =B12*(1+3*G8) -> 51000000 | D12: =C12*(1+H7) -> 51000000 | E12: =D12*(1+I7) -> 51000000 | F12: =E12*(1+J7) -> 51000000 | G12: =F12*(1+K7) -> 51000000 | H12: =G12*(1+L7) -> 51000000
A13: Cap Cost (INR/MW AC) | B13: =B12/'AC DC Derate Factor'!$A$3 -> 59371362 | C13: =C12/'AC DC Derate Factor'!$A$3 -> 59371362 | D13: =D12/'AC DC Derate Factor'!$A$3 -> 59371362 | E13: =E12/'AC DC Derate Factor'!$A$3 -> 59371362 | F13: =F12/'AC DC Derate Factor'!$A$3 -> 59371362 | G13: =G12/'AC DC Derate Factor'!$A$3 -> 59371362 | H13: =H12/'AC DC Derate Factor'!$A$3 -> 59371362 | Q13: =Q9/1000 -> 0.043 | R13: =R9/1000 -> 0.036 | S13: =S9/1000 -> 0.0333 | T13: =T9/1000 -> 0.0306 | U13: =U9/1000 -> 0.0279 | V13: =V9/1000 -> 0.0234 | W13: =W9/1000 -> 0.0189 | X13: =X9/1000 -> 0.01755 | ... AB13: =AB9/1000 -> 0.0162
Q14: =Q10/1000 -> 0.043 | R14: =R10/1000 -> 0.04 | S14: =S10/1000 -> 0.037 | T14: =T10/1000 -> 0.034 | U14: =U10/1000 -> 0.031 | V14: =V10/1000 -> 0.026 | W14: =W10/1000 -> 0.021 | X14: =X10/1000 -> 0.0195 | ... AB14: =AB10/1000 -> 0.018
Q15: =Q11/1000 -> 0.043 | R15: =R11/1000 -> 0.044 | S15: =S11/1000 -> 0.0407 | T15: =T11/1000 -> 0.0374 | U15: =U11/1000 -> 0.0341 | V15: =V11/1000 -> 0.0286 | W15: =W11/1000 -> 0.0231 | X15: =X11/1000 -> 0.02145 | ... AB15: =AB11/1000 -> 0.0198
A16: Currency Conversion (for data sources, see scaling-factors.xlsx)
A17: India Inflation Rates | Q17: 0.043 | R17: 0.036 | S17: 0.0333 | T17: 0.0306 | U17: 0.0279 | V17: 0.0234 | W17: 0.0189 | X17: 0.01755 | Y17: 0.0162 | Z17: 0.0162 | AA17: 0.0162 | AB17: 0.0162
A18: Year | B18: Rate | C18: Value Indexed to 2012 | Q18: 0.043 | R18: 0.04 | S18: 0.037 | T18: 0.034 | U18: 0.031 | V18: 0.026 | W18: 0.021 | X18: 0.0195 | Y18: 0.018 | Z18: 0.018 | AA18: 0.018 | AB18: 0.018
A19: 2010 | B19: 0.0947 | C19: =C20/(1+B20) -> 0.84470209 | Q19: 0.043 | R19: 0.044 | S19: 0.0407 | T19: 0.0374 | U19: 0.0341 | V19: 0.0286 | W19: 0.0231 | X19: 0.02145 | Y19: 0.0198 | Z19: 0.0198 | AA19: 0.0198 | AB19: 0.0198
A20: 2011 | B20: 0.0649 | C20: =C21/(1+B21) -> 0.89952325
A21: 2012 | B21: 0.1117 | C21: 1
A22: 2013 | B22: 0.0913 | C22: =C21*(1+B22) -> 1.0913
A23: 2014 | B23: 0.0586 | C23: =C22*(1+B23) -> 1.1552502
A24: 2015 | B24: 0.0632 | C24: =C23*(1+B24) -> 1.228262
A25: 2016 | B25: 0.0223 | C25: =C24*(1+B25) -> 1.2556522
A26: 2017 | B26: 0.04 | C26: =C25*(1+B26) -> 1.3058783
A27: 2018 | B27: 0.0524 | C27: =C26*(1+B27) -> 1.3743063
A28: 2019 | B28: 0.0737 | C28: =C27*(1+B28) -> 1.4755927 | D28: (2019 value is a current average, as Dec. vs. Dec Inflation rate is not available at the time of data updation)
A29: Rupees per dollar
A30: 2010 | B30: 44.81
A31: 2011 | B31: 53.26
A32: 2012 | B32: 54.77
A33: 2013 | B33: 61.89
A34: 2014 | B34: 63.33
A35: 2015 | B35: 66.32
A36: 2016 | B36: 67.95
A37: 2017 | B37: 63.92
A38: 2018 | B38: 68.6573
B39: 2017 | C39: 2022 | D39: 2027 | E39: 2032 | F39: 2037 | G39: 2042 | H39: 2047
A40: Cap Cost (2012USD/MW) | B40: =B13/$C$28/$B$32 -> 734628.49 | C40: =C13/$C$28/$B$32 -> 734628.49 | D40: =D13/$C$28/$B$32 -> 734628.49 | E40: =E13/$C$28/$B$32 -> 734628.49 | F40: =F13/$C$28/$B$32 -> 734628.49 | G40: =G13/$C$28/$B$32 -> 734628.49 | H40: =H13/$C$28/$B$32 -> 734628.49
...

Sheet Soft Cost Data
A1: Solar PV
A3: Solar PV Type | B3: Non-Hardware Cost %
A4: Residential | B4: 0.63
A5: Commercial | B5: 0.56
A6: Utility-Scale | B6: 0.35
A8: For distributed PV on buildings, we use the average
A9: of residential and commercial soft cost shares.
A10: Buildings | B10: =AVERAGE(B4:B5) -> 0.595

Sheet AC DC Derate Factor
A1: Watts DC are lower than Watts AC, but AC is needed to either sell to the grid or to power devices in homes.
A2: Therefore, we convert to the cost per Watt AC using a derate factor:
A3: 0.859 | B3: DC to AC derate factor

Sheet CpUDSC-totalcost
A1: Unit: $/MW | B1: Distributed Solar Cap Cost ($/MW)
A2: 2020 | B2: ='India Calcs'!B57 -> 734628.49
A3: 2021 | B3: ='India Calcs'!B58 -> 734628.49
A4: 2022 | B4: ='India Calcs'!B59 -> 734628.49
A5: 2023 | B5: ='India Calcs'!B60 -> 734628.49
A6: 2024 | B6: ='India Calcs'!B61 -> 734628.49
A7: 2025 | B7: ='India Calcs'!B62 -> 734628.49
A8: 2026 | B8: ='India Calcs'!B63 -> 734628.49
A9: 2027 | B9: ='India Calcs'!B64 -> 734628.49
A10: 2028 | B10: ='India Calcs'!B65 -> 734628.49
A11: 2029 | B11: ='India Calcs'!B66 -> 734628.49
A12: 2030 | B12: ='India Calcs'!B67 -> 734628.49
A13: 2031 | B13: ='India Calcs'!B68 -> 734628.49
... A52: 2070 | B52: ='India Calcs'!B107 -> 734628.49

Sheet CpUDSC-softcosts
A1: Unit: $/MW | B1: Distributed Solar Soft Costs
A2: 2020 | B2: ='CpUDSC-totalcost'!B2*'Soft Cost Data'!$B$10 -> 437103.95
A3: 2021 | B3: ='CpUDSC-totalcost'!B3*'Soft Cost Data'!$B$10 -> 437103.95
A4: 2022 | B4: ='CpUDSC-totalcost'!B4*'Soft Cost Data'!$B$10 -> 437103.95
A5: 2023 | B5: ='CpUDSC-totalcost'!B5*'Soft Cost Data'!$B$10 -> 437103.95
A6: 2024 | B6: ='CpUDSC-totalcost'!B6*'Soft Cost Data'!$B$10 -> 437103.95
A7: 2025 | B7: ='CpUDSC-totalcost'!B7*'Soft Cost Data'!$B$10 -> 437103.95
A8: 2026 | B8: ='CpUDSC-totalcost'!B8*'Soft Cost Data'!$B$10 -> 437103.95
A9: 2027 | B9: ='CpUDSC-totalcost'!B9*'Soft Cost Data'!$B$10 -> 437103.95
A10: 2028 | B10: ='CpUDSC-totalcost'!B10*'Soft Cost Data'!$B$10 -> 437103.95
A11: 2029 | B11: ='CpUDSC-totalcost'!B11*'Soft Cost Data'!$B$10 -> 437103.95
A12: 2030 | B12: ='CpUDSC-totalcost'!B12*'Soft Cost Data'!$B$10 -> 437103.95
A13: 2031 | B13: ='CpUDSC-totalcost'!B13*'Soft Cost Data'!$B$10 -> 437103.95
... A52: 2070 | B52: ='CpUDSC-totalcost'!B52*'Soft Cost Data'!$B$10 -> 437103.95
