Workbook
Name BTU_per_GWh: '[1]Conversion Factors'!$A$3
Name BTU_per_PJ: '[1]Conversion Factors'!$A$6
Name BTU_per_thousand_tons_kerosene: '[1]Conversion Factors'!$A$21
Name BTU_per_thousand_tons_LPG: '[1]Conversion Factors'!$A$14
Name INRLac: [2]Conversions!$E$113
Name plantsize.iv.a: '[3]India Data'!$E$99
Name Preferences.PowerUnits: [2]Preferences!$C$5
Name Unit.kW: [2]Conversions!$F$57
Name Unit.MW: [2]Conversions!$F$56

Sheet About
A1: BDESC BAU Distributed Electricity Source Capacities
A3: Sources: | B3: Distributed Generation Quantity, Urban vs. Rural Shares | E3: Distributed Rooftop PV Capacity Factor projections
B4: NITI Aayog, Government of India | E4: See variable "bldgs/DSCF" for more info
B5: 2023
B6: India Energy Security Scenarios 2047 downloadable Excel model | E6: Back up electricity from diesel generators
B7: http://indiaenergy.gov.in/iess/docs/IESS_Version2.2.xlsx | E7: NITI Aayog, Government of India
B8: Tab IV.e | E8: 2023
E9: India Energy Security Scenarios 2047 downloadable Excel model
B10: Residential vs. Non-Residential Shares | E10: http://indiaenergy.gov.in/iess/docs/IESS_Version2.2.xlsx
B11: CPI, ICRIER, SEI | E11: Tab I.e
B12: 2018
B13: Scaling up Rooftop Solar Power in India: The Potential of Municipal Solar Bonds
B14: http://icrier.org/pdf/Working_Paper_353.pdf
B15: Page 3, Figure 2
B17: Solar DC to AC Derate Value
B18: Jens Schoene, EnerNex
B19: 2015
B20: Production Levels of Utility-Scale and Residential-Scale PV Systems
B21: http://brattle.com/system/publications/pdfs/000/005/188/original/Comparative_Generation_Costs_of_Utility-Scale_and_Residential-Scale_PV_in_Xcel_Energy_Colorado's_Service_Area.pdf?1436797265
B22: This document is included as Appendix B of a report by Brattle Group. It is on Page 10 of the EnerNex report, which is Page 70 of the PDF
A24: Notes
A25: The variable "BCEU BAU Components Energy Use" includes only "purchased electricity"
A26: (i.e. that which buildings get from the grid, not generate on-site), so the quantities
A27: of generation in this variable are additional. Electricity Output is reported in MWh and
A28: Capacity is reported in MW.
A30: For India, we only have data for solar PV, which likely dominates distributed generation in buildings.
A31: The IESS BAU trajectory is used to scale the current (2021) breakdown of capacity by building type,
A32: assuming that the relative shares are constant through the model run.
A34: We assume capacities are given in DC, not AC, which is typical when reporting solar PV capacities.
A35: Accordingly, we convert to AC using an appropriate derate factor.

Sheet India Dist Solar PV Data
A1: Distributed Solar PV Cumulative Capacity
L2: GW
A3: Trajectory | B3: Description | C3: Notes | D3: 2007 | E3: 2012 | F3: 2017 | G3: 2022 | H3: 2027 | I3: 2032 | J3: 2037 | K3: 2042 | L3: 2047
A4: 1 | D4: 0 | E4: 0.033019625 | F4: 0.40244397 | G4: 0.76878176 | H4: 1.1534866 | I4: 1.4638898 | J4: 2.097696 | K4: 2.3636373 | L4: 2.4519923
A5: 2 | D5: 0 | E5: 0.033019625 | F5: 0.48953669 | G5: 3.0901798 | H5: 3.4604599 | I5: 6.3024804 | J5: 10.301595 | K5: 13.972524 | L5: 16.024941
A6: 3 | D6: 0 | E6: 0.033019625 | F6: 1.7088347 | G6: 5.4836178 | H6: 6.9209197 | I6: 14.515772 | J6: 22.243969 | K6: 31.923417 | L6: 42.411501
A7: 4 | D7: 0 | E7: 0.033019625 | F7: 15.208206 | G7: 20.886135 | H7: 18.886385 | I7: 40.526799 | J7: 52.442399 | K7: 62.855911 | L7: 93.317985
A9: In the IESS model, we use Trajectory 2 (existing, but no additional policies) as our BAU case.
A11: First, we apply a derate factor to convert DC to AC.
B13: 2012 | C13: 2017 | D13: 2022 | E13: 2027 | F13: 2032 | G13: 2037 | H13: 2042 | I13: 2047
A14: Capacity (GW AC) | B14: =E5*'AC DC Derate Factor'!$A$3 -> 0.028363858 | C14: =F5*'AC DC Derate Factor'!$A$3 -> 0.42051201 | D14: =G5*'AC DC Derate Factor'!$A$3 -> 2.6544644 | E14: =H5*'AC DC Derate Factor'!$A$3 -> 2.972535 | F14: =I5*'AC DC Derate Factor'!$A$3 -> 5.4138307 | G14: =J5*'AC DC Derate Factor'!$A$3 -> 8.8490699 | H14: =K5*'AC DC Derate Factor'!$A$3 -> 12.002399 | I14: =L5*'AC DC Derate Factor'!$A$3 -> 13.765424
A16: IESS has a breakdown between residential and non-residential (showing residential has roughly 3x greater
A17: capacity than non-residential through 2047), but the India team considers this breakdown unreliable.
A18: Instead, we use the breakdown by building type based on existing (2016) installations, which show
A19: 3/4 of capacity on non-residential buildings. We assume the share is constant through the model run.
A21: 2016 Existing Distributed Solar PV Breakdown
A22: Building Type | B22: Capacity (GW) | C22: Share
A23: Residential | B23: =C23*B$27 -> 0.3125 | C23: 0.25
A24: Government | B24: =C24*B$27 -> 0.15 | C24: 0.12
A25: Commercial | B25: =C25*B$27 -> 0.325 | C25: 0.26
A26: Industrial | B26: =C26*B$27 -> 0.4625 | C26: 0.37
A27: Total | B27: 1.25 | C27: =SUM(C23:C26) -> 1
A29: For residential buildings, we use IESS to divide up by number of households:
A31: Number of households
M32: Millions
B33: Description | C33: Notes | D33: 2007 | E33: 2012 | F33: 2020 | G33: 2022 | H33: 2023 | I33: 2027 | J33: 2032 | K33: 2037 | L33: 2042 | M33: 2047 | N33: 2050 | O33: 2055 | P33: 2060 | Q33: 2065 | R33: 2070
B34: Urban | E34: 74.294157 | F34: 112.1599 | G34: 119.89051 | H34: 123.86955 | I34: 140.51693 | J34: 162.89154 | K34: 186.7537 | L34: 211.82321 | M34: 238.10599 | N34: 248.39926 | O34: 264.79732 | P34: 280.25103 | Q34: 294.5559 | R34: 307.44985
B35: Rural | E35: 173.35303 | F35: 195.00987 | G35: 197.3782 | H35: 198.48987 | I35: 202.38495 | J35: 205.85713 | K35: 207.47254 | L35: 207.04441 | M35: 204.75081 | N35: 198.85636 | O35: 188.02225 | P35: 176.20505 | Q35: 163.5557 | R35: 150.20291
A38: Capacity by Building Type (GW) | B38: 2012 | C38: 2017 | D38: 2022 | E38: 2027 | F38: 2032 | G38: 2037 | H38: 2042 | I38: 2047 | J38: 2050 | K38: 2055 | L38: 2060 | M38: 2065 | N38: 2070
A39: urban residential | B39: =B14*$C23*E34/SUM(E34:E35) -> 0.0021272894 | C39: =C14*$C23*F34/SUM(F34:F35) -> 0.038386414 | D39: =D14*$C23*G34/SUM(G34:G35) -> 0.25076937 | E39: =E14*$C23*H34/SUM(H34:H35) -> 0.28555593 | F39: =F14*$C23*I34/SUM(I34:I35) -> 0.55463013 | G39: =G14*$C23*J34/SUM(J34:J35) -> 0.97725002 | H39: =H14*$C23*K34/SUM(K34:K35) -> 1.4214505 | I39: =I14*$C23*L34/SUM(L34:L35) -> 1.740309
A40: rural residential | B40: =B14*$C23*E35/SUM(E34:E35) -> 0.0049636752 | C40: =C14*$C23*F35/SUM(F34:F35) -> 0.066741589 | D40: =D14*$C23*G35/SUM(G34:G35) -> 0.41284673 | E40: =E14*$C23*H35/SUM(H34:H35) -> 0.45757782 | F40: =F14*$C23*I35/SUM(I34:I35) -> 0.79882754 | G40: =G14*$C23*J35/SUM(J34:J35) -> 1.2350175 | H40: =H14*$C23*K35/SUM(K34:K35) -> 1.5791492 | I40: =I14*$C23*L35/SUM(L34:L35) -> 1.7010471
A41: commercial | B41: =B14*SUM($C24:$C26) -> 0.021272894 | C41: =C14*SUM($C24:$C26) -> 0.31538401 | D41: =D14*SUM($C24:$C26) -> 1.9908483 | E41: =E14*SUM($C24:$C26) -> 2.2294013 | F41: =F14*SUM($C24:$C26) -> 4.060373 | G41: =G14*SUM($C24:$C26) -> 6.6368024 | H41: =H14*SUM($C24:$C26) -> 9.0017989 | I41: =I14*SUM($C24:$C26) -> 10.324068
A44: Capacity by Building Type (MW) | B44: 2016 | C44: 2017 | D44: 2018 | E44: 2019 | F44: 2020 | G44: 2021 | H44: 2022 | I44: 2023 | J44: 2024 | K44: 2025 | L44: 2026 | M44: 2027 | N44: 2028 | O44: 2029 | P44: 2030 | Q44: 2031 | R44: 2032 | S44: 2033 | T44: 2034 | U44: 2035 | V44: 2036 | W44: 2037 | X44: 2038 | Y44: 2039 | Z44: 2040 | AA44: 2041 | AB44: 2042 | AC44: 2043 | AD44: 2044 | AE44: 2045 | AF44: 2046 | AG44: 2047 | AH44: 2048 | AI44: 2049 | AJ44: 2050 | AK44: 2051 | AL44: 2052 | AM44: 2053 | AN44: 2054 | AO44: 2055 | AP44: 2056 | AQ44: 2057 | AR44: 2058 | AS44: 2059 | AT44: 2060 | AU44: 2061 | AV44: 2062 | AW44: 2063 | AX44: 2064 | AY44: 2065 | AZ44: 2066 | BA44: 2067 | BB44: 2068 | BC44: 2069 | BD44: 2070
A45: urban residential | B45: =TREND($B39:$C39,$B$38:$C$38,B$44)*1000 -> 31.134589 | C45: =TREND($C39:$D39,$C$38:$D$38,C$44)*1000 -> 38.386414 | D45: =TREND($C39:$D39,$C$38:$D$38,D$44)*1000 -> 80.863006 | E45: =TREND($C39:$D39,$C$38:$D$38,E$44)*1000 -> 123.3396 | F45: =TREND($C39:$D39,$C$38:$D$38,F$44)*1000 -> 165.81619 | G45: =TREND($C39:$D39,$C$38:$D$38,G$44)*1000 -> 208.29278 | H45: =TREND($C39:$D39,$C$38:$D$38,H$44)*1000 -> 250.76937 | I45: =TREND($D39:$E39,$D$38:$E$38,I$44)*1000 -> 257.72668 | J45: =TREND($D39:$E39,$D$38:$E$38,J$44)*1000 -> 264.684 | K45: =TREND($D39:$E39,$D$38:$E$38,K$44)*1000 -> 271.64131 | L45: =TREND($D39:$E39,$D$38:$E$38,L$44)*1000 -> 278.59862 | M45: =TREND($D39:$E39,$D$38:$E$38,M$44)*1000 -> 285.55593 | N45: =TREND($E39:$F39,$E$38:$F$38,N$44)*1000 -> 339.37077 | O45: =TREND($E39:$F39,$E$38:$F$38,O$44)*1000 -> 393.18561 | P45: =TREND($E39:$F39,$E$38:$F$38,P$44)*1000 -> 447.00045 | Q45: =TREND($E39:$F39,$E$38:$F$38,Q$44)*1000 -> 500.81529 | R45: =TREND($E39:$F39,$E$38:$F$38,R$44)*1000 -> 554.63013 | S45: =TREND($F39:$G39,$F$38:$G$38,S$44)*1000 -> 639.15411 | T45: =TREND($F39:$G39,$F$38:$G$38,T$44)*1000 -> 723.67809 | U45: =TREND($F39:$G39,$F$38:$G$38,U$44)*1000 -> 808.20207 | V45: =TREND($F39:$G39,$F$38:$G$38,V$44)*1000 -> 892.72605 | W45: =TREND($F39:$G39,$F$38:$G$38,W$44)*1000 -> 977.25002 | X45: =TREND($G39:$H39,$G$38:$H$38,X$44)*1000 -> 1066.0901 | Y45: =TREND($G39:$H39,$G$38:$H$38,Y$44)*1000 -> 1154.9302 | Z45: =TREND($G39:$H39,$G$38:$H$38,Z$44)*1000 -> 1243.7703 | AA45: =TREND($G39:$H39,$G$38:$H$38,AA$44)*1000 -> 1332.6104 | AB45: =TREND($G39:$H39,$G$38:$H$38,AB$44)*1000 -> 1421.4505 | AC45: =TREND($H39:$I39,$H$38:$I$38,AC$44)*1000 -> 1485.2222 | AD45: =TREND($H39:$I39,$H$38:$I$38,AD$44)*1000 -> 1548.9939 | AE45: =TREND($H39:$I39,$H$38:$I$38,AE$44)*1000 -> 1612.7656 | AF45: =TREND($H39:$I39,$H$38:$I$38,AF$44)*1000 -> 1676.5373 | AG45: =TREND($H39:$I39,$H$38:$I$38,AG$44)*1000 -> 1740.309 | AH45: =TREND($H39:$I39,$H$38:$I$38,AH$44)*1000 -> 1804.0807 | AI45: =TREND($H39:$I39,$H$38:$I$38,AI$44)*1000 -> 1867.8524 | AJ45: =TREND($H39:$I39,$H$38:$I$38,AJ$44)*1000 -> 1931.6241 | ... BD45: =TREND($H39:$I39,$H$38:$I$38,BD$44)*1000 -> 3207.0581
A46: rural residential | B46: =TREND($B40:$C40,$B$38:$C$38,B$44)*1000 -> 54.386006 | C46: =TREND($C40:$D40,$C$38:$D$38,C$44)*1000 -> 66.741589 | D46: =TREND($C40:$D40,$C$38:$D$38,D$44)*1000 -> 135.96262 | E46: =TREND($C40:$D40,$C$38:$D$38,E$44)*1000 -> 205.18365 | F46: =TREND($C40:$D40,$C$38:$D$38,F$44)*1000 -> 274.40467 | G46: =TREND($C40:$D40,$C$38:$D$38,G$44)*1000 -> 343.6257 | H46: =TREND($C40:$D40,$C$38:$D$38,H$44)*1000 -> 412.84673 | I46: =TREND($D40:$E40,$D$38:$E$38,I$44)*1000 -> 421.79295 | J46: =TREND($D40:$E40,$D$38:$E$38,J$44)*1000 -> 430.73917 | K46: =TREND($D40:$E40,$D$38:$E$38,K$44)*1000 -> 439.68538 | L46: =TREND($D40:$E40,$D$38:$E$38,L$44)*1000 -> 448.6316 | M46: =TREND($D40:$E40,$D$38:$E$38,M$44)*1000 -> 457.57782 | N46: =TREND($E40:$F40,$E$38:$F$38,N$44)*1000 -> 525.82776 | O46: =TREND($E40:$F40,$E$38:$F$38,O$44)*1000 -> 594.07771 | P46: =TREND($E40:$F40,$E$38:$F$38,P$44)*1000 -> 662.32765 | Q46: =TREND($E40:$F40,$E$38:$F$38,Q$44)*1000 -> 730.57759 | R46: =TREND($E40:$F40,$E$38:$F$38,R$44)*1000 -> 798.82754 | S46: =TREND($F40:$G40,$F$38:$G$38,S$44)*1000 -> 886.06552 | T46: =TREND($F40:$G40,$F$38:$G$38,T$44)*1000 -> 973.3035 | U46: =TREND($F40:$G40,$F$38:$G$38,U$44)*1000 -> 1060.5415 | V46: =TREND($F40:$G40,$F$38:$G$38,V$44)*1000 -> 1147.7795 | W46: =TREND($F40:$G40,$F$38:$G$38,W$44)*1000 -> 1235.0175 | X46: =TREND($G40:$H40,$G$38:$H$38,X$44)*1000 -> 1303.8438 | Y46: =TREND($G40:$H40,$G$38:$H$38,Y$44)*1000 -> 1372.6701 | Z46: =TREND($G40:$H40,$G$38:$H$38,Z$44)*1000 -> 1441.4965 | AA46: =TREND($G40:$H40,$G$38:$H$38,AA$44)*1000 -> 1510.3228 | AB46: =TREND($G40:$H40,$G$38:$H$38,AB$44)*1000 -> 1579.1492 | AC46: =TREND($H40:$I40,$H$38:$I$38,AC$44)*1000 -> 1603.5287 | AD46: =TREND($H40:$I40,$H$38:$I$38,AD$44)*1000 -> 1627.9083 | AE46: =TREND($H40:$I40,$H$38:$I$38,AE$44)*1000 -> 1652.2879 | AF46: =TREND($H40:$I40,$H$38:$I$38,AF$44)*1000 -> 1676.6675 | AG46: =TREND($H40:$I40,$H$38:$I$38,AG$44)*1000 -> 1701.0471 | AH46: =TREND($H40:$I40,$H$38:$I$38,AH$44)*1000 -> 1725.4266 | AI46: =TREND($H40:$I40,$H$38:$I$38,AI$44)*1000 -> 1749.8062 | AJ46: =TREND($H40:$I40,$H$38:$I$38,AJ$44)*1000 -> 1774.1858 | ... BD46: =TREND($H40:$I40,$H$38:$I$38,BD$44)*1000 -> 2261.7775
A47: commercial | B47: =TREND($B41:$C41,$B$38:$C$38,B$44)*1000 -> 256.56179 | C47: =TREND($C41:$D41,$C$38:$D$38,C$44)*1000 -> 315.38401 | D47: =TREND($C41:$D41,$C$38:$D$38,D$44)*1000 -> 650.47687 | E47: =TREND($C41:$D41,$C$38:$D$38,E$44)*1000 -> 985.56973 | F47: =TREND($C41:$D41,$C$38:$D$38,F$44)*1000 -> 1320.6626 | G47: =TREND($C41:$D41,$C$38:$D$38,G$44)*1000 -> 1655.7555 | H47: =TREND($C41:$D41,$C$38:$D$38,H$44)*1000 -> 1990.8483 | I47: =TREND($D41:$E41,$D$38:$E$38,I$44)*1000 -> 2038.5589 | J47: =TREND($D41:$E41,$D$38:$E$38,J$44)*1000 -> 2086.2695 | K47: =TREND($D41:$E41,$D$38:$E$38,K$44)*1000 -> 2133.9801 | L47: =TREND($D41:$E41,$D$38:$E$38,L$44)*1000 -> 2181.6907 | M47: =TREND($D41:$E41,$D$38:$E$38,M$44)*1000 -> 2229.4013 | N47: =TREND($E41:$F41,$E$38:$F$38,N$44)*1000 -> 2595.5956 | O47: =TREND($E41:$F41,$E$38:$F$38,O$44)*1000 -> 2961.79 | P47: =TREND($E41:$F41,$E$38:$F$38,P$44)*1000 -> 3327.9843 | Q47: =TREND($E41:$F41,$E$38:$F$38,Q$44)*1000 -> 3694.1787 | R47: =TREND($E41:$F41,$E$38:$F$38,R$44)*1000 -> 4060.373 | S47: =TREND($F41:$G41,$F$38:$G$38,S$44)*1000 -> 4575.6589 | T47: =TREND($F41:$G41,$F$38:$G$38,T$44)*1000 -> 5090.9448 | U47: =TREND($F41:$G41,$F$38:$G$38,U$44)*1000 -> 5606.2307 | V47: =TREND($F41:$G41,$F$38:$G$38,V$44)*1000 -> 6121.5165 | W47: =TREND($F41:$G41,$F$38:$G$38,W$44)*1000 -> 6636.8024 | X47: =TREND($G41:$H41,$G$38:$H$38,X$44)*1000 -> 7109.8017 | Y47: =TREND($G41:$H41,$G$38:$H$38,Y$44)*1000 -> 7582.801 | Z47: =TREND($G41:$H41,$G$38:$H$38,Z$44)*1000 -> 8055.8003 | AA47: =TREND($G41:$H41,$G$38:$H$38,AA$44)*1000 -> 8528.7996 | AB47: =TREND($G41:$H41,$G$38:$H$38,AB$44)*1000 -> 9001.7989 | AC47: =TREND($H41:$I41,$H$38:$I$38,AC$44)*1000 -> 9266.2527 | AD47: =TREND($H41:$I41,$H$38:$I$38,AD$44)*1000 -> 9530.7066 | AE47: =TREND($H41:$I41,$H$38:$I$38,AE$44)*1000 -> 9795.1604 | AF47: =TREND($H41:$I41,$H$38:$I$38,AF$44)*1000 -> 10059.614 | AG47: =TREND($H41:$I41,$H$38:$I$38,AG$44)*1000 -> 10324.068 | AH47: =TREND($H41:$I41,$H$38:$I$38,AH$44)*1000 -> 10588.522 | AI47: =TREND($H41:$I41,$H$38:$I$38,AI$44)*1000 -> 10852.976 | AJ47: =TREND($H41:$I41,$H$38:$I$38,AJ$44)*1000 -> 11117.43 | ... BD47: =TREND($H41:$I41,$H$38:$I$38,BD$44)*1000 -> 16406.507
A51: Capacity Utilization factor
A53: Fuel | B53: Plant type | C53: Notes | D53: 2007 | E53: 2012 | F53: 2017 | G53: 2022 | H53: 2027 | I53: 2032 | J53: 2037 | K53: 2042 | L53: 2047 | M53: 2050 | N53: 2055 | O53: 2060 | P53: 2065 | Q53: 2070
A54: R.01 | B54: Solar | D54: 0 | E54: 0.16 | F54: 0.17 | G54: 0.1725 | H54: 0.175 | I54: 0.1775 | J54: 0.18 | K54: 0.185 | L54: 0.19 | M54: 0.19 | N54: 0.19 | O54: 0.19 | P54: 0.19 | Q54: 0.19
A57: Capacity Factor (interpolated) | B57: 2016 | C57: 2017 | D57: 2018 | E57: 2019 | F57: 2020 | G57: 2021 | H57: 2022 | I57: 2023 | J57: 2024 | K57: 2025 | L57: 2026 | M57: 2027 | N57: 2028 | O57: 2029 | P57: 2030 | Q57: 2031 | R57: 2032 | S57: 2033 | T57: 2034 | U57: 2035 | V57: 2036 | W57: 2037 | X57: 2038 | Y57: 2039 | Z57: 2040 | AA57: 2041 | AB57: 2042 | AC57: 2043 | AD57: 2044 | AE57: 2045 | AF57: 2046 | AG57: 2047 | AH57: 2048 | AI57: 2049 | AJ57: 2050 | AK57: 2051 | AL57: 2052 | AM57: 2053 | AN57: 2054 | AO57: 2055 | AP57: 2056 | AQ57: 2057 | AR57: 2058 | AS57: 2059 | AT57: 2060 | AU57: 2061 | AV57: 2062 | AW57: 2063 | AX57: 2064 | AY57: 2065 | AZ57: 2066 | BA57: 2067 | BB57: 2068 | BC57: 2069 | BD57: 2070
...

Sheet AC DC Derate Factor
A1: Watts DC are lower than Watts AC, but AC is needed to either sell to the grid or to power devices in homes.
A2: Therefore, we convert to the cost per Watt AC using a derate factor:
A3: 0.859 | B3: DC to AC derate factor

Sheet DSCF
B1: 2017 | C1: 2018 | D1: 2019 | E1: 2020 | F1: 2021 | G1: 2022 | H1: 2023 | I1: 2024 | J1: 2025 | K1: 2026 | L1: 2027 | M1: 2028 | N1: 2029 | O1: 2030 | P1: 2031 | Q1: 2032 | R1: 2033 | S1: 2034 | T1: 2035 | U1: 2036 | V1: 2037 | W1: 2038 | X1: 2039 | Y1: 2040 | Z1: 2041 | AA1: 2042 | AB1: 2043 | AC1: 2044 | AD1: 2045 | AE1: 2046 | AF1: 2047 | AG1: 2048 | AH1: 2049 | AI1: 2050 | AJ1: 2051 | AK1: 2052 | AL1: 2053 | AM1: 2054 | AN1: 2055 | AO1: 2056 | AP1: 2057 | AQ1: 2058 | AR1: 2059 | AS1: 2060 | AT1: 2061 | AU1: 2062 | AV1: 2063 | AW1: 2064 | AX1: 2065 | AY1: 2066 | AZ1: 2067 | BA1: 2068 | BB1: 2069 | BC1: 2070
A2: Capacity Factor | B2: 0.179075 | C2: 0.18271667 | D2: 0.18635833 | E2: 0.19 | F2: 0.190934 | G2: 0.191868 | H2: 0.192802 | I2: 0.193736 | J2: 0.19467 | K2: 0.195604 | L2: 0.196538 | M2: 0.197472 | N2: 0.198406 | O2: 0.19934 | P2: 0.200274 | Q2: 0.201208 | R2: 0.202142 | S2: 0.203076 | T2: 0.20401 | U2: 0.204944 | V2: 0.205878 | W2: 0.206812 | X2: 0.207746 | Y2: 0.20868 | Z2: 0.209614 | AA2: 0.210548 | AB2: 0.211482 | AC2: 0.212416 | AD2: 0.21335 | AE2: 0.214284 | AF2: 0.215218 | AG2: 0.216152 | AH2: 0.217086 | AI2: 0.21802 | AJ2: 0.218954 | AK2: 0.219888 | AL2: 0.220822 | AM2: 0.221756 | AN2: 0.22269 | AO2: 0.223624 | AP2: 0.224558 | AQ2: 0.225492 | AR2: 0.226426 | AS2: 0.22736 | AT2: 0.228294 | AU2: 0.229228 | AV2: 0.230162 | AW2: 0.231096 | AX2: 0.23203 | AY2: 0.232964 | AZ2: 0.233898 | BA2: 0.234832 | BB2: 0.235766 | BC2: 0.2367

Sheet Back up generators
A1: Back up electricity by diesel
A2: Load factor
A4: Fuel | B4: Plant type | C4: Notes | D4: 2007 | E4: 2012 | F4: 2017 | G4: 2022 | H4: 2027 | I4: 2032 | J4: 2037 | K4: 2042 | L4: 2047 | M4: 2052
A5: V.04 | B5: Local diesel geneators | C5: [1] | D5: 0.1 | E5: 0.1 | F5: 0.1 | G5: 0.1 | H5: 0.1 | I5: 0.1 | J5: 0.1 | K5: 0.1 | L5: 0.1 | M5: 0.1
D7: 2007 | E7: 2012 | F7: 2017 | G7: 2022 | H7: 2027 | I7: 2032 | J7: 2037 | K7: 2042 | L7: 2047 | M7: 2052
A8: Electricity supplied | C8: TWh | D8: 0 | E8: -13.178832 | F8: -16.150921 | G8: -19.756173 | H8: -20.56745 | I8: -18.182206 | J8: -12.518809 | K8: 0 | L8: 0
A9: Own-use requirements | C9: TWh | D9: 0 | E9: 0 | F9: 0 | G9: 0 | H9: 0 | I9: 0 | J9: 0 | K9: 0 | L9: 0
A11: Installed Capacity | D11: 2007 | E11: 2012 | F11: 2017 | G11: 2022 | H11: 2027 | I11: 2032 | J11: 2037 | K11: 2042 | L11: 2047
A12: Diesel backup generators | C12: GW | D12: 0 | E12: 15.034032 | F12: 18.424505 | G12: 22.537273 | H12: 23.462754 | I12: 20.741736 | J12: 14.281096 | K12: 0 | L12: 0
A14: Interpolations
B15: 2017 | C15: 2018 | D15: 2019 | E15: 2020 | F15: 2021 | G15: 2022 | H15: 2023 | I15: 2024 | J15: 2025 | K15: 2026 | L15: 2027 | M15: 2028 | N15: 2029 | O15: 2030 | P15: 2031 | Q15: 2032 | R15: 2033 | S15: 2034 | T15: 2035 | U15: 2036 | V15: 2037 | W15: 2038 | X15: 2039 | Y15: 2040 | Z15: 2041 | AA15: 2042 | AB15: 2043 | AC15: 2044 | AD15: 2045 | AE15: 2046 | AF15: 2047 | AG15: 2048 | AH15: 2049 | AI15: 2050
A16: Electricity supplied (TWh) | B16: =TREND($F8:$G8,$F7:$G7,B$15) -> -16.150921 | C16: =TREND($F8:$G8,$F7:$G7,C$15) -> -16.871972 | D16: =TREND($F8:$G8,$F7:$G7,D$15) -> -17.593022 | E16: =TREND($F8:$G8,$F7:$G7,E$15) -> -18.314073 | F16: =TREND($F8:$G8,$F7:$G7,F$15) -> -19.035123 | G16: =TREND($F8:$G8,$F7:$G7,G$15) -> -19.756173 | H16: =TREND($G8:$H8,$G7:$H7,H$15) -> -19.918429 | I16: =TREND($G8:$H8,$G7:$H7,I$15) -> -20.080684 | J16: =TREND($G8:$H8,$G7:$H7,J$15) -> -20.242939 | K16: =TREND($G8:$H8,$G7:$H7,K$15) -> -20.405195 | L16: =TREND($G8:$H8,$G7:$H7,L$15) -> -20.56745 | M16: =TREND($H8:$I8,$H7:$I7,M$15) -> -20.090401 | N16: =TREND($H8:$I8,$H7:$I7,N$15) -> -19.613352 | O16: =TREND($H8:$I8,$H7:$I7,O$15) -> -19.136304 | P16: =TREND($H8:$I8,$H7:$I7,P$15) -> -18.659255 | Q16: =TREND($H8:$I8,$H7:$I7,Q$15) -> -18.182206 | R16: =TREND($I8:$J8,$I7:$J7,R$15) -> -17.049526 | S16: =TREND($I8:$J8,$I7:$J7,S$15) -> -15.916847 | T16: =TREND($I8:$J8,$I7:$J7,T$15) -> -14.784168 | U16: =TREND($I8:$J8,$I7:$J7,U$15) -> -13.651488 | V16: =TREND($I8:$J8,$I7:$J7,V$15) -> -12.518809 | W16: =TREND($J8:$K8,$J7:$K7,W$15) -> -10.015047 | X16: =TREND($J8:$K8,$J7:$K7,X$15) -> -7.5112852 | Y16: =TREND($J8:$K8,$J7:$K7,Y$15) -> -5.0075235 | Z16: =TREND($J8:$K8,$J7:$K7,Z$15) -> -2.5037617 | AA16: =TREND($J8:$K8,$J7:$K7,AA$15) -> 0 | AB16: =AA16 -> 0 | AC16: =AB16 -> 0 | AD16: =AC16 -> 0 | AE16: =AD16 -> 0 | AF16: =AE16 -> 0 | AG16: =AF16 -> 0 | AH16: =AG16 -> 0 | AI16: =AH16 -> 0
A17: Electricity supplied (MWh) | B17: =-B16*1000000 -> 16150921 | C17: =-C16*1000000 -> 16871972 | D17: =-D16*1000000 -> 17593022 | E17: =-E16*1000000 -> 18314073 | F17: =-F16*1000000 -> 19035123 | G17: =-G16*1000000 -> 19756173 | H17: =-H16*1000000 -> 19918429 | I17: =-I16*1000000 -> 20080684 | ... AI17: =-AI16*1000000 -> 0
A18: Installed capacity (GW) | B18: =TREND($F12:$G12,$F11:$G11,B$15) -> 18.424505 | C18: =TREND($F12:$G12,$F11:$G11,C$15) -> 19.247059 | D18: =TREND($F12:$G12,$F11:$G11,D$15) -> 20.069612 | E18: =TREND($F12:$G12,$F11:$G11,E$15) -> 20.892166 | F18: =TREND($F12:$G12,$F11:$G11,F$15) -> 21.714719 | G18: =TREND($F12:$G12,$F11:$G11,G$15) -> 22.537273 | H18: =TREND($G12:$H12,$G11:$H11,H$15) -> 22.722369 | I18: =TREND($G12:$H12,$G11:$H11,I$15) -> 22.907465 | J18: =TREND($G12:$H12,$G11:$H11,J$15) -> 23.092562 | K18: =TREND($G12:$H12,$G11:$H11,K$15) -> 23.277658 | L18: =TREND($G12:$H12,$G11:$H11,L$15) -> 23.462754 | M18: =TREND($H12:$I12,$H11:$I11,M$15) -> 22.91855 | N18: =TREND($H12:$I12,$H11:$I11,N$15) -> 22.374347 | O18: =TREND($H12:$I12,$H11:$I11,O$15) -> 21.830143 | P18: =TREND($H12:$I12,$H11:$I11,P$15) -> 21.28594 | Q18: =TREND($H12:$I12,$H11:$I11,Q$15) -> 20.741736 | R18: =TREND($I12:$J12,$I11:$J11,R$15) -> 19.449608 | S18: =TREND($I12:$J12,$I11:$J11,S$15) -> 18.15748 | T18: =TREND($I12:$J12,$I11:$J11,T$15) -> 16.865352 | U18: =TREND($I12:$J12,$I11:$J11,U$15) -> 15.573224 | V18: =TREND($I12:$J12,$I11:$J11,V$15) -> 14.281096 | W18: =TREND($J12:$K12,$J11:$K11,W$15) -> 11.424877 | X18: =TREND($J12:$K12,$J11:$K11,X$15) -> 8.5686575 | Y18: =TREND($J12:$K12,$J11:$K11,Y$15) -> 5.7124384 | Z18: =TREND($J12:$K12,$J11:$K11,Z$15) -> 2.8562192 | AA18: =TREND($J12:$K12,$J11:$K11,AA$15) -> 0 | AB18: =AA18 -> 0 | AC18: =AB18 -> 0 | AD18: =AC18 -> 0 | AE18: =AD18 -> 0 | AF18: =AE18 -> 0 | AG18: =AF18 -> 0 | AH18: =AG18 -> 0 | AI18: =AH18 -> 0
A19: Installed capacity (MW) | B19: =B18*1000 -> 18424.505 | C19: =C18*1000 -> 19247.059 | D19: =D18*1000 -> 20069.612 | E19: =E18*1000 -> 20892.166 | F19: =F18*1000 -> 21714.719 | G19: =G18*1000 -> 22537.273 | H19: =H18*1000 -> 22722.369 | I19: =I18*1000 -> 22907.465 | ... AI19: =AI18*1000 -> 0

Sheet BDESC-urban-residential
A1: MW | B1: 2020 | C1: 2021 | D1: 2022 | E1: 2023 | F1: 2024 | G1: 2025 | H1: 2026 | I1: 2027 | J1: 2028 | K1: 2029 | L1: 2030 | M1: 2031 | N1: 2032 | O1: 2033 | P1: 2034 | Q1: 2035 | R1: 2036 | S1: 2037 | T1: 2038 | U1: 2039 | V1: 2040 | W1: 2041 | X1: 2042 | Y1: 2043 | Z1: 2044 | AA1: 2045 | AB1: 2046 | AC1: 2047 | AD1: 2048 | AE1: 2049 | AF1: 2050 | AG1: 2051 | AH1: 2052 | AI1: 2053 | AJ1: 2054 | AK1: 2055 | AL1: 2056 | AM1: 2057 | AN1: 2058 | AO1: 2059 | AP1: 2060 | AQ1: 2061 | AR1: 2062 | AS1: 2063 | AT1: 2064 | AU1: 2065 | AV1: 2066 | AW1: 2067 | AX1: 2068 | AY1: 2069 | AZ1: 2070
A2: hard coal | B2: 0 | C2: 0 | D2: 0 | E2: 0 | F2: 0 | G2: 0 | H2: 0 | I2: 0 | J2: 0 | K2: 0 | L2: 0 | M2: 0 | N2: 0 | O2: 0 | P2: 0 | Q2: 0 | R2: 0 | S2: 0 | T2: 0 | U2: 0 | V2: 0 | W2: 0 | X2: 0 | Y2: 0 | Z2: 0 | AA2: 0 | AB2: 0 | AC2: 0 | AD2: 0 | AE2: 0 | AF2: 0 | AG2: 0 | AH2: 0 | AI2: 0 | AJ2: 0 | AK2: 0 | AL2: 0 | AM2: 0 | AN2: 0 | AO2: 0 | AP2: 0 | AQ2: 0 | AR2: 0 | AS2: 0 | AT2: 0 | AU2: 0 | AV2: 0 | AW2: 0 | AX2: 0 | AY2: 0 | AZ2: 0
A3: natural gas steam turbine | B3: 0 | C3: 0 | D3: 0 | E3: 0 | F3: 0 | G3: 0 | H3: 0 | I3: 0 | J3: 0 | K3: 0 | L3: 0 | M3: 0 | N3: 0 | O3: 0 | P3: 0 | Q3: 0 | R3: 0 | S3: 0 | T3: 0 | U3: 0 | V3: 0 | W3: 0 | X3: 0 | Y3: 0 | Z3: 0 | AA3: 0 | AB3: 0 | AC3: 0 | AD3: 0 | AE3: 0 | AF3: 0 | AG3: 0 | AH3: 0 | AI3: 0 | AJ3: 0 | AK3: 0 | AL3: 0 | AM3: 0 | AN3: 0 | AO3: 0 | AP3: 0 | AQ3: 0 | AR3: 0 | AS3: 0 | AT3: 0 | AU3: 0 | AV3: 0 | AW3: 0 | AX3: 0 | AY3: 0 | AZ3: 0
A4: natural gas combined cycle | B4: 0 | C4: 0 | D4: 0 | E4: 0 | F4: 0 | G4: 0 | H4: 0 | I4: 0 | J4: 0 | K4: 0 | L4: 0 | M4: 0 | N4: 0 | O4: 0 | P4: 0 | Q4: 0 | R4: 0 | S4: 0 | T4: 0 | U4: 0 | V4: 0 | W4: 0 | X4: 0 | Y4: 0 | Z4: 0 | AA4: 0 | AB4: 0 | AC4: 0 | AD4: 0 | AE4: 0 | AF4: 0 | AG4: 0 | AH4: 0 | AI4: 0 | AJ4: 0 | AK4: 0 | AL4: 0 | AM4: 0 | AN4: 0 | AO4: 0 | AP4: 0 | AQ4: 0 | AR4: 0 | AS4: 0 | AT4: 0 | AU4: 0 | AV4: 0 | AW4: 0 | AX4: 0 | AY4: 0 | AZ4: 0
A5: nuclear | B5: 0 | C5: 0 | D5: 0 | E5: 0 | F5: 0 | G5: 0 | H5: 0 | I5: 0 | J5: 0 | K5: 0 | L5: 0 | M5: 0 | N5: 0 | O5: 0 | P5: 0 | Q5: 0 | R5: 0 | S5: 0 | T5: 0 | U5: 0 | V5: 0 | W5: 0 | X5: 0 | Y5: 0 | Z5: 0 | AA5: 0 | AB5: 0 | AC5: 0 | AD5: 0 | AE5: 0 | AF5: 0 | AG5: 0 | AH5: 0 | AI5: 0 | AJ5: 0 | AK5: 0 | AL5: 0 | AM5: 0 | AN5: 0 | AO5: 0 | AP5: 0 | AQ5: 0 | AR5: 0 | AS5: 0 | AT5: 0 | AU5: 0 | AV5: 0 | AW5: 0 | AX5: 0 | AY5: 0 | AZ5: 0
A6: hydro | B6: 0 | C6: 0 | D6: 0 | E6: 0 | F6: 0 | G6: 0 | H6: 0 | I6: 0 | J6: 0 | K6: 0 | L6: 0 | M6: 0 | N6: 0 | O6: 0 | P6: 0 | Q6: 0 | R6: 0 | S6: 0 | T6: 0 | U6: 0 | V6: 0 | W6: 0 | X6: 0 | Y6: 0 | Z6: 0 | AA6: 0 | AB6: 0 | AC6: 0 | AD6: 0 | AE6: 0 | AF6: 0 | AG6: 0 | AH6: 0 | AI6: 0 | AJ6: 0 | AK6: 0 | AL6: 0 | AM6: 0 | AN6: 0 | AO6: 0 | AP6: 0 | AQ6: 0 | AR6: 0 | AS6: 0 | AT6: 0 | AU6: 0 | AV6: 0 | AW6: 0 | AX6: 0 | AY6: 0 | AZ6: 0
A7: onshore wind | B7: 0 | C7: 0 | D7: 0 | E7: 0 | F7: 0 | G7: 0 | H7: 0 | I7: 0 | J7: 0 | K7: 0 | L7: 0 | M7: 0 | N7: 0 | O7: 0 | P7: 0 | Q7: 0 | R7: 0 | S7: 0 | T7: 0 | U7: 0 | V7: 0 | W7: 0 | X7: 0 | Y7: 0 | Z7: 0 | AA7: 0 | AB7: 0 | AC7: 0 | AD7: 0 | AE7: 0 | AF7: 0 | AG7: 0 | AH7: 0 | AI7: 0 | AJ7: 0 | AK7: 0 | AL7: 0 | AM7: 0 | AN7: 0 | AO7: 0 | AP7: 0 | AQ7: 0 | AR7: 0 | AS7: 0 | AT7: 0 | AU7: 0 | AV7: 0 | AW7: 0 | AX7: 0 | AY7: 0 | AZ7: 0
A8: solar PV | B8: ='India Dist Solar PV Data'!E45 -> 123.3396 | C8: ='India Dist Solar PV Data'!F45 -> 165.81619 | D8: ='India Dist Solar PV Data'!G45 -> 208.29278 | E8: ='India Dist Solar PV Data'!H45 -> 250.76937 | F8: ='India Dist Solar PV Data'!I45 -> 257.72668 | G8: ='India Dist Solar PV Data'!J45 -> 264.684 | H8: ='India Dist Solar PV Data'!K45 -> 271.64131 | I8: ='India Dist Solar PV Data'!L45 -> 278.59862 | ... AZ8: ='India Dist Solar PV Data'!BC45 -> 3143.2864
A9: solar thermal | B9: 0 | C9: 0 | D9: 0 | E9: 0 | F9: 0 | G9: 0 | H9: 0 | I9: 0 | J9: 0 | K9: 0 | L9: 0 | M9: 0 | N9: 0 | O9: 0 | P9: 0 | Q9: 0 | R9: 0 | S9: 0 | T9: 0 | U9: 0 | V9: 0 | W9: 0 | X9: 0 | Y9: 0 | Z9: 0 | AA9: 0 | AB9: 0 | AC9: 0 | AD9: 0 | AE9: 0 | AF9: 0 | AG9: 0 | AH9: 0 | AI9: 0 | AJ9: 0 | AK9: 0 | AL9: 0 | AM9: 0 | AN9: 0 | AO9: 0 | AP9: 0 | AQ9: 0 | AR9: 0 | AS9: 0 | AT9: 0 | AU9: 0 | AV9: 0 | AW9: 0 | AX9: 0 | AY9: 0 | AZ9: 0
A10: biomass | B10: 0 | C10: 0 | D10: 0 | E10: 0 | F10: 0 | G10: 0 | H10: 0 | I10: 0 | J10: 0 | K10: 0 | L10: 0 | M10: 0 | N10: 0 | O10: 0 | P10: 0 | Q10: 0 | R10: 0 | S10: 0 | T10: 0 | U10: 0 | V10: 0 | W10: 0 | X10: 0 | Y10: 0 | Z10: 0 | AA10: 0 | AB10: 0 | AC10: 0 | AD10: 0 | AE10: 0 | AF10: 0 | AG10: 0 | AH10: 0 | AI10: 0 | AJ10: 0 | AK10: 0 | AL10: 0 | AM10: 0 | AN10: 0 | AO10: 0 | AP10: 0 | AQ10: 0 | AR10: 0 | AS10: 0 | AT10: 0 | AU10: 0 | AV10: 0 | AW10: 0 | AX10: 0 | AY10: 0 | AZ10: 0
A11: geothermal | B11: 0 | C11: 0 | D11: 0 | E11: 0 | F11: 0 | G11: 0 | H11: 0 | I11: 0 | J11: 0 | K11: 0 | L11: 0 | M11: 0 | N11: 0 | O11: 0 | P11: 0 | Q11: 0 | R11: 0 | S11: 0 | T11: 0 | U11: 0 | V11: 0 | W11: 0 | X11: 0 | Y11: 0 | Z11: 0 | AA11: 0 | AB11: 0 | AC11: 0 | AD11: 0 | AE11: 0 | AF11: 0 | AG11: 0 | AH11: 0 | AI11: 0 | AJ11: 0 | AK11: 0 | AL11: 0 | AM11: 0 | AN11: 0 | AO11: 0 | AP11: 0 | AQ11: 0 | AR11: 0 | AS11: 0 | AT11: 0 | AU11: 0 | AV11: 0 | AW11: 0 | AX11: 0 | AY11: 0 | AZ11: 0
A12: petroleum | B12: 0 | C12: 0 | D12: 0 | E12: 0 | F12: 0 | G12: 0 | H12: 0 | I12: 0 | J12: 0 | K12: 0 | L12: 0 | M12: 0 | N12: 0 | O12: 0 | P12: 0 | Q12: 0 | R12: 0 | S12: 0 | T12: 0 | U12: 0 | V12: 0 | W12: 0 | X12: 0 | Y12: 0 | Z12: 0 | AA12: 0 | AB12: 0 | AC12: 0 | AD12: 0 | AE12: 0 | AF12: 0 | AG12: 0 | AH12: 0 | AI12: 0 | AJ12: 0 | AK12: 0 | AL12: 0 | AM12: 0 | AN12: 0 | AO12: 0 | AP12: 0 | AQ12: 0 | AR12: 0 | AS12: 0 | AT12: 0 | AU12: 0 | AV12: 0 | AW12: 0 | AX12: 0 | AY12: 0 | AZ12: 0
A13: natural gas peaker | B13: 0 | C13: 0 | D13: 0 | E13: 0 | F13: 0 | G13: 0 | H13: 0 | I13: 0 | J13: 0 | K13: 0 | L13: 0 | M13: 0 | N13: 0 | O13: 0 | P13: 0 | Q13: 0 | R13: 0 | S13: 0 | T13: 0 | U13: 0 | V13: 0 | W13: 0 | X13: 0 | Y13: 0 | Z13: 0 | AA13: 0 | AB13: 0 | AC13: 0 | AD13: 0 | AE13: 0 | AF13: 0 | AG13: 0 | AH13: 0 | AI13: 0 | AJ13: 0 | AK13: 0 | AL13: 0 | AM13: 0 | AN13: 0 | AO13: 0 | AP13: 0 | AQ13: 0 | AR13: 0 | AS13: 0 | AT13: 0 | AU13: 0 | AV13: 0 | AW13: 0 | AX13: 0 | AY13: 0 | AZ13: 0
A14: lignite | B14: 0 | C14: 0 | D14: 0 | E14: 0 | F14: 0 | G14: 0 | H14: 0 | I14: 0 | J14: 0 | K14: 0 | L14: 0 | M14: 0 | N14: 0 | O14: 0 | P14: 0 | Q14: 0 | R14: 0 | S14: 0 | T14: 0 | U14: 0 | V14: 0 | W14: 0 | X14: 0 | Y14: 0 | Z14: 0 | AA14: 0 | AB14: 0 | AC14: 0 | AD14: 0 | AE14: 0 | AF14: 0 | AG14: 0 | AH14: 0 | AI14: 0 | AJ14: 0 | AK14: 0 | AL14: 0 | AM14: 0 | AN14: 0 | AO14: 0 | AP14: 0 | AQ14: 0 | AR14: 0 | AS14: 0 | AT14: 0 | AU14: 0 | AV14: 0 | AW14: 0 | AX14: 0 | AY14: 0 | AZ14: 0
A15: offshore wind | B15: 0 | C15: 0 | D15: 0 | E15: 0 | F15: 0 | G15: 0 | H15: 0 | I15: 0 | J15: 0 | K15: 0 | L15: 0 | M15: 0 | N15: 0 | O15: 0 | P15: 0 | Q15: 0 | R15: 0 | S15: 0 | T15: 0 | U15: 0 | V15: 0 | W15: 0 | X15: 0 | Y15: 0 | Z15: 0 | AA15: 0 | AB15: 0 | AC15: 0 | AD15: 0 | AE15: 0 | AF15: 0 | AG15: 0 | AH15: 0 | AI15: 0 | AJ15: 0 | AK15: 0 | AL15: 0 | AM15: 0 | AN15: 0 | AO15: 0 | AP15: 0 | AQ15: 0 | AR15: 0 | AS15: 0 | AT15: 0 | AU15: 0 | AV15: 0 | AW15: 0 | AX15: 0 | AY15: 0 | AZ15: 0
A16: crude oil | B16: 0 | C16: 0 | D16: 0 | E16: 0 | F16: 0 | G16: 0 | H16: 0 | I16: 0 | J16: 0 | K16: 0 | L16: 0 | M16: 0 | N16: 0 | O16: 0 | P16: 0 | Q16: 0 | R16: 0 | S16: 0 | T16: 0 | U16: 0 | V16: 0 | W16: 0 | X16: 0 | Y16: 0 | Z16: 0 | AA16: 0 | AB16: 0 | AC16: 0 | AD16: 0 | AE16: 0 | AF16: 0 | AG16: 0 | AH16: 0 | AI16: 0 | AJ16: 0 | AK16: 0 | AL16: 0 | AM16: 0 | AN16: 0 | AO16: 0 | AP16: 0 | AQ16: 0 | AR16: 0 | AS16: 0 | AT16: 0 | AU16: 0 | AV16: 0 | AW16: 0 | AX16: 0 | AY16: 0 | AZ16: 0
A17: heavy or residual fuel oil | B17: 0 | C17: 0 | D17: 0 | E17: 0 | F17: 0 | G17: 0 | H17: 0 | I17: 0 | J17: 0 | K17: 0 | L17: 0 | M17: 0 | N17: 0 | O17: 0 | P17: 0 | Q17: 0 | R17: 0 | S17: 0 | T17: 0 | U17: 0 | V17: 0 | W17: 0 | X17: 0 | Y17: 0 | Z17: 0 | AA17: 0 | AB17: 0 | AC17: 0 | AD17: 0 | AE17: 0 | AF17: 0 | AG17: 0 | AH17: 0 | AI17: 0 | AJ17: 0 | AK17: 0 | AL17: 0 | AM17: 0 | AN17: 0 | AO17: 0 | AP17: 0 | AQ17: 0 | AR17: 0 | AS17: 0 | AT17: 0 | AU17: 0 | AV17: 0 | AW17: 0 | AX17: 0 | AY17: 0 | AZ17: 0
A18: municipal solid waste | B18: 0 | C18: 0 | D18: 0 | E18: 0 | F18: 0 | G18: 0 | H18: 0 | I18: 0 | J18: 0 | K18: 0 | L18: 0 | M18: 0 | N18: 0 | O18: 0 | P18: 0 | Q18: 0 | R18: 0 | S18: 0 | T18: 0 | U18: 0 | V18: 0 | W18: 0 | X18: 0 | Y18: 0 | Z18: 0 | AA18: 0 | AB18: 0 | AC18: 0 | AD18: 0 | AE18: 0 | AF18: 0 | AG18: 0 | AH18: 0 | AI18: 0 | AJ18: 0 | AK18: 0 | AL18: 0 | AM18: 0 | AN18: 0 | AO18: 0 | AP18: 0 | AQ18: 0 | AR18: 0 | AS18: 0 | AT18: 0 | AU18: 0 | AV18: 0 | AW18: 0 | AX18: 0 | AY18: 0 | AZ18: 0
A19: hard coal w CCS | B19: 0 | C19: 0 | D19: 0 | E19: 0 | F19: 0 | G19: 0 | H19: 0 | I19: 0 | J19: 0 | K19: 0 | L19: 0 | M19: 0 | N19: 0 | O19: 0 | P19: 0 | Q19: 0 | R19: 0 | S19: 0 | T19: 0 | U19: 0 | V19: 0 | W19: 0 | X19: 0 | Y19: 0 | Z19: 0 | AA19: 0 | AB19: 0 | AC19: 0 | AD19: 0 | AE19: 0 | AF19: 0 | AG19: 0 | AH19: 0 | AI19: 0 | AJ19: 0 | AK19: 0 | AL19: 0 | AM19: 0 | AN19: 0 | AO19: 0 | AP19: 0 | AQ19: 0 | AR19: 0 | AS19: 0 | AT19: 0 | AU19: 0 | AV19: 0 | AW19: 0 | AX19: 0 | AY19: 0 | AZ19: 0
A20: natural gas combined cycle w CCS | B20: 0 | C20: 0 | D20: 0 | E20: 0 | F20: 0 | G20: 0 | H20: 0 | I20: 0 | J20: 0 | K20: 0 | L20: 0 | M20: 0 | N20: 0 | O20: 0 | P20: 0 | Q20: 0 | R20: 0 | S20: 0 | T20: 0 | U20: 0 | V20: 0 | W20: 0 | X20: 0 | Y20: 0 | Z20: 0 | AA20: 0 | AB20: 0 | AC20: 0 | AD20: 0 | AE20: 0 | AF20: 0 | AG20: 0 | AH20: 0 | AI20: 0 | AJ20: 0 | AK20: 0 | AL20: 0 | AM20: 0 | AN20: 0 | AO20: 0 | AP20: 0 | AQ20: 0 | AR20: 0 | AS20: 0 | AT20: 0 | AU20: 0 | AV20: 0 | AW20: 0 | AX20: 0 | AY20: 0 | AZ20: 0
... A25: hydrogen combined cycle | B25: 0 | C25: 0 | D25: 0 | E25: 0 | F25: 0 | G25: 0 | H25: 0 | I25: 0 | J25: 0 | K25: 0 | L25: 0 | M25: 0 | N25: 0 | O25: 0 | P25: 0 | Q25: 0 | R25: 0 | S25: 0 | T25: 0 | U25: 0 | V25: 0 | W25: 0 | X25: 0 | Y25: 0 | Z25: 0 | AA25: 0 | AB25: 0 | AC25: 0 | AD25: 0 | AE25: 0 | AF25: 0 | AG25: 0 | AH25: 0 | AI25: 0 | AJ25: 0 | AK25: 0 | AL25: 0 | AM25: 0 | AN25: 0 | AO25: 0 | AP25: 0 | AQ25: 0 | AR25: 0 | AS25: 0 | AT25: 0 | AU25: 0 | AV25: 0 | AW25: 0 | AX25: 0 | AY25: 0 | AZ25: 0

Sheet BDESC-rural-residential
A1: MW | B1: 2020 | C1: 2021 | D1: 2022 | E1: 2023 | F1: 2024 | G1: 2025 | H1: 2026 | I1: 2027 | J1: 2028 | K1: 2029 | L1: 2030 | M1: 2031 | N1: 2032 | O1: 2033 | P1: 2034 | Q1: 2035 | R1: 2036 | S1: 2037 | T1: 2038 | U1: 2039 | V1: 2040 | W1: 2041 | X1: 2042 | Y1: 2043 | Z1: 2044 | AA1: 2045 | AB1: 2046 | AC1: 2047 | AD1: 2048 | AE1: 2049 | AF1: 2050 | AG1: 2051 | AH1: 2052 | AI1: 2053 | AJ1: 2054 | AK1: 2055 | AL1: 2056 | AM1: 2057 | AN1: 2058 | AO1: 2059 | AP1: 2060 | AQ1: 2061 | AR1: 2062 | AS1: 2063 | AT1: 2064 | AU1: 2065 | AV1: 2066 | AW1: 2067 | AX1: 2068 | AY1: 2069 | AZ1: 2070
A2: hard coal | B2: 0 | C2: 0 | D2: 0 | E2: 0 | F2: 0 | G2: 0 | H2: 0 | I2: 0 | J2: 0 | K2: 0 | L2: 0 | M2: 0 | N2: 0 | O2: 0 | P2: 0 | Q2: 0 | R2: 0 | S2: 0 | T2: 0 | U2: 0 | V2: 0 | W2: 0 | X2: 0 | Y2: 0 | Z2: 0 | AA2: 0 | AB2: 0 | AC2: 0 | AD2: 0 | AE2: 0 | AF2: 0 | AG2: 0 | AH2: 0 | AI2: 0 | AJ2: 0 | AK2: 0 | AL2: 0 | AM2: 0 | AN2: 0 | AO2: 0 | AP2: 0 | AQ2: 0 | AR2: 0 | AS2: 0 | AT2: 0 | AU2: 0 | AV2: 0 | AW2: 0 | AX2: 0 | AY2: 0 | AZ2: 0
A3: natural gas steam turbine | B3: 0 | C3: 0 | D3: 0 | E3: 0 | F3: 0 | G3: 0 | H3: 0 | I3: 0 | J3: 0 | K3: 0 | L3: 0 | M3: 0 | N3: 0 | O3: 0 | P3: 0 | Q3: 0 | R3: 0 | S3: 0 | T3: 0 | U3: 0 | V3: 0 | W3: 0 | X3: 0 | Y3: 0 | Z3: 0 | AA3: 0 | AB3: 0 | AC3: 0 | AD3: 0 | AE3: 0 | AF3: 0 | AG3: 0 | AH3: 0 | AI3: 0 | AJ3: 0 | AK3: 0 | AL3: 0 | AM3: 0 | AN3: 0 | AO3: 0 | AP3: 0 | AQ3: 0 | AR3: 0 | AS3: 0 | AT3: 0 | AU3: 0 | AV3: 0 | AW3: 0 | AX3: 0 | AY3: 0 | AZ3: 0
A4: natural gas combined cycle | B4: 0 | C4: 0 | D4: 0 | E4: 0 | F4: 0 | G4: 0 | H4: 0 | I4: 0 | J4: 0 | K4: 0 | L4: 0 | M4: 0 | N4: 0 | O4: 0 | P4: 0 | Q4: 0 | R4: 0 | S4: 0 | T4: 0 | U4: 0 | V4: 0 | W4: 0 | X4: 0 | Y4: 0 | Z4: 0 | AA4: 0 | AB4: 0 | AC4: 0 | AD4: 0 | AE4: 0 | AF4: 0 | AG4: 0 | AH4: 0 | AI4: 0 | AJ4: 0 | AK4: 0 | AL4: 0 | AM4: 0 | AN4: 0 | AO4: 0 | AP4: 0 | AQ4: 0 | AR4: 0 | AS4: 0 | AT4: 0 | AU4: 0 | AV4: 0 | AW4: 0 | AX4: 0 | AY4: 0 | AZ4: 0
A5: nuclear | B5: 0 | C5: 0 | D5: 0 | E5: 0 | F5: 0 | G5: 0 | H5: 0 | I5: 0 | J5: 0 | K5: 0 | L5: 0 | M5: 0 | N5: 0 | O5: 0 | P5: 0 | Q5: 0 | R5: 0 | S5: 0 | T5: 0 | U5: 0 | V5: 0 | W5: 0 | X5: 0 | Y5: 0 | Z5: 0 | AA5: 0 | AB5: 0 | AC5: 0 | AD5: 0 | AE5: 0 | AF5: 0 | AG5: 0 | AH5: 0 | AI5: 0 | AJ5: 0 | AK5: 0 | AL5: 0 | AM5: 0 | AN5: 0 | AO5: 0 | AP5: 0 | AQ5: 0 | AR5: 0 | AS5: 0 | AT5: 0 | AU5: 0 | AV5: 0 | AW5: 0 | AX5: 0 | AY5: 0 | AZ5: 0
A6: hydro | B6: 0 | C6: 0 | D6: 0 | E6: 0 | F6: 0 | G6: 0 | H6: 0 | I6: 0 | J6: 0 | K6: 0 | L6: 0 | M6: 0 | N6: 0 | O6: 0 | P6: 0 | Q6: 0 | R6: 0 | S6: 0 | T6: 0 | U6: 0 | V6: 0 | W6: 0 | X6: 0 | Y6: 0 | Z6: 0 | AA6: 0 | AB6: 0 | AC6: 0 | AD6: 0 | AE6: 0 | AF6: 0 | AG6: 0 | AH6: 0 | AI6: 0 | AJ6: 0 | AK6: 0 | AL6: 0 | AM6: 0 | AN6: 0 | AO6: 0 | AP6: 0 | AQ6: 0 | AR6: 0 | AS6: 0 | AT6: 0 | AU6: 0 | AV6: 0 | AW6: 0 | AX6: 0 | AY6: 0 | AZ6: 0
A7: onshore wind | B7: 0 | C7: 0 | D7: 0 | E7: 0 | F7: 0 | G7: 0 | H7: 0 | I7: 0 | J7: 0 | K7: 0 | L7: 0 | M7: 0 | N7: 0 | O7: 0 | P7: 0 | Q7: 0 | R7: 0 | S7: 0 | T7: 0 | U7: 0 | V7: 0 | W7: 0 | X7: 0 | Y7: 0 | Z7: 0 | AA7: 0 | AB7: 0 | AC7: 0 | AD7: 0 | AE7: 0 | AF7: 0 | AG7: 0 | AH7: 0 | AI7: 0 | AJ7: 0 | AK7: 0 | AL7: 0 | AM7: 0 | AN7: 0 | AO7: 0 | AP7: 0 | AQ7: 0 | AR7: 0 | AS7: 0 | AT7: 0 | AU7: 0 | AV7: 0 | AW7: 0 | AX7: 0 | AY7: 0 | AZ7: 0
A8: solar PV | B8: ='India Dist Solar PV Data'!E46 -> 205.18365 | C8: ='India Dist Solar PV Data'!F46 -> 274.40467 | D8: ='India Dist Solar PV Data'!G46 -> 343.6257 | E8: ='India Dist Solar PV Data'!H46 -> 412.84673 | F8: ='India Dist Solar PV Data'!I46 -> 421.79295 | G8: ='India Dist Solar PV Data'!J46 -> 430.73917 | H8: ='India Dist Solar PV Data'!K46 -> 439.68538 | I8: ='India Dist Solar PV Data'!L46 -> 448.6316 | ... AZ8: ='India Dist Solar PV Data'!BC46 -> 2237.3979
A9: solar thermal | B9: 0 | C9: 0 | D9: 0 | E9: 0 | F9: 0 | G9: 0 | H9: 0 | I9: 0 | J9: 0 | K9: 0 | L9: 0 | M9: 0 | N9: 0 | O9: 0 | P9: 0 | Q9: 0 | R9: 0 | S9: 0 | T9: 0 | U9: 0 | V9: 0 | W9: 0 | X9: 0 | Y9: 0 | Z9: 0 | AA9: 0 | AB9: 0 | AC9: 0 | AD9: 0 | AE9: 0 | AF9: 0 | AG9: 0 | AH9: 0 | AI9: 0 | AJ9: 0 | AK9: 0 | AL9: 0 | AM9: 0 | AN9: 0 | AO9: 0 | AP9: 0 | AQ9: 0 | AR9: 0 | AS9: 0 | AT9: 0 | AU9: 0 | AV9: 0 | AW9: 0 | AX9: 0 | AY9: 0 | AZ9: 0
A10: biomass | B10: 0 | C10: 0 | D10: 0 | E10: 0 | F10: 0 | G10: 0 | H10: 0 | I10: 0 | J10: 0 | K10: 0 | L10: 0 | M10: 0 | N10: 0 | O10: 0 | P10: 0 | Q10: 0 | R10: 0 | S10: 0 | T10: 0 | U10: 0 | V10: 0 | W10: 0 | X10: 0 | Y10: 0 | Z10: 0 | AA10: 0 | AB10: 0 | AC10: 0 | AD10: 0 | AE10: 0 | AF10: 0 | AG10: 0 | AH10: 0 | AI10: 0 | AJ10: 0 | AK10: 0 | AL10: 0 | AM10: 0 | AN10: 0 | AO10: 0 | AP10: 0 | AQ10: 0 | AR10: 0 | AS10: 0 | AT10: 0 | AU10: 0 | AV10: 0 | AW10: 0 | AX10: 0 | AY10: 0 | AZ10: 0
A11: geothermal | B11: 0 | C11: 0 | D11: 0 | E11: 0 | F11: 0 | G11: 0 | H11: 0 | I11: 0 | J11: 0 | K11: 0 | L11: 0 | M11: 0 | N11: 0 | O11: 0 | P11: 0 | Q11: 0 | R11: 0 | S11: 0 | T11: 0 | U11: 0 | V11: 0 | W11: 0 | X11: 0 | Y11: 0 | Z11: 0 | AA11: 0 | AB11: 0 | AC11: 0 | AD11: 0 | AE11: 0 | AF11: 0 | AG11: 0 | AH11: 0 | AI11: 0 | AJ11: 0 | AK11: 0 | AL11: 0 | AM11: 0 | AN11: 0 | AO11: 0 | AP11: 0 | AQ11: 0 | AR11: 0 | AS11: 0 | AT11: 0 | AU11: 0 | AV11: 0 | AW11: 0 | AX11: 0 | AY11: 0 | AZ11: 0
A12: petroleum | B12: 0 | C12: 0 | D12: 0 | E12: 0 | F12: 0 | G12: 0 | H12: 0 | I12: 0 | J12: 0 | K12: 0 | L12: 0 | M12: 0 | N12: 0 | O12: 0 | P12: 0 | Q12: 0 | R12: 0 | S12: 0 | T12: 0 | U12: 0 | V12: 0 | W12: 0 | X12: 0 | Y12: 0 | Z12: 0 | AA12: 0 | AB12: 0 | AC12: 0 | AD12: 0 | AE12: 0 | AF12: 0 | AG12: 0 | AH12: 0 | AI12: 0 | AJ12: 0 | AK12: 0 | AL12: 0 | AM12: 0 | AN12: 0 | AO12: 0 | AP12: 0 | AQ12: 0 | AR12: 0 | AS12: 0 | AT12: 0 | AU12: 0 | AV12: 0 | AW12: 0 | AX12: 0 | AY12: 0 | AZ12: 0
A13: natural gas peaker | B13: 0 | C13: 0 | D13: 0 | E13: 0 | F13: 0 | G13: 0 | H13: 0 | I13: 0 | J13: 0 | K13: 0 | L13: 0 | M13: 0 | N13: 0 | O13: 0 | P13: 0 | Q13: 0 | R13: 0 | S13: 0 | T13: 0 | U13: 0 | V13: 0 | W13: 0 | X13: 0 | Y13: 0 | Z13: 0 | AA13: 0 | AB13: 0 | AC13: 0 | AD13: 0 | AE13: 0 | AF13: 0 | AG13: 0 | AH13: 0 | AI13: 0 | AJ13: 0 | AK13: 0 | AL13: 0 | AM13: 0 | AN13: 0 | AO13: 0 | AP13: 0 | AQ13: 0 | AR13: 0 | AS13: 0 | AT13: 0 | AU13: 0 | AV13: 0 | AW13: 0 | AX13: 0 | AY13: 0 | AZ13: 0
A14: lignite | B14: 0 | C14: 0 | D14: 0 | E14: 0 | F14: 0 | G14: 0 | H14: 0 | I14: 0 | J14: 0 | K14: 0 | L14: 0 | M14: 0 | N14: 0 | O14: 0 | P14: 0 | Q14: 0 | R14: 0 | S14: 0 | T14: 0 | U14: 0 | V14: 0 | W14: 0 | X14: 0 | Y14: 0 | Z14: 0 | AA14: 0 | AB14: 0 | AC14: 0 | AD14: 0 | AE14: 0 | AF14: 0 | AG14: 0 | AH14: 0 | AI14: 0 | AJ14: 0 | AK14: 0 | AL14: 0 | AM14: 0 | AN14: 0 | AO14: 0 | AP14: 0 | AQ14: 0 | AR14: 0 | AS14: 0 | AT14: 0 | AU14: 0 | AV14: 0 | AW14: 0 | AX14: 0 | AY14: 0 | AZ14: 0
A15: offshore wind | B15: 0 | C15: 0 | D15: 0 | E15: 0 | F15: 0 | G15: 0 | H15: 0 | I15: 0 | J15: 0 | K15: 0 | L15: 0 | M15: 0 | N15: 0 | O15: 0 | P15: 0 | Q15: 0 | R15: 0 | S15: 0 | T15: 0 | U15: 0 | V15: 0 | W15: 0 | X15: 0 | Y15: 0 | Z15: 0 | AA15: 0 | AB15: 0 | AC15: 0 | AD15: 0 | AE15: 0 | AF15: 0 | AG15: 0 | AH15: 0 | AI15: 0 | AJ15: 0 | AK15: 0 | AL15: 0 | AM15: 0 | AN15: 0 | AO15: 0 | AP15: 0 | AQ15: 0 | AR15: 0 | AS15: 0 | AT15: 0 | AU15: 0 | AV15: 0 | AW15: 0 | AX15: 0 | AY15: 0 | AZ15: 0
A16: crude oil | B16: 0 | C16: 0 | D16: 0 | E16: 0 | F16: 0 | G16: 0 | H16: 0 | I16: 0 | J16: 0 | K16: 0 | L16: 0 | M16: 0 | N16: 0 | O16: 0 | P16: 0 | Q16: 0 | R16: 0 | S16: 0 | T16: 0 | U16: 0 | V16: 0 | W16: 0 | X16: 0 | Y16: 0 | Z16: 0 | AA16: 0 | AB16: 0 | AC16: 0 | AD16: 0 | AE16: 0 | AF16: 0 | AG16: 0 | AH16: 0 | AI16: 0 | AJ16: 0 | AK16: 0 | AL16: 0 | AM16: 0 | AN16: 0 | AO16: 0 | AP16: 0 | AQ16: 0 | AR16: 0 | AS16: 0 | AT16: 0 | AU16: 0 | AV16: 0 | AW16: 0 | AX16: 0 | AY16: 0 | AZ16: 0
A17: heavy or residual fuel oil | B17: 0 | C17: 0 | D17: 0 | E17: 0 | F17: 0 | G17: 0 | H17: 0 | I17: 0 | J17: 0 | K17: 0 | L17: 0 | M17: 0 | N17: 0 | O17: 0 | P17: 0 | Q17: 0 | R17: 0 | S17: 0 | T17: 0 | U17: 0 | V17: 0 | W17: 0 | X17: 0 | Y17: 0 | Z17: 0 | AA17: 0 | AB17: 0 | AC17: 0 | AD17: 0 | AE17: 0 | AF17: 0 | AG17: 0 | AH17: 0 | AI17: 0 | AJ17: 0 | AK17: 0 | AL17: 0 | AM17: 0 | AN17: 0 | AO17: 0 | AP17: 0 | AQ17: 0 | AR17: 0 | AS17: 0 | AT17: 0 | AU17: 0 | AV17: 0 | AW17: 0 | AX17: 0 | AY17: 0 | AZ17: 0
A18: municipal solid waste | B18: 0 | C18: 0 | D18: 0 | E18: 0 | F18: 0 | G18: 0 | H18: 0 | I18: 0 | J18: 0 | K18: 0 | L18: 0 | M18: 0 | N18: 0 | O18: 0 | P18: 0 | Q18: 0 | R18: 0 | S18: 0 | T18: 0 | U18: 0 | V18: 0 | W18: 0 | X18: 0 | Y18: 0 | Z18: 0 | AA18: 0 | AB18: 0 | AC18: 0 | AD18: 0 | AE18: 0 | AF18: 0 | AG18: 0 | AH18: 0 | AI18: 0 | AJ18: 0 | AK18: 0 | AL18: 0 | AM18: 0 | AN18: 0 | AO18: 0 | AP18: 0 | AQ18: 0 | AR18: 0 | AS18: 0 | AT18: 0 | AU18: 0 | AV18: 0 | AW18: 0 | AX18: 0 | AY18: 0 | AZ18: 0
A19: hard coal w CCS | B19: 0 | C19: 0 | D19: 0 | E19: 0 | F19: 0 | G19: 0 | H19: 0 | I19: 0 | J19: 0 | K19: 0 | L19: 0 | M19: 0 | N19: 0 | O19: 0 | P19: 0 | Q19: 0 | R19: 0 | S19: 0 | T19: 0 | U19: 0 | V19: 0 | W19: 0 | X19: 0 | Y19: 0 | Z19: 0 | AA19: 0 | AB19: 0 | AC19: 0 | AD19: 0 | AE19: 0 | AF19: 0 | AG19: 0 | AH19: 0 | AI19: 0 | AJ19: 0 | AK19: 0 | AL19: 0 | AM19: 0 | AN19: 0 | AO19: 0 | AP19: 0 | AQ19: 0 | AR19: 0 | AS19: 0 | AT19: 0 | AU19: 0 | AV19: 0 | AW19: 0 | AX19: 0 | AY19: 0 | AZ19: 0
A20: natural gas combined cycle w CCS | B20: 0 | C20: 0 | D20: 0 | E20: 0 | F20: 0 | G20: 0 | H20: 0 | I20: 0 | J20: 0 | K20: 0 | L20: 0 | M20: 0 | N20: 0 | O20: 0 | P20: 0 | Q20: 0 | R20: 0 | S20: 0 | T20: 0 | U20: 0 | V20: 0 | W20: 0 | X20: 0 | Y20: 0 | Z20: 0 | AA20: 0 | AB20: 0 | AC20: 0 | AD20: 0 | AE20: 0 | AF20: 0 | AG20: 0 | AH20: 0 | AI20: 0 | AJ20: 0 | AK20: 0 | AL20: 0 | AM20: 0 | AN20: 0 | AO20: 0 | AP20: 0 | AQ20: 0 | AR20: 0 | AS20: 0 | AT20: 0 | AU20: 0 | AV20: 0 | AW20: 0 | AX20: 0 | AY20: 0 | AZ20: 0
... A25: hydrogen combined cycle | B25: 0 | C25: 0 | D25: 0 | E25: 0 | F25: 0 | G25: 0 | H25: 0 | I25: 0 | J25: 0 | K25: 0 | L25: 0 | M25: 0 | N25: 0 | O25: 0 | P25: 0 | Q25: 0 | R25: 0 | S25: 0 | T25: 0 | U25: 0 | V25: 0 | W25: 0 | X25: 0 | Y25: 0 | Z25: 0 | AA25: 0 | AB25: 0 | AC25: 0 | AD25: 0 | AE25: 0 | AF25: 0 | AG25: 0 | AH25: 0 | AI25: 0 | AJ25: 0 | AK25: 0 | AL25: 0 | AM25: 0 | AN25: 0 | AO25: 0 | AP25: 0 | AQ25: 0 | AR25: 0 | AS25: 0 | AT25: 0 | AU25: 0 | AV25: 0 | AW25: 0 | AX25: 0 | AY25: 0 | AZ25: 0

Sheet BDESC-commercial
A1: MW | B1: 2020 | C1: 2021 | D1: 2022 | E1: 2023 | F1: 2024 | G1: 2025 | H1: 2026 | I1: 2027 | J1: 2028 | K1: 2029 | L1: 2030 | M1: 2031 | N1: 2032 | O1: 2033 | P1: 2034 | Q1: 2035 | R1: 2036 | S1: 2037 | T1: 2038 | U1: 2039 | V1: 2040 | W1: 2041 | X1: 2042 | Y1: 2043 | Z1: 2044 | AA1: 2045 | AB1: 2046 | AC1: 2047 | AD1: 2048 | AE1: 2049 | AF1: 2050 | AG1: 2051 | AH1: 2052 | AI1: 2053 | AJ1: 2054 | AK1: 2055 | AL1: 2056 | AM1: 2057 | AN1: 2058 | AO1: 2059 | AP1: 2060 | AQ1: 2061 | AR1: 2062 | AS1: 2063 | AT1: 2064 | AU1: 2065 | AV1: 2066 | AW1: 2067 | AX1: 2068 | AY1: 2069 | AZ1: 2070
A2: hard coal | B2: 0 | C2: 0 | D2: 0 | E2: 0 | F2: 0 | G2: 0 | H2: 0 | I2: 0 | J2: 0 | K2: 0 | L2: 0 | M2: 0 | N2: 0 | O2: 0 | P2: 0 | Q2: 0 | R2: 0 | S2: 0 | T2: 0 | U2: 0 | V2: 0 | W2: 0 | X2: 0 | Y2: 0 | Z2: 0 | AA2: 0 | AB2: 0 | AC2: 0 | AD2: 0 | AE2: 0 | AF2: 0 | AG2: 0 | AH2: 0 | AI2: 0 | AJ2: 0 | AK2: 0 | AL2: 0 | AM2: 0 | AN2: 0 | AO2: 0 | AP2: 0 | AQ2: 0 | AR2: 0 | AS2: 0 | AT2: 0 | AU2: 0 | AV2: 0 | AW2: 0 | AX2: 0 | AY2: 0 | AZ2: 0
A3: natural gas steam turbine | B3: 0 | C3: 0 | D3: 0 | E3: 0 | F3: 0 | G3: 0 | H3: 0 | I3: 0 | J3: 0 | K3: 0 | L3: 0 | M3: 0 | N3: 0 | O3: 0 | P3: 0 | Q3: 0 | R3: 0 | S3: 0 | T3: 0 | U3: 0 | V3: 0 | W3: 0 | X3: 0 | Y3: 0 | Z3: 0 | AA3: 0 | AB3: 0 | AC3: 0 | AD3: 0 | AE3: 0 | AF3: 0 | AG3: 0 | AH3: 0 | AI3: 0 | AJ3: 0 | AK3: 0 | AL3: 0 | AM3: 0 | AN3: 0 | AO3: 0 | AP3: 0 | AQ3: 0 | AR3: 0 | AS3: 0 | AT3: 0 | AU3: 0 | AV3: 0 | AW3: 0 | AX3: 0 | AY3: 0 | AZ3: 0
A4: natural gas combined cycle | B4: 0 | C4: 0 | D4: 0 | E4: 0 | F4: 0 | G4: 0 | H4: 0 | I4: 0 | J4: 0 | K4: 0 | L4: 0 | M4: 0 | N4: 0 | O4: 0 | P4: 0 | Q4: 0 | R4: 0 | S4: 0 | T4: 0 | U4: 0 | V4: 0 | W4: 0 | X4: 0 | Y4: 0 | Z4: 0 | AA4: 0 | AB4: 0 | AC4: 0 | AD4: 0 | AE4: 0 | AF4: 0 | AG4: 0 | AH4: 0 | AI4: 0 | AJ4: 0 | AK4: 0 | AL4: 0 | AM4: 0 | AN4: 0 | AO4: 0 | AP4: 0 | AQ4: 0 | AR4: 0 | AS4: 0 | AT4: 0 | AU4: 0 | AV4: 0 | AW4: 0 | AX4: 0 | AY4: 0 | AZ4: 0
A5: nuclear | B5: 0 | C5: 0 | D5: 0 | E5: 0 | F5: 0 | G5: 0 | H5: 0 | I5: 0 | J5: 0 | K5: 0 | L5: 0 | M5: 0 | N5: 0 | O5: 0 | P5: 0 | Q5: 0 | R5: 0 | S5: 0 | T5: 0 | U5: 0 | V5: 0 | W5: 0 | X5: 0 | Y5: 0 | Z5: 0 | AA5: 0 | AB5: 0 | AC5: 0 | AD5: 0 | AE5: 0 | AF5: 0 | AG5: 0 | AH5: 0 | AI5: 0 | AJ5: 0 | AK5: 0 | AL5: 0 | AM5: 0 | AN5: 0 | AO5: 0 | AP5: 0 | AQ5: 0 | AR5: 0 | AS5: 0 | AT5: 0 | AU5: 0 | AV5: 0 | AW5: 0 | AX5: 0 | AY5: 0 | AZ5: 0
A6: hydro | B6: 0 | C6: 0 | D6: 0 | E6: 0 | F6: 0 | G6: 0 | H6: 0 | I6: 0 | J6: 0 | K6: 0 | L6: 0 | M6: 0 | N6: 0 | O6: 0 | P6: 0 | Q6: 0 | R6: 0 | S6: 0 | T6: 0 | U6: 0 | V6: 0 | W6: 0 | X6: 0 | Y6: 0 | Z6: 0 | AA6: 0 | AB6: 0 | AC6: 0 | AD6: 0 | AE6: 0 | AF6: 0 | AG6: 0 | AH6: 0 | AI6: 0 | AJ6: 0 | AK6: 0 | AL6: 0 | AM6: 0 | AN6: 0 | AO6: 0 | AP6: 0 | AQ6: 0 | AR6: 0 | AS6: 0 | AT6: 0 | AU6: 0 | AV6: 0 | AW6: 0 | AX6: 0 | AY6: 0 | AZ6: 0
A7: onshore wind | B7: 0 | C7: 0 | D7: 0 | E7: 0 | F7: 0 | G7: 0 | H7: 0 | I7: 0 | J7: 0 | K7: 0 | L7: 0 | M7: 0 | N7: 0 | O7: 0 | P7: 0 | Q7: 0 | R7: 0 | S7: 0 | T7: 0 | U7: 0 | V7: 0 | W7: 0 | X7: 0 | Y7: 0 | Z7: 0 | AA7: 0 | AB7: 0 | AC7: 0 | AD7: 0 | AE7: 0 | AF7: 0 | AG7: 0 | AH7: 0 | AI7: 0 | AJ7: 0 | AK7: 0 | AL7: 0 | AM7: 0 | AN7: 0 | AO7: 0 | AP7: 0 | AQ7: 0 | AR7: 0 | AS7: 0 | AT7: 0 | AU7: 0 | AV7: 0 | AW7: 0 | AX7: 0 | AY7: 0 | AZ7: 0
A8: solar PV | B8: ='India Dist Solar PV Data'!E47 -> 985.56973 | C8: ='India Dist Solar PV Data'!F47 -> 1320.6626 | D8: ='India Dist Solar PV Data'!G47 -> 1655.7555 | E8: ='India Dist Solar PV Data'!H47 -> 1990.8483 | F8: ='India Dist Solar PV Data'!I47 -> 2038.5589 | G8: ='India Dist Solar PV Data'!J47 -> 2086.2695 | H8: ='India Dist Solar PV Data'!K47 -> 2133.9801 | I8: ='India Dist Solar PV Data'!L47 -> 2181.6907 | ... AZ8: ='India Dist Solar PV Data'!BC47 -> 16142.053
A9: solar thermal | B9: 0 | C9: 0 | D9: 0 | E9: 0 | F9: 0 | G9: 0 | H9: 0 | I9: 0 | J9: 0 | K9: 0 | L9: 0 | M9: 0 | N9: 0 | O9: 0 | P9: 0 | Q9: 0 | R9: 0 | S9: 0 | T9: 0 | U9: 0 | V9: 0 | W9: 0 | X9: 0 | Y9: 0 | Z9: 0 | AA9: 0 | AB9: 0 | AC9: 0 | AD9: 0 | AE9: 0 | AF9: 0 | AG9: 0 | AH9: 0 | AI9: 0 | AJ9: 0 | AK9: 0 | AL9: 0 | AM9: 0 | AN9: 0 | AO9: 0 | AP9: 0 | AQ9: 0 | AR9: 0 | AS9: 0 | AT9: 0 | AU9: 0 | AV9: 0 | AW9: 0 | AX9: 0 | AY9: 0 | AZ9: 0
A10: biomass | B10: 0 | C10: 0 | D10: 0 | E10: 0 | F10: 0 | G10: 0 | H10: 0 | I10: 0 | J10: 0 | K10: 0 | L10: 0 | M10: 0 | N10: 0 | O10: 0 | P10: 0 | Q10: 0 | R10: 0 | S10: 0 | T10: 0 | U10: 0 | V10: 0 | W10: 0 | X10: 0 | Y10: 0 | Z10: 0 | AA10: 0 | AB10: 0 | AC10: 0 | AD10: 0 | AE10: 0 | AF10: 0 | AG10: 0 | AH10: 0 | AI10: 0 | AJ10: 0 | AK10: 0 | AL10: 0 | AM10: 0 | AN10: 0 | AO10: 0 | AP10: 0 | AQ10: 0 | AR10: 0 | AS10: 0 | AT10: 0 | AU10: 0 | AV10: 0 | AW10: 0 | AX10: 0 | AY10: 0 | AZ10: 0
A11: geothermal | B11: 0 | C11: 0 | D11: 0 | E11: 0 | F11: 0 | G11: 0 | H11: 0 | I11: 0 | J11: 0 | K11: 0 | L11: 0 | M11: 0 | N11: 0 | O11: 0 | P11: 0 | Q11: 0 | R11: 0 | S11: 0 | T11: 0 | U11: 0 | V11: 0 | W11: 0 | X11: 0 | Y11: 0 | Z11: 0 | AA11: 0 | AB11: 0 | AC11: 0 | AD11: 0 | AE11: 0 | AF11: 0 | AG11: 0 | AH11: 0 | AI11: 0 | AJ11: 0 | AK11: 0 | AL11: 0 | AM11: 0 | AN11: 0 | AO11: 0 | AP11: 0 | AQ11: 0 | AR11: 0 | AS11: 0 | AT11: 0 | AU11: 0 | AV11: 0 | AW11: 0 | AX11: 0 | AY11: 0 | AZ11: 0
A12: petroleum | B12: ='Back up generators'!E19 -> 20892.166 | C12: ='Back up generators'!F19 -> 21714.719 | D12: ='Back up generators'!G19 -> 22537.273 | E12: ='Back up generators'!H19 -> 22722.369 | F12: ='Back up generators'!I19 -> 22907.465 | G12: ='Back up generators'!J19 -> 23092.562 | H12: ='Back up generators'!K19 -> 23277.658 | I12: ='Back up generators'!L19 -> 23462.754 | ... AZ12: ='Back up generators'!BC19 -> 0
A13: natural gas peaker | B13: 0 | C13: 0 | D13: 0 | E13: 0 | F13: 0 | G13: 0 | H13: 0 | I13: 0 | J13: 0 | K13: 0 | L13: 0 | M13: 0 | N13: 0 | O13: 0 | P13: 0 | Q13: 0 | R13: 0 | S13: 0 | T13: 0 | U13: 0 | V13: 0 | W13: 0 | X13: 0 | Y13: 0 | Z13: 0 | AA13: 0 | AB13: 0 | AC13: 0 | AD13: 0 | AE13: 0 | AF13: 0 | AG13: 0 | AH13: 0 | AI13: 0 | AJ13: 0 | AK13: 0 | AL13: 0 | AM13: 0 | AN13: 0 | AO13: 0 | AP13: 0 | AQ13: 0 | AR13: 0 | AS13: 0 | AT13: 0 | AU13: 0 | AV13: 0 | AW13: 0 | AX13: 0 | AY13: 0 | AZ13: 0
A14: lignite | B14: 0 | C14: 0 | D14: 0 | E14: 0 | F14: 0 | G14: 0 | H14: 0 | I14: 0 | J14: 0 | K14: 0 | L14: 0 | M14: 0 | N14: 0 | O14: 0 | P14: 0 | Q14: 0 | R14: 0 | S14: 0 | T14: 0 | U14: 0 | V14: 0 | W14: 0 | X14: 0 | Y14: 0 | Z14: 0 | AA14: 0 | AB14: 0 | AC14: 0 | AD14: 0 | AE14: 0 | AF14: 0 | AG14: 0 | AH14: 0 | AI14: 0 | AJ14: 0 | AK14: 0 | AL14: 0 | AM14: 0 | AN14: 0 | AO14: 0 | AP14: 0 | AQ14: 0 | AR14: 0 | AS14: 0 | AT14: 0 | AU14: 0 | AV14: 0 | AW14: 0 | AX14: 0 | AY14: 0 | AZ14: 0
A15: offshore wind | B15: 0 | C15: 0 | D15: 0 | E15: 0 | F15: 0 | G15: 0 | H15: 0 | I15: 0 | J15: 0 | K15: 0 | L15: 0 | M15: 0 | N15: 0 | O15: 0 | P15: 0 | Q15: 0 | R15: 0 | S15: 0 | T15: 0 | U15: 0 | V15: 0 | W15: 0 | X15: 0 | Y15: 0 | Z15: 0 | AA15: 0 | AB15: 0 | AC15: 0 | AD15: 0 | AE15: 0 | AF15: 0 | AG15: 0 | AH15: 0 | AI15: 0 | AJ15: 0 | AK15: 0 | AL15: 0 | AM15: 0 | AN15: 0 | AO15: 0 | AP15: 0 | AQ15: 0 | AR15: 0 | AS15: 0 | AT15: 0 | AU15: 0 | AV15: 0 | AW15: 0 | AX15: 0 | AY15: 0 | AZ15: 0
A16: crude oil | B16: 0 | C16: 0 | D16: 0 | E16: 0 | F16: 0 | G16: 0 | H16: 0 | I16: 0 | J16: 0 | K16: 0 | L16: 0 | M16: 0 | N16: 0 | O16: 0 | P16: 0 | Q16: 0 | R16: 0 | S16: 0 | T16: 0 | U16: 0 | V16: 0 | W16: 0 | X16: 0 | Y16: 0 | Z16: 0 | AA16: 0 | AB16: 0 | AC16: 0 | AD16: 0 | AE16: 0 | AF16: 0 | AG16: 0 | AH16: 0 | AI16: 0 | AJ16: 0 | AK16: 0 | AL16: 0 | AM16: 0 | AN16: 0 | AO16: 0 | AP16: 0 | AQ16: 0 | AR16: 0 | AS16: 0 | AT16: 0 | AU16: 0 | AV16: 0 | AW16: 0 | AX16: 0 | AY16: 0 | AZ16: 0
A17: heavy or residual fuel oil | B17: 0 | C17: 0 | D17: 0 | E17: 0 | F17: 0 | G17: 0 | H17: 0 | I17: 0 | J17: 0 | K17: 0 | L17: 0 | M17: 0 | N17: 0 | O17: 0 | P17: 0 | Q17: 0 | R17: 0 | S17: 0 | T17: 0 | U17: 0 | V17: 0 | W17: 0 | X17: 0 | Y17: 0 | Z17: 0 | AA17: 0 | AB17: 0 | AC17: 0 | AD17: 0 | AE17: 0 | AF17: 0 | AG17: 0 | AH17: 0 | AI17: 0 | AJ17: 0 | AK17: 0 | AL17: 0 | AM17: 0 | AN17: 0 | AO17: 0 | AP17: 0 | AQ17: 0 | AR17: 0 | AS17: 0 | AT17: 0 | AU17: 0 | AV17: 0 | AW17: 0 | AX17: 0 | AY17: 0 | AZ17: 0
A18: municipal solid waste | B18: 0 | C18: 0 | D18: 0 | E18: 0 | F18: 0 | G18: 0 | H18: 0 | I18: 0 | J18: 0 | K18: 0 | L18: 0 | M18: 0 | N18: 0 | O18: 0 | P18: 0 | Q18: 0 | R18: 0 | S18: 0 | T18: 0 | U18: 0 | V18: 0 | W18: 0 | X18: 0 | Y18: 0 | Z18: 0 | AA18: 0 | AB18: 0 | AC18: 0 | AD18: 0 | AE18: 0 | AF18: 0 | AG18: 0 | AH18: 0 | AI18: 0 | AJ18: 0 | AK18: 0 | AL18: 0 | AM18: 0 | AN18: 0 | AO18: 0 | AP18: 0 | AQ18: 0 | AR18: 0 | AS18: 0 | AT18: 0 | AU18: 0 | AV18: 0 | AW18: 0 | AX18: 0 | AY18: 0 | AZ18: 0
A19: hard coal w CCS | B19: 0 | C19: 0 | D19: 0 | E19: 0 | F19: 0 | G19: 0 | H19: 0 | I19: 0 | J19: 0 | K19: 0 | L19: 0 | M19: 0 | N19: 0 | O19: 0 | P19: 0 | Q19: 0 | R19: 0 | S19: 0 | T19: 0 | U19: 0 | V19: 0 | W19: 0 | X19: 0 | Y19: 0 | Z19: 0 | AA19: 0 | AB19: 0 | AC19: 0 | AD19: 0 | AE19: 0 | AF19: 0 | AG19: 0 | AH19: 0 | AI19: 0 | AJ19: 0 | AK19: 0 | AL19: 0 | AM19: 0 | AN19: 0 | AO19: 0 | AP19: 0 | AQ19: 0 | AR19: 0 | AS19: 0 | AT19: 0 | AU19: 0 | AV19: 0 | AW19: 0 | AX19: 0 | AY19: 0 | AZ19: 0
A20: natural gas combined cycle w CCS | B20: 0 | C20: 0 | D20: 0 | E20: 0 | F20: 0 | G20: 0 | H20: 0 | I20: 0 | J20: 0 | K20: 0 | L20: 0 | M20: 0 | N20: 0 | O20: 0 | P20: 0 | Q20: 0 | R20: 0 | S20: 0 | T20: 0 | U20: 0 | V20: 0 | W20: 0 | X20: 0 | Y20: 0 | Z20: 0 | AA20: 0 | AB20: 0 | AC20: 0 | AD20: 0 | AE20: 0 | AF20: 0 | AG20: 0 | AH20: 0 | AI20: 0 | AJ20: 0 | AK20: 0 | AL20: 0 | AM20: 0 | AN20: 0 | AO20: 0 | AP20: 0 | AQ20: 0 | AR20: 0 | AS20: 0 | AT20: 0 | AU20: 0 | AV20: 0 | AW20: 0 | AX20: 0 | AY20: 0 | AZ20: 0
A21: biomass w CCS | B21: 0 | C21: 0 | D21: 0 | E21: 0 | F21: 0 | G21: 0 | H21: 0 | I21: 0 | J21: 0 | K21: 0 | L21: 0 | M21: 0 | N21: 0 | O21: 0 | P21: 0 | Q21: 0 | R21: 0 | S21: 0 | T21: 0 | U21: 0 | V21: 0 | W21: 0 | X21: 0 | Y21: 0 | Z21: 0 | AA21: 0 | AB21: 0 | AC21: 0 | AD21: 0 | AE21: 0 | AF21: 0 | AG21: 0 | AH21: 0 | AI21: 0 | AJ21: 0 | AK21: 0 | AL21: 0 | AM21: 0 | AN21: 0 | AO21: 0 | AP21: 0 | AQ21: 0 | AR21: 0 | AS21: 0 | AT21: 0 | AU21: 0 | AV21: 0 | AW21: 0 | AX21: 0 | AY21: 0 | AZ21: 0
A22: lignite w CCS | B22: 0 | C22: 0 | D22: 0 | E22: 0 | F22: 0 | G22: 0 | H22: 0 | I22: 0 | J22: 0 | K22: 0 | L22: 0 | M22: 0 | N22: 0 | O22: 0 | P22: 0 | Q22: 0 | R22: 0 | S22: 0 | T22: 0 | U22: 0 | V22: 0 | W22: 0 | X22: 0 | Y22: 0 | Z22: 0 | AA22: 0 | AB22: 0 | AC22: 0 | AD22: 0 | AE22: 0 | AF22: 0 | AG22: 0 | AH22: 0 | AI22: 0 | AJ22: 0 | AK22: 0 | AL22: 0 | AM22: 0 | AN22: 0 | AO22: 0 | AP22: 0 | AQ22: 0 | AR22: 0 | AS22: 0 | AT22: 0 | AU22: 0 | AV22: 0 | AW22: 0 | AX22: 0 | AY22: 0 | AZ22: 0
A23: small modular reactor | B23: 0 | C23: 0 | D23: 0 | E23: 0 | F23: 0 | G23: 0 | H23: 0 | I23: 0 | J23: 0 | K23: 0 | L23: 0 | M23: 0 | N23: 0 | O23: 0 | P23: 0 | Q23: 0 | R23: 0 | S23: 0 | T23: 0 | U23: 0 | V23: 0 | W23: 0 | X23: 0 | Y23: 0 | Z23: 0 | AA23: 0 | AB23: 0 | AC23: 0 | AD23: 0 | AE23: 0 | AF23: 0 | AG23: 0 | AH23: 0 | AI23: 0 | AJ23: 0 | AK23: 0 | AL23: 0 | AM23: 0 | AN23: 0 | AO23: 0 | AP23: 0 | AQ23: 0 | AR23: 0 | AS23: 0 | AT23: 0 | AU23: 0 | AV23: 0 | AW23: 0 | AX23: 0 | AY23: 0 | AZ23: 0
A24: hydrogen combustion turbine | B24: 0 | C24: 0 | D24: 0 | E24: 0 | F24: 0 | G24: 0 | H24: 0 | I24: 0 | J24: 0 | K24: 0 | L24: 0 | M24: 0 | N24: 0 | O24: 0 | P24: 0 | Q24: 0 | R24: 0 | S24: 0 | T24: 0 | U24: 0 | V24: 0 | W24: 0 | X24: 0 | Y24: 0 | Z24: 0 | AA24: 0 | AB24: 0 | AC24: 0 | AD24: 0 | AE24: 0 | AF24: 0 | AG24: 0 | AH24: 0 | AI24: 0 | AJ24: 0 | AK24: 0 | AL24: 0 | AM24: 0 | AN24: 0 | AO24: 0 | AP24: 0 | AQ24: 0 | AR24: 0 | AS24: 0 | AT24: 0 | AU24: 0 | AV24: 0 | AW24: 0 | AX24: 0 | AY24: 0 | AZ24: 0
A25: hydrogen combined cycle | B25: 0 | C25: 0 | D25: 0 | E25: 0 | F25: 0 | G25: 0 | H25: 0 | I25: 0 | J25: 0 | K25: 0 | L25: 0 | M25: 0 | N25: 0 | O25: 0 | P25: 0 | Q25: 0 | R25: 0 | S25: 0 | T25: 0 | U25: 0 | V25: 0 | W25: 0 | X25: 0 | Y25: 0 | Z25: 0 | AA25: 0 | AB25: 0 | AC25: 0 | AD25: 0 | AE25: 0 | AF25: 0 | AG25: 0 | AH25: 0 | AI25: 0 | AJ25: 0 | AK25: 0 | AL25: 0 | AM25: 0 | AN25: 0 | AO25: 0 | AP25: 0 | AQ25: 0 | AR25: 0 | AS25: 0 | AT25: 0 | AU25: 0 | AV25: 0 | AW25: 0 | AX25: 0 | AY25: 0 | AZ25: 0
