Workbook

Sheet About
A1: PPEIdtIL Potential Percentage Eff Improvement due to Improved Labeling
A3: Source: | B3: Star Labeling Schedules of Appliances & Equipment | J3: Assumption for choice between bands for estimating improvement
B4: Bureau of Energy Efficiency/Ministry of Power | J4: Simonson & Tversky
B5: 2023 | J5: 1992
B6: Schedules for Equipments | J6: Choice in Context: Tradeoff Contrast and Extremeness Aversion
B7: https://beestarlabel.com/Home/EquipmentSchemes?type=M | J7: https://www.gsb.stanford.edu/faculty-research/publications/choice-context-tradeoff-contrast-extremeness-aversion
B8: Individual schedules for select appliances/equipments | J8: Journal of Marketing Research. 1992, Vol. 29, Issue 3, Pages 281-295
B9: (sources noted under each data table in "India Data' tab)
B11: Selection of Top 10 Appliances in India
B12: Lawrence Berkeley National Laboratory (LBNL)
B13: 2017
B14: Assessing the Cost-Effective Energy Saving Potential from Top-10 Appliances in India
B15: https://eta.lbl.gov/sites/default/files/publications/india_appliance_ee_potential_eedal_conference_paper_0.pdf
B16: Section 2, pp 4-10
A18: Note:
A19: This variable reflects improvement in efficiency components selected by consumers due
A20: to improved labeling. The labeling influences consumers who are buying appliances of all
A21: Quality levels, so it's represented as a simple percentage increase in the efficiency of
A22: components sold (at all quality levels). If Quality Levels are defined based on
A23: particular efficiency thresholds, this may mean the number of square feet served by
A24: components of a given quality level will not be accurate. It's just a question of the meaning
A25: of the labels given to each Quality Level.
A27: India has a Standards & Labeling (S&L) program implemented by the Bureau of
A28: Energy Efficiency (BEE) under the Ministry of Power since 2006. Under this,
A29: BEE promotes the use of star-rated appliances for residential, commercial and
A30: agricultural sectors, either through mandatory or voluntary schemes.
... A47: categories in this variable.

Sheet India Data
A1: Frost-free Refrigerators | L1: Building Component | M1: Average Improvement
A2: Table 1 (Page 6): Star level Valid from 1st January, 2023 to 31st December, 2024 | J2: Component Match | L2: heating | M2: 0
A3: Star rating band | B3: Minimum CEC | C3: Maximum CEC | D3: Min* | E3: Max | F3: Avg | G3: improvement | L3: cooling and ventilation | M3: =AVERAGE(E20,E79) -> 0.084684092
A4: 1 Star * | B4: (0.157* Vtot+243) | C4: (0.180* Vtot+279) | D4: =0.157+243 -> 243.157 | E4: =0.18+279 -> 279.18 | F4: =AVERAGE(D4:E4) -> 261.1685 | G4: =(F4-F5)/F4 -> 0.13026839 | L4: envelope | M4: =E56 -> 0.088490082
A5: 2 Star * * | B5: (0.136*Vtot+211) | C5: (0.157* Vtot+243) | D5: =0.136+211 -> 211.136 | E5: =0.157+243 -> 243.157 | F5: =AVERAGE(D5:E5) -> 227.1465 | G5: =(F5-F6)/F5 -> 0.12995798 | L5: lighting | M5: =AVERAGE(E101,E91) -> 0.24523218
A6: 3 Star * * * | B6: (0.118*Vtot+184) | C6: (0.136* Vtot+211) | D6: =0.118+184 -> 184.118 | E6: =0.136+211 -> 211.136 | F6: =AVERAGE(D6:E6) -> 197.627 | G6: =(F6-F7)/F6 -> 0.12911444 | L6: appliances | M6: =AVERAGE(G8,C31,I45,E68) -> 0.092746032
A7: 4 Star * * * * | B7: (0.103* Vtot +160) | C7: (0.118*Vtot +184) | D7: =0.103+160 -> 160.103 | E7: =0.118+184 -> 184.118 | F7: =AVERAGE(D7:E7) -> 172.1105 | G7: =(F7-F8)/F7 -> 0.069766226 | L7: other component | M7: 0
A8: 5 Star * * * * * | B8: (0.103*Vtot+160) | D8: =0.103+160 -> 160.103 | F8: =AVERAGE(D8:E8) -> 160.103 | G8: =AVERAGE(G4:G7) -> 0.11477676 | J8: Appliances
A9: * calculated with (Vadj_tot_nf = 1)
A10: Source: Refrigerator labeling schedule - https://beestarlabel.com/Content/Notification/Refrigerators/14a_Refrigerator.pdf
A12: Air Conditioners
A13: Table 2.6: Star level valid for split type air conditioners(From 1stJanuary, 2021 to 31stDecember, 2023)
B14: Energy Efficiency Ratio (Watt/Watt)
A15: Star level | B15: Min | C15: Max | D15: Avg | E15: improvement
A16: 1 Star * | B16: 2.7 | C16: 2.89 | D16: =AVERAGE(B16:C16) -> 2.795 | E16: =(D17-D16)/D16 -> 0.071556351
A17: 2 Star * * | B17: 2.9 | C17: 3.09 | D17: =AVERAGE(B17:C17) -> 2.995 | E17: =(D18-D17)/D17 -> 0.066777963
A18: 3 Star * * * | B18: 3.1 | C18: 3.29 | D18: =AVERAGE(B18:C18) -> 3.195 | E18: =(D19-D18)/D18 -> 0.062597809
A19: 4 Star * * * * | B19: 3.3 | C19: 3.49 | D19: =AVERAGE(B19:C19) -> 3.395 | E19: =(D20-D19)/D19 -> 0.030927835
A20: 5 Star * * * * * | B20: 3.5 | D20: =AVERAGE(B20:C20) -> 3.5 | E20: =AVERAGE(E16:E19) -> 0.05796499 | J20: Cooling & Ventilation
A21: Source: AC labeling schedule - https://beestarlabel.com/Content/Files/Schedule3A-RAC9jun.pdf
A23: Televisions
A24: Table 2.1.3: Star wise Annual Energy consumption for LED TVs (with LED backlight) for preferred
A25: Screen Sizes (from January 01, 2021 to December 31, 2023)
A26: Star level | B26: Maximum Annual Energy Consumption kWh/yr | C26: improvement
A27: 1 Star * | B27: 87 | C27: =(B27-B28)/B27 -> 0.091954023
A28: 2 Star * * | B28: 79 | C28: =(B28-B29)/B28 -> 0.088607595
A29: 3 Star * * * | B29: 72 | C29: =(B29-B30)/B29 -> 0.11111111
A30: 4 Star * * * * | B30: 64 | C30: =(B30-B31)/B30 -> 0.125
A31: 5 Star * * * * * | B31: 56 | C31: =AVERAGE(C27:C30) -> 0.10416818 | J31: Appliances
A32: Size selected as per LBNL study - 32" screen size and aspect ratio 16:9
A33: Source: Color TV labeling schedule - https://beestarlabel.com/Content/Files/Schedule-11=CTV.pdf
A35: Electric water heaters
A36: Table 3: Star rating plan valid from 1stJuly2015to 30thJune 2017
B38: Standing Losses (kWh/24 hour/45°C)
A39: Rated Capacity-> | B39: 15 litres | E39: 25 litres | H39: improvement
A40: Star level | B40: Max | C40: Min | D40: Avg | E40: Max | F40: Min | G40: Avg | H40: 15 litres | I40: 25 litres
A41: 1 Star * | B41: 0.675 | C41: 0.614 | D41: =AVERAGE(B41:C41) -> 0.6445 | E41: 0.823 | F41: 0.748 | G41: =AVERAGE(E41:F41) -> 0.7855 | H41: =(D41-D42)/D41 -> 0.090768037 | I41: =(G41-G42)/G41 -> 0.091024825
A42: 2 Star * * | B42: =C41 -> 0.614 | C42: 0.558 | D42: =AVERAGE(B42:C42) -> 0.586 | E42: =F41 -> 0.748 | F42: 0.68 | G42: =AVERAGE(E42:F42) -> 0.714 | H42: =(D42-D43)/D42 -> 0.091296928 | I42: =(G42-G43)/G42 -> 0.091036415
A43: 3 Star * * * | B43: =C42 -> 0.558 | C43: 0.507 | D43: =AVERAGE(B43:C43) -> 0.5325 | E43: =F42 -> 0.68 | F43: 0.618 | G43: =AVERAGE(E43:F43) -> 0.649 | H43: =(D43-D44)/D43 -> 0.091079812 | I43: =(G43-G44)/G43 -> 0.090909091
A44: 4 Star * * * * | B44: =C43 -> 0.507 | C44: 0.461 | D44: =AVERAGE(B44:C44) -> 0.484 | E44: =F43 -> 0.618 | F44: 0.562 | G44: =AVERAGE(E44:F44) -> 0.59 | H44: =(D44-D45)/D44 -> 0.047520661 | I44: =(G44-G45)/G44 -> 0.047457627
...

Sheet PPEIdtIL
A1: Efficiency Improvement by Building Component (dimensionless) | B1: Urban Residential | C1: Rural Residential | D1: Commercial
A2: heating | B2: ='India Data'!$M$2 -> 0 | C2: ='India Data'!$M$2 -> 0 | D2: ='India Data'!$M$2 -> 0
A3: cooling and ventilation | B3: ='India Data'!$M$3 -> 0.084684092 | C3: ='India Data'!$M$3 -> 0.084684092 | D3: ='India Data'!$M$3 -> 0.084684092
A4: envelope | B4: ='India Data'!$M$4 -> 0.088490082 | C4: ='India Data'!$M$4 -> 0.088490082 | D4: ='India Data'!$M$4 -> 0.088490082
A5: lighting | B5: ='India Data'!$M$5 -> 0.24523218 | C5: ='India Data'!$M$5 -> 0.24523218 | D5: ='India Data'!$M$5 -> 0.24523218
A6: appliances | B6: ='India Data'!$M$6 -> 0.092746032 | C6: ='India Data'!$M$6 -> 0.092746032 | D6: ='India Data'!$M$6 -> 0.092746032
A7: other component | B7: 0 | C7: =B7 -> 0 | D7: 0
