Workbook

Sheet About
A1: CtIEPpUESoS Cost to Implement Efficiency Policy per Unit Energy Saved or Shifted
A3: Source: | B3: early retirement of equipment | D3: substitute other fuels for coal: conversion costs per unit capacity
B4: Alex MacCurdy et al. | D4: Babcock and Wilcox
B5: 2013 | D5: 2010
B6: Dual Baselines for Industrial Retrofits that Trigger Energy Codes | D6: Natural Gas Conversions of Existing Coal-Fired Boilers
B7: http://aceee.org/files/proceedings/2013/data/papers/3_166.pdf | D7: http://www.babcock.com/library/Documents/MS-14.pdf
B8: Page 3-8, Table 4 | D8: Page 2, "Financial Considerations," paragraph 1
B10: cogeneration and WHR: total cost | D10: substitute other fuels for coal: conversion costs per unit capacity
B11: Rocky Mountain Institute | D11: McKinsey
B12: 2011 | D12: 2009
B13: Reinventing Fire: Bold Business Solutions for the New Energy Era | D13: Unlocking Energy Efficiency in the U.S. Economy
B14: http://www.rmi.org/RFGraph-Cumulative_2010_value_capital_investment_fuel_savings | D14: https://www.sallan.org/pdf-docs/MCKINSEY_US_energy_efficiency.pdf
B15: Cumulative 2010 present value of capital investment and fuel savings | D15: Tables 15 and 16
B17: cogeneration and WHR: annual energy savings
B18: Rocky Mountain Institute
B19: 2011
B20: Reinventing Fire
B21: http://www.rmi.org/RFGraph-US_industry_energy_saving_potential
B22: Book page 127, Figure 4-2 (or see link above)
B24: elec and hydrogen shifting (boiler conversion)
B25: E3
B26: "Achieving Carbon Neutrality in California (Revised Report): 2045 Abatement Cost Estimates"
B27: 2020
B28: https://ww2.arb.ca.gov/sites/default/files/2020-09/e3_cn_draft_report_supp_data_aug2020.xlsx
B30: elec shifting (heat pump)
B31: Emerson
B32: 2011
B33: Industrial Heat Pumps
B34: https://climate.emerson.com/documents/vilter-heat-pump-white-paper-en-us-5411194.pdf
A36: Notes:
A38: This variable supports time series data for adaptation to other regions, but as of EPS 1.5.0, we
A39: have only time-invariant data for the U.S.
A41: For fuel type shifting we take an average of electric boiler conversion and hydrogen boiler conversion.
A42: We assume the majority of energy and costs will be from boiler conversion instead of process heaters.
A44: All costs are per BTU of energy saved or shifted per year. That is, it is the cost to buy equipment that
A45: achieves this energy savings/shifting annually.
A47: We assume the "proper installation and use of equipment" has no investment cost, as it is a different
A48: way of doing things that are already done, rather than doing or buying something new.
A50: We do not model costs of R&D per unit of energy saved/shifted as a result of that R&D investment.
A52: Currency Year
...

Sheet early retirement
A1: Early Retirement of Equipment
A3: Methodology Notes: | B3: We estimate the cost of industrial equipment replacement per unit energy saved
B4: via industrial motors, because of the availability of data.
B5: Motors (and chillers) seem to be the focus of industrial equipment
B6: early retirement programs- for instance, see Southern California
B7: Edison's program, at: | C7: https://www.sce.com/SC3/b-rs/large-business/spc/calculating-energy-savings.htm
B8: So this seems like a reasonable means of estimation.
A10: Motor Horsepower | B10: Annual Energy Savings (Super Premium Motor vs. Rewind Existing Motor) (kWh) | C10: Incremental Cost (cost of replacement above cost of rewinding) ($) | D10: Investment per Unit Annual Energy Savings ($/kWh)
A11: 21-50 | B11: 4262 | C11: 1558 | D11: =C11/B11 -> 0.36555608
A12: 51-100 | B12: 8738 | C12: 4305 | D12: =C12/B12 -> 0.49267567
A13: 101-200 | B13: 13901 | C13: 8610 | D13: =C13/B13 -> 0.6193799
A14: Average | D14: =AVERAGE(D11:D13) -> 0.49253722
A16: kWh per BTU (pure unit conversion, no efficiency loss)
A17: =2.93*10^-4 -> 0.000293
A19: Investment per Unit Annual Energy Savings ($/BTU)
A20: =D14*A17 -> 0.0001443134

Sheet cogen and WHR
A1: Cogeneration and Waste Heat Recovery, Equipment Efficiency Standards
A3: Annual energy savings achievable in 2050 (BTU)
A4: CHP & waste heat | B4: =2.4*10^15 -> 2.4e+15
A7: Total investment cost to achieve those annual savings in 2050
A8: The graph used appears below. To correspond to the total energy savings found above, we want to use the set of pink bars that
A9: correspond to investment over the 2010-2050 period. We assume the key inside the rightmost blue bar applies to all bars, so
A10: light pink corresponds to CHP Waste Heat and midtone pink corresponds to efficiency technology.
A11: Since RMI only provides a numerical value for the hight of the complete pink bar, not values for each of the three shades of
A12: pink that compose it, we muse use pixel-based measurement to obtain our data from the graph.
A14: Note on pixel measurement of this bar graph:
A15: RMI's graph was made in Excel. For this type of graph (namely, white lines separating stacked bars),
A16: Excel replaces an equal number of rows of colored pixels
A17: with white pixels from the upper and lower bar segments at each junction, with an extra row of the bottom bar at each junction replaced if there
A18: are an odd number of lines of white pixel rows to be applied (which is based on zoom level and graph settings). The top of the uppermost bar
A19: segment is covered with the same number of rows of white pixels as the top of any other bar segment (half of a gap, rounding up).
... A23: Cumulative Cost of Upgrades (2009 $)
B24: 2010-2050, total (pixels) | C24: 2010-2050, this policy (pixels) | D24: Investment, total (2009 $) | E24: Investment, this policy (2009 $)
A25: CHP & waste heat | B25: 114 | C25: 22 | D25: =284*10^9 -> 284000000000 | E25: =(C25/B25)*D25 -> 5.4807018e+10
A28: Cost per Unit Energy Saved Annually ($/BTU)
A29: CHP & waste heat | B29: =E25/B4 -> 2.2836257e-05

Sheet efficiency
B1: 2009 | C1: 2010 | D1: 2011 | E1: 2012 | F1: 2013 | G1: 2014 | H1: 2015 | I1: 2016 | J1: 2017 | K1: 2018 | L1: 2019 | M1: 2020
A2: =NPV(0.07,B2:M2) -> 7.9e+10 | B2: 9.9462571e+09 | C2: =B2 -> 9.9462571e+09 | D2: =C2 -> 9.9462571e+09 | E2: =D2 -> 9.9462571e+09 | F2: =E2 -> 9.9462571e+09 | G2: =F2 -> 9.9462571e+09 | H2: =G2 -> 9.9462571e+09 | I2: =H2 -> 9.9462571e+09 | J2: =I2 -> 9.9462571e+09 | ... M2: =L2 -> 9.9462571e+09
A3: =51+28 -> 79
B4: =M4/COUNT(B1:M1) -> 201.66667 | C4: Tbtu/year | M4: =1550+870 -> 2420
B5: =B2/(B4*1000000000000)*Q5 -> 5.2772703e-05 | O5: 2009 to 2012 USD | Q5: 1.07
A7: We assume outlays are uniform in each year and that savings also accrue uniformly.
A8: McKinsey used a 7 percent discount rate in their main scenario

Sheet shift to electricity
A1: Example 1: Industrial Heat Pump
A3: Emerson Industrial heat pump case studies:
B5: Annual heat delivered (MMbtu) | C5: Capital Cost (USD) | D5: $/annual BTU
A6: Case Study 1 | B6: 56603 | C6: 750000 | D6: =C6/(B6*10^6) -> 1.3250181e-05
A7: Case Study 2 | B7: 25717 | C7: 700000 | D7: =C7/(B7*10^6) -> 2.7219349e-05
A8: Case Study 3 | B8: 60507 | C8: 1250000 | D8: =C8/(B8*10^6) -> 2.0658767e-05
A9: Simple average | B9: =AVERAGE(B6:B8) -> 47609 | C9: =AVERAGE(C6:C8) -> 900000 | D9: =C9/(B9*10^6) -> 1.8903989e-05
A11: This is the cost per unit heat delivered via heat pump.
A12: We want the cost per unit energy saved or shifted.
A13: Therefore, we need to take into account the difference in efficiency of heat use.
A15: From variable indst/PIFURfE
A16: Percent reduction in fuel use from switching from fossil fuels to heat pump is:
A17: 0.674
A19: Therefore, the capital cost per unit energy saved (not per unit energy delivered) is:
A20: =D9*(1-A17) -> 6.1627003e-06
A23: Example 2: Industrial Electric Boiler
A25: Electric Boiler Conversion
A27: Industrial Boiler Inputs
A28: General Inputs
A29: Input Name | B29: Units | C29: Value
A30: Equipment Lifetime | B30: yr | C30: 25
A31: Discount Rate | B31: % | C31: 0.05
A32: Natural Gas Price | B32: $/MMBtu | C32: 6.5242598
A33: Electricity Emissions Intensity | B33: kg CO2e/kWh | C33: 0.006395414
A34: Natural Gas Emissions Intensity | B34: kg CO2e/MMBtu | C34: 52.826854
A36: Industrial Boiler Inputs
A37: Input Name | B37: Units | C37: Electric Boiler | D37: Natural Gas Boiler
A38: Boiler Purchase Price | B38: $ | C38: 53860 | D38: 87540
A39: Boiler Efficiency | B39: % | C39: 1 | D39: 0.8
A40: Hourly Service Demand | B40: MMBtu/hr | C40: 3.3475 | D40: 3.3475
A41: Annual Operating Hours | B41: hr/yr | C41: 5280 | D41: 5280
A42: Annual Service Demand | B42: MMBtu/yr | C42: =C40*C41 -> 17674.8 | D42: =D40*D41 -> 17674.8
A45: Investment per Unit Energy Converted in First Year ($/BTU)
A46: =C38/(C42*10^6) -> 3.0472763e-06
A51: Average
A53: =AVERAGE(A20,A46) -> 4.6049883e-06 | B53: $/BTU

Sheet shift to hydrogen
A1: Hydrogen Boiler Conversion
A3: General Inputs
A4: Input Name | B4: Units | C4: Value
A5: Equipment Lifetime | B5: yr | C5: 25
A6: Discount Rate | B6: % | C6: 0.05
A7: Natural Gas Price | B7: $/MMBtu | C7: ='shift to electricity'!C32 -> 6.5242598
A8: Synthetic Natural Gas Price (Conservative) | B8: $/MMBtu | C8: 44
A9: Synthetic Natural Gas Price (Optimistic) | B9: $/MMBtu | C9: 34
A10: Hydrogen Price (Conservative) | B10: $/MMBtu | C10: 21
A11: Hydrogen Price (Optimistic) | B11: $/MMBtu | C11: 15
A12: Hydrogen Storage and Delivery Cost | B12: $/MMBTU | C12: 4
A14: Industrial Boiler Inputs
A15: Input Name | B15: Units | C15: Hydrogen Boiler Conservative | D15: Hydrogen Boiler Optimistic
A16: Natural Gas Boiler Pice | B16: $ | C16: 87540 | D16: 87540
A17: H2 Boiler Price | B17: $ | C17: =C16*1.5 -> 131310 | D17: 87540
A18: H2 Boiler Efficiency | B18: % | C18: =D18 -> 0.8 | D18: 0.8
A19: Hourly Service Demand | B19: MMBtu/hr | C19: 3.3475 | D19: 3.3475
A20: Annual Operating Hours | B20: hr/yr | C20: 5280 | D20: 5280
A21: Annual Service Demand | B21: MMBtu/yr | C21: =C19*C20 -> 17674.8 | D21: =D19*D20 -> 17674.8
A23: Investment per Unit Energy Converted in First Year ($/BTU)
A24: =AVERAGE(C17:D17)/(AVERAGE(C21:D21)*10^6) -> 6.1910177e-06

Sheet substitute fuels for coal
A1: Substitute Other Fuels for Coal
A3: Methodology Notes: | B3: We estimate the cost of converting coal equipment to use other fuel types
B4: via the conversion of coal-fired biolers to natural gas, because of the
B5: availability of data.
A7: Typical Pulverized Coal to Natural Gas Conversions
A8: Estimate | B8: Cost per Unit Capacity ($/kW)
A9: Low | B9: 50
A10: High | B10: 75
A11: Avg | B11: =AVERAGE(B9:B10) -> 62.5
A13: Industrial Boiler Capacity Factor
A14: 0.47
A16: Hours per Year
A17: =24*365 -> 8760
A19: Investment Cost per Unit Annual Energy Converted ($/kWh)
A20: =B11/(A17*A14) -> 0.01518022
A22: kWh per BTU (pure unit conversion, no efficiency loss)
A23: =2.93*10^-4 -> 0.000293
A25: Investment per Unit Energy Converted ($/BTU)
A26: =A20*A23 -> 4.4478043e-06

Sheet India cost adjustment
A22: Share of spending for construction and misc | B22: 0.5
A23: Share of spending for machinery | B23: 0.5
A25: Calculated India multiplier | B25: =B22*About!A65+'India cost adjustment'!B23*About!A68 -> 0.27237457

Sheet CtIEPpUESoS
A1: Cost ($/BTU) | B1: 2021 | C1: 2022 | D1: 2023 | E1: 2024 | F1: 2025 | G1: 2026 | H1: 2027 | I1: 2028 | J1: 2029 | K1: 2030 | L1: 2031 | M1: 2032 | N1: 2033 | O1: 2034 | P1: 2035 | Q1: 2036 | R1: 2037 | S1: 2038 | T1: 2039 | U1: 2040 | V1: 2041 | W1: 2042 | X1: 2043 | Y1: 2044 | Z1: 2045 | AA1: 2046 | AB1: 2047 | AC1: 2048 | AD1: 2049 | AE1: 2050 | AF1: 2051 | AG1: 2052 | AH1: 2053 | AI1: 2054 | AJ1: 2055 | AK1: 2056 | AL1: 2057 | AM1: 2058 | AN1: 2059 | AO1: 2060 | AP1: 2061 | AQ1: 2062 | AR1: 2063 | AS1: 2064 | AT1: 2065 | AU1: 2066 | AV1: 2067 | AW1: 2068 | AX1: 2069 | AY1: 2070
A2: early eqpt retirement | B2: ='early retirement'!A20*About!$A$57*'India cost adjustment'!$B$25 -> 3.8796306e-05 | C2: =$B2 -> 3.8796306e-05 | D2: =$B2 -> 3.8796306e-05 | E2: =$B2 -> 3.8796306e-05 | F2: =$B2 -> 3.8796306e-05 | G2: =$B2 -> 3.8796306e-05 | H2: =$B2 -> 3.8796306e-05 | I2: =$B2 -> 3.8796306e-05 | J2: =$B2 -> 3.8796306e-05 | ... AY2: =$B2 -> 3.8796306e-05
A3: proper installation and use of eqpt | B3: 0 | C3: 0 | D3: 0 | E3: 0 | F3: 0 | G3: 0 | H3: 0 | I3: 0 | J3: 0 | K3: 0 | L3: 0 | M3: 0 | N3: 0 | O3: 0 | P3: 0 | Q3: 0 | R3: 0 | S3: 0 | T3: 0 | U3: 0 | V3: 0 | W3: 0 | X3: 0 | Y3: 0 | Z3: 0 | AA3: 0 | AB3: 0 | AC3: 0 | AD3: 0 | AE3: 0 | AF3: 0 | AG3: 0 | AH3: 0 | AI3: 0 | AJ3: 0 | AK3: 0 | AL3: 0 | AM3: 0 | AN3: 0 | AO3: 0 | AP3: 0 | AQ3: 0 | AR3: 0 | AS3: 0 | AT3: 0 | AU3: 0 | AV3: 0 | AW3: 0 | AX3: 0 | AY3: 0
A4: cogeneration and waste heat recovery | B4: ='cogen and WHR'!B29*About!$A$58*'India cost adjustment'!$B$25 -> 6.5621166e-06 | C4: =$B4 -> 6.5621166e-06 | D4: =$B4 -> 6.5621166e-06 | E4: =$B4 -> 6.5621166e-06 | F4: =$B4 -> 6.5621166e-06 | G4: =$B4 -> 6.5621166e-06 | H4: =$B4 -> 6.5621166e-06 | I4: =$B4 -> 6.5621166e-06 | J4: =$B4 -> 6.5621166e-06 | ... AY4: =$B4 -> 6.5621166e-06
A5: eqpt efficiency stds | B5: =efficiency!B5*'India cost adjustment'!$B$25 -> 1.4373942e-05 | C5: =$B5 -> 1.4373942e-05 | D5: =$B5 -> 1.4373942e-05 | E5: =$B5 -> 1.4373942e-05 | F5: =$B5 -> 1.4373942e-05 | G5: =$B5 -> 1.4373942e-05 | H5: =$B5 -> 1.4373942e-05 | I5: =$B5 -> 1.4373942e-05 | J5: =$B5 -> 1.4373942e-05 | ... AY5: =$B5 -> 1.4373942e-05
A6: shift to electricity | B6: ='shift to electricity'!A53*'India cost adjustment'!$B$25 -> 1.2542817e-06 | C6: =$B6 -> 1.2542817e-06 | D6: =$B6 -> 1.2542817e-06 | E6: =$B6 -> 1.2542817e-06 | F6: =$B6 -> 1.2542817e-06 | G6: =$B6 -> 1.2542817e-06 | H6: =$B6 -> 1.2542817e-06 | I6: =$B6 -> 1.2542817e-06 | J6: =$B6 -> 1.2542817e-06 | ... AY6: =$B6 -> 1.2542817e-06
A7: shift to hydrogen | B7: ='shift to hydrogen'!A24 -> 6.1910177e-06 | C7: =$B7 -> 6.1910177e-06 | D7: =$B7 -> 6.1910177e-06 | E7: =$B7 -> 6.1910177e-06 | F7: =$B7 -> 6.1910177e-06 | G7: =$B7 -> 6.1910177e-06 | H7: =$B7 -> 6.1910177e-06 | I7: =$B7 -> 6.1910177e-06 | J7: =$B7 -> 6.1910177e-06 | ... AY7: =$B7 -> 6.1910177e-06
A8: research and development | B8: 0 | C8: 0 | D8: 0 | E8: 0 | F8: 0 | G8: 0 | H8: 0 | I8: 0 | J8: 0 | K8: 0 | L8: 0 | M8: 0 | N8: 0 | O8: 0 | P8: 0 | Q8: 0 | R8: 0 | S8: 0 | T8: 0 | U8: 0 | V8: 0 | W8: 0 | X8: 0 | Y8: 0 | Z8: 0 | AA8: 0 | AB8: 0 | AC8: 0 | AD8: 0 | AE8: 0 | AF8: 0 | AG8: 0 | AH8: 0 | AI8: 0 | AJ8: 0 | AK8: 0 | AL8: 0 | AM8: 0 | AN8: 0 | AO8: 0 | AP8: 0 | AQ8: 0 | AR8: 0 | AS8: 0 | AT8: 0 | AU8: 0 | AV8: 0 | AW8: 0 | AX8: 0 | AY8: 0
