Workbook
Name dollars_2022_2012: [1]About!$A$103

Sheet About
A1: BS BAU Subsidy for Thermal Fuels per Energy Unit Produced
A2: BS BAU Subsidy per Unit Electricity Output
A3: BS BAU Subsidy per Unit Electricity Capacity Built
A5: Source | B5: Discontinuation of Wind Generation Incentive
B6: CEEW-IISD
B7: Mapping India's Energy Policy 2022
B8: https://www.iisd.org/story/mapping-india-energy-policy-2022-update
B9: Annex A1.4
B10: Natural Gas Production | D10: Domestic LPG Subsidy
B11: Ministry of Petroleum and Natural Gas | D11: Ministry of Petroleum and Natural Gas (PPAC)
B12: 2021 | D12: 2023
B13: Indian Petroleum and Natural Gas Statistics 2021-22 | D13: Snapshot of India's oil and gas data
B14: https://mopng.gov.in/files/TableManagements/IPNG-2021-22_L.pdf | D14: https://ppac.gov.in/uploads/whatsnew/1700660621_MRR-October23_Final_upload.pdf
B15: Table V.1, Page 125
B17: Natural Gas Subsidies | D17: Coal Indirect Subsidies
B18: Ministry of Petroleum and Natural Gas | D18: CEEW-IISD
B19: 2021 | D19: 2022
B20: Indian Petroleum and Natural Gas Statistics 2021-22 | D20: Mapping India's Energy Policy 2022
B21: https://mopng.gov.in/files/TableManagements/IPNG-2021-22_L.pdf | D21: https://www.iisd.org/story/mapping-india-energy-policy-2022-update
B22: Table IV.7, Page 105 | D22: Annex A1.1
A23: Notes
A24: There are two fuels in India that get direct consumer subsidy i.e.LPG Natural Gas (which are accounted in this variable).
A25: Natural gas subsidy is only provided for the North-East states, and thus the NE subsidy was divided by the total consumption of natural gas in the country to arrive at a country-level subsidy.
A26: Data for coal subsidy is provided for future reference but not included in the calculations because they are not direct subsidies.
A27: Since India has a capacity target for renewables, the subsidies by way of state-level feed-in-tariffs or Viability Gap funding are not accounted for,
A28: but instead the phased capacity construction over the years is force fed into the model in the BAU Policy Mandated Capacity Construction variable of the Electricity sector.
A30: Until 2017, a generation-based incentive for wind was available. It is discontinued now as wind technology
A31: is mature, and the government is also moving towards competitive auctions for wind, like solar.
A33: Domestic LPG is considered as it constitutes most (~90%) of the consumption in India.

Sheet Conversion Factors
A1: Currency
A2: India Inflation Rates | B2: See scaling-factors.xlsx for source info
A3: Year | B3: Rate | C3: Value Indexed to 2012
A4: 2010 | B4: 0.0947 | C4: 0.84470209
A5: 2011 | B5: 0.0649 | C5: 0.89952325
A6: 2012 | B6: 0.1117 | C6: 1
A7: 2013 | B7: 0.0913 | C7: 1.0913
A8: 2014 | B8: 0.0586 | C8: 1.1552502
A9: 2015 | B9: 0.0632 | C9: 1.228262
A10: 2016 | B10: 0.0223 | C10: 1.2556522
A11: 2017 | B11: 0.04 | C11: 1.3058783
A12: 2018 | B12: 0.0524 | C12: 1.374
A13: 2019 | B13: 0.0766 | C13: 1.5278164
A14: 2020 | B14: 0.0558 | C14: 1.6448471
A15: 2021 | B15: 0.0489 | C15: 1.7366296
A17: Rupees per dollar | B17: See scaling-factors.xlsx for source info
A18: 2010 | B18: 44.81
A19: 2011 | B19: 53.26
A20: 2012 | B20: 54.77
A21: 2013 | B21: 61.89
A22: 2014 | B22: 63.33
A23: 2015 | B23: 66.32
A24: 2016 | B24: 67.95
A25: 2017 | B25: 63.92
A26: 2018 | B26: 68.66
A27: 2019 | B27: 70.897
A28: 2020 | B28: 74.225
A29: 2021 | B29: 74.504
A30: Source: Economic Survey (30.01.2023) https://www.indiabudget.gov.in/economicsurvey/doc/stat/tab54.pdf
A31: Fuel-Independent Conversion Factors
A32: liters per barrel | B32: 158.9873
A33: BTU/kcal | B33: 3.96567
A34: BTU/kWh (unit conversion, not a heat rate) | B34: 3412.14
A36: Energy in Biomass
A37: Wood wastes | B37: =AVERAGE(2500,3850) -> 3175 | C37: kcal/kg
A38: Cowdung | B38: =AVERAGE(3140,3290) -> 3215 | C38: kcal/kg
A39: Average of biomass fuels | B39: =AVERAGE(B37:B38) -> 3195 | C39: kcal/kg
B40: 3.96567 | C40: BTU/kcal
B41: =B39*B40 -> 12670.316 | C41: BTU/kg
B42: =B41*1000 -> 12670316 | C42: BTU/ton
...

Sheet NatGas Calculations
A1: Natural Gas
B2: 2021-22 | C2: Unit
A3: Northeast Total Consumption Subsidy | B3: 405 | C3: Crores
B4: =B3*10^7 -> 4050000000 | C4: Rs
A6: Total consumption of Natural Gas | B6: 61491 | C6: Million Metric Standard Cubic Meters
A8: Conversions | B8: =B4/B6 -> 65863.297 | C8: Rs/MMSCM
B9: =B8/1000 -> 65.863297 | C9: Rs/thousand metric cubic meter
B10: =B9/'Conversion Factors'!B68 -> 1.829536e-06 | C10: Rs/BTU
B11: =B10/'Conversion Factors'!B29 -> 2.4556212e-08 | C11: USD/BTU
E22: Source: Indian Petroleum & Nat Gas Statistics, 2021-22
E23: Table V.1, Page 125

Sheet LPG
A1: Subsidy per selling unit (Rs per Litre/Cylinder ) of sensitive petroleum products
A2: Domestic LPG
B3: Total Subsidy | C3: Unit
B4: 242 | C4: (2021 rs/liter/cl)
B6: =B4 -> 242 | C6: 2021 Rs/cyl
B7: =B6/'Conversion Factors'!B64 -> 0.00038030497 | C7: 2021 Rs/BTU
B8: =B7/'Conversion Factors'!$C$15 -> 0.00021899027 | C8: 2012 Rs/BTU
A9: LPG Subsidy | B9: =B8/'Conversion Factors'!$B$20 -> 3.9983617e-06 | C9: 2012 USD/BTU
E13: Source: Snapshot of India's Oil and Gas data October 2023
E14: Table 25, page 35

Sheet Electricity
A1: Year | B1: 2013 | C1: 2014 | D1: 2015 | E1: 2016 | F1: 2017 | G1: 2018 | H1: 2019 | I1: 2020 | J1: 2021 | K1: 2022 | L1: 2023 | M1: 2024 | N1: 2025 | O1: 2026 | P1: 2027 | Q1: 2028 | R1: 2029 | S1: 2030 | T1: 2031 | U1: 2032 | V1: 2033 | W1: 2034 | X1: 2035 | Y1: 2036 | Z1: 2037 | AA1: 2038 | AB1: 2039 | AC1: 2040 | AD1: 2041 | AE1: 2042 | AF1: 2043 | AG1: 2044 | AH1: 2045 | AI1: 2046 | AJ1: 2047 | AK1: 2048 | AL1: 2049 | AM1: 2050
A2: Hydro ($subsidy) | B2: 0 | C2: 0 | D2: 0 | E2: 0 | F2: 0 | G2: 0 | H2: 0 | I2: 0 | J2: 0 | K2: 0 | L2: 0 | M2: 0 | N2: 0 | O2: 0 | P2: 0 | Q2: 0 | R2: 0 | S2: 0 | T2: 0 | U2: 0 | V2: 0 | W2: 0 | X2: 0 | Y2: 0 | Z2: 0 | AA2: 0 | AB2: 0 | AC2: 0 | AD2: 0 | AE2: 0 | AF2: 0 | AG2: 0 | AH2: 0 | AI2: 0 | AJ2: 0 | AK2: 0 | AL2: 0 | AM2: 0
A3: Hydro (MWh) | B3: 0 | C3: 0 | D3: 0 | E3: 0 | F3: 0 | G3: 0 | H3: 0 | I3: 0 | J3: 0 | K3: 0 | L3: 0 | M3: 0 | N3: 0 | O3: 0 | P3: 0 | Q3: 0 | R3: 0 | S3: 0 | T3: 0 | U3: 0 | V3: 0 | W3: 0 | X3: 0 | Y3: 0 | Z3: 0 | AA3: 0 | AB3: 0 | AC3: 0 | AD3: 0 | AE3: 0 | AF3: 0 | AG3: 0 | AH3: 0 | AI3: 0 | AJ3: 0 | AK3: 0 | AL3: 0 | AM3: 0
A4: hydro ($/MWh) | B4: 0 | C4: 0 | D4: 0 | E4: 0 | F4: 0 | G4: 0 | H4: 0 | I4: 0 | J4: 0 | K4: 0 | L4: 0 | M4: 0 | N4: 0 | O4: 0 | P4: 0 | Q4: 0 | R4: 0 | S4: 0 | T4: 0 | U4: 0 | V4: 0 | W4: 0 | X4: 0 | Y4: 0 | Z4: 0 | AA4: 0 | AB4: 0 | AC4: 0 | AD4: 0 | AE4: 0 | AF4: 0 | AG4: 0 | AH4: 0 | AI4: 0 | AJ4: 0 | AK4: 0 | AL4: 0 | AM4: 0
A5: onshore wind ($ subsidy) | B5: 0 | C5: - | D5: - | E5: - | F5: - | G5: 0 | H5: 0 | I5: 0 | J5: 0 | K5: 0 | L5: 0 | M5: 0 | N5: 0 | O5: 0 | P5: 0 | Q5: 0 | R5: 0 | S5: 0 | T5: 0 | U5: 0 | V5: 0 | W5: 0 | X5: 0 | Y5: 0 | Z5: 0 | AA5: 0 | AB5: 0 | AC5: 0 | AD5: 0 | AE5: 0 | AF5: 0 | AG5: 0 | AH5: 0 | AI5: 0 | AJ5: 0 | AK5: 0 | AL5: 0 | AM5: 0
A6: onshore wind (MWh) | B6: 0 | C6: 0 | D6: 0 | E6: 0 | F6: 0 | G6: 0 | H6: 0 | I6: 0 | J6: 0 | K6: 0 | L6: 0 | M6: 0 | N6: 0 | O6: 0 | P6: 0 | Q6: 0 | R6: 0 | S6: 0 | T6: 0 | U6: 0 | V6: 0 | W6: 0 | X6: 0 | Y6: 0 | Z6: 0 | AA6: 0 | AB6: 0 | AC6: 0 | AD6: 0 | AE6: 0 | AF6: 0 | AG6: 0 | AH6: 0 | AI6: 0 | AJ6: 0 | AK6: 0 | AL6: 0 | AM6: 0
A7: onshore wind ($/MWh) | B7: =C27/'Conversion Factors'!B20*1000 -> 9.1290853 | C7: =B7 -> 9.1290853 | D7: =C7 -> 9.1290853 | E7: =D7 -> 9.1290853 | F7: =E7 -> 9.1290853 | G7: 0 | H7: 0 | I7: 0 | J7: 0 | K7: 0 | L7: 0 | M7: 0 | N7: 0 | O7: 0 | P7: 0 | Q7: 0 | R7: 0 | S7: 0 | T7: 0 | U7: 0 | V7: 0 | W7: 0 | X7: 0 | Y7: 0 | Z7: 0 | AA7: 0 | AB7: 0 | AC7: 0 | AD7: 0 | AE7: 0 | AF7: 0 | AG7: 0 | AH7: 0 | AI7: 0 | AJ7: 0 | AK7: 0 | AL7: 0 | AM7: 0
A8: solar PV ($subsidy) | B8: 0 | C8: 0 | D8: 0 | E8: 0 | F8: 0 | G8: 0 | H8: 0 | I8: 0 | J8: 0 | K8: 0 | L8: 0 | M8: 0 | N8: 0 | O8: 0 | P8: 0 | Q8: 0 | R8: 0 | S8: 0 | T8: 0 | U8: 0 | V8: 0 | W8: 0 | X8: 0 | Y8: 0 | Z8: 0 | AA8: 0 | AB8: 0 | AC8: 0 | AD8: 0 | AE8: 0 | AF8: 0 | AG8: 0 | AH8: 0 | AI8: 0 | AJ8: 0 | AK8: 0 | AL8: 0 | AM8: 0
A9: solar PV (MWh) | B9: 0 | C9: 0 | D9: 0 | E9: 0 | F9: 0 | G9: 0 | H9: 0 | I9: 0 | J9: 0 | K9: 0 | L9: 0 | M9: 0 | N9: 0 | O9: 0 | P9: 0 | Q9: 0 | R9: 0 | S9: 0 | T9: 0 | U9: 0 | V9: 0 | W9: 0 | X9: 0 | Y9: 0 | Z9: 0 | AA9: 0 | AB9: 0 | AC9: 0 | AD9: 0 | AE9: 0 | AF9: 0 | AG9: 0 | AH9: 0 | AI9: 0 | AJ9: 0 | AK9: 0 | AL9: 0 | AM9: 0
A10: solar PV ($/MWh) | B10: 0 | C10: 0 | D10: 0 | E10: 0 | F10: 0 | G10: 0 | H10: 0 | I10: 0 | J10: 0 | K10: 0 | L10: 0 | M10: 0 | N10: 0 | O10: 0 | P10: 0 | Q10: 0 | R10: 0 | S10: 0 | T10: 0 | U10: 0 | V10: 0 | W10: 0 | X10: 0 | Y10: 0 | Z10: 0 | AA10: 0 | AB10: 0 | AC10: 0 | AD10: 0 | AE10: 0 | AF10: 0 | AG10: 0 | AH10: 0 | AI10: 0 | AJ10: 0 | AK10: 0 | AL10: 0 | AM10: 0
A11: solar thermal ($subsidy) | B11: 0 | C11: 0 | D11: 0 | E11: 0 | F11: 0 | G11: 0 | H11: 0 | I11: 0 | J11: 0 | K11: 0 | L11: 0 | M11: 0 | N11: 0 | O11: 0 | P11: 0 | Q11: 0 | R11: 0 | S11: 0 | T11: 0 | U11: 0 | V11: 0 | W11: 0 | X11: 0 | Y11: 0 | Z11: 0 | AA11: 0 | AB11: 0 | AC11: 0 | AD11: 0 | AE11: 0 | AF11: 0 | AG11: 0 | AH11: 0 | AI11: 0 | AJ11: 0 | AK11: 0 | AL11: 0 | AM11: 0
A12: solar thermal (MWh) | B12: 0 | C12: 0 | D12: 0 | E12: 0 | F12: 0 | G12: 0 | H12: 0 | I12: 0 | J12: 0 | K12: 0 | L12: 0 | M12: 0 | N12: 0 | O12: 0 | P12: 0 | Q12: 0 | R12: 0 | S12: 0 | T12: 0 | U12: 0 | V12: 0 | W12: 0 | X12: 0 | Y12: 0 | Z12: 0 | AA12: 0 | AB12: 0 | AC12: 0 | AD12: 0 | AE12: 0 | AF12: 0 | AG12: 0 | AH12: 0 | AI12: 0 | AJ12: 0 | AK12: 0 | AL12: 0 | AM12: 0
A13: solar thermal ($/MWh) | B13: 0 | C13: 0 | D13: 0 | E13: 0 | F13: 0 | G13: 0 | H13: 0 | I13: 0 | J13: 0 | K13: 0 | L13: 0 | M13: 0 | N13: 0 | O13: 0 | P13: 0 | Q13: 0 | R13: 0 | S13: 0 | T13: 0 | U13: 0 | V13: 0 | W13: 0 | X13: 0 | Y13: 0 | Z13: 0 | AA13: 0 | AB13: 0 | AC13: 0 | AD13: 0 | AE13: 0 | AF13: 0 | AG13: 0 | AH13: 0 | AI13: 0 | AJ13: 0 | AK13: 0 | AL13: 0 | AM13: 0
A14: biomass ($subsidy) | B14: 0 | C14: 0 | D14: 0 | E14: 0 | F14: 0 | G14: 0 | H14: 0 | I14: 0 | J14: 0 | K14: 0 | L14: 0 | M14: 0 | N14: 0 | O14: 0 | P14: 0 | Q14: 0 | R14: 0 | S14: 0 | T14: 0 | U14: 0 | V14: 0 | W14: 0 | X14: 0 | Y14: 0 | Z14: 0 | AA14: 0 | AB14: 0 | AC14: 0 | AD14: 0 | AE14: 0 | AF14: 0 | AG14: 0 | AH14: 0 | AI14: 0 | AJ14: 0 | AK14: 0 | AL14: 0 | AM14: 0
A15: biomass (MWh) | B15: 0 | C15: 0 | D15: 0 | E15: 0 | F15: 0 | G15: 0 | H15: 0 | I15: 0 | J15: 0 | K15: 0 | L15: 0 | M15: 0 | N15: 0 | O15: 0 | P15: 0 | Q15: 0 | R15: 0 | S15: 0 | T15: 0 | U15: 0 | V15: 0 | W15: 0 | X15: 0 | Y15: 0 | Z15: 0 | AA15: 0 | AB15: 0 | AC15: 0 | AD15: 0 | AE15: 0 | AF15: 0 | AG15: 0 | AH15: 0 | AI15: 0 | AJ15: 0 | AK15: 0 | AL15: 0 | AM15: 0
A16: biomass ($/MWh) | B16: 0 | C16: 0 | D16: 0 | E16: 0 | F16: 0 | G16: 0 | H16: 0 | I16: 0 | J16: 0 | K16: 0 | L16: 0 | M16: 0 | N16: 0 | O16: 0 | P16: 0 | Q16: 0 | R16: 0 | S16: 0 | T16: 0 | U16: 0 | V16: 0 | W16: 0 | X16: 0 | Y16: 0 | Z16: 0 | AA16: 0 | AB16: 0 | AC16: 0 | AD16: 0 | AE16: 0 | AF16: 0 | AG16: 0 | AH16: 0 | AI16: 0 | AJ16: 0 | AK16: 0 | AL16: 0 | AM16: 0
A17: geothermal ($Subsidy) | B17: 0 | C17: 0 | D17: 0 | E17: 0 | F17: 0 | G17: 0 | H17: 0 | I17: 0 | J17: 0 | K17: 0 | L17: 0 | M17: 0 | N17: 0 | O17: 0 | P17: 0 | Q17: 0 | R17: 0 | S17: 0 | T17: 0 | U17: 0 | V17: 0 | W17: 0 | X17: 0 | Y17: 0 | Z17: 0 | AA17: 0 | AB17: 0 | AC17: 0 | AD17: 0 | AE17: 0 | AF17: 0 | AG17: 0 | AH17: 0 | AI17: 0 | AJ17: 0 | AK17: 0 | AL17: 0 | AM17: 0
A18: geothermal (MWh) | B18: 0 | C18: 0 | D18: 0 | E18: 0 | F18: 0 | G18: 0 | H18: 0 | I18: 0 | J18: 0 | K18: 0 | L18: 0 | M18: 0 | N18: 0 | O18: 0 | P18: 0 | Q18: 0 | R18: 0 | S18: 0 | T18: 0 | U18: 0 | V18: 0 | W18: 0 | X18: 0 | Y18: 0 | Z18: 0 | AA18: 0 | AB18: 0 | AC18: 0 | AD18: 0 | AE18: 0 | AF18: 0 | AG18: 0 | AH18: 0 | AI18: 0 | AJ18: 0 | AK18: 0 | AL18: 0 | AM18: 0
A19: geothermal ($/MWh) | B19: 0 | C19: 0 | D19: 0 | E19: 0 | F19: 0 | G19: 0 | H19: 0 | I19: 0 | J19: 0 | K19: 0 | L19: 0 | M19: 0 | N19: 0 | O19: 0 | P19: 0 | Q19: 0 | R19: 0 | S19: 0 | T19: 0 | U19: 0 | V19: 0 | W19: 0 | X19: 0 | Y19: 0 | Z19: 0 | AA19: 0 | AB19: 0 | AC19: 0 | AD19: 0 | AE19: 0 | AF19: 0 | AG19: 0 | AH19: 0 | AI19: 0 | AJ19: 0 | AK19: 0 | AL19: 0 | AM19: 0
A23: https://www.pressreader.com/india/the-hindu-business-line/20180203/281728384962385
A24: GBI at INR 0.5/kWh was discontinued last year, but may be reintroduced
A25: For all other RE sources, the target figures for capacity addition will be checked with the capacity additions in the model, and caliberated accordingly, so subsidy values may not be required
A26: http://pib.nic.in/newsite/PrintRelease.aspx?relid=78829
A27: Generation based incentive for Wind | B27: INR/KWh | C27: =0.5 -> 0.5

Sheet RE
A1: Central Government Support to Renewable Energy (RE) sector (in INR crore)
A2: Subsidy | B2: SDG 12.c.1 category | C2: FY 2014 | D2: FY 2015 | E2: FY 2016 | F2: FY 2017 | G2: FY 2018 | H2: FY 2019 | I2: FY 2020 | J2: FY 2021 | K2: FY 2022
A3: Viability Gap Funding (VGF) under JNNSM Phase II | B3: Direct transfer of government funds | C3: 148.35 | D3: 148.35 | E3: 148.35 | F3: 148.35 | G3: 210.896 | H3: 398.445 | I3: 343.57775 | J3: 226.9632 | K3: 167.35
A4: Off-Grid and Decentralized Solar Application Scheme | B4: Direct transfer of government funds | C4: not available | D4: 224.27044 | E4: 684.47633 | F4: 548.83 | G4: 888.64 | H4: 620.89 | I4: 460.32 | J4: 149.43 | K4: 210
A5: Scheme for development of solar parks and Ultra Mega Solar Power projects | B5: Direct transfer of government funds | C5: not applicable | D5: 172.75 | E5: 370.29 | F5: 540.04 | G5: 358.71 | H5: 612.99 | I5: 291.7 | J5: 68.183456 | K5: 207.33
A6: Support for research and development activities | B6: Direct transfer of government funds | C6: 146.94 | D6: 131.634 | E6: 92.254 | F6: 258.831 | G6: 111.56 | H6: 44.43 | I6: 51.7 | J6: 67.32 | K6: 67.5
A7: Grid-Connected Solar Photovoltaic (PV) Rooftop and Small Solar Power Programme | B7: Direct transfer of government funds | C7: 1.5381886 | D7: 3.6824 | E7: 4.0157544 | F7: 499.6 | G7: 622.38 | H7: 446.77 | I7: 261.62 | J7: 297.22 | K7: 255.55
A8: National Biogas and Manure Management Programme (NBMMP) | B8: Direct transfer of government funds | C8: 90.26 | D8: 122.73 | E8: 131.1 | F8: not applicable | G8: not applicable | H8: not applicable | I8: not applicable | J8: not applicable | K8: not applicable
A9: Scheme for setting up of over 300 MW of solar power projects by defence establishments | B9: Direct transfer of government funds | C9: not applicable | D9: not available | E9: not available | F9: not available | G9: 27.535632 | H9: 58.75 | I9: 5.15 | J9: 10.895 | K9: 0
A10: Central Public Sector Undertakings (CPSUs) under JNNSM Phase II | B10: Direct transfer of government funds | C10: 0 | D10: 0 | E10: 128.75 | F10: 304.51 | G10: 148.74 | H10: 210 | I10: 319 | J10: 323.05 | K10: 27.37
A11: MNRE small hydro incentive schemes | B11: Direct transfer of government funds | C11: 114.1222 | D11: 106.49431 | E11: 105 | F11: 122 | G11: 120.41 | H11: 137.67 | I11: 77.27 | J11: 40.78 | K11: 66
A12: Financing and non-financing schemes: IREDA and other organizations | B12: Tax expenditure, other revenue foregone, and under-pricing of goods | C12: 65.135116 | D12: 106.04091 | E12: 159.54211 | F12: 270.63463 | G12: 401.50769 | H12: 501.63663 | I12: 536.71185 | J12: 522.25354 | K12: 590.95043
A13: Canal Bank/Canal Top Scheme | B13: Direct transfer of government funds | C13: not applicable | D13: 69 | E13: 0 | F13: 0 | G13: 0 | H13: 63.79 | I13: 11.5 | J13: 19.406829 | K13: 0
A14: Support for grid-interactive biomass power and bagasse cogeneration in sugar mills | B14: Direct transfer of government funds | C14: 5.59 | D14: 0 | E14: 29 | F14: 10.3 | G14: 7.79 | H14: 6.83 | I14: 4.5 | J14: 6.22 | K14: 56.85
A15: Biomass gasifier program | B15: Direct transfer of government funds | C15: 0 | D15: 14.333333 | E15: 14.333333 | F15: 14.333333 | G15: not applicable | H15: not applicable | I15: not applicable | J15: not applicabe | K15: not applicable
A16: Small Wind Energy and Hybrid Systems (SWES) program | B16: Direct transfer of government funds | C16: 5 | D16: 10 | E16: 3 | F16: 10 | G16: not applicable | H16: not applicable | I16: not applicable | J16: not applicable | K16: not applicable
A17: Capital subsidy scheme for promoting solar PV water pumping systems for irrigation purposes | B17: Direct transfer of government funds | C17: 0 | D17: 5.91 | E17: 14.7 | F17: 60.71 | G17: 9 | H17: 0.14 | I17: 0 | J17: 0 | K17: not available
A18: Biogas power (off-grid) program for decentralized power generation applications and thermal applications | B18: Direct transfer of government funds | C18: 5.84824 | D18: 0.4354 | E18: 28.7413 | F18: 91.17 | G18: 80.92 | H18: 46.06 | I18: 36.9 | J18: 49.27 | K18: 61.48
A19: Implementation of wind resource assessment in uncovered/new areas under the NCEF scheme and subsequent development | B19: Direct transfer of government funds | C19: 0.89086667 | D19: 0.45943333 | E19: 1.8020333 | F19: 0.98480667 | G19: not available | H19: not available | I19: not available | J19: not available | K19: not available
A20: Scheme for installation of solar charging stations with LED lanterns | B20: Direct transfer of government funds | C20: not applicable | D20: not applicable | E20: not applicable | F20: not applicable | G20: not available | H20: not available | I20: not available | J20: not available | K20: not available
A21: Akshay Urja Shops Programme | B21: Direct transfer of government funds | C21: 1.6955 | D21: 1.704 | E21: 1.704 | F21: 1.704 | G21: not applicable | H21: not applicable | I21: not applicable | J21: not applicable | K21: not applicable
A22: Accelerated depreciation for solar and wind projects | B22: Tax expenditure, other revenue foregone, and under-pricing of goods | C22: 1172.554 | D22: 2035.1961 | E22: 3309.4148 | F22: 5421.6923 | G22: 5754.0829 | H22: 2229.9205 | I22: 1715.8226 | J22: 334.39688 | K22: 3506.0487
A23: Tax breaks on excise and customs duty: Solar | B23: Tax expenditure, other revenue foregone, and under-pricing of goods | C23: 349.02581 | D23: 404.79187 | E23: 1042.1166 | F23: 1920.3034 | G23: not applicable | H23: not applicable | I23: not applicable | J23: not applicable | K23: not applicable
A24: Tax breaks on excise and customs duty: Wind | B24: Tax expenditure, other revenue foregone, and under-pricing of goods | C24: 624.97572 | D24: 655.83953 | E24: 1382.4259 | F24: 2896.0625 | G24: not applicable | H24: not applicable | I24: not applicable | J24: not applicable | K24: not applicable
A25: Waiver of inter-state transmission charges and losses on transmission of electricity generated from solar and wind plants | B25: Tax expenditure, other revenue foregone, and under-pricing of goods | C25: not available | D25: not available | E25: not available | F25: not available | G25: not available | H25: not available | I25: 430.44041 | J25: 1042.9851 | K25: 1085.0478
A26: Generation-based incentive (GBI) for grid -interactive wind power projects | B26: Induced transfers (price support) | C26: 290.89759 | D26: 563.83391 | E26: 306.84032 | F26: 634.26326 | G26: 1368.7253 | H26: 991.23539 | I26: 1129.9335 | J26: 1042.84 | K26: 1085.99
A27: GBI for small solar power generation | B27: Induced transfers (price support) | C27: 99.621871 | D27: 128.22821 | E27: 197.71202 | F27: 144.29065 | G27: 112.39702 | H27: 137.59029 | I27: 95.925508 | J27: 76.98 | K27: 91.13
A28: Market development and promotion of solar concentrator-based process heat applications | B28: Direct transfer of government funds | C28: 7.5 | D28: 8.3 | E28: 0 | F28: 6 | G28: 6 | H28: 3.76 | I28: 0.37 | J28: 0 | K28: not applicable
A29: Lower GST and customs duty: Solar | B29: Tax expenditure, other revenue foregone, and under-pricing of goods | C29: not applicable | D29: not applicable | E29: not applicable | F29: not applicable | G29: 1954.7081 | H29: 318.93074 | I29: 299.16147 | J29: 233.09701 | K29: 757.77041
A30: Lower GST and customs duty: Wind | B30: Tax expenditure, other revenue foregone, and under-pricing of goods | C30: not applicable | D30: not applicable | E30: not applicable | F30: not applicable | G30: 1276.293 | H30: 878.24631 | I30: 1131.911 | J30: 899.07676 | K30: 642.79387
A31: Pradhan Mantri Kisan Urja Suraksha evam Utthaan Mahabhiyan (PM-KUSUM) | B31: Direct transfer of government funds | C31: not applicable | D31: not applicable | E31: not applicable | F31: not applicable | G31: not applicable | H31: not applicable | I31: not applicable | J31: 0 | K31: 150
A32: Capital infusion for development of RE sector | B32: Direct transfer of government funds | C32: not applicable | D32: not applicable | E32: not applicable | F32: not applicable | G32: not applicable | H32: not applicable | I32: not applicable | J32: not applicable | K32: 2500
A33: Total | C33: =SUM(C3:C32) -> 3129.9451 | D33: =SUM(D3:D32) -> 4913.9838 | E33: =SUM(E3:E32) -> 8155.5685 | F33: =SUM(F3:F32) -> 13904.61 | G33: =SUM(G3:G32) -> 13460.296 | H33: =SUM(H3:H32) -> 7708.0849 | I33: =SUM(I3:I32) -> 7203.5141 | J33: =SUM(J3:J32) -> 5410.3678 | K33: =SUM(K3:K32) -> 11529.161
A36: Central Government Support to Renewable Energy Sector (in USD million)
A38: Subsidy | B38: SDG 12.c.1 category | C38: FY 2014 | D38: FY 2015 | E38: FY 2016 | F38: FY 2017 | G38: FY 2018 | H38: FY 2019 | I38: FY 2020 | J38: FY 2021 | K38: FY 2022
A39: Viability Gap Funding (VGF) under JNNSM Phase II | B39: Direct transfer of government funds | C39: 28.379391 | D39: 25.940942 | E39: 24.495696 | F39: 23.351474 | G39: 31.76719 | H39: 57.932075 | I39: 48.31202 | J39: 32.50197 | K39: 22.454045
A40: Off-Grid and Decentralized Solar Application Scheme | B40: Direct transfer of government funds | C40: not available | D40: 39.216626 | E40: 113.0214 | F40: 86.390222 | G40: 133.85553 | H40: 90.274557 | I40: 64.727675 | J40: 21.398929 | K40: 28.176573
A41: Scheme for development of solar parks and Ultra Mega Solar Power projects | B41: Direct transfer of government funds | C41: not applicable | D41: 30.207602 | E41: 61.142644 | F41: 85.006606 | G41: 54.03236 | H41: 89.125933 | I41: 41.017255 | J41: 9.7641231 | K41: 27.818328
A42: Support for research and development activities | B42: Direct transfer of government funds | C42: 28.109657 | D42: 23.01793 | E42: 15.23307 | F42: 40.742065 | G42: 16.804243 | H42: 6.4599181 | I42: 7.2697706 | J42: 9.6404731 | K42: 9.0567557
A43: Grid-Connected Solar Photovoltaic (PV) Rooftop and Small Solar Power Programme | B43: Direct transfer of government funds | C43: 0.29425585 | D43: 0.64391591 | E43: 0.66308527 | F43: 78.641027 | G43: 93.748879 | H43: 64.958308 | I43: 36.78757 | J43: 42.563004 | K43: 34.288206
...

Sheet Coal_Indirect
A1: Subsidy (in INR crores) | B1: 2013 | C1: 2014 | D1: 2015 | E1: 2016 | F1: 2017 | G1: 2018 | H1: 2019 | I1: 2020 | J1: 2021 | K1: 2022 | L1: 2023 | M1: 2024 | N1: 2025 | O1: 2026 | P1: 2027 | Q1: 2028 | R1: 2029 | S1: 2030 | T1: 2031 | U1: 2032 | V1: 2033 | W1: 2034 | X1: 2035 | Y1: 2036 | Z1: 2037 | AA1: 2038 | AB1: 2039 | AC1: 2040 | AD1: 2041 | AE1: 2042 | AF1: 2043 | AG1: 2044 | AH1: 2045 | AI1: 2046 | AJ1: 2047 | AK1: 2048 | AL1: 2049 | AM1: 2050
A2: Concessional custom duty rates on import of coal | C2: 7991 | D2: 7839 | E2: 6452 | F2: 7523
A3: Concessional excise duty rates on coal production | C3: 6215 | D3: 6526 | E3: 6886 | F3: 6896
A4: Concessional duty rebates on coal mining equipment | C4: 46 | D4: 59 | E4: 35 | F4: 68 | G4: 54
A5: Total | C5: =SUM(C2:C4) -> 14252 | D5: =SUM(D2:D4) -> 14424 | E5: =SUM(E2:E4) -> 13373 | F5: =SUM(F2:F4) -> 14487 | G5: =SUM(G2:G4) -> 54
A6: Total in $ | C6: =C5/C38*10000000 -> 2.2504342e+09 | D6: =D5/C39*10000000 -> 2.1749095e+09 | E6: =E5/C40*10000000 -> 1.9680648e+09 | F6: =F5/C41*10000000 -> 2.2664268e+09
A7: Coal consumption (million tonnes) | C7: =C24+D24 -> 998.19 | D7: =C25+D25 -> 944.82 | E7: =C26+D26 -> 1077.19 | F7: =D26+E26 -> 49.07
A8: Coal consumption (in BTU) | C8: =22829550700*1000000 -> 2.2829551e+16 | D8: =23242891000*1000000 -> 2.3242891e+16 | E8: =23377059900*1000000 -> 2.337706e+16 | F8: =23377059900*1000000 -> 2.337706e+16
A9: $/BTU | B9: =C9 -> 9.8575494e-08 | C9: =C6/C8 -> 9.8575494e-08 | D9: =D6/D8 -> 9.3573107e-08 | E9: =E6/E8 -> 8.4187865e-08 | F9: =E9 -> 8.4187865e-08 | G9: =F9 -> 8.4187865e-08 | H9: =G9 -> 8.4187865e-08 | I9: =H9 -> 8.4187865e-08 | J9: =I9 -> 8.4187865e-08 | K9: =J9 -> 8.4187865e-08 | L9: =K9 -> 8.4187865e-08 | M9: =L9 -> 8.4187865e-08 | ... AM9: =AL9 -> 8.4187865e-08
A10: $/MWh | C10: 0 | D10: 0 | E10: 0 | F10: 0 | G10: 0 | H10: 0 | I10: 0 | J10: 0 | K10: 0 | L10: 0 | M10: 0 | N10: 0 | O10: 0 | P10: 0 | Q10: 0 | R10: 0 | S10: 0 | T10: 0 | U10: 0 | V10: 0 | W10: 0 | X10: 0 | Y10: 0 | Z10: 0 | AA10: 0 | AB10: 0 | AC10: 0 | AD10: 0 | AE10: 0 | AF10: 0 | AG10: 0 | AH10: 0 | AI10: 0 | AJ10: 0 | AK10: 0 | AL10: 0 | AM10: 0
A14: Year | C14: Coal # | D14: Lignite
C15: (Million Tonnes)
A16: 1 | C16: 2 | D16: 3
A17: 2012-13 | C17: 713.39 | D17: 46.31
A18: 2013-14 | C18: 739.34 | D18: 43.9
A19: 2014-15 | C19: 822.13 | D19: 46.95
A20: 2015-16 | C20: 836.73 | D20: 42.21
A21: 2016-17 | C21: 837.22 | D21: 43.16
A22: 2017-18 | C22: 898.49 | D22: 46.32
A23: 2018-19 | C23: 968.36 | D23: 45.81
A24: 2019-20 | C24: 955.92 | D24: 42.27
A25: 2020-21 | C25: 906.33 | D25: 38.49
A26: 2021-22 (P) | C26: 1028.12 | D26: 49.07
A27: Growth rate of 2021-22 over 2020-21 (%) | C27: 13.44 | D27: 27.49
A28: CAGR 2012-13 to 2021-22 (P) (%) | C28: 4.14 | D28: 0.65
A31: Conversion Rates
A33: Rupees per dollar
A34: 2010 | C34: 44.81
A35: 2011 | C35: 53.26
A36: 2012 | C36: 54.77
A37: 2013 | C37: 61.89
A38: 2014 | C38: 63.33
A39: 2015 | C39: 66.32
A40: 2016 | C40: 67.95
A41: 2017 | C41: 63.92
A42: 2018 | C42: 68.66
A43: 2019 | C43: 70.897
A44: 2020 | C44: 74.225
A45: 2021 | C45: 74.504

Sheet BS-BSfTFpEUP
A1: Year | B1: 2021 | C1: 2022 | D1: 2023 | E1: 2024 | F1: 2025 | G1: 2026 | H1: 2027 | I1: 2028 | J1: 2029 | K1: 2030 | L1: 2031 | M1: 2032 | N1: 2033 | O1: 2034 | P1: 2035 | Q1: 2036 | R1: 2037 | S1: 2038 | T1: 2039 | U1: 2040 | V1: 2041 | W1: 2042 | X1: 2043 | Y1: 2044 | Z1: 2045 | AA1: 2046 | AB1: 2047 | AC1: 2048 | AD1: 2049 | AE1: 2050 | AF1: 2051 | AG1: 2052 | AH1: 2053 | AI1: 2054 | AJ1: 2055 | AK1: 2056 | AL1: 2057 | AM1: 2058 | AN1: 2059 | AO1: 2060 | AP1: 2061 | AQ1: 2062 | AR1: 2063 | AS1: 2064 | AT1: 2065 | AU1: 2066 | AV1: 2067 | AW1: 2068 | AX1: 2069 | AY1: 2070
A2: electricity | B2: 0 | C2: 0 | D2: 0 | E2: 0 | F2: 0 | G2: 0 | H2: 0 | I2: 0 | J2: 0 | K2: 0 | L2: 0 | M2: 0 | N2: 0 | O2: 0 | P2: 0 | Q2: =TREND($H2:$P2,$G$1:$O$1,P$1) -> 0 | R2: =TREND($H2:$P2,$G$1:$O$1,Q$1) -> 0 | S2: =TREND($H2:$P2,$G$1:$O$1,R$1) -> 0 | T2: =TREND($H2:$P2,$G$1:$O$1,S$1) -> 0 | U2: =TREND($H2:$P2,$G$1:$O$1,T$1) -> 0 | V2: =TREND($H2:$P2,$G$1:$O$1,U$1) -> 0 | W2: =TREND($H2:$P2,$G$1:$O$1,V$1) -> 0 | X2: =TREND($H2:$P2,$G$1:$O$1,W$1) -> 0 | ... AE2: =TREND($H2:$P2,$G$1:$O$1,AD$1) -> 0
A3: hard coal ($/BTU) | B3: =0 -> 0 | C3: =0 -> 0 | D3: =0 -> 0 | E3: =0 -> 0 | F3: =0 -> 0 | G3: =0 -> 0 | H3: =0 -> 0 | I3: =0 -> 0 | ... AE3: =0 -> 0
A4: natural gas ($/BTU) | B4: ='NatGas Calculations'!$B11 -> 2.4556212e-08 | C4: ='NatGas Calculations'!$B11 -> 2.4556212e-08 | D4: ='NatGas Calculations'!$B11 -> 2.4556212e-08 | E4: ='NatGas Calculations'!$B11 -> 2.4556212e-08 | F4: ='NatGas Calculations'!$B11 -> 2.4556212e-08 | G4: ='NatGas Calculations'!$B11 -> 2.4556212e-08 | H4: ='NatGas Calculations'!$B11 -> 2.4556212e-08 | I4: ='NatGas Calculations'!$B11 -> 2.4556212e-08 | ... AE4: ='NatGas Calculations'!$B11 -> 2.4556212e-08
A5: nuclear | B5: 0 | C5: 0 | D5: 0 | E5: 0 | F5: 0 | G5: 0 | H5: 0 | I5: 0 | J5: 0 | K5: 0 | L5: 0 | M5: 0 | N5: 0 | O5: 0 | P5: 0 | Q5: =TREND($H5:$P5,$G$1:$O$1,P$1) -> 0 | R5: =TREND($H5:$P5,$G$1:$O$1,Q$1) -> 0 | S5: =TREND($H5:$P5,$G$1:$O$1,R$1) -> 0 | T5: =TREND($H5:$P5,$G$1:$O$1,S$1) -> 0 | U5: =TREND($H5:$P5,$G$1:$O$1,T$1) -> 0 | V5: =TREND($H5:$P5,$G$1:$O$1,U$1) -> 0 | W5: =TREND($H5:$P5,$G$1:$O$1,V$1) -> 0 | X5: =TREND($H5:$P5,$G$1:$O$1,W$1) -> 0 | ... AE5: =TREND($H5:$P5,$G$1:$O$1,AD$1) -> 0
A6: hydro | B6: 0 | C6: 0 | D6: 0 | E6: 0 | F6: 0 | G6: 0 | H6: 0 | I6: 0 | J6: 0 | K6: 0 | L6: 0 | M6: 0 | N6: 0 | O6: 0 | P6: 0 | Q6: =TREND($H6:$P6,$G$1:$O$1,P$1) -> 0 | R6: =TREND($H6:$P6,$G$1:$O$1,Q$1) -> 0 | S6: =TREND($H6:$P6,$G$1:$O$1,R$1) -> 0 | T6: =TREND($H6:$P6,$G$1:$O$1,S$1) -> 0 | U6: =TREND($H6:$P6,$G$1:$O$1,T$1) -> 0 | V6: =TREND($H6:$P6,$G$1:$O$1,U$1) -> 0 | W6: =TREND($H6:$P6,$G$1:$O$1,V$1) -> 0 | X6: =TREND($H6:$P6,$G$1:$O$1,W$1) -> 0 | ... AE6: =TREND($H6:$P6,$G$1:$O$1,AD$1) -> 0
A7: wind | B7: 0 | C7: 0 | D7: 0 | E7: 0 | F7: 0 | G7: 0 | H7: 0 | I7: 0 | J7: 0 | K7: 0 | L7: 0 | M7: 0 | N7: 0 | O7: 0 | P7: 0 | Q7: =TREND($H7:$P7,$G$1:$O$1,P$1) -> 0 | R7: =TREND($H7:$P7,$G$1:$O$1,Q$1) -> 0 | S7: =TREND($H7:$P7,$G$1:$O$1,R$1) -> 0 | T7: =TREND($H7:$P7,$G$1:$O$1,S$1) -> 0 | U7: =TREND($H7:$P7,$G$1:$O$1,T$1) -> 0 | V7: =TREND($H7:$P7,$G$1:$O$1,U$1) -> 0 | W7: =TREND($H7:$P7,$G$1:$O$1,V$1) -> 0 | X7: =TREND($H7:$P7,$G$1:$O$1,W$1) -> 0 | ... AE7: =TREND($H7:$P7,$G$1:$O$1,AD$1) -> 0
A8: solar | B8: 0 | C8: 0 | D8: 0 | E8: 0 | F8: 0 | G8: 0 | H8: 0 | I8: 0 | J8: 0 | K8: 0 | L8: 0 | M8: 0 | N8: 0 | O8: 0 | P8: 0 | Q8: =TREND($H8:$P8,$G$1:$O$1,P$1) -> 0 | R8: =TREND($H8:$P8,$G$1:$O$1,Q$1) -> 0 | S8: =TREND($H8:$P8,$G$1:$O$1,R$1) -> 0 | T8: =TREND($H8:$P8,$G$1:$O$1,S$1) -> 0 | U8: =TREND($H8:$P8,$G$1:$O$1,T$1) -> 0 | V8: =TREND($H8:$P8,$G$1:$O$1,U$1) -> 0 | W8: =TREND($H8:$P8,$G$1:$O$1,V$1) -> 0 | X8: =TREND($H8:$P8,$G$1:$O$1,W$1) -> 0 | ... AE8: =TREND($H8:$P8,$G$1:$O$1,AD$1) -> 0
A9: biomass ($/BTU) | B9: 0 | C9: 0 | D9: 0 | E9: 0 | F9: 0 | G9: 0 | H9: 0 | I9: 0 | J9: 0 | K9: 0 | L9: 0 | M9: 0 | N9: 0 | O9: 0 | P9: 0 | Q9: 0 | R9: 0 | S9: 0 | T9: 0 | U9: 0 | V9: 0 | W9: 0 | X9: 0 | Y9: 0 | Z9: 0 | AA9: 0 | AB9: 0 | AC9: 0 | AD9: 0 | AE9: 0
A10: petroleum gasoline ($/BTU) | B10: =0 -> 0 | C10: =0 -> 0 | D10: =0 -> 0 | E10: =0 -> 0 | F10: =0 -> 0 | G10: =0 -> 0 | H10: =0 -> 0 | I10: =0 -> 0 | ... AE10: =0 -> 0
A11: petroleum diesel ($/BTU) | B11: =0 -> 0 | C11: =0 -> 0 | D11: =0 -> 0 | E11: =0 -> 0 | F11: =0 -> 0 | G11: =0 -> 0 | H11: =0 -> 0 | I11: =0 -> 0 | ... AE11: =0 -> 0
A12: biofuel gasoline | B12: 0 | C12: 0 | D12: 0 | E12: 0 | F12: 0 | G12: 0 | H12: 0 | I12: 0 | J12: 0 | K12: 0 | L12: 0 | M12: 0 | N12: 0 | O12: 0 | P12: 0 | Q12: =TREND($H12:$P12,$G$1:$O$1,P$1) -> 0 | R12: =TREND($H12:$P12,$G$1:$O$1,Q$1) -> 0 | S12: =TREND($H12:$P12,$G$1:$O$1,R$1) -> 0 | T12: =TREND($H12:$P12,$G$1:$O$1,S$1) -> 0 | U12: =TREND($H12:$P12,$G$1:$O$1,T$1) -> 0 | V12: =TREND($H12:$P12,$G$1:$O$1,U$1) -> 0 | W12: =TREND($H12:$P12,$G$1:$O$1,V$1) -> 0 | X12: =TREND($H12:$P12,$G$1:$O$1,W$1) -> 0 | ... AE12: =TREND($H12:$P12,$G$1:$O$1,AD$1) -> 0
A13: biofuel diesel | B13: 0 | C13: 0 | D13: 0 | E13: 0 | F13: 0 | G13: 0 | H13: 0 | I13: 0 | J13: 0 | K13: 0 | L13: 0 | M13: 0 | N13: 0 | O13: 0 | P13: 0 | Q13: =TREND($H13:$P13,$G$1:$O$1,P$1) -> 0 | R13: =TREND($H13:$P13,$G$1:$O$1,Q$1) -> 0 | S13: =TREND($H13:$P13,$G$1:$O$1,R$1) -> 0 | T13: =TREND($H13:$P13,$G$1:$O$1,S$1) -> 0 | U13: =TREND($H13:$P13,$G$1:$O$1,T$1) -> 0 | V13: =TREND($H13:$P13,$G$1:$O$1,U$1) -> 0 | W13: =TREND($H13:$P13,$G$1:$O$1,V$1) -> 0 | X13: =TREND($H13:$P13,$G$1:$O$1,W$1) -> 0 | ... AE13: =TREND($H13:$P13,$G$1:$O$1,AD$1) -> 0
A14: jet fuel ($/BTU) | B14: 0 | C14: 0 | D14: 0 | E14: 0 | F14: 0 | G14: 0 | H14: 0 | I14: 0 | J14: 0 | K14: 0 | L14: 0 | M14: 0 | N14: 0 | O14: 0 | P14: 0 | Q14: 0 | R14: 0 | S14: 0 | T14: 0 | U14: 0 | V14: 0 | W14: 0 | X14: 0 | Y14: 0 | Z14: 0 | AA14: 0 | AB14: 0 | AC14: 0 | AD14: 0 | AE14: 0
A15: heat | B15: 0 | C15: 0 | D15: 0 | E15: 0 | F15: 0 | G15: 0 | H15: 0 | I15: 0 | J15: 0 | K15: 0 | L15: 0 | M15: 0 | N15: 0 | O15: 0 | P15: 0 | Q15: 0 | R15: 0 | S15: 0 | T15: 0 | U15: 0 | V15: 0 | W15: 0 | X15: 0 | Y15: 0 | Z15: 0 | AA15: 0 | AB15: 0 | AC15: 0 | AD15: 0 | AE15: 0
A16: geothermal | B16: 0 | C16: 0 | D16: 0 | E16: 0 | F16: 0 | G16: 0 | H16: 0 | I16: 0 | J16: 0 | K16: 0 | L16: 0 | M16: 0 | N16: 0 | O16: 0 | P16: 0 | Q16: 0 | R16: 0 | S16: 0 | T16: 0 | U16: 0 | V16: 0 | W16: 0 | X16: 0 | Y16: 0 | Z16: 0 | AA16: 0 | AB16: 0 | AC16: 0 | AD16: 0 | AE16: 0
A17: lignite ($/BTU) | B17: =B3 -> 0 | C17: =C3 -> 0 | D17: =D3 -> 0 | E17: =E3 -> 0 | F17: =F3 -> 0 | G17: =G3 -> 0 | H17: =H3 -> 0 | I17: =I3 -> 0 | ... O17: =O3 -> 0 | P17: 0 | Q17: 0 | R17: 0 | S17: 0 | T17: 0 | U17: 0 | V17: 0 | W17: 0 | X17: 0 | Y17: 0 | Z17: 0 | AA17: 0 | AB17: 0 | AC17: 0 | AD17: 0 | AE17: 0
A18: crude oil | B18: 0 | C18: 0 | D18: 0 | E18: 0 | F18: 0 | G18: 0 | H18: 0 | I18: 0 | J18: 0 | K18: 0 | L18: 0 | M18: 0 | N18: 0 | O18: 0 | P18: 0 | Q18: 0 | R18: 0 | S18: 0 | T18: 0 | U18: 0 | V18: 0 | W18: 0 | X18: 0 | Y18: 0 | Z18: 0 | AA18: 0 | AB18: 0 | AC18: 0 | AD18: 0 | AE18: 0
A19: heavy fuel oil | B19: 0 | C19: 0 | D19: 0 | E19: 0 | F19: 0 | G19: 0 | H19: 0 | I19: 0 | J19: 0 | K19: 0 | L19: 0 | M19: 0 | N19: 0 | O19: 0 | P19: 0 | Q19: 0 | R19: 0 | S19: 0 | T19: 0 | U19: 0 | V19: 0 | W19: 0 | X19: 0 | Y19: 0 | Z19: 0 | AA19: 0 | AB19: 0 | AC19: 0 | AD19: 0 | AE19: 0
A20: LPG propane or butane | B20: =LPG!B9 -> 3.9983617e-06 | C20: =B20 -> 3.9983617e-06 | D20: =C20 -> 3.9983617e-06 | E20: =D20 -> 3.9983617e-06 | F20: =E20 -> 3.9983617e-06 | G20: =F20 -> 3.9983617e-06 | H20: =G20 -> 3.9983617e-06 | I20: =H20 -> 3.9983617e-06 | J20: =I20 -> 3.9983617e-06 | ... AE20: =AD20 -> 3.9983617e-06
A21: municipal solid waste | B21: 0 | C21: 0 | D21: 0 | E21: 0 | F21: 0 | G21: 0 | H21: 0 | I21: 0 | J21: 0 | K21: 0 | L21: 0 | M21: 0 | N21: 0 | O21: 0 | P21: 0 | Q21: =TREND($H21:$P21,$G$1:$O$1,P$1) -> 0 | R21: =TREND($H21:$P21,$G$1:$O$1,Q$1) -> 0 | S21: =TREND($H21:$P21,$G$1:$O$1,R$1) -> 0 | T21: =TREND($H21:$P21,$G$1:$O$1,S$1) -> 0 | U21: =TREND($H21:$P21,$G$1:$O$1,T$1) -> 0 | V21: =TREND($H21:$P21,$G$1:$O$1,U$1) -> 0 | W21: =TREND($H21:$P21,$G$1:$O$1,V$1) -> 0 | X21: =TREND($H21:$P21,$G$1:$O$1,W$1) -> 0 | ... AE21: =TREND($H21:$P21,$G$1:$O$1,AD$1) -> 0
A22: hydrogen | B22: 0 | C22: 0 | D22: 0 | E22: 0 | F22: 0 | G22: 0 | H22: 0 | I22: 0 | J22: 0 | K22: 0 | L22: 0 | M22: 0 | N22: 0 | O22: 0 | P22: 0 | Q22: =TREND($H22:$P22,$G$1:$O$1,P$1) -> 0 | R22: =TREND($H22:$P22,$G$1:$O$1,Q$1) -> 0 | S22: =TREND($H22:$P22,$G$1:$O$1,R$1) -> 0 | T22: =TREND($H22:$P22,$G$1:$O$1,S$1) -> 0 | U22: =TREND($H22:$P22,$G$1:$O$1,T$1) -> 0 | V22: =TREND($H22:$P22,$G$1:$O$1,U$1) -> 0 | W22: =TREND($H22:$P22,$G$1:$O$1,V$1) -> 0 | X22: =TREND($H22:$P22,$G$1:$O$1,W$1) -> 0 | ... AE22: =TREND($H22:$P22,$G$1:$O$1,AD$1) -> 0

Sheet BS-BSpUEO
A1: Year | B1: 2021 | C1: 2022 | D1: 2023 | E1: 2024 | F1: 2025 | G1: 2026 | H1: 2027 | I1: 2028 | J1: 2029 | K1: 2030 | L1: 2031 | M1: 2032 | N1: 2033 | O1: 2034 | P1: 2035 | Q1: 2036 | R1: 2037 | S1: 2038 | T1: 2039 | U1: 2040 | V1: 2041 | W1: 2042 | X1: 2043 | Y1: 2044 | Z1: 2045 | AA1: 2046 | AB1: 2047 | AC1: 2048 | AD1: 2049 | AE1: 2050 | AF1: 2051 | AG1: 2052 | AH1: 2053 | AI1: 2054 | AJ1: 2055 | AK1: 2056 | AL1: 2057 | AM1: 2058 | AN1: 2059 | AO1: 2060 | AP1: 2061 | AQ1: 2062 | AR1: 2063 | AS1: 2064 | AT1: 2065 | AU1: 2066 | AV1: 2067 | AW1: 2068 | AX1: 2069 | AY1: 2070
A2: hard coal | B2: 0 | C2: 0 | D2: 0 | E2: 0 | F2: 0 | G2: 0 | H2: 0 | I2: 0 | J2: 0 | K2: 0 | L2: 0 | M2: 0 | N2: 0 | O2: 0 | P2: 0 | Q2: 0 | R2: 0 | S2: 0 | T2: 0 | U2: 0 | V2: 0 | W2: 0 | X2: 0 | Y2: 0 | Z2: 0 | AA2: 0 | AB2: 0 | AC2: 0 | AD2: 0 | AE2: 0
A3: natural gas steam turbine | B3: 0 | C3: 0 | D3: 0 | E3: 0 | F3: 0 | G3: 0 | H3: 0 | I3: 0 | J3: 0 | K3: 0 | L3: 0 | M3: 0 | N3: 0 | O3: 0 | P3: 0 | Q3: 0 | R3: 0 | S3: 0 | T3: 0 | U3: 0 | V3: 0 | W3: 0 | X3: 0 | Y3: 0 | Z3: 0 | AA3: 0 | AB3: 0 | AC3: 0 | AD3: 0 | AE3: 0
A4: natural gas combined cycle | B4: 0 | C4: 0 | D4: 0 | E4: 0 | F4: 0 | G4: 0 | H4: 0 | I4: 0 | J4: 0 | K4: 0 | L4: 0 | M4: 0 | N4: 0 | O4: 0 | P4: 0 | Q4: 0 | R4: 0 | S4: 0 | T4: 0 | U4: 0 | V4: 0 | W4: 0 | X4: 0 | Y4: 0 | Z4: 0 | AA4: 0 | AB4: 0 | AC4: 0 | AD4: 0 | AE4: 0
A5: nuclear | B5: 0 | C5: 0 | D5: 0 | E5: 0 | F5: 0 | G5: 0 | H5: 0 | I5: 0 | J5: 0 | K5: 0 | L5: 0 | M5: 0 | N5: 0 | O5: 0 | P5: 0 | Q5: 0 | R5: 0 | S5: 0 | T5: 0 | U5: 0 | V5: 0 | W5: 0 | X5: 0 | Y5: 0 | Z5: 0 | AA5: 0 | AB5: 0 | AC5: 0 | AD5: 0 | AE5: 0
A6: hydro | B6: 0 | C6: 0 | D6: 0 | E6: 0 | F6: 0 | G6: 0 | H6: 0 | I6: 0 | J6: 0 | K6: 0 | L6: 0 | M6: 0 | N6: 0 | O6: 0 | P6: 0 | Q6: 0 | R6: 0 | S6: 0 | T6: 0 | U6: 0 | V6: 0 | W6: 0 | X6: 0 | Y6: 0 | Z6: 0 | AA6: 0 | AB6: 0 | AC6: 0 | AD6: 0 | AE6: 0
A7: onshore wind | B7: 0 | C7: 0 | D7: 0 | E7: 0 | F7: 0 | G7: 0 | H7: 0 | I7: 0 | J7: 0 | K7: 0 | L7: 0 | M7: 0 | N7: 0 | O7: 0 | P7: 0 | Q7: 0 | R7: 0 | S7: 0 | T7: 0 | U7: 0 | V7: 0 | W7: 0 | X7: 0 | Y7: 0 | Z7: 0 | AA7: 0 | AB7: 0 | AC7: 0 | AD7: 0 | AE7: 0
A8: solar PV | B8: 0 | C8: 0 | D8: 0 | E8: 0 | F8: 0 | G8: 0 | H8: 0 | I8: 0 | J8: 0 | K8: 0 | L8: 0 | M8: 0 | N8: 0 | O8: 0 | P8: 0 | Q8: 0 | R8: 0 | S8: 0 | T8: 0 | U8: 0 | V8: 0 | W8: 0 | X8: 0 | Y8: 0 | Z8: 0 | AA8: 0 | AB8: 0 | AC8: 0 | AD8: 0 | AE8: 0
A9: solar thermal | B9: 0 | C9: 0 | D9: 0 | E9: 0 | F9: 0 | G9: 0 | H9: 0 | I9: 0 | J9: 0 | K9: 0 | L9: 0 | M9: 0 | N9: 0 | O9: 0 | P9: 0 | Q9: 0 | R9: 0 | S9: 0 | T9: 0 | U9: 0 | V9: 0 | W9: 0 | X9: 0 | Y9: 0 | Z9: 0 | AA9: 0 | AB9: 0 | AC9: 0 | AD9: 0 | AE9: 0
A10: biomass | B10: 0 | C10: 0 | D10: 0 | E10: 0 | F10: 0 | G10: 0 | H10: 0 | I10: 0 | J10: 0 | K10: 0 | L10: 0 | M10: 0 | N10: 0 | O10: 0 | P10: 0 | Q10: 0 | R10: 0 | S10: 0 | T10: 0 | U10: 0 | V10: 0 | W10: 0 | X10: 0 | Y10: 0 | Z10: 0 | AA10: 0 | AB10: 0 | AC10: 0 | AD10: 0 | AE10: 0
A11: geothermal | B11: 0 | C11: 0 | D11: 0 | E11: 0 | F11: 0 | G11: 0 | H11: 0 | I11: 0 | J11: 0 | K11: 0 | L11: 0 | M11: 0 | N11: 0 | O11: 0 | P11: 0 | Q11: 0 | R11: 0 | S11: 0 | T11: 0 | U11: 0 | V11: 0 | W11: 0 | X11: 0 | Y11: 0 | Z11: 0 | AA11: 0 | AB11: 0 | AC11: 0 | AD11: 0 | AE11: 0
A12: petroleum | B12: 0 | C12: 0 | D12: 0 | E12: 0 | F12: 0 | G12: 0 | H12: 0 | I12: 0 | J12: 0 | K12: 0 | L12: 0 | M12: 0 | N12: 0 | O12: 0 | P12: 0 | Q12: 0 | R12: 0 | S12: 0 | T12: 0 | U12: 0 | V12: 0 | W12: 0 | X12: 0 | Y12: 0 | Z12: 0 | AA12: 0 | AB12: 0 | AC12: 0 | AD12: 0 | AE12: 0
A13: natural gas peaker | B13: 0 | C13: 0 | D13: 0 | E13: 0 | F13: 0 | G13: 0 | H13: 0 | I13: 0 | J13: 0 | K13: 0 | L13: 0 | M13: 0 | N13: 0 | O13: 0 | P13: 0 | Q13: 0 | R13: 0 | S13: 0 | T13: 0 | U13: 0 | V13: 0 | W13: 0 | X13: 0 | Y13: 0 | Z13: 0 | AA13: 0 | AB13: 0 | AC13: 0 | AD13: 0 | AE13: 0
... A25: hydrogen combined cycle | B25: 0 | C25: 0 | D25: 0 | E25: 0 | F25: 0 | G25: 0 | H25: 0 | I25: 0 | J25: 0 | K25: 0 | L25: 0 | M25: 0 | N25: 0 | O25: 0 | P25: 0 | Q25: 0 | R25: 0 | S25: 0 | T25: 0 | U25: 0 | V25: 0 | W25: 0 | X25: 0 | Y25: 0 | Z25: 0 | AA25: 0 | AB25: 0 | AC25: 0 | AD25: 0 | AE25: 0

Sheet BS-BSpUECB
A1: % of capital costs | B1: 2021 | C1: 2022 | D1: 2023 | E1: 2024 | F1: 2025 | G1: 2026 | H1: 2027 | I1: 2028 | J1: 2029 | K1: 2030 | L1: 2031 | M1: 2032 | N1: 2033 | O1: 2034 | P1: 2035 | Q1: 2036 | R1: 2037 | S1: 2038 | T1: 2039 | U1: 2040 | V1: 2041 | W1: 2042 | X1: 2043 | Y1: 2044 | Z1: 2045 | AA1: 2046 | AB1: 2047 | AC1: 2048 | AD1: 2049 | AE1: 2050 | AF1: 2051 | AG1: 2052 | AH1: 2053 | AI1: 2054 | AJ1: 2055 | AK1: 2056 | AL1: 2057 | AM1: 2058 | AN1: 2059 | AO1: 2060 | AP1: 2061 | AQ1: 2062 | AR1: 2063 | AS1: 2064 | AT1: 2065 | AU1: 2066 | AV1: 2067 | AW1: 2068 | AX1: 2069 | AY1: 2070
A2: hard coal | B2: 0 | C2: 0 | D2: 0 | E2: 0 | F2: 0 | G2: 0 | H2: 0 | I2: 0 | J2: 0 | K2: 0 | L2: 0 | M2: 0 | N2: 0 | O2: 0 | P2: 0 | Q2: 0 | R2: 0 | S2: 0 | T2: 0 | U2: 0 | V2: 0 | W2: 0 | X2: 0 | Y2: 0 | Z2: 0 | AA2: 0 | AB2: 0 | AC2: 0 | AD2: 0 | AE2: 0
A3: natural gas steam turbine | B3: 0 | C3: 0 | D3: 0 | E3: 0 | F3: 0 | G3: 0 | H3: 0 | I3: 0 | J3: 0 | K3: 0 | L3: 0 | M3: 0 | N3: 0 | O3: 0 | P3: 0 | Q3: 0 | R3: 0 | S3: 0 | T3: 0 | U3: 0 | V3: 0 | W3: 0 | X3: 0 | Y3: 0 | Z3: 0 | AA3: 0 | AB3: 0 | AC3: 0 | AD3: 0 | AE3: 0
A4: natural gas combined cycle | B4: 0 | C4: 0 | D4: 0 | E4: 0 | F4: 0 | G4: 0 | H4: 0 | I4: 0 | J4: 0 | K4: 0 | L4: 0 | M4: 0 | N4: 0 | O4: 0 | P4: 0 | Q4: 0 | R4: 0 | S4: 0 | T4: 0 | U4: 0 | V4: 0 | W4: 0 | X4: 0 | Y4: 0 | Z4: 0 | AA4: 0 | AB4: 0 | AC4: 0 | AD4: 0 | AE4: 0
A5: nuclear | B5: 0 | C5: 0 | D5: 0 | E5: 0 | F5: 0 | G5: 0 | H5: 0 | I5: 0 | J5: 0 | K5: 0 | L5: 0 | M5: 0 | N5: 0 | O5: 0 | P5: 0 | Q5: 0 | R5: 0 | S5: 0 | T5: 0 | U5: 0 | V5: 0 | W5: 0 | X5: 0 | Y5: 0 | Z5: 0 | AA5: 0 | AB5: 0 | AC5: 0 | AD5: 0 | AE5: 0
A6: hydro | B6: 0 | C6: 0 | D6: 0 | E6: 0 | F6: 0 | G6: 0 | H6: 0 | I6: 0 | J6: 0 | K6: 0 | L6: 0 | M6: 0 | N6: 0 | O6: 0 | P6: 0 | Q6: 0 | R6: 0 | S6: 0 | T6: 0 | U6: 0 | V6: 0 | W6: 0 | X6: 0 | Y6: 0 | Z6: 0 | AA6: 0 | AB6: 0 | AC6: 0 | AD6: 0 | AE6: 0
A7: onshore wind | B7: 0 | C7: 0 | D7: 0 | E7: 0 | F7: 0 | G7: 0 | H7: 0 | I7: 0 | J7: 0 | K7: 0 | L7: 0 | M7: 0 | N7: 0 | O7: 0 | P7: 0 | Q7: 0 | R7: 0 | S7: 0 | T7: 0 | U7: 0 | V7: 0 | W7: 0 | X7: 0 | Y7: 0 | Z7: 0 | AA7: 0 | AB7: 0 | AC7: 0 | AD7: 0 | AE7: 0
A8: solar PV | B8: 0 | C8: 0 | D8: 0 | E8: 0 | F8: 0 | G8: 0 | H8: 0 | I8: 0 | J8: 0 | K8: 0 | L8: 0 | M8: 0 | N8: 0 | O8: 0 | P8: 0 | Q8: 0 | R8: 0 | S8: 0 | T8: 0 | U8: 0 | V8: 0 | W8: 0 | X8: 0 | Y8: 0 | Z8: 0 | AA8: 0 | AB8: 0 | AC8: 0 | AD8: 0 | AE8: 0
A9: solar thermal | B9: 0 | C9: 0 | D9: 0 | E9: 0 | F9: 0 | G9: 0 | H9: 0 | I9: 0 | J9: 0 | K9: 0 | L9: 0 | M9: 0 | N9: 0 | O9: 0 | P9: 0 | Q9: 0 | R9: 0 | S9: 0 | T9: 0 | U9: 0 | V9: 0 | W9: 0 | X9: 0 | Y9: 0 | Z9: 0 | AA9: 0 | AB9: 0 | AC9: 0 | AD9: 0 | AE9: 0
A10: biomass | B10: 0 | C10: 0 | D10: 0 | E10: 0 | F10: 0 | G10: 0 | H10: 0 | I10: 0 | J10: 0 | K10: 0 | L10: 0 | M10: 0 | N10: 0 | O10: 0 | P10: 0 | Q10: 0 | R10: 0 | S10: 0 | T10: 0 | U10: 0 | V10: 0 | W10: 0 | X10: 0 | Y10: 0 | Z10: 0 | AA10: 0 | AB10: 0 | AC10: 0 | AD10: 0 | AE10: 0
A11: geothermal | B11: 0 | C11: 0 | D11: 0 | E11: 0 | F11: 0 | G11: 0 | H11: 0 | I11: 0 | J11: 0 | K11: 0 | L11: 0 | M11: 0 | N11: 0 | O11: 0 | P11: 0 | Q11: 0 | R11: 0 | S11: 0 | T11: 0 | U11: 0 | V11: 0 | W11: 0 | X11: 0 | Y11: 0 | Z11: 0 | AA11: 0 | AB11: 0 | AC11: 0 | AD11: 0 | AE11: 0
A12: petroleum | B12: 0 | C12: 0 | D12: 0 | E12: 0 | F12: 0 | G12: 0 | H12: 0 | I12: 0 | J12: 0 | K12: 0 | L12: 0 | M12: 0 | N12: 0 | O12: 0 | P12: 0 | Q12: 0 | R12: 0 | S12: 0 | T12: 0 | U12: 0 | V12: 0 | W12: 0 | X12: 0 | Y12: 0 | Z12: 0 | AA12: 0 | AB12: 0 | AC12: 0 | AD12: 0 | AE12: 0
A13: natural gas peaker | B13: 0 | C13: 0 | D13: 0 | E13: 0 | F13: 0 | G13: 0 | H13: 0 | I13: 0 | J13: 0 | K13: 0 | L13: 0 | M13: 0 | N13: 0 | O13: 0 | P13: 0 | Q13: 0 | R13: 0 | S13: 0 | T13: 0 | U13: 0 | V13: 0 | W13: 0 | X13: 0 | Y13: 0 | Z13: 0 | AA13: 0 | AB13: 0 | AC13: 0 | AD13: 0 | AE13: 0
... A25: hydrogen combined cycle | B25: 0 | C25: 0 | D25: 0 | E25: 0 | F25: 0 | G25: 0 | H25: 0 | I25: 0 | J25: 0 | K25: 0 | L25: 0 | M25: 0 | N25: 0 | O25: 0 | P25: 0 | Q25: 0 | R25: 0 | S25: 0 | T25: 0 | U25: 0 | V25: 0 | W25: 0 | X25: 0 | Y25: 0 | Z25: 0 | AA25: 0 | AB25: 0 | AC25: 0 | AD25: 0 | AE25: 0

Sheet BS-DoSpUEO
A1: Year | B1: 2021 | C1: 2022 | D1: 2023 | E1: 2024 | F1: 2025 | G1: 2026 | H1: 2027 | I1: 2028 | J1: 2029 | K1: 2030 | L1: 2031 | M1: 2032 | N1: 2033 | O1: 2034 | P1: 2035 | Q1: 2036 | R1: 2037 | S1: 2038 | T1: 2039 | U1: 2040 | V1: 2041 | W1: 2042 | X1: 2043 | Y1: 2044 | Z1: 2045 | AA1: 2046 | AB1: 2047 | AC1: 2048 | AD1: 2049 | AE1: 2050
A2: hard coal | B2: 10 | C2: 10 | D2: 10 | E2: 10 | F2: 10 | G2: 10 | H2: 10 | I2: 10 | J2: 10 | K2: 10 | L2: 10 | M2: 10 | N2: 10 | O2: 10 | P2: 10 | Q2: 10 | R2: 10 | S2: 10 | T2: 10 | U2: 10 | V2: 10 | W2: 10 | X2: 10 | Y2: 10 | Z2: 10 | AA2: 10 | AB2: 10 | AC2: 10 | AD2: 10 | AE2: 10
A3: natural gas steam turbine | B3: 10 | C3: 10 | D3: 10 | E3: 10 | F3: 10 | G3: 10 | H3: 10 | I3: 10 | J3: 10 | K3: 10 | L3: 10 | M3: 10 | N3: 10 | O3: 10 | P3: 10 | Q3: 10 | R3: 10 | S3: 10 | T3: 10 | U3: 10 | V3: 10 | W3: 10 | X3: 10 | Y3: 10 | Z3: 10 | AA3: 10 | AB3: 10 | AC3: 10 | AD3: 10 | AE3: 10
A4: natural gas combined cycle | B4: 10 | C4: 10 | D4: 10 | E4: 10 | F4: 10 | G4: 10 | H4: 10 | I4: 10 | J4: 10 | K4: 10 | L4: 10 | M4: 10 | N4: 10 | O4: 10 | P4: 10 | Q4: 10 | R4: 10 | S4: 10 | T4: 10 | U4: 10 | V4: 10 | W4: 10 | X4: 10 | Y4: 10 | Z4: 10 | AA4: 10 | AB4: 10 | AC4: 10 | AD4: 10 | AE4: 10
A5: nuclear | B5: 10 | C5: 10 | D5: 10 | E5: 10 | F5: 10 | G5: 10 | H5: 10 | I5: 10 | J5: 10 | K5: 10 | L5: 10 | M5: 10 | N5: 10 | O5: 10 | P5: 10 | Q5: 10 | R5: 10 | S5: 10 | T5: 10 | U5: 10 | V5: 10 | W5: 10 | X5: 10 | Y5: 10 | Z5: 10 | AA5: 10 | AB5: 10 | AC5: 10 | AD5: 10 | AE5: 10
A6: hydro | B6: 10 | C6: 10 | D6: 10 | E6: 10 | F6: 10 | G6: 10 | H6: 10 | I6: 10 | J6: 10 | K6: 10 | L6: 10 | M6: 10 | N6: 10 | O6: 10 | P6: 10 | Q6: 10 | R6: 10 | S6: 10 | T6: 10 | U6: 10 | V6: 10 | W6: 10 | X6: 10 | Y6: 10 | Z6: 10 | AA6: 10 | AB6: 10 | AC6: 10 | AD6: 10 | AE6: 10
A7: onshore wind | B7: 10 | C7: 10 | D7: 10 | E7: 10 | F7: 10 | G7: 10 | H7: 10 | I7: 10 | J7: 10 | K7: 10 | L7: 10 | M7: 10 | N7: 10 | O7: 10 | P7: 10 | Q7: 10 | R7: 10 | S7: 10 | T7: 10 | U7: 10 | V7: 10 | W7: 10 | X7: 10 | Y7: 10 | Z7: 10 | AA7: 10 | AB7: 10 | AC7: 10 | AD7: 10 | AE7: 10
A8: solar PV | B8: 10 | C8: 10 | D8: 10 | E8: 10 | F8: 10 | G8: 10 | H8: 10 | I8: 10 | J8: 10 | K8: 10 | L8: 10 | M8: 10 | N8: 10 | O8: 10 | P8: 10 | Q8: 10 | R8: 10 | S8: 10 | T8: 10 | U8: 10 | V8: 10 | W8: 10 | X8: 10 | Y8: 10 | Z8: 10 | AA8: 10 | AB8: 10 | AC8: 10 | AD8: 10 | AE8: 10
A9: solar thermal | B9: 10 | C9: 10 | D9: 10 | E9: 10 | F9: 10 | G9: 10 | H9: 10 | I9: 10 | J9: 10 | K9: 10 | L9: 10 | M9: 10 | N9: 10 | O9: 10 | P9: 10 | Q9: 10 | R9: 10 | S9: 10 | T9: 10 | U9: 10 | V9: 10 | W9: 10 | X9: 10 | Y9: 10 | Z9: 10 | AA9: 10 | AB9: 10 | AC9: 10 | AD9: 10 | AE9: 10
A10: biomass | B10: 10 | C10: 10 | D10: 10 | E10: 10 | F10: 10 | G10: 10 | H10: 10 | I10: 10 | J10: 10 | K10: 10 | L10: 10 | M10: 10 | N10: 10 | O10: 10 | P10: 10 | Q10: 10 | R10: 10 | S10: 10 | T10: 10 | U10: 10 | V10: 10 | W10: 10 | X10: 10 | Y10: 10 | Z10: 10 | AA10: 10 | AB10: 10 | AC10: 10 | AD10: 10 | AE10: 10
A11: geothermal | B11: 10 | C11: 10 | D11: 10 | E11: 10 | F11: 10 | G11: 10 | H11: 10 | I11: 10 | J11: 10 | K11: 10 | L11: 10 | M11: 10 | N11: 10 | O11: 10 | P11: 10 | Q11: 10 | R11: 10 | S11: 10 | T11: 10 | U11: 10 | V11: 10 | W11: 10 | X11: 10 | Y11: 10 | Z11: 10 | AA11: 10 | AB11: 10 | AC11: 10 | AD11: 10 | AE11: 10
A12: petroleum | B12: 10 | C12: 10 | D12: 10 | E12: 10 | F12: 10 | G12: 10 | H12: 10 | I12: 10 | J12: 10 | K12: 10 | L12: 10 | M12: 10 | N12: 10 | O12: 10 | P12: 10 | Q12: 10 | R12: 10 | S12: 10 | T12: 10 | U12: 10 | V12: 10 | W12: 10 | X12: 10 | Y12: 10 | Z12: 10 | AA12: 10 | AB12: 10 | AC12: 10 | AD12: 10 | AE12: 10
... A25: hydrogen combined cycle | B25: 10 | C25: 10 | D25: 10 | E25: 10 | F25: 10 | G25: 10 | H25: 10 | I25: 10 | J25: 10 | K25: 10 | L25: 10 | M25: 10 | N25: 10 | O25: 10 | P25: 10 | Q25: 10 | R25: 10 | S25: 10 | T25: 10 | U25: 10 | V25: 10 | W25: 10 | X25: 10 | Y25: 10 | Z25: 10 | AA25: 10 | AB25: 10 | AC25: 10 | AD25: 10 | AE25: 10
