Workbook
Name btu_per_EGJ: About!$A$26
Name btu_per_EJ: About!$A$26
Name btu_per_GJ: About!$A$26
Name HHV_Adjust: [1]About!$A$160
Name lignite_multiplier: #REF!
Name nonlignite_multiplier: #REF!
Name tax_fuel_labels: '[2]Tax_Share of Price'!$A$2:$A$22
Name Tax_share_2: '[2]Tax_Share of Price'!$B$2:$BC$22
Name use_lifecycle_biofuel_EIs: [1]About!$A$61

Sheet About
A1: ICtPSFfL Incremental Cost to Produce Substitute Fuel for LCFS
A3: Source: | B3: Fuel Production Costs
B4: E3 Pathways
B5: 2018
B6: Weighted Average Delivered Energy Costs
B8: File fuels/BFPaT for both India and US EPS 3.1
A10: Notes:
A11: This varibale calculates the incremental fuel production cost from switching from
A12: conventional fuels to LCFS substitute fuels. In Pathways, conventional ethanol
A13: has the same price as gasoline, so it has no incremental cost. Electricity credits
A14: are typically delivered to electric charging station owners, and there is no incremental
A15: cost of electricity production. Similarly, in Pathways the delivered natural gas prices
A16: are all below the gasoline price, so we use a value of zero. Only renewable diesel,
A17: which we use as the substitute fuel for petroleum diesel, has an incremental cost
A18: increase. Note also that per Pathways, this value drops over time, eventually falling so far
A19: that it costs lets than traditional diesel to produce, though we limit our incremental
A20: costs to a low value of zero.
A22: Conventional fuels under the LCFS (petroleum gasoline, petroleum diesel, and
... A25: Conversion Factor
A26: 947817.12 | B26: BTU/GJ
A28: For India, we apply an adjustment factor based on the ratio of biofuel costs in
A29: India compared to the US.

Sheet Calcs
A1: $/GJ
B2: 2021 | C2: 2022 | D2: 2023 | E2: 2024 | F2: 2025 | G2: 2026 | H2: 2027 | I2: 2028 | J2: 2029 | K2: 2030 | L2: 2031 | M2: 2032 | N2: 2033 | O2: 2034 | P2: 2035 | Q2: 2036 | R2: 2037 | S2: 2038 | T2: 2039 | U2: 2040 | V2: 2041 | W2: 2042 | X2: 2043 | Y2: 2044 | Z2: 2045 | AA2: 2046 | AB2: 2047 | AC2: 2048 | AD2: 2049 | AE2: 2050
A3: Renewable Diesel | B3: 37.140569 | C3: 37.201342 | D3: 36.728316 | E3: 36.677829 | F3: 36.6266 | G3: 36.572461 | H3: 36.514273 | I3: 36.448878 | J3: 36.376962 | K3: 36.290113 | L3: 39.485802 | M3: 39.360336 | N3: 39.22744 | O3: 39.065413 | P3: 42.199322 | Q3: 41.794951 | R3: 41.583448 | S3: 40.963429 | T3: 40.145704 | U3: 38.195291 | V3: 35.931081 | W3: 32.806003 | X3: 33.516126 | Y3: 34.240401 | Z3: 34.979111 | AA3: 35.732543 | AB3: 36.500991 | AC3: 37.284755 | AD3: 38.084138 | AE3: 38.899453
A4: Biodiesel | B4: 37.546766 | C4: 37.654388 | D4: 36.90184 | E4: 36.851084 | F4: 36.799581 | G4: 36.745154 | H4: 36.686655 | I4: 36.624657 | J4: 36.555261 | K4: 36.479154 | L4: 39.732316 | M4: 39.647693 | N4: 39.553434 | O4: 39.446444 | P4: 42.643601 | Q4: 42.525742 | R4: 42.392771 | S4: 42.24159 | T4: 42.068931 | U4: 41.870521 | V4: 41.653902 | W4: 47.526139 | X4: 47.526139 | Y4: 47.526139 | Z4: 47.526139 | AA4: 47.526139 | AB4: 47.526139 | AC4: 47.526139 | AD4: 47.526139 | AE4: 47.526139
A5: Renewable Gasoline | B5: 24.412383 | C5: 22.145681 | D5: NAN | E5: NAN | F5: NAN | G5: 21.396477 | H5: 21.772915 | I5: 22.243661 | J5: 22.683598 | K5: 23.121866 | L5: 23.566177 | M5: 24.13107 | N5: 24.704385 | O5: 25.255916 | P5: 25.8264 | Q5: 26.402123 | R5: 26.909596 | S5: 27.534997 | T5: 28.245734 | U5: 28.879223 | V5: 29.531294 | W5: 30.196645 | X5: 30.875547 | Y5: 31.568276 | Z5: 32.275115 | AA5: 32.996349 | AB5: 33.732272 | AC5: 34.483184 | AD5: 35.24939 | AE5: 36.031201
A6: Renewable Ethanol | B6: 33.61229 | C6: 35.599416 | D6: 32.242667 | E6: 33.606556 | F6: 33.686472 | G6: 32.536154 | H6: 32.601074 | I6: 32.578973 | J6: 33.997588 | K6: NAN | L6: NAN | M6: NAN | N6: NAN | O6: NAN | P6: NAN | Q6: NAN | R6: NAN | S6: NAN | T6: NAN | U6: NAN | V6: NAN | W6: NAN | X6: NAN | Y6: NAN | Z6: NAN | AA6: NAN | AB6: NAN | AC6: NAN | AD6: NAN | AE6: 41.934835
A7: Gasoline | B7: 19.837493 | C7: 20.124146 | D7: 20.405841 | E7: 20.681107 | F7: 21.044223 | G7: 21.396822 | H7: 21.773061 | I7: 22.243805 | J7: 22.683749 | K7: 23.121866 | L7: 23.566177 | M7: 24.13107 | N7: 24.704385 | O7: 25.255916 | P7: 25.8264 | Q7: 26.402123 | R7: 26.909596 | S7: 27.534997 | T7: 28.245734 | U7: 28.879223 | V7: 29.531294 | W7: 30.196645 | X7: 30.875547 | Y7: 31.568276 | Z7: 32.275115 | AA7: 32.996349 | AB7: 33.732272 | AC7: 34.483184 | AD7: 35.24939 | AE7: 36.031508
A8: Diesel | B8: 25.114456 | C8: 26.273551 | D8: 27.113186 | E8: 27.175034 | F8: 27.264087 | G8: 27.360005 | H8: 27.458948 | I8: 27.725498 | J8: 27.866533 | K8: 27.992114 | L8: 29.580078 | M8: 29.747935 | N8: 29.946868 | O8: 30.216647 | P8: 31.657737 | Q8: 31.893495 | R8: 32.102231 | S8: 32.422004 | T8: 32.771369 | U8: 33.088395 | V8: 33.492031 | W8: 34.821931 | X8: 35.430388 | Y8: 35.90318 | Z8: 36.375364 | AA8: 36.886318 | AB8: 37.435508 | AC8: 38.02261 | AD8: 38.647347 | AE8: 39.309585
A9: Conventional Gasoline/Ethanol
A10: Renewable Diesel | B10: 37.136317 | C10: 37.204454 | D10: 36.744946 | E10: 36.922279 | F10: 36.894382 | G10: 36.864546 | H10: 36.830346 | I10: 36.775999 | J10: 36.899417 | K10: 36.764804 | L10: 39.536667 | M10: 39.450583 | N10: 39.238066 | O10: 38.96111 | P10: 41.072339 | Q10: 40.593926 | R10: 39.715411 | S10: 38.548229 | T10: 38.856084 | U10: 37.613623 | V10: 37.000345 | W10: 40.01669 | X10: 38.701382 | Y10: 35.727966 | Z10: 34.979111 | AA10: 35.732543 | AB10: 36.500991 | AC10: 37.284755 | AD10: 38.084138 | AE10: 38.899453
A11: Biodiesel | B11: 37.547684 | C11: 37.657657 | D11: 36.918558 | E11: 37.096838 | F11: 37.068793 | G11: 37.038797 | H11: 37.004415 | I11: 36.965788 | J11: 37.097612 | K11: 37.054397 | L11: 40.056672 | M11: 40.001327 | N11: 39.939845 | O11: 39.87108 | P11: 42.844448 | Q11: 42.756298 | R11: 42.656276 | S11: 42.542546 | T11: 42.63798 | U11: 42.50607 | V11: 42.361629 | W11: 48.293856 | X11: 48.095016 | Y11: 47.858122 | Z11: 47.570329 | AA11: 47.526139 | AB11: 47.526139 | AC11: 47.526139 | AD11: 47.526139 | AE11: 47.526139
A13: $/BTU
A14: Renewable Diesel | B14: =B3/btu_per_EJ -> 3.9185375e-05 | C14: =C3/btu_per_EJ -> 3.9249493e-05 | D14: =D3/btu_per_EJ -> 3.8750425e-05 | E14: =E3/btu_per_EJ -> 3.8697158e-05 | F14: =F3/btu_per_EJ -> 3.8643109e-05 | G14: =G3/btu_per_EJ -> 3.8585989e-05 | H14: =H3/btu_per_EJ -> 3.8524597e-05 | I14: =I3/btu_per_EJ -> 3.8455602e-05 | ... AE14: =AE3/btu_per_EJ -> 4.1041096e-05
A15: Biodiesel | B15: =B4/btu_per_EJ -> 3.9613935e-05 | C15: =C4/btu_per_EJ -> 3.9727482e-05 | D15: =D4/btu_per_EJ -> 3.8933503e-05 | E15: =E4/btu_per_EJ -> 3.8879951e-05 | F15: =F4/btu_per_EJ -> 3.8825614e-05 | G15: =G4/btu_per_EJ -> 3.876819e-05 | H15: =H4/btu_per_EJ -> 3.870647e-05 | I15: =I4/btu_per_EJ -> 3.8641059e-05 | ... AE15: =AE4/btu_per_EJ -> 5.0142731e-05
A16: Renewable Gasoline | B16: =B5/btu_per_EJ -> 2.5756427e-05 | C16: =C5/btu_per_EJ -> 2.336493e-05 | D16: =D5/btu_per_EJ -> #VALUE! | E16: =E5/btu_per_EJ -> #VALUE! | F16: =F5/btu_per_EJ -> #VALUE! | G16: =G5/btu_per_EJ -> 2.2574478e-05 | H16: =H5/btu_per_EJ -> 2.2971641e-05 | I16: =I5/btu_per_EJ -> 2.3468305e-05 | ... AE16: =AE5/btu_per_EJ -> 3.8014929e-05
A17: Renewable Ethanol | B17: =B6/btu_per_EJ -> 3.5462843e-05 | C17: =C6/btu_per_EJ -> 3.7559372e-05 | D17: =D6/btu_per_EJ -> 3.4017815e-05 | E17: =E6/btu_per_EJ -> 3.5456794e-05 | F17: =F6/btu_per_EJ -> 3.5541109e-05 | G17: =G6/btu_per_EJ -> 3.4327459e-05 | H17: =H6/btu_per_EJ -> 3.4395954e-05 | I17: =I6/btu_per_EJ -> 3.4372636e-05 | ... AE17: =AE6/btu_per_EJ -> 4.4243593e-05
A18: Gasoline | B18: =B7/btu_per_EJ -> 2.0929663e-05 | C18: =C7/btu_per_EJ -> 2.1232098e-05 | D18: =D7/btu_per_EJ -> 2.1529302e-05 | E18: =E7/btu_per_EJ -> 2.1819723e-05 | F18: =F7/btu_per_EJ -> 2.2202831e-05 | G18: =G7/btu_per_EJ -> 2.2574842e-05 | H18: =H7/btu_per_EJ -> 2.2971796e-05 | I18: =I7/btu_per_EJ -> 2.3468457e-05 | ... AE18: =AE7/btu_per_EJ -> 3.8015254e-05
A19: Diesel | B19: =B8/btu_per_EJ -> 2.6497154e-05 | C19: =C8/btu_per_EJ -> 2.7720064e-05 | D19: =D8/btu_per_EJ -> 2.8605925e-05 | E19: =E8/btu_per_EJ -> 2.8671178e-05 | F19: =F8/btu_per_EJ -> 2.8765135e-05 | G19: =G8/btu_per_EJ -> 2.8866333e-05 | H19: =H8/btu_per_EJ -> 2.8970723e-05 | I19: =I8/btu_per_EJ -> 2.9251949e-05 | ... AE19: =AE8/btu_per_EJ -> 4.1473808e-05
A20: Conventional Gasoline/Ethanol | B20: =B9/btu_per_EJ -> 0 | C20: =C9/btu_per_EJ -> 0 | D20: =D9/btu_per_EJ -> 0 | E20: =E9/btu_per_EJ -> 0 | F20: =F9/btu_per_EJ -> 0 | G20: =G9/btu_per_EJ -> 0 | H20: =H9/btu_per_EJ -> 0 | I20: =I9/btu_per_EJ -> 0 | ... AE20: =AE9/btu_per_EJ -> 0
A21: Renewable Diesel | B21: =B10/btu_per_EJ -> 3.9180889e-05 | C21: =C10/btu_per_EJ -> 3.9252777e-05 | D21: =D10/btu_per_EJ -> 3.876797e-05 | E21: =E10/btu_per_EJ -> 3.8955066e-05 | F21: =F10/btu_per_EJ -> 3.8925634e-05 | G21: =G10/btu_per_EJ -> 3.8894155e-05 | H21: =H10/btu_per_EJ -> 3.8858072e-05 | I21: =I10/btu_per_EJ -> 3.8800733e-05 | ... AE21: =AE10/btu_per_EJ -> 4.1041096e-05
A22: Biodiesel | B22: =B11/btu_per_EJ -> 3.9614904e-05 | C22: =C11/btu_per_EJ -> 3.9730931e-05 | D22: =D11/btu_per_EJ -> 3.8951141e-05 | E22: =E11/btu_per_EJ -> 3.9139236e-05 | F22: =F11/btu_per_EJ -> 3.9109647e-05 | G22: =G11/btu_per_EJ -> 3.9078e-05 | H22: =H11/btu_per_EJ -> 3.9041724e-05 | I22: =I11/btu_per_EJ -> 3.9000971e-05 | ... AE22: =AE11/btu_per_EJ -> 5.0142731e-05
A24: Reference Fuels
A25: electricity | B25: petroleum gasoline
A26: natural gas | B26: petroleum gasoline
A27: biofuel gasoline | B27: petroleum gasoline
A28: biofuel diesel | B28: petroleum diesel
A30: Incremental Costs of Production ($/BTU)
B31: 2021 | C31: 2022 | D31: 2023 | E31: 2024 | F31: 2025 | G31: 2026 | H31: 2027 | I31: 2028 | J31: 2029 | K31: 2030 | L31: 2031 | M31: 2032 | N31: 2033 | O31: 2034 | P31: 2035 | Q31: 2036 | R31: 2037 | S31: 2038 | T31: 2039 | U31: 2040 | V31: 2041 | W31: 2042 | X31: 2043 | Y31: 2044 | Z31: 2045 | AA31: 2046 | AB31: 2047 | AC31: 2048 | AD31: 2049 | AE31: 2050 | AF31: 2051 | AG31: 2052 | AH31: 2053 | AI31: 2054 | AJ31: 2055 | AK31: 2056 | AL31: 2057 | AM31: 2058 | AN31: 2059 | AO31: 2060 | AP31: 2061 | AQ31: 2062 | AR31: 2063 | AS31: 2064 | AT31: 2065 | AU31: 2066 | AV31: 2067 | AW31: 2068 | AX31: 2069 | AY31: 2070
A32: electricity | B32: 0 | C32: 0 | D32: 0 | E32: 0 | F32: 0 | G32: 0 | H32: 0 | I32: 0 | J32: 0 | K32: 0 | L32: 0 | M32: 0 | N32: 0 | O32: 0 | P32: 0 | Q32: 0 | R32: 0 | S32: 0 | T32: 0 | U32: 0 | V32: 0 | W32: 0 | X32: 0 | Y32: 0 | Z32: 0 | AA32: 0 | AB32: 0 | AC32: 0 | AD32: 0 | AE32: 0 | AF32: 0 | AG32: 0 | AH32: 0 | AI32: 0 | AJ32: 0 | AK32: 0 | AL32: 0 | AM32: 0 | AN32: 0 | AO32: 0 | AP32: 0 | AQ32: 0 | AR32: 0 | AS32: 0 | AT32: 0 | AU32: 0 | AV32: 0 | AW32: 0 | AX32: 0 | AY32: 0
A33: natural gas | B33: 0 | C33: 0 | D33: 0 | E33: 0 | F33: 0 | G33: 0 | H33: 0 | I33: 0 | J33: 0 | K33: 0 | L33: 0 | M33: 0 | N33: 0 | O33: 0 | P33: 0 | Q33: 0 | R33: 0 | S33: 0 | T33: 0 | U33: 0 | V33: 0 | W33: 0 | X33: 0 | Y33: 0 | Z33: 0 | AA33: 0 | AB33: 0 | AC33: 0 | AD33: 0 | AE33: 0 | AF33: 0 | AG33: 0 | AH33: 0 | AI33: 0 | AJ33: 0 | AK33: 0 | AL33: 0 | AM33: 0 | AN33: 0 | AO33: 0 | AP33: 0 | AQ33: 0 | AR33: 0 | AS33: 0 | AT33: 0 | AU33: 0 | AV33: 0 | AW33: 0 | AX33: 0 | AY33: 0
A34: biofuel gasoline | B34: =0 -> 0 | C34: =0 -> 0 | D34: =0 -> 0 | E34: =0 -> 0 | F34: =0 -> 0 | G34: =0 -> 0 | H34: =0 -> 0 | I34: =0 -> 0 | ... AY34: =0 -> 0
A35: biofuel diesel | B35: =B21-B19 -> 1.2683735e-05 | C35: =C21-C19 -> 1.1532713e-05 | D35: =D21-D19 -> 1.0162044e-05 | E35: =E21-E19 -> 1.0283888e-05 | F35: =F21-F19 -> 1.0160499e-05 | G35: =G21-G19 -> 1.0027822e-05 | H35: =H21-H19 -> 9.887349e-06 | I35: =I21-I19 -> 9.5487842e-06 | ... AE35: =AE21-AE19 -> -4.3271218e-07
A37: Biofuel diesel [2051-2070]
A38: $/BTU (India Total Fuel Prices)
B39: 2051 | C39: 2052 | D39: 2053 | E39: 2054 | F39: 2055 | G39: 2056 | H39: 2057 | I39: 2058 | J39: 2059 | K39: 2060 | L39: 2061 | M39: 2062 | N39: 2063 | O39: 2064 | P39: 2065 | Q39: 2066 | R39: 2067 | S39: 2068 | T39: 2069 | U39: 2070
A40: Diesel pre tax | B40: 1.441042e-05 | C40: 1.4535411e-05 | D40: 1.4623946e-05 | E40: 1.4702065e-05 | F40: 1.4819682e-05 | G40: 1.4938239e-05 | H40: 1.5057745e-05 | I40: 1.5178207e-05 | J40: 1.5299633e-05 | K40: 1.542203e-05 | L40: 1.5545406e-05 | M40: 1.5669769e-05 | N40: 1.5795127e-05 | O40: 1.5921488e-05 | P40: 1.604886e-05 | Q40: 1.6177251e-05 | R40: 1.6306669e-05 | S40: 1.6437123e-05 | T40: 1.656862e-05 | U40: 1.6701169e-05
A41: Diesel fuel tax | B41: 1.0749755e-05 | C41: 1.0842995e-05 | D41: 1.0909039e-05 | E41: 1.0967314e-05 | F41: 1.1055053e-05 | G41: 1.1143493e-05 | H41: 1.1232641e-05 | I41: 1.1322502e-05 | J41: 1.1413082e-05 | K41: 1.1504387e-05 | L41: 1.1596422e-05 | M41: 1.1689193e-05 | N41: 1.1782707e-05 | O41: 1.1876969e-05 | P41: 1.1971984e-05 | Q41: 1.206776e-05 | R41: 1.2164302e-05 | S41: 1.2261617e-05 | T41: 1.235971e-05 | U41: 1.2458587e-05
A42: Diesel total fuel price | B42: =B40+B41 -> 2.5160175e-05 | C42: =C40+C41 -> 2.5378405e-05 | D42: =D40+D41 -> 2.5532985e-05 | E42: =E40+E41 -> 2.5669379e-05 | F42: =F40+F41 -> 2.5874734e-05 | G42: =G40+G41 -> 2.6081732e-05 | H42: =H40+H41 -> 2.6290386e-05 | I42: =I40+I41 -> 2.6500709e-05 | ... U42: =U40+U41 -> 2.9159756e-05
A43: Biodiesel pre tax | B43: 2.3902166e-05 | C43: 2.4109485e-05 | D43: 2.4256336e-05 | E43: 2.438591e-05 | F43: 2.4580998e-05 | G43: 2.4777646e-05 | H43: 2.4975867e-05 | I43: 2.5175674e-05 | J43: 2.5377079e-05 | K43: 2.5580096e-05 | L43: 2.5784737e-05 | M43: 2.5991014e-05 | N43: 2.6198943e-05 | O43: 2.6408534e-05 | P43: 2.6619802e-05 | Q43: 2.6832761e-05 | R43: 2.7047423e-05 | S43: 2.7263802e-05 | T43: 2.7481913e-05 | U43: 2.7701768e-05
A44: Biodiesel fuel tax | B44: 1.2580087e-06 | C44: 1.2689203e-06 | D44: 1.2766493e-06 | E44: 1.283469e-06 | F44: 1.2937367e-06 | G44: 1.3040866e-06 | H44: 1.3145193e-06 | I44: 1.3250355e-06 | J44: 1.3356357e-06 | K44: 1.3463208e-06 | L44: 1.3570914e-06 | M44: 1.3679481e-06 | N44: 1.3788917e-06 | O44: 1.3899228e-06 | P44: 1.4010422e-06 | Q44: 1.4122506e-06 | R44: 1.4235486e-06 | S44: 1.434937e-06 | T44: 1.4464165e-06 | U44: 1.4579878e-06
...

Sheet India Adjustment
A1: biodiesel | B1: BFPaT-pretax | C1: India | D1: 2.4943595e-05
A2: biodiesel | B2: BFPaT-pretax | C2: US | D2: 1.3741805e-05
A3: biodiesel | B3: BFPaT-tax | C3: India | D3: 1.3128208e-06
A4: biodiesel | B4: BFPaT-tax | C4: US | D4: 4.3719605e-06
A6: biodiesel | B6: total | C6: India | D6: =D1+D3 -> 2.6256416e-05
A7: biodiesel | B7: total | C7: US | D7: =D2+D4 -> 1.8113766e-05
A9: Ratio | B9: =D6/D7 -> 1.4495283

Sheet ICtPSFfL
A1: Cost ($/BTU) | B1: 2021 | C1: 2022 | D1: 2023 | E1: 2024 | F1: 2025 | G1: 2026 | H1: 2027 | I1: 2028 | J1: 2029 | K1: 2030 | L1: 2031 | M1: 2032 | N1: 2033 | O1: 2034 | P1: 2035 | Q1: 2036 | R1: 2037 | S1: 2038 | T1: 2039 | U1: 2040 | V1: 2041 | W1: 2042 | X1: 2043 | Y1: 2044 | Z1: 2045 | AA1: 2046 | AB1: 2047 | AC1: 2048 | AD1: 2049 | AE1: 2050 | AF1: 2051 | AG1: 2052 | AH1: 2053 | AI1: 2054 | AJ1: 2055 | AK1: 2056 | AL1: 2057 | AM1: 2058 | AN1: 2059 | AO1: 2060 | AP1: 2061 | AQ1: 2062 | AR1: 2063 | AS1: 2064 | AT1: 2065 | AU1: 2066 | AV1: 2067 | AW1: 2068 | AX1: 2069 | AY1: 2070
A2: electricity | B2: =Calcs!B32 -> 0 | C2: =Calcs!C32 -> 0 | D2: =Calcs!D32 -> 0 | E2: =Calcs!E32 -> 0 | F2: =Calcs!F32 -> 0 | G2: =Calcs!G32 -> 0 | H2: =Calcs!H32 -> 0 | I2: =Calcs!I32 -> 0 | ... AY2: =Calcs!AY32 -> 0
A3: natural gas | B3: =Calcs!B33 -> 0 | C3: =Calcs!C33 -> 0 | D3: =Calcs!D33 -> 0 | E3: =Calcs!E33 -> 0 | F3: =Calcs!F33 -> 0 | G3: =Calcs!G33 -> 0 | H3: =Calcs!H33 -> 0 | I3: =Calcs!I33 -> 0 | ... AY3: =Calcs!AY33 -> 0
A4: petroleum gasoline | B4: =0 -> 0 | C4: =0 -> 0 | D4: =0 -> 0 | E4: =0 -> 0 | F4: =0 -> 0 | G4: =0 -> 0 | H4: =0 -> 0 | I4: =0 -> 0 | ... AY4: =0 -> 0
A5: petroleum diesel | B5: =0 -> 0 | C5: =0 -> 0 | D5: =0 -> 0 | E5: =0 -> 0 | F5: =0 -> 0 | G5: =0 -> 0 | H5: =0 -> 0 | I5: =0 -> 0 | ... AY5: =0 -> 0
A6: biofuel gasoline | B6: =Calcs!B34 -> 0 | C6: =Calcs!C34 -> 0 | D6: =Calcs!D34 -> 0 | E6: =Calcs!E34 -> 0 | F6: =Calcs!F34 -> 0 | G6: =Calcs!G34 -> 0 | H6: =Calcs!H34 -> 0 | I6: =Calcs!I34 -> 0 | ... AY6: =Calcs!AY34 -> 0
A7: biofuel diesel | B7: =MAX(Calcs!B35,0)*'India Adjustment'!$B$9 -> 1.8385432e-05 | C7: =MAX(Calcs!C35,0)*'India Adjustment'!$B$9 -> 1.6716994e-05 | D7: =MAX(Calcs!D35,0)*'India Adjustment'!$B$9 -> 1.4730171e-05 | E7: =MAX(Calcs!E35,0)*'India Adjustment'!$B$9 -> 1.4906787e-05 | F7: =MAX(Calcs!F35,0)*'India Adjustment'!$B$9 -> 1.4727931e-05 | G7: =MAX(Calcs!G35,0)*'India Adjustment'!$B$9 -> 1.4535612e-05 | H7: =MAX(Calcs!H35,0)*'India Adjustment'!$B$9 -> 1.4331992e-05 | I7: =MAX(Calcs!I35,0)*'India Adjustment'!$B$9 -> 1.3841233e-05 | ... AE7: =MAX(Calcs!AE35,0)*'India Adjustment'!$B$9 -> 0 | AF7: =Calcs!B49 -> 0 | AG7: =Calcs!C49 -> 0 | AH7: =Calcs!D49 -> 0 | AI7: =Calcs!E49 -> 0 | AJ7: =Calcs!F49 -> 0 | AK7: =Calcs!G49 -> 0 | AL7: =Calcs!H49 -> 0 | AM7: =Calcs!I49 -> 0 | ... AY7: =Calcs!U49 -> 0
A8: jet fuel | B8: =0 -> 0 | C8: =0 -> 0 | D8: =0 -> 0 | E8: =0 -> 0 | F8: =0 -> 0 | G8: =0 -> 0 | H8: =0 -> 0 | I8: =0 -> 0 | ... AY8: =0 -> 0
A9: heavy or residual fuel oil | B9: =0 -> 0 | C9: =0 -> 0 | D9: =0 -> 0 | E9: =0 -> 0 | F9: =0 -> 0 | G9: =0 -> 0 | H9: =0 -> 0 | I9: =0 -> 0 | ... AY9: =0 -> 0
A10: LPG propane or butane | B10: =0 -> 0 | C10: =0 -> 0 | D10: =0 -> 0 | E10: =0 -> 0 | F10: =0 -> 0 | G10: =0 -> 0 | H10: =0 -> 0 | I10: =0 -> 0 | ... AY10: =0 -> 0
A11: hydrogen | B11: =0 -> 0 | C11: =0 -> 0 | D11: =0 -> 0 | E11: =0 -> 0 | F11: =0 -> 0 | G11: =0 -> 0 | H11: =0 -> 0 | I11: =0 -> 0 | ... AY11: =0 -> 0
