Workbook
Name IQ_CH: 110000
Name IQ_CQ: 5000
Name IQ_CY: 10000
Name IQ_DAILY: 500000
Name IQ_FH: 100000
Name IQ_FQ: 500
Name IQ_FY: 1000
Name IQ_LTM: 2000
Name IQ_MONTH: 15000
Name IQ_NTM: 6000
Name IQ_WEEK: 50000
Name IQ_YTD: 3000
Name Net_Generation_by_State__Type_1: #REF!
Name Net_Generation_by_State__Type_of_Producer__Energy_Source: #REF!
Name Net_Generation_by_State__Type_of_Producer__Energy_Source: #REF!

Sheet About
A1: BRPSDbS BAU Renewable Portfolio Std Percentage by Subregion
A2: BRPSDbS BAU Electricity Shares by Subregion
A4: Sources: | B4: RPO targets and Compliance by state
B5: Ministry of Power, Govt of India
B6: 2023
B7: Rajya Sabha report
B8: AS122.pdf (sansad.in)
B9: Annexure 1 and Annexure 2
B10: RPO Compliance by state, 2023
B11: EIA
B12: 2023
B13: EIA-923 Power Plant Operations Report
B14: https://www.eia.gov/electricity/data/state/
B15: Net Generation by State by Type of Producer by Energy Source (EIA-906, EIA-920, and EIA-923)
B17: State's share of generation
B18: Press Information Bureau
B19: 2023
B20: The State-wise power supply position for the year 2021-22 and current year 2022-23
B21: https://pib.gov.in/PressReleaseIframePage.aspx?PRID=1909932
B22: Annexure 1 Table
B24: Actual share of RE
B25: CEA
B26: 2024
B27: All India Electricity Statistics
B28: https://cea.nic.in/wp-content/uploads/general/2024/General_Review_2024_2.pdf
B29: Page 19
A30: Note:
A31: The purpose of this variable is to specify the renewable portfolio standard requirement that must be met in the BAU case (which the user may increase
A32: via a policy lever, affecting the policy case).
A35: Notes on Output Data Formatting
A36: Note that the blue output tab "BRPSDbS-RPS-percentages" is populating the "Future Year" subscript. It is not a normal time-series variable.
A37: Therefore, it must include a value for every year that exists in the Future Year subscript (and no other years should be present).
A38: It is designed this way for compatibility with the RPS foresight option (enabled via a control setting).
A40: The blue output tab "BRPSDbS-electricity-shares" contains the share of electricity sales in each subregion.
A41: The data in this tab must sum to 1.
A44: NOtes for India
A45: Although India has RPS as a policy instrument, it has been subject to consistent non-compliance by across states. Therefore, we set an RPO mandate of 30% by 2030 which is slightly more than the actual share of generation by states.
A46: This is assumed to remain constant from 2030
A47: States are assumed to comply have the same RPS targets in each year

Sheet India Data
B2: pib.gov.in/PressReleaseIframePage.aspx?PRID=1909932 | K2: Source: | L2: AS122.pdf (sansad.in)
B15: YEar | C15: MoP's RPO Target
B16: 2023 | C16: 24.61
B17: 2024 | C17: 27.08
B18: 2025 | C18: 29.91
B19: 2026 | C19: 33.01
B20: 2027 | C20: 35.95
B21: 2028 | C21: 38.81
B22: 2029 | C22: 41.36
B23: 2030 | C23: 43.33

Sheet India's generation numbers
A1: Column1 | B1: Column2 | C1: Column3 | D1: Column4 | E1: Column5 | F1: Column6
A2: State/ System/Region | B2: April, 2022 - February, 2023 | C2: April, 2022 - February, 2023 | D2: April, 2022 - February, 2023 | E2: April, 2022 - February, 2023 | F2: State's share of energy supplied
B3: Energy requirement | C3: Energy supplied | D3: Energy not supplied | E3: Energy not supplied
B4: ( MU ) | C4: ( MU ) | D4: ( MU ) | E4: ( % )
A5: Chandigarh | B5: 1,687 | C5: 1,687 | D5: 0 | E5: 0.0 | F5: =Table_2[[#This Row],[Column3]]/C46 -> #VALUE!
A6: Delhi | B6: 33,012 | C6: 33,002 | D6: 10 | E6: 0.0
A7: Haryana | B7: 57,564 | C7: 57,061 | D7: 503 | E7: 0.9
A8: Himachal Pradesh | B8: 11,601 | C8: 11,497 | D8: 104 | E8: 0.9
A9: UT of J&K and Ladakh | B9: 17,914 | C9: 17,604 | D9: 309 | E9: 1.7
A10: Punjab | B10: 65,282 | C10: 64,996 | D10: 286 | E10: 0.4
A11: Rajasthan | B11: 94,270 | C11: 92,557 | D11: 1,712 | E11: 1.8
A12: Uttar Pradesh | B12: 1,34,645 | C12: 1,33,449 | D12: 1,196 | E12: 0.9
A13: Uttarakhand | B13: 14,496 | C13: 14,247 | D13: 249 | E13: 1.7
A14: Northern Region | B14: 4,31,544 | C14: 4,27,175 | D14: 4,369 | E14: 1.0
A15: Chhattisgarh | B15: 35,450 | C15: 35,381 | D15: 69 | E15: 0.2
A16: Gujarat | B16: 1,26,657 | C16: 1,26,613 | D16: 44 | E16: 0.0
A17: Madhya Pradesh | B17: 84,434 | C17: 84,105 | D17: 329 | E17: 0.4
... A49: Note: Power Supply Position Report has been compiled based on the data furnished by State Utilities/Electricity Departments. The MU figures have been rounded off to nearest unit place. | B49: Note: Power Supply Position Report has been compiled based on the data furnished by State Utilities/Electricity Departments. The MU figures have been rounded off to nearest unit place. | C49: Note: Power Supply Position Report has been compiled based on the data furnished by State Utilities/Electricity Departments. The MU figures have been rounded off to nearest unit place. | D49: Note: Power Supply Position Report has been compiled based on the data furnished by State Utilities/Electricity Departments. The MU figures have been rounded off to nearest unit place. | E49: Note: Power Supply Position Report has been compiled based on the data furnished by State Utilities/Electricity Departments. The MU figures have been rounded off to nearest unit place.
A52: Chandigarh | B52: 1687 | C52: 1687 | D52: 0 | E52: 0.0
A53: Delhi | B53: 33012 | C53: 33002 | D53: 10 | E53: 0.0 | F53: =C53/$C$94 -> 0.024081229
A54: Haryana | B54: 57564 | C54: 57061 | D54: 503 | E54: 0.9 | F54: =C54/$C$94 -> 0.041636841
A55: Himachal Pradesh | B55: 11601 | C55: 11497 | D55: 104 | E55: 0.9 | F55: =C55/$C$94 -> 0.0083892458
A56: UT of J&K and Ladakh | B56: 17914 | C56: 17604 | D56: 309 | E56: 1.7 | F56: =C56/$C$94 -> 0.012845463
A57: Punjab | B57: 65282 | C57: 64996 | D57: 286 | E57: 0.4 | F57: =C57/$C$94 -> 0.047426931
A58: Rajasthan | B58: 94270 | C58: 92557 | D58: 1,712 | E58: 1.8 | F58: =C58/$C$94 -> 0.067537917
A59: Uttar Pradesh | B59: 134645 | C59: 133449 | D59: 1,196 | E59: 0.9 | F59: =C59/$C$94 -> 0.0973764
A60: Uttarakhand | B60: 14496 | C60: 14247 | D60: 249 | E60: 1.7 | F60: =C60/$C$94 -> 0.010395893
A61: Northern Region | B61: 431544 | D61: 4,369 | E61: 1.0 | F61: =C61/$C$94 -> 0
A62: Chhattisgarh | B62: 35450 | C62: 35381 | D62: 69 | E62: 0.2 | F62: =C62/$C$94 -> 0.025817162
A63: Gujarat | B63: 126657 | C63: 126613 | D63: 44 | E63: 0.0 | F63: =C63/$C$94 -> 0.092388239
A64: Madhya Pradesh | B64: 84434 | C64: 84105 | D64: 329 | E64: 0.4 | F64: =C64/$C$94 -> 0.061370577
A65: Maharashtra | B65: 169433 | C65: 169322 | D65: 111 | E65: 0.1 | F65: =C65/$C$94 -> 0.12355257
A66: Dadra & Nagar Haveli and Daman & Diu | B66: 9169 | C66: 9169 | D66: 0 | E66: 0.0 | F66: =C66/$C$94 -> 0.0066905275
A67: Goa | B67: 4279 | C67: 4279 | D67: 0 | E67: 0.0 | F67: =C67/$C$94 -> 0.0031223435
A68: Western Region | B68: 433746 | D68: 553 | E68: 0.1 | F68: =C68/$C$94 -> 0
A69: Andhra Pradesh | B69: 65604 | C69: 65194 | D69: 410 | E69: 0.6 | F69: =C69/$C$94 -> 0.047571409
A70: Telangana | B70: 68609 | C70: 68576 | D70: 34 | E70: 0.0 | F70: =C70/$C$94 -> 0.050039221
A71: Karnataka | B71: 67159 | C71: 67133 | D71: 26 | E71: 0.0 | F71: =C71/$C$94 -> 0.048986278
A72: Kerala | B72: 25028 | C72: 25007 | D72: 21 | E72: 0.1 | F72: =C72/$C$94 -> 0.018247358
A73: Tamil Nadu | B73: 103794 | C73: 103718 | D73: 77 | E73: 0.1 | F73: =C73/$C$94 -> 0.075681987
...

Sheet RPO State forecasts
A1: Looking at past trends, the share of RE (including hydro) in generation has only grown by 2% in the last decade. Policies (like the RPO) can drive this share higher in the future
A2: However, rampant non-compliance may make the 43% RPO target by 2030 unfeasable. We instead set a target of 30% RE generation by 2030 for all states as a proxy that may be replaces later
A3: Unit: dimensionless (share of RPS-qualifying electricity) | B3: 2016 | C3: 2017 | D3: 2018 | E3: 2019 | F3: 2020 | G3: 2021 | H3: 2022 | I3: 2023 | J3: 2024 | K3: 2025 | L3: 2026 | M3: 2027 | N3: 2028 | O3: 2029 | P3: 2030
A4: Chandigarh
A5: Delhi | AA5: Year | AB5: RE+Hydro | AC5: RE (without hydro) | AD5: Thermal | AE5: Nuclear | AF5: Total gen (check) | AG5: Total gen | AH5: Share of RE (+hydro)
A6: Haryana | AA6: 2013 | AB6: =65520+134847 -> 200367 | AC6: 134847 | AD6: 792054 | AE6: 34228 | AF6: =AB6+792054+34228 -> 1026649 | AG6: =AE6+AD6+AB6 -> 1026649 | AH6: =AB6/AG6 -> 0.19516602
A7: Himachal Pradesh | AA7: 2014 | AB7: =61785+129244 -> 191029 | AC7: 129244 | AD7: 877941 | AE7: 36102 | AG7: =AE7+AD7+AB7 -> 1105072 | AH7: =AB7/AG7 -> 0.17286566
A8: UT of J&K and Ladakh | AA8: 2015 | AB8: =65781+121377 -> 187158 | AC8: 121377 | AD8: 943013 | AE8: 37413 | AG8: =AE8+AD8+AB8 -> 1167584 | AH8: =AB8/AG8 -> 0.16029511
A9: Punjab | AA9: 2016 | AB9: =81548+122378 -> 203926 | AC9: 122378 | AD9: 993516 | AE9: 37916 | AG9: =AE9+AD9+AB9 -> 1235358 | AH9: =AB9/AG9 -> 0.16507442
A10: Rajasthan | AA10: 2017 | AB10: =101839+126123 -> 227962 | AC10: 126123 | AD10: 1037146 | AE10: 38346 | AG10: =AE10+AD10+AB10 -> 1303454 | AH10: =AB10/AG10 -> 0.17489071
A11: Uttar Pradesh | AA11: 2018 | AB11: =126759+134894 -> 261653 | AC11: 134894 | AD11: 1072314 | AE11: 37813 | AG11: =AE11+AD11+AB11 -> 1371780 | AH11: =AB11/AG11 -> 0.19073977
A12: Uttarakhand | AA12: 2019 | AB12: =138337+155769 -> 294106 | AC12: 155769 | AD12: 1042838 | AE12: 46472 | AG12: =AE12+AD12+AB12 -> 1383416 | AH12: =AB12/AG12 -> 0.21259404
A13: Chhattisgarh | AA13: 2020 | AB13: =147248+150300 -> 297548 | AC13: 150300 | AD13: 1032611 | AE13: 43029 | AG13: =AE13+AD13+AB13 -> 1373188 | AH13: =AB13/AG13 -> 0.2166841
A14: Gujarat | AA14: 2021 | AB14: =170912+151627 -> 322539 | AC14: 151627 | AD14: 1114811 | AE14: 47112 | AG14: =AE14+AD14+AB14 -> 1484462 | AH14: =AB14/AG14 -> 0.2172767
A15: Madhya Pradesh | AA15: 2022 | AB15: =203533+162099 -> 365632 | AC15: 162099 | AD15: 1206390 | AE15: 45861 | AG15: =AE15+AD15+AB15 -> 1617883 | AH15: =AB15/AG15 -> 0.22599409 | AI15: =(AH15-AH6)/AH6 -> 0.15795819 | AJ15: =AH15-AH6 -> 0.030828072
A16: Maharashtra | AA16: 2030 | AH16: =_xlfn.FORECAST.LINEAR(AA16,AH6:AH15,AA6:AA15) -> 0.27108858
A17: Dadra & Nagar Haveli and Daman & Diu
A18: Goa | AA18: shareo
A19: Andhra Pradesh | C19: 0.05 | D19: 0.09 | E19: 0.11 | F19: 0.13 | G19: 0.15 | H19: 0.17 | I19: 0.18 | J19: 0.19 | K19: 0.2 | L19: 0.22 | M19: 0.24 | N19: =_xlfn.FORECAST.LINEAR(N3,$C19:$M19,$C$3:$M$3) -> 0.26036364 | O19: =_xlfn.FORECAST.LINEAR(O3,$C19:$M19,$C$3:$M$3) -> 0.27754545 | P19: =_xlfn.FORECAST.LINEAR(P3,$C19:$M19,$C$3:$M$3) -> 0.29472727
A20: Telangana
A21: Karnataka
A22: Kerala
A23: Tamil Nadu
A24: Puducherry
A25: Lakshadweep
A26: Bihar
A27: DVC
A28: Jharkhand
A29: Odisha
A30: West Bengal | Q30: Source | R30: General_Review_2024_2.pdf
A31: Sikkim
A32: Andaman-Nicobar Islands
A33: Arunachal Pradesh
A34: Assam
A35: Total RPO | I35: 24.61 | J35: 27.08 | K35: 29.91 | L35: 33.01 | M35: 35.95 | N35: 38.81 | O35: 41.36 | P35: 43.33
A36: Actual share of RE | I36: 22.6 | J36: =I36*(1+0.1349) -> 25.64874 | K36: =J36+(J36-I36) -> 28.69748 | L36: =K36+(K36-J36) -> 31.74622 | M36: =L36+(L36-K36) -> 34.79496 | N36: =M36+(M36-L36) -> 37.8437 | O36: =N36+(N36-M36) -> 40.89244 | P36: =O36+(O36-N36) -> 43.94118

Sheet BRPSDbS-electricity-shares
A1: Unit: dimensionless (share of electricity sales by subregion) | B1: Share of electricity
A2: Chandigarh | B2: 0.001230987
A3: Delhi | B3: 0.024081229
A4: Haryana | B4: 0.041636841
A5: Himachal Pradesh | B5: 0.0083892458
A6: UT of JK and Ladakh | B6: 0.012845463
A7: Punjab | B7: 0.047426931
A8: Rajasthan | B8: 0.067537917
A9: Uttar Pradesh | B9: 0.0973764
A10: Uttarakhand | B10: 0.010395893
A11: Chhattisgarh | B11: 0.025817162
A12: Gujarat | B12: 0.092388239
A13: Madhya Pradesh | B13: 0.061370577
... A61: subregion60 | B61: 0

Sheet BRPSDbS-RPS-percentages
A1: Unit: dimensionless (share of RPS-qualifying electricity) | B1: Year2021 | C1: Year2022 | D1: Year2023 | E1: Year2024 | F1: Year2025 | G1: Year2026 | H1: Year2027 | I1: Year2028 | J1: Year2029 | K1: Year2030 | L1: Year2031 | M1: Year2032 | N1: Year2033 | O1: Year2034 | P1: Year2035 | Q1: Year2036 | R1: Year2037 | S1: Year2038 | T1: Year2039 | U1: Year2040 | V1: Year2041 | W1: Year2042 | X1: Year2043 | Y1: Year2044 | Z1: Year2045 | AA1: Year2046 | AB1: Year2047 | AC1: Year2048 | AD1: Year2049 | AE1: Year2050 | AF1: Year2051 | AG1: Year2052 | AH1: Year2053 | AI1: Year2054 | AJ1: Year2055 | AK1: Year2056 | AL1: Year2057 | AM1: Year2058 | AN1: Year2059 | AO1: Year2060 | AP1: Year2061 | AQ1: Year2062 | AR1: Year2063 | AS1: Year2064 | AT1: Year2065 | AU1: Year2066 | AV1: Year2067 | AW1: Year2068 | AX1: Year2069 | AY1: Year2070 | AZ1: Year2071 | BA1: Year2072 | BB1: Year2073 | BC1: Year2074 | BD1: Year2075 | BE1: Year2076 | BF1: Year2077 | BG1: Year2078 | BH1: Year2079 | BI1: Year2080 | BJ1: Year2081 | BK1: Year2082 | BL1: Year2083 | BM1: Year2084 | BN1: Year2085 | BO1: Year2086 | BP1: Year2087 | BQ1: Year2088 | BR1: Year2089 | BS1: Year2090 | BT1: Year2091 | BU1: Year2092 | BV1: Year2093 | BW1: Year2094 | BX1: Year2095 | BY1: Year2096 | BZ1: Year2097 | CA1: Year2098 | CB1: Year2099 | CC1: Year2100
A2: Chandigarh | B2: ='RPO State forecasts'!$AH$14 -> 0.2172767 | C2: =B2+($K2-$B2)/10 -> 0.22554903 | D2: =C2+($K2-$B2)/10 -> 0.23382136 | E2: =D2+($K2-$B2)/10 -> 0.24209369 | F2: =E2+($K2-$B2)/10 -> 0.25036602 | G2: =F2+($K2-$B2)/10 -> 0.25863835 | H2: =G2+($K2-$B2)/10 -> 0.26691068 | I2: =H2+($K2-$B2)/10 -> 0.27518301 | J2: =I2+($K2-$B2)/10 -> 0.28345534 | K2: 0.3 | L2: 0.3 | M2: 0.3 | N2: 0.3 | O2: 0.3 | P2: 0.3 | Q2: 0.3 | R2: 0.3 | S2: 0.3 | T2: 0.3 | U2: 0.3 | V2: 0.3 | W2: 0.3 | X2: 0.3 | Y2: 0.3 | Z2: 0.3 | AA2: 0.3 | AB2: 0.3 | AC2: 0.3 | AD2: 0.3 | AE2: 0.3 | AF2: 0.3 | AG2: 0.3 | AH2: 0.3 | AI2: 0.3 | AJ2: 0.3 | AK2: 0.3 | AL2: 0.3 | AM2: 0.3 | AN2: 0.3 | AO2: 0.3 | AP2: 0.3 | AQ2: 0.3 | AR2: 0.3 | AS2: 0.3 | AT2: 0.3 | AU2: 0.3 | AV2: 0.3 | AW2: 0.3 | AX2: 0.3 | AY2: 0.3 | AZ2: 0.3 | BA2: 0.3 | BB2: 0.3 | BC2: 0.3 | BD2: 0.3 | BE2: 0.3 | BF2: 0.3 | BG2: 0.3 | BH2: 0.3 | BI2: 0.3 | BJ2: 0.3 | BK2: 0.3 | BL2: 0.3 | BM2: 0.3 | BN2: 0.3 | BO2: 0.3 | BP2: 0.3 | BQ2: 0.3 | BR2: 0.3 | BS2: 0.3 | BT2: 0.3 | BU2: 0.3 | BV2: 0.3 | BW2: 0.3 | BX2: 0.3 | BY2: 0.3 | BZ2: 0.3 | CA2: 0.3 | CB2: 0.3 | CC2: 0.3
A3: Delhi | B3: ='RPO State forecasts'!$AH$14 -> 0.2172767 | C3: =B3+($K3-$B3)/10 -> 0.22554903 | D3: =C3+($K3-$B3)/10 -> 0.23382136 | E3: =D3+($K3-$B3)/10 -> 0.24209369 | F3: =E3+($K3-$B3)/10 -> 0.25036602 | G3: =F3+($K3-$B3)/10 -> 0.25863835 | H3: =G3+($K3-$B3)/10 -> 0.26691068 | I3: =H3+($K3-$B3)/10 -> 0.27518301 | J3: =I3+($K3-$B3)/10 -> 0.28345534 | K3: 0.3 | L3: 0.3 | M3: 0.3 | N3: 0.3 | O3: 0.3 | P3: 0.3 | Q3: 0.3 | R3: 0.3 | S3: 0.3 | T3: 0.3 | U3: 0.3 | V3: 0.3 | W3: 0.3 | X3: 0.3 | Y3: 0.3 | Z3: 0.3 | AA3: 0.3 | AB3: 0.3 | AC3: 0.3 | AD3: 0.3 | AE3: 0.3 | AF3: 0.3 | AG3: 0.3 | AH3: 0.3 | AI3: 0.3 | AJ3: 0.3 | AK3: 0.3 | AL3: 0.3 | AM3: 0.3 | AN3: 0.3 | AO3: 0.3 | AP3: 0.3 | AQ3: 0.3 | AR3: 0.3 | AS3: 0.3 | AT3: 0.3 | AU3: 0.3 | AV3: 0.3 | AW3: 0.3 | AX3: 0.3 | AY3: 0.3 | AZ3: 0.3 | BA3: 0.3 | BB3: 0.3 | BC3: 0.3 | BD3: 0.3 | BE3: 0.3 | BF3: 0.3 | BG3: 0.3 | BH3: 0.3 | BI3: 0.3 | BJ3: 0.3 | BK3: 0.3 | BL3: 0.3 | BM3: 0.3 | BN3: 0.3 | BO3: 0.3 | BP3: 0.3 | BQ3: 0.3 | BR3: 0.3 | BS3: 0.3 | BT3: 0.3 | BU3: 0.3 | BV3: 0.3 | BW3: 0.3 | BX3: 0.3 | BY3: 0.3 | BZ3: 0.3 | CA3: 0.3 | CB3: 0.3 | CC3: 0.3
A4: Haryana | B4: ='RPO State forecasts'!$AH$14 -> 0.2172767 | C4: =B4+($K4-$B4)/10 -> 0.22554903 | D4: =C4+($K4-$B4)/10 -> 0.23382136 | E4: =D4+($K4-$B4)/10 -> 0.24209369 | F4: =E4+($K4-$B4)/10 -> 0.25036602 | G4: =F4+($K4-$B4)/10 -> 0.25863835 | H4: =G4+($K4-$B4)/10 -> 0.26691068 | I4: =H4+($K4-$B4)/10 -> 0.27518301 | J4: =I4+($K4-$B4)/10 -> 0.28345534 | K4: 0.3 | L4: 0.3 | M4: 0.3 | N4: 0.3 | O4: 0.3 | P4: 0.3 | Q4: 0.3 | R4: 0.3 | S4: 0.3 | T4: 0.3 | U4: 0.3 | V4: 0.3 | W4: 0.3 | X4: 0.3 | Y4: 0.3 | Z4: 0.3 | AA4: 0.3 | AB4: 0.3 | AC4: 0.3 | AD4: 0.3 | AE4: 0.3 | AF4: 0.3 | AG4: 0.3 | AH4: 0.3 | AI4: 0.3 | AJ4: 0.3 | AK4: 0.3 | AL4: 0.3 | AM4: 0.3 | AN4: 0.3 | AO4: 0.3 | AP4: 0.3 | AQ4: 0.3 | AR4: 0.3 | AS4: 0.3 | AT4: 0.3 | AU4: 0.3 | AV4: 0.3 | AW4: 0.3 | AX4: 0.3 | AY4: 0.3 | AZ4: 0.3 | BA4: 0.3 | BB4: 0.3 | BC4: 0.3 | BD4: 0.3 | BE4: 0.3 | BF4: 0.3 | BG4: 0.3 | BH4: 0.3 | BI4: 0.3 | BJ4: 0.3 | BK4: 0.3 | BL4: 0.3 | BM4: 0.3 | BN4: 0.3 | BO4: 0.3 | BP4: 0.3 | BQ4: 0.3 | BR4: 0.3 | BS4: 0.3 | BT4: 0.3 | BU4: 0.3 | BV4: 0.3 | BW4: 0.3 | BX4: 0.3 | BY4: 0.3 | BZ4: 0.3 | CA4: 0.3 | CB4: 0.3 | CC4: 0.3
A5: Himachal Pradesh | B5: ='RPO State forecasts'!$AH$14 -> 0.2172767 | C5: =B5+($K5-$B5)/10 -> 0.22554903 | D5: =C5+($K5-$B5)/10 -> 0.23382136 | E5: =D5+($K5-$B5)/10 -> 0.24209369 | F5: =E5+($K5-$B5)/10 -> 0.25036602 | G5: =F5+($K5-$B5)/10 -> 0.25863835 | H5: =G5+($K5-$B5)/10 -> 0.26691068 | I5: =H5+($K5-$B5)/10 -> 0.27518301 | J5: =I5+($K5-$B5)/10 -> 0.28345534 | K5: 0.3 | L5: 0.3 | M5: 0.3 | N5: 0.3 | O5: 0.3 | P5: 0.3 | Q5: 0.3 | R5: 0.3 | S5: 0.3 | T5: 0.3 | U5: 0.3 | V5: 0.3 | W5: 0.3 | X5: 0.3 | Y5: 0.3 | Z5: 0.3 | AA5: 0.3 | AB5: 0.3 | AC5: 0.3 | AD5: 0.3 | AE5: 0.3 | AF5: 0.3 | AG5: 0.3 | AH5: 0.3 | AI5: 0.3 | AJ5: 0.3 | AK5: 0.3 | AL5: 0.3 | AM5: 0.3 | AN5: 0.3 | AO5: 0.3 | AP5: 0.3 | AQ5: 0.3 | AR5: 0.3 | AS5: 0.3 | AT5: 0.3 | AU5: 0.3 | AV5: 0.3 | AW5: 0.3 | AX5: 0.3 | AY5: 0.3 | AZ5: 0.3 | BA5: 0.3 | BB5: 0.3 | BC5: 0.3 | BD5: 0.3 | BE5: 0.3 | BF5: 0.3 | BG5: 0.3 | BH5: 0.3 | BI5: 0.3 | BJ5: 0.3 | BK5: 0.3 | BL5: 0.3 | BM5: 0.3 | BN5: 0.3 | BO5: 0.3 | BP5: 0.3 | BQ5: 0.3 | BR5: 0.3 | BS5: 0.3 | BT5: 0.3 | BU5: 0.3 | BV5: 0.3 | BW5: 0.3 | BX5: 0.3 | BY5: 0.3 | BZ5: 0.3 | CA5: 0.3 | CB5: 0.3 | CC5: 0.3
A6: UT of JK and Ladakh | B6: ='RPO State forecasts'!$AH$14 -> 0.2172767 | C6: =B6+($K6-$B6)/10 -> 0.22554903 | D6: =C6+($K6-$B6)/10 -> 0.23382136 | E6: =D6+($K6-$B6)/10 -> 0.24209369 | F6: =E6+($K6-$B6)/10 -> 0.25036602 | G6: =F6+($K6-$B6)/10 -> 0.25863835 | H6: =G6+($K6-$B6)/10 -> 0.26691068 | I6: =H6+($K6-$B6)/10 -> 0.27518301 | J6: =I6+($K6-$B6)/10 -> 0.28345534 | K6: 0.3 | L6: 0.3 | M6: 0.3 | N6: 0.3 | O6: 0.3 | P6: 0.3 | Q6: 0.3 | R6: 0.3 | S6: 0.3 | T6: 0.3 | U6: 0.3 | V6: 0.3 | W6: 0.3 | X6: 0.3 | Y6: 0.3 | Z6: 0.3 | AA6: 0.3 | AB6: 0.3 | AC6: 0.3 | AD6: 0.3 | AE6: 0.3 | AF6: 0.3 | AG6: 0.3 | AH6: 0.3 | AI6: 0.3 | AJ6: 0.3 | AK6: 0.3 | AL6: 0.3 | AM6: 0.3 | AN6: 0.3 | AO6: 0.3 | AP6: 0.3 | AQ6: 0.3 | AR6: 0.3 | AS6: 0.3 | AT6: 0.3 | AU6: 0.3 | AV6: 0.3 | AW6: 0.3 | AX6: 0.3 | AY6: 0.3 | AZ6: 0.3 | BA6: 0.3 | BB6: 0.3 | BC6: 0.3 | BD6: 0.3 | BE6: 0.3 | BF6: 0.3 | BG6: 0.3 | BH6: 0.3 | BI6: 0.3 | BJ6: 0.3 | BK6: 0.3 | BL6: 0.3 | BM6: 0.3 | BN6: 0.3 | BO6: 0.3 | BP6: 0.3 | BQ6: 0.3 | BR6: 0.3 | BS6: 0.3 | BT6: 0.3 | BU6: 0.3 | BV6: 0.3 | BW6: 0.3 | BX6: 0.3 | BY6: 0.3 | BZ6: 0.3 | CA6: 0.3 | CB6: 0.3 | CC6: 0.3
A7: Punjab | B7: ='RPO State forecasts'!$AH$14 -> 0.2172767 | C7: =B7+($K7-$B7)/10 -> 0.22554903 | D7: =C7+($K7-$B7)/10 -> 0.23382136 | E7: =D7+($K7-$B7)/10 -> 0.24209369 | F7: =E7+($K7-$B7)/10 -> 0.25036602 | G7: =F7+($K7-$B7)/10 -> 0.25863835 | H7: =G7+($K7-$B7)/10 -> 0.26691068 | I7: =H7+($K7-$B7)/10 -> 0.27518301 | J7: =I7+($K7-$B7)/10 -> 0.28345534 | K7: 0.3 | L7: 0.3 | M7: 0.3 | N7: 0.3 | O7: 0.3 | P7: 0.3 | Q7: 0.3 | R7: 0.3 | S7: 0.3 | T7: 0.3 | U7: 0.3 | V7: 0.3 | W7: 0.3 | X7: 0.3 | Y7: 0.3 | Z7: 0.3 | AA7: 0.3 | AB7: 0.3 | AC7: 0.3 | AD7: 0.3 | AE7: 0.3 | AF7: 0.3 | AG7: 0.3 | AH7: 0.3 | AI7: 0.3 | AJ7: 0.3 | AK7: 0.3 | AL7: 0.3 | AM7: 0.3 | AN7: 0.3 | AO7: 0.3 | AP7: 0.3 | AQ7: 0.3 | AR7: 0.3 | AS7: 0.3 | AT7: 0.3 | AU7: 0.3 | AV7: 0.3 | AW7: 0.3 | AX7: 0.3 | AY7: 0.3 | AZ7: 0.3 | BA7: 0.3 | BB7: 0.3 | BC7: 0.3 | BD7: 0.3 | BE7: 0.3 | BF7: 0.3 | BG7: 0.3 | BH7: 0.3 | BI7: 0.3 | BJ7: 0.3 | BK7: 0.3 | BL7: 0.3 | BM7: 0.3 | BN7: 0.3 | BO7: 0.3 | BP7: 0.3 | BQ7: 0.3 | BR7: 0.3 | BS7: 0.3 | BT7: 0.3 | BU7: 0.3 | BV7: 0.3 | BW7: 0.3 | BX7: 0.3 | BY7: 0.3 | BZ7: 0.3 | CA7: 0.3 | CB7: 0.3 | CC7: 0.3
A8: Rajasthan | B8: ='RPO State forecasts'!$AH$14 -> 0.2172767 | C8: =B8+($K8-$B8)/10 -> 0.22554903 | D8: =C8+($K8-$B8)/10 -> 0.23382136 | E8: =D8+($K8-$B8)/10 -> 0.24209369 | F8: =E8+($K8-$B8)/10 -> 0.25036602 | G8: =F8+($K8-$B8)/10 -> 0.25863835 | H8: =G8+($K8-$B8)/10 -> 0.26691068 | I8: =H8+($K8-$B8)/10 -> 0.27518301 | J8: =I8+($K8-$B8)/10 -> 0.28345534 | K8: 0.3 | L8: 0.3 | M8: 0.3 | N8: 0.3 | O8: 0.3 | P8: 0.3 | Q8: 0.3 | R8: 0.3 | S8: 0.3 | T8: 0.3 | U8: 0.3 | V8: 0.3 | W8: 0.3 | X8: 0.3 | Y8: 0.3 | Z8: 0.3 | AA8: 0.3 | AB8: 0.3 | AC8: 0.3 | AD8: 0.3 | AE8: 0.3 | AF8: 0.3 | AG8: 0.3 | AH8: 0.3 | AI8: 0.3 | AJ8: 0.3 | AK8: 0.3 | AL8: 0.3 | AM8: 0.3 | AN8: 0.3 | AO8: 0.3 | AP8: 0.3 | AQ8: 0.3 | AR8: 0.3 | AS8: 0.3 | AT8: 0.3 | AU8: 0.3 | AV8: 0.3 | AW8: 0.3 | AX8: 0.3 | AY8: 0.3 | AZ8: 0.3 | BA8: 0.3 | BB8: 0.3 | BC8: 0.3 | BD8: 0.3 | BE8: 0.3 | BF8: 0.3 | BG8: 0.3 | BH8: 0.3 | BI8: 0.3 | BJ8: 0.3 | BK8: 0.3 | BL8: 0.3 | BM8: 0.3 | BN8: 0.3 | BO8: 0.3 | BP8: 0.3 | BQ8: 0.3 | BR8: 0.3 | BS8: 0.3 | BT8: 0.3 | BU8: 0.3 | BV8: 0.3 | BW8: 0.3 | BX8: 0.3 | BY8: 0.3 | BZ8: 0.3 | CA8: 0.3 | CB8: 0.3 | CC8: 0.3
A9: Uttar Pradesh | B9: ='RPO State forecasts'!$AH$14 -> 0.2172767 | C9: =B9+($K9-$B9)/10 -> 0.22554903 | D9: =C9+($K9-$B9)/10 -> 0.23382136 | E9: =D9+($K9-$B9)/10 -> 0.24209369 | F9: =E9+($K9-$B9)/10 -> 0.25036602 | G9: =F9+($K9-$B9)/10 -> 0.25863835 | H9: =G9+($K9-$B9)/10 -> 0.26691068 | I9: =H9+($K9-$B9)/10 -> 0.27518301 | J9: =I9+($K9-$B9)/10 -> 0.28345534 | K9: 0.3 | L9: 0.3 | M9: 0.3 | N9: 0.3 | O9: 0.3 | P9: 0.3 | Q9: 0.3 | R9: 0.3 | S9: 0.3 | T9: 0.3 | U9: 0.3 | V9: 0.3 | W9: 0.3 | X9: 0.3 | Y9: 0.3 | Z9: 0.3 | AA9: 0.3 | AB9: 0.3 | AC9: 0.3 | AD9: 0.3 | AE9: 0.3 | AF9: 0.3 | AG9: 0.3 | AH9: 0.3 | AI9: 0.3 | AJ9: 0.3 | AK9: 0.3 | AL9: 0.3 | AM9: 0.3 | AN9: 0.3 | AO9: 0.3 | AP9: 0.3 | AQ9: 0.3 | AR9: 0.3 | AS9: 0.3 | AT9: 0.3 | AU9: 0.3 | AV9: 0.3 | AW9: 0.3 | AX9: 0.3 | AY9: 0.3 | AZ9: 0.3 | BA9: 0.3 | BB9: 0.3 | BC9: 0.3 | BD9: 0.3 | BE9: 0.3 | BF9: 0.3 | BG9: 0.3 | BH9: 0.3 | BI9: 0.3 | BJ9: 0.3 | BK9: 0.3 | BL9: 0.3 | BM9: 0.3 | BN9: 0.3 | BO9: 0.3 | BP9: 0.3 | BQ9: 0.3 | BR9: 0.3 | BS9: 0.3 | BT9: 0.3 | BU9: 0.3 | BV9: 0.3 | BW9: 0.3 | BX9: 0.3 | BY9: 0.3 | BZ9: 0.3 | CA9: 0.3 | CB9: 0.3 | CC9: 0.3
A10: Uttarakhand | B10: ='RPO State forecasts'!$AH$14 -> 0.2172767 | C10: =B10+($K10-$B10)/10 -> 0.22554903 | D10: =C10+($K10-$B10)/10 -> 0.23382136 | E10: =D10+($K10-$B10)/10 -> 0.24209369 | F10: =E10+($K10-$B10)/10 -> 0.25036602 | G10: =F10+($K10-$B10)/10 -> 0.25863835 | H10: =G10+($K10-$B10)/10 -> 0.26691068 | I10: =H10+($K10-$B10)/10 -> 0.27518301 | J10: =I10+($K10-$B10)/10 -> 0.28345534 | K10: 0.3 | L10: 0.3 | M10: 0.3 | N10: 0.3 | O10: 0.3 | P10: 0.3 | Q10: 0.3 | R10: 0.3 | S10: 0.3 | T10: 0.3 | U10: 0.3 | V10: 0.3 | W10: 0.3 | X10: 0.3 | Y10: 0.3 | Z10: 0.3 | AA10: 0.3 | AB10: 0.3 | AC10: 0.3 | AD10: 0.3 | AE10: 0.3 | AF10: 0.3 | AG10: 0.3 | AH10: 0.3 | AI10: 0.3 | AJ10: 0.3 | AK10: 0.3 | AL10: 0.3 | AM10: 0.3 | AN10: 0.3 | AO10: 0.3 | AP10: 0.3 | AQ10: 0.3 | AR10: 0.3 | AS10: 0.3 | AT10: 0.3 | AU10: 0.3 | AV10: 0.3 | AW10: 0.3 | AX10: 0.3 | AY10: 0.3 | AZ10: 0.3 | BA10: 0.3 | BB10: 0.3 | BC10: 0.3 | BD10: 0.3 | BE10: 0.3 | BF10: 0.3 | BG10: 0.3 | BH10: 0.3 | BI10: 0.3 | BJ10: 0.3 | BK10: 0.3 | BL10: 0.3 | BM10: 0.3 | BN10: 0.3 | BO10: 0.3 | BP10: 0.3 | BQ10: 0.3 | BR10: 0.3 | BS10: 0.3 | BT10: 0.3 | BU10: 0.3 | BV10: 0.3 | BW10: 0.3 | BX10: 0.3 | BY10: 0.3 | BZ10: 0.3 | CA10: 0.3 | CB10: 0.3 | CC10: 0.3
A11: Chhattisgarh | B11: ='RPO State forecasts'!$AH$14 -> 0.2172767 | C11: =B11+($K11-$B11)/10 -> 0.22554903 | D11: =C11+($K11-$B11)/10 -> 0.23382136 | E11: =D11+($K11-$B11)/10 -> 0.24209369 | F11: =E11+($K11-$B11)/10 -> 0.25036602 | G11: =F11+($K11-$B11)/10 -> 0.25863835 | H11: =G11+($K11-$B11)/10 -> 0.26691068 | I11: =H11+($K11-$B11)/10 -> 0.27518301 | J11: =I11+($K11-$B11)/10 -> 0.28345534 | K11: 0.3 | L11: 0.3 | M11: 0.3 | N11: 0.3 | O11: 0.3 | P11: 0.3 | Q11: 0.3 | R11: 0.3 | S11: 0.3 | T11: 0.3 | U11: 0.3 | V11: 0.3 | W11: 0.3 | X11: 0.3 | Y11: 0.3 | Z11: 0.3 | AA11: 0.3 | AB11: 0.3 | AC11: 0.3 | AD11: 0.3 | AE11: 0.3 | AF11: 0.3 | AG11: 0.3 | AH11: 0.3 | AI11: 0.3 | AJ11: 0.3 | AK11: 0.3 | AL11: 0.3 | AM11: 0.3 | AN11: 0.3 | AO11: 0.3 | AP11: 0.3 | AQ11: 0.3 | AR11: 0.3 | AS11: 0.3 | AT11: 0.3 | AU11: 0.3 | AV11: 0.3 | AW11: 0.3 | AX11: 0.3 | AY11: 0.3 | AZ11: 0.3 | BA11: 0.3 | BB11: 0.3 | BC11: 0.3 | BD11: 0.3 | BE11: 0.3 | BF11: 0.3 | BG11: 0.3 | BH11: 0.3 | BI11: 0.3 | BJ11: 0.3 | BK11: 0.3 | BL11: 0.3 | BM11: 0.3 | BN11: 0.3 | BO11: 0.3 | BP11: 0.3 | BQ11: 0.3 | BR11: 0.3 | BS11: 0.3 | BT11: 0.3 | BU11: 0.3 | BV11: 0.3 | BW11: 0.3 | BX11: 0.3 | BY11: 0.3 | BZ11: 0.3 | CA11: 0.3 | CB11: 0.3 | CC11: 0.3
A12: Gujarat | B12: ='RPO State forecasts'!$AH$14 -> 0.2172767 | C12: =B12+($K12-$B12)/10 -> 0.22554903 | D12: =C12+($K12-$B12)/10 -> 0.23382136 | E12: =D12+($K12-$B12)/10 -> 0.24209369 | F12: =E12+($K12-$B12)/10 -> 0.25036602 | G12: =F12+($K12-$B12)/10 -> 0.25863835 | H12: =G12+($K12-$B12)/10 -> 0.26691068 | I12: =H12+($K12-$B12)/10 -> 0.27518301 | J12: =I12+($K12-$B12)/10 -> 0.28345534 | K12: 0.3 | L12: 0.3 | M12: 0.3 | N12: 0.3 | O12: 0.3 | P12: 0.3 | Q12: 0.3 | R12: 0.3 | S12: 0.3 | T12: 0.3 | U12: 0.3 | V12: 0.3 | W12: 0.3 | X12: 0.3 | Y12: 0.3 | Z12: 0.3 | AA12: 0.3 | AB12: 0.3 | AC12: 0.3 | AD12: 0.3 | AE12: 0.3 | AF12: 0.3 | AG12: 0.3 | AH12: 0.3 | AI12: 0.3 | AJ12: 0.3 | AK12: 0.3 | AL12: 0.3 | AM12: 0.3 | AN12: 0.3 | AO12: 0.3 | AP12: 0.3 | AQ12: 0.3 | AR12: 0.3 | AS12: 0.3 | AT12: 0.3 | AU12: 0.3 | AV12: 0.3 | AW12: 0.3 | AX12: 0.3 | AY12: 0.3 | AZ12: 0.3 | BA12: 0.3 | BB12: 0.3 | BC12: 0.3 | BD12: 0.3 | BE12: 0.3 | BF12: 0.3 | BG12: 0.3 | BH12: 0.3 | BI12: 0.3 | BJ12: 0.3 | BK12: 0.3 | BL12: 0.3 | BM12: 0.3 | BN12: 0.3 | BO12: 0.3 | BP12: 0.3 | BQ12: 0.3 | BR12: 0.3 | BS12: 0.3 | BT12: 0.3 | BU12: 0.3 | BV12: 0.3 | BW12: 0.3 | BX12: 0.3 | BY12: 0.3 | BZ12: 0.3 | CA12: 0.3 | CB12: 0.3 | CC12: 0.3
A13: Madhya Pradesh | B13: ='RPO State forecasts'!$AH$14 -> 0.2172767 | C13: =B13+($K13-$B13)/10 -> 0.22554903 | D13: =C13+($K13-$B13)/10 -> 0.23382136 | E13: =D13+($K13-$B13)/10 -> 0.24209369 | F13: =E13+($K13-$B13)/10 -> 0.25036602 | G13: =F13+($K13-$B13)/10 -> 0.25863835 | H13: =G13+($K13-$B13)/10 -> 0.26691068 | I13: =H13+($K13-$B13)/10 -> 0.27518301 | J13: =I13+($K13-$B13)/10 -> 0.28345534 | K13: 0.3 | L13: 0.3 | M13: 0.3 | N13: 0.3 | O13: 0.3 | P13: 0.3 | Q13: 0.3 | R13: 0.3 | S13: 0.3 | T13: 0.3 | U13: 0.3 | V13: 0.3 | W13: 0.3 | X13: 0.3 | Y13: 0.3 | Z13: 0.3 | AA13: 0.3 | AB13: 0.3 | AC13: 0.3 | AD13: 0.3 | AE13: 0.3 | AF13: 0.3 | AG13: 0.3 | AH13: 0.3 | AI13: 0.3 | AJ13: 0.3 | AK13: 0.3 | AL13: 0.3 | AM13: 0.3 | AN13: 0.3 | AO13: 0.3 | AP13: 0.3 | AQ13: 0.3 | AR13: 0.3 | AS13: 0.3 | AT13: 0.3 | AU13: 0.3 | AV13: 0.3 | AW13: 0.3 | AX13: 0.3 | AY13: 0.3 | AZ13: 0.3 | BA13: 0.3 | BB13: 0.3 | BC13: 0.3 | BD13: 0.3 | BE13: 0.3 | BF13: 0.3 | BG13: 0.3 | BH13: 0.3 | BI13: 0.3 | BJ13: 0.3 | BK13: 0.3 | BL13: 0.3 | BM13: 0.3 | BN13: 0.3 | BO13: 0.3 | BP13: 0.3 | BQ13: 0.3 | BR13: 0.3 | BS13: 0.3 | BT13: 0.3 | BU13: 0.3 | BV13: 0.3 | BW13: 0.3 | BX13: 0.3 | BY13: 0.3 | BZ13: 0.3 | CA13: 0.3 | CB13: 0.3 | CC13: 0.3
... A37: Tripura | B37: ='RPO State forecasts'!$AH$14 -> 0.2172767 | C37: =B37+($K37-$B37)/10 -> 0.22554903 | D37: =C37+($K37-$B37)/10 -> 0.23382136 | E37: =D37+($K37-$B37)/10 -> 0.24209369 | F37: =E37+($K37-$B37)/10 -> 0.25036602 | G37: =F37+($K37-$B37)/10 -> 0.25863835 | H37: =G37+($K37-$B37)/10 -> 0.26691068 | I37: =H37+($K37-$B37)/10 -> 0.27518301 | J37: =I37+($K37-$B37)/10 -> 0.28345534 | K37: 0.3 | L37: 0.3 | M37: 0.3 | N37: 0.3 | O37: 0.3 | P37: 0.3 | Q37: 0.3 | R37: 0.3 | S37: 0.3 | T37: 0.3 | U37: 0.3 | V37: 0.3 | W37: 0.3 | X37: 0.3 | Y37: 0.3 | Z37: 0.3 | AA37: 0.3 | AB37: 0.3 | AC37: 0.3 | AD37: 0.3 | AE37: 0.3 | AF37: 0.3 | AG37: 0.3 | AH37: 0.3 | AI37: 0.3 | AJ37: 0.3 | AK37: 0.3 | AL37: 0.3 | AM37: 0.3 | AN37: 0.3 | AO37: 0.3 | AP37: 0.3 | AQ37: 0.3 | AR37: 0.3 | AS37: 0.3 | AT37: 0.3 | AU37: 0.3 | AV37: 0.3 | AW37: 0.3 | AX37: 0.3 | AY37: 0.3 | AZ37: 0.3 | BA37: 0.3 | BB37: 0.3 | BC37: 0.3 | BD37: 0.3 | BE37: 0.3 | BF37: 0.3 | BG37: 0.3 | BH37: 0.3 | BI37: 0.3 | BJ37: 0.3 | BK37: 0.3 | BL37: 0.3 | BM37: 0.3 | BN37: 0.3 | BO37: 0.3 | BP37: 0.3 | BQ37: 0.3 | BR37: 0.3 | BS37: 0.3 | BT37: 0.3 | BU37: 0.3 | BV37: 0.3 | BW37: 0.3 | BX37: 0.3 | BY37: 0.3 | BZ37: 0.3 | CA37: 0.3 | CB37: 0.3 | CC37: 0.3
A38: subregion37 | B38: 0 | C38: 0 | D38: 0 | E38: 0 | F38: 0 | G38: 0 | H38: 0 | I38: 0 | J38: 0 | K38: 0 | L38: 0 | M38: 0 | N38: 0 | O38: 0 | P38: 0 | Q38: 0 | R38: 0 | S38: 0 | T38: 0 | U38: 0 | V38: 0 | W38: 0 | X38: 0 | Y38: 0 | Z38: 0 | AA38: 0 | AB38: 0 | AC38: 0 | AD38: 0 | AE38: 0 | AF38: 0 | AG38: 0 | AH38: 0 | AI38: 0 | AJ38: 0 | AK38: 0 | AL38: 0 | AM38: 0 | AN38: 0 | AO38: 0 | AP38: 0 | AQ38: 0 | AR38: 0 | AS38: 0 | AT38: 0 | AU38: 0 | AV38: 0 | AW38: 0 | AX38: 0 | AY38: 0 | AZ38: 0 | BA38: 0 | BB38: 0 | BC38: 0 | BD38: 0 | BE38: 0 | BF38: 0 | BG38: 0 | BH38: 0 | BI38: 0 | BJ38: 0 | BK38: 0 | BL38: 0 | BM38: 0 | BN38: 0 | BO38: 0 | BP38: 0 | BQ38: 0 | BR38: 0 | BS38: 0 | BT38: 0 | BU38: 0 | BV38: 0 | BW38: 0 | BX38: 0 | BY38: 0 | BZ38: 0 | CA38: 0 | CB38: 0 | CC38: 0
A39: subregion38 | B39: 0 | C39: 0 | D39: 0 | E39: 0 | F39: 0 | G39: 0 | H39: 0 | I39: 0 | J39: 0 | K39: 0 | L39: 0 | M39: 0 | N39: 0 | O39: 0 | P39: 0 | Q39: 0 | R39: 0 | S39: 0 | T39: 0 | U39: 0 | V39: 0 | W39: 0 | X39: 0 | Y39: 0 | Z39: 0 | AA39: 0 | AB39: 0 | AC39: 0 | AD39: 0 | AE39: 0 | AF39: 0 | AG39: 0 | AH39: 0 | AI39: 0 | AJ39: 0 | AK39: 0 | AL39: 0 | AM39: 0 | AN39: 0 | AO39: 0 | AP39: 0 | AQ39: 0 | AR39: 0 | AS39: 0 | AT39: 0 | AU39: 0 | AV39: 0 | AW39: 0 | AX39: 0 | AY39: 0 | AZ39: 0 | BA39: 0 | BB39: 0 | BC39: 0 | BD39: 0 | BE39: 0 | BF39: 0 | BG39: 0 | BH39: 0 | BI39: 0 | BJ39: 0 | BK39: 0 | BL39: 0 | BM39: 0 | BN39: 0 | BO39: 0 | BP39: 0 | BQ39: 0 | BR39: 0 | BS39: 0 | BT39: 0 | BU39: 0 | BV39: 0 | BW39: 0 | BX39: 0 | BY39: 0 | BZ39: 0 | CA39: 0 | CB39: 0 | CC39: 0
A40: subregion39 | B40: 0 | C40: 0 | D40: 0 | E40: 0 | F40: 0 | G40: 0 | H40: 0 | I40: 0 | J40: 0 | K40: 0 | L40: 0 | M40: 0 | N40: 0 | O40: 0 | P40: 0 | Q40: 0 | R40: 0 | S40: 0 | T40: 0 | U40: 0 | V40: 0 | W40: 0 | X40: 0 | Y40: 0 | Z40: 0 | AA40: 0 | AB40: 0 | AC40: 0 | AD40: 0 | AE40: 0 | AF40: 0 | AG40: 0 | AH40: 0 | AI40: 0 | AJ40: 0 | AK40: 0 | AL40: 0 | AM40: 0 | AN40: 0 | AO40: 0 | AP40: 0 | AQ40: 0 | AR40: 0 | AS40: 0 | AT40: 0 | AU40: 0 | AV40: 0 | AW40: 0 | AX40: 0 | AY40: 0 | AZ40: 0 | BA40: 0 | BB40: 0 | BC40: 0 | BD40: 0 | BE40: 0 | BF40: 0 | BG40: 0 | BH40: 0 | BI40: 0 | BJ40: 0 | BK40: 0 | BL40: 0 | BM40: 0 | BN40: 0 | BO40: 0 | BP40: 0 | BQ40: 0 | BR40: 0 | BS40: 0 | BT40: 0 | BU40: 0 | BV40: 0 | BW40: 0 | BX40: 0 | BY40: 0 | BZ40: 0 | CA40: 0 | CB40: 0 | CC40: 0
A41: subregion40 | B41: 0 | C41: 0 | D41: 0 | E41: 0 | F41: 0 | G41: 0 | H41: 0 | I41: 0 | J41: 0 | K41: 0 | L41: 0 | M41: 0 | N41: 0 | O41: 0 | P41: 0 | Q41: 0 | R41: 0 | S41: 0 | T41: 0 | U41: 0 | V41: 0 | W41: 0 | X41: 0 | Y41: 0 | Z41: 0 | AA41: 0 | AB41: 0 | AC41: 0 | AD41: 0 | AE41: 0 | AF41: 0 | AG41: 0 | AH41: 0 | AI41: 0 | AJ41: 0 | AK41: 0 | AL41: 0 | AM41: 0 | AN41: 0 | AO41: 0 | AP41: 0 | AQ41: 0 | AR41: 0 | AS41: 0 | AT41: 0 | AU41: 0 | AV41: 0 | AW41: 0 | AX41: 0 | AY41: 0 | AZ41: 0 | BA41: 0 | BB41: 0 | BC41: 0 | BD41: 0 | BE41: 0 | BF41: 0 | BG41: 0 | BH41: 0 | BI41: 0 | BJ41: 0 | BK41: 0 | BL41: 0 | BM41: 0 | BN41: 0 | BO41: 0 | BP41: 0 | BQ41: 0 | BR41: 0 | BS41: 0 | BT41: 0 | BU41: 0 | BV41: 0 | BW41: 0 | BX41: 0 | BY41: 0 | BZ41: 0 | CA41: 0 | CB41: 0 | CC41: 0
A42: subregion41 | B42: 0 | C42: 0 | D42: 0 | E42: 0 | F42: 0 | G42: 0 | H42: 0 | I42: 0 | J42: 0 | K42: 0 | L42: 0 | M42: 0 | N42: 0 | O42: 0 | P42: 0 | Q42: 0 | R42: 0 | S42: 0 | T42: 0 | U42: 0 | V42: 0 | W42: 0 | X42: 0 | Y42: 0 | Z42: 0 | AA42: 0 | AB42: 0 | AC42: 0 | AD42: 0 | AE42: 0 | AF42: 0 | AG42: 0 | AH42: 0 | AI42: 0 | AJ42: 0 | AK42: 0 | AL42: 0 | AM42: 0 | AN42: 0 | AO42: 0 | AP42: 0 | AQ42: 0 | AR42: 0 | AS42: 0 | AT42: 0 | AU42: 0 | AV42: 0 | AW42: 0 | AX42: 0 | AY42: 0 | AZ42: 0 | BA42: 0 | BB42: 0 | BC42: 0 | BD42: 0 | BE42: 0 | BF42: 0 | BG42: 0 | BH42: 0 | BI42: 0 | BJ42: 0 | BK42: 0 | BL42: 0 | BM42: 0 | BN42: 0 | BO42: 0 | BP42: 0 | BQ42: 0 | BR42: 0 | BS42: 0 | BT42: 0 | BU42: 0 | BV42: 0 | BW42: 0 | BX42: 0 | BY42: 0 | BZ42: 0 | CA42: 0 | CB42: 0 | CC42: 0
A43: subregion42 | B43: 0 | C43: 0 | D43: 0 | E43: 0 | F43: 0 | G43: 0 | H43: 0 | I43: 0 | J43: 0 | K43: 0 | L43: 0 | M43: 0 | N43: 0 | O43: 0 | P43: 0 | Q43: 0 | R43: 0 | S43: 0 | T43: 0 | U43: 0 | V43: 0 | W43: 0 | X43: 0 | Y43: 0 | Z43: 0 | AA43: 0 | AB43: 0 | AC43: 0 | AD43: 0 | AE43: 0 | AF43: 0 | AG43: 0 | AH43: 0 | AI43: 0 | AJ43: 0 | AK43: 0 | AL43: 0 | AM43: 0 | AN43: 0 | AO43: 0 | AP43: 0 | AQ43: 0 | AR43: 0 | AS43: 0 | AT43: 0 | AU43: 0 | AV43: 0 | AW43: 0 | AX43: 0 | AY43: 0 | AZ43: 0 | BA43: 0 | BB43: 0 | BC43: 0 | BD43: 0 | BE43: 0 | BF43: 0 | BG43: 0 | BH43: 0 | BI43: 0 | BJ43: 0 | BK43: 0 | BL43: 0 | BM43: 0 | BN43: 0 | BO43: 0 | BP43: 0 | BQ43: 0 | BR43: 0 | BS43: 0 | BT43: 0 | BU43: 0 | BV43: 0 | BW43: 0 | BX43: 0 | BY43: 0 | BZ43: 0 | CA43: 0 | CB43: 0 | CC43: 0
A44: subregion43 | B44: 0 | C44: 0 | D44: 0 | E44: 0 | F44: 0 | G44: 0 | H44: 0 | I44: 0 | J44: 0 | K44: 0 | L44: 0 | M44: 0 | N44: 0 | O44: 0 | P44: 0 | Q44: 0 | R44: 0 | S44: 0 | T44: 0 | U44: 0 | V44: 0 | W44: 0 | X44: 0 | Y44: 0 | Z44: 0 | AA44: 0 | AB44: 0 | AC44: 0 | AD44: 0 | AE44: 0 | AF44: 0 | AG44: 0 | AH44: 0 | AI44: 0 | AJ44: 0 | AK44: 0 | AL44: 0 | AM44: 0 | AN44: 0 | AO44: 0 | AP44: 0 | AQ44: 0 | AR44: 0 | AS44: 0 | AT44: 0 | AU44: 0 | AV44: 0 | AW44: 0 | AX44: 0 | AY44: 0 | AZ44: 0 | BA44: 0 | BB44: 0 | BC44: 0 | BD44: 0 | BE44: 0 | BF44: 0 | BG44: 0 | BH44: 0 | BI44: 0 | BJ44: 0 | BK44: 0 | BL44: 0 | BM44: 0 | BN44: 0 | BO44: 0 | BP44: 0 | BQ44: 0 | BR44: 0 | BS44: 0 | BT44: 0 | BU44: 0 | BV44: 0 | BW44: 0 | BX44: 0 | BY44: 0 | BZ44: 0 | CA44: 0 | CB44: 0 | CC44: 0
A45: subregion44 | B45: 0 | C45: 0 | D45: 0 | E45: 0 | F45: 0 | G45: 0 | H45: 0 | I45: 0 | J45: 0 | K45: 0 | L45: 0 | M45: 0 | N45: 0 | O45: 0 | P45: 0 | Q45: 0 | R45: 0 | S45: 0 | T45: 0 | U45: 0 | V45: 0 | W45: 0 | X45: 0 | Y45: 0 | Z45: 0 | AA45: 0 | AB45: 0 | AC45: 0 | AD45: 0 | AE45: 0 | AF45: 0 | AG45: 0 | AH45: 0 | AI45: 0 | AJ45: 0 | AK45: 0 | AL45: 0 | AM45: 0 | AN45: 0 | AO45: 0 | AP45: 0 | AQ45: 0 | AR45: 0 | AS45: 0 | AT45: 0 | AU45: 0 | AV45: 0 | AW45: 0 | AX45: 0 | AY45: 0 | AZ45: 0 | BA45: 0 | BB45: 0 | BC45: 0 | BD45: 0 | BE45: 0 | BF45: 0 | BG45: 0 | BH45: 0 | BI45: 0 | BJ45: 0 | BK45: 0 | BL45: 0 | BM45: 0 | BN45: 0 | BO45: 0 | BP45: 0 | BQ45: 0 | BR45: 0 | BS45: 0 | BT45: 0 | BU45: 0 | BV45: 0 | BW45: 0 | BX45: 0 | BY45: 0 | BZ45: 0 | CA45: 0 | CB45: 0 | CC45: 0
A46: subregion45 | B46: 0 | C46: 0 | D46: 0 | E46: 0 | F46: 0 | G46: 0 | H46: 0 | I46: 0 | J46: 0 | K46: 0 | L46: 0 | M46: 0 | N46: 0 | O46: 0 | P46: 0 | Q46: 0 | R46: 0 | S46: 0 | T46: 0 | U46: 0 | V46: 0 | W46: 0 | X46: 0 | Y46: 0 | Z46: 0 | AA46: 0 | AB46: 0 | AC46: 0 | AD46: 0 | AE46: 0 | AF46: 0 | AG46: 0 | AH46: 0 | AI46: 0 | AJ46: 0 | AK46: 0 | AL46: 0 | AM46: 0 | AN46: 0 | AO46: 0 | AP46: 0 | AQ46: 0 | AR46: 0 | AS46: 0 | AT46: 0 | AU46: 0 | AV46: 0 | AW46: 0 | AX46: 0 | AY46: 0 | AZ46: 0 | BA46: 0 | BB46: 0 | BC46: 0 | BD46: 0 | BE46: 0 | BF46: 0 | BG46: 0 | BH46: 0 | BI46: 0 | BJ46: 0 | BK46: 0 | BL46: 0 | BM46: 0 | BN46: 0 | BO46: 0 | BP46: 0 | BQ46: 0 | BR46: 0 | BS46: 0 | BT46: 0 | BU46: 0 | BV46: 0 | BW46: 0 | BX46: 0 | BY46: 0 | BZ46: 0 | CA46: 0 | CB46: 0 | CC46: 0
A47: subregion46 | B47: 0 | C47: 0 | D47: 0 | E47: 0 | F47: 0 | G47: 0 | H47: 0 | I47: 0 | J47: 0 | K47: 0 | L47: 0 | M47: 0 | N47: 0 | O47: 0 | P47: 0 | Q47: 0 | R47: 0 | S47: 0 | T47: 0 | U47: 0 | V47: 0 | W47: 0 | X47: 0 | Y47: 0 | Z47: 0 | AA47: 0 | AB47: 0 | AC47: 0 | AD47: 0 | AE47: 0 | AF47: 0 | AG47: 0 | AH47: 0 | AI47: 0 | AJ47: 0 | AK47: 0 | AL47: 0 | AM47: 0 | AN47: 0 | AO47: 0 | AP47: 0 | AQ47: 0 | AR47: 0 | AS47: 0 | AT47: 0 | AU47: 0 | AV47: 0 | AW47: 0 | AX47: 0 | AY47: 0 | AZ47: 0 | BA47: 0 | BB47: 0 | BC47: 0 | BD47: 0 | BE47: 0 | BF47: 0 | BG47: 0 | BH47: 0 | BI47: 0 | BJ47: 0 | BK47: 0 | BL47: 0 | BM47: 0 | BN47: 0 | BO47: 0 | BP47: 0 | BQ47: 0 | BR47: 0 | BS47: 0 | BT47: 0 | BU47: 0 | BV47: 0 | BW47: 0 | BX47: 0 | BY47: 0 | BZ47: 0 | CA47: 0 | CB47: 0 | CC47: 0
A48: subregion47 | B48: 0 | C48: 0 | D48: 0 | E48: 0 | F48: 0 | G48: 0 | H48: 0 | I48: 0 | J48: 0 | K48: 0 | L48: 0 | M48: 0 | N48: 0 | O48: 0 | P48: 0 | Q48: 0 | R48: 0 | S48: 0 | T48: 0 | U48: 0 | V48: 0 | W48: 0 | X48: 0 | Y48: 0 | Z48: 0 | AA48: 0 | AB48: 0 | AC48: 0 | AD48: 0 | AE48: 0 | AF48: 0 | AG48: 0 | AH48: 0 | AI48: 0 | AJ48: 0 | AK48: 0 | AL48: 0 | AM48: 0 | AN48: 0 | AO48: 0 | AP48: 0 | AQ48: 0 | AR48: 0 | AS48: 0 | AT48: 0 | AU48: 0 | AV48: 0 | AW48: 0 | AX48: 0 | AY48: 0 | AZ48: 0 | BA48: 0 | BB48: 0 | BC48: 0 | BD48: 0 | BE48: 0 | BF48: 0 | BG48: 0 | BH48: 0 | BI48: 0 | BJ48: 0 | BK48: 0 | BL48: 0 | BM48: 0 | BN48: 0 | BO48: 0 | BP48: 0 | BQ48: 0 | BR48: 0 | BS48: 0 | BT48: 0 | BU48: 0 | BV48: 0 | BW48: 0 | BX48: 0 | BY48: 0 | BZ48: 0 | CA48: 0 | CB48: 0 | CC48: 0
A49: subregion48 | B49: 0 | C49: 0 | D49: 0 | E49: 0 | F49: 0 | G49: 0 | H49: 0 | I49: 0 | J49: 0 | K49: 0 | L49: 0 | M49: 0 | N49: 0 | O49: 0 | P49: 0 | Q49: 0 | R49: 0 | S49: 0 | T49: 0 | U49: 0 | V49: 0 | W49: 0 | X49: 0 | Y49: 0 | Z49: 0 | AA49: 0 | AB49: 0 | AC49: 0 | AD49: 0 | AE49: 0 | AF49: 0 | AG49: 0 | AH49: 0 | AI49: 0 | AJ49: 0 | AK49: 0 | AL49: 0 | AM49: 0 | AN49: 0 | AO49: 0 | AP49: 0 | AQ49: 0 | AR49: 0 | AS49: 0 | AT49: 0 | AU49: 0 | AV49: 0 | AW49: 0 | AX49: 0 | AY49: 0 | AZ49: 0 | BA49: 0 | BB49: 0 | BC49: 0 | BD49: 0 | BE49: 0 | BF49: 0 | BG49: 0 | BH49: 0 | BI49: 0 | BJ49: 0 | BK49: 0 | BL49: 0 | BM49: 0 | BN49: 0 | BO49: 0 | BP49: 0 | BQ49: 0 | BR49: 0 | BS49: 0 | BT49: 0 | BU49: 0 | BV49: 0 | BW49: 0 | BX49: 0 | BY49: 0 | BZ49: 0 | CA49: 0 | CB49: 0 | CC49: 0
... A61: subregion60 | B61: 0 | C61: 0 | D61: 0 | E61: 0 | F61: 0 | G61: 0 | H61: 0 | I61: 0 | J61: 0 | K61: 0 | L61: 0 | M61: 0 | N61: 0 | O61: 0 | P61: 0 | Q61: 0 | R61: 0 | S61: 0 | T61: 0 | U61: 0 | V61: 0 | W61: 0 | X61: 0 | Y61: 0 | Z61: 0 | AA61: 0 | AB61: 0 | AC61: 0 | AD61: 0 | AE61: 0 | AF61: 0 | AG61: 0 | AH61: 0 | AI61: 0 | AJ61: 0 | AK61: 0 | AL61: 0 | AM61: 0 | AN61: 0 | AO61: 0 | AP61: 0 | AQ61: 0 | AR61: 0 | AS61: 0 | AT61: 0 | AU61: 0 | AV61: 0 | AW61: 0 | AX61: 0 | AY61: 0 | AZ61: 0 | BA61: 0 | BB61: 0 | BC61: 0 | BD61: 0 | BE61: 0 | BF61: 0 | BG61: 0 | BH61: 0 | BI61: 0 | BJ61: 0 | BK61: 0 | BL61: 0 | BM61: 0 | BN61: 0 | BO61: 0 | BP61: 0 | BQ61: 0 | BR61: 0 | BS61: 0 | BT61: 0 | BU61: 0 | BV61: 0 | BW61: 0 | BX61: 0 | BY61: 0 | BZ61: 0 | CA61: 0 | CB61: 0 | CC61: 0

Sheet Not Used ->
A1: The sheets to the right are not used in the calculations leading to the blue output tabs.
A2: They are retained here for reference and possible future use.

Sheet EIA 2020 ESRAP Table 10
A1: 2020 Utility Bundled Sales to Ultimate Customers- Total
A2: (Data from forms EIA-861- schedules 4A & 4D and EIA-861S)
A3: Entity | B3: State | C3: Ownership | D3: Customers (Count) | E3: Sales (Megawatthours) | F3: Revenues (Thousands Dollars) | G3: Average Price (cents/kWh)
A4: Alaska Electric Light&Power Co | B4: AK | C4: Investor Owned | D4: 17403 | E4: 384981 | F4: 44688.6 | G4: 11.608001
A5: Alaska Power and Telephone Co | B5: AK | C5: Investor Owned | D5: 8168 | E5: 64407 | F5: 17068 | G5: 26.500225
A6: Alaska Village Elec Coop, Inc | B6: AK | C6: Cooperative | D6: 11513 | E6: 120835 | F6: 53906.3 | G6: 44.611495
A7: Anchorage Municipal Light and Power | B7: AK | C7: Municipal | D7: 31291 | E7: 732828 | F7: 121486.1 | G7: 16.57771
A8: Chugach Electric Assn Inc | B8: AK | C8: Cooperative | D8: 112593 | E8: 1212687 | F8: 226490.8 | G8: 18.676773
A9: Golden Valley Elec Assn Inc | B9: AK | C9: Cooperative | D9: 47059 | E9: 1221811 | F9: 236609 | G9: 19.365434
A10: Homer Electric Assn Inc | B10: AK | C10: Cooperative | D10: 32511 | E10: 437105 | F10: 103146.7 | G10: 23.597694
A11: Ketchikan Public Utilities | B11: AK | C11: Municipal | D11: 7856 | E11: 166832 | F11: 18488.7 | G11: 11.082226
A12: Kodiak Electric Assn Inc | B12: AK | C12: Cooperative | D12: 6086 | E12: 139401 | F12: 22998 | G12: 16.49773
A13: Kotzebue Electric Assn Inc | B13: AK | C13: Cooperative | D13: 1293 | E13: 18915 | F13: 7374.6 | G13: 38.988105
A14: Matanuska Electric Assn Inc | B14: AK | C14: Cooperative | D14: 66667 | E14: 751476 | F14: 153435.2 | G14: 20.417844
A15: TDX North Slope Generating Co | B15: AK | C15: Investor Owned | D15: 165 | E15: 53030 | F15: 11562 | G15: 21.802753
... A1371: MidAmerican Energy Services, LLC | B1371: TX | C1371: Retail Power Marketer | D1371: 15379 | E1371: 1999738 | F1371: 143170.7 | G1371: 7.1594729
A1372: Morgan Stanley Capital Grp Inc | B1372: TX | C1372: Retail Power Marketer | D1372: 1 | E1372: 0 | F1372: 20338 | G1372: .
A1373: Navarro County Elec Coop, Inc | B1373: TX | C1373: Cooperative | D1373: 17307 | E1373: 532085 | F1373: 40300.1 | G1373: 7.5739966
A1374: Navasota Valley Elec Coop, Inc | B1374: TX | C1374: Cooperative | D1374: 20147 | E1374: 369665 | F1374: 34610.7 | G1374: 9.3627203
A1375: NextEra Energy Services, LLC | B1375: TX | C1375: Retail Power Marketer | D1375: 276133 | E1375: 9802936 | F1375: 831334.9 | G1375: 8.4804685
A1376: North Plains Electric Coop Inc | B1376: TX | C1376: Cooperative | D1376: 7122 | E1376: 372752 | F1376: 32634 | G1376: 8.7548826
A1377: Nueces Electric Cooperative | B1377: TX | C1377: Cooperative | D1377: 44596 | E1377: 997403 | F1377: 89447 | G1377: 8.9679899
A1378: Our Energy LLC | B1378: TX | C1378: Retail Power Marketer | D1378: 62719 | E1378: 1500109 | F1378: 134502 | G1378: 8.9661485
A1379: Panola-Harrison Elec Coop, Inc | B1379: TX | C1379: Cooperative | D1379: 10806 | E1379: 199755 | F1379: 17688 | G1379: 8.8548472
A1380: Pedernales Electric Coop, Inc | B1380: TX | C1380: Cooperative | D1380: 379832 | E1380: 6533473 | F1380: 630919.9 | G1380: 9.6567308
A1381: Pogo Energy LLC | B1381: TX | C1381: Retail Power Marketer | D1381: 13647 | E1381: 162924 | F1381: 11194.6 | G1381: 6.8710564
A1382: Pro Power Providers | B1382: TX | C1382: Retail Power Marketer | D1382: 178 | E1382: 519 | F1382: 53.7 | G1382: 10.346821
A1383: Pulse Power, LLC | B1383: TX | C1383: Retail Power Marketer | D1383: 75356 | E1383: 1220110 | F1383: 128014 | G1383: 10.492005
A1384: Reliant Energy Retail Services | B1384: TX | C1384: Retail Power Marketer | D1384: 1404752 | E1384: 39602218 | F1384: 3880617.6 | G1384: 9.7989906
... A1619: Withheld | B1619: TX | C1619: Retail Power Marketer | D1619: 24 | E1619: 6454584 | F1619: 216095.6 | G1619: 3.34794
A1620: Adjustment 2020 | B1620: AK | C1620: Other | D1620: 35725 | E1620: 613269 | F1620: 155580.8 | G1620: .
A1621: Adjustment 2020 | B1621: AL | C1621: Other | D1621: 70418 | E1621: 1371994 | F1621: 153714.5 | G1621: .
A1622: Adjustment 2020 | B1622: AR | C1622: Other | D1622: 28612 | E1622: 606815 | F1622: 65621.9 | G1622: .
A1623: Adjustment 2020 | B1623: AZ | C1623: Other | D1623: -43153 | E1623: 1457512 | F1623: 123329.6 | G1623: .
A1624: Adjustment 2020 | B1624: CA | C1624: Other | D1624: -327155 | E1624: 1836367 | F1624: 273111.2 | G1624: .
A1625: Adjustment 2020 | B1625: CO | C1625: Other | D1625: 58520 | E1625: 1151881 | F1625: 159910.9 | G1625: .
A1626: Adjustment 2020 | B1626: CT | C1626: Other | D1626: -17583 | E1626: 291718 | F1626: 40488.7 | G1626: .
A1627: Adjustment 2020 | B1627: DC | C1627: Other | D1627: -536 | E1627: 0 | F1627: 0 | G1627: .
A1628: Adjustment 2020 | B1628: DE | C1628: Other | D1628: 14372 | E1628: 388579 | F1628: 44066.3 | G1628: .
A1629: Adjustment 2020 | B1629: FL | C1629: Other | D1629: 49950 | E1629: 1142488 | F1629: 131572.3 | G1629: .
...

Sheet BNL_RPS Targets (%)
C1: RPS Targets
M3: Contact: Galen Barbose
M4: Lawrence Berkeley National Laboratory
M5: (510) 495-2593, glbarbose@lbl.gov
M6: Last update: February 5, 2021
C24: RPS Targets (Percent of Applicable Retail Electricity Sales) | BE24: Search terms
C25: State | D25: Special Notes | E25: RPS Tier or Carve Out | F25: 2000 | G25: 2001 | H25: 2002 | I25: 2003 | J25: 2004 | K25: 2005 | L25: 2006 | M25: 2007 | N25: 2008 | O25: 2009 | P25: 2010 | Q25: 2011 | R25: 2012 | S25: 2013 | T25: 2014 | U25: 2015 | V25: 2016 | W25: 2017 | X25: 2018 | Y25: 2019 | Z25: 2020 | AA25: 2021 | AB25: 2022 | AC25: 2023 | AD25: 2024 | AE25: 2025 | AF25: 2026 | AG25: 2027 | AH25: 2028 | AI25: 2029 | AJ25: 2030 | AK25: 2031 | AL25: 2032 | AM25: 2033 | AN25: 2034 | AO25: 2035 | AP25: 2036 | AQ25: 2037 | AR25: 2038 | AS25: 2039 | AT25: 2040 | AU25: 2041 | AV25: 2042 | AW25: 2043 | AX25: 2044 | AY25: 2045 | AZ25: 2046 | BA25: 2047 | BB25: 2048 | BC25: 2049 | BD25: 2050 | BE25: State | BF25: Tier
A26: =IF(E26="Total RPS",1,0)+IF(E26="Total RPS (Wtd. Avg.)",1,0) -> 1 | B26: =INDEX(#REF!,MATCH('BNL_RPS Targets (%)'!C26,#REF!,0)) -> #REF! | C26: AZ | D26: Arizona had a solar carve-out, which was subsequently replaced by the current DG carve-out in 2008. | E26: Total RPS | F26: 0 | G26: 0.002 | H26: 0.004 | I26: 0.006 | J26: 0.008 | K26: 0.01 | L26: 0.0125 | M26: 0.015 | N26: 0.0175 | O26: 0.02 | P26: 0.025 | Q26: 0.03 | R26: 0.035 | S26: 0.04 | T26: 0.045 | U26: 0.05 | V26: 0.06 | W26: 0.07 | X26: 0.08 | Y26: 0.09 | Z26: 0.1 | AA26: 0.11 | AB26: 0.12 | AC26: 0.13 | AD26: 0.14 | AE26: 0.15 | AF26: 0.15 | AG26: 0.15 | AH26: 0.15 | AI26: 0.15 | AJ26: 0.15 | AK26: 0.15 | AL26: 0.15 | AM26: 0.15 | AN26: 0.15 | AO26: 0.15 | AP26: 0.15 | AQ26: 0.15 | AR26: 0.15 | AS26: 0.15 | AT26: 0.15 | AU26: 0.15 | AV26: 0.15 | AW26: 0.15 | AX26: 0.15 | AY26: 0.15 | AZ26: 0.15 | BA26: 0.15 | BB26: 0.15 | BC26: 0.15 | BD26: 0.15 | BE26: AZ | BF26: Total RPS
A27: =IF(E27="Total RPS",1,0)+IF(E27="Total RPS (Wtd. Avg.)",1,0) -> 0 | B27: =INDEX(#REF!,MATCH('BNL_RPS Targets (%)'!C27,#REF!,0)) -> #REF! | C27: AZ | E27: DG Carve-Out | F27: 0 | G27: 0 | H27: 0 | I27: 0 | J27: 0 | K27: 0 | L27: 0 | M27: 0 | N27: 0.00175 | O27: 0.003 | P27: 0.005 | Q27: 0.0075 | R27: 0.0105 | S27: 0.012 | T27: 0.0135 | U27: 0.015 | V27: 0.018 | W27: 0.021 | X27: 0.024 | Y27: 0.027 | Z27: 0.03 | AA27: 0.033 | AB27: 0.036 | AC27: 0.039 | AD27: 0.042 | AE27: 0.045 | AF27: 0.045 | AG27: 0.045 | AH27: 0.045 | AI27: 0.045 | AJ27: 0.045 | AK27: 0.045 | AL27: 0.045 | AM27: 0.045 | AN27: 0.045 | AO27: 0.045 | AP27: 0.045 | AQ27: 0.045 | AR27: 0.045 | AS27: 0.045 | AT27: 0.045 | AU27: 0.045 | AV27: 0.045 | AW27: 0.045 | AX27: 0.045 | AY27: 0.045 | AZ27: 0.045 | BA27: 0.045 | BB27: 0.045 | BC27: 0.045 | BD27: 0.045 | BE27: AZ | BF27: Solar or DG Carve-Out
A28: =IF(E28="Total RPS",1,0)+IF(E28="Total RPS (Wtd. Avg.)",1,0) -> 1 | B28: =INDEX(#REF!,MATCH('BNL_RPS Targets (%)'!C28,#REF!,0)) -> #REF! | C28: CA | D28: Through 2015, the values shown here represent targets for the state's three large IOUs through 2015 (targets for other utilities' were lower). From 2016 onward, the values shown here represent statewide targets applicable to all utilities. | E28: Total RPS | F28: 0 | G28: 0 | H28: 0 | I28: 0.11852494 | J28: 0.12852494 | K28: 0.13852494 | L28: 0.14852494 | M28: 0.15852494 | N28: 0.16852494 | O28: 0.17852494 | P28: 0.2 | Q28: 0.2 | R28: 0.2 | S28: 0.2 | T28: 0.217 | U28: 0.233 | V28: 0.25 | W28: 0.27 | X28: 0.29 | Y28: 0.31 | Z28: 0.33 | AA28: 0.33 | AB28: 0.33 | AC28: 0.33 | AD28: 0.44 | AE28: 0.44 | AF28: 0.44 | AG28: 0.52 | AH28: 0.52 | AI28: 0.52 | AJ28: 0.6 | AK28: 0.6 | AL28: 0.6 | AM28: 0.6 | AN28: 0.6 | AO28: 0.6 | AP28: 0.6 | AQ28: 0.6 | AR28: 0.6 | AS28: 0.6 | AT28: 0.6 | AU28: 0.6 | AV28: 0.6 | AW28: 0.6 | AX28: 0.6 | AY28: 0.6 | AZ28: 0.6 | BA28: 0.6 | BB28: 0.6 | BC28: 0.6 | BD28: 0.6 | BE28: CA | BF28: Total RPS
A29: =IF(E29="Total RPS",1,0)+IF(E29="Total RPS (Wtd. Avg.)",1,0) -> 1 | B29: =INDEX(#REF!,MATCH('BNL_RPS Targets (%)'!C29,#REF!,0)) -> #REF! | C29: CO | D29: Targets vary based on utility type and size, and whether the utility is served by a generation and transmission (G&T) cooperative. Weighted averages are based on the retail electricity sales of utilities subject to the RPS. | E29: Total RPS (Wtd. Avg.) | F29: 0 | G29: 0 | H29: 0 | I29: 0 | J29: 0 | K29: 0 | L29: 0 | M29: 0.03 | N29: 0.034567782 | O29: 0.034261979 | P29: 0.034203742 | Q29: 0.08435376 | R29: 0.084921879 | S29: 0.085100327 | T29: 0.084973227 | U29: 0.14498606 | V29: 0.144233 | W29: 0.14368257 | X29: 0.14191418 | Y29: 0.14191418 | Z29: 0.2410564 | AA29: 0.2410564 | AB29: 0.2410564 | AC29: 0.23922197 | AD29: 0.23922197 | AE29: 0.23922197 | AF29: 0.23922197 | AG29: 0.23922197 | AH29: 0.23922197 | AI29: 0.23922197 | AJ29: 0.23922197 | AK29: 0.23922197 | AL29: 0.23922197 | AM29: 0.23922197 | AN29: 0.23922197 | AO29: 0.23922197 | AP29: 0.23922197 | AQ29: 0.23922197 | AR29: 0.23922197 | AS29: 0.23922197 | AT29: 0.23922197 | AU29: 0.23922197 | AV29: 0.23922197 | AW29: 0.23922197 | AX29: 0.23922197 | AY29: 0.23922197 | AZ29: 0.23922197 | BA29: 0.23922197 | BB29: 0.23922197 | BC29: 0.23922197 | BD29: 0.23922197 | BE29: CO | BF29: Total RPS
A30: =IF(E30="Total RPS",1,0)+IF(E30="Total RPS (Wtd. Avg.)",1,0) -> 0 | B30: =INDEX(#REF!,MATCH('BNL_RPS Targets (%)'!C30,#REF!,0)) -> #REF! | C30: CO | E30: IOUs | F30: 0 | G30: 0 | H30: 0 | I30: 0 | J30: 0 | K30: 0 | L30: 0 | M30: 0.03 | N30: 0.05 | O30: 0.05 | P30: 0.05 | Q30: 0.12 | R30: 0.12 | S30: 0.12 | T30: 0.12 | U30: 0.2 | V30: 0.2 | W30: 0.2 | X30: 0.2 | Y30: 0.2 | Z30: 0.3 | AA30: 0.3 | AB30: 0.3 | AC30: 0.3 | AD30: 0.3 | AE30: 0.3 | AF30: 0.3 | AG30: 0.3 | AH30: 0.3 | AI30: 0.3 | AJ30: 0.3 | AK30: 0.3 | AL30: 0.3 | AM30: 0.3 | AN30: 0.3 | AO30: 0.3 | AP30: 0.3 | AQ30: 0.3 | AR30: 0.3 | AS30: 0.3 | AT30: 0.3 | AU30: 0.3 | AV30: 0.3 | AW30: 0.3 | AX30: 0.3 | AY30: 0.3 | AZ30: 0.3 | BA30: 0.3 | BB30: 0.3 | BC30: 0.3 | BD30: 0.3 | BE30: CO
A31: =IF(E31="Total RPS",1,0)+IF(E31="Total RPS (Wtd. Avg.)",1,0) -> 0 | B31: =INDEX(#REF!,MATCH('BNL_RPS Targets (%)'!C31,#REF!,0)) -> #REF! | C31: CO | E31: Coops (G&T-served or >100k customers) | F31: 0 | G31: 0 | H31: 0 | I31: 0 | J31: 0 | K31: 0 | L31: 0 | M31: 0 | N31: 0.01 | O31: 0.01 | P31: 0.01 | Q31: 0.03 | R31: 0.03 | S31: 0.03 | T31: 0.03 | U31: 0.06 | V31: 0.06 | W31: 0.06 | X31: 0.06 | Y31: 0.06 | Z31: 0.2 | AA31: 0.2 | AB31: 0.2 | AC31: 0.2 | AD31: 0.2 | AE31: 0.2 | AF31: 0.2 | AG31: 0.2 | AH31: 0.2 | AI31: 0.2 | AJ31: 0.2 | AK31: 0.2 | AL31: 0.2 | AM31: 0.2 | AN31: 0.2 | AO31: 0.2 | AP31: 0.2 | AQ31: 0.2 | AR31: 0.2 | AS31: 0.2 | AT31: 0.2 | AU31: 0.2 | AV31: 0.2 | AW31: 0.2 | AX31: 0.2 | AY31: 0.2 | AZ31: 0.2 | BA31: 0.2 | BB31: 0.2 | BC31: 0.2 | BD31: 0.2 | BE31: CO
A32: =IF(E32="Total RPS",1,0)+IF(E32="Total RPS (Wtd. Avg.)",1,0) -> 0 | B32: =INDEX(#REF!,MATCH('BNL_RPS Targets (%)'!C32,#REF!,0)) -> #REF! | C32: CO | E32: Munis & Non-G&T served Coops with <100k customers) | F32: 0 | G32: 0 | H32: 0 | I32: 0 | J32: 0 | K32: 0 | L32: 0 | M32: 0 | N32: 0.01 | O32: 0.01 | P32: 0.01 | Q32: 0.03 | R32: 0.03 | S32: 0.03 | T32: 0.03 | U32: 0.06 | V32: 0.06 | W32: 0.06 | X32: 0.06 | Y32: 0.06 | Z32: 0.1 | AA32: 0.1 | AB32: 0.1 | AC32: 0.1 | AD32: 0.1 | AE32: 0.1 | AF32: 0.1 | AG32: 0.1 | AH32: 0.1 | AI32: 0.1 | AJ32: 0.1 | AK32: 0.1 | AL32: 0.1 | AM32: 0.1 | AN32: 0.1 | AO32: 0.1 | AP32: 0.1 | AQ32: 0.1 | AR32: 0.1 | AS32: 0.1 | AT32: 0.1 | AU32: 0.1 | AV32: 0.1 | AW32: 0.1 | AX32: 0.1 | AY32: 0.1 | AZ32: 0.1 | BA32: 0.1 | BB32: 0.1 | BC32: 0.1 | BD32: 0.1 | BE32: CO
A33: =IF(E33="Total RPS",1,0)+IF(E33="Total RPS (Wtd. Avg.)",1,0) -> 0 | B33: =INDEX(#REF!,MATCH('BNL_RPS Targets (%)'!C33,#REF!,0)) -> #REF! | C33: CO | E33: DG Carve-Out (Wtd. Avg.) | F33: 0 | G33: 0 | H33: 0 | I33: 0 | J33: 0 | K33: 0 | L33: 0 | M33: 0 | N33: 0 | O33: 0 | P33: 0 | Q33: 0.0060393067 | R33: 0.0061024311 | S33: 0.0076528231 | T33: 0.0076351704 | U33: 0.010623257 | V33: 0.010529125 | W33: 0.011954652 | X33: 0.011702025 | Y33: 0.011702025 | Z33: 0.019456432 | AA33: 0.019456432 | AB33: 0.019456432 | AC33: 0.019203402 | AD33: 0.019203402 | AE33: 0.019203402 | AF33: 0.019203402 | AG33: 0.019203402 | AH33: 0.019203402 | AI33: 0.019203402 | AJ33: 0.019203402 | AK33: 0.019203402 | AL33: 0.019203402 | AM33: 0.019203402 | AN33: 0.019203402 | AO33: 0.019203402 | AP33: 0.019203402 | AQ33: 0.019203402 | AR33: 0.019203402 | AS33: 0.019203402 | AT33: 0.019203402 | AU33: 0.019203402 | AV33: 0.019203402 | AW33: 0.019203402 | AX33: 0.019203402 | AY33: 0.019203402 | AZ33: 0.019203402 | BA33: 0.019203402 | BB33: 0.019203402 | BC33: 0.019203402 | BD33: 0.019203402 | BE33: CO | BF33: Solar or DG Carve-Out
A34: =IF(E34="Total RPS",1,0)+IF(E34="Total RPS (Wtd. Avg.)",1,0) -> 0 | B34: =INDEX(#REF!,MATCH('BNL_RPS Targets (%)'!C34,#REF!,0)) -> #REF! | C34: CO | E34: IOUs | F34: 0 | G34: 0 | H34: 0 | I34: 0 | J34: 0 | K34: 0 | L34: 0 | M34: 0 | N34: 0 | O34: 0 | P34: 0 | Q34: 0.01 | R34: 0.01 | S34: 0.0125 | T34: 0.0125 | U34: 0.0175 | V34: 0.0175 | W34: 0.02 | X34: 0.02 | Y34: 0.02 | Z34: 0.03 | AA34: 0.03 | AB34: 0.03 | AC34: 0.03 | AD34: 0.03 | AE34: 0.03 | AF34: 0.03 | AG34: 0.03 | AH34: 0.03 | AI34: 0.03 | AJ34: 0.03 | AK34: 0.03 | AL34: 0.03 | AM34: 0.03 | AN34: 0.03 | AO34: 0.03 | AP34: 0.03 | AQ34: 0.03 | AR34: 0.03 | AS34: 0.03 | AT34: 0.03 | AU34: 0.03 | AV34: 0.03 | AW34: 0.03 | AX34: 0.03 | AY34: 0.03 | AZ34: 0.03 | BA34: 0.03 | BB34: 0.03 | BC34: 0.03 | BD34: 0.03 | BE34: CO
A35: =IF(E35="Total RPS",1,0)+IF(E35="Total RPS (Wtd. Avg.)",1,0) -> 0 | B35: =INDEX(#REF!,MATCH('BNL_RPS Targets (%)'!C35,#REF!,0)) -> #REF! | C35: CO | E35: Coops (>10k customers) | F35: 0 | G35: 0 | H35: 0 | I35: 0 | J35: 0 | K35: 0 | L35: 0 | M35: 0 | N35: 0 | O35: 0 | P35: 0 | Q35: 0 | R35: 0 | S35: 0 | T35: 0 | U35: 0 | V35: 0 | W35: 0 | X35: 0 | Y35: 0 | Z35: 0.01 | AA35: 0.01 | AB35: 0.01 | AC35: 0.01 | AD35: 0.01 | AE35: 0.01 | AF35: 0.01 | AG35: 0.01 | AH35: 0.01 | AI35: 0.01 | AJ35: 0.01 | AK35: 0.01 | AL35: 0.01 | AM35: 0.01 | AN35: 0.01 | AO35: 0.01 | AP35: 0.01 | AQ35: 0.01 | AR35: 0.01 | AS35: 0.01 | AT35: 0.01 | AU35: 0.01 | AV35: 0.01 | AW35: 0.01 | AX35: 0.01 | AY35: 0.01 | AZ35: 0.01 | BA35: 0.01 | BB35: 0.01 | BC35: 0.01 | BD35: 0.01 | BE35: CO
A36: =IF(E36="Total RPS",1,0)+IF(E36="Total RPS (Wtd. Avg.)",1,0) -> 0 | B36: =INDEX(#REF!,MATCH('BNL_RPS Targets (%)'!C36,#REF!,0)) -> #REF! | C36: CO | E36: Coops (<10k customers) | F36: 0 | G36: 0 | H36: 0 | I36: 0 | J36: 0 | K36: 0 | L36: 0 | M36: 0 | N36: 0 | O36: 0 | P36: 0 | Q36: 0 | R36: 0 | S36: 0 | T36: 0 | U36: 0 | V36: 0 | W36: 0 | X36: 0 | Y36: 0 | Z36: 0.0075 | AA36: 0.0075 | AB36: 0.0075 | AC36: 0.0075 | AD36: 0.0075 | AE36: 0.0075 | AF36: 0.0075 | AG36: 0.0075 | AH36: 0.0075 | AI36: 0.0075 | AJ36: 0.0075 | AK36: 0.0075 | AL36: 0.0075 | AM36: 0.0075 | AN36: 0.0075 | AO36: 0.0075 | AP36: 0.0075 | AQ36: 0.0075 | AR36: 0.0075 | AS36: 0.0075 | AT36: 0.0075 | AU36: 0.0075 | AV36: 0.0075 | AW36: 0.0075 | AX36: 0.0075 | AY36: 0.0075 | AZ36: 0.0075 | BA36: 0.0075 | BB36: 0.0075 | BC36: 0.0075 | BD36: 0.0075 | BE36: CO
A37: =IF(E37="Total RPS",1,0)+IF(E37="Total RPS (Wtd. Avg.)",1,0) -> 1 | B37: =INDEX(#REF!,MATCH('BNL_RPS Targets (%)'!C37,#REF!,0)) -> #REF! | C37: CT | D37: None | E37: Total RPS | F37: 0 | G37: 0.0625 | H37: 0.065 | I37: 0.07 | J37: 0.04 | K37: 0.045 | L37: 0.05 | M37: 0.065 | N37: 0.08 | O37: 0.09 | P37: 0.1 | Q37: 0.11 | R37: 0.12 | S37: 0.13 | T37: 0.14 | U37: 0.155 | V37: 0.17 | W37: 0.185 | X37: 0.21 | Y37: 0.235 | Z37: 0.25 | AA37: 0.265 | AB37: 0.28 | AC37: 0.3 | AD37: 0.32 | AE37: 0.34 | AF37: 0.36 | AG37: 0.38 | AH37: 0.4 | AI37: 0.42 | AJ37: 0.44 | AK37: 0.44 | AL37: 0.44 | AM37: 0.44 | AN37: 0.44 | AO37: 0.44 | AP37: 0.44 | AQ37: 0.44 | AR37: 0.44 | AS37: 0.44 | AT37: 0.44 | AU37: 0.44 | AV37: 0.44 | AW37: 0.44 | AX37: 0.44 | AY37: 0.44 | AZ37: 0.44 | BA37: 0.44 | BB37: 0.44 | BC37: 0.44 | BD37: 0.44 | BE37: CT | BF37: Total RPS
A38: =IF(E38="Total RPS",1,0)+IF(E38="Total RPS (Wtd. Avg.)",1,0) -> 0 | B38: =INDEX(#REF!,MATCH('BNL_RPS Targets (%)'!C38,#REF!,0)) -> #REF! | C38: CT | E38: Class I | F38: 0 | G38: 0.0075 | H38: 0.01 | I38: 0.015 | J38: 0.01 | K38: 0.015 | L38: 0.02 | M38: 0.035 | N38: 0.05 | O38: 0.06 | P38: 0.07 | Q38: 0.08 | R38: 0.09 | S38: 0.1 | T38: 0.11 | U38: 0.125 | V38: 0.14 | W38: 0.155 | X38: 0.17 | Y38: 0.195 | Z38: 0.21 | AA38: 0.225 | AB38: 0.24 | AC38: 0.26 | AD38: 0.28 | AE38: 0.3 | AF38: 0.32 | AG38: 0.34 | AH38: 0.36 | AI38: 0.38 | AJ38: 0.4 | AK38: 0.4 | AL38: 0.4 | AM38: 0.4 | AN38: 0.4 | AO38: 0.4 | AP38: 0.4 | AQ38: 0.4 | AR38: 0.4 | AS38: 0.4 | AT38: 0.4 | AU38: 0.4 | AV38: 0.4 | AW38: 0.4 | AX38: 0.4 | AY38: 0.4 | AZ38: 0.4 | BA38: 0.4 | BB38: 0.4 | BC38: 0.4 | BD38: 0.4 | BE38: CT | BF38: General RPS/Primary Tier
A39: =IF(E39="Total RPS",1,0)+IF(E39="Total RPS (Wtd. Avg.)",1,0) -> 0 | B39: =INDEX(#REF!,MATCH('BNL_RPS Targets (%)'!C39,#REF!,0)) -> #REF! | C39: CT | E39: Class II | F39: 0 | G39: 0.055 | H39: 0.055 | I39: 0.055 | J39: 0.03 | K39: 0.03 | L39: 0.03 | M39: 0.03 | N39: 0.03 | O39: 0.03 | P39: 0.03 | Q39: 0.03 | R39: 0.03 | S39: 0.03 | T39: 0.03 | U39: 0.03 | V39: 0.03 | W39: 0.03 | X39: 0.04 | Y39: 0.04 | Z39: 0.04 | AA39: 0.04 | AB39: 0.04 | AC39: 0.04 | AD39: 0.04 | AE39: 0.04 | AF39: 0.04 | AG39: 0.04 | AH39: 0.04 | AI39: 0.04 | AJ39: 0.04 | AK39: 0.04 | AL39: 0.04 | AM39: 0.04 | AN39: 0.04 | AO39: 0.04 | AP39: 0.04 | AQ39: 0.04 | AR39: 0.04 | AS39: 0.04 | AT39: 0.04 | AU39: 0.04 | AV39: 0.04 | AW39: 0.04 | AX39: 0.04 | AY39: 0.04 | AZ39: 0.04 | BA39: 0.04 | BB39: 0.04 | BC39: 0.04 | BD39: 0.04 | BE39: CT | BF39: Secondary Tier
A40: =IF(E40="Total RPS",1,0)+IF(E40="Total RPS (Wtd. Avg.)",1,0) -> 1 | B40: =INDEX(#REF!,MATCH('BNL_RPS Targets (%)'!C40,#REF!,0)) -> #REF! | C40: DC | D40: None | E40: Total RPS | F40: 0 | G40: 0 | H40: 0 | I40: 0 | J40: 0 | K40: 0 | L40: 0 | M40: 0.04 | N40: 0.045 | O40: 0.05 | P40: 0.055 | Q40: 0.065 | R40: 0.075 | S40: 0.09 | T40: 0.105 | U40: 0.12 | V40: 0.135 | W40: 0.15 | X40: 0.165 | Y40: 0.18 | Z40: 0.2 | AA40: 0.2625 | AB40: 0.325 | AC40: 0.3875 | AD40: 0.45 | AE40: 0.52 | AF40: 0.59 | AG40: 0.66 | AH40: 0.73 | AI40: 0.8 | AJ40: 0.87 | AK40: 0.94 | AL40: 1 | AM40: 1 | AN40: 1 | AO40: 1 | AP40: 1 | AQ40: 1 | AR40: 1 | AS40: 1 | AT40: 1 | AU40: 1 | AV40: 1 | AW40: 1 | AX40: 1 | AY40: 1 | AZ40: 1 | BA40: 1 | BB40: 1 | BC40: 1 | BD40: 1 | BE40: DC | BF40: Total RPS
A41: =IF(E41="Total RPS",1,0)+IF(E41="Total RPS (Wtd. Avg.)",1,0) -> 0 | B41: =INDEX(#REF!,MATCH('BNL_RPS Targets (%)'!C41,#REF!,0)) -> #REF! | C41: DC | E41: Solar Carve-Out | F41: 0 | G41: 0 | H41: 0 | I41: 0 | J41: 0 | K41: 0 | L41: 0 | M41: 0.0005 | N41: 0.0011 | O41: 0.0019 | P41: 0.0028 | Q41: 0.004 | R41: 0.005 | S41: 0.005 | T41: 0.006 | U41: 0.007 | V41: 0.0083 | W41: 0.0098 | X41: 0.0115 | Y41: 0.0185 | Z41: 0.02175 | AA41: 0.025 | AB41: 0.026 | AC41: 0.0285 | AD41: 0.0315 | AE41: 0.0345 | AF41: 0.0375 | AG41: 0.041 | AH41: 0.045 | AI41: 0.0475 | AJ41: 0.05 | AK41: 0.0525 | AL41: 0.055 | AM41: 0.06 | AN41: 0.065 | AO41: 0.07 | AP41: 0.075 | AQ41: 0.08 | AR41: 0.085 | AS41: 0.09 | AT41: 0.095 | AU41: 0.1 | AV41: 0.1 | AW41: 0.1 | AX41: 0.1 | AY41: 0.1 | AZ41: 0.1 | BA41: 0.1 | BB41: 0.1 | BC41: 0.1 | BD41: 0.1 | BE41: DC | BF41: Solar or DG Carve-Out
A42: =IF(E42="Total RPS",1,0)+IF(E42="Total RPS (Wtd. Avg.)",1,0) -> 0 | B42: =INDEX(#REF!,MATCH('BNL_RPS Targets (%)'!C42,#REF!,0)) -> #REF! | C42: DC | E42: Tier I Non-Solar | F42: 0 | G42: 0 | H42: 0 | I42: 0 | J42: 0 | K42: 0 | L42: 0 | M42: 0.0145 | N42: 0.0189 | O42: 0.0231 | P42: 0.0272 | Q42: 0.036 | R42: 0.045 | S42: 0.06 | T42: 0.074 | U42: 0.088 | V42: 0.1067 | W42: 0.1252 | X42: 0.1435 | Y42: 0.1565 | Z42: 0.17825 | AA42: 0.2375 | AB42: 0.299 | AC42: 0.359 | AD42: 0.4185 | AE42: 0.4855 | AF42: 0.5525 | AG42: 0.619 | AH42: 0.685 | AI42: 0.7525 | AJ42: 0.82 | AK42: 0.8875 | AL42: 0.945 | AM42: 0.94 | AN42: 0.935 | AO42: 0.93 | AP42: 0.925 | AQ42: 0.92 | AR42: 0.915 | AS42: 0.91 | AT42: 0.905 | AU42: 0.9 | AV42: 0.9 | AW42: 0.9 | AX42: 0.9 | AY42: 0.9 | AZ42: 0.9 | BA42: 0.9 | BB42: 0.9 | BC42: 0.9 | BD42: 0.9 | BE42: DC | BF42: General RPS/Primary Tier
