Workbook
Name dollars_2019_2012: [1]About!$A$99
Name dollars_2019_2012: About!$A$254
Name gal_per_barrel: [2]About!$A$40
Name lignite_multiplier: #REF!
Name lignite_multiplier: #REF!
Name lignite_multiplier: #REF!
Name lignite_multiplier: #REF!
Name lignite_multiplier: #REF!
Name lignite_multiplier: #REF!
Name lignite_multiplier: #REF!
Name lignite_multiplier: #REF!
Name lignite_multiplier: #REF!
Name lignite_multiplier: '[1]Hard Coal and Lig Multipliers'!$N$15
Name lignite_multiplier: #REF!
Name lignite_multiplier: #REF!
Name lignite_multiplier: #REF!
Name lignite_multiplier: #REF!
Name lignite_multiplier: #REF!
Name lignite_multiplier: #REF!
Name lignite_multiplier: #REF!
Name lignite_multiplier: #REF!
Name lignite_multiplier: #REF!
Name lignite_multiplier: #REF!
Name nonlignite_multiplier: #REF!
Name nonlignite_multiplier: #REF!
Name nonlignite_multiplier: #REF!
Name nonlignite_multiplier: #REF!
Name nonlignite_multiplier: #REF!
Name nonlignite_multiplier: #REF!
Name nonlignite_multiplier: #REF!
Name nonlignite_multiplier: #REF!
Name nonlignite_multiplier: #REF!
Name nonlignite_multiplier: '[1]Hard Coal and Lig Multipliers'!$N$16
Name nonlignite_multiplier: #REF!
Name nonlignite_multiplier: #REF!
Name nonlignite_multiplier: #REF!
Name nonlignite_multiplier: #REF!
Name nonlignite_multiplier: #REF!
Name nonlignite_multiplier: #REF!
Name nonlignite_multiplier: #REF!
Name nonlignite_multiplier: #REF!
Name nonlignite_multiplier: #REF!
Name nonlignite_multiplier: #REF!
Name tax_fuel_labels: 'Tax_Share of Price'!$A$2:$A$22
Name Tax_share: 'Tax_Share of Price'!$B$2:$AI$22

Sheet About
A1: BFPaT BAU Pretax Fuel Price by Sector
A2: BFPaT BAU Fuel Tax by Sector
A4: Sources: | B4: Prices
B6: Electricity Price | D6: hydrogen start year costs
B7: Central Electricity Authority | D7: California Energy Commission and California Air Resources Board
B8: 2022 | D8: 2015
B9: Electricity Tariff & Duty & Average Rates of Electricity Supply in India | D9: Assessment of Time and Cost Needed to Attain 100 Hydrogen Refueling Stations in California
B10: Cover 3rd book 2023 FINAL.cdr (cea.nic.in) | D10: https://ww2.energy.ca.gov/2015publications/CEC-600-2015-016/CEC-600-2015-016.pdf
D11: Page 57, Table 12
B13: 2014 Coal Price | D13: hydrogen future costs
B14: Planning Commission, Government of India | D14: Bloomberg New Energy Finance
B15: 2014 | D15: 2020
B16: Annual Report (2013-14) on the Working of State Power Utilities & Electricity Departments | D16: Hydrogen Economy Outlook: Key Messages
B17: http://planningcommission.nic.in/reports/genrep/rep_arpower0306.pdf | D17: https://data.bloomberglp.com/professional/sites/24/BNEF-Hydrogen-Economy-Outlook-Key-Messages-30-Mar-2020.pdf
B18: Annex 4.8 and 4.10 | D18: Page 5
B20: Coal and Lignite Price Scaling Factors to Start Year | D20: Industry-wise consumption of Coal & Lignite in India
B21: Ministry of Coal, Government of India | D21: Ministry of Statistics and Programme Implementation
B22: 2019 | D22: 2019
B23: Coal Statistics | D23: Energy Statistics
B24: http://www.coalcontroller.gov.in/writereaddata/files/download/coaldirectory/CoalDirectory2019-20.pdf | D24: http://www.mospi.gov.in/sites/default/files/publication_reports/Energy%20Statistics%202019-finall.pdf
B25: Section VI, Page 6.1 (Statement 6.1) & Page 6.2 (Table 6.1) | D25: Tables 6.4, 6.5; pp 62-63
B27: Kerosene, LPG, Kerosene, Prices | D27: NE states population for weighting Nat Gas price
B28: Ministry of Petroleum and Natural Gas | D28: Census of India - Demographics
B29: 2021 | D29: 2011
B30: Indian Petroleum and Natural Gas Statistics, 2021-22 | D30: Indiastat Database
D31: https://www.indiastat.com/
B32: Nat Gas - Table IV.1 (Page 71), LPG&Kerosene - Table IV.11 (Page 78), | D32: Table: State-wise Total Population by Residence and Sex in India
B34: Start Year Natural Gas Prices and Imported Coal Price
B35: IEA
B36: 2021
B37: India Energy Outlook 2021
B38: https://iea.blob.core.windows.net/assets/1de6d91e-e23f-4e02-b1fb-51fdd6283b22/India_Energy_Outlook_2021.pdf
B39: page 139 and Figure 3.15
B41: Standing Committee on Energy
B42: Stressed/Non-Performing Assets in Gas based Power Plants
B43: 2019
B44: http://164.100.47.193/lsscommittee/Energy/16_Energy_42.pdf
B45: Table 3.11
B47: Jet Fuel Prices | D47: Communication on Kerosene price increase
B48: IndianOil | D48: Public Information Bureau
...

Sheet Tax Data>

Sheet Petroleum & Diesel Prices
A1: 23. Information on Prices, Taxes and Under-recoveries/Subsidies
A2: Price buildup of petroleum products (Rs./litre/Cylinder)
A3: Particulars | B3: Petrol | C3: Diesel
A4: Price charged to dealers (excluding Excise Duty and VAT) | B4: 48.23 | C4: 49.61
A5: Excise Duty | B5: 27.9 | C5: 21.8 | D5: |
A6: Dealer Commission (Average) | B6: 3.78 | C6: 2.55 | D6: |<-- Tax component
A7: VAT (incl VAT on dealer commission) | B7: 15.5 | C7: 12.68 | D7: |
A8: Retail selling price (RSP) -RoundedFO | B8: 95.41 | C8: 86.67
A9: Tax percentage | B9: =SUM(B5:B7)/B8 -> 0.49449743 | C9: =SUM(C5:C7)/C8 -> 0.4272528
A11: Source: Snapshot of India's Oil & Gas Data, Dec 2021 (PPAC)
A12: Table 23, Page 18
A14: Note: We include Excise Duty and Dealer commission as it is passed on to the consumer in the final retail price

Sheet Tax Rates
A1: VII.3 Sales tax rates applicable on crude oil, natural gas and petroleum products (Contd...) | I1: (Excerpt for Crude Oil, Natural Gas and ATF (Bonded))
A2: (As on 01.04.2022)
A3: (in Percentage)
A4: State/U.T | B4: Crude Oil | C4: Natural Gas | D4: MS (Petrol) | E4: Branded Petrol | F4: HSD (Diesel) | G4: Branded Diesel | H4: Naphtha | I4: LPG(Domestic) | J4: LPG (Non Dom) | K4: AUTO LPG | L4: SKO (PDS) | M4: SKO(IND) | N4: FO | O4: LSHS | P4: ATF (Duty Paid/ Bonded) | Q4: ATF Declared | R4: ATF (When Sold to Aircraft having maximum take off mass of < 40000 Kgs, operated by scheduled airlines) i.e. declared goods under CST Act | S4: BITUMEN | T4: LDO | U4: LUBE | V4: SULPHUR | W4: ASPHALT | Y4: ATF Consumption | Z4: NG Consumption
A5: -1 | B5: -2 | C5: -3 | D5: -4 | E5: -5 | F5: -6 | G5: -7 | H5: -8 | I5: -9 | J5: -10 | K5: -11 | L5: -12 | M5: -13 | N5: -14 | O5: -15 | P5: -16 | Q5: -17 | R5: -18 | S5: -19 | T5: -20 | U5: -21 | V5: -22 | W5: -23
A6: Andhra Pradesh | B6: 0.05 | C6: 0.245 | P6: 0.01 | X6: =A6 -> Andhra Pradesh | Y6: =IFERROR(INDEX('Petroleum Products Consumption'!$F$5:$F$40,MATCH('Tax Rates'!A6,'Petroleum Products Consumption'!$A$5:$A$40,0),1),0) -> 58.1 | Z6: =SUMIFS('NG Sales'!$H$6:$H$74,'NG Sales'!$I$6:$I$74,'Tax Rates'!A6,'NG Sales'!$A$6:$A$74,"Net Production (sales)") -> 743.76
A7: Arunachal Pradesh | B7: 0.04 | C7: 0.2 | P7: 0.2 | X7: =A7 -> Arunachal Pradesh | Y7: =IFERROR(INDEX('Petroleum Products Consumption'!$F$5:$F$40,MATCH('Tax Rates'!A7,'Petroleum Products Consumption'!$A$5:$A$40,0),1),0) -> 1.5 | Z7: =SUMIFS('NG Sales'!$H$6:$H$74,'NG Sales'!$I$6:$I$74,'Tax Rates'!A7,'NG Sales'!$A$6:$A$74,"Net Production (sales)") -> 0
A8: Assam | B8: 0.05 | C8: 0.145 | P8: 0.2365 | X8: =A8 -> Assam | Y8: =IFERROR(INDEX('Petroleum Products Consumption'!$F$5:$F$40,MATCH('Tax Rates'!A8,'Petroleum Products Consumption'!$A$5:$A$40,0),1),0) -> 122.6 | Z8: =SUMIFS('NG Sales'!$H$6:$H$74,'NG Sales'!$I$6:$I$74,'Tax Rates'!A8,'NG Sales'!$A$6:$A$74,"Net Production (sales)") -> 2486.43
A9: Bihar | B9: 0.06 | C9: 0.2 | P9: 0.29 | X9: =A9 -> Bihar | Y9: =IFERROR(INDEX('Petroleum Products Consumption'!$F$5:$F$40,MATCH('Tax Rates'!A9,'Petroleum Products Consumption'!$A$5:$A$40,0),1),0) -> 26.6 | Z9: =SUMIFS('NG Sales'!$H$6:$H$74,'NG Sales'!$I$6:$I$74,'Tax Rates'!A9,'NG Sales'!$A$6:$A$74,"Net Production (sales)") -> 0
A10: Chandigarh | B10: 0.125 | C10: 0.05 | P10: 0.2 | X10: =A10 -> Chandigarh | Y10: =IFERROR(INDEX('Petroleum Products Consumption'!$F$5:$F$40,MATCH('Tax Rates'!A10,'Petroleum Products Consumption'!$A$5:$A$40,0),1),0) -> 26.6 | Z10: =SUMIFS('NG Sales'!$H$6:$H$74,'NG Sales'!$I$6:$I$74,'Tax Rates'!A10,'NG Sales'!$A$6:$A$74,"Net Production (sales)") -> 0
A11: Chhattisgarh | B11: 0.05 | C11: 0.25 | P11: 0.04 | X11: =A11 -> Chhattisgarh | Y11: =IFERROR(INDEX('Petroleum Products Consumption'!$F$5:$F$40,MATCH('Tax Rates'!A11,'Petroleum Products Consumption'!$A$5:$A$40,0),1),0) -> 28.5 | Z11: =SUMIFS('NG Sales'!$H$6:$H$74,'NG Sales'!$I$6:$I$74,'Tax Rates'!A11,'NG Sales'!$A$6:$A$74,"Net Production (sales)") -> 0
A12: Delhi | B12: 0.05 | C12: 0 | P12: 0.25 | X12: =A12 -> Delhi | Y12: =IFERROR(INDEX('Petroleum Products Consumption'!$F$5:$F$40,MATCH('Tax Rates'!A12,'Petroleum Products Consumption'!$A$5:$A$40,0),1),0) -> 1314.4 | Z12: =SUMIFS('NG Sales'!$H$6:$H$74,'NG Sales'!$I$6:$I$74,'Tax Rates'!A12,'NG Sales'!$A$6:$A$74,"Net Production (sales)") -> 0
A13: Goa | B13: 0.2 | C13: 0.3 | P13: 0.18 | X13: =A13 -> Goa | Y13: =IFERROR(INDEX('Petroleum Products Consumption'!$F$5:$F$40,MATCH('Tax Rates'!A13,'Petroleum Products Consumption'!$A$5:$A$40,0),1),0) -> 87.7 | Z13: =SUMIFS('NG Sales'!$H$6:$H$74,'NG Sales'!$I$6:$I$74,'Tax Rates'!A13,'NG Sales'!$A$6:$A$74,"Net Production (sales)") -> 0
A14: Gujarat | B14: 0.05 | C14: 0.15 | P14: 0.38 | X14: =A14 -> Gujarat | Y14: =IFERROR(INDEX('Petroleum Products Consumption'!$F$5:$F$40,MATCH('Tax Rates'!A14,'Petroleum Products Consumption'!$A$5:$A$40,0),1),0) -> 172 | Z14: =SUMIFS('NG Sales'!$H$6:$H$74,'NG Sales'!$I$6:$I$74,'Tax Rates'!A14,'NG Sales'!$A$6:$A$74,"Net Production (sales)") -> 635.05
A15: Haryana | B15: 0.125 | C15: 0.125 | P15: 0.2 | X15: =A15 -> Haryana | Y15: =IFERROR(INDEX('Petroleum Products Consumption'!$F$5:$F$40,MATCH('Tax Rates'!A15,'Petroleum Products Consumption'!$A$5:$A$40,0),1),0) -> 27.8 | Z15: =SUMIFS('NG Sales'!$H$6:$H$74,'NG Sales'!$I$6:$I$74,'Tax Rates'!A15,'NG Sales'!$A$6:$A$74,"Net Production (sales)") -> 0
A16: Himachal Pradesh | B16: 0.1375 | C16: 0.04 | P16: 0.26 | X16: =A16 -> Himachal Pradesh | Y16: =IFERROR(INDEX('Petroleum Products Consumption'!$F$5:$F$40,MATCH('Tax Rates'!A16,'Petroleum Products Consumption'!$A$5:$A$40,0),1),0) -> 4.4 | Z16: =SUMIFS('NG Sales'!$H$6:$H$74,'NG Sales'!$I$6:$I$74,'Tax Rates'!A16,'NG Sales'!$A$6:$A$74,"Net Production (sales)") -> 0
A17: J & K | B17: 0.145 | C17: 0.21 | P17: 0.01 | X17: =A17 -> J & K | Y17: =IFERROR(INDEX('Petroleum Products Consumption'!$F$5:$F$40,MATCH('Tax Rates'!A17,'Petroleum Products Consumption'!$A$5:$A$40,0),1),0) -> 0 | Z17: =SUMIFS('NG Sales'!$H$6:$H$74,'NG Sales'!$I$6:$I$74,'Tax Rates'!A17,'NG Sales'!$A$6:$A$74,"Net Production (sales)") -> 0
... A40: Ladakh | B40: 0.145 | C40: 0.21 | P40: 0.01 | X40: =A40 -> Ladakh | Y40: =IFERROR(INDEX('Petroleum Products Consumption'!$F$5:$F$40,MATCH('Tax Rates'!A40,'Petroleum Products Consumption'!$A$5:$A$40,0),1),0) -> 0 | Z40: =SUMIFS('NG Sales'!$H$6:$H$74,'NG Sales'!$I$6:$I$74,'Tax Rates'!A40,'NG Sales'!$A$6:$A$74,"Net Production (sales)") -> 0
A42: Source: Indian Petroleum and Natural Gas Statistics, 2021-22 (MoPNG)
A43: Table IV.14, Page 112

Sheet Electricity Tax Rates
A1: Tax
A2: State | B2: Domestic | C2: Commercial | D2: Agriculture | E2: LT Industry | F2: HT industry | G2: Railway
A3: Andhra Pradesh | B3: 6 | C3: 6 | D3: 6 | E3: 6 | F3: 6
A4: Assam | B4: 0.05 | C4: 0.05 | D4: 0.05 | E4: 0.05 | F4: 0.05 | G4: 0.05
A5: Bihar | B5: 0.06 | C5: 0.06 | D5: 6 | E5: 0.06 | F5: 0.06
A6: Chandigarh | B6: 9 | C6: 11 | D6: 0 | E6: 11 | F6: 11
A7: Delhi | B7: 0.05 | C7: 0.05 | D7: 0.05 | E7: 0.05 | F7: 0.05 | G7: 0.05
A8: Goa | B8: 20 | C8: 70 | D8: 20 | E8: 70 | F8: 70
A9: Gujarat | B9: 0.1125 | C9: 0.2 | D9: 0 | E9: 0.1 | F9: 0.15
A10: Haryana | B10: 10 | C10: 10 | D10: 0 | E10: 10 | F10: 10 | G10: 10
A11: Himachal Pradesh | B11: 0.03 | C11: 0.08 | D11: 0.1 | E11: 0.07 | F11: 0.11 | G11: 0.1
A12: Jammu and Kashmir | B12: 0.15 | C12: 0.15 | D12: 0.15 | E12: 0.15 | F12: 0.15 | G12: 0.15
A13: Jharkhand | B13: 22 | C13: 27 | D13: 2 | E13: 5 | F13: 5 | G13: 15
A14: Karnataka | B14: 0.09 | C14: 0.09 | D14: 0.09 | E14: 0.09 | F14: 0.09 | G14: 0.09
A15: Kerala | B15: 0.1 | C15: 0.1 | D15: 0.1 | E15: 0.1 | F15: 10
A16: Madhya Pradesh | B16: 0.105 | C16: 0.12 | E16: 0.09 | F16: 0.15
A17: Maharashtra | B17: 0.16 | C17: 0.21 | E17: 0.075 | F17: 0.075
A18: Manipur
A19: Meghalaya | B19: 5 | C19: 6 | D19: 6 | E19: 4.1666667 | F19: 4.1666667
A20: Orissa | B20: 0.04 | C20: 0.04 | D20: 0.02 | E20: 0.05 | F20: 0.08
A21: Punjab | B21: 0.13 | C21: 0.13 | E21: 0.13 | F21: 0.13
A22: Rajasthan | B22: 40 | C22: 40 | D22: 4 | E22: 40 | F22: 40 | G22: 40
A23: Tamil Nadu | C23: 0.05 | E23: 0.05 | F23: 0.05 | G23: 0.05
A24: Uttarakhand | B24: 22.5 | C24: 35 | E24: 40 | F24: 60
A25: Uttar Pradesh | B25: 0.05 | C25: 0.075 | E25: 0.075 | F25: 0.075
A26: West Bengal | B26: 0.1 | C26: 0.125 | E26: 0.075 | F26: 0.15
A27: Source: CEA | B27: Cover 3rd book 2023 FINAL.cdr (cea.nic.in)
A28: Equivalent Tax Rate
A29: State | B29: Domestic | C29: Commercial | D29: Agriculture | E29: LT Industry | F29: HT industry | G29: Railway
A30: Andhra Pradesh | B30: =IF(B3<1,B3,B3/INDEX('Electricity Tariffs and Consump'!$C$4:$G$35,MATCH('Electricity Tax Rates'!$A3,'Electricity Tariffs and Consump'!$B$4:$B$35,0),MATCH('Electricity Tax Rates'!B$2,'Electricity Tariffs and Consump'!$C$3:$G$3,0))) -> 0.010273973 | C30: =IF(C3<1,C3,C3/INDEX('Electricity Tariffs and Consump'!$C$4:$G$35,MATCH('Electricity Tax Rates'!$A3,'Electricity Tariffs and Consump'!$B$4:$B$35,0),MATCH('Electricity Tax Rates'!C$2,'Electricity Tariffs and Consump'!$C$3:$G$3,0))) -> 0.005907173 | D30: =IF(D3<1,D3,D3/INDEX('Electricity Tariffs and Consump'!$C$4:$G$35,MATCH('Electricity Tax Rates'!$A3,'Electricity Tariffs and Consump'!$B$4:$B$35,0),MATCH('Electricity Tax Rates'!D$2,'Electricity Tariffs and Consump'!$C$3:$G$3,0))) -> 0.026666667 | E30: =IF(E3<1,E3,E3/INDEX('Electricity Tariffs and Consump'!$C$4:$G$35,MATCH('Electricity Tax Rates'!$A3,'Electricity Tariffs and Consump'!$B$4:$B$35,0),MATCH("Industry",'Electricity Tariffs and Consump'!$C$3:$G$3,0))) -> 0.00795053 | F30: =IF(F3<1,F3,F3/INDEX('Electricity Tariffs and Consump'!$C$4:$G$35,MATCH('Electricity Tax Rates'!$A3,'Electricity Tariffs and Consump'!$B$4:$B$35,0),MATCH("Industry",'Electricity Tariffs and Consump'!$C$3:$G$3,0))) -> 0.00795053 | G30: =IF(G3<1,G3,G3/INDEX('Electricity Tariffs and Consump'!$C$4:$G$35,MATCH('Electricity Tax Rates'!$A3,'Electricity Tariffs and Consump'!$B$4:$B$35,0),MATCH("Railway",'Electricity Tariffs and Consump'!$C$3:$G$3,0))) -> 0
A31: Assam | B31: =IF(B4<1,B4,B4/INDEX('Electricity Tariffs and Consump'!$C$4:$G$35,MATCH('Electricity Tax Rates'!$A4,'Electricity Tariffs and Consump'!$B$4:$B$35,0),MATCH('Electricity Tax Rates'!B$2,'Electricity Tariffs and Consump'!$C$3:$G$3,0))) -> 0.05 | C31: =IF(C4<1,C4,C4/INDEX('Electricity Tariffs and Consump'!$C$4:$G$35,MATCH('Electricity Tax Rates'!$A4,'Electricity Tariffs and Consump'!$B$4:$B$35,0),MATCH('Electricity Tax Rates'!C$2,'Electricity Tariffs and Consump'!$C$3:$G$3,0))) -> 0.05 | D31: =IF(D4<1,D4,D4/INDEX('Electricity Tariffs and Consump'!$C$4:$G$35,MATCH('Electricity Tax Rates'!$A4,'Electricity Tariffs and Consump'!$B$4:$B$35,0),MATCH('Electricity Tax Rates'!D$2,'Electricity Tariffs and Consump'!$C$3:$G$3,0))) -> 0.05 | E31: =IF(E4<1,E4,E4/INDEX('Electricity Tariffs and Consump'!$C$4:$G$35,MATCH('Electricity Tax Rates'!$A4,'Electricity Tariffs and Consump'!$B$4:$B$35,0),MATCH("Industry",'Electricity Tariffs and Consump'!$C$3:$G$3,0))) -> 0.05 | F31: =IF(F4<1,F4,F4/INDEX('Electricity Tariffs and Consump'!$C$4:$G$35,MATCH('Electricity Tax Rates'!$A4,'Electricity Tariffs and Consump'!$B$4:$B$35,0),MATCH("Industry",'Electricity Tariffs and Consump'!$C$3:$G$3,0))) -> 0.05 | G31: =IF(G4<1,G4,G4/INDEX('Electricity Tariffs and Consump'!$C$4:$G$35,MATCH('Electricity Tax Rates'!$A4,'Electricity Tariffs and Consump'!$B$4:$B$35,0),MATCH("Railway",'Electricity Tariffs and Consump'!$C$3:$G$3,0))) -> 0.05
A32: Bihar | B32: =IF(B5<1,B5,B5/INDEX('Electricity Tariffs and Consump'!$C$4:$G$35,MATCH('Electricity Tax Rates'!$A5,'Electricity Tariffs and Consump'!$B$4:$B$35,0),MATCH('Electricity Tax Rates'!B$2,'Electricity Tariffs and Consump'!$C$3:$G$3,0))) -> 0.06 | C32: =IF(C5<1,C5,C5/INDEX('Electricity Tariffs and Consump'!$C$4:$G$35,MATCH('Electricity Tax Rates'!$A5,'Electricity Tariffs and Consump'!$B$4:$B$35,0),MATCH('Electricity Tax Rates'!C$2,'Electricity Tariffs and Consump'!$C$3:$G$3,0))) -> 0.06 | D32: =IF(D5<1,D5,D5/INDEX('Electricity Tariffs and Consump'!$C$4:$G$35,MATCH('Electricity Tax Rates'!$A5,'Electricity Tariffs and Consump'!$B$4:$B$35,0),MATCH('Electricity Tax Rates'!D$2,'Electricity Tariffs and Consump'!$C$3:$G$3,0))) -> 0.010526316 | E32: =IF(E5<1,E5,E5/INDEX('Electricity Tariffs and Consump'!$C$4:$G$35,MATCH('Electricity Tax Rates'!$A5,'Electricity Tariffs and Consump'!$B$4:$B$35,0),MATCH("Industry",'Electricity Tariffs and Consump'!$C$3:$G$3,0))) -> 0.06 | F32: =IF(F5<1,F5,F5/INDEX('Electricity Tariffs and Consump'!$C$4:$G$35,MATCH('Electricity Tax Rates'!$A5,'Electricity Tariffs and Consump'!$B$4:$B$35,0),MATCH("Industry",'Electricity Tariffs and Consump'!$C$3:$G$3,0))) -> 0.06 | G32: =IF(G5<1,G5,G5/INDEX('Electricity Tariffs and Consump'!$C$4:$G$35,MATCH('Electricity Tax Rates'!$A5,'Electricity Tariffs and Consump'!$B$4:$B$35,0),MATCH("Railway",'Electricity Tariffs and Consump'!$C$3:$G$3,0))) -> 0
A33: Chandigarh | B33: 0 | C33: 0 | D33: =IF(D6<1,D6,D6/INDEX('Electricity Tariffs and Consump'!$C$4:$G$35,MATCH('Electricity Tax Rates'!$A6,'Electricity Tariffs and Consump'!$B$4:$B$35,0),MATCH('Electricity Tax Rates'!D$2,'Electricity Tariffs and Consump'!$C$3:$G$3,0))) -> 0 | E33: 0 | F33: 0 | G33: =IF(G6<1,G6,G6/INDEX('Electricity Tariffs and Consump'!$C$4:$G$35,MATCH('Electricity Tax Rates'!$A6,'Electricity Tariffs and Consump'!$B$4:$B$35,0),MATCH("Railway",'Electricity Tariffs and Consump'!$C$3:$G$3,0))) -> 0
A34: Delhi | B34: =IF(B7<1,B7,B7/INDEX('Electricity Tariffs and Consump'!$C$4:$G$35,MATCH('Electricity Tax Rates'!$A7,'Electricity Tariffs and Consump'!$B$4:$B$35,0),MATCH('Electricity Tax Rates'!B$2,'Electricity Tariffs and Consump'!$C$3:$G$3,0))) -> 0.05 | C34: =IF(C7<1,C7,C7/INDEX('Electricity Tariffs and Consump'!$C$4:$G$35,MATCH('Electricity Tax Rates'!$A7,'Electricity Tariffs and Consump'!$B$4:$B$35,0),MATCH('Electricity Tax Rates'!C$2,'Electricity Tariffs and Consump'!$C$3:$G$3,0))) -> 0.05 | D34: =IF(D7<1,D7,D7/INDEX('Electricity Tariffs and Consump'!$C$4:$G$35,MATCH('Electricity Tax Rates'!$A7,'Electricity Tariffs and Consump'!$B$4:$B$35,0),MATCH('Electricity Tax Rates'!D$2,'Electricity Tariffs and Consump'!$C$3:$G$3,0))) -> 0.05 | E34: =IF(E7<1,E7,E7/INDEX('Electricity Tariffs and Consump'!$C$4:$G$35,MATCH('Electricity Tax Rates'!$A7,'Electricity Tariffs and Consump'!$B$4:$B$35,0),MATCH("Industry",'Electricity Tariffs and Consump'!$C$3:$G$3,0))) -> 0.05 | F34: =IF(F7<1,F7,F7/INDEX('Electricity Tariffs and Consump'!$C$4:$G$35,MATCH('Electricity Tax Rates'!$A7,'Electricity Tariffs and Consump'!$B$4:$B$35,0),MATCH("Industry",'Electricity Tariffs and Consump'!$C$3:$G$3,0))) -> 0.05 | G34: =IF(G7<1,G7,G7/INDEX('Electricity Tariffs and Consump'!$C$4:$G$35,MATCH('Electricity Tax Rates'!$A7,'Electricity Tariffs and Consump'!$B$4:$B$35,0),MATCH("Railway",'Electricity Tariffs and Consump'!$C$3:$G$3,0))) -> 0.05
A35: Goa | B35: =IF(B8<1,B8,B8/INDEX('Electricity Tariffs and Consump'!$C$4:$G$35,MATCH('Electricity Tax Rates'!$A8,'Electricity Tariffs and Consump'!$B$4:$B$35,0),MATCH('Electricity Tax Rates'!B$2,'Electricity Tariffs and Consump'!$C$3:$G$3,0))) -> 0.072332731 | C35: =IF(C8<1,C8,C8/INDEX('Electricity Tariffs and Consump'!$C$4:$G$35,MATCH('Electricity Tax Rates'!$A8,'Electricity Tariffs and Consump'!$B$4:$B$35,0),MATCH('Electricity Tax Rates'!C$2,'Electricity Tariffs and Consump'!$C$3:$G$3,0))) -> 0.13964092 | D35: =IF(D8<1,D8,D8/INDEX('Electricity Tariffs and Consump'!$C$4:$G$35,MATCH('Electricity Tax Rates'!$A8,'Electricity Tariffs and Consump'!$B$4:$B$35,0),MATCH('Electricity Tax Rates'!D$2,'Electricity Tariffs and Consump'!$C$3:$G$3,0))) -> 0.12578616 | E35: =IF(E8<1,E8,E8/INDEX('Electricity Tariffs and Consump'!$C$4:$G$35,MATCH('Electricity Tax Rates'!$A8,'Electricity Tariffs and Consump'!$B$4:$B$35,0),MATCH("Industry",'Electricity Tariffs and Consump'!$C$3:$G$3,0))) -> 0.12076291 | F35: =IF(F8<1,F8,F8/INDEX('Electricity Tariffs and Consump'!$C$4:$G$35,MATCH('Electricity Tax Rates'!$A8,'Electricity Tariffs and Consump'!$B$4:$B$35,0),MATCH("Industry",'Electricity Tariffs and Consump'!$C$3:$G$3,0))) -> 0.12076291 | G35: =IF(G8<1,G8,G8/INDEX('Electricity Tariffs and Consump'!$C$4:$G$35,MATCH('Electricity Tax Rates'!$A8,'Electricity Tariffs and Consump'!$B$4:$B$35,0),MATCH("Railway",'Electricity Tariffs and Consump'!$C$3:$G$3,0))) -> 0
A36: Gujarat | B36: =IF(B9<1,B9,B9/INDEX('Electricity Tariffs and Consump'!$C$4:$G$35,MATCH('Electricity Tax Rates'!$A9,'Electricity Tariffs and Consump'!$B$4:$B$35,0),MATCH('Electricity Tax Rates'!B$2,'Electricity Tariffs and Consump'!$C$3:$G$3,0))) -> 0.1125 | C36: =IF(C9<1,C9,C9/INDEX('Electricity Tariffs and Consump'!$C$4:$G$35,MATCH('Electricity Tax Rates'!$A9,'Electricity Tariffs and Consump'!$B$4:$B$35,0),MATCH('Electricity Tax Rates'!C$2,'Electricity Tariffs and Consump'!$C$3:$G$3,0))) -> 0.2 | D36: =IF(D9<1,D9,D9/INDEX('Electricity Tariffs and Consump'!$C$4:$G$35,MATCH('Electricity Tax Rates'!$A9,'Electricity Tariffs and Consump'!$B$4:$B$35,0),MATCH('Electricity Tax Rates'!D$2,'Electricity Tariffs and Consump'!$C$3:$G$3,0))) -> 0 | E36: =IF(E9<1,E9,E9/INDEX('Electricity Tariffs and Consump'!$C$4:$G$35,MATCH('Electricity Tax Rates'!$A9,'Electricity Tariffs and Consump'!$B$4:$B$35,0),MATCH("Industry",'Electricity Tariffs and Consump'!$C$3:$G$3,0))) -> 0.1 | F36: =IF(F9<1,F9,F9/INDEX('Electricity Tariffs and Consump'!$C$4:$G$35,MATCH('Electricity Tax Rates'!$A9,'Electricity Tariffs and Consump'!$B$4:$B$35,0),MATCH("Industry",'Electricity Tariffs and Consump'!$C$3:$G$3,0))) -> 0.15 | G36: =IF(G9<1,G9,G9/INDEX('Electricity Tariffs and Consump'!$C$4:$G$35,MATCH('Electricity Tax Rates'!$A9,'Electricity Tariffs and Consump'!$B$4:$B$35,0),MATCH("Railway",'Electricity Tariffs and Consump'!$C$3:$G$3,0))) -> 0
A37: Haryana | B37: =IF(B10<1,B10,B10/INDEX('Electricity Tariffs and Consump'!$C$4:$G$35,MATCH('Electricity Tax Rates'!$A10,'Electricity Tariffs and Consump'!$B$4:$B$35,0),MATCH('Electricity Tax Rates'!B$2,'Electricity Tariffs and Consump'!$C$3:$G$3,0))) -> 0.022099448 | C37: =IF(C10<1,C10,C10/INDEX('Electricity Tariffs and Consump'!$C$4:$G$35,MATCH('Electricity Tax Rates'!$A10,'Electricity Tariffs and Consump'!$B$4:$B$35,0),MATCH('Electricity Tax Rates'!C$2,'Electricity Tariffs and Consump'!$C$3:$G$3,0))) -> 0.013180192 | D37: =IF(D10<1,D10,D10/INDEX('Electricity Tariffs and Consump'!$C$4:$G$35,MATCH('Electricity Tax Rates'!$A10,'Electricity Tariffs and Consump'!$B$4:$B$35,0),MATCH('Electricity Tax Rates'!D$2,'Electricity Tariffs and Consump'!$C$3:$G$3,0))) -> 0 | E37: =IF(E10<1,E10,E10/INDEX('Electricity Tariffs and Consump'!$C$4:$G$35,MATCH('Electricity Tax Rates'!$A10,'Electricity Tariffs and Consump'!$B$4:$B$35,0),MATCH("Industry",'Electricity Tariffs and Consump'!$C$3:$G$3,0))) -> 0.013807446 | F37: =IF(F10<1,F10,F10/INDEX('Electricity Tariffs and Consump'!$C$4:$G$35,MATCH('Electricity Tax Rates'!$A10,'Electricity Tariffs and Consump'!$B$4:$B$35,0),MATCH("Industry",'Electricity Tariffs and Consump'!$C$3:$G$3,0))) -> 0.013807446 | G37: =IF(G10<1,G10,G10/INDEX('Electricity Tariffs and Consump'!$C$4:$G$35,MATCH('Electricity Tax Rates'!$A10,'Electricity Tariffs and Consump'!$B$4:$B$35,0),MATCH("Railway",'Electricity Tariffs and Consump'!$C$3:$G$3,0))) -> 0.012288786
A38: Himachal Pradesh | B38: =IF(B11<1,B11,B11/INDEX('Electricity Tariffs and Consump'!$C$4:$G$35,MATCH('Electricity Tax Rates'!$A11,'Electricity Tariffs and Consump'!$B$4:$B$35,0),MATCH('Electricity Tax Rates'!B$2,'Electricity Tariffs and Consump'!$C$3:$G$3,0))) -> 0.03 | C38: =IF(C11<1,C11,C11/INDEX('Electricity Tariffs and Consump'!$C$4:$G$35,MATCH('Electricity Tax Rates'!$A11,'Electricity Tariffs and Consump'!$B$4:$B$35,0),MATCH('Electricity Tax Rates'!C$2,'Electricity Tariffs and Consump'!$C$3:$G$3,0))) -> 0.08 | D38: =IF(D11<1,D11,D11/INDEX('Electricity Tariffs and Consump'!$C$4:$G$35,MATCH('Electricity Tax Rates'!$A11,'Electricity Tariffs and Consump'!$B$4:$B$35,0),MATCH('Electricity Tax Rates'!D$2,'Electricity Tariffs and Consump'!$C$3:$G$3,0))) -> 0.1 | E38: =IF(E11<1,E11,E11/INDEX('Electricity Tariffs and Consump'!$C$4:$G$35,MATCH('Electricity Tax Rates'!$A11,'Electricity Tariffs and Consump'!$B$4:$B$35,0),MATCH("Industry",'Electricity Tariffs and Consump'!$C$3:$G$3,0))) -> 0.07 | F38: =IF(F11<1,F11,F11/INDEX('Electricity Tariffs and Consump'!$C$4:$G$35,MATCH('Electricity Tax Rates'!$A11,'Electricity Tariffs and Consump'!$B$4:$B$35,0),MATCH("Industry",'Electricity Tariffs and Consump'!$C$3:$G$3,0))) -> 0.11 | G38: =IF(G11<1,G11,G11/INDEX('Electricity Tariffs and Consump'!$C$4:$G$35,MATCH('Electricity Tax Rates'!$A11,'Electricity Tariffs and Consump'!$B$4:$B$35,0),MATCH("Railway",'Electricity Tariffs and Consump'!$C$3:$G$3,0))) -> 0.1
A39: Jammu and Kashmir | B39: =IF(B12<1,B12,B12/INDEX('Electricity Tariffs and Consump'!$C$4:$G$35,MATCH('Electricity Tax Rates'!$A12,'Electricity Tariffs and Consump'!$B$4:$B$35,0),MATCH('Electricity Tax Rates'!B$2,'Electricity Tariffs and Consump'!$C$3:$G$3,0))) -> 0.15 | C39: =IF(C12<1,C12,C12/INDEX('Electricity Tariffs and Consump'!$C$4:$G$35,MATCH('Electricity Tax Rates'!$A12,'Electricity Tariffs and Consump'!$B$4:$B$35,0),MATCH('Electricity Tax Rates'!C$2,'Electricity Tariffs and Consump'!$C$3:$G$3,0))) -> 0.15 | D39: =IF(D12<1,D12,D12/INDEX('Electricity Tariffs and Consump'!$C$4:$G$35,MATCH('Electricity Tax Rates'!$A12,'Electricity Tariffs and Consump'!$B$4:$B$35,0),MATCH('Electricity Tax Rates'!D$2,'Electricity Tariffs and Consump'!$C$3:$G$3,0))) -> 0.15 | E39: =IF(E12<1,E12,E12/INDEX('Electricity Tariffs and Consump'!$C$4:$G$35,MATCH('Electricity Tax Rates'!$A12,'Electricity Tariffs and Consump'!$B$4:$B$35,0),MATCH("Industry",'Electricity Tariffs and Consump'!$C$3:$G$3,0))) -> 0.15 | F39: =IF(F12<1,F12,F12/INDEX('Electricity Tariffs and Consump'!$C$4:$G$35,MATCH('Electricity Tax Rates'!$A12,'Electricity Tariffs and Consump'!$B$4:$B$35,0),MATCH("Industry",'Electricity Tariffs and Consump'!$C$3:$G$3,0))) -> 0.15 | G39: =IF(G12<1,G12,G12/INDEX('Electricity Tariffs and Consump'!$C$4:$G$35,MATCH('Electricity Tax Rates'!$A12,'Electricity Tariffs and Consump'!$B$4:$B$35,0),MATCH("Railway",'Electricity Tariffs and Consump'!$C$3:$G$3,0))) -> 0.15
A40: Jharkhand | B40: =IF(B13<1,B13,B13/INDEX('Electricity Tariffs and Consump'!$C$4:$G$35,MATCH('Electricity Tax Rates'!$A13,'Electricity Tariffs and Consump'!$B$4:$B$35,0),MATCH('Electricity Tax Rates'!B$2,'Electricity Tariffs and Consump'!$C$3:$G$3,0))) -> 0.035651587 | C40: =IF(C13<1,C13,C13/INDEX('Electricity Tariffs and Consump'!$C$4:$G$35,MATCH('Electricity Tax Rates'!$A13,'Electricity Tariffs and Consump'!$B$4:$B$35,0),MATCH('Electricity Tax Rates'!C$2,'Electricity Tariffs and Consump'!$C$3:$G$3,0))) -> 0.042857143 | D40: =IF(D13<1,D13,D13/INDEX('Electricity Tariffs and Consump'!$C$4:$G$35,MATCH('Electricity Tax Rates'!$A13,'Electricity Tariffs and Consump'!$B$4:$B$35,0),MATCH('Electricity Tax Rates'!D$2,'Electricity Tariffs and Consump'!$C$3:$G$3,0))) -> 0.0039215686 | E40: =IF(E13<1,E13,E13/INDEX('Electricity Tariffs and Consump'!$C$4:$G$35,MATCH('Electricity Tax Rates'!$A13,'Electricity Tariffs and Consump'!$B$4:$B$35,0),MATCH("Industry",'Electricity Tariffs and Consump'!$C$3:$G$3,0))) -> 0.0075659923 | F40: =IF(F13<1,F13,F13/INDEX('Electricity Tariffs and Consump'!$C$4:$G$35,MATCH('Electricity Tax Rates'!$A13,'Electricity Tariffs and Consump'!$B$4:$B$35,0),MATCH("Industry",'Electricity Tariffs and Consump'!$C$3:$G$3,0))) -> 0.0075659923 | G40: =IF(G13<1,G13,G13/INDEX('Electricity Tariffs and Consump'!$C$4:$G$35,MATCH('Electricity Tax Rates'!$A13,'Electricity Tariffs and Consump'!$B$4:$B$35,0),MATCH("Railway",'Electricity Tariffs and Consump'!$C$3:$G$3,0))) -> 0.018203883
...

Sheet Electricity Tariffs and Consump
A1: CONSUMER CATEGORYWISE AVERAGE TARIFF, 2022
A2: SPUs (Paise/Kwh)
A3: Sr. No | B3: State | C3: Domestic | D3: Commercial | E3: Agriculture | F3: Industry | G3: Railway
A4: 1 | B4: Andhra Pradesh | C4: 584 | D4: 1015.7143 | E4: 225 | F4: 754.66667 | G4: 763
A5: 2 | B5: Assam | C5: 662.16667 | D5: 825.85714 | E5: 447 | F5: 650.46154 | G5: 771
A6: 3 | B6: Bihar | C6: 706.08333 | D6: 792.85714 | E6: 570 | F6: 615.85185 | G6: 900
A7: 4 | B7: Chattisgarh | C7: 499.16667 | D7: 444.87 | E7: 540 | F7: 773.85185 | G7: 697
A8: 5 | B8: Delhi | C8: 482.5 | D8: 1090.2857 | E8: 197 | F8: 868.59259 | G8: 836
A9: 6 | B9: Gujarat | C9: 494.66667 | D9: 500.57143 | E9: 90 | F9: 500.81481 | G9: 600
A10: 7 | B10: Haryana | C10: 452.5 | D10: 758.71429 | E10: 10 | F10: 724.24691 | G10: =AVERAGE(831,819,808,797) -> 813.75
A11: 8 | B11: Himachal Pradesh | C11: 494.33333 | D11: 582.71429 | E11: 383 | F11: 561.77778 | G11: 744
A12: 9 | B12: Jammu & Kashmir | C12: 261.83333 | D12: 523 | E12: 74 | F12: 390.37037 | G12: 0
A13: 10 | B13: Jharkhand | C13: 617.08333 | D13: 630 | E13: 510 | F13: 660.85185 | G13: 824
A14: 11 | B14: Karnataka | C14: 738.83333 | D14: 972.28571 | E14: 0 | F14: 764.90123 | G14: 794
A15: 12 | B15: Kerala | C15: 756.5 | D15: 961.85714 | E15: 234 | F15: 623 | G15: 677
A16: 13 | B16: Madhya Pradesh | C16: 788.25 | D16: 776.35714 | E16: 568 | F16: 793.14815 | G16: 762
A17: 14 | B17: Maharashtra | C17: 899.16667 | D17: 1175.8571 | E17: 350 | F17: 869.27778 | G17: 1064
A18: 15 | B18: Meghalaya | C18: 558.16667 | D18: 801.28571 | E18: 341 | F18: 746.66667 | G18: 0
A19: 16 | B19: Orissa | C19: 522.83333 | D19: 754.28571 | E19: 156.25 | F19: 665.07407 | G19: 724
A20: 17 | B20: Punjab | C20: 629.33333 | D20: 767 | E20: 566 | F20: 757.14815 | G20: 963
A21: 18 | B21: Rajasthan | C21: 782.83333 | D21: 1032.4286 | E21: 570 | F21: 538.40741 | G21: 645
A22: 19 | B22: Tamil Nadu | C22: 407.5 | D22: 838.28571 | E22: 0 | F22: 672.01852 | G22: 802
A23: 20 | B23: Uttar Pradesh | C23: 629.91667 | D23: 872.57143 | E23: 450 | F23: 836.78395 | G23: =AVERAGE(1235,1271) -> 1253
A24: 21 | B24: Uttarakhand | C24: 491 | D24: 688.42857 | E24: 208 | F24: 619.11111 | G24: 709
A25: 22 | B25: West Bengal | C25: 785.25 | D25: 908.57143 | E25: 510 | F25: 759.68519 | G25: =AVERAGE(936) -> 936
A26: Average of SPUs 303.89 648.80 138.18 488.22 494.34 351.26 368.27
A27: II. EDs
A28: 1 | B28: Arunachal Pradesh | C28: 400 | D28: 500 | E28: 310 | F28: 354.44444 | G28: 0
A29: 2 | B29: Goa | C29: 276.5 | D29: 501.28571 | E29: 159 | F29: 579.64815 | G29: 0
A30: 3 | B30: Manipur | C30: 666 | D30: 808.57143 | E30: 479 | F30: 573.48148 | G30: 0
A31: 4 | B31: Mizoram | C31: 593.16667 | D31: 755.14286 | E31: 384 | F31: 506 | G31: 0
A32: 5 | B32: Nagaland | C32: 612.16667 | D32: 869.28571 | E32: 310 | F32: 444.7037 | G32: 0
A33: 6 | B33: Pondicherry | C33: 379.16667 | D33: 774.28571 | E33: 0 | F33: 491.48148 | G33: 0
A34: 7 | B34: Sikkim | C34: 281.16667 | D34: 623.42857 | E34: 0 | F34: 483.2963 | G34: 0
A35: 8 | B35: Tripura | C35: 659.16667 | D35: 749.14286 | E35: 393.75 | F35: 140.11111 | G35: 0
A38: Source: CEA
A41: CONSUMER CATEGORYWISE SALE OF POWER - 2021-22 (in MU)
A42: S.No | B42: State | C42: Domestic | D42: Commer- cial | E42: Agri/ irrig. | F42: Industry | G42: Railway traction | H42: Total
A43: I. SPUs | C43: domestic | D43: commercial | E43: agriculture | F43: industry | G43: railway
A44: 1 | B44: Andhra Pradesh | C44: 17933.6 | D44: 4957.5 | E44: 16261.8 | F44: 17412 | G44: 0 | H44: =SUM(C44:G44)+3537.5 -> 60102.4
...

Sheet Average electricity tariffs
A1: State | B1: Domestic 6 KW (600 units/month) | C1: Commercial - 30 KW (4500 units/month) | D1: Agriculture - 5 HP (1000 units/Month) | E1: Industry - small/large | F1: Railway traction 12500 KW (2500000 unit/month)
A2: Andhra Pradesh | B2: 708 | C2: 1051 | D2: =(100+350)/2 -> 225 | F2: 763
A3: Assam | B3: 725 | C3: 851 | D3: 447 | F3: 771
A4: Bihar | B4: =(794+664)/2 -> 729 | C4: =(856+751)/2 -> 803.5 | D4: 570 | F4: 900
A5: Chandigarh | B5: 405 | C5: 563 | D5: 260 | F5: 0
A6: Delhi | B6: 567 | C6: 1130 | D6: 197 | F6: 836
A7: Goa | B7: 317 | C7: 519 | D7: 159 | F7: 0
A8: Gujarat | B8: =(469+435)/2 -> 452 | C8: 514 | D8: 90 | F8: 600
A9: Haryana | B9: 531 | C9: 818 | D9: 10 | F9: =(831+819+808+797)/4 -> 813.75
A10: Himachal Pradesh | B10: 508 | C10: 620 | D10: 379 | F10: 744
A11: Jammu and Kashmir | B11: 297 | C11: 571 | D11: 74 | F11: 0
A12: Jharkhand | B12: =(638+578)/2 -> 608 | C12: =(667+608)/2 -> 637.5 | D12: 510 | F12: 824
A13: Karnataka | B13: =(835+783)/2 -> 809 | C13: =(1004+947)/2 -> 975.5 | D13: 0 | F13: 794
A14: Kerala | B14: 940 | C14: 1023 | D14: 234 | F14: 677
A15: Madhya Pradesh | B15: =(862+852)/2 -> 857 | C15: =(823+797)/2 -> 810 | D15: 583 | F15: 762
A16: Maharashtra | B16: 999 | C16: 1524 | D16: 350 | F16: 1064
A17: Manipur | B17: 699 | C17: 818 | D17: 479 | F17: 0
A18: Meghalaya | B18: 600 | C18: 808 | D18: 341 | F18: 0
A19: Orissa | B19: 565 | C19: 774 | D19: 155 | F19: 724
A20: Punjab | B20: 682 | C20: 780 | D20: 566 | F20: 963
A21: Rajasthan | B21: 786 | C21: 1090 | D21: 570 | F21: 645
A22: Tamil Nadu | B22: 533 | C22: 848 | D22: 0 | F22: 802
A23: Uttarakhand | B23: 555 | C23: 753 | D23: 208 | F23: 709
A24: Uttar Pradesh | B24: =(731+586)/2 -> 658.5 | C24: =(1161+623)/2 -> 892 | D24: =(665+235)/2 -> 450 | F24: =(1235+1271)/2 -> 1253
A25: West Bengal | B25: =(840+832)/2 -> 836 | C25: =(931+932)/2 -> 931.5 | D25: =(322+602)/2 -> 462 | F25: 936

Sheet Petroleum Products Consumption
A1: V.13 State-wise Sales of Major Petroleum Products during 2021-22 (P)
A2: ( in '000' Tonnes)
A3: Region/state | B3: Naphtha | C3: LPG | D3: MS | E3: SKO | F3: ATF | G3: HSD | H3: LDO | I3: FO | J3: HHS/LSHS | K3: Lubs/Grs | L3: Bitumen | M3: Others | N3: Total | P3: MS Tax Rate
A4: Region: North
A5: Jammu & Kashmir | B5: 0 | C5: 215.8 | D5: 316.3 | E5: 67.1 | F5: 53.4 | G5: 698 | H5: 1.9 | I5: 4 | J5: 0 | K5: 9.2 | L5: 39.8 | M5: 94.5 | N5: 1500
A6: Punjab | B6: 0 | C6: 1027.1 | D6: 1015.8 | E6: 0.7 | F6: 131.8 | G6: 3113 | H6: 11.5 | I6: 160.7 | J6: 0.9 | K6: 42.3 | L6: 149.7 | M6: 924.5 | N6: 6578
A7: Rajasthan | B7: 2.7 | C7: 1494.1 | D7: 1621.5 | E7: 1.9 | F7: 141.4 | G7: 4452 | H7: 82.2 | I7: 0 | J7: 72.1 | K7: 56.8 | L7: 325.1 | M7: 1991.2 | N7: 10241
A8: Uttar Pradesh | B8: 1.2 | C8: 3855.4 | D8: 3696.1 | E8: 2.5 | F8: 211.1 | G8: 9496 | H8: 99.5 | I8: 0 | J8: 130.7 | K8: 87.4 | L8: 770.3 | M8: 438.8 | N8: 18789
A9: Haryana | B9: 3446.6 | C9: 930.8 | D9: 1113.7 | E9: 0.9 | F9: 27.8 | G9: 4450 | H9: 25.1 | I9: 0 | J9: 77.5 | K9: 54.5 | L9: 279.5 | M9: 139.6 | N9: 10546
A10: Himachal Pradesh | B10: 0 | C10: 194.2 | D10: 272.3 | E10: 5.4 | F10: 4.4 | G10: 777 | H10: 1.3 | I10: 40.8 | J10: 4 | K10: 10.5 | L10: 74.7 | M10: 539.4 | N10: 1924
A11: Uttarakhand | B11: 0 | C11: 321.8 | D11: 338.4 | E11: 3.5 | F11: 15.5 | G11: 700 | H11: 2.9 | I11: 99 | J11: 3.8 | K11: 14.4 | L11: 32.3 | M11: 87.4 | N11: 1619
A12: Chandigarh | B12: 0 | C12: 52.6 | D12: 110 | E12: 0.1 | F12: 26.6 | G12: 171 | H12: 0.5 | I12: 1 | J12: 0 | K12: 2.7 | L12: 0.8 | M12: 3.7 | N12: 369
A13: Delhi | B13: 0 | C13: 771.1 | D13: 693.3 | E13: 0.1 | F13: 1314.4 | G13: 597 | H13: 2.4 | I13: 0 | J13: 0 | K13: 13.6 | L13: 3.5 | M13: 9.6 | N13: 3405
A14: Arunachal Pradesh | B14: 0 | C14: 25.4 | D14: 55.4 | E14: 9.7 | F14: 1.5 | G14: 192 | H14: 0 | I14: 0 | J14: 0 | K14: 0.5 | L14: 17.2 | M14: 0.3 | N14: 302
A15: Assam | B15: 297.4 | C15: 486.3 | D15: 510 | E15: 92.3 | F15: 122.6 | G15: 1123 | H15: 5 | I15: 6.5 | J15: 0 | K15: 37.6 | L15: 20.6 | M15: 221.7 | N15: 2923
A16: Manipur | B16: 0 | C16: 51.9 | D16: 67.5 | E16: 7.9 | F16: 3.3 | G16: 119 | H16: 0.3 | I16: 0.5 | J16: 0 | K16: 0.5 | L16: 2.4 | M16: 0.7 | N16: 254
... A41: Total Consumption | B41: 12709.1 | C41: 28253.4 | D41: 30848.9 | E41: 1493.4 | F41: 5007.1 | G41: 76620 | H41: 1012.6 | I41: 5353.3 | J41: 446.7 | K41: 1544.8 | L41: 5241 | M41: 35702.7 | N41: 204233
A42: Source: Petroleum Planning and Analysis Cell. P: Provisional

Sheet NG Sales
A1: II.17 State-wise Gross & Net Production of Natural Gas in India | I1: (Excerpt for Gross Production & Net Production Values)
A2: (in MMSCM)
A3: State / Utilisation | H3: 2021-22 (P)
A4: -1 | H4: -8
A5: Assam
A6: Gross Production (GP) | H6: 3371.45 | I6: =IF(LEFT(A6,5)="Gross",A5,I5) -> Assam
A7: Flared | I7: =IF(LEFT(A7,5)="Gross",A6,I6) -> Assam
A8: Net Availability | I8: =IF(LEFT(A8,5)="Gross",A7,I7) -> Assam
A9: Internal Use+Losses | I9: =IF(LEFT(A9,5)="Gross",A8,I8) -> Assam
A10: Net Production (Sales) | H10: 2486.43 | I10: =IF(LEFT(A10,5)="Gross",A9,I9) -> Assam
A11: % Flared to GP | I11: =IF(LEFT(A11,5)="Gross",A10,I10) -> Assam
A12: Arunachal Pradesh
A13: Gross Production | H13: 57.7 | I13: =IF(LEFT(A13,5)="Gross",A12,I12) -> Arunachal Pradesh
A14: Flared | I14: =IF(LEFT(A14,5)="Gross",A13,I13) -> Arunachal Pradesh
A15: Net Availability | I15: =IF(LEFT(A15,5)="Gross",A14,I14) -> Arunachal Pradesh
A16: Internal Use+Losses | I16: =IF(LEFT(A16,5)="Gross",A15,I15) -> Arunachal Pradesh
A17: Net Production (Sales) | H17: 0 | I17: =IF(LEFT(A17,5)="Gross",A16,I16) -> Arunachal Pradesh
A18: % Flared to GP | I18: =IF(LEFT(A18,5)="Gross",A17,I17) -> Arunachal Pradesh
A19: Rajasthan
A20: Gross Production | H20: 2618.83 | I20: =IF(LEFT(A20,5)="Gross",A19,I19) -> Rajasthan
A21: Flared | I21: =IF(LEFT(A21,5)="Gross",A20,I20) -> Rajasthan
A22: Net Availability | I22: =IF(LEFT(A22,5)="Gross",A21,I21) -> Rajasthan
A23: Internal Use+Losses | I23: =IF(LEFT(A23,5)="Gross",A22,I22) -> Rajasthan
A24: Net Production (Sales) | H24: 1785.88 | I24: =IF(LEFT(A24,5)="Gross",A23,I23) -> Rajasthan
A25: % Flared to GP | I25: =IF(LEFT(A25,5)="Gross",A24,I24) -> Rajasthan
A26: Gujarat
A27: Gross Production | H27: 1017.29 | I27: =IF(LEFT(A27,5)="Gross",A26,I26) -> Gujarat
A28: Flared | I28: =IF(LEFT(A28,5)="Gross",A27,I27) -> Gujarat
A29: Net Availability | I29: =IF(LEFT(A29,5)="Gross",A28,I28) -> Gujarat
A30: Internal Use+Losses | I30: =IF(LEFT(A30,5)="Gross",A29,I29) -> Gujarat
A31: Net Production (Sales) | H31: 635.05 | I31: =IF(LEFT(A31,5)="Gross",A30,I30) -> Gujarat
A32: % Flared to GP | I32: =IF(LEFT(A32,5)="Gross",A31,I31) -> Gujarat
A33: Tamil Nadu
A34: Gross Production | H34: 1066.52 | I34: =IF(LEFT(A34,5)="Gross",A33,I33) -> Tamil Nadu
A35: Flared | I35: =IF(LEFT(A35,5)="Gross",A34,I34) -> Tamil Nadu
A36: Net Availability | I36: =IF(LEFT(A36,5)="Gross",A35,I35) -> Tamil Nadu
A37: Internal Use+Losses | I37: =IF(LEFT(A37,5)="Gross",A36,I36) -> Tamil Nadu
A38: Net Production (Sales) | H38: 1038.08 | I38: =IF(LEFT(A38,5)="Gross",A37,I37) -> Tamil Nadu
A39: % Flared to GP | I39: =IF(LEFT(A39,5)="Gross",A38,I38) -> Tamil Nadu
A40: Andhra Pradesh
...

Sheet Crude Oil Production
A1: II.12 Production of Crude Oil and Condensate (Financial Year-wise)
A2: State / Region | B2: 2021-22 (P)
A3: -1 | B3: -8
A4: 1. Crude Oil Production (TMT)
A5: (a) Onshore | C5: Tax Rate
A6: Andhra Pradesh | B6: 202 | C6: ='Tax Rates'!B6 -> 0.05 | D6: =B6*C6 -> 10.1
A7: Arunachal Pradesh | B7: 48 | C7: ='Tax Rates'!B7 -> 0.04 | D7: =B7*C7 -> 1.92
A8: Assam | B8: 3988 | C8: ='Tax Rates'!B8 -> 0.05 | D8: =B8*C8 -> 199.4
A9: Gujarat | B9: 4627 | C9: ='Tax Rates'!B14 -> 0.05 | D9: =B9*C9 -> 231.35
A10: Rajasthan | B10: 5887 | C10: ='Tax Rates'!B30 -> 0.05 | D10: =B10*C10 -> 294.35
A11: Tamil Nadu | B11: 367 | C11: ='Tax Rates'!B33 -> 0.05 | D11: =B11*C11 -> 18.35
A12: Total (a) | B12: 15122 | D12: =SUM(D6:D11) -> 755.47
A13: (b) Offshore | D13: =D12/B12 -> 0.049958339 | E13: <-- Weighted tax rate
A14: ONGC | B14: 13619
A15: PSC Regime | B15: 950
A16: Total (b) | B16: 14569

Sheet Coal & Lignite
A1: Coal & Lignite Pit head values (2021-22) | E1: Pit Head Prices of Non-Coking coal (2023)
B2: Coal | C2: Lignite | E2: Prices for Power Utilities (May 2023) (Rs./ton)
A3: Production | B3: 778.21 | C3: 47.37 | E3: Table I | F3: Table II
A4: Pit head value | B4: 1076698.8 | C4: 71267.6 | E4: 1240 | F4: 1490
A5: Value per unit produced | B5: =B4/B3 -> 1383.5582 | C5: =C4/C3 -> 1504.4881 | E5: Avg. (Rs./ton) | F5: =AVERAGE(E4:F4) -> 1365
E6: *Price considered for median grade (G9)
A7: Source: Ministry of Coal, 2021 | E7: Source: Price Notification (May 2023), Coal India Ltd.
A8: Pit head value - coal directory of India 2020-21 | E8: Tables I and II
A10: Scaled Lignite Cost (2021)* | E10: Freight Rates (Coal Transport) (Rs./ton)
A11: =F5*(C5/B5) -> 1484.3078 | B11: Rs./ton | E11: Distance slabs (km)* | F11: Class 145A (Wagon load)
A12: *Scaling is done relative to per unit pit head value of coal in 2018 | E12: 426 - 500 | F12: 1054.7
A14: Price Build-up of Coal & Lignite (2023) (Rs./ton) | E14: Source: Unstarred question - Ministry of parliamentary affairs, coal and mines (https://coal.gov.in/sites/default/files/2022-09/1644383577_1264.PDF)
B15: Coal | C15: Lignite | E15: Rate class 145A (Train Rate)
A16: Pit Head Price | B16: =F5 -> 1365 | C16: =A11 -> 1484.3078
A17: GST (@5%) | B17: =0.05*B16 -> 68.25 | C17: =0.05*C16 -> 74.215392 | E17: *Assumption for average distance transported: "According to Coal India executives, coal travels about 477 km on average from pithead to destination." -- Source: https://economictimes.indiatimes.com/industry/indl-goods/svs/metals-mining/coal-india-looks-to-cut-power-producers-transport-costs/articleshow/61192411.cms?from=mdr
A18: Compensation Cess | B18: 400 | C18: 400
A19: Royalty (@14%-coal;6%-lignite) | B19: =0.14*B16 -> 191.1 | C19: =0.06*C16 -> 89.05847
A20: Transportation | B20: =F12 -> 1054.7 | C20: =F12 -> 1054.7
A21: Transportation tax* (@5%) | B21: =0.05*B20 -> 52.735 | C21: =0.05*C20 -> 52.735
A22: Final Price | B22: =SUM(B16:B21) -> 3131.785 | C22: =SUM(C16:C21) -> 3155.0167
A23: Tax fraction (GST + Cess + Royalty+Transport tax) | B23: =SUM(B17:B19,B21)/B22 -> 0.22737353 | C23: =SUM(C17:C19,C21)/C22 -> 0.19524742
A25: *Transportation tax of 5% under GST: "Under GST, the tax rate on transportation services through rail has been charged at the rate of 5%." -- Source: https://cleartax.in/s/6815

Sheet Fuel Oil & LPG
A1: IV.15: GST Rates Applicable on Select Petroleum Products (As on 01.04.2022)
A2: Product | B2: Central | C2: State/UT | D2: (in %)
A3: Fuel Oil | B3: 9 | C3: 9
A4: LPG - Domestic | B4: 2.5 | C4: 2.5
A5: Source: Indian Petroleum and Natural Gas Statistics, 2021-22 (MoPNG)
A6: Table IV.15, Page 115

Sheet Start Year Taxes
B1: Tax Fraction
A2: hard coal | B2: ='Coal & Lignite'!B23 -> 0.22737353
A3: natural gas | B3: =SUMPRODUCT('Tax Rates'!C6:C38,'Tax Rates'!Z6:Z38)/SUM('Tax Rates'!Z6:Z38) -> 0.1300879
A4: petroleum gasoline | B4: ='Petroleum & Diesel Prices'!B9 -> 0.49449743
A5: petroleum diesel | B5: ='Petroleum & Diesel Prices'!C9 -> 0.4272528
A6: jet fuel | B6: =SUMPRODUCT('Tax Rates'!Y6:Y38,'Tax Rates'!P6:P38)/SUM('Tax Rates'!Y6:Y38) -> 0.17497962
A7: biofuel gasoline | B7: 0.05
A8: biofuel diesel | B8: 0.05
A9: electricity | B9: =SUMPRODUCT('Electricity Tax Rates'!B30:G53,'Electricity Tax Rates'!B57:G80)/SUM('Electricity Tax Rates'!B57:G80) -> 0.063888703
A10: biomass | B10: 0.05
A11: lignite | B11: ='Coal & Lignite'!C23 -> 0.19524742
A12: crude oil | B12: ='Crude Oil Production'!D13 -> 0.049958339
A13: heavy fuel oil | B13: =SUM('Fuel Oil & LPG'!B3:C3)/100 -> 0.18
A14: LPG propane or butane | B14: =SUM('Fuel Oil & LPG'!B4:C4)/100 -> 0.05
A15: municipal solid waste | B15: 0
A16: hydrogen | B16: =B9 -> 0.063888703
A21: Others
A22: Kersoene (PDS SKO) | B22: 1.1 | C22: Rs/liter

Sheet Tax_Share of Price
A1: Share of Price That is Tax (dimensionless) | B1: 2017 | C1: 2018 | D1: 2019 | E1: 2020 | F1: 2021 | G1: 2022 | H1: 2023 | I1: 2024 | J1: 2025 | K1: 2026 | L1: 2027 | M1: 2028 | N1: 2029 | O1: 2030 | P1: 2031 | Q1: 2032 | R1: 2033 | S1: 2034 | T1: 2035 | U1: 2036 | V1: 2037 | W1: 2038 | X1: 2039 | Y1: 2040 | Z1: 2041 | AA1: 2042 | AB1: 2043 | AC1: 2044 | AD1: 2045 | AE1: 2046 | AF1: 2047 | AG1: 2048 | AH1: 2049 | AI1: 2050
A2: electricity | B2: ='Start Year Taxes'!B9 -> 0.063888703 | C2: =B2 -> 0.063888703 | D2: =C2 -> 0.063888703 | E2: =D2 -> 0.063888703 | F2: =E2 -> 0.063888703 | G2: =F2 -> 0.063888703 | H2: =G2 -> 0.063888703 | I2: =H2 -> 0.063888703 | J2: =I2 -> 0.063888703 | ... AI2: =AH2 -> 0.063888703
A3: Coal | B3: ='Start Year Taxes'!B2 -> 0.22737353 | C3: =B3 -> 0.22737353 | D3: =C3 -> 0.22737353 | E3: =D3 -> 0.22737353 | F3: =E3 -> 0.22737353 | G3: =F3 -> 0.22737353 | H3: =G3 -> 0.22737353 | I3: =H3 -> 0.22737353 | J3: =I3 -> 0.22737353 | ... AI3: =AH3 -> 0.22737353
A4: natural gas | B4: ='Start Year Taxes'!B3 -> 0.1300879 | C4: =B4 -> 0.1300879 | D4: =C4 -> 0.1300879 | E4: =D4 -> 0.1300879 | F4: =E4 -> 0.1300879 | G4: =F4 -> 0.1300879 | H4: =G4 -> 0.1300879 | I4: =H4 -> 0.1300879 | J4: =I4 -> 0.1300879 | ... AI4: =AH4 -> 0.1300879
A5: nuclear | B5: =About!$G$59 -> 0 | C5: =B5 -> 0 | D5: =C5 -> 0 | E5: =D5 -> 0 | F5: =E5 -> 0 | G5: =F5 -> 0 | H5: =G5 -> 0 | I5: =H5 -> 0 | J5: =I5 -> 0 | ... AI5: =AH5 -> 0
A6: Hydro | B6: 0 | C6: =B6 -> 0 | D6: =C6 -> 0 | E6: =D6 -> 0 | F6: =E6 -> 0 | G6: =F6 -> 0 | H6: =G6 -> 0 | I6: =H6 -> 0 | J6: =I6 -> 0 | ... AI6: =AH6 -> 0
A7: Wind | B7: 0 | C7: =B7 -> 0 | D7: =C7 -> 0 | E7: =D7 -> 0 | F7: =E7 -> 0 | G7: =F7 -> 0 | H7: =G7 -> 0 | I7: =H7 -> 0 | J7: =I7 -> 0 | ... AI7: =AH7 -> 0
A8: Solar | B8: 0 | C8: =B8 -> 0 | D8: =C8 -> 0 | E8: =D8 -> 0 | F8: =E8 -> 0 | G8: =F8 -> 0 | H8: =G8 -> 0 | I8: =H8 -> 0 | J8: =I8 -> 0 | ... AI8: =AH8 -> 0
A9: biomass | B9: ='Start Year Taxes'!B10 -> 0.05 | C9: =B9 -> 0.05 | D9: =C9 -> 0.05 | E9: =D9 -> 0.05 | F9: =E9 -> 0.05 | G9: =F9 -> 0.05 | H9: =G9 -> 0.05 | I9: =H9 -> 0.05 | J9: =I9 -> 0.05 | ... AI9: =AH9 -> 0.05
A10: petroleum gasoline | B10: ='Start Year Taxes'!B4 -> 0.49449743 | C10: =B10 -> 0.49449743 | D10: =C10 -> 0.49449743 | E10: =D10 -> 0.49449743 | F10: =E10 -> 0.49449743 | G10: =F10 -> 0.49449743 | H10: =G10 -> 0.49449743 | I10: =H10 -> 0.49449743 | J10: =I10 -> 0.49449743 | ... AI10: =AH10 -> 0.49449743
A11: petroleum diesel | B11: ='Start Year Taxes'!B5 -> 0.4272528 | C11: =B11 -> 0.4272528 | D11: =C11 -> 0.4272528 | E11: =D11 -> 0.4272528 | F11: =E11 -> 0.4272528 | G11: =F11 -> 0.4272528 | H11: =G11 -> 0.4272528 | I11: =H11 -> 0.4272528 | J11: =I11 -> 0.4272528 | ... AI11: =AH11 -> 0.4272528
A12: biofuel gasoline | B12: ='Start Year Taxes'!B7 -> 0.05 | C12: =B12 -> 0.05 | D12: =C12 -> 0.05 | E12: =D12 -> 0.05 | F12: =E12 -> 0.05 | G12: =F12 -> 0.05 | H12: =G12 -> 0.05 | I12: =H12 -> 0.05 | J12: =I12 -> 0.05 | ... AI12: =AH12 -> 0.05
A13: biofuel diesel | B13: ='Start Year Taxes'!B8 -> 0.05 | C13: =B13 -> 0.05 | D13: =C13 -> 0.05 | E13: =D13 -> 0.05 | F13: =E13 -> 0.05 | G13: =F13 -> 0.05 | H13: =G13 -> 0.05 | I13: =H13 -> 0.05 | J13: =I13 -> 0.05 | ... AI13: =AH13 -> 0.05
A14: Jet Fuel or Kerosene | B14: ='Start Year Taxes'!B6 -> 0.17497962 | C14: =B14 -> 0.17497962 | D14: =C14 -> 0.17497962 | E14: =D14 -> 0.17497962 | F14: =E14 -> 0.17497962 | G14: =F14 -> 0.17497962 | H14: =G14 -> 0.17497962 | I14: =H14 -> 0.17497962 | J14: =I14 -> 0.17497962 | ... AI14: =AH14 -> 0.17497962
A15: heat | B15: 0 | C15: =B15 -> 0 | D15: =C15 -> 0 | E15: =D15 -> 0 | F15: =E15 -> 0 | G15: =F15 -> 0 | H15: =G15 -> 0 | I15: =H15 -> 0 | J15: =I15 -> 0 | ... AI15: =AH15 -> 0
A16: Geothermal | B16: =0 -> 0 | C16: =B16 -> 0 | D16: =C16 -> 0 | E16: =D16 -> 0 | F16: =E16 -> 0 | G16: =F16 -> 0 | H16: =G16 -> 0 | I16: =H16 -> 0 | J16: =I16 -> 0 | ... AI16: =AH16 -> 0
A17: lignite | B17: ='Start Year Taxes'!B11 -> 0.19524742 | C17: =B17 -> 0.19524742 | D17: =C17 -> 0.19524742 | E17: =D17 -> 0.19524742 | F17: =E17 -> 0.19524742 | G17: =F17 -> 0.19524742 | H17: =G17 -> 0.19524742 | I17: =H17 -> 0.19524742 | J17: =I17 -> 0.19524742 | ... AI17: =AH17 -> 0.19524742
A18: crude oil | B18: ='Start Year Taxes'!B12 -> 0.049958339 | C18: =B18 -> 0.049958339 | D18: =C18 -> 0.049958339 | E18: =D18 -> 0.049958339 | F18: =E18 -> 0.049958339 | G18: =F18 -> 0.049958339 | H18: =G18 -> 0.049958339 | I18: =H18 -> 0.049958339 | J18: =I18 -> 0.049958339 | ... AI18: =AH18 -> 0.049958339
A19: heavy fuel oil | B19: ='Start Year Taxes'!B13 -> 0.18 | C19: =B19 -> 0.18 | D19: =C19 -> 0.18 | E19: =D19 -> 0.18 | F19: =E19 -> 0.18 | G19: =F19 -> 0.18 | H19: =G19 -> 0.18 | I19: =H19 -> 0.18 | J19: =I19 -> 0.18 | ... AI19: =AH19 -> 0.18
A20: LPG propane or butane | B20: ='Start Year Taxes'!B14 -> 0.05 | C20: =B20 -> 0.05 | D20: =C20 -> 0.05 | E20: =D20 -> 0.05 | F20: =E20 -> 0.05 | G20: =F20 -> 0.05 | H20: =G20 -> 0.05 | I20: =H20 -> 0.05 | J20: =I20 -> 0.05 | ... AI20: =AH20 -> 0.05
A21: municipal solid waste | B21: ='Start Year Taxes'!B15 -> 0 | C21: =B21 -> 0 | D21: =C21 -> 0 | E21: =D21 -> 0 | F21: =E21 -> 0 | G21: =F21 -> 0 | H21: =G21 -> 0 | I21: =H21 -> 0 | J21: =I21 -> 0 | ... AI21: =AH21 -> 0
A22: hydrogen | B22: ='Start Year Taxes'!B16 -> 0.063888703 | C22: =B22 -> 0.063888703 | D22: =C22 -> 0.063888703 | E22: =D22 -> 0.063888703 | F22: =E22 -> 0.063888703 | G22: =F22 -> 0.063888703 | H22: =G22 -> 0.063888703 | I22: =H22 -> 0.063888703 | J22: =I22 -> 0.063888703 | ... AI22: =AH22 -> 0.063888703

Sheet Total Fuel Cost>

Sheet Conversion Factors
A1: Currency | E1: Historical Consumer Price Index for All Urban Consumers (CPI-U): U.S. city average, all items, index
A2: India Inflation Rates | B2: See scaling-factors.xlsx for source info | E2: See cpi.xlsx for source info
A3: Year | B3: Rate | C3: Value Indexed to 2012 | E3: Year | F3: Multiply by to get 2012 Dollars
A4: 2010 | B4: 0.0947 | C4: 0.84470209 | E4: 2010............................................................................. . | F4: 1.052913
A5: 2011 | B5: 0.0649 | C5: 0.89952325 | E5: 2011............................................................................. . | F5: 1.0206945
A6: 2012 | B6: 0.1117 | C6: 1 | E6: 2012............................................................................. . | F6: 1
A7: 2013 | B7: 0.0913 | C7: 1.0913 | E7: 2013............................................................................. . | F7: 0.98556386
A8: 2014 | B8: 0.0586 | C8: 1.1552502 | E8: 2014............................................................................. . | F8: 0.96983137
A9: 2015 | B9: 0.0632 | C9: 1.228262 | E9: 2015............................................................................. . | F9: 0.96868157
A10: 2016 | B10: 0.0223 | C10: 1.2556522 | E10: 2016............................................................................. . | F10: 0.95661377
A11: 2017 | B11: 0.04 | C11: 1.3058783 | E11: 2017............................................................................. . | F11: 0.9366596
A12: 2018 | B12: 0.0524 | C12: =C11*(1+B12) -> 1.3743063 | E12: 2018............................................................................. . | F12: 0.91432736
A13: 2019 | B13: 0.0766 | C13: =C12*(1+B13) -> 1.4795782 | E13: 2019............................................................................. . | F13: 0.898
A14: 2020 | B14: 0.0558 | C14: =C13*(1+B14) -> 1.5621387 | E14: 2020............................................................................. . | F14: 0.887
A15: 2021 | B15: 0.0489 | C15: =C14*(1+B15) -> 1.6385273
A17: Rupees per dollar | B17: See scaling-factors.xlsx for source info
A18: 2010 | B18: 44.81
A19: 2011 | B19: 53.26
A20: 2012 | B20: 54.77
A21: 2013 | B21: 61.89
A22: 2014 | B22: 63.33
A23: 2015 | B23: 66.32
A24: 2016 | B24: 67.95
A25: 2017 | B25: 63.92
A26: 2018 | B26: 68.66
A27: 2019 | B27: 70.897
A28: 2020 | B28: 74.225
A29: 2021 | B29: 74.504
A31: Source: Economic Survey (30.01.2023) https://www.indiabudget.gov.in/economicsurvey/doc/stat/tab54.pdf
A33: Fuel-Independent Conversion Factors
A34: liters per barrel | B34: 158.9873
A35: BTU/kcal | B35: 3.96567
A36: BTU/kWh (unit conversion, not a heat rate) | B36: 3412.14
A38: Energy in Biomass
A39: Wood wastes | B39: =AVERAGE(2500,3850) -> 3175 | C39: kcal/kg
A40: Cowdung | B40: =AVERAGE(3140,3290) -> 3215 | C40: kcal/kg
A41: Average of biomass fuels | B41: =AVERAGE(B39:B40) -> 3195 | C41: kcal/kg
B42: 3.96567 | C42: BTU/kcal
B43: =B41*B42 -> 12670.316 | C43: BTU/kg
B44: =B43*1000 -> 12670316 | C44: BTU/ton
...

Sheet AEO Table 73
B1: ref2021.d113020a | C1: 2020 | D1: 2021 | E1: 2022 | F1: 2023 | G1: 2024 | H1: 2025 | I1: 2026 | J1: 2027 | K1: 2028 | L1: 2029 | M1: 2030 | N1: 2031 | O1: 2032 | P1: 2033 | Q1: 2034 | R1: 2035 | S1: 2036 | T1: 2037 | U1: 2038 | V1: 2039 | W1: 2040 | X1: 2041 | Y1: 2042 | Z1: 2043 | AA1: 2044 | AB1: 2045 | AC1: 2046 | AD1: 2047 | AE1: 2048 | AF1: 2049 | AG1: 2050
C3: Report | D3: Annual Energy Outlook 2021
C4: Scenario | D4: ref2021 | G4: Reference case
C5: Datekey | D5: d113020a
C6: Release Date | E6: January 2021
A10: CNV000 | B10: 71. Conversion Factors | AH10: Compound
B11: (from physical units to million Btu) | AH11: Growth
AH12: 2020-2050
C13: 2020 | D13: 2021 | E13: 2022 | F13: 2023 | G13: 2024 | H13: 2025 | I13: 2026 | J13: 2027 | K13: 2028 | L13: 2029 | M13: 2030 | N13: 2031 | O13: 2032 | P13: 2033 | Q13: 2034 | R13: 2035 | S13: 2036 | T13: 2037 | U13: 2038 | V13: 2039 | W13: 2040 | X13: 2041 | Y13: 2042 | Z13: 2043 | AA13: 2044 | AB13: 2045 | AC13: 2046 | AD13: 2047 | AE13: 2048 | AF13: 2049 | AG13: 2050 | AH13: (percent)
B14: Petroleum and Other Liquids
B15: (million Btu per barrel)
A16: CNV000:aa_AsphaltandRoa | B16: Asphalt and Road Oil | C16: 6.636 | D16: 6.636 | E16: 6.636 | F16: 6.636 | G16: 6.636 | H16: 6.636 | I16: 6.636 | J16: 6.636 | K16: 6.636 | L16: 6.636 | M16: 6.636 | N16: 6.636 | O16: 6.636 | P16: 6.636 | Q16: 6.636 | R16: 6.636 | S16: 6.636 | T16: 6.636 | U16: 6.636 | V16: 6.636 | W16: 6.636 | X16: 6.636 | Y16: 6.636 | Z16: 6.636 | AA16: 6.636 | AB16: 6.636 | AC16: 6.636 | AD16: 6.636 | AE16: 6.636 | AF16: 6.636 | AG16: 6.636 | AH16: 0
A17: CNV000:aa_AviationGasol | B17: Aviation Gasoline | C17: 5.048 | D17: 5.048 | E17: 5.048 | F17: 5.048 | G17: 5.048 | H17: 5.048 | I17: 5.048 | J17: 5.048 | K17: 5.048 | L17: 5.048 | M17: 5.048 | N17: 5.048 | O17: 5.048 | P17: 5.048 | Q17: 5.048 | R17: 5.048 | S17: 5.048 | T17: 5.048 | U17: 5.048 | V17: 5.048 | W17: 5.048 | X17: 5.048 | Y17: 5.048 | Z17: 5.048 | AA17: 5.048 | AB17: 5.048 | AC17: 5.048 | AD17: 5.048 | AE17: 5.048 | AF17: 5.048 | AG17: 5.048 | AH17: 0
A18: CNV000:ea_Biodiesel | B18: Biodiesel | C18: 5.359 | D18: 5.359 | E18: 5.359 | F18: 5.359 | G18: 5.359 | H18: 5.359 | I18: 5.359 | J18: 5.359 | K18: 5.359 | L18: 5.359 | M18: 5.359 | N18: 5.359 | O18: 5.359 | P18: 5.359 | Q18: 5.359 | R18: 5.359 | S18: 5.359 | T18: 5.359 | U18: 5.359 | V18: 5.359 | W18: 5.359 | X18: 5.359 | Y18: 5.359 | Z18: 5.359 | AA18: 5.359 | AB18: 5.359 | AC18: 5.359 | AD18: 5.359 | AE18: 5.359 | AF18: 5.359 | AG18: 5.359 | AH18: 0
A19: CNV000:aa_Distillate | B19: Distillate Fuel Oil | C19: 5.825 | D19: 5.825 | E19: 5.825 | F19: 5.825 | G19: 5.825 | H19: 5.825 | I19: 5.825 | J19: 5.825 | K19: 5.825 | L19: 5.825 | M19: 5.825 | N19: 5.825 | O19: 5.825 | P19: 5.825 | Q19: 5.825 | R19: 5.825 | S19: 5.825 | T19: 5.825 | U19: 5.825 | V19: 5.825 | W19: 5.825 | X19: 5.825 | Y19: 5.825 | Z19: 5.825 | AA19: 5.825 | AB19: 5.825 | AC19: 5.825 | AD19: 5.825 | AE19: 5.825 | AF19: 5.825 | AG19: 5.825 | AH19: 0
A20: CNV000:aa_Residential | B20: Residential | C20: 5.772225 | D20: 5.770434 | E20: 5.769468 | F20: 5.769597 | G20: 5.770083 | H20: 5.769742 | I20: 5.769996 | J20: 5.770608 | K20: 5.769846 | L20: 5.770197 | M20: 5.76971 | N20: 5.7698 | O20: 5.769487 | P20: 5.769598 | Q20: 5.769436 | R20: 5.769614 | S20: 5.770103 | T20: 5.769971 | U20: 5.770141 | V20: 5.769869 | W20: 5.770143 | X20: 5.770298 | Y20: 5.770511 | Z20: 5.770051 | AA20: 5.769538 | AB20: 5.769256 | AC20: 5.770041 | AD20: 5.769023 | AE20: 5.768785 | AF20: 5.768611 | AG20: 5.768018 | AH20: -2.4e-05
A21: CNV000:aa_Commercial | B21: Commercial | C21: 5.772225 | D21: 5.770434 | E21: 5.769468 | F21: 5.769597 | G21: 5.770083 | H21: 5.769742 | I21: 5.769996 | J21: 5.770608 | K21: 5.769846 | L21: 5.770197 | M21: 5.76971 | N21: 5.7698 | O21: 5.769487 | P21: 5.769598 | Q21: 5.769436 | R21: 5.769614 | S21: 5.770103 | T21: 5.769971 | U21: 5.770141 | V21: 5.769869 | W21: 5.770143 | X21: 5.770298 | Y21: 5.770511 | Z21: 5.770051 | AA21: 5.769538 | AB21: 5.769256 | AC21: 5.770041 | AD21: 5.769023 | AE21: 5.768785 | AF21: 5.768611 | AG21: 5.768018 | AH21: -2.4e-05
A22: CNV000:aa_Transportatio | B22: Transportation | C22: 5.772225 | D22: 5.770434 | E22: 5.769468 | F22: 5.769597 | G22: 5.770083 | H22: 5.769742 | I22: 5.769996 | J22: 5.770608 | K22: 5.769846 | L22: 5.770197 | M22: 5.76971 | N22: 5.7698 | O22: 5.769487 | P22: 5.769598 | Q22: 5.769436 | R22: 5.769614 | S22: 5.770103 | T22: 5.769971 | U22: 5.770141 | V22: 5.769869 | W22: 5.770143 | X22: 5.770298 | Y22: 5.770511 | Z22: 5.770051 | AA22: 5.769538 | AB22: 5.769256 | AC22: 5.770041 | AD22: 5.769023 | AE22: 5.768785 | AF22: 5.768611 | AG22: 5.768018 | AH22: -2.4e-05
A23: CNV000:aa_Industrial | B23: Industrial | C23: 5.772225 | D23: 5.770434 | E23: 5.769468 | F23: 5.769597 | G23: 5.770083 | H23: 5.769742 | I23: 5.769996 | J23: 5.770608 | K23: 5.769846 | L23: 5.770197 | M23: 5.76971 | N23: 5.7698 | O23: 5.769487 | P23: 5.769598 | Q23: 5.769436 | R23: 5.769614 | S23: 5.770103 | T23: 5.769971 | U23: 5.770141 | V23: 5.769869 | W23: 5.770143 | X23: 5.770298 | Y23: 5.770511 | Z23: 5.770051 | AA23: 5.769538 | AB23: 5.769256 | AC23: 5.770041 | AD23: 5.769023 | AE23: 5.768785 | AF23: 5.768611 | AG23: 5.768018 | AH23: -2.4e-05
A24: CNV000:aa_ElectricPower | B24: Electric Power | C24: 5.772225 | D24: 5.770434 | E24: 5.769468 | F24: 5.769597 | G24: 5.770083 | H24: 5.769742 | I24: 5.769996 | J24: 5.770608 | K24: 5.769846 | L24: 5.770197 | M24: 5.76971 | N24: 5.7698 | O24: 5.769487 | P24: 5.769598 | Q24: 5.769436 | R24: 5.769614 | S24: 5.770103 | T24: 5.769971 | U24: 5.770141 | V24: 5.769869 | W24: 5.770143 | X24: 5.770298 | Y24: 5.770511 | Z24: 5.770051 | AA24: 5.769538 | AB24: 5.769256 | AC24: 5.770041 | AD24: 5.769023 | AE24: 5.768785 | AF24: 5.768611 | AG24: 5.768018 | AH24: -2.4e-05
A25: CNV000:aa_TotalDistilla | B25: Total Distillate | C25: 5.772226 | D25: 5.770434 | E25: 5.769468 | F25: 5.769597 | G25: 5.770083 | H25: 5.769742 | I25: 5.769997 | J25: 5.770607 | K25: 5.769845 | L25: 5.770196 | M25: 5.76971 | N25: 5.7698 | O25: 5.769487 | P25: 5.769598 | Q25: 5.769436 | R25: 5.769614 | S25: 5.770103 | T25: 5.769971 | U25: 5.770141 | V25: 5.769869 | W25: 5.770143 | X25: 5.770298 | Y25: 5.770511 | Z25: 5.770051 | AA25: 5.769537 | AB25: 5.769256 | AC25: 5.770042 | AD25: 5.769023 | AE25: 5.768785 | AF25: 5.768611 | AG25: 5.768018 | AH25: -2.4e-05
A26: CNV000:aa_DistLowSulf | B26: Distillate Fuel Oil - Low Sulfur Diesel | C26: 5.817 | D26: 5.817 | E26: 5.817 | F26: 5.817 | G26: 5.817 | H26: 5.817 | I26: 5.817 | J26: 5.817 | K26: 5.817 | L26: 5.817 | M26: 5.817 | N26: 5.817 | O26: 5.817 | P26: 5.817 | Q26: 5.817 | R26: 5.817 | S26: 5.817 | T26: 5.817 | U26: 5.817 | V26: 5.817 | W26: 5.817 | X26: 5.817 | Y26: 5.817 | Z26: 5.817 | AA26: 5.817 | AB26: 5.817 | AC26: 5.817 | AD26: 5.817 | AE26: 5.817 | AF26: 5.817 | AG26: 5.817 | AH26: 0
A27: CNV000:aa_DistUltraLow | B27: Distillate Fuel Oil - Ultra Low Sulfur Diesel | C27: 5.77 | D27: 5.77 | E27: 5.77 | F27: 5.77 | G27: 5.77 | H27: 5.77 | I27: 5.77 | J27: 5.77 | K27: 5.77 | L27: 5.77 | M27: 5.77 | N27: 5.77 | O27: 5.77 | P27: 5.77 | Q27: 5.77 | R27: 5.77 | S27: 5.77 | T27: 5.77 | U27: 5.77 | V27: 5.77 | W27: 5.77 | X27: 5.77 | Y27: 5.77 | Z27: 5.77 | AA27: 5.77 | AB27: 5.77 | AC27: 5.77 | AD27: 5.77 | AE27: 5.77 | AF27: 5.77 | AG27: 5.77 | AH27: 0
