Workbook
Name BTU_per_GWh: 'Conversion Factors'!$A$3
Name BTU_per_kg_biomass: 'Conversion Factors'!$B$28
Name BTU_per_PJ: 'Conversion Factors'!$A$6
Name BTU_per_thousand_tons_kerosene: 'Conversion Factors'!$A$21
Name BTU_per_thousand_tons_LPG: 'Conversion Factors'!$A$14
Name Fraction_coal: [1]About!$C$50
Name Percent_rural: [1]About!$A$77
Name Percent_urban: [1]About!$A$76
Name preferences.energyunits: [2]Preferences!$C$3
Name quadrillion: [1]About!$B$79
Name Table4: '[1]AEO Table 4'!$C$34:$AI$72
Name Table5: '[1]AEO Table 5'!$C$31:$AI$58

Sheet About
A1: BCEU BAU Components Energy Use
A3: Sources: | B3: Future Year Scaling and non-electricity values | D3: Historical Trends - Urbanization Rates (to estimate demand growth in IESS low GDP trajectory)
B4: NITI Aayog | D4: World Bank
B5: 2023 | D5: 2021
B6: India Energy Security Scenarios | D6: Urban population (% of total population) - India
B7: http://indiaenergy.gov.in/iess/docs/IESS_Version2.2.xlsx | D7: https://data.worldbank.org/indicator/SP.URB.TOTL.IN.ZS?end=2020&locations=IN&start=2000
B8: Tables X.a and X.b
B10: Electricity Use in Residential and Commercial Buildings
B11: Government of India, Ministry of Statistics and Programme Implementation
B12: 2021
B13: Energy Statistics 2021
B14: http://mospi.nic.in/sites/default/files/reports_and_publication/ES/Energy%20Statistics%20India%2020211.pdf
B15: Table 6.8
B17: LPG and Kerosene Use in Buildings
B18: Government of India, Ministry of Statistics and Programme Implementation
B19: 2021
B20: Energy Statistics 2021
B21: http://mospi.nic.in/sites/default/files/reports_and_publication/ES/Energy%20Statistics%20India%2020211.pdf
B22: Tables 6.6(E) and 6.6(G)
B24: Biomass and Coal Use
B25: IIASA
B26: 2018
B27: GAINS Model: South Asia
B28: http://gains.iiasa.ac.at/models/index.html
B29: Activity Data, Energy use in the domestic sector by device type, ECLIPSE_V5a_CLE_base scenario
B31: Energy in LPG and Kerosene
B32: TERI
B33: 2021
B34: TERI Energy and Environmental Data Diary and Yearbook 2021-22
B35: TERI Energy & Environment Data Diary and Yearbook (TEDDY) 2021-22 by A TERI Publication buy online
B36: Page 15, Table 6
A38: Notes:
A39: Notes on Component Categorization
A40: Water heaters are categorized as appliances, not as part of the "heating"
A41: component. The "heating" component refers to heating of air and is affected by
A42: the building envelope, whereas appliances are not affected by envelope.
A43: District heat is not used in the buildings sector in India.
A45: In addition to electricity, kerosene is used for lighting in rural households.
A46: LPG (liquified petroleum gas) is an important cooking fuel in India.
A47: Heavy Fuel Oil consumption is not reported for domestic or commercial sectors in the sector-wise
...

Sheet Elec Use
A1: Table 6.8 (Excerpt): Year-wise Consumption of Electricity- Sectorwise
A3: in Giga Watt Hour = 106 Kilo Watt Hour
A4: Year | B4: Industry | C4: Agriculture | D4: Domestic | E4: Commercial | F4: Traction | G4: Others | H4: Total
F5: & | H5: Electricity
F6: Railways | H6: Consumed
A7: 1 | B7: 2 | C7: 3 | D7: 4 | E7: 5 | F7: 6 | G7: 7 | H7: 8=2 to 7
A17: 2016-17 | B17: 440206 | C17: 191151 | D17: 255826 | E17: 89825 | F17: 15683 | G17: 68493 | H17: 1061183
A18: 2017-18 | B18: 468613 | C18: 199247 | D18: 273545 | E18: 93755 | F18: 17433 | G18: 70834 | H18: 1123427
A19: 2018-19 | B19: 519196 | C19: 213409 | D19: 288243 | E19: 98228 | F19: 18837 | G19: 72058 | H19: 1209972
A22: 2018-19 | B22: 519196.29 | C22: 213409.18 | D22: 288243.11 | E22: 98227.65 | F22: 18837.43 | G22: 72057.98 | H22: 1209971.6
A23: 2019-20 | B23: 532819.7 | C23: 211294.89 | D23: 308745.36 | E23: 106047.13 | F23: 19147.99 | G23: 70030.74 | H23: 1248085.8
A24: 2020-21 | B24: 508776.19 | C24: 221303.44 | D24: 330808.94 | E24: 86950.28 | F24: 14668.02 | G24: 67701.13 | H24: 1230208
A27: Source : Central Electricity Authority.

Sheet LPG, Kerosene, Diesel Use
A1: LPG Use, 2016-17
A2: Residential buildings | B2: 18871 | C2: thousand metric tons | E2: =SUM(B2:B3)*BTU_per_thousand_tons_LPG -> 925234829937000
A3: Commercial buildings | B3: 1776 | C3: thousand metric tons
A4: LPG Use, 2017-18
A5: Residential buildings | B5: 20352 | C5: thousand metric tons
A6: Commercial buildings | B6: 2086 | C6: thousand metric tons
A7: LPG Use, 2018-19
A8: Residential buildings | B8: 21728 | C8: thousand metric tons
A9: Commercial buildings | B9: 2364 | C9: thousand metric tons
A11: LPG Use, 2018-19
A12: Residential buildings | B12: 21728 | C12: thousand metric tons
A13: Commercial buildings | B13: 2364 | C13: thousand metric tons
A15: LPG Use, 2019-20
A16: Residential buildings | B16: 23076 | C16: thousand metric tons
A17: Commercial buildings | B17: 2614 | C17: thousand metric tons
A19: LPG Use, 2020-21 | E19: =SUM(B20:B21)*BTU_per_thousand_tons_LPG -> 1.2105533e+15
A20: Residential buildings | B20: 25128 | C20: thousand metric tons
A21: Commercial buildings | B21: 1886 | C21: thousand metric tons
A23: LPG Use, 2021-22 (P)
A24: Residential buildings | B24: 25502 | C24: thousand metric tons | E24: =SUM(B24:B25)*BTU_per_thousand_tons_LPG -> 1.2431317e+15
A25: Commercial buildings | B25: 2239 | C25: thousand metric tons
H28: Source for consumption data of all 3 fuels: MoPNG (as reporetd in MoSPI's Annual Energy Statistics)
A29: We assume all LPG is used for appliances (primarily cooking,
A30: perhaps some water heating).
A32: Kerosene Use, 2016-17
A33: Residential buildings | B33: 5204.12 | C33: thousand metric tons
A34: Commercial buildings | B34: 77.11 | C34: thousand metric tons
A35: Kerosene Use, 2017-18
A36: Residential buildings | B36: 3633.59 | C36: thousand metric tons
A37: Commercial buildings | B37: 96.99 | C37: thousand metric tons
A38: Kerosene Use, 2018-19
A39: Residential buildings | B39: 3231.21 | C39: thousand metric tons
A40: Commercial buildings | B40: 97.3 | C40: thousand metric tons
A42: Kerosene Use, 2018-19
A43: Residential buildings | B43: 3231.21 | C43: thousand metric tons
A44: Commercial buildings | B44: 97.3 | C44: thousand metric tons
A46: Kerosene Use, 2019-20
A47: Residential buildings | B47: 2173.71 | C47: thousand metric tons
A48: Commercial buildings | B48: 86.52 | C48: thousand metric tons
A50: Kerosene Use, 2020-21
...

Sheet 2015 Activity Data
A1: Region | B1: Energy use by sector and fuel | C1: Brown coal/lignite grade 1 | D1: Brown coal/lignite grade 2 (also peat) | E1: Hard coal, grade 1 | F1: Hard coal, grade 2 | G1: Hard coal, grade 3 | H1: Derived coal (coke, briquettes) | I1: Agricultural residues | J1: Bagasse | K1: Biogas | L1: Biomass gasification | M1: Charcoal | N1: Dung | O1: Fuelwood | P1: Black liquor | Q1: Waste fuels, non-renewable | R1: Waste fuel, renewable | S1: Biomass fuels | T1: Other biomass and waste fuels | U1: Heavy fuel oil | V1: Diesel | W1: Gasoline | X1: LPG | Y1: Natural gas (incl. other gases) | Z1: Hydrogen | AA1: Renewable energy other than biomass | AB1: Geothermal | AC1: Small hydro power | AD1: Solar photovoltaic | AE1: Solar thermal | AF1: Wind | AG1: Hydro | AH1: Nuclear | AI1: Electricity | AJ1: Heat (steam, hot water)
A2: India, India Bihar | B2: Fuel conversion - combustion | C2: 0 | D2: 0 | E2: 2.65 | F2: 0 | G2: 0 | H2: 0 | I2: 0 | J2: 0 | K2: 0 | L2: 0 | M2: 0 | N2: 0 | O2: 0 | P2: 0 | Q2: 0 | R2: 0 | S2: 0 | T2: 0 | U2: 0 | V2: 0 | W2: 0 | X2: 0 | Y2: 0 | Z2: 0 | AA2: 0 | AB2: 0 | AC2: 0 | AD2: 0 | AE2: 0 | AF2: 0 | AG2: 0 | AH2: 0 | AI2: 0 | AJ2: 0
A3: India, India Bihar | B3: Transformation - losses | C3: 4.74 | D3: 0 | E3: 0 | F3: 264.35 | G3: 0 | H3: 0 | I3: 0 | J3: 0 | K3: 0 | L3: 0 | M3: 0 | N3: 0 | O3: 0 | P3: 0 | Q3: 0 | R3: 0 | S3: 0 | T3: 0 | U3: 0 | V3: 0 | W3: 0 | X3: 0 | Y3: 0 | Z3: 0 | AA3: 0 | AB3: 0 | AC3: 0 | AD3: 0 | AE3: 0 | AF3: 0 | AG3: 0 | AH3: 0 | AI3: 15.44 | AJ3: 2.16
A4: India, India Bihar | B4: Chemical industry (boilers) | C4: 0 | D4: 0 | E4: 0 | F4: 0 | G4: 0 | H4: 0 | I4: 0 | J4: 0 | K4: 0 | L4: 0 | M4: 0 | N4: 0 | O4: 0 | P4: 0 | Q4: 0 | R4: 0 | S4: 0.13 | T4: 0 | U4: 0 | V4: 0 | W4: 0 | X4: 0 | Y4: 0 | Z4: 0 | AA4: 0 | AB4: 0 | AC4: 0 | AD4: 0 | AE4: 0 | AF4: 0 | AG4: 0 | AH4: 0 | AI4: 0 | AJ4: -0.11
A5: India, India Bihar | B5: Transformation sector (boilers) | C5: 0 | D5: 0 | E5: 2.54 | F5: 0 | G5: 0 | H5: 0 | I5: 0 | J5: 0 | K5: 0 | L5: 0 | M5: 0 | N5: 0 | O5: 0 | P5: 0 | Q5: 0 | R5: 0 | S5: 0 | T5: 0 | U5: 0 | V5: 0 | W5: 0 | X5: 0 | Y5: 0 | Z5: 0 | AA5: 0 | AB5: 0 | AC5: 0 | AD5: 0 | AE5: 0 | AF5: 0 | AG5: 0 | AH5: 0 | AI5: 0 | AJ5: -2.16
A6: India, India Bihar | B6: Other industry (boilers; liquid and gaseous fuels) | C6: 0 | D6: 0 | E6: 0 | F6: 0 | G6: 0 | H6: 0 | I6: 0 | J6: 0 | K6: 0 | L6: 0 | M6: 0 | N6: 0 | O6: 0 | P6: 0 | Q6: 0 | R6: 0 | S6: 100.93 | T6: 0 | U6: 18.84 | V6: 0 | W6: 0 | X6: 0 | Y6: 8.03 | Z6: 0 | AA6: 0 | AB6: 0 | AC6: 0 | AD6: 0 | AE6: 0 | AF6: 0 | AG6: 0 | AH6: 0 | AI6: 0 | AJ6: -109.53
A7: India, India Bihar | B7: Other industry (large coal boilers; > 50 MWth ) | C7: 0.02 | D7: 0 | E7: 0 | F7: 1.12 | G7: 0 | H7: 0 | I7: 0 | J7: 0 | K7: 0 | L7: 0 | M7: 0 | N7: 0 | O7: 0 | P7: 0 | Q7: 0 | R7: 0 | S7: 0 | T7: 0 | U7: 0 | V7: 0 | W7: 0 | X7: 0 | Y7: 0 | Z7: 0 | AA7: 0 | AB7: 0 | AC7: 0 | AD7: 0 | AE7: 0 | AF7: 0 | AG7: 0 | AH7: 0 | AI7: 0 | AJ7: -0.97
A8: India, India Bihar | B8: Other industry (small coal boilers; < 50 MWth ) | C8: 0 | D8: 0 | E8: 0 | F8: 0 | G8: 0 | H8: 0 | I8: 0 | J8: 0 | K8: 0 | L8: 0 | M8: 0 | N8: 0 | O8: 0 | P8: 0 | Q8: 0 | R8: 0 | S8: 0 | T8: 0 | U8: 0 | V8: 0 | W8: 0 | X8: 0 | Y8: 0 | Z8: 0 | AA8: 0 | AB8: 0 | AC8: 0 | AD8: 0 | AE8: 0 | AF8: 0 | AG8: 0 | AH8: 0 | AI8: 0 | AJ8: 0
A9: India, India Bihar | B9: Paper & pulp (boilers) | C9: 0 | D9: 0 | E9: 6.11 | F9: 0 | G9: 0 | H9: 0 | I9: 0 | J9: 0 | K9: 0 | L9: 0 | M9: 0 | N9: 0 | O9: 0 | P9: 0 | Q9: 0 | R9: 0 | S9: 0.38 | T9: 0.38 | U9: 0 | V9: 0 | W9: 0 | X9: 0 | Y9: 0 | Z9: 0 | AA9: 0 | AB9: 0 | AC9: 0 | AD9: 0 | AE9: 0 | AF9: 0 | AG9: 0 | AH9: 0 | AI9: 0 | AJ9: -5.83
A10: India, India Bihar | B10: Other industry (furnaces) | C10: 0.48 | D10: 0 | E10: 2.43 | F10: 44.58 | G10: 0 | H10: 0.03 | I10: 0 | J10: 0 | K10: 0 | L10: 0 | M10: 0 | N10: 0 | O10: 0 | P10: 0 | Q10: 0 | R10: 0 | S10: 1.88 | T10: 0.08 | U10: 0.08 | V10: 14.28 | W10: 13.71 | X10: 0.18 | Y10: 13.78 | Z10: 0 | AA10: 0 | AB10: 0 | AC10: 0 | AD10: 0 | AE10: 0 | AF10: 0 | AG10: 0 | AH10: 0 | AI10: 121.21 | AJ10: 116.44
A11: India, India Bihar | B11: Non-energy use | C11: 0 | D11: 0 | E11: 0 | F11: 0 | G11: 0 | H11: 0 | I11: 0 | J11: 0 | K11: 0 | L11: 0 | M11: 0 | N11: 0 | O11: 0 | P11: 0 | Q11: 0 | R11: 0 | S11: 0 | T11: 0 | U11: 0 | V11: 0 | W11: 0 | X11: 0 | Y11: 0 | Z11: 0 | AA11: 0 | AB11: 0 | AC11: 0 | AD11: 0 | AE11: 0 | AF11: 0 | AG11: 0 | AH11: 0 | AI11: 0 | AJ11: 0
A12: India, India Bihar | B12: Diesel generator sets | C12: 0 | D12: 0 | E12: 0 | F12: 0 | G12: 0 | H12: 0 | I12: 0 | J12: 0 | K12: 0 | L12: 0 | M12: 0 | N12: 0 | O12: 0 | P12: 0 | Q12: 0 | R12: 0 | S12: 0 | T12: 0 | U12: 0.4 | V12: 5.8 | W12: 0 | X12: 0 | Y12: 0 | Z12: 0 | AA12: 0 | AB12: 0 | AC12: 0 | AD12: 0 | AE12: 0 | AF12: 0 | AG12: 0 | AH12: 0 | AI12: 0 | AJ12: 0
A13: India, India Bihar | B13: Power & district heat plants - existing coal (>50 MWth) | C13: 1.86 | D13: 0 | E13: 0 | F13: 33.56 | G13: 0 | H13: 0 | I13: 0 | J13: 0 | K13: 0 | L13: 0 | M13: 0 | N13: 0 | O13: 0 | P13: 0 | Q13: 0 | R13: 0 | S13: 0 | T13: 0 | U13: 0 | V13: 0 | W13: 0 | X13: 0 | Y13: 0 | Z13: 0 | AA13: 0 | AB13: 0 | AC13: 0 | AD13: 0 | AE13: 0 | AF13: 0 | AG13: 0 | AH13: 0 | AI13: 0 | AJ13: 0
... A1254: India, India Assam | B1254: Heating stoves | C1254: 0 | D1254: 0 | E1254: 0 | F1254: 0 | G1254: 0 | H1254: 0 | I1254: 0 | J1254: 0 | K1254: 0 | L1254: 0 | M1254: 0 | N1254: 0 | O1254: 4.04 | P1254: 0 | Q1254: 0 | R1254: 0 | S1254: 0 | T1254: 0 | U1254: 0 | V1254: 0 | W1254: 0 | X1254: 0 | Y1254: 0 | Z1254: 0 | AA1254: 0 | AB1254: 0 | AC1254: 0 | AD1254: 0 | AE1254: 0 | AF1254: 0 | AG1254: 0 | AH1254: 0 | AI1254: 0 | AJ1254: 0

Sheet 2020 Activity Data
A1: Region | B1: Energy use by sector and fuel | C1: Brown coal/lignite grade 1 | D1: Hard coal, grade 2 | E1: Agricultural residues | F1: Dung | G1: Fuelwood
A2: India Andhra Pradesh | B2: Medium boilers (<50MW) - automatic (commercial) | D2: 24.06 | G2: 5.57
A3: India Andhra Pradesh | B3: Medium boilers (<1MW) - manual (commercial) | D3: 0 | G3: 5.57
A4: India Andhra Pradesh | B4: Fireplaces (agr, forestry, other) | G4: 0
A5: India Andhra Pradesh | B5: Medium boilers (<50MW) - automatic (agr, forestry, other) | D5: 0 | G5: 0
A6: India Andhra Pradesh | B6: Medium boilers (<1MW) - manual (agr, forestry, other) | D6: 0 | G6: 0
A7: India Andhra Pradesh | B7: Three-stone stove (agr, forestry, other) | G7: 0.22
A8: India Andhra Pradesh | B8: Single house boilers (<50 kW) - automatic (agr, forestry, other) | D8: 0 | G8: 0
A9: India Andhra Pradesh | B9: Single house boilers (<50 kW) - manual (agr, forestry, other) | D9: 0 | G9: 0
A10: India Andhra Pradesh | B10: Cooking stoves (agr, forestry, other) | D10: 40.61 | G10: 20.47
A11: India Andhra Pradesh | B11: Heating stoves (agr, forestry, other) | D11: 0.83 | G11: 0.86
A12: India Andhra Pradesh | B12: Fireplaces (households) | G12: 0
A13: India Andhra Pradesh | B13: Three-stone stove (households) | E13: 1.02 | F13: 0.7 | G13: 2.56
A14: India Andhra Pradesh | B14: Single house boilers (<50 kW) - automatic (households) | D14: 0 | E14: 0 | G14: 0
A15: India Andhra Pradesh | B15: Single house boilers (<50 kW) - manual (households) | C15: 0 | D15: 0 | G15: 0
A16: India Andhra Pradesh | B16: Cooking stoves (households) | C16: 0.23 | D16: 2.24 | E16: 101.45 | F16: 69.44 | G16: 242.75
A17: India Andhra Pradesh | B17: Heating stoves (households) | C17: 0 | D17: 0.05 | E17: 0 | F17: 0 | G17: 10.22
A18: India Assam | B18: Medium boilers (<50MW) - automatic (commercial) | D18: 0.39 | G18: 0.86
A19: India Assam | B19: Medium boilers (<1MW) - manual (commercial) | D19: 0 | G19: 0.86
A20: India Assam | B20: Fireplaces (agr, forestry, other) | G20: 0
A21: India Assam | B21: Medium boilers (<50MW) - automatic (agr, forestry, other) | D21: 0 | G21: 0
A22: India Assam | B22: Medium boilers (<1MW) - manual (agr, forestry, other) | D22: 0 | G22: 0
A23: India Assam | B23: Three-stone stove (agr, forestry, other) | G23: 0.03
A24: India Assam | B24: Single house boilers (<50 kW) - automatic (agr, forestry, other) | D24: 0 | G24: 0
A25: India Assam | B25: Single house boilers (<50 kW) - manual (agr, forestry, other) | D25: 0 | G25: 0
A26: India Assam | B26: Cooking stoves (agr, forestry, other) | D26: 0.02 | G26: 2.8
A27: India Assam | B27: Heating stoves (agr, forestry, other) | D27: 0 | G27: 0.12
A28: India Assam | B28: Fireplaces (households) | G28: 0
A29: India Assam | B29: Three-stone stove (households) | E29: 0.42 | F29: 0.29 | G29: 1.05
A30: India Assam | B30: Single house boilers (<50 kW) - automatic (households) | D30: 0 | E30: 0 | G30: 0
A31: India Assam | B31: Single house boilers (<50 kW) - manual (households) | C31: 0 | D31: 0 | G31: 0
A32: India Assam | B32: Cooking stoves (households) | C32: 0.02 | D32: 0.21 | E32: 41.5 | F32: 28.4 | G32: 99.3
A33: India Assam | B33: Heating stoves (households) | C33: 0 | D33: 0 | E33: 0 | F33: 0 | G33: 4.18
A34: India Bihar | B34: Medium boilers (<50MW) - automatic (commercial) | D34: 3.51 | G34: 2.3
A35: India Bihar | B35: Medium boilers (<1MW) - manual (commercial) | D35: 0 | G35: 2.3
A36: India Bihar | B36: Fireplaces (agr, forestry, other) | G36: 0
A37: India Bihar | B37: Medium boilers (<50MW) - automatic (agr, forestry, other) | D37: 0 | G37: 0
A38: India Bihar | B38: Medium boilers (<1MW) - manual (agr, forestry, other) | D38: 0 | G38: 0
A39: India Bihar | B39: Three-stone stove (agr, forestry, other) | G39: 0.05
A40: India Bihar | B40: Single house boilers (<50 kW) - automatic (agr, forestry, other) | D40: 0 | G40: 0
...

Sheet Summed Activity Data
A1: 2015
B2: Brown coal/lignite grade 1 | C2: Brown coal/lignite grade 2 (also peat) | D2: Hard coal, grade 1 | E2: Hard coal, grade 2 | F2: Hard coal, grade 3 | G2: Derived coal (coke, briquettes) | H2: Agricultural residues | I2: Bagasse | J2: Biogas | K2: Biomass gasification | L2: Charcoal | M2: Dung | N2: Fuelwood | O2: Black liquor | P2: Waste fuels, non-renewable | Q2: Waste fuel, renewable | R2: Biomass fuels | S2: Other biomass and waste fuels | T2: Heavy fuel oil | U2: Diesel | V2: Gasoline | W2: LPG | X2: Natural gas (incl. other gases) | Y2: Hydrogen | Z2: Renewable energy other than biomass | AA2: Geothermal | AB2: Small hydro power | AC2: Solar photovoltaic | AD2: Solar thermal | AE2: Wind | AF2: Hydro | AG2: Nuclear | AH2: Electricity | AI2: Heat (steam, hot water)
A3: Row Labels | B3: Sum of Brown coal/lignite grade 1 | C3: Sum of Brown coal/lignite grade 2 (also peat) | D3: Sum of Hard coal, grade 1 | E3: Sum of Hard coal, grade 2 | F3: Sum of Hard coal, grade 3 | G3: Sum of Derived coal (coke, briquettes) | H3: Sum of Agricultural residues | I3: Sum of Bagasse | J3: Sum of Biogas | K3: Sum of Biomass gasification | L3: Sum of Charcoal | M3: Sum of Dung | N3: Sum of Fuelwood | O3: Sum of Black liquor | P3: Sum of Waste fuels, non-renewable | Q3: Sum of Waste fuel, renewable | R3: Sum of Biomass fuels | S3: Sum of Other biomass and waste fuels | T3: Sum of Heavy fuel oil | U3: Sum of Diesel | V3: Sum of Gasoline | W3: Sum of LPG | X3: Sum of Natural gas (incl. other gases) | Y3: Sum of Hydrogen | Z3: Sum of Renewable energy other than biomass | AA3: Sum of Geothermal | AB3: Sum of Small hydro power | AC3: Sum of Solar photovoltaic | AD3: Sum of Solar thermal | AE3: Sum of Wind | AF3: Sum of Hydro | AG3: Sum of Nuclear | AH3: Sum of Electricity | AI3: Sum of Heat (steam, hot water)
A4: Medium boilers (<50MW) - automatic (commercial) | B4: 0 | C4: 0 | D4: 0 | E4: 274.2 | F4: 0 | G4: 0 | H4: 0 | I4: 0 | J4: 0 | K4: 0 | L4: 0 | M4: 0 | N4: 63.84 | O4: 0 | P4: 0 | Q4: 0 | R4: 0 | S4: 0 | T4: 0 | U4: 0 | V4: 0 | W4: 0 | X4: 0 | Y4: 0 | Z4: 0 | AA4: 0 | AB4: 0 | AC4: 0 | AD4: 0 | AE4: 0 | AF4: 0 | AG4: 0 | AH4: 0 | AI4: 0
A5: Medium boilers (<1MW) - manual (commercial) | B5: 0 | C5: 0 | D5: 0 | E5: 0 | F5: 0 | G5: 0 | H5: 0 | I5: 0 | J5: 0 | K5: 0 | L5: 0 | M5: 0 | N5: 63.84 | O5: 0 | P5: 0 | Q5: 0 | R5: 0 | S5: 0 | T5: 0 | U5: 0 | V5: 0 | W5: 0 | X5: 0 | Y5: 0 | Z5: 0 | AA5: 0 | AB5: 0 | AC5: 0 | AD5: 0 | AE5: 0 | AF5: 0 | AG5: 0 | AH5: 0 | AI5: 0
A6: Fireplaces | B6: 0 | C6: 0 | D6: 0 | E6: 0 | F6: 0 | G6: 0 | H6: 0 | I6: 0 | J6: 0 | K6: 0 | L6: 0 | M6: 0 | N6: 0 | O6: 0 | P6: 0 | Q6: 0 | R6: 0 | S6: 0 | T6: 0 | U6: 0 | V6: 0 | W6: 0 | X6: 0 | Y6: 0 | Z6: 0 | AA6: 0 | AB6: 0 | AC6: 0 | AD6: 0 | AE6: 0 | AF6: 0 | AG6: 0 | AH6: 0 | AI6: 0
A7: Medium boilers (<50MW) - automatic | B7: 0 | C7: 0 | D7: 0 | E7: 0 | F7: 0 | G7: 0 | H7: 0 | I7: 0 | J7: 0 | K7: 0 | L7: 0 | M7: 0 | N7: 0 | O7: 0 | P7: 0 | Q7: 0 | R7: 0 | S7: 0 | T7: 0 | U7: 0 | V7: 0 | W7: 0 | X7: 0 | Y7: 0 | Z7: 0 | AA7: 0 | AB7: 0 | AC7: 0 | AD7: 0 | AE7: 0 | AF7: 0 | AG7: 0 | AH7: 0 | AI7: 0
A8: Medium boilers (<1MW) - manual | B8: 0 | C8: 0 | D8: 0 | E8: 0 | F8: 0 | G8: 0 | H8: 0 | I8: 0 | J8: 0 | K8: 0 | L8: 0 | M8: 0 | N8: 0 | O8: 0 | P8: 0 | Q8: 0 | R8: 0 | S8: 0 | T8: 0 | U8: 0 | V8: 0 | W8: 0 | X8: 0 | Y8: 0 | Z8: 0 | AA8: 0 | AB8: 0 | AC8: 0 | AD8: 0 | AE8: 0 | AF8: 0 | AG8: 0 | AH8: 0 | AI8: 0
A9: Three-stone stove | B9: 0 | C9: 0 | D9: 0 | E9: 0 | F9: 0 | G9: 0 | H9: 12.98 | I9: 0 | J9: 0 | K9: 0 | L9: 0 | M9: 8.88 | N9: 35.41 | O9: 0 | P9: 0 | Q9: 0 | R9: 0 | S9: 0 | T9: 0 | U9: 0 | V9: 0 | W9: 0 | X9: 0 | Y9: 0 | Z9: 0 | AA9: 0 | AB9: 0 | AC9: 0 | AD9: 0 | AE9: 0 | AF9: 0 | AG9: 0 | AH9: 0 | AI9: 0
A10: Single house boilers (<50 kW) - automatic | B10: 0 | C10: 0 | D10: 0 | E10: 0 | F10: 0 | G10: 0 | H10: 0 | I10: 0 | J10: 0 | K10: 0 | L10: 0 | M10: 0 | N10: 0 | O10: 0 | P10: 0 | Q10: 0 | R10: 0 | S10: 0 | T10: 0 | U10: 0 | V10: 0 | W10: 0 | X10: 0 | Y10: 0 | Z10: 0 | AA10: 0 | AB10: 0 | AC10: 0 | AD10: 0 | AE10: 0 | AF10: 0 | AG10: 0 | AH10: 0 | AI10: 0
A11: Single house boilers (<50 kW) - manual | B11: 0 | C11: 0 | D11: 0 | E11: 0 | F11: 0 | G11: 0 | H11: 0 | I11: 0 | J11: 0 | K11: 0 | L11: 0 | M11: 0 | N11: 0 | O11: 0 | P11: 0 | Q11: 0 | R11: 0 | S11: 0 | T11: 0 | U11: 0 | V11: 0 | W11: 0 | X11: 0 | Y11: 0 | Z11: 0 | AA11: 0 | AB11: 0 | AC11: 0 | AD11: 0 | AE11: 0 | AF11: 0 | AG11: 0 | AH11: 0 | AI11: 0
A12: Cooking stoves | B12: 11.4 | C12: 0 | D12: 0 | E12: 417.79 | F12: 0 | G12: 0 | H12: 1286.18 | I12: 0 | J12: 0 | K12: 0 | L12: 0 | M12: 880.34 | N12: 3365.19 | O12: 0 | P12: 0 | Q12: 0 | R12: 0 | S12: 0 | T12: 0 | U12: 0 | V12: 0 | W12: 0 | X12: 0 | Y12: 0 | Z12: 0 | AA12: 0 | AB12: 0 | AC12: 0 | AD12: 0 | AE12: 0 | AF12: 0 | AG12: 0 | AH12: 0 | AI12: 0
A13: Heating stoves | B13: 0.21 | C13: 0 | D13: 0 | E13: 8.51 | F13: 0 | G13: 0 | H13: 0 | I13: 0 | J13: 0 | K13: 0 | L13: 0 | M13: 0 | N13: 141.7 | O13: 0 | P13: 0 | Q13: 0 | R13: 0 | S13: 0 | T13: 0 | U13: 0 | V13: 0 | W13: 0 | X13: 0 | Y13: 0 | Z13: 0 | AA13: 0 | AB13: 0 | AC13: 0 | AD13: 0 | AE13: 0 | AF13: 0 | AG13: 0 | AH13: 0 | AI13: 0
A14: Grand Total | B14: 11.61 | C14: 0 | D14: 0 | E14: 700.5 | F14: 0 | G14: 0 | H14: 1299.16 | I14: 0 | J14: 0 | K14: 0 | L14: 0 | M14: 889.22 | N14: 3669.98 | O14: 0 | P14: 0 | Q14: 0 | R14: 0 | S14: 0 | T14: 0 | U14: 0 | V14: 0 | W14: 0 | X14: 0 | Y14: 0 | Z14: 0 | AA14: 0 | AB14: 0 | AC14: 0 | AD14: 0 | AE14: 0 | AF14: 0 | AG14: 0 | AH14: 0 | AI14: 0
A16: 2020
A17: Row Labels | B17: Sum of Brown coal/lignite grade 1 | C17: Sum of Hard coal, grade 2 | D17: Sum of Agricultural residues | E17: Sum of Dung | F17: Sum of Fuelwood
A18: Cooking stoves (agr, forestry, other) | C18: 258.97 | F18: 310.02
A19: Cooking stoves (households) | B19: 11.4 | C19: 111.02 | D19: 1332.12 | E19: 911.81 | F19: 3187.6
A20: Fireplaces (agr, forestry, other) | F20: 0
A21: Fireplaces (households) | F21: 0
A22: Heating stoves (agr, forestry, other) | C22: 5.28 | F22: 13.05
A23: Heating stoves (households) | B23: 0.21 | C23: 2.25 | D23: 0 | E23: 0 | F23: 134.21
A24: Medium boilers (<1MW) - manual (agr, forestry, other) | C24: 0 | F24: 0
A25: Medium boilers (<1MW) - manual (commercial) | C25: 0 | F25: 74.06
A26: Medium boilers (<50MW) - automatic (agr, forestry, other) | C26: 0 | F26: 0
A27: Medium boilers (<50MW) - automatic (commercial) | C27: 324.3 | F27: 74.06
A28: Single house boilers (<50 kW) - automatic (agr, forestry, other) | C28: 0 | F28: 0
A29: Single house boilers (<50 kW) - automatic (households) | C29: 0 | D29: 0 | F29: 0
A30: Single house boilers (<50 kW) - manual (agr, forestry, other) | C30: 0 | F30: 0
A31: Single house boilers (<50 kW) - manual (households) | B31: 0 | C31: 0 | F31: 0
A32: Three-stone stove (agr, forestry, other) | F32: 3.27
A33: Three-stone stove (households) | D33: 13.46 | E33: 9.21 | F33: 33.55
A34: Grand Total | B34: 11.61 | C34: 701.82 | D34: 1345.58 | E34: 921.02 | F34: 3829.82
B36: Sum of Agricultural Residues
A37: 2015 | B37: =H14 -> 1299.16
A38: 2020 | B38: =D34 -> 1345.58
A40: Interpolated 2017 Value for Agricultural residues | B40: =TREND(B37:B38,$A$37:$A$38,2017) -> 1317.728

Sheet India Urbanization Trends
A1: Data Source | B1: World Development Indicators
A2: Last Updated Date | B2: 44497
A4: Country Name | B4: Country Code | C4: Indicator Name | D4: Indicator Code | E4: 1960 | F4: 1961 | G4: 1962 | H4: 1963 | I4: 1964 | J4: 1965 | K4: 1966 | L4: 1967 | M4: 1968 | N4: 1969 | O4: 1970 | P4: 1971 | Q4: 1972 | R4: 1973 | S4: 1974 | T4: 1975 | U4: 1976 | V4: 1977 | W4: 1978 | X4: 1979 | Y4: 1980 | Z4: 1981 | AA4: 1982 | AB4: 1983 | AC4: 1984 | AD4: 1985 | AE4: 1986 | AF4: 1987 | AG4: 1988 | AH4: 1989 | AI4: 1990 | AJ4: 1991 | AK4: 1992 | AL4: 1993 | AM4: 1994 | AN4: 1995 | AO4: 1996 | AP4: 1997 | AQ4: 1998 | AR4: 1999 | AS4: 2000 | AT4: 2001 | AU4: 2002 | AV4: 2003 | AW4: 2004 | AX4: 2005 | AY4: 2006 | AZ4: 2007 | BA4: 2008 | BB4: 2009 | BC4: 2010 | BD4: 2011 | BE4: 2012 | BF4: 2013 | BG4: 2014 | BH4: 2015 | BI4: 2016 | BJ4: 2017 | BK4: 2018 | BL4: 2019 | BM4: 2020
A5: India | B5: IND | C5: Urban population (% of total population) | D5: SP.URB.TOTL.IN.ZS | E5: 17.924 | F5: 18.032 | G5: 18.218 | H5: 18.405 | I5: 18.595 | J5: 18.785 | K5: 18.977 | L5: 19.171 | M5: 19.366 | N5: 19.562 | O5: 19.76 | P5: 19.991 | Q5: 20.321 | R5: 20.653 | S5: 20.991 | T5: 21.332 | U5: 21.677 | V5: 22.026 | W5: 22.379 | X5: 22.736 | Y5: 23.098 | Z5: 23.417 | AA5: 23.647 | AB5: 23.879 | AC5: 24.113 | AD5: 24.348 | AE5: 24.585 | AF5: 24.823 | AG5: 25.063 | AH5: 25.305 | AI5: 25.547 | AJ5: 25.778 | AK5: 25.984 | AL5: 26.191 | AM5: 26.399 | AN5: 26.607 | AO5: 26.817 | AP5: 27.028 | AQ5: 27.24 | AR5: 27.453 | AS5: 27.667 | AT5: 27.918 | AU5: 28.244 | AV5: 28.572 | AW5: 28.903 | AX5: 29.235 | AY5: 29.569 | AZ5: 29.906 | BA5: 30.246 | BB5: 30.587 | BC5: 30.93 | BD5: 31.276 | BE5: 31.634 | BF5: 32.003 | BG5: 32.384 | BH5: 32.777 | BI5: 33.182 | BJ5: 33.6 | BK5: 34.03 | BL5: 34.472 | BM5: 34.926
A7: Trend-based Projection for low GDP BAU
A9: 20-yr trend
A10: 2000 | B10: 2020
A11: =AS5 -> 27.667 | B11: =BM5 -> 34.926
A12: Forecast till 2050
A13: 2021 | B13: 2022 | C13: 2023 | D13: 2024 | E13: 2025 | F13: 2026 | G13: 2027 | H13: 2028 | I13: 2029 | J13: 2030 | K13: 2031 | L13: 2032 | M13: 2033 | N13: 2034 | O13: 2035 | P13: 2036 | Q13: 2037 | R13: 2038 | S13: 2039 | T13: 2040 | U13: 2041 | V13: 2042 | W13: 2043 | X13: 2044 | Y13: 2045 | Z13: 2046 | AA13: 2047 | AB13: 2048 | AC13: 2049 | AD13: 2050
A14: =FORECAST(A13,$A$11:$B$11,$A$10:$B$10) -> 35.28895 | B14: =FORECAST(B13,$A$11:$B$11,$A$10:$B$10) -> 35.6519 | C14: =FORECAST(C13,$A$11:$B$11,$A$10:$B$10) -> 36.01485 | D14: =FORECAST(D13,$A$11:$B$11,$A$10:$B$10) -> 36.3778 | E14: =FORECAST(E13,$A$11:$B$11,$A$10:$B$10) -> 36.74075 | F14: =FORECAST(F13,$A$11:$B$11,$A$10:$B$10) -> 37.1037 | G14: =FORECAST(G13,$A$11:$B$11,$A$10:$B$10) -> 37.46665 | H14: =FORECAST(H13,$A$11:$B$11,$A$10:$B$10) -> 37.8296 | ... AD14: =FORECAST(AD13,$A$11:$B$11,$A$10:$B$10) -> 45.8145
A16: 5-yr averages for plugging into IESS (Global Assumptions tab)
A17: 2012 | B17: 2017 | C17: 2022 | D17: 2027 | E17: 2032 | F17: 2037 | G17: 2042 | H17: 2047
A18: - | B18: =AVERAGE(BF5:BJ5) -> 32.7892 | C18: =AVERAGE(BK5:BM5,A14:B14) -> 34.87377 | D18: =AVERAGE(C14:G14) -> 36.74075 | E18: =AVERAGE(H14:L14) -> 38.5555 | F18: =AVERAGE(M14:Q14) -> 40.37025 | G18: =AVERAGE(R14:V14) -> 42.185 | H18: =AVERAGE(W14:AA14) -> 43.99975

Sheet IESS Demand
A1: IESS Residential Demand
D2: Units | F2: 2020 | G2: 2022 | H2: 2023 | I2: 2027 | J2: 2032 | K2: 2037 | L2: 2042 | M2: 2047 | N2: 2050 | O2: 2055 | P2: 2060 | Q2: 2065 | R2: 2070
A3: IX | F3: 108.37652 | G3: 143.91225 | T3: =SUM(M5,M6,M15,M22,M28,M33,M34,-M108) -> 947.50626
A4: H.01 | B4: Cooling Demand from the Residential Sector | F4: 199.62891 | G4: 315.01872 | H4: 552.83731 | I4: 806.48613 | J4: 1171.2404 | K4: 1587.2321 | L4: 2008.6954 | M4: 2446.1441
B5: Electricity Demand by Ceiling Fans* | D5: TWh/year | F5: 37.188085 | G5: 40.27943 | H5: 41.688002 | I5: 47.588454 | J5: 55.52488 | K5: 63.976974 | L5: 72.819446 | M5: 82.019951 | N5: 85.391408 | O5: 90.603246 | P5: 95.289762 | Q5: 99.365459 | R5: 102.73169
B6: Electricity Demand by Acs* | D6: TWh/year | F6: 11.445828 | G6: 16.218951 | H6: 18.822807 | I6: 31.049043 | J6: 50.839618 | K6: 76.236633 | L6: 107.77935 | M6: 146.05972 | N6: 165.50738 | O6: 200.37935 | P6: 238.13146 | Q6: 278.31186 | R6: 320.29639
A7: * | B7: http://www.moef.nic.in/downloads/public-information/Residentialpowerconsumption.pdf | E7: Net Electricity Demand for cooling for the base year is being matched to the electricity demand for cooling as mentioned in this MoEF report.
B11: Lighting
B12: No of Appliances | F12: 5.9444746e+08 | G12: 6.5939782e+08 | H12: 6.936695e+08 | I12: 8.4310156e+08 | J12: 1.058795e+09 | K12: 1.3072759e+09 | L12: 1.5886741e+09 | M12: 1.9048479e+09 | N12: 2.1167937e+09 | O12: 2.4867922e+09 | P12: 2.8756193e+09 | Q12: 3.2785352e+09 | R12: 3.6893982e+09
A13: x | B13: Weighted usage hours | D13: Hours | F13: 188 | G13: 187.62419 | H13: 187.43656 | I13: 186.68794 | J13: 185.75637 | K13: 184.82944 | L13: 183.90714 | M13: 182.98944 | N13: 182.44102 | O13: 181.53064 | P13: 180.6248 | Q13: 179.72348 | R13: 178.82666
A14: x | B14: Weighted average of Wattage Efficiency | D14: GW | F14: 3.9196e-08 | G14: 3.9196e-08 | H14: 3.9196e-08 | I14: 3.9196e-08 | J14: 3.9196e-08 | K14: 3.9196e-08 | L14: 3.9196e-08 | M14: 3.9196e-08 | N14: 3.9196e-08 | O14: 3.9196e-08 | P14: 3.9196e-08 | Q14: 3.9196e-08 | R14: 3.9196e-08
A15: = | B15: Total demand by lighting | D15: TWh/year | F15: 36.935261 | G15: 39.659085 | H15: 41.065718 | I15: 46.987261 | J15: 55.046071 | K15: 63.781953 | L15: 73.134468 | M15: 83.141732 | N15: 92.58647 | O15: 108.99206 | P15: 126.11236 | Q15: 143.71631 | R15: 161.5155
B18: Televisions
B19: Demand scenario | F19: 68305377 | G19: 83587665 | H19: 91824501 | I19: 1.2895238e+08 | J19: 1.7103611e+08 | K19: 1.9609138e+08 | L19: 2.2241437e+08 | M19: 2.5001129e+08 | N19: 2.6243922e+08 | O19: 2.8264235e+08 | P19: 3.0218372e+08 | Q19: 3.208098e+08 | R19: 3.3819484e+08
A20: x | B20: Weighted usage hours | D20: Hours | F20: 2190 | G20: 2190 | H20: 2190 | I20: 2190 | J20: 2190 | K20: 2190 | L20: 2190 | M20: 2190 | N20: 2190 | O20: 2190 | P20: 2190 | Q20: 2190 | R20: 2190
A21: x | B21: Weighted average of efficiency | D21: GW | F21: 7.935e-08 | G21: 7.5519232e-08 | H21: 7.182782e-08 | I21: 6.8272288e-08 | J21: 6.4849241e-08 | K21: 6.2373315e-08 | L21: 5.9996982e-08 | M21: 5.7717788e-08 | N21: 5.7717788e-08 | O21: 5.7717788e-08 | P21: 5.7717788e-08 | Q21: 5.7717788e-08 | R21: 5.7717788e-08
A22: = | B22: Total demand by televisions | D22: TWh/year | F22: 12.030495 | G22: 15.732004 | H22: 17.68358 | I22: 26.453955 | J22: 39.68799 | K22: 55.532038 | L22: 74.003609 | M22: 95.161239 | N22: 98.560828 | O22: 103.77639 | P22: 108.43793 | Q22: 112.47726 | R22: 115.80942
B24: Refrigirators
B25: Demand scenario | F25: 51871542 | G25: 75905252 | H25: 1.0516326e+08 | I25: 1.3926384e+08 | J25: 1.7903205e+08 | K25: 2.1410127e+08 | L25: 2.5176571e+08 | M25: 2.8991009e+08
A26: x | B26: Weighted usage hours | D26: Hours | F26: 1 | G26: 1 | H26: 1 | I26: 1 | J26: 1 | K26: 1 | L26: 1 | M26: 1
A27: x | B27: Weighted average of efficiency | D27: GW | F27: 4.09492e-07 | G27: 3.7517455e-07 | H27: 3.4347502e-07 | I27: 3.1425185e-07 | J27: 2.8737011e-07 | K27: 2.6950189e-07 | L27: 2.5295343e-07 | M27: 2.3765666e-07
A28: = | B28: Total demand by refrigirators | D28: TWh/year | F28: 21.240981 | G28: 28.477718 | H28: 36.120953 | I28: 43.763919 | J28: 51.44846 | K28: 57.700696 | L28: 63.684999 | M28: 68.899063
B31: Total demand by above appliances | D31: TWh/year | F31: 151.51127 | G31: 218.01252 | H31: 325.61057 | I31: 425.95689 | J31: 558.44221 | K31: 694.91016 | L31: 822.01948 | M31: 941.4932
B32: Total demand by others | D32: TWh/year | F32: 39.068944 | G32: 60.153374 | H32: 95.891786 | I32: 133.59239 | J32: 186.1474 | K32: 247.3409 | L32: 311.80049 | M32: 379.90076
B33: Demand Consumed by water heaters | D33: TWh/year | F33: 22.853156 | G33: 34.342824 | H33: 52.959965 | I33: 64.08997 | J33: 75.684541 | K33: 75.023778 | L33: 72.7892 | M33: 68.619314
B34: water Heating adjusted demand by other appliances | D34: TWh/year | F34: 16.215788 | G34: 25.81055 | H34: 42.93182 | I34: 69.502422 | J34: 110.46286 | K34: 172.31713 | L34: 239.01129 | M34: 311.28145
B35: Total demand by all appliances | D35: TWh/year | F35: 190.58021 | G35: 278.16589 | H35: 421.50235 | I35: 559.54929 | J35: 744.58961 | K35: 942.25107 | L35: 1133.82 | M35: 1321.394
B38: Total demand by lighting | D38: TWh/year | F38: 38.745578 | G38: 52.782885 | H38: 65.355083 | I38: 67.053933 | J38: 67.048731 | K38: 70.63206 | L38: 73.556045 | M38: 75.142025
B39: Total demand by room airconditoners | D39: TWh/year | F39: 39.349552 | G39: 71.003453 | H39: 138.6719 | I39: 219.15321 | J39: 334.9825 | K39: 446.03269 | L39: 549.85993 | M39: 649.54414
B40: Total demand by ceiling fans | D40: TWh/year | F40: 31 | G40: 38.72959 | H40: 51.808402 | I40: 55.21839 | J40: 56.499141 | K40: 67.847157 | L40: 78.07824 | M40: 87.475752
B44: Net energy demand | F44: 190.58021 | G44: 278.16589 | H44: 421.50235 | I44: 559.54929 | J44: 744.58961 | K44: 942.25107 | L44: 1133.82 | M44: 1321.394
B46: Consumption of kerosene
B47: Urban | D47: TWh | F47: 0.59884186 | G47: 0 | H47: 0 | I47: 0 | J47: 0 | K47: 0 | L47: 0 | M47: 0
B48: Rural | D48: TWh | F48: 8.5560556 | G48: 4.5141701 | H48: 0 | I48: 0 | J48: 0 | K48: 0 | L48: 0 | M48: 0
B49: Total | D49: TWh | F49: 9.1548975 | G49: 4.5141701 | H49: 0 | I49: 0 | J49: 0 | K49: 0 | L49: 0 | M49: 0
B52: Cost calculations
B53: Lighting | D53: INR Trillion | F53: 0.020529398 | G53: 0.040539493 | H53: 0.065762469 | I53: 0.083443553 | J53: 0.099407486 | K53: 0.11615853 | L53: 0.13287905 | M53: 0.14791282 | N53: 0
B54: Ceiling Fans | D54: INR Trillion | F54: 0.027608043 | G54: 0.04005281 | H54: 0.061017304 | I54: 0.072961868 | J54: 0.082766514 | K54: 0.10695548 | L54: 0.13178979 | M54: 0.15740572 | N54: 0
B55: Televisions | D55: INR Trillion | F55: 0.12478786 | G55: 0.17660886 | H55: 0.2416332 | I55: 0.31893397 | J55: 0.41032137 | K55: 0.47110566 | L55: 0.53503594 | M55: 0.59744173 | N55: 0
B56: Refrigerators | D56: INR Trillion | F56: 0.09140012 | G56: 0.14311875 | H56: 0.20763301 | I56: 0.28319202 | J56: 0.37009619 | K56: 0.44402199 | L56: 0.5220254 | M56: 0.59933373 | N56: 0
...

Sheet Conversion Factors
A1: BTU per GWh | F1: Weight to Volume Conversion
A2: This is a pure unit conversion. It does not involve a heat rate. | F2: Product | G2: Weight | H2: Volume | I2: Barrel
A3: =3.41214*10^9 -> 3412140000 | G3: (MT) | H3: (KL) | I3: (bbl)
F4: LPG | G4: 1 | H4: 1.844 | I4: 11.6
A5: BTU per PJ | F5: Petrol (MS) | G5: 1 | H5: 1.411 | I5: 8.88
A6: 947817120000 | F6: Diesel (HSD) | G6: 1 | H6: 1.21 | I6: 7.61
F7: Kerosene (SKO) | G7: 1 | H7: 1.285 | I7: 8.08
F8: ATF | G8: 1 | H8: 1.288 | I8: 8.1
A9: Energy in LPG | F9: Light Diesel Oil (LDO) | G9: 1 | H9: 1.172 | I9: 7.37
A10: 11300 | B10: kcal/kg | F10: Furnace Oil (FO) | G10: 1 | H10: 1.071 | I10: 6.74
A11: =A10*1000 -> 11300000 | B11: kcal/ton | F11: Crude Oil | G11: 1 | H11: 1.17 | I11: 7.33
A12: 3.96567 | B12: BTU/kcal | F12: Source: PPAC
A13: =A11*A12 -> 44812071 | B13: BTU/ton
A14: =A13*1000 -> 44812071000 | B14: BTU/thousand tons
A16: Energy in Kerosene
A17: 10450 | B17: kcal/kg
A18: =A17*1000 -> 10450000 | B18: kcal/ton
A19: 3.96567 | B19: BTU/kcal
A20: =A18*A19 -> 41441252 | B20: BTU/ton
A21: =A20*1000 -> 41441251500 | B21: BTU/thousand tons
A23: Energy in Biomass
A24: Wood wastes | B24: =AVERAGE(2500,3850) -> 3175 | C24: kcal/kg
A25: Cowdung | B25: =AVERAGE(3140,3290) -> 3215 | C25: kcal/kg
A26: Average of biomass fuels | B26: =AVERAGE(B24:B25) -> 3195 | C26: kcal/kg
B27: 3.96567 | C27: BTU/kcal
B28: =B26*B27 -> 12670.316 | C28: BTU/kg
A30: Energy in Petroleum Diesel
B31: 5.817 | C31: million BTU/barrel
B32: 7.61 | C32: barrel/MT
B33: =B32*B31 -> 44.26737 | C33: million BTU/MT
B34: =B33*1000 -> 44267.37 | C34: million BTU/'000 MT
B35: =B34*10^6 -> 44267370000 | C35: BTU/'000 MT

Sheet Calculations
A1: Building Type | B1: Fuel Type | C1: Service | D1: 2017 | E1: 2018 | F1: 2019 | G1: 2020 | H1: 2021 | I1: 2022 | J1: 2023 | K1: 2024 | L1: 2025 | M1: 2026 | N1: 2027 | O1: 2028 | P1: 2029 | Q1: 2030 | R1: 2031 | S1: 2032 | T1: 2033 | U1: 2034 | V1: 2035 | W1: 2036 | X1: 2037 | Y1: 2038 | Z1: 2039 | AA1: 2040 | AB1: 2041 | AC1: 2042 | AD1: 2043 | AE1: 2044 | AF1: 2045 | AG1: 2046 | AH1: 2047 | AI1: 2048 | AJ1: 2049 | AK1: 2050 | AL1: 2051 | AM1: 2052 | AN1: 2053 | AO1: 2054 | AP1: 2055 | AQ1: 2056 | AR1: 2057 | AS1: 2058 | AT1: 2059 | AU1: 2060 | AV1: 2061 | AW1: 2062 | AX1: 2063 | AY1: 2064 | AZ1: 2065 | BA1: 2066 | BB1: 2067 | BC1: 2068 | BD1: 2069 | BE1: 2070
A2: Urban Residential | B2: electricity (BTU) | C2: Heating | D2: 0 | E2: 0 | F2: 0 | G2: 0 | H2: 0 | I2: 0 | J2: 0 | K2: 0 | L2: 0 | M2: 0 | N2: 0 | O2: 0 | P2: 0 | Q2: 0 | R2: 0 | S2: 0 | T2: 0 | U2: 0 | V2: 0 | W2: 0 | X2: 0 | Y2: 0 | Z2: 0 | AA2: 0 | AB2: 0 | AC2: 0 | AD2: 0 | AE2: 0 | AF2: 0 | AG2: 0 | AH2: 0 | AI2: 0 | AJ2: 0 | AK2: 0 | AL2: 0 | AM2: 0 | AN2: 0 | AO2: 0 | AP2: 0 | AQ2: 0 | AR2: 0 | AS2: 0 | AT2: 0 | AU2: 0 | AV2: 0 | AW2: 0 | AX2: 0 | AY2: 0 | AZ2: 0 | BA2: 0 | BB2: 0 | BC2: 0 | BD2: 0 | BE2: 0
A3: Urban Residential | B3: electricity (BTU) | C3: Cooling and Ventilation | D3: =('Elec Use'!$D$24*BTU_per_GWh)*'IESS Demand'!$C133*'IESS Demand'!G$77*'IESS Demand'!D116/'IESS Demand'!$D116 -> 1.6657047e+13 | E3: =('Elec Use'!$D$18*BTU_per_GWh)*'IESS Demand'!$C133*'IESS Demand'!H$77*'IESS Demand'!E116/'IESS Demand'!$E116 -> 1.4006486e+13 | F3: =('Elec Use'!$D$19*BTU_per_GWh)*'IESS Demand'!$C133*'IESS Demand'!I$77*'IESS Demand'!F116/'IESS Demand'!$F116 -> 1.5065586e+13 | G3: =('Elec Use'!$D$19*BTU_per_GWh)*'IESS Demand'!$C133*'IESS Demand'!J$77*'IESS Demand'!G116/'IESS Demand'!$F116 -> 1.5825421e+13 | H3: =('Elec Use'!$D$19*BTU_per_GWh)*'IESS Demand'!$C133*'IESS Demand'!K$77*'IESS Demand'!H116/'IESS Demand'!$F116 -> 1.6592891e+13 | I3: =('Elec Use'!$D$19*BTU_per_GWh)*'IESS Demand'!$C133*'IESS Demand'!L$77*'IESS Demand'!I116/'IESS Demand'!$F116 -> 1.7367628e+13 | J3: =('Elec Use'!$D$19*BTU_per_GWh)*'IESS Demand'!$C133*'IESS Demand'!M$77*'IESS Demand'!J116/'IESS Demand'!$F116 -> 1.9954943e+13 | K3: =('Elec Use'!$D$19*BTU_per_GWh)*'IESS Demand'!$C133*'IESS Demand'!N$77*'IESS Demand'!K116/'IESS Demand'!$F116 -> 2.2636137e+13 | L3: =('Elec Use'!$D$19*BTU_per_GWh)*'IESS Demand'!$C133*'IESS Demand'!O$77*'IESS Demand'!L116/'IESS Demand'!$F116 -> 2.5383948e+13 | M3: =('Elec Use'!$D$19*BTU_per_GWh)*'IESS Demand'!$C133*'IESS Demand'!P$77*'IESS Demand'!M116/'IESS Demand'!$F116 -> 2.8195336e+13 | ... BE3: =('Elec Use'!$D$19*BTU_per_GWh)*'IESS Demand'!$C133*'IESS Demand'!BH$77*'IESS Demand'!BE116/'IESS Demand'!$F116 -> 5.1047076e+14
A4: Urban Residential | B4: electricity (BTU) | C4: Lighting | D4: =('Elec Use'!$D$24*BTU_per_GWh)*'IESS Demand'!$C134*'IESS Demand'!J$77*'IESS Demand'!H117/'IESS Demand'!$H117 -> 3.8464435e+13 | E4: =('Elec Use'!$D$18*BTU_per_GWh)*'IESS Demand'!$C134*'IESS Demand'!H$77*'IESS Demand'!E117/'IESS Demand'!$E117 -> 3.0557952e+13 | F4: =('Elec Use'!$D$19*BTU_per_GWh)*'IESS Demand'!$C134*'IESS Demand'!I$77*'IESS Demand'!F117/'IESS Demand'!$F117 -> 3.2868589e+13 | G4: =('Elec Use'!$D$19*BTU_per_GWh)*'IESS Demand'!$C134*'IESS Demand'!J$77*'IESS Demand'!G117/'IESS Demand'!$F117 -> 3.3749546e+13 | H4: =('Elec Use'!$D$19*BTU_per_GWh)*'IESS Demand'!$C134*'IESS Demand'!K$77*'IESS Demand'!H117/'IESS Demand'!$F117 -> 3.4618167e+13 | I4: =('Elec Use'!$D$19*BTU_per_GWh)*'IESS Demand'!$C134*'IESS Demand'!L$77*'IESS Demand'!I117/'IESS Demand'!$F117 -> 3.5475044e+13 | J4: =('Elec Use'!$D$19*BTU_per_GWh)*'IESS Demand'!$C134*'IESS Demand'!M$77*'IESS Demand'!J117/'IESS Demand'!$F117 -> 3.7113946e+13 | K4: =('Elec Use'!$D$19*BTU_per_GWh)*'IESS Demand'!$C134*'IESS Demand'!N$77*'IESS Demand'!K117/'IESS Demand'!$F117 -> 3.8817797e+13 | L4: =('Elec Use'!$D$19*BTU_per_GWh)*'IESS Demand'!$C134*'IESS Demand'!O$77*'IESS Demand'!L117/'IESS Demand'!$F117 -> 4.0536784e+13 | M4: =('Elec Use'!$D$19*BTU_per_GWh)*'IESS Demand'!$C134*'IESS Demand'!P$77*'IESS Demand'!M117/'IESS Demand'!$F117 -> 4.2270218e+13 | ... BE4: =('Elec Use'!$D$19*BTU_per_GWh)*'IESS Demand'!$C134*'IESS Demand'!BH$77*'IESS Demand'!BE117/'IESS Demand'!$F117 -> 1.9163723e+14
A5: Urban Residential | B5: electricity (BTU) | C5: Appliances | D5: =('Elec Use'!$D$17*BTU_per_GWh)*'IESS Demand'!$C135*'IESS Demand'!G$77*'IESS Demand'!D118/'IESS Demand'!$D118 -> 1.3488114e+14 | E5: =('Elec Use'!$D$18*BTU_per_GWh)*'IESS Demand'!$C135*'IESS Demand'!H$77*'IESS Demand'!E118/'IESS Demand'!$E118 -> 1.4666112e+14 | F5: =('Elec Use'!$D$19*BTU_per_GWh)*'IESS Demand'!$C135*'IESS Demand'!I$77*'IESS Demand'!F118/'IESS Demand'!$F118 -> 1.5775089e+14 | G5: =('Elec Use'!$D$19*BTU_per_GWh)*'IESS Demand'!$C135*'IESS Demand'!J$77*'IESS Demand'!G118/'IESS Demand'!$F118 -> 1.6899816e+14 | H5: =('Elec Use'!$D$19*BTU_per_GWh)*'IESS Demand'!$C135*'IESS Demand'!K$77*'IESS Demand'!H118/'IESS Demand'!$F118 -> 1.8044821e+14 | I5: =('Elec Use'!$D$19*BTU_per_GWh)*'IESS Demand'!$C135*'IESS Demand'!L$77*'IESS Demand'!I118/'IESS Demand'!$F118 -> 1.9209127e+14 | J5: =('Elec Use'!$D$19*BTU_per_GWh)*'IESS Demand'!$C135*'IESS Demand'!M$77*'IESS Demand'!J118/'IESS Demand'!$F118 -> 2.0668146e+14 | K5: =('Elec Use'!$D$19*BTU_per_GWh)*'IESS Demand'!$C135*'IESS Demand'!N$77*'IESS Demand'!K118/'IESS Demand'!$F118 -> 2.2182212e+14 | L5: =('Elec Use'!$D$19*BTU_per_GWh)*'IESS Demand'!$C135*'IESS Demand'!O$77*'IESS Demand'!L118/'IESS Demand'!$F118 -> 2.3723434e+14 | M5: =('Elec Use'!$D$19*BTU_per_GWh)*'IESS Demand'!$C135*'IESS Demand'!P$77*'IESS Demand'!M118/'IESS Demand'!$F118 -> 2.5290573e+14 | ... BE5: =('Elec Use'!$D$19*BTU_per_GWh)*'IESS Demand'!$C135*'IESS Demand'!BH$77*'IESS Demand'!BE118/'IESS Demand'!$F118 -> 1.2604079e+15
A6: Urban Residential | B6: electricity (BTU) | C6: Other | D6: =('Elec Use'!$D$17*BTU_per_GWh)*'IESS Demand'!$C136*'IESS Demand'!G$77*'IESS Demand'!D119/'IESS Demand'!$D119 -> 2.9380581e+13 | E6: =('Elec Use'!$D$18*BTU_per_GWh)*'IESS Demand'!$C136*'IESS Demand'!H$77*'IESS Demand'!E119/'IESS Demand'!$E119 -> 3.1946562e+13 | F6: =('Elec Use'!$D$19*BTU_per_GWh)*'IESS Demand'!$C136*'IESS Demand'!I$77*'IESS Demand'!F119/'IESS Demand'!$F119 -> 3.4362199e+13 | G6: =('Elec Use'!$D$19*BTU_per_GWh)*'IESS Demand'!$C136*'IESS Demand'!J$77*'IESS Demand'!G119/'IESS Demand'!$F119 -> 3.5038118e+13 | H6: =('Elec Use'!$D$24*BTU_per_GWh)*'IESS Demand'!$C136*'IESS Demand'!K$77*'IESS Demand'!H119/'IESS Demand'!$F119 -> 4.0962765e+13 | I6: =('Elec Use'!$D$19*BTU_per_GWh)*'IESS Demand'!$C136*'IESS Demand'!L$77*'IESS Demand'!I119/'IESS Demand'!$F119 -> 3.6324884e+13 | J6: =('Elec Use'!$D$19*BTU_per_GWh)*'IESS Demand'!$C136*'IESS Demand'!M$77*'IESS Demand'!J119/'IESS Demand'!$F119 -> 4.1509962e+13 | K6: =('Elec Use'!$D$19*BTU_per_GWh)*'IESS Demand'!$C136*'IESS Demand'!N$77*'IESS Demand'!K119/'IESS Demand'!$F119 -> 4.6883517e+13 | L6: =('Elec Use'!$D$19*BTU_per_GWh)*'IESS Demand'!$C136*'IESS Demand'!O$77*'IESS Demand'!L119/'IESS Demand'!$F119 -> 5.2388893e+13 | M6: =('Elec Use'!$D$19*BTU_per_GWh)*'IESS Demand'!$C136*'IESS Demand'!P$77*'IESS Demand'!M119/'IESS Demand'!$F119 -> 5.8020078e+13 | N6: =('Elec Use'!$D$19*BTU_per_GWh)*'IESS Demand'!$C136*'IESS Demand'!Q$77*'IESS Demand'!N119/'IESS Demand'!$F119 -> 6.3771419e+13 | O6: =('Elec Use'!$D$19*BTU_per_GWh)*'IESS Demand'!$C136*'IESS Demand'!R$77*'IESS Demand'!O119/'IESS Demand'!$F119 -> 7.2465809e+13 | P6: =('Elec Use'!$D$19*BTU_per_GWh)*'IESS Demand'!$C136*'IESS Demand'!S$77*'IESS Demand'!P119/'IESS Demand'!$F119 -> 8.1370466e+13 | ... BE6: =('Elec Use'!$D$19*BTU_per_GWh)*'IESS Demand'!$C136*'IESS Demand'!BH$77*'IESS Demand'!BE119/'IESS Demand'!$F119 -> 9.3536722e+14
A7: Rural Residential | B7: electricity (BTU) | C7: Heating | D7: 0 | E7: 0 | F7: 0 | G7: 0 | H7: 0 | I7: 0 | J7: 0 | K7: 0 | L7: 0 | M7: 0 | N7: 0 | O7: 0 | P7: 0 | Q7: 0 | R7: 0 | S7: 0 | T7: 0 | U7: 0 | V7: 0 | W7: 0 | X7: 0 | Y7: 0 | Z7: 0 | AA7: 0 | AB7: 0 | AC7: 0 | AD7: 0 | AE7: 0 | AF7: 0 | AG7: 0 | AH7: 0 | AI7: 0 | AJ7: 0 | AK7: 0 | AL7: 0 | AM7: 0 | AN7: 0 | AO7: 0 | AP7: 0 | AQ7: 0 | AR7: 0 | AS7: 0 | AT7: 0 | AU7: 0 | AV7: 0 | AW7: 0 | AX7: 0 | AY7: 0 | AZ7: 0 | BA7: 0 | BB7: 0 | BC7: 0 | BD7: 0 | BE7: 0
A8: Rural Residential | B8: electricity (BTU) | C8: Cooling and Ventilation | D8: =('Elec Use'!$D$17*BTU_per_GWh)*'IESS Demand'!$C133*'IESS Demand'!G$78*'IESS Demand'!D116/'IESS Demand'!$D116 -> 2.4524217e+13 | E8: =('Elec Use'!$D$18*BTU_per_GWh)*'IESS Demand'!$C133*'IESS Demand'!H$78*'IESS Demand'!E116/'IESS Demand'!$E116 -> 2.5989992e+13 | F8: =('Elec Use'!$D$19*BTU_per_GWh)*'IESS Demand'!$C133*'IESS Demand'!I$78*'IESS Demand'!F116/'IESS Demand'!$F116 -> 2.7079966e+13 | G8: =('Elec Use'!$D$19*BTU_per_GWh)*'IESS Demand'!$C133*'IESS Demand'!J$78*'IESS Demand'!G116/'IESS Demand'!$F116 -> 2.7591715e+13 | H8: =('Elec Use'!$D$24*BTU_per_GWh)*'IESS Demand'!$C133*'IESS Demand'!K$78*'IESS Demand'!H116/'IESS Demand'!$F116 -> 3.2244849e+13 | I8: =('Elec Use'!$D$19*BTU_per_GWh)*'IESS Demand'!$C133*'IESS Demand'!L$78*'IESS Demand'!I116/'IESS Demand'!$F116 -> 2.859268e+13 | J8: =('Elec Use'!$D$19*BTU_per_GWh)*'IESS Demand'!$C133*'IESS Demand'!M$78*'IESS Demand'!J116/'IESS Demand'!$F116 -> 3.197601e+13 | K8: =('Elec Use'!$D$19*BTU_per_GWh)*'IESS Demand'!$C133*'IESS Demand'!N$78*'IESS Demand'!K116/'IESS Demand'!$F116 -> 3.5265462e+13 | L8: =('Elec Use'!$D$19*BTU_per_GWh)*'IESS Demand'!$C133*'IESS Demand'!O$78*'IESS Demand'!L116/'IESS Demand'!$F116 -> 3.8488298e+13 | M8: =('Elec Use'!$D$19*BTU_per_GWh)*'IESS Demand'!$C133*'IESS Demand'!P$78*'IESS Demand'!M116/'IESS Demand'!$F116 -> 4.1647556e+13 | N8: =('Elec Use'!$D$19*BTU_per_GWh)*'IESS Demand'!$C133*'IESS Demand'!Q$78*'IESS Demand'!N116/'IESS Demand'!$F116 -> 4.4746093e+13 | O8: =('Elec Use'!$D$19*BTU_per_GWh)*'IESS Demand'!$C133*'IESS Demand'!R$78*'IESS Demand'!O116/'IESS Demand'!$F116 -> 4.9871578e+13 | P8: =('Elec Use'!$D$19*BTU_per_GWh)*'IESS Demand'!$C133*'IESS Demand'!S$78*'IESS Demand'!P116/'IESS Demand'!$F116 -> 5.4885049e+13 | ... BE8: =('Elec Use'!$D$19*BTU_per_GWh)*'IESS Demand'!$C133*'IESS Demand'!BH$78*'IESS Demand'!BE116/'IESS Demand'!$F116 -> 2.7613278e+14
A9: Rural Residential | B9: electricity (BTU) | C9: Lighting | D9: =('Elec Use'!$D$17*BTU_per_GWh)*'IESS Demand'!$C134*'IESS Demand'!G$78*'IESS Demand'!D117/'IESS Demand'!$D117 -> 5.3504486e+13 | E9: =('Elec Use'!$D$18*BTU_per_GWh)*'IESS Demand'!$C134*'IESS Demand'!H$78*'IESS Demand'!E117/'IESS Demand'!$E117 -> 5.6702366e+13 | F9: =('Elec Use'!$D$19*BTU_per_GWh)*'IESS Demand'!$C134*'IESS Demand'!I$78*'IESS Demand'!F117/'IESS Demand'!$F117 -> 5.9080362e+13 | G9: =('Elec Use'!$D$19*BTU_per_GWh)*'IESS Demand'!$C134*'IESS Demand'!J$78*'IESS Demand'!G117/'IESS Demand'!$F117 -> 5.8842532e+13 | H9: =('Elec Use'!$D$24*BTU_per_GWh)*'IESS Demand'!$C134*'IESS Demand'!K$78*'IESS Demand'!H117/'IESS Demand'!$F117 -> 6.7273239e+13 | I9: =('Elec Use'!$D$19*BTU_per_GWh)*'IESS Demand'!$C134*'IESS Demand'!L$78*'IESS Demand'!I117/'IESS Demand'!$F117 -> 5.8403288e+13 | J9: =('Elec Use'!$D$19*BTU_per_GWh)*'IESS Demand'!$C134*'IESS Demand'!M$78*'IESS Demand'!J117/'IESS Demand'!$F117 -> 5.9471776e+13 | K9: =('Elec Use'!$D$19*BTU_per_GWh)*'IESS Demand'!$C134*'IESS Demand'!N$78*'IESS Demand'!K117/'IESS Demand'!$F117 -> 6.0475315e+13 | L9: =('Elec Use'!$D$19*BTU_per_GWh)*'IESS Demand'!$C134*'IESS Demand'!O$78*'IESS Demand'!L117/'IESS Demand'!$F117 -> 6.1463718e+13 | M9: =('Elec Use'!$D$19*BTU_per_GWh)*'IESS Demand'!$C134*'IESS Demand'!P$78*'IESS Demand'!M117/'IESS Demand'!$F117 -> 6.2437675e+13 | N9: =('Elec Use'!$D$19*BTU_per_GWh)*'IESS Demand'!$C134*'IESS Demand'!Q$78*'IESS Demand'!N117/'IESS Demand'!$F117 -> 6.3397835e+13 | O9: =('Elec Use'!$D$19*BTU_per_GWh)*'IESS Demand'!$C134*'IESS Demand'!R$78*'IESS Demand'!O117/'IESS Demand'!$F117 -> 6.4820323e+13 | P9: =('Elec Use'!$D$19*BTU_per_GWh)*'IESS Demand'!$C134*'IESS Demand'!S$78*'IESS Demand'!P117/'IESS Demand'!$F117 -> 6.6215665e+13 | ... BE9: =('Elec Use'!$D$19*BTU_per_GWh)*'IESS Demand'!$C134*'IESS Demand'!BH$78*'IESS Demand'!BE117/'IESS Demand'!$F117 -> 1.0366377e+14
A10: Rural Residential | B10: electricity (BTU) | C10: Appliances | D10: =('Elec Use'!$D$17*BTU_per_GWh)*'IESS Demand'!$C135*'IESS Demand'!G$78*'IESS Demand'!D118/'IESS Demand'!$D118 -> 2.5679168e+14 | E10: =('Elec Use'!$D$18*BTU_per_GWh)*'IESS Demand'!$C135*'IESS Demand'!H$78*'IESS Demand'!E118/'IESS Demand'!$E118 -> 2.7213972e+14 | F10: =('Elec Use'!$D$19*BTU_per_GWh)*'IESS Demand'!$C135*'IESS Demand'!I$78*'IESS Demand'!F118/'IESS Demand'!$F118 -> 283552771406053 | G10: =('Elec Use'!$D$19*BTU_per_GWh)*'IESS Demand'!$C135*'IESS Demand'!J$78*'IESS Demand'!G118/'IESS Demand'!$F118 -> 2.9464929e+14 | H10: =('Elec Use'!$D$24*BTU_per_GWh)*'IESS Demand'!$C135*'IESS Demand'!K$78*'IESS Demand'!H118/'IESS Demand'!$F118 -> 3.5066374e+14 | I10: =('Elec Use'!$D$24*BTU_per_GWh)*'IESS Demand'!$C135*'IESS Demand'!L$78*'IESS Demand'!I118/'IESS Demand'!$F118 -> 3.629447e+14 | J10: =('Elec Use'!$D$24*BTU_per_GWh)*'IESS Demand'!$C135*'IESS Demand'!M$78*'IESS Demand'!J118/'IESS Demand'!$F118 -> 3.800964e+14 | K10: =('Elec Use'!$D$24*BTU_per_GWh)*'IESS Demand'!$C135*'IESS Demand'!N$78*'IESS Demand'!K118/'IESS Demand'!$F118 -> 3.9661632e+14 | L10: =('Elec Use'!$D$24*BTU_per_GWh)*'IESS Demand'!$C135*'IESS Demand'!O$78*'IESS Demand'!L118/'IESS Demand'!$F118 -> 4.1282459e+14 | M10: =('Elec Use'!$D$24*BTU_per_GWh)*'IESS Demand'!$C135*'IESS Demand'!P$78*'IESS Demand'!M118/'IESS Demand'!$F118 -> 4.2873543e+14 | N10: =('Elec Use'!$D$24*BTU_per_GWh)*'IESS Demand'!$C135*'IESS Demand'!Q$78*'IESS Demand'!N118/'IESS Demand'!$F118 -> 4.4436219e+14 | O10: =('Elec Use'!$D$24*BTU_per_GWh)*'IESS Demand'!$C135*'IESS Demand'!R$78*'IESS Demand'!O118/'IESS Demand'!$F118 -> 4.6136866e+14 | ... BE10: =('Elec Use'!$D$24*BTU_per_GWh)*'IESS Demand'!$C135*'IESS Demand'!BH$78*'IESS Demand'!BE118/'IESS Demand'!$F118 -> 7.8248621e+14
A11: Rural Residential | B11: electricity (BTU) | C11: Other | D11: =('Elec Use'!$D$17*BTU_per_GWh)*'IESS Demand'!$C136*'IESS Demand'!G$78*'IESS Demand'!D119/'IESS Demand'!$D119 -> 5.5935829e+13 | E11: =('Elec Use'!$D$18*BTU_per_GWh)*'IESS Demand'!$C136*'IESS Demand'!H$78*'IESS Demand'!E119/'IESS Demand'!$E119 -> 5.9279027e+13 | F11: =('Elec Use'!$D$19*BTU_per_GWh)*'IESS Demand'!$C136*'IESS Demand'!I$78*'IESS Demand'!F119/'IESS Demand'!$F119 -> 6.1765083e+13 | G11: =('Elec Use'!$D$19*BTU_per_GWh)*'IESS Demand'!$C136*'IESS Demand'!J$78*'IESS Demand'!G119/'IESS Demand'!$F119 -> 6.1089164e+13 | H11: =('Elec Use'!$D$19*BTU_per_GWh)*'IESS Demand'!$C136*'IESS Demand'!K$78*'IESS Demand'!H119/'IESS Demand'!$F119 -> 6.0435289e+13 | I11: =('Elec Use'!$D$19*BTU_per_GWh)*'IESS Demand'!$C136*'IESS Demand'!L$78*'IESS Demand'!I119/'IESS Demand'!$F119 -> 5.9802398e+13 | J11: =('Elec Use'!$D$19*BTU_per_GWh)*'IESS Demand'!$C136*'IESS Demand'!M$78*'IESS Demand'!J119/'IESS Demand'!$F119 -> 6.6515998e+13 | K11: =('Elec Use'!$D$19*BTU_per_GWh)*'IESS Demand'!$C136*'IESS Demand'!N$78*'IESS Demand'!K119/'IESS Demand'!$F119 -> 7.3041122e+13 | L11: =('Elec Use'!$D$19*BTU_per_GWh)*'IESS Demand'!$C136*'IESS Demand'!O$78*'IESS Demand'!L119/'IESS Demand'!$F119 -> 7.9434425e+13 | M11: =('Elec Use'!$D$19*BTU_per_GWh)*'IESS Demand'!$C136*'IESS Demand'!P$78*'IESS Demand'!M119/'IESS Demand'!$F119 -> 8.5701919e+13 | ... BE11: =('Elec Use'!$D$19*BTU_per_GWh)*'IESS Demand'!$C136*'IESS Demand'!BH$78*'IESS Demand'!BE119/'IESS Demand'!$F119 -> 5.0597521e+14
A12: Commercial | B12: electricity (BTU) | C12: Heating | D12: 0 | E12: 0 | F12: 0 | G12: 0 | H12: 0 | I12: 0 | J12: 0 | K12: 0 | L12: 0 | M12: 0 | N12: 0 | O12: 0 | P12: 0 | Q12: 0 | R12: 0 | S12: 0 | T12: 0 | U12: 0 | V12: 0 | W12: 0 | X12: 0 | Y12: 0 | Z12: 0 | AA12: 0 | AB12: 0 | AC12: 0 | AD12: 0 | AE12: 0 | AF12: 0 | AG12: 0 | AH12: 0 | AI12: 0 | AJ12: 0 | AK12: 0 | AL12: 0 | AM12: 0 | AN12: 0 | AO12: 0 | AP12: 0 | AQ12: 0 | AR12: 0 | AS12: 0 | AT12: 0 | AU12: 0 | AV12: 0 | AW12: 0 | AX12: 0 | AY12: 0 | AZ12: 0 | BA12: 0 | BB12: 0 | BC12: 0 | BD12: 0 | BE12: 0
A13: Commercial | B13: electricity (BTU) | C13: Cooling and Ventilation | D13: =('Elec Use'!$E$17*BTU_per_GWh)*'IESS Demand'!$C167*'IESS Demand'!C160/'IESS Demand'!$C160 -> 1.8115555e+14 | E13: =('Elec Use'!$E$18*BTU_per_GWh)*'IESS Demand'!$C167*'IESS Demand'!D160/'IESS Demand'!$D160 -> 1.8908143e+14 | F13: =('Elec Use'!$E$19*BTU_per_GWh)*'IESS Demand'!$C167*'IESS Demand'!E160/'IESS Demand'!$E160 -> 1.981024e+14 | G13: =('Elec Use'!$E$19*BTU_per_GWh)*'IESS Demand'!$C167*'IESS Demand'!F160/'IESS Demand'!$E160 -> 2.0676738e+14 | H13: =('Elec Use'!$E$24*BTU_per_GWh)*'IESS Demand'!$C167*'IESS Demand'!G160/'IESS Demand'!$E160 -> 1.9069822e+14 | I13: =('Elec Use'!$E$19*BTU_per_GWh)*'IESS Demand'!$C167*'IESS Demand'!H160/'IESS Demand'!$E160 -> 2.2409735e+14 | J13: =('Elec Use'!$E$19*BTU_per_GWh)*'IESS Demand'!$C167*'IESS Demand'!I160/'IESS Demand'!$E160 -> 2.3648852e+14 | K13: =('Elec Use'!$E$19*BTU_per_GWh)*'IESS Demand'!$C167*'IESS Demand'!J160/'IESS Demand'!$E160 -> 2.4887969e+14 | L13: =('Elec Use'!$E$19*BTU_per_GWh)*'IESS Demand'!$C167*'IESS Demand'!K160/'IESS Demand'!$E160 -> 2.6127087e+14 | M13: =('Elec Use'!$E$19*BTU_per_GWh)*'IESS Demand'!$C167*'IESS Demand'!L160/'IESS Demand'!$E160 -> 2.7366204e+14 | N13: =('Elec Use'!$E$19*BTU_per_GWh)*'IESS Demand'!$C167*'IESS Demand'!M160/'IESS Demand'!$E160 -> 2.8605321e+14 | O13: =('Elec Use'!$E$19*BTU_per_GWh)*'IESS Demand'!$C167*'IESS Demand'!N160/'IESS Demand'!$E160 -> 3.0440671e+14 | P13: =('Elec Use'!$E$19*BTU_per_GWh)*'IESS Demand'!$C167*'IESS Demand'!O160/'IESS Demand'!$E160 -> 3.2276021e+14 | ... BE13: =('Elec Use'!$E$19*BTU_per_GWh)*'IESS Demand'!$C167*'IESS Demand'!BD160/'IESS Demand'!$E160 -> 1.6786618e+15
A14: Commercial | B14: electricity (BTU) | C14: Lighting | D14: =('Elec Use'!$E$17*BTU_per_GWh)*'IESS Demand'!$C168*'IESS Demand'!C161/'IESS Demand'!$C161 -> 3.7652421e+13 | E14: =('Elec Use'!$E$18*BTU_per_GWh)*'IESS Demand'!$C168*'IESS Demand'!D161/'IESS Demand'!$D161 -> 3.929978e+13 | F14: =('Elec Use'!$E$19*BTU_per_GWh)*'IESS Demand'!$C168*'IESS Demand'!E161/'IESS Demand'!$E161 -> 4.1174751e+13 | G14: =('Elec Use'!$E$19*BTU_per_GWh)*'IESS Demand'!$C168*'IESS Demand'!F161/'IESS Demand'!$E161 -> 4.215154e+13 | H14: =('Elec Use'!$E$24*BTU_per_GWh)*'IESS Demand'!$C168*'IESS Demand'!G161/'IESS Demand'!$E161 -> 3.8176694e+13 | I14: =('Elec Use'!$E$19*BTU_per_GWh)*'IESS Demand'!$C168*'IESS Demand'!H161/'IESS Demand'!$E161 -> 4.4105118e+13 | J14: =('Elec Use'!$E$19*BTU_per_GWh)*'IESS Demand'!$C168*'IESS Demand'!I161/'IESS Demand'!$E161 -> 4.5537087e+13 | K14: =('Elec Use'!$E$19*BTU_per_GWh)*'IESS Demand'!$C168*'IESS Demand'!J161/'IESS Demand'!$E161 -> 4.6969055e+13 | L14: =('Elec Use'!$E$19*BTU_per_GWh)*'IESS Demand'!$C168*'IESS Demand'!K161/'IESS Demand'!$E161 -> 4.8401024e+13 | M14: =('Elec Use'!$E$19*BTU_per_GWh)*'IESS Demand'!$C168*'IESS Demand'!L161/'IESS Demand'!$E161 -> 4.9832992e+13 | N14: =('Elec Use'!$E$19*BTU_per_GWh)*'IESS Demand'!$C168*'IESS Demand'!M161/'IESS Demand'!$E161 -> 51264960799005 | O14: =('Elec Use'!$E$19*BTU_per_GWh)*'IESS Demand'!$C168*'IESS Demand'!N161/'IESS Demand'!$E161 -> 5.3405225e+13 | P14: =('Elec Use'!$E$19*BTU_per_GWh)*'IESS Demand'!$C168*'IESS Demand'!O161/'IESS Demand'!$E161 -> 5.5545489e+13 | ... BE14: =('Elec Use'!$E$19*BTU_per_GWh)*'IESS Demand'!$C168*'IESS Demand'!BD161/'IESS Demand'!$E161 -> 3.3021525e+14
A15: Commercial | B15: electricity (BTU) | C15: Appliances | D15: =('Elec Use'!$E$17*BTU_per_GWh)*'IESS Demand'!$C169*'IESS Demand'!C162/'IESS Demand'!$C162 -> 5.7688405e+13 | E15: =('Elec Use'!$E$18*BTU_per_GWh)*'IESS Demand'!$C169*'IESS Demand'!D162/'IESS Demand'!$D162 -> 6.0212373e+13 | F15: =('Elec Use'!$E$19*BTU_per_GWh)*'IESS Demand'!$C169*'IESS Demand'!E162/'IESS Demand'!$E162 -> 6.3085072e+13 | G15: =('Elec Use'!$E$19*BTU_per_GWh)*'IESS Demand'!$C169*'IESS Demand'!F162/'IESS Demand'!$E162 -> 6.4728891e+13 | H15: =('Elec Use'!$E$24*BTU_per_GWh)*'IESS Demand'!$C169*'IESS Demand'!G162/'IESS Demand'!$E162 -> 5.8752349e+13 | I15: =('Elec Use'!$E$19*BTU_per_GWh)*'IESS Demand'!$C169*'IESS Demand'!H162/'IESS Demand'!$E162 -> 6.8016529e+13 | J15: =('Elec Use'!$E$19*BTU_per_GWh)*'IESS Demand'!$C169*'IESS Demand'!I162/'IESS Demand'!$E162 -> 6.9453496e+13 | K15: =('Elec Use'!$E$19*BTU_per_GWh)*'IESS Demand'!$C169*'IESS Demand'!J162/'IESS Demand'!$E162 -> 7.0890463e+13 | L15: =('Elec Use'!$E$19*BTU_per_GWh)*'IESS Demand'!$C169*'IESS Demand'!K162/'IESS Demand'!$E162 -> 7.232743e+13 | M15: =('Elec Use'!$E$19*BTU_per_GWh)*'IESS Demand'!$C169*'IESS Demand'!L162/'IESS Demand'!$E162 -> 7.3764397e+13 | N15: =('Elec Use'!$E$19*BTU_per_GWh)*'IESS Demand'!$C169*'IESS Demand'!M162/'IESS Demand'!$E162 -> 7.5201364e+13 | O15: =('Elec Use'!$E$19*BTU_per_GWh)*'IESS Demand'!$C169*'IESS Demand'!N162/'IESS Demand'!$E162 -> 7.6855825e+13 | P15: =('Elec Use'!$E$19*BTU_per_GWh)*'IESS Demand'!$C169*'IESS Demand'!O162/'IESS Demand'!$E162 -> 7.8510286e+13 | ... BE15: =('Elec Use'!$E$19*BTU_per_GWh)*'IESS Demand'!$C169*'IESS Demand'!BD162/'IESS Demand'!$E162 -> 1.3780799e+14
A16: Commercial | B16: electricity (BTU) | C16: Other | D16: =('Elec Use'!$E$17*BTU_per_GWh)*'IESS Demand'!$C170*'IESS Demand'!C163/'IESS Demand'!$C163 -> 2.9999095e+13 | E16: =('Elec Use'!$E$18*BTU_per_GWh)*'IESS Demand'!$C170*'IESS Demand'!D163/'IESS Demand'!$D163 -> 3.1311608e+13 | F16: =('Elec Use'!$E$19*BTU_per_GWh)*'IESS Demand'!$C170*'IESS Demand'!E163/'IESS Demand'!$E163 -> 3.2805468e+13 | G16: =('Elec Use'!$E$19*BTU_per_GWh)*'IESS Demand'!$C170*'IESS Demand'!F163/'IESS Demand'!$E163 -> 3.381106e+13 | H16: =('Elec Use'!$E$24*BTU_per_GWh)*'IESS Demand'!$C170*'IESS Demand'!G163/'IESS Demand'!$E163 -> 3.0819295e+13 | I16: =('Elec Use'!$E$24*BTU_per_GWh)*'IESS Demand'!$C170*'IESS Demand'!H163/'IESS Demand'!$E163 -> 3.1709434e+13 | J16: =('Elec Use'!$E$24*BTU_per_GWh)*'IESS Demand'!$C170*'IESS Demand'!I163/'IESS Demand'!$E163 -> 3.250376e+13 | K16: =('Elec Use'!$E$24*BTU_per_GWh)*'IESS Demand'!$C170*'IESS Demand'!J163/'IESS Demand'!$E163 -> 3.3298086e+13 | L16: =('Elec Use'!$E$24*BTU_per_GWh)*'IESS Demand'!$C170*'IESS Demand'!K163/'IESS Demand'!$E163 -> 3.4092412e+13 | M16: =('Elec Use'!$E$24*BTU_per_GWh)*'IESS Demand'!$C170*'IESS Demand'!L163/'IESS Demand'!$E163 -> 3.4886738e+13 | N16: =('Elec Use'!$E$24*BTU_per_GWh)*'IESS Demand'!$C170*'IESS Demand'!M163/'IESS Demand'!$E163 -> 3.5681064e+13 | O16: =('Elec Use'!$E$24*BTU_per_GWh)*'IESS Demand'!$C170*'IESS Demand'!N163/'IESS Demand'!$E163 -> 3.7179202e+13 | ... BE16: =('Elec Use'!$E$24*BTU_per_GWh)*'IESS Demand'!$C170*'IESS Demand'!BD163/'IESS Demand'!$E163 -> 1.6690584e+14
A17: Urban Residential | B17: coal (BTU) | C17: Heating | D17: 0 | E17: 0 | F17: 0 | G17: 0 | H17: 0 | I17: 0 | J17: 0 | K17: 0 | L17: 0 | M17: 0 | N17: 0 | O17: 0 | P17: 0 | Q17: 0 | R17: 0 | S17: 0 | T17: 0 | U17: 0 | V17: 0 | W17: 0 | X17: 0 | Y17: 0 | Z17: 0 | AA17: 0 | AB17: 0 | AC17: 0 | AD17: 0 | AE17: 0 | AF17: 0 | AG17: 0 | AH17: 0 | AI17: 0 | AJ17: 0 | AK17: 0 | AL17: 0 | AM17: 0 | AN17: 0 | AO17: 0 | AP17: 0 | AQ17: 0 | AR17: 0 | AS17: 0 | AT17: 0 | AU17: 0 | AV17: 0 | AW17: 0 | AX17: 0 | AY17: 0 | AZ17: 0 | BA17: 0 | BB17: 0 | BC17: 0 | BD17: 0 | BE17: 0
A18: Urban Residential | B18: coal (BTU) | C18: Cooling and Ventilation | D18: 0 | E18: 0 | F18: 0 | G18: 0 | H18: 0 | I18: 0 | J18: 0 | K18: 0 | L18: 0 | M18: 0 | N18: 0 | O18: 0 | P18: 0 | Q18: 0 | R18: 0 | S18: 0 | T18: 0 | U18: 0 | V18: 0 | W18: 0 | X18: 0 | Y18: 0 | Z18: 0 | AA18: 0 | AB18: 0 | AC18: 0 | AD18: 0 | AE18: 0 | AF18: 0 | AG18: 0 | AH18: 0 | AI18: 0 | AJ18: 0 | AK18: 0 | AL18: 0 | AM18: 0 | AN18: 0 | AO18: 0 | AP18: 0 | AQ18: 0 | AR18: 0 | AS18: 0 | AT18: 0 | AU18: 0 | AV18: 0 | AW18: 0 | AX18: 0 | AY18: 0 | AZ18: 0 | BA18: 0 | BB18: 0 | BC18: 0 | BD18: 0 | BE18: 0
A19: Urban Residential | B19: coal (BTU) | C19: Lighting | D19: 0 | E19: 0 | F19: 0 | G19: 0 | H19: 0 | I19: 0 | J19: 0 | K19: 0 | L19: 0 | M19: 0 | N19: 0 | O19: 0 | P19: 0 | Q19: 0 | R19: 0 | S19: 0 | T19: 0 | U19: 0 | V19: 0 | W19: 0 | X19: 0 | Y19: 0 | Z19: 0 | AA19: 0 | AB19: 0 | AC19: 0 | AD19: 0 | AE19: 0 | AF19: 0 | AG19: 0 | AH19: 0 | AI19: 0 | AJ19: 0 | AK19: 0 | AL19: 0 | AM19: 0 | AN19: 0 | AO19: 0 | AP19: 0 | AQ19: 0 | AR19: 0 | AS19: 0 | AT19: 0 | AU19: 0 | AV19: 0 | AW19: 0 | AX19: 0 | AY19: 0 | AZ19: 0 | BA19: 0 | BB19: 0 | BC19: 0 | BD19: 0 | BE19: 0
