Workbook
Name nonlignite_multiplier: #REF!
Name tax_fuel_labels: '[1]Tax_Share of Price'!$A$2:$A$22
Name Tax_share: '[1]Tax_Share of Price'!$B$2:$AI$22

Sheet About
A1: IMFPbFT International Market Fuel Price by Fuel Type
A3: Source: | B3: Crude oil, selected petroleum products (petroleum, diesel, LPG) | D3: Start year coal, crude, and natural gas prices | F3: Petroleum gasoline, petroleum diesel, LPG
B4: Ministry of Petroleum and Natural Gas | D4: International Energy Agency | F4: Ministry of Petroleum and Natural Gas
B5: 2019 | D5: 2021 | F5: 2019
B6: Indian Petroleum and Nat Gas Statistics | D6: India Energy Outlook | F6: Indian Petroleum and Natural Gas Statistics 2018-2019
B7: http://petroleum.nic.in/sites/default/files/arep2020.pdf | D7: https://iea.blob.core.windows.net/assets/1de6d91e-e23f-4e02-b1fb-51fdd6283b22/India_Energy_Outlook_2021.pdf | F7: http://petroleum.nic.in/sites/default/files/arep2020.pdf
D8: Table 1.3 | F8: Table IV.4
B9: Table IV.4, page 80
B10: LNG | D10: Jet Fuel and Heavy Fuel Oil | F10: Crude oil scaling
B11: Petroleum Planning & Analysis Cell (PPAC) | D11: Petroleum Planning & Analysis Cell (PPAC) | F11: Energy Information Administration
B12: 2020 | D12: 2020 | F12: 2020
B13: Ready Reckoner: Oil Industry Information at a Glance | D13: Import/Export data tab | F13: Annual Energy Outlook
B14: https://www.ppac.gov.in/WriteReadData/Reports/202101120159244134186PPACRRNov2020WebVersion.pdf | D14: https://www.ppac.gov.in/content/212_1_ImportExport.aspx | F14: https://www.eia.gov/outlooks/aeo/
B15: Table 3.10, page 26 | D15: Data for Crude and Products - Value in Dollars (Historical); Data for Crude and Products - Quantity (Historical) | F15: Table 1
C17: Other fuels: fuel prices in EPS file fuels/BFPaT
A19: Notes | C19: 2019 to 2012 USD | D19: 0.89805482
A20: The prices in this variable should include export taxes, if any. In other words, they should be
A21: the prices paid on the global market.
A23: Electricity exports are handled separately (in the power sector), not in this variable.
A25: Nuclear here refers to nuclear fuel, i.e. uranium oxide, not electricity from nuclear plants.
A27: We estimate this value based on the prices seen within the United States.
A28: For fuels that vary by sector, we take a weighted average based on the first year consumption in the model.
A35: BTU per barrel crude oil | B35: 5698000 | C35: https://www.eia.gov/energyexplained/units-and-calculators/
A36: BTU per gallon motor gasoline | B36: 120286 | C36: https://www.eia.gov/energyexplained/units-and-calculators/
A37: BTU per gallon diesel fuel | B37: 137381 | C37: https://www.eia.gov/energyexplained/units-and-calculators/
A38: BTU per gallon propane | B38: 91452 | C38: https://www.eia.gov/energyexplained/units-and-calculators/
A39: gallons per barrel | B39: 42
A40: pounds per gallon propane | B40: 4.23 | C40: https://www.elgas.com.au/blog/1675-propane-conversion-values-pounds-gallons-btu-therms-ft-usa
A41: pounds per metric ton | B41: 2204.62
A42: 2019 to 2012 USD | B42: 0.89805482

Sheet Crude
B1: ref2020.d112119a | C1: 2019 | D1: 2020 | E1: 2021 | F1: 2022 | G1: 2023 | H1: 2024 | I1: 2025 | J1: 2026 | K1: 2027 | L1: 2028 | M1: 2029 | N1: 2030 | O1: 2031 | P1: 2032 | Q1: 2033 | R1: 2034 | S1: 2035 | T1: 2036 | U1: 2037 | V1: 2038 | W1: 2039 | X1: 2040 | Y1: 2041 | Z1: 2042 | AA1: 2043 | AB1: 2044 | AC1: 2045 | AD1: 2046 | AE1: 2047 | AF1: 2048 | AG1: 2049 | AH1: 2050
C3: Report | D3: Annual Energy Outlook 2020
C4: Scenario | D4: ref2020 | G4: Reference case
C5: Datekey | D5: d112119a
C6: Release Date | E6: January 2020
A10: SUP000 | B10: 1. Total Energy Supply, Disposition, and Price Summary
B11: (quadrillion Btu, unless otherwise noted)
AI12: 2019-
B13: Supply, Disposition, and Prices | C13: 2019 | D13: 2020 | E13: 2021 | F13: 2022 | G13: 2023 | H13: 2024 | I13: 2025 | J13: 2026 | K13: 2027 | L13: 2028 | M13: 2029 | N13: 2030 | O13: 2031 | P13: 2032 | Q13: 2033 | R13: 2034 | S13: 2035 | T13: 2036 | U13: 2037 | V13: 2038 | W13: 2039 | X13: 2040 | Y13: 2041 | Z13: 2042 | AA13: 2043 | AB13: 2044 | AC13: 2045 | AD13: 2046 | AE13: 2047 | AF13: 2048 | AG13: 2049 | AH13: 2050 | AI13: 2050
B15: Production
A16: SUP000:ba_CrudeOilLease | B16: Crude Oil and Lease Condensate | C16: 25.611994 | D16: 27.470049 | E16: 28.494802 | F16: 29.284983 | G16: 29.437077 | H16: 29.64554 | I16: 29.641726 | J16: 29.790983 | K16: 29.775187 | L16: 29.516684 | M16: 29.532515 | N16: 29.747253 | O16: 29.890884 | P16: 30.092388 | Q16: 30.068521 | R16: 29.858009 | S16: 29.67897 | T16: 29.407721 | U16: 29.011501 | V16: 28.693754 | W16: 28.532722 | X16: 28.853626 | Y16: 29.041647 | Z16: 29.058006 | AA16: 28.954979 | AB16: 28.623829 | AC16: 28.151617 | AD16: 27.620865 | AE16: 27.029858 | AF16: 26.494122 | AG16: 25.881308 | AH16: 24.79623 | AI16: -0.001044
A17: SUP000:ba_NaturalGasPla | B17: Natural Gas Plant Liquids | C17: 6.601902 | D17: 7.23189 | E17: 7.384439 | F17: 8.154555 | G17: 8.19707 | H17: 8.271167 | I17: 8.376472 | J17: 8.540577 | K17: 8.686964 | L17: 8.760511 | M17: 8.773496 | N17: 8.743604 | O17: 8.729358 | P17: 8.687426 | Q17: 8.662551 | R17: 8.694551 | S17: 8.730196 | T17: 8.706344 | U17: 8.6321 | V17: 8.586074 | W17: 8.573707 | X17: 8.595632 | Y17: 8.611508 | Z17: 8.613832 | AA17: 8.620247 | AB17: 8.584071 | AC17: 8.544112 | AD17: 8.467919 | AE17: 8.443357 | AF17: 8.449029 | AG17: 8.39084 | AH17: 8.190884 | AI17: 0.006981
A18: SUP000:ba_DryNaturalGas | B18: Dry Natural Gas | C18: 35.031666 | D18: 36.033657 | E18: 37.331188 | F18: 37.590195 | G18: 37.847775 | H18: 38.332695 | I18: 39.291294 | J18: 39.964729 | K18: 40.147495 | L18: 40.689774 | M18: 40.984024 | N18: 40.933514 | O18: 41.105022 | P18: 41.415512 | Q18: 41.783867 | R18: 42.303432 | S18: 42.534462 | T18: 42.787468 | U18: 43.062252 | V18: 43.329517 | W18: 43.569817 | X18: 43.935242 | Y18: 44.149738 | Z18: 44.370525 | AA18: 44.607227 | AB18: 44.817394 | AC18: 44.978981 | AD18: 45.196522 | AE18: 45.565365 | AF18: 46.018311 | AG18: 46.380791 | AH18: 46.616814 | AI18: 0.009259
A19: SUP000:ba_Coal | B19: Coal 1/ | C19: 13.567287 | D19: 12.301702 | E19: 11.91614 | F19: 12.097934 | G19: 11.528378 | H19: 11.431785 | I19: 10.959244 | J19: 11.374875 | K19: 11.346438 | L19: 11.251115 | M19: 11.165606 | N19: 11.150665 | O19: 11.095863 | P19: 11.075275 | Q19: 11.138651 | R19: 11.05944 | S19: 10.961893 | T19: 10.900166 | U19: 10.886232 | V19: 10.788899 | W19: 10.74003 | X19: 10.712185 | Y19: 10.675381 | Z19: 10.670083 | AA19: 10.665628 | AB19: 10.664737 | AC19: 10.636406 | AD19: 10.700363 | AE19: 10.683536 | AF19: 10.674273 | AG19: 10.64956 | AH19: 10.675206 | AI19: -0.007704
A20: SUP000:ba_NuclearPower | B20: Nuclear / Uranium 2/ | C20: 8.444715 | D20: 8.296324 | E20: 8.161823 | F20: 8.00919 | G20: 8.031043 | H20: 8.063392 | I20: 7.822189 | J20: 7.098251 | K20: 7.101179 | L20: 7.104901 | M20: 7.108607 | N20: 7.115708 | O20: 7.126846 | P20: 7.134424 | Q20: 6.972309 | R20: 6.798795 | S20: 6.813493 | T20: 6.82442 | U20: 6.826629 | V20: 6.828832 | W20: 6.828832 | X20: 6.739802 | Y20: 6.752901 | Z20: 6.762374 | AA20: 6.679939 | AB20: 6.687841 | AC20: 6.696404 | AD20: 6.700862 | AE20: 6.705318 | AF20: 6.708094 | AG20: 6.711448 | AH20: 6.716295 | AI20: -0.00736
A21: SUP000:ba_Hydropower | B21: Conventional Hydroelectric Power | C21: 2.627223 | D21: 2.628049 | E21: 2.60916 | F21: 2.559922 | G21: 2.51507 | H21: 2.473457 | I21: 2.458508 | J21: 2.399374 | K21: 2.392694 | L21: 2.383727 | M21: 2.377184 | N21: 2.371095 | O21: 2.372903 | P21: 2.363693 | Q21: 2.359036 | R21: 2.356455 | S21: 2.347385 | T21: 2.341803 | U21: 2.334253 | V21: 2.326471 | W21: 2.316797 | X21: 2.30683 | Y21: 2.298737 | Z21: 2.284055 | AA21: 2.284775 | AB21: 2.281344 | AC21: 2.272747 | AD21: 2.273704 | AE21: 2.281751 | AF21: 2.27995 | AG21: 2.273778 | AH21: 2.262525 | AI21: -0.004809
A22: SUP000:ba_Biomass | B22: Biomass 3/ | C22: 4.82346 | D22: 4.739875 | E22: 4.813442 | F22: 4.877365 | G22: 4.894251 | H22: 4.927381 | I22: 4.956337 | J22: 4.994683 | K22: 5.023758 | L22: 5.07172 | M22: 5.099788 | N22: 5.133343 | O22: 5.150183 | P22: 5.161369 | Q22: 5.174324 | R22: 5.189592 | S22: 5.204309 | T22: 5.217783 | U22: 5.227083 | V22: 5.240051 | W22: 5.251781 | X22: 5.269779 | Y22: 5.290954 | Z22: 5.310064 | AA22: 5.335333 | AB22: 5.360538 | AC22: 5.388065 | AD22: 5.414016 | AE22: 5.44756 | AF22: 5.475977 | AG22: 5.506855 | AH22: 5.535339 | AI22: 0.004451
A23: SUP000:ba_RenewableEner | B23: Other Renewable Energy 4/ | C23: 3.986613 | D23: 4.492028 | E23: 5.064552 | F23: 5.879107 | G23: 6.4833 | H23: 6.778963 | I23: 7.215426 | J23: 7.376397 | K23: 7.580525 | L23: 7.776433 | M23: 8.060765 | N23: 8.472414 | O23: 8.59905 | P23: 8.625295 | Q23: 8.670287 | R23: 8.711535 | S23: 8.961061 | T23: 9.156096 | U23: 9.308583 | V23: 9.491894 | W23: 9.665843 | X23: 9.871405 | Y23: 10.118544 | Z23: 10.417507 | AA23: 10.760035 | AB23: 11.121703 | AC23: 11.526014 | AD23: 11.799397 | AE23: 12.039868 | AF23: 12.214866 | AG23: 12.415702 | AH23: 12.642707 | AI23: 0.037932
A24: SUP000:ba_Other | B24: Other 5/ | C24: 1.418888 | D24: 0.827416 | E24: 0.769159 | F24: 0.813704 | G24: 0.904986 | H24: 0.936299 | I24: 0.882399 | J24: 0.736504 | K24: 0.703379 | L24: 0.718961 | M24: 0.716729 | N24: 0.678758 | O24: 0.673709 | P24: 0.67886 | Q24: 0.659729 | R24: 0.685346 | S24: 0.687655 | T24: 0.673603 | U24: 0.709672 | V24: 0.714011 | W24: 0.714281 | X24: 0.708251 | Y24: 0.716679 | Z24: 0.717886 | AA24: 0.720414 | AB24: 0.727804 | AC24: 0.736641 | AD24: 0.732407 | AE24: 0.752588 | AF24: 0.763026 | AG24: 0.771784 | AH24: 0.771613 | AI24: -0.019458
A25: SUP000:ba_Total | B25: Total | C25: 102.11375 | D25: 104.021 | E25: 106.5447 | F25: 109.26695 | G25: 109.83895 | H25: 110.86069 | I25: 111.60359 | J25: 112.27638 | K25: 112.75762 | L25: 113.27383 | M25: 113.81872 | N25: 114.34635 | O25: 114.74382 | P25: 115.23424 | Q25: 115.48928 | R25: 115.65715 | S25: 115.91942 | T25: 116.0154 | U25: 115.99831 | V25: 115.99951 | W25: 116.19381 | X25: 116.99274 | Y25: 117.65609 | Z25: 118.20432 | AA25: 118.62857 | AB25: 118.86927 | AC25: 118.93099 | AD25: 118.90606 | AE25: 118.94919 | AF25: 119.07764 | AG25: 118.98206 | AH25: 118.20762 | AI25: 0.004732
B27: Imports
A28: SUP000:ca_CrudeOil | B28: Crude Oil | C28: 15.553844 | D28: 15.955926 | E28: 14.746981 | F28: 14.677569 | G28: 14.71904 | H28: 15.418278 | I28: 14.744417 | J28: 15.570346 | K28: 14.863302 | L28: 15.257556 | M28: 15.021279 | N28: 14.408842 | O28: 14.093936 | P28: 14.057603 | Q28: 13.628367 | R28: 14.341786 | S28: 14.514404 | T28: 14.28753 | U28: 15.278381 | V28: 15.240164 | W28: 15.243741 | X28: 15.07306 | Y28: 15.523646 | Z28: 15.26584 | AA28: 15.396822 | AB28: 15.742918 | AC28: 16.219759 | AD28: 15.569624 | AE28: 16.714657 | AF28: 17.507576 | AG28: 17.736099 | AH28: 17.060543 | AI28: 0.002987
A29: SUP000:ca_PetroleumProd | B29: Petroleum and Other Liquids 6/ | C29: 4.821846 | D29: 4.868283 | E29: 4.253634 | F29: 4.223125 | G29: 4.250302 | H29: 4.26148 | I29: 4.086537 | J29: 3.826477 | K29: 3.768937 | L29: 3.592145 | M29: 3.521687 | N29: 3.555264 | O29: 3.535076 | P29: 3.544602 | Q29: 3.573062 | R29: 3.546082 | S29: 3.558302 | T29: 3.549997 | U29: 3.605515 | V29: 3.636478 | W29: 3.669384 | X29: 3.704446 | Y29: 3.763665 | Z29: 3.789318 | AA29: 3.821779 | AB29: 3.847737 | AC29: 3.916323 | AD29: 3.991392 | AE29: 4.004275 | AF29: 4.06438 | AG29: 4.142569 | AH29: 4.259105 | AI29: -0.003995
A30: SUP000:ca_NaturalGas | B30: Natural Gas | C30: 2.790417 | D30: 2.737625 | E30: 2.505311 | F30: 2.498467 | G30: 2.401366 | H30: 2.379171 | I30: 2.454679 | J30: 2.571234 | K30: 2.459452 | L30: 2.242131 | M30: 2.195501 | N30: 2.176357 | O30: 2.236829 | P30: 2.212133 | Q30: 2.110987 | R30: 2.082128 | S30: 2.056724 | T30: 2.042701 | U30: 2.06943 | V30: 2.063668 | W30: 2.065515 | X30: 2.069751 | Y30: 2.065326 | Z30: 2.055792 | AA30: 2.045062 | AB30: 2.024317 | AC30: 2.0111 | AD30: 2.004917 | AE30: 2.008925 | AF30: 1.993243 | AG30: 1.992269 | AH30: 1.991732 | AI30: -0.010818
A31: SUP000:ca_OtherImports | B31: Other 7/ | C31: 0.291471 | D31: 0.311483 | E31: 0.197879 | F31: 0.192162 | G31: 0.189143 | H31: 0.192052 | I31: 0.185666 | J31: 0.196601 | K31: 0.210408 | L31: 0.216355 | M31: 0.210658 | N31: 0.210847 | O31: 0.202959 | P31: 0.21087 | Q31: 0.211023 | R31: 0.219916 | S31: 0.217975 | T31: 0.213222 | U31: 0.212056 | V31: 0.210805 | W31: 0.211803 | X31: 0.211116 | Y31: 0.212711 | Z31: 0.211293 | AA31: 0.209861 | AB31: 0.208391 | AC31: 0.207404 | AD31: 0.202997 | AE31: 0.200745 | AF31: 0.198074 | AG31: 0.196592 | AH31: 0.195047 | AI31: -0.012874
A32: SUP000:ca_Total | B32: Total | C32: 23.457579 | D32: 23.873318 | E32: 21.703804 | F32: 21.591322 | G32: 21.559851 | H32: 22.250982 | I32: 21.4713 | J32: 22.164658 | K32: 21.302099 | L32: 21.308189 | M32: 20.949127 | N32: 20.351311 | O32: 20.068798 | P32: 20.025208 | Q32: 19.523439 | R32: 20.189913 | S32: 20.347406 | T32: 20.093451 | U32: 21.16538 | V32: 21.151117 | W32: 21.190443 | X32: 21.058371 | Y32: 21.56535 | Z32: 21.322243 | AA32: 21.473522 | AB32: 21.823364 | AC32: 22.354588 | AD32: 21.76893 | AE32: 22.9286 | AF32: 23.763273 | AG32: 24.06753 | AH32: 23.506428 | AI32: 6.7e-05
B34: Exports
A35: SUP000:da_Petroleum | B35: Petroleum and Other Liquids 8/ | C35: 16.702091 | D35: 19.42975 | E35: 19.203918 | F35: 20.904346 | G35: 21.426332 | H35: 22.721699 | I35: 22.201431 | J35: 23.043636 | K35: 22.691139 | L35: 22.76705 | M35: 22.613102 | N35: 22.22241 | O35: 22.091738 | P35: 22.258442 | Q35: 21.989693 | R35: 22.429056 | S35: 22.497185 | T35: 22.096922 | U35: 22.619617 | V35: 22.251133 | W35: 22.084496 | X35: 22.271158 | Y35: 22.863661 | Z35: 22.565138 | AA35: 22.484831 | AB35: 22.337135 | AC35: 22.191292 | AD35: 20.846298 | AE35: 21.177912 | AF35: 21.276543 | AG35: 20.703648 | AH35: 18.656487 | AI35: 0.003576
A36: SUP000:da_NaturalGas | B36: Natural Gas | C36: 4.483311 | D36: 5.391038 | E36: 6.298673 | F36: 6.64667 | G36: 6.840334 | H36: 7.332547 | I36: 8.27201 | J36: 9.033115 | K36: 9.262769 | L36: 9.576627 | M36: 9.78857 | N36: 9.935247 | O36: 9.964076 | P36: 10.002685 | Q36: 10.012971 | R36: 10.033694 | S36: 10.057024 | T36: 10.103948 | U36: 10.085648 | V36: 10.09483 | W36: 10.105273 | X36: 10.137658 | Y36: 10.119766 | Z36: 10.127851 | AA36: 10.137839 | AB36: 10.175268 | AC36: 10.159142 | AD36: 10.165966 | AE36: 10.173054 | AF36: 10.20885 | AG36: 10.192398 | AH36: 10.173193 | AI36: 0.026785
A37: SUP000:da_Coal | B37: Coal | C37: 2.384848 | D37: 2.087301 | E37: 2.218853 | F37: 2.73313 | G37: 2.749026 | H37: 2.765525 | I37: 2.784021 | J37: 2.799102 | K37: 2.782602 | L37: 2.714034 | M37: 2.662478 | N37: 2.660494 | O37: 2.659725 | P37: 2.65904 | Q37: 2.658399 | R37: 2.651743 | S37: 2.651135 | T37: 2.650574 | U37: 2.650053 | V37: 2.649575 | W37: 2.649134 | X37: 2.64873 | Y37: 2.648362 | Z37: 2.672349 | AA37: 2.697726 | AB37: 2.697454 | AC37: 2.705754 | AD37: 2.705624 | AE37: 2.69681 | AF37: 2.696648 | AG37: 2.705398 | AH37: 2.705374 | AI37: 0.004076
A38: SUP000:da_Total | B38: Total | C38: 23.57025 | D38: 26.908091 | E38: 27.721443 | F38: 30.284147 | G38: 31.015694 | H38: 32.819771 | I38: 33.257462 | J38: 34.875854 | K38: 34.736507 | L38: 35.057713 | M38: 35.064152 | N38: 34.818153 | O38: 34.715538 | P38: 34.920166 | Q38: 34.66106 | R38: 35.114494 | S38: 35.205341 | T38: 34.851444 | U38: 35.355316 | V38: 34.995537 | W38: 34.838905 | X38: 35.057549 | Y38: 35.63179 | Z38: 35.365337 | AA38: 35.320396 | AB38: 35.209858 | AC38: 35.056187 | AD38: 33.717888 | AE38: 34.047775 | AF38: 34.182041 | AG38: 33.601444 | AH38: 31.535053 | AI38: 0.009435
A40: SUP000:ea_Discrepancy | B40: Discrepancy 9/ | C40: 2.005173 | D40: 1.395311 | E40: 0.313889 | F40: 0.279282 | G40: 0.270277 | H40: 0.280891 | I40: 0.242027 | J40: 0.302582 | K40: 0.246792 | L40: 0.316021 | M40: 0.313488 | N40: 0.326683 | O40: 0.305225 | P40: 0.30619 | Q40: 0.196102 | R40: 0.262886 | S40: 0.272327 | T40: 0.187534 | U40: 0.302933 | V40: 0.293968 | W40: 0.297363 | X40: 0.276245 | Y40: 0.310047 | Z40: 0.27367 | AA40: 0.284153 | AB40: 0.290325 | AC40: 0.27346 | AD40: 0.243225 | AE40: 0.282581 | AF40: 0.31216 | AG40: 0.295788 | AH40: 0.254417 | AI40: - -
B42: Consumption
A43: SUP000:fa_PetroleumProd | B43: Petroleum and Other Liquids 10/ | C43: 38.035393 | D43: 38.281551 | E43: 38.194523 | F43: 38.067791 | G43: 37.910881 | H43: 37.636486 | I43: 37.401596 | J43: 37.254978 | K43: 37.025654 | L43: 36.959 | M43: 36.854237 | N43: 36.842789 | O43: 36.79459 | P43: 36.740559 | Q43: 36.651112 | R43: 36.683517 | S43: 36.670483 | T43: 36.619984 | U43: 36.633987 | V43: 36.659451 | W43: 36.704563 | X43: 36.747784 | Y43: 36.86544 | Z43: 36.99564 | AA43: 37.145874 | AB43: 37.317387 | AC43: 37.533596 | AD43: 37.730907 | AE43: 37.954109 | AF43: 38.181633 | AG43: 38.41666 | AH43: 38.663658 | AI43: 0.000529
A44: SUP000:fa_NaturalGas | B44: Natural Gas | C44: 32.14539 | D44: 32.202682 | E44: 33.071632 | F44: 32.998856 | G44: 32.985462 | H44: 32.969063 | I44: 33.063847 | J44: 33.072159 | K44: 32.902473 | L44: 32.90086 | M44: 32.929447 | N44: 32.68071 | O44: 32.879433 | P44: 33.152905 | Q44: 33.413578 | R44: 33.883789 | S44: 34.050732 | T44: 34.238548 | U44: 34.522491 | V44: 34.760571 | W44: 34.983902 | X44: 35.316647 | Y44: 35.527851 | Z44: 35.729935 | AA44: 35.940025 | AB44: 36.082645 | AC44: 36.243198 | AD44: 36.443565 | AE44: 36.785 | AF44: 37.169861 | AG44: 37.552456 | AH44: 37.810448 | AI44: 0.00525
A45: SUP000:fa_Coal | B45: Coal 11/ | C45: 11.249906 | D45: 10.258844 | E45: 9.692323 | F45: 9.344917 | G45: 8.750343 | H45: 8.628566 | I45: 8.145056 | J45: 8.559067 | K45: 8.541109 | L45: 8.518984 | M45: 8.481165 | N45: 8.459363 | O45: 8.403361 | P45: 8.385563 | Q45: 8.449744 | R45: 8.376008 | S45: 8.278006 | T45: 8.216821 | U45: 8.203781 | V45: 8.111191 | W45: 8.057528 | X45: 8.031965 | Y45: 7.995692 | Z45: 7.965323 | AA45: 7.935738 | AB45: 7.933951 | AC45: 7.896763 | AD45: 7.962496 | AE45: 7.953084 | AF45: 7.944196 | AG45: 7.91083 | AH45: 7.936447 | AI45: -0.011192
A46: SUP000:fa_NuclearPower | B46: Nuclear / Uranium 2/ | C46: 8.444715 | D46: 8.296324 | E46: 8.161823 | F46: 8.00919 | G46: 8.031043 | H46: 8.063392 | I46: 7.822189 | J46: 7.098251 | K46: 7.101179 | L46: 7.104901 | M46: 7.108607 | N46: 7.115708 | O46: 7.126846 | P46: 7.134424 | Q46: 6.972309 | R46: 6.798795 | S46: 6.813493 | T46: 6.82442 | U46: 6.826629 | V46: 6.828832 | W46: 6.828832 | X46: 6.739802 | Y46: 6.752901 | Z46: 6.762374 | AA46: 6.679939 | AB46: 6.687841 | AC46: 6.696404 | AD46: 6.700862 | AE46: 6.705318 | AF46: 6.708094 | AG46: 6.711448 | AH46: 6.716295 | AI46: -0.00736
A47: SUP000:fa_Hydropower | B47: Conventional Hydroelectric Power | C47: 2.627223 | D47: 2.628049 | E47: 2.60916 | F47: 2.559922 | G47: 2.51507 | H47: 2.473457 | I47: 2.458508 | J47: 2.399374 | K47: 2.392694 | L47: 2.383727 | M47: 2.377184 | N47: 2.371095 | O47: 2.372903 | P47: 2.363693 | Q47: 2.359036 | R47: 2.356455 | S47: 2.347385 | T47: 2.341803 | U47: 2.334253 | V47: 2.326471 | W47: 2.316797 | X47: 2.30683 | Y47: 2.298737 | Z47: 2.284055 | AA47: 2.284775 | AB47: 2.281344 | AC47: 2.272747 | AD47: 2.273704 | AE47: 2.281751 | AF47: 2.27995 | AG47: 2.273778 | AH47: 2.262525 | AI47: -0.004809
A48: SUP000:fa_Biomass | B48: Biomass 12/ | C48: 3.225397 | D48: 3.108829 | E48: 3.111676 | F48: 3.142795 | G48: 3.15063 | H48: 3.167369 | I48: 3.186579 | J48: 3.215469 | K48: 3.232934 | L48: 3.257947 | M48: 3.275252 | N48: 3.298345 | O48: 3.311273 | P48: 3.31843 | Q48: 3.327163 | R48: 3.338353 | S48: 3.348562 | T48: 3.357383 | U48: 3.361934 | V48: 3.370085 | W48: 3.376801 | X48: 3.389724 | Y48: 3.405491 | Z48: 3.419021 | AA48: 3.438693 | AB48: 3.456382 | AC48: 3.476807 | AD48: 3.496759 | AE48: 3.524088 | AF48: 3.546339 | AG48: 3.570926 | AH48: 3.59317 | AI48: 0.003489
A49: SUP000:fa_RenewableEner | B49: Other Renewable Energy 4/ | C49: 3.986613 | D49: 4.492028 | E49: 5.064552 | F49: 5.879107 | G49: 6.4833 | H49: 6.778963 | I49: 7.215426 | J49: 7.376397 | K49: 7.580525 | L49: 7.776433 | M49: 8.060765 | N49: 8.472414 | O49: 8.59905 | P49: 8.625295 | Q49: 8.670287 | R49: 8.711535 | S49: 8.961061 | T49: 9.156096 | U49: 9.308583 | V49: 9.491894 | W49: 9.665843 | X49: 9.871405 | Y49: 10.118544 | Z49: 10.417507 | AA49: 10.760035 | AB49: 11.121703 | AC49: 11.526014 | AD49: 11.799397 | AE49: 12.039868 | AF49: 12.214866 | AG49: 12.415702 | AH49: 12.642707 | AI49: 0.037932
...

Sheet India Petroleum Products
C23: crude | D23: petrol | E23: diesel | F23: kerosene | G23: LPG
B24: 2018-2019 | C24: 69.88 | D24: 75.58 | E24: 82.51 | F24: 82.24 | G24: 526
B25: correct units | D25: =D24/About!B39/About!B36*About!B42 -> 1.3435238e-05 | E25: =E24/About!B39/About!B37*About!B42 -> 1.2842024e-05 | G25: =G24/About!B38*About!B42*About!B40/About!B41 -> 9.910647e-06
B26: US value | C26: =Crude!C54 -> 63.371998
B27: ratio to US | C27: =C24/Crude!C54 -> 1.1026952

Sheet IEA
A2: crude oil | B2: 2019 USD / barrel | C2: 63
A3: natural gas | B3: 2019 USD / Mbtu | C3: 11
A4: coal | B4: 2019 USD / tonne | C4: 68
A6: crude oil | B6: 2012 USD / BTU | C6: =C2/B25*About!D19 -> 9.9415662e-06
A7: natural gas | B7: 2012 USD / BTU | C7: =C3/1000000*About!D19 -> 9.878603e-06
A8: coal | B8: 2012 USD / BTU | C8: =C4/1000/6000/B26 -> 2.8566363e-06
A25: BTU per gallon crude | B25: 5691000 | C25: https://www.eia.gov/energyexplained/units-and-calculators/
A26: kcal per BTU | B26: 3.96737 | C26: https://www.convertunits.com/from/btu/to/kcal

Sheet LNG
A1: Import Quantity and Value of LNG in India
A2: Financial Year | B2: LNG Import Quantity (MMT) | C2: Value (Million USD) | D2: Price (USD/MT)
A3: 2019 | B3: 21.7 | C3: 10253 | D3: =C3/B3 -> 472.48848
A4: 2020 | B4: 25.6 | C4: 9489 | D4: =C4/B4 -> 370.66406
G13: Source: | H13: PPAC

Sheet Data - Other Petroleum Producs
E3: Petroleum Planning & Analysis Cell
A5: Period : 1998-99 - 2019-20
A6: ('Million US$)
A7: Import/Export of Crude oil and Petroleum Products
A8: IMPORT/EXPORT | B8: 1998-99 | C8: 1999-2000 | D8: 2000-01 | E8: 2001-02 | F8: 2002-03 | G8: 2003-04 | H8: 2004-05 | I8: 2005-06 | J8: 2006-07 | K8: 2007-08 | L8: 2008-09 | M8: 2009-10 | N8: 2010-11 | O8: 2011-12 | P8: 2012-13 | Q8: 2013-14 | R8: 2014-15 | S8: 2015-16 | T8: 2016-17 | U8: 2017-18 | V8: 2018-19 | W8: 2019-20
A9: IMPORT^
A10: CRUDE OIL$ | B10: 3518 | C10: 9210 | D10: 14403 | E10: 12635 | F10: 15759 | G10: 18268 | H10: 25990 | I10: 38776 | J10: 48389 | K10: 67988 | L10: 76876 | M10: 79553 | N10: 100080 | O10: 139689.92 | P10: 144293.12 | Q10: 142961.59 | R10: 112743.58 | S10: 63972.376 | T10: 70196.061 | U10: 87803.146 | V10: 111914.67 | W10: 101376.19
A11: PRODUCTS
A12: LPG | B12: 300 | C12: 414 | D12: 291 | E12: 168 | F12: 388 | G12: 561 | H12: 998 | I12: 1575 | J12: 1276 | K12: 2163 | L12: 1733 | M12: 1767.1847 | N12: 3469.1717 | O12: 5584.0221 | P12: 5803.2922 | Q12: 6144.0164 | R12: 5954.7569 | S12: 3921.7221 | T12: 4774.5942 | U12: 5848.8457 | V12: 7178.232 | W12: 7069.9862
A13: MS | B13: 45 | C13: 0 | D13: 0 | E13: 0 | F13: 0 | G13: 0 | H13: 114 | I13: 293 | J13: 290 | K13: 281 | L13: 352 | M13: 266.12711 | N13: 1403.3623 | O13: 716.13787 | P13: 159.86164 | Q13: 247.54491 | R13: 375.45 | S13: 648.2648 | T13: 239.491 | U13: 90.872213 | V13: 444.88045 | W13: 1356.8026
A14: Naphtha | B14: 315 | C14: 452 | D14: 897 | E14: 724 | F14: 729 | G14: 626 | H14: 841 | I14: 1209 | J14: 3142 | K14: 4582 | L14: 3802 | M14: 1029.1056 | N14: 1452.9948 | O14: 2022.4442 | P14: 1691.3716 | Q14: 981.7382 | R14: 744.49111 | S14: 1462.9304 | T14: 1239.774 | U14: 1260.6556 | V14: 1390.5608 | W14: 941.03583
A15: ATF | B15: 0 | C15: 0 | D15: 0 | E15: 0 | F15: 0 | G15: 0 | H15: 0 | I15: 0 | J15: 0 | K15: 0 | L15: 0 | N15: 0 | O15: 0 | P15: 0 | Q15: 0 | R15: 113.70392 | S15: 135.31372 | T15: 163.38542 | U15: 178.43668 | V15: 199.98127 | W15: 44.667822
A16: SKO | B16: 923 | C16: 1276 | D16: 521 | E16: 81 | F16: 166 | G16: 191 | H16: 98 | I16: 597 | J16: 933 | K16: 2072 | L16: 1486 | M16: 614.22717 | N16: 1080.9681 | O16: 596.83554 | P16: 0 | Q16: 0 | R16: 28.813641 | S16: 24.659992 | T16: 0 | U16: 0 | V16: 0 | W16: 0
A17: HSD | B17: 1134 | C17: 854 | D17: 0 | E17: 6 | F17: 24 | G17: 25 | H17: 361 | I17: 435 | J17: 589 | K17: 2265 | L17: 2198 | M17: 1331.5644 | N17: 1505.0639 | O17: 1096.036 | P17: 506.88767 | Q17: 74.072632 | R17: 108.41536 | S17: 91.621161 | T17: 438.26333 | U17: 659.50824 | V17: 360.45934 | W17: 1632.3766
A18: LOBS/ Lube oil | B18: 35 | C18: 68 | D18: 123 | E18: 123 | F18: 108 | G18: 213 | H18: 215 | I18: 661 | J18: 748 | K18: 844 | L18: 988 | M18: 732.67094 | N18: 854.70487 | O18: 1707.5715 | P18: 2067.5304 | Q18: 2121.5847 | R18: 2067.2065 | S18: 1438.875 | T18: 1275.6037 | U18: 1860.1072 | V18: 1909.5383 | W18: 1672.9278
A19: Fuel Oil | B19: 142 | C19: 199 | D19: 286 | E19: 306 | F19: 403 | G19: 337 | H19: 374 | I19: 685 | J19: 1142 | K19: 1861 | L19: 1748 | M19: 405.54544 | N19: 527.18041 | O19: 911.78997 | P19: 777.60723 | Q19: 942.13116 | R19: 598.74818 | S19: 363.3913 | T19: 273.42338 | U19: 499.38452 | V19: 696.48878 | W19: 1649.7757
A20: Bitumen | B20: 0 | C20: 0 | D20: 0 | E20: 1 | F20: 0 | G20: 1 | H20: 4 | I20: 5 | J20: 4 | K20: 13 | L20: 43.022 | M20: 28.920326 | N20: 43.495004 | O20: 40.240202 | P20: 49.799675 | Q20: 132.43756 | R20: 261.51723 | S20: 278.89057 | T20: 242.41381 | U20: 293.24164 | V20: 309.13012 | W20: 509.73769
A21: Others& | B21: 1 | C21: 1 | D21: 524 | E21: 102 | F21: 4 | G21: 160 | H21: 273 | I21: 842 | J21: 944 | K21: 1045 | L21: 1207 | M21: 912.25609 | N21: 1731.3884 | O21: 1513.7227 | P21: 1533.6298 | Q21: 1822.2735 | R21: 1884.8814 | S21: 1586.4007 | T21: 1966.8227 | U21: 2945.9146 | V21: 3851.5187 | W21: 2811.3684
A22: PRODUCT IMPORT* | B22: =SUM(B12:B21) -> 2895 | C22: =SUM(C12:C21) -> 3264 | D22: =SUM(D12:D21) -> 2642 | E22: =SUM(E12:E21) -> 1511 | F22: =SUM(F12:F21) -> 1822 | G22: =SUM(G12:G21) -> 2114 | H22: =SUM(H12:H21) -> 3278 | I22: =SUM(I12:I21) -> 6302 | ... W22: =SUM(W12:W21) -> 17688.679
A24: TOTAL IMPORTS | B24: =+B10+B22 -> 6413 | C24: =+C10+C22 -> 12474 | D24: =+D10+D22 -> 17045 | E24: =+E10+E22 -> 14146 | F24: =+F10+F22 -> 17581 | G24: =+G10+G22 -> 20382 | H24: =+H10+H22 -> 29268 | I24: =+I10+I22 -> 45078 | ... W24: =+W10+W22 -> 119064.87
A26: PRODUCT EXPORT @
A27: LPG | B27: 0 | C27: 0 | D27: 0 | E27: 0 | F27: 0 | G27: 0 | H27: 69 | I27: 37 | J27: 75 | K27: 99 | L27: 97 | M27: 104 | N27: 151 | O27: 195.03531 | P27: 235.95505 | Q27: 259.57026 | R27: 235.74398 | S27: 119.53333 | T27: 172.90567 | U27: 231.16794 | V27: 282.75008 | W27: 276.98938
A28: MS! | B28: 0 | C28: 32 | D28: 315 | E28: 538 | F28: 623 | G28: 876 | H28: 1251 | I28: 1314 | J28: 2252 | K28: 3392 | L28: 4008 | M28: 6650 | N28: 10861 | O28: 15477.819 | P28: 17528.218 | Q28: 15397.215 | R28: 13453.878 | S28: 9119.5401 | T28: 7895.4941 | U28: 8464.4876 | V28: 8641.1337 | W28: 7707.509
A29: Naphtha$ | B29: 86 | C29: 120 | D29: 715 | E29: 479 | F29: 485 | G29: 577 | H29: 1123 | I29: 2426 | J29: 4741 | K29: 6791 | L29: 5643 | M29: 6419 | N29: 8161 | O29: 9482.1125 | P29: 7991.7216 | Q29: 7583.6722 | R29: 5176.2248 | S29: 3070.8717 | T29: 3666.0796 | U29: 4504.6418 | V29: 4137.0453 | W29: 4438.9957
A30: ATF# | B30: 0 | C30: 0 | D30: 38 | E30: 36 | F30: 169 | G30: 427 | H30: 991 | I30: 1588 | J30: 2264 | K30: 3376 | L30: 2999 | M30: 2824 | N30: 3546 | O30: 4568.3114 | P30: 4644.5557 | Q30: 5487.0023 | R30: 4155.3918 | S30: 2439.7655 | T30: 3323.9504 | U30: 3931.1457 | V30: 4866.6891 | W30: 4020.9875
A31: SKO | B31: 0 | C31: 0 | D31: 0 | E31: 0 | F31: 0 | G31: 0 | H31: 102 | I31: 84 | J31: 119 | K31: 122 | L31: 77 | M31: 32 | N31: 30.905 | O31: 39.352431 | P31: 25.468013 | Q31: 16.068751 | R31: 13.153516 | S31: 5.3835747 | T31: 8.0592246 | U31: 10.48838 | V31: 14.004637 | W31: 77.579332
A32: HSD | B32: 0 | C32: 0 | D32: 409 | E32: 533 | F32: 735 | G32: 1475 | H32: 2627 | I32: 4189 | J32: 6427 | K32: 10178 | L32: 11032 | M32: 10747 | N32: 15220 | O32: 21746.08 | P32: 21252.772 | Q32: 24336.183 | R32: 18865.25 | S32: 10179.635 | T32: 11904.571 | U32: 15420.008 | V32: 17625.177 | W32: 17480.663
A33: LDO | B33: 0 | C33: 0 | D33: 2 | E33: 5 | F33: 0 | G33: 0 | H33: 0 | I33: 0.1 | J33: 0.1 | K33: 0 | L33: 0.29 | M33: 19 | N33: 56 | O33: 69.168862 | P33: 7.8491182 | Q33: 21.569 | R33: 4.7613024 | S33: 0 | T33: 58.93556 | U33: 5.7399022 | V33: 49.59 | W33: 0
A34: LOBS/ Lube Oil | B34: 0 | C34: 0 | D34: 0 | E34: 0 | F34: 5 | G34: 8 | H34: 5 | I34: 80 | J34: 273 | K34: 171 | L34: 136 | M34: 26 | N34: 33.6 | O34: 36.499165 | P34: 64.939777 | Q34: 26.531846 | R34: 16.008203 | S34: 19.626317 | T34: 15.403929 | U34: 18.280079 | V34: 15.122732 | W34: 13.483252
A35: Fuel Oil | B35: 0 | C35: 0 | D35: 70 | E35: 53 | F35: 178 | G35: 204 | H35: 338 | I35: 522 | J35: 1101 | K35: 1696 | L35: 2737 | M35: 2250 | N35: 3318 | O35: 5311.9325 | P35: 3757.0654 | Q35: 3670.7011 | R35: 2320.6854 | S35: 687.76926 | T35: 583.31613 | U35: 817.37605 | V35: 922.63138 | W35: 536.51121
A36: Bitumen | B36: 0 | C36: 0 | D36: 0 | E36: 0 | F36: 0 | G36: 1 | H36: 7 | I36: 6 | J36: 17 | K36: 13 | L36: 13.6 | M36: 12 | N36: 27 | O36: 5.6141804 | P36: 52.028923 | Q36: 52.35385 | R36: 40.032269 | S36: 27.439318 | T36: 5.5166441 | U36: 18.248011 | V36: 10.180122 | W36: 12.514926
A37: Others% | B37: 0 | C37: 9 | D37: 127 | E37: 87 | F37: 56 | G37: 93 | H37: 147 | I37: 987 | J37: 638 | K37: 1718 | L37: 539 | M37: 1580 | N37: 1935.4 | O37: 2386.993 | P37: 3287.8382 | Q37: 3813.5562 | R37: 2995.4754 | S37: 1389.7833 | T37: 1415.1403 | U37: 1518.2003 | V37: 1671.2996 | W37: 1282.7146
A38: TOTAL PRODUCT EXPORT | B38: =SUM(B27:B37) -> 86 | C38: =SUM(C27:C37) -> 161 | D38: =SUM(D27:D37) -> 1676 | E38: =SUM(E27:E37) -> 1731 | F38: =SUM(F27:F37) -> 2251 | G38: =SUM(G27:G37) -> 3661 | H38: =SUM(H27:H37) -> 6660 | I38: =SUM(I27:I37) -> 11233.1 | ... W38: =SUM(W27:W37) -> 35847.948
A40: NET IMPORT | B40: =+B24-B38 -> 6327 | C40: =+C24-C38 -> 12313 | D40: =+D24-D38 -> 15369 | E40: =+E24-E38 -> 12415 | F40: =+F24-F38 -> 15330 | G40: =+G24-G38 -> 16721 | H40: =+H24-H38 -> 22608 | I40: =+I24-I38 -> 33844.9 | ... W40: =+W24-W38 -> 83216.923
A42: NET PRODUCT EXPORT | B42: =+B38-B22 -> -2809 | C42: =+C38-C22 -> -3103 | D42: =+D38-D22 -> -966 | E42: =+E38-E22 -> 220 | F42: =+F38-F22 -> 429 | G42: =+G38-G22 -> 1547 | H42: =+H38-H22 -> 3382 | I42: =+I38-I22 -> 4931.1 | ... W42: =+W38-W22 -> 18159.27
A43: Source : Oil Companies & DGCIS, (P) : Provisional
A44: Notes:
A45: RIL SEZ imports/exports included in country's import/export data
A46: ^LNG import not included
A47: $Crude oil imports does not include value of crude oil quantity of 756 TMT imported at ISPRL, Mangalore during 2018-19.
...

Sheet Pretax Fuel Prices
A1: Hard Coal
A2: Year | B2: 2021 | C2: 2022 | D2: 2023 | E2: 2024 | F2: 2025 | G2: 2026 | H2: 2027 | I2: 2028 | J2: 2029 | K2: 2030 | L2: 2031 | M2: 2032 | N2: 2033 | O2: 2034 | P2: 2035 | Q2: 2036 | R2: 2037 | S2: 2038 | T2: 2039 | U2: 2040 | V2: 2041 | W2: 2042 | X2: 2043 | Y2: 2044 | Z2: 2045 | AA2: 2046 | AB2: 2047 | AC2: 2048 | AD2: 2049 | AE2: 2050 | AF2: 2051 | AG2: 2052 | AH2: 2053 | AI2: 2054 | AJ2: 2055 | AK2: 2056 | AL2: 2057 | AM2: 2058 | AN2: 2059 | AO2: 2060 | AP2: 2061 | AQ2: 2062 | AR2: 2063 | AS2: 2064 | AT2: 2065 | AU2: 2066 | AV2: 2067 | AW2: 2068 | AX2: 2069 | AY2: 2070
A3: Transportation Sector | B3: 0 | C3: 0 | D3: 0 | E3: 0 | F3: 0 | G3: 0 | H3: 0 | I3: 0 | J3: 0 | K3: 0 | L3: 0 | M3: 0 | N3: 0 | O3: 0 | P3: 0 | Q3: 0 | R3: 0 | S3: 0 | T3: 0 | U3: 0 | V3: 0 | W3: 0 | X3: 0 | Y3: 0 | Z3: 0 | AA3: 0 | AB3: 0 | AC3: 0 | AD3: 0 | AE3: 0
A4: Electricity Sector | B4: 1.5268673e-06 | C4: 1.5268673e-06 | D4: 1.5194553e-06 | E4: 1.5268673e-06 | F4: 1.5046313e-06 | G4: 1.4823954e-06 | H4: 1.4675714e-06 | I4: 1.4601595e-06 | J4: 1.4453355e-06 | K4: 1.4527475e-06 | L4: 1.4601595e-06 | M4: 1.4527475e-06 | N4: 1.4527475e-06 | O4: 1.4527475e-06 | P4: 1.4453355e-06 | Q4: 1.4453355e-06 | R4: 1.4527475e-06 | S4: 1.4527475e-06 | T4: 1.4453355e-06 | U4: 1.4453355e-06 | V4: 1.4527475e-06 | W4: 1.4527475e-06 | X4: 1.4453355e-06 | Y4: 1.4453355e-06 | Z4: 1.4453355e-06 | AA4: 1.4453355e-06 | AB4: 1.4453355e-06 | AC4: 1.4453355e-06 | AD4: 1.4453355e-06 | AE4: 1.4453355e-06
A5: Residential Buildings Sector | B5: 0 | C5: 0 | D5: 0 | E5: 0 | F5: 0 | G5: 0 | H5: 0 | I5: 0 | J5: 0 | K5: 0 | L5: 0 | M5: 0 | N5: 0 | O5: 0 | P5: 0 | Q5: 0 | R5: 0 | S5: 0 | T5: 0 | U5: 0 | V5: 0 | W5: 0 | X5: 0 | Y5: 0 | Z5: 0 | AA5: 0 | AB5: 0 | AC5: 0 | AD5: 0 | AE5: 0
A6: Commercial Buildings Sector | B6: 0 | C6: 0 | D6: 0 | E6: 0 | F6: 0 | G6: 0 | H6: 0 | I6: 0 | J6: 0 | K6: 0 | L6: 0 | M6: 0 | N6: 0 | O6: 0 | P6: 0 | Q6: 0 | R6: 0 | S6: 0 | T6: 0 | U6: 0 | V6: 0 | W6: 0 | X6: 0 | Y6: 0 | Z6: 0 | AA6: 0 | AB6: 0 | AC6: 0 | AD6: 0 | AE6: 0
A7: Industry Sector | B7: 1.8314932e-06 | C7: 1.8314932e-06 | D7: 1.8314932e-06 | E7: 1.8314932e-06 | F7: 1.8526258e-06 | G7: 1.8526258e-06 | H7: 1.8526258e-06 | I7: 1.85967e-06 | J7: 1.8667142e-06 | K7: 1.8737584e-06 | L7: 1.8878468e-06 | M7: 1.8878468e-06 | N7: 1.894891e-06 | O7: 1.9019352e-06 | P7: 1.9089794e-06 | Q7: 1.9089794e-06 | R7: 1.9160236e-06 | S7: 1.9160236e-06 | T7: 1.9230678e-06 | U7: 1.9230678e-06 | V7: 1.930112e-06 | W7: 1.9371562e-06 | X7: 1.9442004e-06 | Y7: 1.9512446e-06 | Z7: 1.9582888e-06 | AA7: 1.965333e-06 | AB7: 1.9723773e-06 | AC7: 1.9794215e-06 | AD7: 1.9864657e-06 | AE7: 1.9935099e-06
A8: District Heating Sector | B8: 1.8314932e-06 | C8: 1.8314932e-06 | D8: 1.8314932e-06 | E8: 1.8314932e-06 | F8: 1.8526258e-06 | G8: 1.8526258e-06 | H8: 1.8526258e-06 | I8: 1.85967e-06 | J8: 1.8667142e-06 | K8: 1.8737584e-06 | L8: 1.8878468e-06 | M8: 1.8878468e-06 | N8: 1.894891e-06 | O8: 1.9019352e-06 | P8: 1.9089794e-06 | Q8: 1.9089794e-06 | R8: 1.9160236e-06 | S8: 1.9160236e-06 | T8: 1.9230678e-06 | U8: 1.9230678e-06 | V8: 1.930112e-06 | W8: 1.9371562e-06 | X8: 1.9442004e-06 | Y8: 1.9512446e-06 | Z8: 1.9582888e-06 | AA8: 1.965333e-06 | AB8: 1.9723773e-06 | AC8: 1.9794215e-06 | AD8: 1.9864657e-06 | AE8: 1.9935099e-06
A9: LULUCF Sector | B9: 0 | C9: 0 | D9: 0 | E9: 0 | F9: 0 | G9: 0 | H9: 0 | I9: 0 | J9: 0 | K9: 0 | L9: 0 | M9: 0 | N9: 0 | O9: 0 | P9: 0 | Q9: 0 | R9: 0 | S9: 0 | T9: 0 | U9: 0 | V9: 0 | W9: 0 | X9: 0 | Y9: 0 | Z9: 0 | AA9: 0 | AB9: 0 | AC9: 0 | AD9: 0 | AE9: 0
A10: Geoengineering Sector | B10: 1.8314932e-06 | C10: 1.8314932e-06 | D10: 1.8314932e-06 | E10: 1.8314932e-06 | F10: 1.8526258e-06 | G10: 1.8526258e-06 | H10: 1.8526258e-06 | I10: 1.85967e-06 | J10: 1.8667142e-06 | K10: 1.8737584e-06 | L10: 1.8878468e-06 | M10: 1.8878468e-06 | N10: 1.894891e-06 | O10: 1.9019352e-06 | P10: 1.9089794e-06 | Q10: 1.9089794e-06 | R10: 1.9160236e-06 | S10: 1.9160236e-06 | T10: 1.9230678e-06 | U10: 1.9230678e-06 | V10: 1.930112e-06 | W10: 1.9371562e-06 | X10: 1.9442004e-06 | Y10: 1.9512446e-06 | Z10: 1.9582888e-06 | AA10: 1.965333e-06 | AB10: 1.9723773e-06 | AC10: 1.9794215e-06 | AD10: 1.9864657e-06 | AE10: 1.9935099e-06
A11: Natural Gas
A12: Year | B12: 2021 | C12: 2022 | D12: 2023 | E12: 2024 | F12: 2025 | G12: 2026 | H12: 2027 | I12: 2028 | J12: 2029 | K12: 2030 | L12: 2031 | M12: 2032 | N12: 2033 | O12: 2034 | P12: 2035 | Q12: 2036 | R12: 2037 | S12: 2038 | T12: 2039 | U12: 2040 | V12: 2041 | W12: 2042 | X12: 2043 | Y12: 2044 | Z12: 2045 | AA12: 2046 | AB12: 2047 | AC12: 2048 | AD12: 2049 | AE12: 2050 | AF12: 2051 | AG12: 2052 | AH12: 2053 | AI12: 2054 | AJ12: 2055 | AK12: 2056 | AL12: 2057 | AM12: 2058 | AN12: 2059 | AO12: 2060 | AP12: 2061 | AQ12: 2062 | AR12: 2063 | AS12: 2064 | AT12: 2065 | AU12: 2066 | AV12: 2067 | AW12: 2068 | AX12: 2069 | AY12: 2070
A13: Transportation Sector | B13: 9.374745e-06 | C13: 9.374745e-06 | D13: 9.374745e-06 | E13: 9.374745e-06 | F13: 1.4066754e-05 | G13: 1.463362e-05 | H13: 1.357496e-05 | I13: 1.2710594e-05 | J13: 1.3066861e-05 | K13: 1.3538699e-05 | L13: 1.3800959e-05 | M13: 1.4406e-05 | N13: 1.4928258e-05 | O13: 1.5170167e-05 | P13: 1.5236079e-05 | Q13: 1.5528957e-05 | R13: 1.5820057e-05 | S13: 1.5955383e-05 | T13: 1.6026417e-05 | U13: 1.6047372e-05 | V13: 1.6006556e-05 | W13: 1.610373e-05 | X13: 1.6106525e-05 | Y13: 1.6101521e-05 | Z13: 1.6100477e-05 | AA13: 1.6008398e-05 | AB13: 1.5903716e-05 | AC13: 1.5886559e-05 | AD13: 1.5913007e-05 | AE13: 1.597338e-05
A14: Electricity Sector | B14: 5.68763e-06 | C14: 5.68763e-06 | D14: 5.68763e-06 | E14: 5.68763e-06 | F14: 8.5342578e-06 | G14: 8.8781735e-06 | H14: 8.2358879e-06 | I14: 7.7114793e-06 | J14: 7.927626e-06 | K14: 8.2138884e-06 | L14: 8.3730011e-06 | M14: 8.7400777e-06 | N14: 9.0569296e-06 | O14: 9.2036953e-06 | P14: 9.243684e-06 | Q14: 9.4213722e-06 | R14: 9.5979815e-06 | S14: 9.6800838e-06 | T14: 9.7231799e-06 | U14: 9.735893e-06 | V14: 9.7111302e-06 | W14: 9.7700852e-06 | X14: 9.7717807e-06 | Y14: 9.7687449e-06 | Z14: 9.7681118e-06 | AA14: 9.7122476e-06 | AB14: 9.6487374e-06 | AC14: 9.6383281e-06 | AD14: 9.6543742e-06 | AE14: 9.6910023e-06
A15: Residential Buildings Sector | B15: 9.374745e-06 | C15: 9.374745e-06 | D15: 9.374745e-06 | E15: 9.374745e-06 | F15: 9.374745e-06 | G15: 9.374745e-06 | H15: 9.374745e-06 | I15: 9.374745e-06 | J15: 9.374745e-06 | K15: 9.374745e-06 | L15: 9.374745e-06 | M15: 9.374745e-06 | N15: 9.374745e-06 | O15: 9.374745e-06 | P15: 9.374745e-06 | Q15: 9.374745e-06 | R15: 9.374745e-06 | S15: 9.374745e-06 | T15: 9.374745e-06 | U15: 9.374745e-06 | V15: 9.374745e-06 | W15: 9.374745e-06 | X15: 9.374745e-06 | Y15: 9.374745e-06 | Z15: 9.374745e-06 | AA15: 9.374745e-06 | AB15: 9.374745e-06 | AC15: 9.374745e-06 | AD15: 9.374745e-06 | AE15: 9.374745e-06
A16: Commercial Buildings Sector | B16: 9.374745e-06 | C16: 9.374745e-06 | D16: 9.374745e-06 | E16: 9.374745e-06 | F16: 9.374745e-06 | G16: 9.374745e-06 | H16: 9.374745e-06 | I16: 9.374745e-06 | J16: 9.374745e-06 | K16: 9.374745e-06 | L16: 9.374745e-06 | M16: 9.374745e-06 | N16: 9.374745e-06 | O16: 9.374745e-06 | P16: 9.374745e-06 | Q16: 9.374745e-06 | R16: 9.374745e-06 | S16: 9.374745e-06 | T16: 9.374745e-06 | U16: 9.374745e-06 | V16: 9.374745e-06 | W16: 9.374745e-06 | X16: 9.374745e-06 | Y16: 9.374745e-06 | Z16: 9.374745e-06 | AA16: 9.374745e-06 | AB16: 9.374745e-06 | AC16: 9.374745e-06 | AD16: 9.374745e-06 | AE16: 9.374745e-06
A17: Industry Sector | B17: 9.374745e-06 | C17: 9.374745e-06 | D17: 9.374745e-06 | E17: 9.374745e-06 | F17: 9.374745e-06 | G17: 9.374745e-06 | H17: 9.374745e-06 | I17: 9.374745e-06 | J17: 9.374745e-06 | K17: 9.374745e-06 | L17: 9.374745e-06 | M17: 9.374745e-06 | N17: 9.374745e-06 | O17: 9.374745e-06 | P17: 9.374745e-06 | Q17: 9.374745e-06 | R17: 9.374745e-06 | S17: 9.374745e-06 | T17: 9.374745e-06 | U17: 9.374745e-06 | V17: 9.374745e-06 | W17: 9.374745e-06 | X17: 9.374745e-06 | Y17: 9.374745e-06 | Z17: 9.374745e-06 | AA17: 9.374745e-06 | AB17: 9.374745e-06 | AC17: 9.374745e-06 | AD17: 9.374745e-06 | AE17: 9.374745e-06
A18: District Heating Sector | B18: 9.374745e-06 | C18: 9.374745e-06 | D18: 9.374745e-06 | E18: 9.374745e-06 | F18: 9.374745e-06 | G18: 9.374745e-06 | H18: 9.374745e-06 | I18: 9.374745e-06 | J18: 9.374745e-06 | K18: 9.374745e-06 | L18: 9.374745e-06 | M18: 9.374745e-06 | N18: 9.374745e-06 | O18: 9.374745e-06 | P18: 9.374745e-06 | Q18: 9.374745e-06 | R18: 9.374745e-06 | S18: 9.374745e-06 | T18: 9.374745e-06 | U18: 9.374745e-06 | V18: 9.374745e-06 | W18: 9.374745e-06 | X18: 9.374745e-06 | Y18: 9.374745e-06 | Z18: 9.374745e-06 | AA18: 9.374745e-06 | AB18: 9.374745e-06 | AC18: 9.374745e-06 | AD18: 9.374745e-06 | AE18: 9.374745e-06
A19: LULUCF Sector | B19: 9.374745e-06 | C19: 9.374745e-06 | D19: 9.374745e-06 | E19: 9.374745e-06 | F19: 9.374745e-06 | G19: 9.374745e-06 | H19: 9.374745e-06 | I19: 9.374745e-06 | J19: 9.374745e-06 | K19: 9.374745e-06 | L19: 9.374745e-06 | M19: 9.374745e-06 | N19: 9.374745e-06 | O19: 9.374745e-06 | P19: 9.374745e-06 | Q19: 9.374745e-06 | R19: 9.374745e-06 | S19: 9.374745e-06 | T19: 9.374745e-06 | U19: 9.374745e-06 | V19: 9.374745e-06 | W19: 9.374745e-06 | X19: 9.374745e-06 | Y19: 9.374745e-06 | Z19: 9.374745e-06 | AA19: 9.374745e-06 | AB19: 9.374745e-06 | AC19: 9.374745e-06 | AD19: 9.374745e-06 | AE19: 9.374745e-06
A20: Geoengineering Sector | B20: 9.374745e-06 | C20: 9.374745e-06 | D20: 9.374745e-06 | E20: 9.374745e-06 | F20: 9.374745e-06 | G20: 9.374745e-06 | H20: 9.374745e-06 | I20: 9.374745e-06 | J20: 9.374745e-06 | K20: 9.374745e-06 | L20: 9.374745e-06 | M20: 9.374745e-06 | N20: 9.374745e-06 | O20: 9.374745e-06 | P20: 9.374745e-06 | Q20: 9.374745e-06 | R20: 9.374745e-06 | S20: 9.374745e-06 | T20: 9.374745e-06 | U20: 9.374745e-06 | V20: 9.374745e-06 | W20: 9.374745e-06 | X20: 9.374745e-06 | Y20: 9.374745e-06 | Z20: 9.374745e-06 | AA20: 9.374745e-06 | AB20: 9.374745e-06 | AC20: 9.374745e-06 | AD20: 9.374745e-06 | AE20: 9.374745e-06
A21: Nuclear
A22: Year | B22: 2021 | C22: 2022 | D22: 2023 | E22: 2024 | F22: 2025 | G22: 2026 | H22: 2027 | I22: 2028 | J22: 2029 | K22: 2030 | L22: 2031 | M22: 2032 | N22: 2033 | O22: 2034 | P22: 2035 | Q22: 2036 | R22: 2037 | S22: 2038 | T22: 2039 | U22: 2040 | V22: 2041 | W22: 2042 | X22: 2043 | Y22: 2044 | Z22: 2045 | AA22: 2046 | AB22: 2047 | AC22: 2048 | AD22: 2049 | AE22: 2050 | AF22: 2051 | AG22: 2052 | AH22: 2053 | AI22: 2054 | AJ22: 2055 | AK22: 2056 | AL22: 2057 | AM22: 2058 | AN22: 2059 | AO22: 2060 | AP22: 2061 | AQ22: 2062 | AR22: 2063 | AS22: 2064 | AT22: 2065 | AU22: 2066 | AV22: 2067 | AW22: 2068 | AX22: 2069 | AY22: 2070
A23: Transportation Sector | B23: 0 | C23: 0 | D23: 0 | E23: 0 | F23: 0 | G23: 0 | H23: 0 | I23: 0 | J23: 0 | K23: 0 | L23: 0 | M23: 0 | N23: 0 | O23: 0 | P23: 0 | Q23: 0 | R23: 0 | S23: 0 | T23: 0 | U23: 0 | V23: 0 | W23: 0 | X23: 0 | Y23: 0 | Z23: 0 | AA23: 0 | AB23: 0 | AC23: 0 | AD23: 0 | AE23: 0
A24: Electricity Sector | B24: 7.4e-07 | C24: 7.4e-07 | D24: 7.4e-07 | E24: 7.4e-07 | F24: 7.4e-07 | G24: 7.4e-07 | H24: 7.4e-07 | I24: 7.4e-07 | J24: 7.5088235e-07 | K24: 7.5088235e-07 | L24: 7.5088235e-07 | M24: 7.5088235e-07 | N24: 7.5088235e-07 | O24: 7.5088235e-07 | P24: 7.5088235e-07 | Q24: 7.6176471e-07 | R24: 7.6176471e-07 | S24: 7.6176471e-07 | T24: 7.6176471e-07 | U24: 7.6176471e-07 | V24: 7.6176471e-07 | W24: 7.7264706e-07 | X24: 7.7264706e-07 | Y24: 7.7264706e-07 | Z24: 7.7264706e-07 | AA24: 7.7264706e-07 | AB24: 7.8352941e-07 | AC24: 7.8352941e-07 | AD24: 7.8352941e-07 | AE24: 7.8352941e-07
A25: Residential Buildings Sector | B25: 0 | C25: 0 | D25: 0 | E25: 0 | F25: 0 | G25: 0 | H25: 0 | I25: 0 | J25: 0 | K25: 0 | L25: 0 | M25: 0 | N25: 0 | O25: 0 | P25: 0 | Q25: 0 | R25: 0 | S25: 0 | T25: 0 | U25: 0 | V25: 0 | W25: 0 | X25: 0 | Y25: 0 | Z25: 0 | AA25: 0 | AB25: 0 | AC25: 0 | AD25: 0 | AE25: 0
A26: Commercial Buildings Sector | B26: 0 | C26: 0 | D26: 0 | E26: 0 | F26: 0 | G26: 0 | H26: 0 | I26: 0 | J26: 0 | K26: 0 | L26: 0 | M26: 0 | N26: 0 | O26: 0 | P26: 0 | Q26: 0 | R26: 0 | S26: 0 | T26: 0 | U26: 0 | V26: 0 | W26: 0 | X26: 0 | Y26: 0 | Z26: 0 | AA26: 0 | AB26: 0 | AC26: 0 | AD26: 0 | AE26: 0
A27: Industry Sector | B27: 0 | C27: 0 | D27: 0 | E27: 0 | F27: 0 | G27: 0 | H27: 0 | I27: 0 | J27: 0 | K27: 0 | L27: 0 | M27: 0 | N27: 0 | O27: 0 | P27: 0 | Q27: 0 | R27: 0 | S27: 0 | T27: 0 | U27: 0 | V27: 0 | W27: 0 | X27: 0 | Y27: 0 | Z27: 0 | AA27: 0 | AB27: 0 | AC27: 0 | AD27: 0 | AE27: 0
A28: District Heating Sector | B28: 0 | C28: 0 | D28: 0 | E28: 0 | F28: 0 | G28: 0 | H28: 0 | I28: 0 | J28: 0 | K28: 0 | L28: 0 | M28: 0 | N28: 0 | O28: 0 | P28: 0 | Q28: 0 | R28: 0 | S28: 0 | T28: 0 | U28: 0 | V28: 0 | W28: 0 | X28: 0 | Y28: 0 | Z28: 0 | AA28: 0 | AB28: 0 | AC28: 0 | AD28: 0 | AE28: 0
A29: LULUCF Sector | B29: 0 | C29: 0 | D29: 0 | E29: 0 | F29: 0 | G29: 0 | H29: 0 | I29: 0 | J29: 0 | K29: 0 | L29: 0 | M29: 0 | N29: 0 | O29: 0 | P29: 0 | Q29: 0 | R29: 0 | S29: 0 | T29: 0 | U29: 0 | V29: 0 | W29: 0 | X29: 0 | Y29: 0 | Z29: 0 | AA29: 0 | AB29: 0 | AC29: 0 | AD29: 0 | AE29: 0
A30: Geoengineering Sector | B30: 0 | C30: 0 | D30: 0 | E30: 0 | F30: 0 | G30: 0 | H30: 0 | I30: 0 | J30: 0 | K30: 0 | L30: 0 | M30: 0 | N30: 0 | O30: 0 | P30: 0 | Q30: 0 | R30: 0 | S30: 0 | T30: 0 | U30: 0 | V30: 0 | W30: 0 | X30: 0 | Y30: 0 | Z30: 0 | AA30: 0 | AB30: 0 | AC30: 0 | AD30: 0 | AE30: 0
A31: Biomass
A32: Year | B32: 2021 | C32: 2022 | D32: 2023 | E32: 2024 | F32: 2025 | G32: 2026 | H32: 2027 | I32: 2028 | J32: 2029 | K32: 2030 | L32: 2031 | M32: 2032 | N32: 2033 | O32: 2034 | P32: 2035 | Q32: 2036 | R32: 2037 | S32: 2038 | T32: 2039 | U32: 2040 | V32: 2041 | W32: 2042 | X32: 2043 | Y32: 2044 | Z32: 2045 | AA32: 2046 | AB32: 2047 | AC32: 2048 | AD32: 2049 | AE32: 2050 | AF32: 2051 | AG32: 2052 | AH32: 2053 | AI32: 2054 | AJ32: 2055 | AK32: 2056 | AL32: 2057 | AM32: 2058 | AN32: 2059 | AO32: 2060 | AP32: 2061 | AQ32: 2062 | AR32: 2063 | AS32: 2064 | AT32: 2065 | AU32: 2066 | AV32: 2067 | AW32: 2068 | AX32: 2069 | AY32: 2070
A33: Transportation Sector | B33: 0 | C33: 0 | D33: 0 | E33: 0 | F33: 0 | G33: 0 | H33: 0 | I33: 0 | J33: 0 | K33: 0 | L33: 0 | M33: 0 | N33: 0 | O33: 0 | P33: 0 | Q33: 0 | R33: 0 | S33: 0 | T33: 0 | U33: 0 | V33: 0 | W33: 0 | X33: 0 | Y33: 0 | Z33: 0 | AA33: 0 | AB33: 0 | AC33: 0 | AD33: 0 | AE33: 0
A34: Electricity Sector | B34: 2.2777859e-06 | C34: 2.2777859e-06 | D34: 2.2777859e-06 | E34: 2.2777859e-06 | F34: 2.2777859e-06 | G34: 2.2777859e-06 | H34: 2.2777859e-06 | I34: 2.2777859e-06 | J34: 2.2777859e-06 | K34: 2.2777859e-06 | L34: 2.2777859e-06 | M34: 2.2777859e-06 | N34: 2.2777859e-06 | O34: 2.2777859e-06 | P34: 2.2777859e-06 | Q34: 2.2777859e-06 | R34: 2.2777859e-06 | S34: 2.2777859e-06 | T34: 2.2777859e-06 | U34: 2.2777859e-06 | V34: 2.2777859e-06 | W34: 2.2777859e-06 | X34: 2.2777859e-06 | Y34: 2.2777859e-06 | Z34: 2.2777859e-06 | AA34: 2.2777859e-06 | AB34: 2.2777859e-06 | AC34: 2.2777859e-06 | AD34: 2.2777859e-06 | AE34: 2.2777859e-06
A35: Residential Buildings Sector | B35: 2.2777859e-06 | C35: 2.2777859e-06 | D35: 2.2777859e-06 | E35: 2.2777859e-06 | F35: 2.2777859e-06 | G35: 2.2777859e-06 | H35: 2.2777859e-06 | I35: 2.2777859e-06 | J35: 2.2777859e-06 | K35: 2.2777859e-06 | L35: 2.2777859e-06 | M35: 2.2777859e-06 | N35: 2.2777859e-06 | O35: 2.2777859e-06 | P35: 2.2777859e-06 | Q35: 2.2777859e-06 | R35: 2.2777859e-06 | S35: 2.2777859e-06 | T35: 2.2777859e-06 | U35: 2.2777859e-06 | V35: 2.2777859e-06 | W35: 2.2777859e-06 | X35: 2.2777859e-06 | Y35: 2.2777859e-06 | Z35: 2.2777859e-06 | AA35: 2.2777859e-06 | AB35: 2.2777859e-06 | AC35: 2.2777859e-06 | AD35: 2.2777859e-06 | AE35: 2.2777859e-06
A36: Commercial Buildings Sector | B36: 2.2777859e-06 | C36: 2.2777859e-06 | D36: 2.2777859e-06 | E36: 2.2777859e-06 | F36: 2.2777859e-06 | G36: 2.2777859e-06 | H36: 2.2777859e-06 | I36: 2.2777859e-06 | J36: 2.2777859e-06 | K36: 2.2777859e-06 | L36: 2.2777859e-06 | M36: 2.2777859e-06 | N36: 2.2777859e-06 | O36: 2.2777859e-06 | P36: 2.2777859e-06 | Q36: 2.2777859e-06 | R36: 2.2777859e-06 | S36: 2.2777859e-06 | T36: 2.2777859e-06 | U36: 2.2777859e-06 | V36: 2.2777859e-06 | W36: 2.2777859e-06 | X36: 2.2777859e-06 | Y36: 2.2777859e-06 | Z36: 2.2777859e-06 | AA36: 2.2777859e-06 | AB36: 2.2777859e-06 | AC36: 2.2777859e-06 | AD36: 2.2777859e-06 | AE36: 2.2777859e-06
A37: Industry Sector | B37: 2.2777859e-06 | C37: 2.2777859e-06 | D37: 2.2777859e-06 | E37: 2.2777859e-06 | F37: 2.2777859e-06 | G37: 2.2777859e-06 | H37: 2.2777859e-06 | I37: 2.2777859e-06 | J37: 2.2777859e-06 | K37: 2.2777859e-06 | L37: 2.2777859e-06 | M37: 2.2777859e-06 | N37: 2.2777859e-06 | O37: 2.2777859e-06 | P37: 2.2777859e-06 | Q37: 2.2777859e-06 | R37: 2.2777859e-06 | S37: 2.2777859e-06 | T37: 2.2777859e-06 | U37: 2.2777859e-06 | V37: 2.2777859e-06 | W37: 2.2777859e-06 | X37: 2.2777859e-06 | Y37: 2.2777859e-06 | Z37: 2.2777859e-06 | AA37: 2.2777859e-06 | AB37: 2.2777859e-06 | AC37: 2.2777859e-06 | AD37: 2.2777859e-06 | AE37: 2.2777859e-06
A38: District Heating Sector | B38: 2.2777859e-06 | C38: 2.2777859e-06 | D38: 2.2777859e-06 | E38: 2.2777859e-06 | F38: 2.2777859e-06 | G38: 2.2777859e-06 | H38: 2.2777859e-06 | I38: 2.2777859e-06 | J38: 2.2777859e-06 | K38: 2.2777859e-06 | L38: 2.2777859e-06 | M38: 2.2777859e-06 | N38: 2.2777859e-06 | O38: 2.2777859e-06 | P38: 2.2777859e-06 | Q38: 2.2777859e-06 | R38: 2.2777859e-06 | S38: 2.2777859e-06 | T38: 2.2777859e-06 | U38: 2.2777859e-06 | V38: 2.2777859e-06 | W38: 2.2777859e-06 | X38: 2.2777859e-06 | Y38: 2.2777859e-06 | Z38: 2.2777859e-06 | AA38: 2.2777859e-06 | AB38: 2.2777859e-06 | AC38: 2.2777859e-06 | AD38: 2.2777859e-06 | AE38: 2.2777859e-06
A39: LULUCF Sector | B39: 0 | C39: 0 | D39: 0 | E39: 0 | F39: 0 | G39: 0 | H39: 0 | I39: 0 | J39: 0 | K39: 0 | L39: 0 | M39: 0 | N39: 0 | O39: 0 | P39: 0 | Q39: 0 | R39: 0 | S39: 0 | T39: 0 | U39: 0 | V39: 0 | W39: 0 | X39: 0 | Y39: 0 | Z39: 0 | AA39: 0 | AB39: 0 | AC39: 0 | AD39: 0 | AE39: 0
A40: Geoengineering Sector | B40: 2.2777859e-06 | C40: 2.2777859e-06 | D40: 2.2777859e-06 | E40: 2.2777859e-06 | F40: 2.2777859e-06 | G40: 2.2777859e-06 | H40: 2.2777859e-06 | I40: 2.2777859e-06 | J40: 2.2777859e-06 | K40: 2.2777859e-06 | L40: 2.2777859e-06 | M40: 2.2777859e-06 | N40: 2.2777859e-06 | O40: 2.2777859e-06 | P40: 2.2777859e-06 | Q40: 2.2777859e-06 | R40: 2.2777859e-06 | S40: 2.2777859e-06 | T40: 2.2777859e-06 | U40: 2.2777859e-06 | V40: 2.2777859e-06 | W40: 2.2777859e-06 | X40: 2.2777859e-06 | Y40: 2.2777859e-06 | Z40: 2.2777859e-06 | AA40: 2.2777859e-06 | AB40: 2.2777859e-06 | AC40: 2.2777859e-06 | AD40: 2.2777859e-06 | AE40: 2.2777859e-06
...

Sheet Fuel Taxes
A1: Hard Coal
A2: Year | B2: 2021 | C2: 2022 | D2: 2023 | E2: 2024 | F2: 2025 | G2: 2026 | H2: 2027 | I2: 2028 | J2: 2029 | K2: 2030 | L2: 2031 | M2: 2032 | N2: 2033 | O2: 2034 | P2: 2035 | Q2: 2036 | R2: 2037 | S2: 2038 | T2: 2039 | U2: 2040 | V2: 2041 | W2: 2042 | X2: 2043 | Y2: 2044 | Z2: 2045 | AA2: 2046 | AB2: 2047 | AC2: 2048 | AD2: 2049 | AE2: 2050 | AF2: 2051 | AG2: 2052 | AH2: 2053 | AI2: 2054 | AJ2: 2055 | AK2: 2056 | AL2: 2057 | AM2: 2058 | AN2: 2059 | AO2: 2060 | AP2: 2061 | AQ2: 2062 | AR2: 2063 | AS2: 2064 | AT2: 2065 | AU2: 2066 | AV2: 2067 | AW2: 2068 | AX2: 2069 | AY2: 2070
A3: Transportation Sector | B3: 0 | C3: 0 | D3: 0 | E3: 0 | F3: 0 | G3: 0 | H3: 0 | I3: 0 | J3: 0 | K3: 0 | L3: 0 | M3: 0 | N3: 0 | O3: 0 | P3: 0 | Q3: 0 | R3: 0 | S3: 0 | T3: 0 | U3: 0 | V3: 0 | W3: 0 | X3: 0 | Y3: 0 | Z3: 0 | AA3: 0 | AB3: 0 | AC3: 0 | AD3: 0 | AE3: 0
A4: Electricity Sector | B4: 4.4933639e-07 | C4: 4.4933639e-07 | D4: 4.4715515e-07 | E4: 4.4933639e-07 | F4: 4.4279266e-07 | G4: 4.3624893e-07 | H4: 4.3188644e-07 | I4: 4.2970519e-07 | J4: 4.253427e-07 | K4: 4.2752395e-07 | L4: 4.2970519e-07 | M4: 4.2752395e-07 | N4: 4.2752395e-07 | O4: 4.2752395e-07 | P4: 4.253427e-07 | Q4: 4.253427e-07 | R4: 4.2752395e-07 | S4: 4.2752395e-07 | T4: 4.253427e-07 | U4: 4.253427e-07 | V4: 4.2752395e-07 | W4: 4.2752395e-07 | X4: 4.253427e-07 | Y4: 4.253427e-07 | Z4: 4.253427e-07 | AA4: 4.253427e-07 | AB4: 4.253427e-07 | AC4: 4.253427e-07 | AD4: 4.253427e-07 | AE4: 4.253427e-07
A5: Residential Buildings Sector | B5: 0 | C5: 0 | D5: 0 | E5: 0 | F5: 0 | G5: 0 | H5: 0 | I5: 0 | J5: 0 | K5: 0 | L5: 0 | M5: 0 | N5: 0 | O5: 0 | P5: 0 | Q5: 0 | R5: 0 | S5: 0 | T5: 0 | U5: 0 | V5: 0 | W5: 0 | X5: 0 | Y5: 0 | Z5: 0 | AA5: 0 | AB5: 0 | AC5: 0 | AD5: 0 | AE5: 0
A6: Commercial Buildings Sector | B6: 0 | C6: 0 | D6: 0 | E6: 0 | F6: 0 | G6: 0 | H6: 0 | I6: 0 | J6: 0 | K6: 0 | L6: 0 | M6: 0 | N6: 0 | O6: 0 | P6: 0 | Q6: 0 | R6: 0 | S6: 0 | T6: 0 | U6: 0 | V6: 0 | W6: 0 | X6: 0 | Y6: 0 | Z6: 0 | AA6: 0 | AB6: 0 | AC6: 0 | AD6: 0 | AE6: 0
A7: Industry Sector | B7: 5.3898368e-07 | C7: 5.3898368e-07 | D7: 5.3898368e-07 | E7: 5.3898368e-07 | F7: 5.4520272e-07 | G7: 5.4520272e-07 | H7: 5.4520272e-07 | I7: 5.4727574e-07 | J7: 5.4934875e-07 | K7: 5.5142176e-07 | L7: 5.5556779e-07 | M7: 5.5556779e-07 | N7: 5.5764081e-07 | O7: 5.5971382e-07 | P7: 5.6178683e-07 | Q7: 5.6178683e-07 | R7: 5.6385985e-07 | S7: 5.6385985e-07 | T7: 5.6593286e-07 | U7: 5.6593286e-07 | V7: 5.6800588e-07 | W7: 5.7007889e-07 | X7: 5.7215191e-07 | Y7: 5.7422492e-07 | Z7: 5.7629793e-07 | AA7: 5.7837095e-07 | AB7: 5.8044396e-07 | AC7: 5.8251698e-07 | AD7: 5.8458999e-07 | AE7: 5.86663e-07
A8: District Heating Sector | B8: 5.3898368e-07 | C8: 5.3898368e-07 | D8: 5.3898368e-07 | E8: 5.3898368e-07 | F8: 5.4520272e-07 | G8: 5.4520272e-07 | H8: 5.4520272e-07 | I8: 5.4727574e-07 | J8: 5.4934875e-07 | K8: 5.5142176e-07 | L8: 5.5556779e-07 | M8: 5.5556779e-07 | N8: 5.5764081e-07 | O8: 5.5971382e-07 | P8: 5.6178683e-07 | Q8: 5.6178683e-07 | R8: 5.6385985e-07 | S8: 5.6385985e-07 | T8: 5.6593286e-07 | U8: 5.6593286e-07 | V8: 5.6800588e-07 | W8: 5.7007889e-07 | X8: 5.7215191e-07 | Y8: 5.7422492e-07 | Z8: 5.7629793e-07 | AA8: 5.7837095e-07 | AB8: 5.8044396e-07 | AC8: 5.8251698e-07 | AD8: 5.8458999e-07 | AE8: 5.86663e-07
A9: LULUCF Sector | B9: 0 | C9: 0 | D9: 0 | E9: 0 | F9: 0 | G9: 0 | H9: 0 | I9: 0 | J9: 0 | K9: 0 | L9: 0 | M9: 0 | N9: 0 | O9: 0 | P9: 0 | Q9: 0 | R9: 0 | S9: 0 | T9: 0 | U9: 0 | V9: 0 | W9: 0 | X9: 0 | Y9: 0 | Z9: 0 | AA9: 0 | AB9: 0 | AC9: 0 | AD9: 0 | AE9: 0
A10: Geoengineering Sector | B10: 5.3898368e-07 | C10: 5.3898368e-07 | D10: 5.3898368e-07 | E10: 5.3898368e-07 | F10: 5.4520272e-07 | G10: 5.4520272e-07 | H10: 5.4520272e-07 | I10: 5.4727574e-07 | J10: 5.4934875e-07 | K10: 5.5142176e-07 | L10: 5.5556779e-07 | M10: 5.5556779e-07 | N10: 5.5764081e-07 | O10: 5.5971382e-07 | P10: 5.6178683e-07 | Q10: 5.6178683e-07 | R10: 5.6385985e-07 | S10: 5.6385985e-07 | T10: 5.6593286e-07 | U10: 5.6593286e-07 | V10: 5.6800588e-07 | W10: 5.7007889e-07 | X10: 5.7215191e-07 | Y10: 5.7422492e-07 | Z10: 5.7629793e-07 | AA10: 5.7837095e-07 | AB10: 5.8044396e-07 | AC10: 5.8251698e-07 | AD10: 5.8458999e-07 | AE10: 5.86663e-07
A11: Natural Gas
A12: Year | B12: 2021 | C12: 2022 | D12: 2023 | E12: 2024 | F12: 2025 | G12: 2026 | H12: 2027 | I12: 2028 | J12: 2029 | K12: 2030 | L12: 2031 | M12: 2032 | N12: 2033 | O12: 2034 | P12: 2035 | Q12: 2036 | R12: 2037 | S12: 2038 | T12: 2039 | U12: 2040 | V12: 2041 | W12: 2042 | X12: 2043 | Y12: 2044 | Z12: 2045 | AA12: 2046 | AB12: 2047 | AC12: 2048 | AD12: 2049 | AE12: 2050 | AF12: 2051 | AG12: 2052 | AH12: 2053 | AI12: 2054 | AJ12: 2055 | AK12: 2056 | AL12: 2057 | AM12: 2058 | AN12: 2059 | AO12: 2060 | AP12: 2061 | AQ12: 2062 | AR12: 2063 | AS12: 2064 | AT12: 2065 | AU12: 2066 | AV12: 2067 | AW12: 2068 | AX12: 2069 | AY12: 2070
A13: Transportation Sector | B13: 1.4019128e-06 | C13: 1.4019128e-06 | D13: 1.4019128e-06 | E13: 1.4019128e-06 | F13: 2.1035625e-06 | G13: 2.1883324e-06 | H13: 2.0300189e-06 | I13: 1.9007603e-06 | J13: 1.9540371e-06 | K13: 2.0245964e-06 | L13: 2.0638152e-06 | M13: 2.1542939e-06 | N13: 2.232393e-06 | O13: 2.2685685e-06 | P13: 2.2784251e-06 | Q13: 2.3222225e-06 | R13: 2.3657539e-06 | S13: 2.3859909e-06 | T13: 2.3966134e-06 | U13: 2.3997469e-06 | V13: 2.3936433e-06 | W13: 2.4081748e-06 | X13: 2.4085927e-06 | Y13: 2.4078444e-06 | Z13: 2.4076884e-06 | AA13: 2.3939187e-06 | AB13: 2.3782645e-06 | AC13: 2.3756987e-06 | AD13: 2.3796538e-06 | AE13: 2.3886821e-06
A14: Electricity Sector | B14: 8.5053632e-07 | C14: 8.5053632e-07 | D14: 8.5053632e-07 | E14: 8.5053632e-07 | F14: 1.2762251e-06 | G14: 1.3276548e-06 | H14: 1.2316064e-06 | I14: 1.1531856e-06 | J14: 1.1855085e-06 | K14: 1.2283166e-06 | L14: 1.2521106e-06 | M14: 1.3070037e-06 | N14: 1.3543862e-06 | O14: 1.3763338e-06 | P14: 1.3823137e-06 | Q14: 1.4088855e-06 | R14: 1.4352959e-06 | S14: 1.4475736e-06 | T14: 1.4540182e-06 | U14: 1.4559193e-06 | V14: 1.4522163e-06 | W14: 1.4610325e-06 | X14: 1.4612861e-06 | Y14: 1.4608321e-06 | Z14: 1.4607374e-06 | AA14: 1.4523834e-06 | AB14: 1.442886e-06 | AC14: 1.4413294e-06 | AD14: 1.4437289e-06 | AE14: 1.4492063e-06
A15: Residential Buildings Sector | B15: 1.4019128e-06 | C15: 1.4019128e-06 | D15: 1.4019128e-06 | E15: 1.4019128e-06 | F15: 1.4019128e-06 | G15: 1.4019128e-06 | H15: 1.4019128e-06 | I15: 1.4019128e-06 | J15: 1.4019128e-06 | K15: 1.4019128e-06 | L15: 1.4019128e-06 | M15: 1.4019128e-06 | N15: 1.4019128e-06 | O15: 1.4019128e-06 | P15: 1.4019128e-06 | Q15: 1.4019128e-06 | R15: 1.4019128e-06 | S15: 1.4019128e-06 | T15: 1.4019128e-06 | U15: 1.4019128e-06 | V15: 1.4019128e-06 | W15: 1.4019128e-06 | X15: 1.4019128e-06 | Y15: 1.4019128e-06 | Z15: 1.4019128e-06 | AA15: 1.4019128e-06 | AB15: 1.4019128e-06 | AC15: 1.4019128e-06 | AD15: 1.4019128e-06 | AE15: 1.4019128e-06
A16: Commercial Buildings Sector | B16: 1.4019128e-06 | C16: 1.4019128e-06 | D16: 1.4019128e-06 | E16: 1.4019128e-06 | F16: 1.4019128e-06 | G16: 1.4019128e-06 | H16: 1.4019128e-06 | I16: 1.4019128e-06 | J16: 1.4019128e-06 | K16: 1.4019128e-06 | L16: 1.4019128e-06 | M16: 1.4019128e-06 | N16: 1.4019128e-06 | O16: 1.4019128e-06 | P16: 1.4019128e-06 | Q16: 1.4019128e-06 | R16: 1.4019128e-06 | S16: 1.4019128e-06 | T16: 1.4019128e-06 | U16: 1.4019128e-06 | V16: 1.4019128e-06 | W16: 1.4019128e-06 | X16: 1.4019128e-06 | Y16: 1.4019128e-06 | Z16: 1.4019128e-06 | AA16: 1.4019128e-06 | AB16: 1.4019128e-06 | AC16: 1.4019128e-06 | AD16: 1.4019128e-06 | AE16: 1.4019128e-06
A17: Industry Sector | B17: 1.4019128e-06 | C17: 1.4019128e-06 | D17: 1.4019128e-06 | E17: 1.4019128e-06 | F17: 1.4019128e-06 | G17: 1.4019128e-06 | H17: 1.4019128e-06 | I17: 1.4019128e-06 | J17: 1.4019128e-06 | K17: 1.4019128e-06 | L17: 1.4019128e-06 | M17: 1.4019128e-06 | N17: 1.4019128e-06 | O17: 1.4019128e-06 | P17: 1.4019128e-06 | Q17: 1.4019128e-06 | R17: 1.4019128e-06 | S17: 1.4019128e-06 | T17: 1.4019128e-06 | U17: 1.4019128e-06 | V17: 1.4019128e-06 | W17: 1.4019128e-06 | X17: 1.4019128e-06 | Y17: 1.4019128e-06 | Z17: 1.4019128e-06 | AA17: 1.4019128e-06 | AB17: 1.4019128e-06 | AC17: 1.4019128e-06 | AD17: 1.4019128e-06 | AE17: 1.4019128e-06
A18: District Heating Sector | B18: 1.4019128e-06 | C18: 1.4019128e-06 | D18: 1.4019128e-06 | E18: 1.4019128e-06 | F18: 1.4019128e-06 | G18: 1.4019128e-06 | H18: 1.4019128e-06 | I18: 1.4019128e-06 | J18: 1.4019128e-06 | K18: 1.4019128e-06 | L18: 1.4019128e-06 | M18: 1.4019128e-06 | N18: 1.4019128e-06 | O18: 1.4019128e-06 | P18: 1.4019128e-06 | Q18: 1.4019128e-06 | R18: 1.4019128e-06 | S18: 1.4019128e-06 | T18: 1.4019128e-06 | U18: 1.4019128e-06 | V18: 1.4019128e-06 | W18: 1.4019128e-06 | X18: 1.4019128e-06 | Y18: 1.4019128e-06 | Z18: 1.4019128e-06 | AA18: 1.4019128e-06 | AB18: 1.4019128e-06 | AC18: 1.4019128e-06 | AD18: 1.4019128e-06 | AE18: 1.4019128e-06
A19: LULUCF Sector | B19: 1.4019128e-06 | C19: 1.4019128e-06 | D19: 1.4019128e-06 | E19: 1.4019128e-06 | F19: 1.4019128e-06 | G19: 1.4019128e-06 | H19: 1.4019128e-06 | I19: 1.4019128e-06 | J19: 1.4019128e-06 | K19: 1.4019128e-06 | L19: 1.4019128e-06 | M19: 1.4019128e-06 | N19: 1.4019128e-06 | O19: 1.4019128e-06 | P19: 1.4019128e-06 | Q19: 1.4019128e-06 | R19: 1.4019128e-06 | S19: 1.4019128e-06 | T19: 1.4019128e-06 | U19: 1.4019128e-06 | V19: 1.4019128e-06 | W19: 1.4019128e-06 | X19: 1.4019128e-06 | Y19: 1.4019128e-06 | Z19: 1.4019128e-06 | AA19: 1.4019128e-06 | AB19: 1.4019128e-06 | AC19: 1.4019128e-06 | AD19: 1.4019128e-06 | AE19: 1.4019128e-06
A20: Geoengineering Sector | B20: 1.4019128e-06 | C20: 1.4019128e-06 | D20: 1.4019128e-06 | E20: 1.4019128e-06 | F20: 1.4019128e-06 | G20: 1.4019128e-06 | H20: 1.4019128e-06 | I20: 1.4019128e-06 | J20: 1.4019128e-06 | K20: 1.4019128e-06 | L20: 1.4019128e-06 | M20: 1.4019128e-06 | N20: 1.4019128e-06 | O20: 1.4019128e-06 | P20: 1.4019128e-06 | Q20: 1.4019128e-06 | R20: 1.4019128e-06 | S20: 1.4019128e-06 | T20: 1.4019128e-06 | U20: 1.4019128e-06 | V20: 1.4019128e-06 | W20: 1.4019128e-06 | X20: 1.4019128e-06 | Y20: 1.4019128e-06 | Z20: 1.4019128e-06 | AA20: 1.4019128e-06 | AB20: 1.4019128e-06 | AC20: 1.4019128e-06 | AD20: 1.4019128e-06 | AE20: 1.4019128e-06
A21: Nuclear
A22: Year | B22: 2021 | C22: 2022 | D22: 2023 | E22: 2024 | F22: 2025 | G22: 2026 | H22: 2027 | I22: 2028 | J22: 2029 | K22: 2030 | L22: 2031 | M22: 2032 | N22: 2033 | O22: 2034 | P22: 2035 | Q22: 2036 | R22: 2037 | S22: 2038 | T22: 2039 | U22: 2040 | V22: 2041 | W22: 2042 | X22: 2043 | Y22: 2044 | Z22: 2045 | AA22: 2046 | AB22: 2047 | AC22: 2048 | AD22: 2049 | AE22: 2050 | AF22: 2051 | AG22: 2052 | AH22: 2053 | AI22: 2054 | AJ22: 2055 | AK22: 2056 | AL22: 2057 | AM22: 2058 | AN22: 2059 | AO22: 2060 | AP22: 2061 | AQ22: 2062 | AR22: 2063 | AS22: 2064 | AT22: 2065 | AU22: 2066 | AV22: 2067 | AW22: 2068 | AX22: 2069 | AY22: 2070
