Workbook

Sheet About
A1: BCRbQ BAU Capacity Retirements before Quantization
A3: Sources: | B3: Projected Retirements
B4: CEA
B5: 2023
B6: National Electricity Plan - Generation
B7: NEP_2022_32_FINAL_GAZETTE-1.pdf (cea.nic.in)
B8: Data on schedules capacity retirements for coal based power plants between 2022-2031
B9: Annexure 5.2 - List of LIST OF COAL BASED PLANTS FOR LIKELY RETIREMENT DURING 2022-32
B10: Historical Retirements
B11: CEA
B12: 2021-2024
B13: Monthly Installed Capacity Report - jan 2021 - Feb 2024
B14: Installed Capacity Report - Central Electricity Authority (cea.nic.in)
B15: Section B in each of the monthly reports
B16: Historical 'Other' Changes in Capacity
B17: CEA
B18: 2023
B19: Annual Report
B20: Approved_CEA_Annual_Report_2022_23.pdf
A22: Notes
A23: This variable represents BAU planned capacity retirements and expected capacity
A24: retirements planned in CEA's National Electricity Plan, 2023
A25: It does not represent any other projected economic retirements.
A27: Quantization
A28: The EPS retires (and builds) power plants in increments of the minimum power plant size,
A29: specified in elec/MPPC. If the BAU retirements you get when running the model do not
A30: match those specified in this variable, this may be because your values here are not
A31: even multiples of the values in elec/MPPC. If you wish to ensure your retirement schedule
A32: is followed precisely, make sure that retirements specified here are even multiples of the
A33: values in elec/MPPC. You can reduce the values in elec/MPPC if helpful.

Sheet CEA Annual Review Report

Sheet CEA Monthly Reports Raw Data
A1: Month - Year | B1: Capacity Added/Uprated | C1: Capacity Retired/Converted from IPP to CPP | D1: Total Retired (in MW) | E1: Source | F1: Action | G1: Type
A2: 44197 | B2: Unit-1,2&3 (37*3=111 MW) of SAWRA KUDDU HPS has been commissioned and added to state sector of Himachal Pradesh. | C2: Unit-1&2 (2x120 = 240 MW) of KORBA-III has been retired from state sector of Chhattisgarh | D2: 240 | E2: coal | F2: retired
B3: 2. Unit-2 (660 MW) of MEJA STPP has been commissioned and added to central sector of NR states as per their allocation | C3: Unit-1&2 (2x70 = 140 MW) of KUTCH LIG. TPS has been retired from state sector of Gujarat | D3: 140 | E3: lignite | F3: retired
B4: 3. Unit-3 (150 MW) of KAMENG HPS has been commissioned and added to central sector of NER, NR & WR states as per their allocation
A5: 44228 | B5: 1. Unit-2 (800 MW) of GADARWARA TPP has been commissioned and added to central sector of WR states as per their allocation.
B6: 2. Unit-2 (500 MW) of NEYVELI NEW TPP has been commissioned and added to central sector of SR states as per their allocation
B7: 3. Unit-4 (150 MW) of KAMENG HPS has been commissioned and added to central sector of NER, NR & WR states as per their allocation
A8: 44256 | C8: 1. Unit-1,2&3 (2*5 + 1*6.5 = 16.5 MW) of BARAMURA GT has been retired from state sector of Tripura. | D8: 16.5 | E8: Gas | F8: retired | G8: gas turbine
C9: 2. Unit-1&2 (2x8 = 16 MW) of ROKHIA GT has been retired from state sector of Tripura. | D9: 16 | E9: Gas | F9: retired | G9: gas turbine
A11: 44287 | B11: 0 | C11: 0
A12: 44317 | B12: 0 | C12: 0
A13: 44348 | B13: 1. Unit-1&2 (56.5*2 = 113 MW) of RONGNICHU HPS has been commissioned and added to private sector of Sikkim. | C13: 1. Unit-3 (210 MW) of BOKARO `B` TPS has been retired from central sector of Eastern Region w.e.f. 01.04.2021 | D13: 210 | E13: Coal | F13: retired
C14: 2. Unit-1 to 6 (4*60 MW + 2*110 MW = 460 MW) of TALCHER (OLD) TPS has been retired from central sector of Eastern Region w.e.f. 01.04.2021 | D14: 460 | E14: Coal | F14: retired
A15: 44378 | B15: . Unit-2 (800 MW) of DARLIPALI STPS has been commissioned and added to central sector of ER & WR states as per their allocation.
B16: 1. KARCHAM WANGTOO HPS uprated from 1000 MW (4x250 MW) to 1045 MW (4x261.25 MW)
A18: 44409 | B18: . U1,2&3 of KALINADI HPS have been uprated from 135 MW to 150 MW each | C18: 1. STERLITE TPP U-1 (600 MW) has been converted from IPP to CPP. | D18: 600 | E18: Coal | F18: conversion
A19: 44440 | B19: 1. Unit-1&2 (2x50 = 100 MW) of SORANG HPS has been commissioned and added to private sector of Himachal Pradesh. | C19: . Unit-7 (210 MW) of KORADI TPS has been retired from state sector of Maharashtra. | D19: 210 | E19: Coal | F19: retired
C20: 2. Unit-1,2,3 (3x3 = 9 MW) of Adamtilla CCPP has been retired from private sector of Assam. | D20: 9 | E20: Gas | F20: retired | G20: ccpp
C21: 3. Unit-1,2,3,4 (3x3.5+1x5 = 15.5 MW) of Baskhandi CCPP has been retired from private sector of Assam. | D21: 15.5 | E21: Gas | F21: retired | G21: ccpp
A22: 44470 | B22: 1. Unit-8 (660 MW) of SURATGARH TPS has been commissioned and added to state sector of Rajasthan. | C22: 1. JSW RATNAGIRI TPP U-2,3&4 (3*300=900 MW) are being used as CPP by JSW ENERGY LTD. | D22: 900 | E22: coal | F22: conversion | G22: ipp to cpp
B23: 2. Unit-1 (660 MW) of BARH I has been commissioned and added to central sector of ER states as per their allocation.
A24: 44501 | B24: 1. Unit 4 (250 MW) of NABI NAGAR TPP has been commissioned and share has been added to the central sector of beneficiary states of ER.
A25: 44531 | B25: 1. Unit-1 (525 MW) of TUTICORIN TPP ST-IV has been commissioned and added to private sector of Tamilnadu.
A26: 44562 | B26: Capacity additions present | C26: 1. Unit-1,2 (2x110 = 220 MW) of MUZAFFARPUR TPS has been retired from state sector of Bihar. | D26: 220 | E26: coal | F26: retired
A27: 44593 | B27: 1. HIRAKUD HPS U-5 & 6 uprated from 37.5 MW to 43.65 MW each.
A28: 44621 | B28: . Unit-3 (660 MW) of NABINAGAR STPP has been commissioned and added to central sector of ER & NR states as per their allocation. | C28: 1. Unit-1 (60 MW) of BANDEL TPS has been retired from state sector of West Bengal. | D28: 60 | E28: coal | F28: retired
B29: 2. Unit-1,2&3 (3x60 = 180 MW) of BAJOLI HOLI HPS has been commissioned and added to private sector of Himachal Pradesh. | C29: 2. Unit-1&2 (2x210 = 420 MW) of KOLAGHAT TPS has been retired from state sector of West Bengal | D29: 420 | E29: coal | F29: retired
B30: . BHAKRA LEFT HPS U-3 uprated from 108 MW to 126 MW.
A31: 44652 | B31: NULL | C31: NULL
A32: 44682 | C32: Unit-1 (20 MW) of SILIGURI GPS has been removed from State sector of West Bengal. | D32: 20 | E32: Gas | F32: removed | G32: gas turbine
A33: 44713 | B33: Unit-1 & 2 (2x60 MW) Vyasi HPS has been commissioned and added in state sector of Uttarakhand | C33: Namrup CCGT Unit-2,3& 6 (21+21+22=64 MW) of APGCL has been derated to (17+ 15+9=41 MW). | D33: =64-41 -> 23 | E33: Gas | F33: derated | G33: CCGT
B34: Unit-1,2 & 3 (3x15=45 MW) of Nariamangalam HE Project has been uprated to (3x17.55=52.65 MW)
A35: 44743 | B35: none | C35: none
A36: 44774 | B36: none | C36: none
A37: 44805 | B37: Revised Diesel based Capacity of A&N Islands is 92.71 MW in place of earlier 40.05 MW | C37: Unit-1 & 2 (2x60 MW) Vyasi HPS has been commissioned and added in state sector of Uttarakhand
A38: 44835 | C38: Obra TPS Unit-7 (94 MW) of UPRVUNL has been retired and removed from state installed capacity of UP | D38: 94 | E38: coal | F38: removed
A39: 44866 | B39: Revised Diesel based capacity of Lakshdweep Islands is 26.83 MW as received from Electricity Department of Lakshadweep
A40: 44896 | C40: Durgapur TPS U-4 (210 MW) of Damodar Valley Corporation has been retired and removed from the capacity of Central sector. | D40: 210 | E40: Coal | F40: retired/removed
A41: 44927 | B41: Unit-1 (660 MW) of North Karanpura STPP, NTPC has been commissioned on 18.01.2023 and capacity added in central sector installed capacity.
A42: 44958 | B42: none | C42: None
...

Sheet CEA monthly calcs
A1: Year | B1: Reduction (in MW) | C1: Source | D1: Action | E1: Type | F1: Retirements | G1: 2021 | H1: 2022
A2: 2021 | B2: 240 | C2: Coal | D2: retired | F2: Coal | G2: 1720 | H2: =SUMIFS($B$2:$B$19,$C$2:$C$19,"Coal",$A$2:$A$19,"2022") -> 1004
A3: 2021 | B3: 140 | C3: lignite | D3: retired | F3: Gas | G3: =SUMIFS($B$2:$B$19,$C$2:$C$19,"Gas",$A$2:$A$19,"2021") -> 57 | H3: =SUMIFS($B$2:$B$19,$C$2:$C$19,"gas",$A$2:$A$19,"2022") -> 43
A4: 2021 | B4: 16.5 | C4: Gas | D4: retired | E4: gas turbine | F4: Lignite | G4: =SUMIFS($B$2:$B$19,$C$2:$C$19,"Lignite",$A$2:$A$19,"2021") -> 140 | H4: =SUMIFS($B$2:$B$19,$C$2:$C$19,"lignite",$A$2:$A$19,"2022") -> 0
A5: 2021 | B5: 16 | C5: Gas | D5: retired | E5: gas turbine | G5: =SUM(G2:G4) -> 1917 | H5: =SUM(H2:H4) -> 1047 | I5: =SUM(G5:H5) -> 2964
A6: 2021 | B6: 210 | C6: Coal | D6: retired
A7: 2021 | B7: 460 | C7: Coal | D7: retired | F7: Check
A8: 2021 | B8: 600 | C8: Coal | D8: conversion
A9: 2021 | B9: 210 | C9: Coal | D9: retired
A10: 2021 | B10: 9 | C10: Gas | D10: retired | E10: ccpp
A11: 2021 | B11: 15.5 | C11: Gas | D11: retired | E11: ccpp
A12: 2021 | B12: 900 | C12: coal | D12: conversion
A13: 2022 | B13: 220 | C13: coal | D13: retired
A14: 2022 | B14: 60 | C14: coal | D14: retired
A15: 2022 | B15: 420 | C15: Coal | D15: retired
A16: 2022 | B16: 20 | C16: Gas | D16: removed
A17: 2022 | B17: =64-41 -> 23 | C17: Gas | D17: derated
A18: 2022 | B18: 94 | C18: coal | D18: removed
A19: 2022 | B19: 210 | C19: Coal | D19: retired/removed
A20: Total retired | B20: =SUM(B2:B19) -> 3864
B21: =SUM(B2,B6,B7,B8,B9,B12) -> 2620
B22: =B21-G2 -> 900

Sheet CEA Ret. Schedule
A4: S.NO | B4: NAME OF PROJECT | C4: STATE | D4: SECTOR | E4: ORGANISATION | F4: TOTAL CAPACITY (MW)
A5: 1 | B5: BARAUNI TPS U6,7 | C5: BIHAR | D5: CENTRAL SECTOR | E5: NTPC | F5: 2*105=210
A6: 2 | B6: TANDA TPS U1-4 | C6: UTTAR PRADESH | D6: CENTRAL SECTOR | E6: NTPC | F6: 4*110=440
A7: 3 | B7: DURGAPUR TPS UNIT 4* | C7: WEST BENGAL | D7: CENTRAL SECTOR | E7: DVC | F7: 210
A8: 4 | B8: RAMAGUNDEM-B TPS U2 | C8: TELANGANA | D8: STATE SECTOR | E8: TSGENCO | F8: 62.5
A9: 5 | B9: OBRA TPS* | C9: UTTAR PARDESH | D9: STATE SECTOR | E9: UPRVUNL | F9: 94
A10: 6 | B10: BANDEL U2 | C10: WEST BENGAL | D10: STATE SECTOR | E10: WBPDC | F10: 1*60=60
A11: 7 | B11: PARICHHA TPS UNIT 1,2 | C11: UTTAR PARDESH | D11: STATE SECTOR | E11: UPRVUNL | F11: 2*110=220
A12: 8 | B12: KOTA TPS UNIT 1-2 | C12: RAJASTHAN | D12: STATE SECTOR | E12: RRVUNL | F12: 2*110=220
A13: 9 | B13: HARDUAGANJ TPS UNIT 7 | C13: UTTAR PRADESH | D13: STATE SECTOR | E13: UPRVUNL | F13: 110
A14: 10 | B14: GEPL TPP PH-I UNIT 1,2 | C14: MAHARASHTRA | D14: PRIVATE SECTOR | E14: GEPL | F14: 2*60=120
A15: 11 | B15: SALORA TPP U1 | C15: CHHATTISGARH | D15: PRIVATE SECTOR | E15: VVL | F15: 135
A16: 12 | B16: TITAGARH TPS UNIT 1-4 | C16: WEST BENGAL | D16: PRIVATE SECTOR | E16: CESC | F16: 4*60=240
B17: TOTAL | F17: 2121.5
B18: Coal plants that have already been retired as a part of this schedule | F18: =94+210+60 -> 364
B19: Capacity to be reitred over the span of the next 8 years 2024-2025 - 2031-2032 | F19: =F17-F18 -> 1757.5
B20: Yearly coal capacity targeted | F20: =F19/8 -> 219.6875

Sheet BCRbQ
A1: BAU Capacity Retirements (MW) | B1: 2021 | C1: 2022 | D1: 2023 | E1: 2024 | F1: 2025 | G1: 2026 | H1: 2027 | I1: 2028 | J1: 2029 | K1: 2030 | L1: 2031 | M1: 2032 | N1: 2033 | O1: 2034 | P1: 2035 | Q1: 2036 | R1: 2037 | S1: 2038 | T1: 2039 | U1: 2040 | V1: 2041 | W1: 2042 | X1: 2043 | Y1: 2044 | Z1: 2045 | AA1: 2046 | AB1: 2047 | AC1: 2048 | AD1: 2049 | AE1: 2050 | AF1: 2051 | AG1: 2052 | AH1: 2053 | AI1: 2054 | AJ1: 2055 | AK1: 2056 | AL1: 2057 | AM1: 2058 | AN1: 2059 | AO1: 2060 | AP1: 2061 | AQ1: 2062 | AR1: 2063 | AS1: 2064 | AT1: 2065 | AU1: 2066 | AV1: 2067 | AW1: 2068 | AX1: 2069 | AY1: 2070
A2: hard coal | B2: ='CEA monthly calcs'!B21 -> 2620 | C2: ='CEA monthly calcs'!H2 -> 1004 | D2: 0 | E2: ='CEA Ret. Schedule'!$F$20 -> 219.6875 | F2: ='CEA Ret. Schedule'!$F$20 -> 219.6875 | G2: ='CEA Ret. Schedule'!$F$20 -> 219.6875 | H2: ='CEA Ret. Schedule'!$F$20 -> 219.6875 | I2: ='CEA Ret. Schedule'!$F$20 -> 219.6875 | J2: ='CEA Ret. Schedule'!$F$20 -> 219.6875 | K2: ='CEA Ret. Schedule'!$F$20 -> 219.6875 | L2: ='CEA Ret. Schedule'!$F$20 -> 219.6875 | M2: 0 | N2: 0 | O2: 0 | P2: 0 | Q2: 0 | R2: 0 | S2: 0 | T2: 0 | U2: 0 | V2: 0 | W2: 0 | X2: 0 | Y2: 0 | Z2: 0 | AA2: 0 | AB2: 0 | AC2: 0 | AD2: 0 | AE2: 0 | AF2: 0 | AG2: 0 | AH2: 0 | AI2: 0 | AJ2: 0 | AK2: 0 | AL2: 0 | AM2: 0 | AN2: 0 | AO2: 0 | AP2: 0 | AQ2: 0 | AR2: 0 | AS2: 0 | AT2: 0 | AU2: 0 | AV2: 0 | AW2: 0 | AX2: 0 | AY2: 0
A3: natural gas steam turbine | B3: 32.5 | C3: 20 | D3: 0 | E3: 0 | F3: 0 | G3: 0 | H3: 0 | I3: 0 | J3: 0 | K3: 0 | L3: 0 | M3: 0 | N3: 0 | O3: 0 | P3: 0 | Q3: 0 | R3: 0 | S3: 0 | T3: 0 | U3: 0 | V3: 0 | W3: 0 | X3: 0 | Y3: 0 | Z3: 0 | AA3: 0 | AB3: 0 | AC3: 0 | AD3: 0 | AE3: 0 | AF3: 0 | AG3: 0 | AH3: 0 | AI3: 0 | AJ3: 0 | AK3: 0 | AL3: 0 | AM3: 0 | AN3: 0 | AO3: 0 | AP3: 0 | AQ3: 0 | AR3: 0 | AS3: 0 | AT3: 0 | AU3: 0 | AV3: 0 | AW3: 0 | AX3: 0 | AY3: 0
A4: natural gas combined cycle | B4: 24.5 | C4: 23 | D4: 0 | E4: 0 | F4: 0 | G4: 0 | H4: 0 | I4: 0 | J4: 0 | K4: 0 | L4: 0 | M4: 0 | N4: 0 | O4: 0 | P4: 0 | Q4: 0 | R4: 0 | S4: 0 | T4: 0 | U4: 0 | V4: 0 | W4: 0 | X4: 0 | Y4: 0 | Z4: 0 | AA4: 0 | AB4: 0 | AC4: 0 | AD4: 0 | AE4: 0 | AF4: 0 | AG4: 0 | AH4: 0 | AI4: 0 | AJ4: 0 | AK4: 0 | AL4: 0 | AM4: 0 | AN4: 0 | AO4: 0 | AP4: 0 | AQ4: 0 | AR4: 0 | AS4: 0 | AT4: 0 | AU4: 0 | AV4: 0 | AW4: 0 | AX4: 0 | AY4: 0
A5: nuclear | B5: 0 | C5: 0 | D5: 0 | E5: 0 | F5: 0 | G5: 0 | H5: 0 | I5: 0 | J5: 0 | K5: 0 | L5: 0 | M5: 0 | N5: 0 | O5: 0 | P5: 0 | Q5: 0 | R5: 0 | S5: 0 | T5: 0 | U5: 0 | V5: 0 | W5: 0 | X5: 0 | Y5: 0 | Z5: 0 | AA5: 0 | AB5: 0 | AC5: 0 | AD5: 0 | AE5: 0 | AF5: 0 | AG5: 0 | AH5: 0 | AI5: 0 | AJ5: 0 | AK5: 0 | AL5: 0 | AM5: 0 | AN5: 0 | AO5: 0 | AP5: 0 | AQ5: 0 | AR5: 0 | AS5: 0 | AT5: 0 | AU5: 0 | AV5: 0 | AW5: 0 | AX5: 0 | AY5: 0
A6: hydro | B6: 0 | C6: 0 | D6: 0 | E6: 0 | F6: 0 | G6: 0 | H6: 0 | I6: 0 | J6: 0 | K6: 0 | L6: 0 | M6: 0 | N6: 0 | O6: 0 | P6: 0 | Q6: 0 | R6: 0 | S6: 0 | T6: 0 | U6: 0 | V6: 0 | W6: 0 | X6: 0 | Y6: 0 | Z6: 0 | AA6: 0 | AB6: 0 | AC6: 0 | AD6: 0 | AE6: 0 | AF6: 0 | AG6: 0 | AH6: 0 | AI6: 0 | AJ6: 0 | AK6: 0 | AL6: 0 | AM6: 0 | AN6: 0 | AO6: 0 | AP6: 0 | AQ6: 0 | AR6: 0 | AS6: 0 | AT6: 0 | AU6: 0 | AV6: 0 | AW6: 0 | AX6: 0 | AY6: 0
A7: onshore wind | B7: 0 | C7: 0 | D7: 0 | E7: 0 | F7: 0 | G7: 0 | H7: 0 | I7: 0 | J7: 0 | K7: 0 | L7: 0 | M7: 0 | N7: 0 | O7: 0 | P7: 0 | Q7: 0 | R7: 0 | S7: 0 | T7: 0 | U7: 0 | V7: 0 | W7: 0 | X7: 0 | Y7: 0 | Z7: 0 | AA7: 0 | AB7: 0 | AC7: 0 | AD7: 0 | AE7: 0 | AF7: 0 | AG7: 0 | AH7: 0 | AI7: 0 | AJ7: 0 | AK7: 0 | AL7: 0 | AM7: 0 | AN7: 0 | AO7: 0 | AP7: 0 | AQ7: 0 | AR7: 0 | AS7: 0 | AT7: 0 | AU7: 0 | AV7: 0 | AW7: 0 | AX7: 0 | AY7: 0
A8: solar pv | B8: 0 | C8: 0 | D8: 0 | E8: 0 | F8: 0 | G8: 0 | H8: 0 | I8: 0 | J8: 0 | K8: 0 | L8: 0 | M8: 0 | N8: 0 | O8: 0 | P8: 0 | Q8: 0 | R8: 0 | S8: 0 | T8: 0 | U8: 0 | V8: 0 | W8: 0 | X8: 0 | Y8: 0 | Z8: 0 | AA8: 0 | AB8: 0 | AC8: 0 | AD8: 0 | AE8: 0 | AF8: 0 | AG8: 0 | AH8: 0 | AI8: 0 | AJ8: 0 | AK8: 0 | AL8: 0 | AM8: 0 | AN8: 0 | AO8: 0 | AP8: 0 | AQ8: 0 | AR8: 0 | AS8: 0 | AT8: 0 | AU8: 0 | AV8: 0 | AW8: 0 | AX8: 0 | AY8: 0
A9: solar thermal | B9: 0 | C9: 0 | D9: 0 | E9: 0 | F9: 0 | G9: 0 | H9: 0 | I9: 0 | J9: 0 | K9: 0 | L9: 0 | M9: 0 | N9: 0 | O9: 0 | P9: 0 | Q9: 0 | R9: 0 | S9: 0 | T9: 0 | U9: 0 | V9: 0 | W9: 0 | X9: 0 | Y9: 0 | Z9: 0 | AA9: 0 | AB9: 0 | AC9: 0 | AD9: 0 | AE9: 0 | AF9: 0 | AG9: 0 | AH9: 0 | AI9: 0 | AJ9: 0 | AK9: 0 | AL9: 0 | AM9: 0 | AN9: 0 | AO9: 0 | AP9: 0 | AQ9: 0 | AR9: 0 | AS9: 0 | AT9: 0 | AU9: 0 | AV9: 0 | AW9: 0 | AX9: 0 | AY9: 0
A10: biomass | B10: 0 | C10: 0 | D10: 0 | E10: 0 | F10: 0 | G10: 0 | H10: 0 | I10: 0 | J10: 0 | K10: 0 | L10: 0 | M10: 0 | N10: 0 | O10: 0 | P10: 0 | Q10: 0 | R10: 0 | S10: 0 | T10: 0 | U10: 0 | V10: 0 | W10: 0 | X10: 0 | Y10: 0 | Z10: 0 | AA10: 0 | AB10: 0 | AC10: 0 | AD10: 0 | AE10: 0 | AF10: 0 | AG10: 0 | AH10: 0 | AI10: 0 | AJ10: 0 | AK10: 0 | AL10: 0 | AM10: 0 | AN10: 0 | AO10: 0 | AP10: 0 | AQ10: 0 | AR10: 0 | AS10: 0 | AT10: 0 | AU10: 0 | AV10: 0 | AW10: 0 | AX10: 0 | AY10: 0
A11: geothermal | B11: 0 | C11: 0 | D11: 0 | E11: 0 | F11: 0 | G11: 0 | H11: 0 | I11: 0 | J11: 0 | K11: 0 | L11: 0 | M11: 0 | N11: 0 | O11: 0 | P11: 0 | Q11: 0 | R11: 0 | S11: 0 | T11: 0 | U11: 0 | V11: 0 | W11: 0 | X11: 0 | Y11: 0 | Z11: 0 | AA11: 0 | AB11: 0 | AC11: 0 | AD11: 0 | AE11: 0 | AF11: 0 | AG11: 0 | AH11: 0 | AI11: 0 | AJ11: 0 | AK11: 0 | AL11: 0 | AM11: 0 | AN11: 0 | AO11: 0 | AP11: 0 | AQ11: 0 | AR11: 0 | AS11: 0 | AT11: 0 | AU11: 0 | AV11: 0 | AW11: 0 | AX11: 0 | AY11: 0
A12: petroleum | B12: 0 | C12: 0 | D12: 0 | E12: 0 | F12: 0 | G12: 0 | H12: 0 | I12: 0 | J12: 0 | K12: 0 | L12: 0 | M12: 0 | N12: 0 | O12: 0 | P12: 0 | Q12: 0 | R12: 0 | S12: 0 | T12: 0 | U12: 0 | V12: 0 | W12: 0 | X12: 0 | Y12: 0 | Z12: 0 | AA12: 0 | AB12: 0 | AC12: 0 | AD12: 0 | AE12: 0 | AF12: 0 | AG12: 0 | AH12: 0 | AI12: 0 | AJ12: 0 | AK12: 0 | AL12: 0 | AM12: 0 | AN12: 0 | AO12: 0 | AP12: 0 | AQ12: 0 | AR12: 0 | AS12: 0 | AT12: 0 | AU12: 0 | AV12: 0 | AW12: 0 | AX12: 0 | AY12: 0
A13: natural gas peaker | B13: 0 | C13: 0 | D13: 0 | E13: 0 | F13: 0 | G13: 0 | H13: 0 | I13: 0 | J13: 0 | K13: 0 | L13: 0 | M13: 0 | N13: 0 | O13: 0 | P13: 0 | Q13: 0 | R13: 0 | S13: 0 | T13: 0 | U13: 0 | V13: 0 | W13: 0 | X13: 0 | Y13: 0 | Z13: 0 | AA13: 0 | AB13: 0 | AC13: 0 | AD13: 0 | AE13: 0 | AF13: 0 | AG13: 0 | AH13: 0 | AI13: 0 | AJ13: 0 | AK13: 0 | AL13: 0 | AM13: 0 | AN13: 0 | AO13: 0 | AP13: 0 | AQ13: 0 | AR13: 0 | AS13: 0 | AT13: 0 | AU13: 0 | AV13: 0 | AW13: 0 | AX13: 0 | AY13: 0
A14: lignite | B14: 140 | C14: 0 | D14: 0 | E14: 0 | F14: 0 | G14: 0 | H14: 0 | I14: 0 | J14: 0 | K14: 0 | L14: 0 | M14: 0 | N14: 0 | O14: 0 | P14: 0 | Q14: 0 | R14: 0 | S14: 0 | T14: 0 | U14: 0 | V14: 0 | W14: 0 | X14: 0 | Y14: 0 | Z14: 0 | AA14: 0 | AB14: 0 | AC14: 0 | AD14: 0 | AE14: 0 | AF14: 0 | AG14: 0 | AH14: 0 | AI14: 0 | AJ14: 0 | AK14: 0 | AL14: 0 | AM14: 0 | AN14: 0 | AO14: 0 | AP14: 0 | AQ14: 0 | AR14: 0 | AS14: 0 | AT14: 0 | AU14: 0 | AV14: 0 | AW14: 0 | AX14: 0 | AY14: 0
... A25: hydrogen combined cycle | B25: 0 | C25: 0 | D25: 0 | E25: 0 | F25: 0 | G25: 0 | H25: 0 | I25: 0 | J25: 0 | K25: 0 | L25: 0 | M25: 0 | N25: 0 | O25: 0 | P25: 0 | Q25: 0 | R25: 0 | S25: 0 | T25: 0 | U25: 0 | V25: 0 | W25: 0 | X25: 0 | Y25: 0 | Z25: 0 | AA25: 0 | AB25: 0 | AC25: 0 | AD25: 0 | AE25: 0 | AF25: 0 | AG25: 0 | AH25: 0 | AI25: 0 | AJ25: 0 | AK25: 0 | AL25: 0 | AM25: 0 | AN25: 0 | AO25: 0 | AP25: 0 | AQ25: 0 | AR25: 0 | AS25: 0 | AT25: 0 | AU25: 0 | AV25: 0 | AW25: 0 | AX25: 0 | AY25: 0
